[2023-12-07T14:52:23.699+0000] {taskinstance.py:1159} INFO - Dependencies all met for dep_context=non-requeueable deps ti=<TaskInstance: my_scraping_dag.main_task scheduled__2023-05-08T00:00:00+00:00 [queued]>
[2023-12-07T14:52:23.702+0000] {taskinstance.py:1159} INFO - Dependencies all met for dep_context=requeueable deps ti=<TaskInstance: my_scraping_dag.main_task scheduled__2023-05-08T00:00:00+00:00 [queued]>
[2023-12-07T14:52:23.702+0000] {taskinstance.py:1361} INFO - Starting attempt 1 of 1
[2023-12-07T14:52:23.707+0000] {taskinstance.py:1382} INFO - Executing <Task(PythonOperator): main_task> on 2023-05-08 00:00:00+00:00
[2023-12-07T14:52:23.709+0000] {standard_task_runner.py:57} INFO - Started process 1019 to run task
[2023-12-07T14:52:23.711+0000] {standard_task_runner.py:84} INFO - Running: ['***', 'tasks', 'run', 'my_scraping_dag', 'main_task', 'scheduled__2023-05-08T00:00:00+00:00', '--job-id', '238', '--raw', '--subdir', 'DAGS_FOLDER/main.py', '--cfg-path', '/tmp/tmppxetah_u']
[2023-12-07T14:52:23.713+0000] {standard_task_runner.py:85} INFO - Job 238: Subtask main_task
[2023-12-07T14:52:23.732+0000] {task_command.py:416} INFO - Running <TaskInstance: my_scraping_dag.main_task scheduled__2023-05-08T00:00:00+00:00 [running]> on host 63b0c7e341c0
[2023-12-07T14:52:23.762+0000] {taskinstance.py:1662} INFO - Exporting env vars: AIRFLOW_CTX_DAG_OWNER='***' AIRFLOW_CTX_DAG_ID='my_scraping_dag' AIRFLOW_CTX_TASK_ID='main_task' AIRFLOW_CTX_EXECUTION_DATE='2023-05-08T00:00:00+00:00' AIRFLOW_CTX_TRY_NUMBER='1' AIRFLOW_CTX_DAG_RUN_ID='scheduled__2023-05-08T00:00:00+00:00'
[2023-12-07T14:52:23.763+0000] {taskinstance.py:1937} ERROR - Task failed with exception
Traceback (most recent call last):
  File "/usr/local/lib/python3.8/configparser.py", line 846, in items
    d.update(self._sections[section])
KeyError: 'web'

During handling of the above exception, another exception occurred:

Traceback (most recent call last):
  File "/home/airflow/.local/lib/python3.8/site-packages/airflow/operators/python.py", line 192, in execute
    return_value = self.execute_callable()
  File "/home/airflow/.local/lib/python3.8/site-packages/airflow/operators/python.py", line 209, in execute_callable
    return self.python_callable(*self.op_args, **self.op_kwargs)
  File "/opt/airflow/dags/main.py", line 61, in main
    config = get_config('web')
  File "/opt/airflow/dags/main.py", line 23, in get_config
    return {key: value for key, value in parser.items(section)}
  File "/usr/local/lib/python3.8/configparser.py", line 849, in items
    raise NoSectionError(section)
configparser.NoSectionError: No section: 'web'
[2023-12-07T14:52:23.766+0000] {taskinstance.py:1400} INFO - Marking task as FAILED. dag_id=my_scraping_dag, task_id=main_task, execution_date=20230508T000000, start_date=20231207T145223, end_date=20231207T145223
[2023-12-07T14:52:23.770+0000] {standard_task_runner.py:104} ERROR - Failed to execute job 238 for task main_task (No section: 'web'; 1019)
[2023-12-07T14:52:23.812+0000] {local_task_job_runner.py:228} INFO - Task exited with return code 1
[2023-12-07T14:52:23.824+0000] {taskinstance.py:2778} INFO - 0 downstream tasks scheduled from follow-on schedule check
[2023-12-07T16:32:23.318+0000] {taskinstance.py:1159} INFO - Dependencies all met for dep_context=non-requeueable deps ti=<TaskInstance: my_scraping_dag.main_task scheduled__2023-05-08T00:00:00+00:00 [queued]>
[2023-12-07T16:32:23.323+0000] {taskinstance.py:1159} INFO - Dependencies all met for dep_context=requeueable deps ti=<TaskInstance: my_scraping_dag.main_task scheduled__2023-05-08T00:00:00+00:00 [queued]>
[2023-12-07T16:32:23.324+0000] {taskinstance.py:1361} INFO - Starting attempt 1 of 1
[2023-12-07T16:32:23.331+0000] {taskinstance.py:1382} INFO - Executing <Task(PythonOperator): main_task> on 2023-05-08 00:00:00+00:00
[2023-12-07T16:32:23.335+0000] {standard_task_runner.py:57} INFO - Started process 3796 to run task
[2023-12-07T16:32:23.338+0000] {standard_task_runner.py:84} INFO - Running: ['***', 'tasks', 'run', 'my_scraping_dag', 'main_task', 'scheduled__2023-05-08T00:00:00+00:00', '--job-id', '716', '--raw', '--subdir', 'DAGS_FOLDER/main.py', '--cfg-path', '/tmp/tmpwgtm0mc4']
[2023-12-07T16:32:23.340+0000] {standard_task_runner.py:85} INFO - Job 716: Subtask main_task
[2023-12-07T16:32:23.376+0000] {task_command.py:416} INFO - Running <TaskInstance: my_scraping_dag.main_task scheduled__2023-05-08T00:00:00+00:00 [running]> on host 63b0c7e341c0
[2023-12-07T16:32:23.432+0000] {taskinstance.py:1662} INFO - Exporting env vars: AIRFLOW_CTX_DAG_OWNER='***' AIRFLOW_CTX_DAG_ID='my_scraping_dag' AIRFLOW_CTX_TASK_ID='main_task' AIRFLOW_CTX_EXECUTION_DATE='2023-05-08T00:00:00+00:00' AIRFLOW_CTX_TRY_NUMBER='1' AIRFLOW_CTX_DAG_RUN_ID='scheduled__2023-05-08T00:00:00+00:00'
[2023-12-07T16:32:23.434+0000] {taskinstance.py:1937} ERROR - Task failed with exception
Traceback (most recent call last):
  File "/usr/local/lib/python3.8/configparser.py", line 846, in items
    d.update(self._sections[section])
KeyError: 'web'

During handling of the above exception, another exception occurred:

Traceback (most recent call last):
  File "/home/airflow/.local/lib/python3.8/site-packages/airflow/operators/python.py", line 192, in execute
    return_value = self.execute_callable()
  File "/home/airflow/.local/lib/python3.8/site-packages/airflow/operators/python.py", line 209, in execute_callable
    return self.python_callable(*self.op_args, **self.op_kwargs)
  File "/opt/airflow/dags/main.py", line 60, in main
    config = get_config('web')
  File "/opt/airflow/dags/main.py", line 22, in get_config
    return {key: value for key, value in parser.items(section)}
  File "/usr/local/lib/python3.8/configparser.py", line 849, in items
    raise NoSectionError(section)
configparser.NoSectionError: No section: 'web'
[2023-12-07T16:32:23.445+0000] {taskinstance.py:1400} INFO - Marking task as FAILED. dag_id=my_scraping_dag, task_id=main_task, execution_date=20230508T000000, start_date=20231207T163223, end_date=20231207T163223
[2023-12-07T16:32:23.461+0000] {standard_task_runner.py:104} ERROR - Failed to execute job 716 for task main_task (No section: 'web'; 3796)
[2023-12-07T16:32:23.471+0000] {local_task_job_runner.py:228} INFO - Task exited with return code 1
[2023-12-07T16:32:23.489+0000] {taskinstance.py:2778} INFO - 0 downstream tasks scheduled from follow-on schedule check
[2023-12-07T16:41:39.816+0000] {taskinstance.py:1159} INFO - Dependencies all met for dep_context=non-requeueable deps ti=<TaskInstance: my_scraping_dag.main_task scheduled__2023-05-08T00:00:00+00:00 [queued]>
[2023-12-07T16:41:39.824+0000] {taskinstance.py:1159} INFO - Dependencies all met for dep_context=requeueable deps ti=<TaskInstance: my_scraping_dag.main_task scheduled__2023-05-08T00:00:00+00:00 [queued]>
[2023-12-07T16:41:39.824+0000] {taskinstance.py:1361} INFO - Starting attempt 1 of 1
[2023-12-07T16:41:39.833+0000] {taskinstance.py:1382} INFO - Executing <Task(PythonOperator): main_task> on 2023-05-08 00:00:00+00:00
[2023-12-07T16:41:39.837+0000] {standard_task_runner.py:57} INFO - Started process 4700 to run task
[2023-12-07T16:41:39.839+0000] {standard_task_runner.py:84} INFO - Running: ['***', 'tasks', 'run', 'my_scraping_dag', 'main_task', 'scheduled__2023-05-08T00:00:00+00:00', '--job-id', '1058', '--raw', '--subdir', 'DAGS_FOLDER/main.py', '--cfg-path', '/tmp/tmp9uw4sy8_']
[2023-12-07T16:41:39.841+0000] {standard_task_runner.py:85} INFO - Job 1058: Subtask main_task
[2023-12-07T16:41:39.867+0000] {task_command.py:416} INFO - Running <TaskInstance: my_scraping_dag.main_task scheduled__2023-05-08T00:00:00+00:00 [running]> on host 63b0c7e341c0
[2023-12-07T16:41:39.909+0000] {taskinstance.py:1662} INFO - Exporting env vars: AIRFLOW_CTX_DAG_OWNER='***' AIRFLOW_CTX_DAG_ID='my_scraping_dag' AIRFLOW_CTX_TASK_ID='main_task' AIRFLOW_CTX_EXECUTION_DATE='2023-05-08T00:00:00+00:00' AIRFLOW_CTX_TRY_NUMBER='1' AIRFLOW_CTX_DAG_RUN_ID='scheduled__2023-05-08T00:00:00+00:00'
[2023-12-07T16:41:39.911+0000] {taskinstance.py:1937} ERROR - Task failed with exception
Traceback (most recent call last):
  File "/usr/local/lib/python3.8/configparser.py", line 846, in items
    d.update(self._sections[section])
KeyError: 'web'

During handling of the above exception, another exception occurred:

Traceback (most recent call last):
  File "/home/airflow/.local/lib/python3.8/site-packages/airflow/operators/python.py", line 192, in execute
    return_value = self.execute_callable()
  File "/home/airflow/.local/lib/python3.8/site-packages/airflow/operators/python.py", line 209, in execute_callable
    return self.python_callable(*self.op_args, **self.op_kwargs)
  File "/opt/airflow/dags/main.py", line 60, in main
    config = get_config('web')
  File "/opt/airflow/dags/main.py", line 22, in get_config
    return {key: value for key, value in parser.items(section)}
  File "/usr/local/lib/python3.8/configparser.py", line 849, in items
    raise NoSectionError(section)
configparser.NoSectionError: No section: 'web'
[2023-12-07T16:41:39.917+0000] {taskinstance.py:1400} INFO - Marking task as FAILED. dag_id=my_scraping_dag, task_id=main_task, execution_date=20230508T000000, start_date=20231207T164139, end_date=20231207T164139
[2023-12-07T16:41:39.927+0000] {standard_task_runner.py:104} ERROR - Failed to execute job 1058 for task main_task (No section: 'web'; 4700)
[2023-12-07T16:41:39.972+0000] {local_task_job_runner.py:228} INFO - Task exited with return code 1
[2023-12-07T16:41:39.990+0000] {taskinstance.py:2778} INFO - 0 downstream tasks scheduled from follow-on schedule check
[2023-12-07T17:00:43.569+0000] {taskinstance.py:1159} INFO - Dependencies all met for dep_context=non-requeueable deps ti=<TaskInstance: my_scraping_dag.main_task scheduled__2023-05-08T00:00:00+00:00 [queued]>
[2023-12-07T17:00:43.574+0000] {taskinstance.py:1159} INFO - Dependencies all met for dep_context=requeueable deps ti=<TaskInstance: my_scraping_dag.main_task scheduled__2023-05-08T00:00:00+00:00 [queued]>
[2023-12-07T17:00:43.574+0000] {taskinstance.py:1361} INFO - Starting attempt 1 of 1
[2023-12-07T17:00:43.582+0000] {taskinstance.py:1382} INFO - Executing <Task(PythonOperator): main_task> on 2023-05-08 00:00:00+00:00
[2023-12-07T17:00:43.585+0000] {standard_task_runner.py:57} INFO - Started process 5876 to run task
[2023-12-07T17:00:43.588+0000] {standard_task_runner.py:84} INFO - Running: ['***', 'tasks', 'run', 'my_scraping_dag', 'main_task', 'scheduled__2023-05-08T00:00:00+00:00', '--job-id', '1411', '--raw', '--subdir', 'DAGS_FOLDER/main.py', '--cfg-path', '/tmp/tmp4eucbi_n']
[2023-12-07T17:00:43.590+0000] {standard_task_runner.py:85} INFO - Job 1411: Subtask main_task
[2023-12-07T17:00:43.619+0000] {task_command.py:416} INFO - Running <TaskInstance: my_scraping_dag.main_task scheduled__2023-05-08T00:00:00+00:00 [running]> on host 63b0c7e341c0
[2023-12-07T17:00:43.663+0000] {taskinstance.py:1662} INFO - Exporting env vars: AIRFLOW_CTX_DAG_OWNER='***' AIRFLOW_CTX_DAG_ID='my_scraping_dag' AIRFLOW_CTX_TASK_ID='main_task' AIRFLOW_CTX_EXECUTION_DATE='2023-05-08T00:00:00+00:00' AIRFLOW_CTX_TRY_NUMBER='1' AIRFLOW_CTX_DAG_RUN_ID='scheduled__2023-05-08T00:00:00+00:00'
[2023-12-07T17:00:43.698+0000] {logging_mixin.py:154} INFO - base_url: https://tuncbotanik.com
[2023-12-07T17:00:43.703+0000] {python.py:194} INFO - Done. Returned value was: ('https://tuncbotanik.com', {'User-Agent': 'Mozilla/5.0 (Macintosh; Intel Mac OS X 10_15_7) AppleWebKit/537.36 (KHTML, like Gecko) Chrome/119.0.0.0 Safari/537.36', 'Accept-Language': 'tr-TR,tr;q=0.9,en-US;q=0.8,en;q=0.7'}, {'dbname': 'plant', 'user': 'aozgokme', 'password': '***', 'host': 'localhost', 'port': '5432'})
[2023-12-07T17:00:43.725+0000] {taskinstance.py:1400} INFO - Marking task as SUCCESS. dag_id=my_scraping_dag, task_id=main_task, execution_date=20230508T000000, start_date=20231207T170043, end_date=20231207T170043
[2023-12-07T17:00:43.802+0000] {local_task_job_runner.py:228} INFO - Task exited with return code 0
[2023-12-07T17:00:43.840+0000] {taskinstance.py:2778} INFO - 0 downstream tasks scheduled from follow-on schedule check
[2023-12-07T17:03:58.590+0000] {taskinstance.py:1159} INFO - Dependencies all met for dep_context=non-requeueable deps ti=<TaskInstance: my_scraping_dag.main_task scheduled__2023-05-08T00:00:00+00:00 [queued]>
[2023-12-07T17:03:58.594+0000] {taskinstance.py:1159} INFO - Dependencies all met for dep_context=requeueable deps ti=<TaskInstance: my_scraping_dag.main_task scheduled__2023-05-08T00:00:00+00:00 [queued]>
[2023-12-07T17:03:58.595+0000] {taskinstance.py:1361} INFO - Starting attempt 1 of 1
[2023-12-07T17:03:58.602+0000] {taskinstance.py:1382} INFO - Executing <Task(PythonOperator): main_task> on 2023-05-08 00:00:00+00:00
[2023-12-07T17:03:58.606+0000] {standard_task_runner.py:57} INFO - Started process 7316 to run task
[2023-12-07T17:03:58.608+0000] {standard_task_runner.py:84} INFO - Running: ['***', 'tasks', 'run', 'my_scraping_dag', 'main_task', 'scheduled__2023-05-08T00:00:00+00:00', '--job-id', '2095', '--raw', '--subdir', 'DAGS_FOLDER/main.py', '--cfg-path', '/tmp/tmpms93m425']
[2023-12-07T17:03:58.610+0000] {standard_task_runner.py:85} INFO - Job 2095: Subtask main_task
[2023-12-07T17:03:58.635+0000] {task_command.py:416} INFO - Running <TaskInstance: my_scraping_dag.main_task scheduled__2023-05-08T00:00:00+00:00 [running]> on host 63b0c7e341c0
[2023-12-07T17:03:58.685+0000] {taskinstance.py:1662} INFO - Exporting env vars: AIRFLOW_CTX_DAG_OWNER='***' AIRFLOW_CTX_DAG_ID='my_scraping_dag' AIRFLOW_CTX_TASK_ID='main_task' AIRFLOW_CTX_EXECUTION_DATE='2023-05-08T00:00:00+00:00' AIRFLOW_CTX_TRY_NUMBER='1' AIRFLOW_CTX_DAG_RUN_ID='scheduled__2023-05-08T00:00:00+00:00'
[2023-12-07T17:03:58.719+0000] {logging_mixin.py:154} INFO - base_url: https://tuncbotanik.com
[2023-12-07T17:03:58.720+0000] {python.py:194} INFO - Done. Returned value was: ('https://tuncbotanik.com', {'User-Agent': 'Mozilla/5.0 (Macintosh; Intel Mac OS X 10_15_7) AppleWebKit/537.36 (KHTML, like Gecko) Chrome/119.0.0.0 Safari/537.36', 'Accept-Language': 'tr-TR,tr;q=0.9,en-US;q=0.8,en;q=0.7'}, {'dbname': 'plant', 'user': 'aozgokme', 'password': '***', 'host': 'localhost', 'port': '5432'})
[2023-12-07T17:03:58.740+0000] {taskinstance.py:1400} INFO - Marking task as SUCCESS. dag_id=my_scraping_dag, task_id=main_task, execution_date=20230508T000000, start_date=20231207T170358, end_date=20231207T170358
[2023-12-07T17:03:58.782+0000] {local_task_job_runner.py:228} INFO - Task exited with return code 0
[2023-12-07T17:03:58.803+0000] {taskinstance.py:2778} INFO - 0 downstream tasks scheduled from follow-on schedule check
[2023-12-07T17:18:44.332+0000] {taskinstance.py:1159} INFO - Dependencies all met for dep_context=non-requeueable deps ti=<TaskInstance: my_scraping_dag.main_task scheduled__2023-05-08T00:00:00+00:00 [queued]>
[2023-12-07T17:18:44.337+0000] {taskinstance.py:1159} INFO - Dependencies all met for dep_context=requeueable deps ti=<TaskInstance: my_scraping_dag.main_task scheduled__2023-05-08T00:00:00+00:00 [queued]>
[2023-12-07T17:18:44.337+0000] {taskinstance.py:1361} INFO - Starting attempt 1 of 1
[2023-12-07T17:18:44.358+0000] {taskinstance.py:1382} INFO - Executing <Task(PythonOperator): main_task> on 2023-05-08 00:00:00+00:00
[2023-12-07T17:18:44.361+0000] {standard_task_runner.py:57} INFO - Started process 8803 to run task
[2023-12-07T17:18:44.363+0000] {standard_task_runner.py:84} INFO - Running: ['***', 'tasks', 'run', 'my_scraping_dag', 'main_task', 'scheduled__2023-05-08T00:00:00+00:00', '--job-id', '2657', '--raw', '--subdir', 'DAGS_FOLDER/main.py', '--cfg-path', '/tmp/tmpdtfwcj9d']
[2023-12-07T17:18:44.365+0000] {standard_task_runner.py:85} INFO - Job 2657: Subtask main_task
[2023-12-07T17:18:44.393+0000] {task_command.py:416} INFO - Running <TaskInstance: my_scraping_dag.main_task scheduled__2023-05-08T00:00:00+00:00 [running]> on host 63b0c7e341c0
[2023-12-07T17:18:44.432+0000] {taskinstance.py:1662} INFO - Exporting env vars: AIRFLOW_CTX_DAG_OWNER='***' AIRFLOW_CTX_DAG_ID='my_scraping_dag' AIRFLOW_CTX_TASK_ID='main_task' AIRFLOW_CTX_EXECUTION_DATE='2023-05-08T00:00:00+00:00' AIRFLOW_CTX_TRY_NUMBER='1' AIRFLOW_CTX_DAG_RUN_ID='scheduled__2023-05-08T00:00:00+00:00'
[2023-12-07T17:18:45.306+0000] {taskinstance.py:1937} ERROR - Task failed with exception
Traceback (most recent call last):
  File "/home/airflow/.local/lib/python3.8/site-packages/airflow/operators/python.py", line 192, in execute
    return_value = self.execute_callable()
  File "/home/airflow/.local/lib/python3.8/site-packages/airflow/operators/python.py", line 209, in execute_callable
    return self.python_callable(*self.op_args, **self.op_kwargs)
  File "/opt/airflow/dags/main.py", line 80, in main
    insert_data_to_db(products, db_params)
  File "/opt/airflow/dags/main.py", line 43, in insert_data_to_db
    with psycopg2.connect(**db_params) as conn:
  File "/home/airflow/.local/lib/python3.8/site-packages/psycopg2/__init__.py", line 122, in connect
    conn = _connect(dsn, connection_factory=connection_factory, **kwasync)
psycopg2.OperationalError: connection to server at "localhost" (127.0.0.1), port 5432 failed: Connection refused
	Is the server running on that host and accepting TCP/IP connections?
connection to server at "localhost" (::1), port 5432 failed: Cannot assign requested address
	Is the server running on that host and accepting TCP/IP connections?

[2023-12-07T17:18:45.310+0000] {taskinstance.py:1400} INFO - Marking task as FAILED. dag_id=my_scraping_dag, task_id=main_task, execution_date=20230508T000000, start_date=20231207T171844, end_date=20231207T171845
[2023-12-07T17:18:45.316+0000] {standard_task_runner.py:104} ERROR - Failed to execute job 2657 for task main_task (connection to server at "localhost" (127.0.0.1), port 5432 failed: Connection refused
	Is the server running on that host and accepting TCP/IP connections?
connection to server at "localhost" (::1), port 5432 failed: Cannot assign requested address
	Is the server running on that host and accepting TCP/IP connections?
; 8803)
[2023-12-07T17:18:45.340+0000] {local_task_job_runner.py:228} INFO - Task exited with return code 1
[2023-12-07T17:18:45.349+0000] {taskinstance.py:2778} INFO - 0 downstream tasks scheduled from follow-on schedule check
[2023-12-07T17:23:03.388+0000] {taskinstance.py:1159} INFO - Dependencies all met for dep_context=non-requeueable deps ti=<TaskInstance: my_scraping_dag.main_task scheduled__2023-05-08T00:00:00+00:00 [queued]>
[2023-12-07T17:23:03.393+0000] {taskinstance.py:1159} INFO - Dependencies all met for dep_context=requeueable deps ti=<TaskInstance: my_scraping_dag.main_task scheduled__2023-05-08T00:00:00+00:00 [queued]>
[2023-12-07T17:23:03.393+0000] {taskinstance.py:1361} INFO - Starting attempt 1 of 1
[2023-12-07T17:23:03.403+0000] {taskinstance.py:1382} INFO - Executing <Task(PythonOperator): main_task> on 2023-05-08 00:00:00+00:00
[2023-12-07T17:23:03.405+0000] {standard_task_runner.py:57} INFO - Started process 9606 to run task
[2023-12-07T17:23:03.409+0000] {standard_task_runner.py:84} INFO - Running: ['***', 'tasks', 'run', 'my_scraping_dag', 'main_task', 'scheduled__2023-05-08T00:00:00+00:00', '--job-id', '2999', '--raw', '--subdir', 'DAGS_FOLDER/main.py', '--cfg-path', '/tmp/tmpm45op29o']
[2023-12-07T17:23:03.413+0000] {standard_task_runner.py:85} INFO - Job 2999: Subtask main_task
[2023-12-07T17:23:03.451+0000] {task_command.py:416} INFO - Running <TaskInstance: my_scraping_dag.main_task scheduled__2023-05-08T00:00:00+00:00 [running]> on host 63b0c7e341c0
[2023-12-07T17:23:03.521+0000] {taskinstance.py:1662} INFO - Exporting env vars: AIRFLOW_CTX_DAG_OWNER='***' AIRFLOW_CTX_DAG_ID='my_scraping_dag' AIRFLOW_CTX_TASK_ID='main_task' AIRFLOW_CTX_EXECUTION_DATE='2023-05-08T00:00:00+00:00' AIRFLOW_CTX_TRY_NUMBER='1' AIRFLOW_CTX_DAG_RUN_ID='scheduled__2023-05-08T00:00:00+00:00'
[2023-12-07T17:23:04.312+0000] {taskinstance.py:1937} ERROR - Task failed with exception
Traceback (most recent call last):
  File "/home/airflow/.local/lib/python3.8/site-packages/airflow/operators/python.py", line 192, in execute
    return_value = self.execute_callable()
  File "/home/airflow/.local/lib/python3.8/site-packages/airflow/operators/python.py", line 209, in execute_callable
    return self.python_callable(*self.op_args, **self.op_kwargs)
  File "/opt/airflow/dags/main.py", line 73, in main
    insert_data_to_db(products, db_params)
  File "/opt/airflow/dags/main.py", line 40, in insert_data_to_db
    with psycopg2.connect(**db_params) as conn:
  File "/home/airflow/.local/lib/python3.8/site-packages/psycopg2/__init__.py", line 122, in connect
    conn = _connect(dsn, connection_factory=connection_factory, **kwasync)
psycopg2.OperationalError: connection to server at "localhost" (127.0.0.1), port 5432 failed: Connection refused
	Is the server running on that host and accepting TCP/IP connections?
connection to server at "localhost" (::1), port 5432 failed: Cannot assign requested address
	Is the server running on that host and accepting TCP/IP connections?

[2023-12-07T17:23:04.337+0000] {taskinstance.py:1400} INFO - Marking task as FAILED. dag_id=my_scraping_dag, task_id=main_task, execution_date=20230508T000000, start_date=20231207T172303, end_date=20231207T172304
[2023-12-07T17:23:04.352+0000] {standard_task_runner.py:104} ERROR - Failed to execute job 2999 for task main_task (connection to server at "localhost" (127.0.0.1), port 5432 failed: Connection refused
	Is the server running on that host and accepting TCP/IP connections?
connection to server at "localhost" (::1), port 5432 failed: Cannot assign requested address
	Is the server running on that host and accepting TCP/IP connections?
; 9606)
[2023-12-07T17:23:04.389+0000] {local_task_job_runner.py:228} INFO - Task exited with return code 1
[2023-12-07T17:23:04.407+0000] {taskinstance.py:2778} INFO - 0 downstream tasks scheduled from follow-on schedule check
[2023-12-07T17:28:45.778+0000] {taskinstance.py:1159} INFO - Dependencies all met for dep_context=non-requeueable deps ti=<TaskInstance: my_scraping_dag.main_task scheduled__2023-05-08T00:00:00+00:00 [queued]>
[2023-12-07T17:28:45.783+0000] {taskinstance.py:1159} INFO - Dependencies all met for dep_context=requeueable deps ti=<TaskInstance: my_scraping_dag.main_task scheduled__2023-05-08T00:00:00+00:00 [queued]>
[2023-12-07T17:28:45.783+0000] {taskinstance.py:1361} INFO - Starting attempt 1 of 1
[2023-12-07T17:28:45.789+0000] {taskinstance.py:1382} INFO - Executing <Task(PythonOperator): main_task> on 2023-05-08 00:00:00+00:00
[2023-12-07T17:28:45.792+0000] {standard_task_runner.py:57} INFO - Started process 10441 to run task
[2023-12-07T17:28:45.793+0000] {standard_task_runner.py:84} INFO - Running: ['***', 'tasks', 'run', 'my_scraping_dag', 'main_task', 'scheduled__2023-05-08T00:00:00+00:00', '--job-id', '3341', '--raw', '--subdir', 'DAGS_FOLDER/main.py', '--cfg-path', '/tmp/tmphlnqy3dn']
[2023-12-07T17:28:45.795+0000] {standard_task_runner.py:85} INFO - Job 3341: Subtask main_task
[2023-12-07T17:28:45.819+0000] {task_command.py:416} INFO - Running <TaskInstance: my_scraping_dag.main_task scheduled__2023-05-08T00:00:00+00:00 [running]> on host 63b0c7e341c0
[2023-12-07T17:28:45.857+0000] {taskinstance.py:1662} INFO - Exporting env vars: AIRFLOW_CTX_DAG_OWNER='***' AIRFLOW_CTX_DAG_ID='my_scraping_dag' AIRFLOW_CTX_TASK_ID='main_task' AIRFLOW_CTX_EXECUTION_DATE='2023-05-08T00:00:00+00:00' AIRFLOW_CTX_TRY_NUMBER='1' AIRFLOW_CTX_DAG_RUN_ID='scheduled__2023-05-08T00:00:00+00:00'
[2023-12-07T17:28:46.533+0000] {taskinstance.py:1937} ERROR - Task failed with exception
Traceback (most recent call last):
  File "/home/airflow/.local/lib/python3.8/site-packages/airflow/operators/python.py", line 192, in execute
    return_value = self.execute_callable()
  File "/home/airflow/.local/lib/python3.8/site-packages/airflow/operators/python.py", line 209, in execute_callable
    return self.python_callable(*self.op_args, **self.op_kwargs)
  File "/opt/airflow/dags/main.py", line 73, in main
    insert_data_to_db(products, db_params)
  File "/opt/airflow/dags/main.py", line 40, in insert_data_to_db
    with psycopg2.connect(**db_params) as conn:
  File "/home/airflow/.local/lib/python3.8/site-packages/psycopg2/__init__.py", line 122, in connect
    conn = _connect(dsn, connection_factory=connection_factory, **kwasync)
psycopg2.OperationalError: connection to server at "localhost" (127.0.0.1), port 5432 failed: Connection refused
	Is the server running on that host and accepting TCP/IP connections?
connection to server at "localhost" (::1), port 5432 failed: Cannot assign requested address
	Is the server running on that host and accepting TCP/IP connections?

[2023-12-07T17:28:46.544+0000] {taskinstance.py:1400} INFO - Marking task as FAILED. dag_id=my_scraping_dag, task_id=main_task, execution_date=20230508T000000, start_date=20231207T172845, end_date=20231207T172846
[2023-12-07T17:28:46.559+0000] {standard_task_runner.py:104} ERROR - Failed to execute job 3341 for task main_task (connection to server at "localhost" (127.0.0.1), port 5432 failed: Connection refused
	Is the server running on that host and accepting TCP/IP connections?
connection to server at "localhost" (::1), port 5432 failed: Cannot assign requested address
	Is the server running on that host and accepting TCP/IP connections?
; 10441)
[2023-12-07T17:28:46.608+0000] {local_task_job_runner.py:228} INFO - Task exited with return code 1
[2023-12-07T17:28:46.629+0000] {taskinstance.py:2778} INFO - 0 downstream tasks scheduled from follow-on schedule check
[2023-12-09T07:34:43.572+0000] {taskinstance.py:1159} INFO - Dependencies all met for dep_context=non-requeueable deps ti=<TaskInstance: my_scraping_dag.main_task scheduled__2023-05-08T00:00:00+00:00 [queued]>
[2023-12-09T07:34:43.576+0000] {taskinstance.py:1159} INFO - Dependencies all met for dep_context=requeueable deps ti=<TaskInstance: my_scraping_dag.main_task scheduled__2023-05-08T00:00:00+00:00 [queued]>
[2023-12-09T07:34:43.576+0000] {taskinstance.py:1361} INFO - Starting attempt 1 of 1
[2023-12-09T07:34:43.584+0000] {taskinstance.py:1382} INFO - Executing <Task(PythonOperator): main_task> on 2023-05-08 00:00:00+00:00
[2023-12-09T07:34:43.586+0000] {standard_task_runner.py:57} INFO - Started process 854 to run task
[2023-12-09T07:34:43.588+0000] {standard_task_runner.py:84} INFO - Running: ['***', 'tasks', 'run', 'my_scraping_dag', 'main_task', 'scheduled__2023-05-08T00:00:00+00:00', '--job-id', '131', '--raw', '--subdir', 'DAGS_FOLDER/main.py', '--cfg-path', '/tmp/tmpyfwedokj']
[2023-12-09T07:34:43.590+0000] {standard_task_runner.py:85} INFO - Job 131: Subtask main_task
[2023-12-09T07:34:43.614+0000] {task_command.py:416} INFO - Running <TaskInstance: my_scraping_dag.main_task scheduled__2023-05-08T00:00:00+00:00 [running]> on host 36b5ef2505c9
[2023-12-09T07:34:43.652+0000] {taskinstance.py:1662} INFO - Exporting env vars: AIRFLOW_CTX_DAG_OWNER='***' AIRFLOW_CTX_DAG_ID='my_scraping_dag' AIRFLOW_CTX_TASK_ID='main_task' AIRFLOW_CTX_EXECUTION_DATE='2023-05-08T00:00:00+00:00' AIRFLOW_CTX_TRY_NUMBER='1' AIRFLOW_CTX_DAG_RUN_ID='scheduled__2023-05-08T00:00:00+00:00'
[2023-12-09T07:34:43.659+0000] {taskinstance.py:1937} ERROR - Task failed with exception
Traceback (most recent call last):
  File "/home/airflow/.local/lib/python3.8/site-packages/airflow/operators/python.py", line 192, in execute
    return_value = self.execute_callable()
  File "/home/airflow/.local/lib/python3.8/site-packages/airflow/operators/python.py", line 209, in execute_callable
    return self.python_callable(*self.op_args, **self.op_kwargs)
  File "/opt/airflow/dags/main.py", line 64, in main
    base_url = Variable.get('base_url')
  File "/home/airflow/.local/lib/python3.8/site-packages/airflow/models/variable.py", line 140, in get
    raise KeyError(f"Variable {key} does not exist")
KeyError: 'Variable base_url does not exist'
[2023-12-09T07:34:43.664+0000] {taskinstance.py:1400} INFO - Marking task as FAILED. dag_id=my_scraping_dag, task_id=main_task, execution_date=20230508T000000, start_date=20231209T073443, end_date=20231209T073443
[2023-12-09T07:34:43.671+0000] {standard_task_runner.py:104} ERROR - Failed to execute job 131 for task main_task ('Variable base_url does not exist'; 854)
[2023-12-09T07:34:43.680+0000] {local_task_job_runner.py:228} INFO - Task exited with return code 1
[2023-12-09T07:34:43.691+0000] {taskinstance.py:2778} INFO - 0 downstream tasks scheduled from follow-on schedule check
