[2023-12-07T14:45:51.208+0000] {taskinstance.py:1159} INFO - Dependencies all met for dep_context=non-requeueable deps ti=<TaskInstance: my_scraping_dag.main_task scheduled__2023-02-21T00:00:00+00:00 [queued]>
[2023-12-07T14:45:51.214+0000] {taskinstance.py:1159} INFO - Dependencies all met for dep_context=requeueable deps ti=<TaskInstance: my_scraping_dag.main_task scheduled__2023-02-21T00:00:00+00:00 [queued]>
[2023-12-07T14:45:51.215+0000] {taskinstance.py:1361} INFO - Starting attempt 1 of 1
[2023-12-07T14:45:51.221+0000] {taskinstance.py:1382} INFO - Executing <Task(PythonOperator): main_task> on 2023-02-21 00:00:00+00:00
[2023-12-07T14:45:51.224+0000] {standard_task_runner.py:57} INFO - Started process 493 to run task
[2023-12-07T14:45:51.226+0000] {standard_task_runner.py:84} INFO - Running: ['***', 'tasks', 'run', 'my_scraping_dag', 'main_task', 'scheduled__2023-02-21T00:00:00+00:00', '--job-id', '63', '--raw', '--subdir', 'DAGS_FOLDER/main.py', '--cfg-path', '/tmp/tmp8fpj4liw']
[2023-12-07T14:45:51.228+0000] {standard_task_runner.py:85} INFO - Job 63: Subtask main_task
[2023-12-07T14:45:51.254+0000] {task_command.py:416} INFO - Running <TaskInstance: my_scraping_dag.main_task scheduled__2023-02-21T00:00:00+00:00 [running]> on host 63b0c7e341c0
[2023-12-07T14:45:51.283+0000] {taskinstance.py:1662} INFO - Exporting env vars: AIRFLOW_CTX_DAG_OWNER='***' AIRFLOW_CTX_DAG_ID='my_scraping_dag' AIRFLOW_CTX_TASK_ID='main_task' AIRFLOW_CTX_EXECUTION_DATE='2023-02-21T00:00:00+00:00' AIRFLOW_CTX_TRY_NUMBER='1' AIRFLOW_CTX_DAG_RUN_ID='scheduled__2023-02-21T00:00:00+00:00'
[2023-12-07T14:45:51.284+0000] {taskinstance.py:1937} ERROR - Task failed with exception
Traceback (most recent call last):
  File "/usr/local/lib/python3.8/configparser.py", line 846, in items
    d.update(self._sections[section])
KeyError: 'web'

During handling of the above exception, another exception occurred:

Traceback (most recent call last):
  File "/home/airflow/.local/lib/python3.8/site-packages/airflow/operators/python.py", line 192, in execute
    return_value = self.execute_callable()
  File "/home/airflow/.local/lib/python3.8/site-packages/airflow/operators/python.py", line 209, in execute_callable
    return self.python_callable(*self.op_args, **self.op_kwargs)
  File "/opt/airflow/dags/main.py", line 61, in main
    config = get_config('web')
  File "/opt/airflow/dags/main.py", line 23, in get_config
    return {key: value for key, value in parser.items(section)}
  File "/usr/local/lib/python3.8/configparser.py", line 849, in items
    raise NoSectionError(section)
configparser.NoSectionError: No section: 'web'
[2023-12-07T14:45:51.288+0000] {taskinstance.py:1400} INFO - Marking task as FAILED. dag_id=my_scraping_dag, task_id=main_task, execution_date=20230221T000000, start_date=20231207T144551, end_date=20231207T144551
[2023-12-07T14:45:51.292+0000] {standard_task_runner.py:104} ERROR - Failed to execute job 63 for task main_task (No section: 'web'; 493)
[2023-12-07T14:45:51.320+0000] {local_task_job_runner.py:228} INFO - Task exited with return code 1
[2023-12-07T14:45:51.331+0000] {taskinstance.py:2778} INFO - 0 downstream tasks scheduled from follow-on schedule check
[2023-12-07T14:51:53.930+0000] {taskinstance.py:1159} INFO - Dependencies all met for dep_context=non-requeueable deps ti=<TaskInstance: my_scraping_dag.main_task scheduled__2023-02-21T00:00:00+00:00 [queued]>
[2023-12-07T14:51:53.935+0000] {taskinstance.py:1159} INFO - Dependencies all met for dep_context=requeueable deps ti=<TaskInstance: my_scraping_dag.main_task scheduled__2023-02-21T00:00:00+00:00 [queued]>
[2023-12-07T14:51:53.936+0000] {taskinstance.py:1361} INFO - Starting attempt 1 of 1
[2023-12-07T14:51:53.954+0000] {taskinstance.py:1382} INFO - Executing <Task(PythonOperator): main_task> on 2023-02-21 00:00:00+00:00
[2023-12-07T14:51:53.958+0000] {standard_task_runner.py:57} INFO - Started process 858 to run task
[2023-12-07T14:51:53.962+0000] {standard_task_runner.py:84} INFO - Running: ['***', 'tasks', 'run', 'my_scraping_dag', 'main_task', 'scheduled__2023-02-21T00:00:00+00:00', '--job-id', '162', '--raw', '--subdir', 'DAGS_FOLDER/main.py', '--cfg-path', '/tmp/tmpviuzo99x']
[2023-12-07T14:51:53.965+0000] {standard_task_runner.py:85} INFO - Job 162: Subtask main_task
[2023-12-07T14:51:54.003+0000] {task_command.py:416} INFO - Running <TaskInstance: my_scraping_dag.main_task scheduled__2023-02-21T00:00:00+00:00 [running]> on host 63b0c7e341c0
[2023-12-07T14:51:54.065+0000] {taskinstance.py:1662} INFO - Exporting env vars: AIRFLOW_CTX_DAG_OWNER='***' AIRFLOW_CTX_DAG_ID='my_scraping_dag' AIRFLOW_CTX_TASK_ID='main_task' AIRFLOW_CTX_EXECUTION_DATE='2023-02-21T00:00:00+00:00' AIRFLOW_CTX_TRY_NUMBER='1' AIRFLOW_CTX_DAG_RUN_ID='scheduled__2023-02-21T00:00:00+00:00'
[2023-12-07T14:51:54.067+0000] {taskinstance.py:1937} ERROR - Task failed with exception
Traceback (most recent call last):
  File "/usr/local/lib/python3.8/configparser.py", line 846, in items
    d.update(self._sections[section])
KeyError: 'web'

During handling of the above exception, another exception occurred:

Traceback (most recent call last):
  File "/home/airflow/.local/lib/python3.8/site-packages/airflow/operators/python.py", line 192, in execute
    return_value = self.execute_callable()
  File "/home/airflow/.local/lib/python3.8/site-packages/airflow/operators/python.py", line 209, in execute_callable
    return self.python_callable(*self.op_args, **self.op_kwargs)
  File "/opt/airflow/dags/main.py", line 61, in main
    config = get_config('web')
  File "/opt/airflow/dags/main.py", line 23, in get_config
    return {key: value for key, value in parser.items(section)}
  File "/usr/local/lib/python3.8/configparser.py", line 849, in items
    raise NoSectionError(section)
configparser.NoSectionError: No section: 'web'
[2023-12-07T14:51:54.075+0000] {taskinstance.py:1400} INFO - Marking task as FAILED. dag_id=my_scraping_dag, task_id=main_task, execution_date=20230221T000000, start_date=20231207T145153, end_date=20231207T145154
[2023-12-07T14:51:54.082+0000] {standard_task_runner.py:104} ERROR - Failed to execute job 162 for task main_task (No section: 'web'; 858)
[2023-12-07T14:51:54.095+0000] {local_task_job_runner.py:228} INFO - Task exited with return code 1
[2023-12-07T14:51:54.142+0000] {taskinstance.py:2778} INFO - 0 downstream tasks scheduled from follow-on schedule check
[2023-12-07T15:00:05.113+0000] {taskinstance.py:1159} INFO - Dependencies all met for dep_context=non-requeueable deps ti=<TaskInstance: my_scraping_dag.main_task scheduled__2023-02-21T00:00:00+00:00 [queued]>
[2023-12-07T15:00:05.117+0000] {taskinstance.py:1159} INFO - Dependencies all met for dep_context=requeueable deps ti=<TaskInstance: my_scraping_dag.main_task scheduled__2023-02-21T00:00:00+00:00 [queued]>
[2023-12-07T15:00:05.117+0000] {taskinstance.py:1361} INFO - Starting attempt 1 of 1
[2023-12-07T15:00:05.128+0000] {taskinstance.py:1382} INFO - Executing <Task(PythonOperator): main_task> on 2023-02-21 00:00:00+00:00
[2023-12-07T15:00:05.131+0000] {standard_task_runner.py:57} INFO - Started process 1478 to run task
[2023-12-07T15:00:05.133+0000] {standard_task_runner.py:84} INFO - Running: ['***', 'tasks', 'run', 'my_scraping_dag', 'main_task', 'scheduled__2023-02-21T00:00:00+00:00', '--job-id', '366', '--raw', '--subdir', 'DAGS_FOLDER/main.py', '--cfg-path', '/tmp/tmpyt6pxq12']
[2023-12-07T15:00:05.135+0000] {standard_task_runner.py:85} INFO - Job 366: Subtask main_task
[2023-12-07T15:00:05.160+0000] {task_command.py:416} INFO - Running <TaskInstance: my_scraping_dag.main_task scheduled__2023-02-21T00:00:00+00:00 [running]> on host 63b0c7e341c0
[2023-12-07T15:00:05.198+0000] {taskinstance.py:1662} INFO - Exporting env vars: AIRFLOW_CTX_DAG_OWNER='***' AIRFLOW_CTX_DAG_ID='my_scraping_dag' AIRFLOW_CTX_TASK_ID='main_task' AIRFLOW_CTX_EXECUTION_DATE='2023-02-21T00:00:00+00:00' AIRFLOW_CTX_TRY_NUMBER='1' AIRFLOW_CTX_DAG_RUN_ID='scheduled__2023-02-21T00:00:00+00:00'
[2023-12-07T15:00:05.199+0000] {taskinstance.py:1937} ERROR - Task failed with exception
Traceback (most recent call last):
  File "/usr/local/lib/python3.8/configparser.py", line 846, in items
    d.update(self._sections[section])
KeyError: 'web'

During handling of the above exception, another exception occurred:

Traceback (most recent call last):
  File "/home/airflow/.local/lib/python3.8/site-packages/airflow/operators/python.py", line 192, in execute
    return_value = self.execute_callable()
  File "/home/airflow/.local/lib/python3.8/site-packages/airflow/operators/python.py", line 209, in execute_callable
    return self.python_callable(*self.op_args, **self.op_kwargs)
  File "/opt/airflow/dags/main.py", line 60, in main
    config = get_config('web')
  File "/opt/airflow/dags/main.py", line 22, in get_config
    return {key: value for key, value in parser.items(section)}
  File "/usr/local/lib/python3.8/configparser.py", line 849, in items
    raise NoSectionError(section)
configparser.NoSectionError: No section: 'web'
[2023-12-07T15:00:05.205+0000] {taskinstance.py:1400} INFO - Marking task as FAILED. dag_id=my_scraping_dag, task_id=main_task, execution_date=20230221T000000, start_date=20231207T150005, end_date=20231207T150005
[2023-12-07T15:00:05.213+0000] {standard_task_runner.py:104} ERROR - Failed to execute job 366 for task main_task (No section: 'web'; 1478)
[2023-12-07T15:00:05.225+0000] {local_task_job_runner.py:228} INFO - Task exited with return code 1
[2023-12-07T15:00:05.261+0000] {taskinstance.py:2778} INFO - 0 downstream tasks scheduled from follow-on schedule check
[2023-12-07T15:10:53.480+0000] {taskinstance.py:1159} INFO - Dependencies all met for dep_context=non-requeueable deps ti=<TaskInstance: my_scraping_dag.main_task scheduled__2023-02-21T00:00:00+00:00 [queued]>
[2023-12-07T15:10:53.485+0000] {taskinstance.py:1159} INFO - Dependencies all met for dep_context=requeueable deps ti=<TaskInstance: my_scraping_dag.main_task scheduled__2023-02-21T00:00:00+00:00 [queued]>
[2023-12-07T15:10:53.485+0000] {taskinstance.py:1361} INFO - Starting attempt 1 of 1
[2023-12-07T15:10:53.492+0000] {taskinstance.py:1382} INFO - Executing <Task(PythonOperator): main_task> on 2023-02-21 00:00:00+00:00
[2023-12-07T15:10:53.495+0000] {standard_task_runner.py:57} INFO - Started process 1949 to run task
[2023-12-07T15:10:53.497+0000] {standard_task_runner.py:84} INFO - Running: ['***', 'tasks', 'run', 'my_scraping_dag', 'main_task', 'scheduled__2023-02-21T00:00:00+00:00', '--job-id', '473', '--raw', '--subdir', 'DAGS_FOLDER/main.py', '--cfg-path', '/tmp/tmpto45cz06']
[2023-12-07T15:10:53.499+0000] {standard_task_runner.py:85} INFO - Job 473: Subtask main_task
[2023-12-07T15:10:53.526+0000] {task_command.py:416} INFO - Running <TaskInstance: my_scraping_dag.main_task scheduled__2023-02-21T00:00:00+00:00 [running]> on host 63b0c7e341c0
[2023-12-07T15:10:53.560+0000] {taskinstance.py:1662} INFO - Exporting env vars: AIRFLOW_CTX_DAG_OWNER='***' AIRFLOW_CTX_DAG_ID='my_scraping_dag' AIRFLOW_CTX_TASK_ID='main_task' AIRFLOW_CTX_EXECUTION_DATE='2023-02-21T00:00:00+00:00' AIRFLOW_CTX_TRY_NUMBER='1' AIRFLOW_CTX_DAG_RUN_ID='scheduled__2023-02-21T00:00:00+00:00'
[2023-12-07T15:10:53.561+0000] {taskinstance.py:1937} ERROR - Task failed with exception
Traceback (most recent call last):
  File "/usr/local/lib/python3.8/configparser.py", line 846, in items
    d.update(self._sections[section])
KeyError: 'web'

During handling of the above exception, another exception occurred:

Traceback (most recent call last):
  File "/home/airflow/.local/lib/python3.8/site-packages/airflow/operators/python.py", line 192, in execute
    return_value = self.execute_callable()
  File "/home/airflow/.local/lib/python3.8/site-packages/airflow/operators/python.py", line 209, in execute_callable
    return self.python_callable(*self.op_args, **self.op_kwargs)
  File "/opt/airflow/dags/main.py", line 63, in main
    config = get_config('web')
  File "/opt/airflow/dags/main.py", line 14, in get_config
    return {key: value for key, value in parser.items(section)}
  File "/usr/local/lib/python3.8/configparser.py", line 849, in items
    raise NoSectionError(section)
configparser.NoSectionError: No section: 'web'
[2023-12-07T15:10:53.568+0000] {taskinstance.py:1400} INFO - Marking task as FAILED. dag_id=my_scraping_dag, task_id=main_task, execution_date=20230221T000000, start_date=20231207T151053, end_date=20231207T151053
[2023-12-07T15:10:53.574+0000] {standard_task_runner.py:104} ERROR - Failed to execute job 473 for task main_task (No section: 'web'; 1949)
[2023-12-07T15:10:53.589+0000] {local_task_job_runner.py:228} INFO - Task exited with return code 1
[2023-12-07T15:10:53.617+0000] {taskinstance.py:2778} INFO - 0 downstream tasks scheduled from follow-on schedule check
[2023-12-07T15:12:16.741+0000] {taskinstance.py:1159} INFO - Dependencies all met for dep_context=non-requeueable deps ti=<TaskInstance: my_scraping_dag.main_task scheduled__2023-02-21T00:00:00+00:00 [queued]>
[2023-12-07T15:12:16.746+0000] {taskinstance.py:1159} INFO - Dependencies all met for dep_context=requeueable deps ti=<TaskInstance: my_scraping_dag.main_task scheduled__2023-02-21T00:00:00+00:00 [queued]>
[2023-12-07T15:12:16.746+0000] {taskinstance.py:1361} INFO - Starting attempt 1 of 1
[2023-12-07T15:12:16.760+0000] {taskinstance.py:1382} INFO - Executing <Task(PythonOperator): main_task> on 2023-02-21 00:00:00+00:00
[2023-12-07T15:12:16.763+0000] {standard_task_runner.py:57} INFO - Started process 2172 to run task
[2023-12-07T15:12:16.765+0000] {standard_task_runner.py:84} INFO - Running: ['***', 'tasks', 'run', 'my_scraping_dag', 'main_task', 'scheduled__2023-02-21T00:00:00+00:00', '--job-id', '562', '--raw', '--subdir', 'DAGS_FOLDER/main.py', '--cfg-path', '/tmp/tmpryioqrd8']
[2023-12-07T15:12:16.767+0000] {standard_task_runner.py:85} INFO - Job 562: Subtask main_task
[2023-12-07T15:12:16.789+0000] {task_command.py:416} INFO - Running <TaskInstance: my_scraping_dag.main_task scheduled__2023-02-21T00:00:00+00:00 [running]> on host 63b0c7e341c0
[2023-12-07T15:12:16.822+0000] {taskinstance.py:1662} INFO - Exporting env vars: AIRFLOW_CTX_DAG_OWNER='***' AIRFLOW_CTX_DAG_ID='my_scraping_dag' AIRFLOW_CTX_TASK_ID='main_task' AIRFLOW_CTX_EXECUTION_DATE='2023-02-21T00:00:00+00:00' AIRFLOW_CTX_TRY_NUMBER='1' AIRFLOW_CTX_DAG_RUN_ID='scheduled__2023-02-21T00:00:00+00:00'
[2023-12-07T15:12:16.823+0000] {taskinstance.py:1937} ERROR - Task failed with exception
Traceback (most recent call last):
  File "/usr/local/lib/python3.8/configparser.py", line 846, in items
    d.update(self._sections[section])
KeyError: 'web'

During handling of the above exception, another exception occurred:

Traceback (most recent call last):
  File "/home/airflow/.local/lib/python3.8/site-packages/airflow/operators/python.py", line 192, in execute
    return_value = self.execute_callable()
  File "/home/airflow/.local/lib/python3.8/site-packages/airflow/operators/python.py", line 209, in execute_callable
    return self.python_callable(*self.op_args, **self.op_kwargs)
  File "/opt/airflow/dags/main.py", line 63, in main
    config = get_config('web')
  File "/opt/airflow/dags/main.py", line 14, in get_config
    return {key: value for key, value in parser.items(section)}
  File "/usr/local/lib/python3.8/configparser.py", line 849, in items
    raise NoSectionError(section)
configparser.NoSectionError: No section: 'web'
[2023-12-07T15:12:16.827+0000] {taskinstance.py:1400} INFO - Marking task as FAILED. dag_id=my_scraping_dag, task_id=main_task, execution_date=20230221T000000, start_date=20231207T151216, end_date=20231207T151216
[2023-12-07T15:12:16.832+0000] {standard_task_runner.py:104} ERROR - Failed to execute job 562 for task main_task (No section: 'web'; 2172)
[2023-12-07T15:12:16.857+0000] {local_task_job_runner.py:228} INFO - Task exited with return code 1
[2023-12-07T15:12:16.865+0000] {taskinstance.py:2778} INFO - 0 downstream tasks scheduled from follow-on schedule check
[2023-12-07T16:31:23.030+0000] {taskinstance.py:1159} INFO - Dependencies all met for dep_context=non-requeueable deps ti=<TaskInstance: my_scraping_dag.main_task scheduled__2023-02-21T00:00:00+00:00 [queued]>
[2023-12-07T16:31:23.034+0000] {taskinstance.py:1159} INFO - Dependencies all met for dep_context=requeueable deps ti=<TaskInstance: my_scraping_dag.main_task scheduled__2023-02-21T00:00:00+00:00 [queued]>
[2023-12-07T16:31:23.034+0000] {taskinstance.py:1361} INFO - Starting attempt 1 of 1
[2023-12-07T16:31:23.039+0000] {taskinstance.py:1382} INFO - Executing <Task(PythonOperator): main_task> on 2023-02-21 00:00:00+00:00
[2023-12-07T16:31:23.042+0000] {standard_task_runner.py:57} INFO - Started process 3613 to run task
[2023-12-07T16:31:23.044+0000] {standard_task_runner.py:84} INFO - Running: ['***', 'tasks', 'run', 'my_scraping_dag', 'main_task', 'scheduled__2023-02-21T00:00:00+00:00', '--job-id', '640', '--raw', '--subdir', 'DAGS_FOLDER/main.py', '--cfg-path', '/tmp/tmpb5ddr33r']
[2023-12-07T16:31:23.045+0000] {standard_task_runner.py:85} INFO - Job 640: Subtask main_task
[2023-12-07T16:31:23.066+0000] {task_command.py:416} INFO - Running <TaskInstance: my_scraping_dag.main_task scheduled__2023-02-21T00:00:00+00:00 [running]> on host 63b0c7e341c0
[2023-12-07T16:31:23.095+0000] {taskinstance.py:1662} INFO - Exporting env vars: AIRFLOW_CTX_DAG_OWNER='***' AIRFLOW_CTX_DAG_ID='my_scraping_dag' AIRFLOW_CTX_TASK_ID='main_task' AIRFLOW_CTX_EXECUTION_DATE='2023-02-21T00:00:00+00:00' AIRFLOW_CTX_TRY_NUMBER='1' AIRFLOW_CTX_DAG_RUN_ID='scheduled__2023-02-21T00:00:00+00:00'
[2023-12-07T16:31:23.096+0000] {taskinstance.py:1937} ERROR - Task failed with exception
Traceback (most recent call last):
  File "/usr/local/lib/python3.8/configparser.py", line 846, in items
    d.update(self._sections[section])
KeyError: 'web'

During handling of the above exception, another exception occurred:

Traceback (most recent call last):
  File "/home/airflow/.local/lib/python3.8/site-packages/airflow/operators/python.py", line 192, in execute
    return_value = self.execute_callable()
  File "/home/airflow/.local/lib/python3.8/site-packages/airflow/operators/python.py", line 209, in execute_callable
    return self.python_callable(*self.op_args, **self.op_kwargs)
  File "/opt/airflow/dags/main.py", line 60, in main
    config = get_config('web')
  File "/opt/airflow/dags/main.py", line 22, in get_config
    return {key: value for key, value in parser.items(section)}
  File "/usr/local/lib/python3.8/configparser.py", line 849, in items
    raise NoSectionError(section)
configparser.NoSectionError: No section: 'web'
[2023-12-07T16:31:23.100+0000] {taskinstance.py:1400} INFO - Marking task as FAILED. dag_id=my_scraping_dag, task_id=main_task, execution_date=20230221T000000, start_date=20231207T163123, end_date=20231207T163123
[2023-12-07T16:31:23.104+0000] {standard_task_runner.py:104} ERROR - Failed to execute job 640 for task main_task (No section: 'web'; 3613)
[2023-12-07T16:31:23.137+0000] {local_task_job_runner.py:228} INFO - Task exited with return code 1
[2023-12-07T16:31:23.149+0000] {taskinstance.py:2778} INFO - 0 downstream tasks scheduled from follow-on schedule check
[2023-12-07T16:41:04.076+0000] {taskinstance.py:1159} INFO - Dependencies all met for dep_context=non-requeueable deps ti=<TaskInstance: my_scraping_dag.main_task scheduled__2023-02-21T00:00:00+00:00 [queued]>
[2023-12-07T16:41:04.081+0000] {taskinstance.py:1159} INFO - Dependencies all met for dep_context=requeueable deps ti=<TaskInstance: my_scraping_dag.main_task scheduled__2023-02-21T00:00:00+00:00 [queued]>
[2023-12-07T16:41:04.081+0000] {taskinstance.py:1361} INFO - Starting attempt 1 of 1
[2023-12-07T16:41:04.105+0000] {taskinstance.py:1382} INFO - Executing <Task(PythonOperator): main_task> on 2023-02-21 00:00:00+00:00
[2023-12-07T16:41:04.107+0000] {standard_task_runner.py:57} INFO - Started process 4531 to run task
[2023-12-07T16:41:04.109+0000] {standard_task_runner.py:84} INFO - Running: ['***', 'tasks', 'run', 'my_scraping_dag', 'main_task', 'scheduled__2023-02-21T00:00:00+00:00', '--job-id', '982', '--raw', '--subdir', 'DAGS_FOLDER/main.py', '--cfg-path', '/tmp/tmp6onvsb05']
[2023-12-07T16:41:04.111+0000] {standard_task_runner.py:85} INFO - Job 982: Subtask main_task
[2023-12-07T16:41:04.141+0000] {task_command.py:416} INFO - Running <TaskInstance: my_scraping_dag.main_task scheduled__2023-02-21T00:00:00+00:00 [running]> on host 63b0c7e341c0
[2023-12-07T16:41:04.175+0000] {taskinstance.py:1662} INFO - Exporting env vars: AIRFLOW_CTX_DAG_OWNER='***' AIRFLOW_CTX_DAG_ID='my_scraping_dag' AIRFLOW_CTX_TASK_ID='main_task' AIRFLOW_CTX_EXECUTION_DATE='2023-02-21T00:00:00+00:00' AIRFLOW_CTX_TRY_NUMBER='1' AIRFLOW_CTX_DAG_RUN_ID='scheduled__2023-02-21T00:00:00+00:00'
[2023-12-07T16:41:04.176+0000] {taskinstance.py:1937} ERROR - Task failed with exception
Traceback (most recent call last):
  File "/usr/local/lib/python3.8/configparser.py", line 846, in items
    d.update(self._sections[section])
KeyError: 'web'

During handling of the above exception, another exception occurred:

Traceback (most recent call last):
  File "/home/airflow/.local/lib/python3.8/site-packages/airflow/operators/python.py", line 192, in execute
    return_value = self.execute_callable()
  File "/home/airflow/.local/lib/python3.8/site-packages/airflow/operators/python.py", line 209, in execute_callable
    return self.python_callable(*self.op_args, **self.op_kwargs)
  File "/opt/airflow/dags/main.py", line 60, in main
    config = get_config('web')
  File "/opt/airflow/dags/main.py", line 22, in get_config
    return {key: value for key, value in parser.items(section)}
  File "/usr/local/lib/python3.8/configparser.py", line 849, in items
    raise NoSectionError(section)
configparser.NoSectionError: No section: 'web'
[2023-12-07T16:41:04.182+0000] {taskinstance.py:1400} INFO - Marking task as FAILED. dag_id=my_scraping_dag, task_id=main_task, execution_date=20230221T000000, start_date=20231207T164104, end_date=20231207T164104
[2023-12-07T16:41:04.188+0000] {standard_task_runner.py:104} ERROR - Failed to execute job 982 for task main_task (No section: 'web'; 4531)
[2023-12-07T16:41:04.202+0000] {local_task_job_runner.py:228} INFO - Task exited with return code 1
[2023-12-07T16:41:04.248+0000] {taskinstance.py:2778} INFO - 0 downstream tasks scheduled from follow-on schedule check
[2023-12-07T17:00:09.795+0000] {taskinstance.py:1159} INFO - Dependencies all met for dep_context=non-requeueable deps ti=<TaskInstance: my_scraping_dag.main_task scheduled__2023-02-21T00:00:00+00:00 [queued]>
[2023-12-07T17:00:09.800+0000] {taskinstance.py:1159} INFO - Dependencies all met for dep_context=requeueable deps ti=<TaskInstance: my_scraping_dag.main_task scheduled__2023-02-21T00:00:00+00:00 [queued]>
[2023-12-07T17:00:09.800+0000] {taskinstance.py:1361} INFO - Starting attempt 1 of 1
[2023-12-07T17:00:09.826+0000] {taskinstance.py:1382} INFO - Executing <Task(PythonOperator): main_task> on 2023-02-21 00:00:00+00:00
[2023-12-07T17:00:09.828+0000] {standard_task_runner.py:57} INFO - Started process 5694 to run task
[2023-12-07T17:00:09.831+0000] {standard_task_runner.py:84} INFO - Running: ['***', 'tasks', 'run', 'my_scraping_dag', 'main_task', 'scheduled__2023-02-21T00:00:00+00:00', '--job-id', '1326', '--raw', '--subdir', 'DAGS_FOLDER/main.py', '--cfg-path', '/tmp/tmpt07bsnyy']
[2023-12-07T17:00:09.833+0000] {standard_task_runner.py:85} INFO - Job 1326: Subtask main_task
[2023-12-07T17:00:09.858+0000] {task_command.py:416} INFO - Running <TaskInstance: my_scraping_dag.main_task scheduled__2023-02-21T00:00:00+00:00 [running]> on host 63b0c7e341c0
[2023-12-07T17:00:09.900+0000] {taskinstance.py:1662} INFO - Exporting env vars: AIRFLOW_CTX_DAG_OWNER='***' AIRFLOW_CTX_DAG_ID='my_scraping_dag' AIRFLOW_CTX_TASK_ID='main_task' AIRFLOW_CTX_EXECUTION_DATE='2023-02-21T00:00:00+00:00' AIRFLOW_CTX_TRY_NUMBER='1' AIRFLOW_CTX_DAG_RUN_ID='scheduled__2023-02-21T00:00:00+00:00'
[2023-12-07T17:00:09.932+0000] {taskinstance.py:1937} ERROR - Task failed with exception
Traceback (most recent call last):
  File "/home/airflow/.local/lib/python3.8/site-packages/airflow/operators/python.py", line 192, in execute
    return_value = self.execute_callable()
  File "/home/airflow/.local/lib/python3.8/site-packages/airflow/operators/python.py", line 209, in execute_callable
    return self.python_callable(*self.op_args, **self.op_kwargs)
  File "/opt/airflow/dags/main.py", line 33, in main
    'host': get_config('localhost'),
  File "/opt/airflow/dags/main.py", line 20, in get_config
    return Variable.get(key)
  File "/home/airflow/.local/lib/python3.8/site-packages/airflow/models/variable.py", line 140, in get
    raise KeyError(f"Variable {key} does not exist")
KeyError: 'Variable localhost does not exist'
[2023-12-07T17:00:09.937+0000] {taskinstance.py:1400} INFO - Marking task as FAILED. dag_id=my_scraping_dag, task_id=main_task, execution_date=20230221T000000, start_date=20231207T170009, end_date=20231207T170009
[2023-12-07T17:00:09.954+0000] {standard_task_runner.py:104} ERROR - Failed to execute job 1326 for task main_task ('Variable localhost does not exist'; 5694)
[2023-12-07T17:00:09.965+0000] {local_task_job_runner.py:228} INFO - Task exited with return code 1
[2023-12-07T17:00:09.978+0000] {taskinstance.py:2778} INFO - 0 downstream tasks scheduled from follow-on schedule check
[2023-12-07T17:03:31.339+0000] {taskinstance.py:1159} INFO - Dependencies all met for dep_context=non-requeueable deps ti=<TaskInstance: my_scraping_dag.main_task scheduled__2023-02-21T00:00:00+00:00 [queued]>
[2023-12-07T17:03:31.356+0000] {taskinstance.py:1159} INFO - Dependencies all met for dep_context=requeueable deps ti=<TaskInstance: my_scraping_dag.main_task scheduled__2023-02-21T00:00:00+00:00 [queued]>
[2023-12-07T17:03:31.357+0000] {taskinstance.py:1361} INFO - Starting attempt 1 of 1
[2023-12-07T17:03:31.387+0000] {taskinstance.py:1382} INFO - Executing <Task(PythonOperator): main_task> on 2023-02-21 00:00:00+00:00
[2023-12-07T17:03:31.400+0000] {standard_task_runner.py:57} INFO - Started process 7002 to run task
[2023-12-07T17:03:31.411+0000] {standard_task_runner.py:84} INFO - Running: ['***', 'tasks', 'run', 'my_scraping_dag', 'main_task', 'scheduled__2023-02-21T00:00:00+00:00', '--job-id', '1942', '--raw', '--subdir', 'DAGS_FOLDER/main.py', '--cfg-path', '/tmp/tmpmv9n80ax']
[2023-12-07T17:03:31.413+0000] {standard_task_runner.py:85} INFO - Job 1942: Subtask main_task
[2023-12-07T17:03:31.475+0000] {task_command.py:416} INFO - Running <TaskInstance: my_scraping_dag.main_task scheduled__2023-02-21T00:00:00+00:00 [running]> on host 63b0c7e341c0
[2023-12-07T17:03:31.563+0000] {taskinstance.py:1662} INFO - Exporting env vars: AIRFLOW_CTX_DAG_OWNER='***' AIRFLOW_CTX_DAG_ID='my_scraping_dag' AIRFLOW_CTX_TASK_ID='main_task' AIRFLOW_CTX_EXECUTION_DATE='2023-02-21T00:00:00+00:00' AIRFLOW_CTX_TRY_NUMBER='1' AIRFLOW_CTX_DAG_RUN_ID='scheduled__2023-02-21T00:00:00+00:00'
[2023-12-07T17:03:31.630+0000] {logging_mixin.py:154} INFO - base_url: https://tuncbotanik.com
[2023-12-07T17:03:31.630+0000] {python.py:194} INFO - Done. Returned value was: ('https://tuncbotanik.com', {'User-Agent': 'Mozilla/5.0 (Macintosh; Intel Mac OS X 10_15_7) AppleWebKit/537.36 (KHTML, like Gecko) Chrome/119.0.0.0 Safari/537.36', 'Accept-Language': 'tr-TR,tr;q=0.9,en-US;q=0.8,en;q=0.7'}, {'dbname': 'plant', 'user': 'aozgokme', 'password': '***', 'host': 'localhost', 'port': '5432'})
[2023-12-07T17:03:31.656+0000] {taskinstance.py:1400} INFO - Marking task as SUCCESS. dag_id=my_scraping_dag, task_id=main_task, execution_date=20230221T000000, start_date=20231207T170331, end_date=20231207T170331
[2023-12-07T17:03:31.750+0000] {local_task_job_runner.py:228} INFO - Task exited with return code 0
[2023-12-07T17:03:31.844+0000] {taskinstance.py:2778} INFO - 0 downstream tasks scheduled from follow-on schedule check
[2023-12-07T17:18:29.543+0000] {taskinstance.py:1159} INFO - Dependencies all met for dep_context=non-requeueable deps ti=<TaskInstance: my_scraping_dag.main_task scheduled__2023-02-21T00:00:00+00:00 [queued]>
[2023-12-07T17:18:29.549+0000] {taskinstance.py:1159} INFO - Dependencies all met for dep_context=requeueable deps ti=<TaskInstance: my_scraping_dag.main_task scheduled__2023-02-21T00:00:00+00:00 [queued]>
[2023-12-07T17:18:29.549+0000] {taskinstance.py:1361} INFO - Starting attempt 1 of 1
[2023-12-07T17:18:29.559+0000] {taskinstance.py:1382} INFO - Executing <Task(PythonOperator): main_task> on 2023-02-21 00:00:00+00:00
[2023-12-07T17:18:29.562+0000] {standard_task_runner.py:57} INFO - Started process 8647 to run task
[2023-12-07T17:18:29.565+0000] {standard_task_runner.py:84} INFO - Running: ['***', 'tasks', 'run', 'my_scraping_dag', 'main_task', 'scheduled__2023-02-21T00:00:00+00:00', '--job-id', '2581', '--raw', '--subdir', 'DAGS_FOLDER/main.py', '--cfg-path', '/tmp/tmp994iuf5j']
[2023-12-07T17:18:29.567+0000] {standard_task_runner.py:85} INFO - Job 2581: Subtask main_task
[2023-12-07T17:18:29.603+0000] {task_command.py:416} INFO - Running <TaskInstance: my_scraping_dag.main_task scheduled__2023-02-21T00:00:00+00:00 [running]> on host 63b0c7e341c0
[2023-12-07T17:18:29.654+0000] {taskinstance.py:1662} INFO - Exporting env vars: AIRFLOW_CTX_DAG_OWNER='***' AIRFLOW_CTX_DAG_ID='my_scraping_dag' AIRFLOW_CTX_TASK_ID='main_task' AIRFLOW_CTX_EXECUTION_DATE='2023-02-21T00:00:00+00:00' AIRFLOW_CTX_TRY_NUMBER='1' AIRFLOW_CTX_DAG_RUN_ID='scheduled__2023-02-21T00:00:00+00:00'
[2023-12-07T17:18:30.436+0000] {taskinstance.py:1937} ERROR - Task failed with exception
Traceback (most recent call last):
  File "/home/airflow/.local/lib/python3.8/site-packages/airflow/operators/python.py", line 192, in execute
    return_value = self.execute_callable()
  File "/home/airflow/.local/lib/python3.8/site-packages/airflow/operators/python.py", line 209, in execute_callable
    return self.python_callable(*self.op_args, **self.op_kwargs)
  File "/opt/airflow/dags/main.py", line 80, in main
    insert_data_to_db(products, db_params)
  File "/opt/airflow/dags/main.py", line 43, in insert_data_to_db
    with psycopg2.connect(**db_params) as conn:
  File "/home/airflow/.local/lib/python3.8/site-packages/psycopg2/__init__.py", line 122, in connect
    conn = _connect(dsn, connection_factory=connection_factory, **kwasync)
psycopg2.OperationalError: connection to server at "localhost" (127.0.0.1), port 5432 failed: Connection refused
	Is the server running on that host and accepting TCP/IP connections?
connection to server at "localhost" (::1), port 5432 failed: Cannot assign requested address
	Is the server running on that host and accepting TCP/IP connections?

[2023-12-07T17:18:30.457+0000] {taskinstance.py:1400} INFO - Marking task as FAILED. dag_id=my_scraping_dag, task_id=main_task, execution_date=20230221T000000, start_date=20231207T171829, end_date=20231207T171830
[2023-12-07T17:18:30.470+0000] {standard_task_runner.py:104} ERROR - Failed to execute job 2581 for task main_task (connection to server at "localhost" (127.0.0.1), port 5432 failed: Connection refused
	Is the server running on that host and accepting TCP/IP connections?
connection to server at "localhost" (::1), port 5432 failed: Cannot assign requested address
	Is the server running on that host and accepting TCP/IP connections?
; 8647)
[2023-12-07T17:18:30.506+0000] {local_task_job_runner.py:228} INFO - Task exited with return code 1
[2023-12-07T17:18:30.521+0000] {taskinstance.py:2778} INFO - 0 downstream tasks scheduled from follow-on schedule check
[2023-12-07T17:22:47.842+0000] {taskinstance.py:1159} INFO - Dependencies all met for dep_context=non-requeueable deps ti=<TaskInstance: my_scraping_dag.main_task scheduled__2023-02-21T00:00:00+00:00 [queued]>
[2023-12-07T17:22:47.846+0000] {taskinstance.py:1159} INFO - Dependencies all met for dep_context=requeueable deps ti=<TaskInstance: my_scraping_dag.main_task scheduled__2023-02-21T00:00:00+00:00 [queued]>
[2023-12-07T17:22:47.847+0000] {taskinstance.py:1361} INFO - Starting attempt 1 of 1
[2023-12-07T17:22:47.854+0000] {taskinstance.py:1382} INFO - Executing <Task(PythonOperator): main_task> on 2023-02-21 00:00:00+00:00
[2023-12-07T17:22:47.857+0000] {standard_task_runner.py:57} INFO - Started process 9441 to run task
[2023-12-07T17:22:47.860+0000] {standard_task_runner.py:84} INFO - Running: ['***', 'tasks', 'run', 'my_scraping_dag', 'main_task', 'scheduled__2023-02-21T00:00:00+00:00', '--job-id', '2923', '--raw', '--subdir', 'DAGS_FOLDER/main.py', '--cfg-path', '/tmp/tmphptr_qcp']
[2023-12-07T17:22:47.862+0000] {standard_task_runner.py:85} INFO - Job 2923: Subtask main_task
[2023-12-07T17:22:47.889+0000] {task_command.py:416} INFO - Running <TaskInstance: my_scraping_dag.main_task scheduled__2023-02-21T00:00:00+00:00 [running]> on host 63b0c7e341c0
[2023-12-07T17:22:47.933+0000] {taskinstance.py:1662} INFO - Exporting env vars: AIRFLOW_CTX_DAG_OWNER='***' AIRFLOW_CTX_DAG_ID='my_scraping_dag' AIRFLOW_CTX_TASK_ID='main_task' AIRFLOW_CTX_EXECUTION_DATE='2023-02-21T00:00:00+00:00' AIRFLOW_CTX_TRY_NUMBER='1' AIRFLOW_CTX_DAG_RUN_ID='scheduled__2023-02-21T00:00:00+00:00'
[2023-12-07T17:22:48.748+0000] {taskinstance.py:1937} ERROR - Task failed with exception
Traceback (most recent call last):
  File "/home/airflow/.local/lib/python3.8/site-packages/airflow/operators/python.py", line 192, in execute
    return_value = self.execute_callable()
  File "/home/airflow/.local/lib/python3.8/site-packages/airflow/operators/python.py", line 209, in execute_callable
    return self.python_callable(*self.op_args, **self.op_kwargs)
  File "/opt/airflow/dags/main.py", line 73, in main
    insert_data_to_db(products, db_params)
  File "/opt/airflow/dags/main.py", line 40, in insert_data_to_db
    with psycopg2.connect(**db_params) as conn:
  File "/home/airflow/.local/lib/python3.8/site-packages/psycopg2/__init__.py", line 122, in connect
    conn = _connect(dsn, connection_factory=connection_factory, **kwasync)
psycopg2.OperationalError: connection to server at "localhost" (127.0.0.1), port 5432 failed: Connection refused
	Is the server running on that host and accepting TCP/IP connections?
connection to server at "localhost" (::1), port 5432 failed: Cannot assign requested address
	Is the server running on that host and accepting TCP/IP connections?

[2023-12-07T17:22:48.753+0000] {taskinstance.py:1400} INFO - Marking task as FAILED. dag_id=my_scraping_dag, task_id=main_task, execution_date=20230221T000000, start_date=20231207T172247, end_date=20231207T172248
[2023-12-07T17:22:48.759+0000] {standard_task_runner.py:104} ERROR - Failed to execute job 2923 for task main_task (connection to server at "localhost" (127.0.0.1), port 5432 failed: Connection refused
	Is the server running on that host and accepting TCP/IP connections?
connection to server at "localhost" (::1), port 5432 failed: Cannot assign requested address
	Is the server running on that host and accepting TCP/IP connections?
; 9441)
[2023-12-07T17:22:48.796+0000] {local_task_job_runner.py:228} INFO - Task exited with return code 1
[2023-12-07T17:22:48.805+0000] {taskinstance.py:2778} INFO - 0 downstream tasks scheduled from follow-on schedule check
[2023-12-07T17:28:28.671+0000] {taskinstance.py:1159} INFO - Dependencies all met for dep_context=non-requeueable deps ti=<TaskInstance: my_scraping_dag.main_task scheduled__2023-02-21T00:00:00+00:00 [queued]>
[2023-12-07T17:28:28.677+0000] {taskinstance.py:1159} INFO - Dependencies all met for dep_context=requeueable deps ti=<TaskInstance: my_scraping_dag.main_task scheduled__2023-02-21T00:00:00+00:00 [queued]>
[2023-12-07T17:28:28.678+0000] {taskinstance.py:1361} INFO - Starting attempt 1 of 1
[2023-12-07T17:28:28.686+0000] {taskinstance.py:1382} INFO - Executing <Task(PythonOperator): main_task> on 2023-02-21 00:00:00+00:00
[2023-12-07T17:28:28.689+0000] {standard_task_runner.py:57} INFO - Started process 10283 to run task
[2023-12-07T17:28:28.692+0000] {standard_task_runner.py:84} INFO - Running: ['***', 'tasks', 'run', 'my_scraping_dag', 'main_task', 'scheduled__2023-02-21T00:00:00+00:00', '--job-id', '3265', '--raw', '--subdir', 'DAGS_FOLDER/main.py', '--cfg-path', '/tmp/tmpot9ensnz']
[2023-12-07T17:28:28.694+0000] {standard_task_runner.py:85} INFO - Job 3265: Subtask main_task
[2023-12-07T17:28:28.729+0000] {task_command.py:416} INFO - Running <TaskInstance: my_scraping_dag.main_task scheduled__2023-02-21T00:00:00+00:00 [running]> on host 63b0c7e341c0
[2023-12-07T17:28:28.776+0000] {taskinstance.py:1662} INFO - Exporting env vars: AIRFLOW_CTX_DAG_OWNER='***' AIRFLOW_CTX_DAG_ID='my_scraping_dag' AIRFLOW_CTX_TASK_ID='main_task' AIRFLOW_CTX_EXECUTION_DATE='2023-02-21T00:00:00+00:00' AIRFLOW_CTX_TRY_NUMBER='1' AIRFLOW_CTX_DAG_RUN_ID='scheduled__2023-02-21T00:00:00+00:00'
[2023-12-07T17:28:29.583+0000] {taskinstance.py:1937} ERROR - Task failed with exception
Traceback (most recent call last):
  File "/home/airflow/.local/lib/python3.8/site-packages/airflow/operators/python.py", line 192, in execute
    return_value = self.execute_callable()
  File "/home/airflow/.local/lib/python3.8/site-packages/airflow/operators/python.py", line 209, in execute_callable
    return self.python_callable(*self.op_args, **self.op_kwargs)
  File "/opt/airflow/dags/main.py", line 73, in main
    insert_data_to_db(products, db_params)
  File "/opt/airflow/dags/main.py", line 40, in insert_data_to_db
    with psycopg2.connect(**db_params) as conn:
  File "/home/airflow/.local/lib/python3.8/site-packages/psycopg2/__init__.py", line 122, in connect
    conn = _connect(dsn, connection_factory=connection_factory, **kwasync)
psycopg2.OperationalError: connection to server at "localhost" (127.0.0.1), port 5432 failed: Connection refused
	Is the server running on that host and accepting TCP/IP connections?
connection to server at "localhost" (::1), port 5432 failed: Cannot assign requested address
	Is the server running on that host and accepting TCP/IP connections?

[2023-12-07T17:28:29.588+0000] {taskinstance.py:1400} INFO - Marking task as FAILED. dag_id=my_scraping_dag, task_id=main_task, execution_date=20230221T000000, start_date=20231207T172828, end_date=20231207T172829
[2023-12-07T17:28:29.594+0000] {standard_task_runner.py:104} ERROR - Failed to execute job 3265 for task main_task (connection to server at "localhost" (127.0.0.1), port 5432 failed: Connection refused
	Is the server running on that host and accepting TCP/IP connections?
connection to server at "localhost" (::1), port 5432 failed: Cannot assign requested address
	Is the server running on that host and accepting TCP/IP connections?
; 10283)
[2023-12-07T17:28:29.637+0000] {local_task_job_runner.py:228} INFO - Task exited with return code 1
[2023-12-07T17:28:29.651+0000] {taskinstance.py:2778} INFO - 0 downstream tasks scheduled from follow-on schedule check
