[2023-12-07T14:46:26.333+0000] {taskinstance.py:1159} INFO - Dependencies all met for dep_context=non-requeueable deps ti=<TaskInstance: my_scraping_dag.main_task scheduled__2023-03-24T00:00:00+00:00 [queued]>
[2023-12-07T14:46:26.337+0000] {taskinstance.py:1159} INFO - Dependencies all met for dep_context=requeueable deps ti=<TaskInstance: my_scraping_dag.main_task scheduled__2023-03-24T00:00:00+00:00 [queued]>
[2023-12-07T14:46:26.337+0000] {taskinstance.py:1361} INFO - Starting attempt 1 of 1
[2023-12-07T14:46:26.342+0000] {taskinstance.py:1382} INFO - Executing <Task(PythonOperator): main_task> on 2023-03-24 00:00:00+00:00
[2023-12-07T14:46:26.344+0000] {standard_task_runner.py:57} INFO - Started process 568 to run task
[2023-12-07T14:46:26.346+0000] {standard_task_runner.py:84} INFO - Running: ['***', 'tasks', 'run', 'my_scraping_dag', 'main_task', 'scheduled__2023-03-24T00:00:00+00:00', '--job-id', '94', '--raw', '--subdir', 'DAGS_FOLDER/main.py', '--cfg-path', '/tmp/tmp_qrpnmwv']
[2023-12-07T14:46:26.348+0000] {standard_task_runner.py:85} INFO - Job 94: Subtask main_task
[2023-12-07T14:46:26.368+0000] {task_command.py:416} INFO - Running <TaskInstance: my_scraping_dag.main_task scheduled__2023-03-24T00:00:00+00:00 [running]> on host 63b0c7e341c0
[2023-12-07T14:46:26.397+0000] {taskinstance.py:1662} INFO - Exporting env vars: AIRFLOW_CTX_DAG_OWNER='***' AIRFLOW_CTX_DAG_ID='my_scraping_dag' AIRFLOW_CTX_TASK_ID='main_task' AIRFLOW_CTX_EXECUTION_DATE='2023-03-24T00:00:00+00:00' AIRFLOW_CTX_TRY_NUMBER='1' AIRFLOW_CTX_DAG_RUN_ID='scheduled__2023-03-24T00:00:00+00:00'
[2023-12-07T14:46:26.398+0000] {taskinstance.py:1937} ERROR - Task failed with exception
Traceback (most recent call last):
  File "/usr/local/lib/python3.8/configparser.py", line 846, in items
    d.update(self._sections[section])
KeyError: 'web'

During handling of the above exception, another exception occurred:

Traceback (most recent call last):
  File "/home/airflow/.local/lib/python3.8/site-packages/airflow/operators/python.py", line 192, in execute
    return_value = self.execute_callable()
  File "/home/airflow/.local/lib/python3.8/site-packages/airflow/operators/python.py", line 209, in execute_callable
    return self.python_callable(*self.op_args, **self.op_kwargs)
  File "/opt/airflow/dags/main.py", line 61, in main
    config = get_config('web')
  File "/opt/airflow/dags/main.py", line 23, in get_config
    return {key: value for key, value in parser.items(section)}
  File "/usr/local/lib/python3.8/configparser.py", line 849, in items
    raise NoSectionError(section)
configparser.NoSectionError: No section: 'web'
[2023-12-07T14:46:26.402+0000] {taskinstance.py:1400} INFO - Marking task as FAILED. dag_id=my_scraping_dag, task_id=main_task, execution_date=20230324T000000, start_date=20231207T144626, end_date=20231207T144626
[2023-12-07T14:46:26.406+0000] {standard_task_runner.py:104} ERROR - Failed to execute job 94 for task main_task (No section: 'web'; 568)
[2023-12-07T14:46:26.438+0000] {local_task_job_runner.py:228} INFO - Task exited with return code 1
[2023-12-07T14:46:26.449+0000] {taskinstance.py:2778} INFO - 0 downstream tasks scheduled from follow-on schedule check
[2023-12-07T14:52:05.827+0000] {taskinstance.py:1159} INFO - Dependencies all met for dep_context=non-requeueable deps ti=<TaskInstance: my_scraping_dag.main_task scheduled__2023-03-24T00:00:00+00:00 [queued]>
[2023-12-07T14:52:05.832+0000] {taskinstance.py:1159} INFO - Dependencies all met for dep_context=requeueable deps ti=<TaskInstance: my_scraping_dag.main_task scheduled__2023-03-24T00:00:00+00:00 [queued]>
[2023-12-07T14:52:05.833+0000] {taskinstance.py:1361} INFO - Starting attempt 1 of 1
[2023-12-07T14:52:05.844+0000] {taskinstance.py:1382} INFO - Executing <Task(PythonOperator): main_task> on 2023-03-24 00:00:00+00:00
[2023-12-07T14:52:05.848+0000] {standard_task_runner.py:57} INFO - Started process 926 to run task
[2023-12-07T14:52:05.851+0000] {standard_task_runner.py:84} INFO - Running: ['***', 'tasks', 'run', 'my_scraping_dag', 'main_task', 'scheduled__2023-03-24T00:00:00+00:00', '--job-id', '193', '--raw', '--subdir', 'DAGS_FOLDER/main.py', '--cfg-path', '/tmp/tmp4chijraq']
[2023-12-07T14:52:05.853+0000] {standard_task_runner.py:85} INFO - Job 193: Subtask main_task
[2023-12-07T14:52:05.881+0000] {task_command.py:416} INFO - Running <TaskInstance: my_scraping_dag.main_task scheduled__2023-03-24T00:00:00+00:00 [running]> on host 63b0c7e341c0
[2023-12-07T14:52:05.920+0000] {taskinstance.py:1662} INFO - Exporting env vars: AIRFLOW_CTX_DAG_OWNER='***' AIRFLOW_CTX_DAG_ID='my_scraping_dag' AIRFLOW_CTX_TASK_ID='main_task' AIRFLOW_CTX_EXECUTION_DATE='2023-03-24T00:00:00+00:00' AIRFLOW_CTX_TRY_NUMBER='1' AIRFLOW_CTX_DAG_RUN_ID='scheduled__2023-03-24T00:00:00+00:00'
[2023-12-07T14:52:05.921+0000] {taskinstance.py:1937} ERROR - Task failed with exception
Traceback (most recent call last):
  File "/usr/local/lib/python3.8/configparser.py", line 846, in items
    d.update(self._sections[section])
KeyError: 'web'

During handling of the above exception, another exception occurred:

Traceback (most recent call last):
  File "/home/airflow/.local/lib/python3.8/site-packages/airflow/operators/python.py", line 192, in execute
    return_value = self.execute_callable()
  File "/home/airflow/.local/lib/python3.8/site-packages/airflow/operators/python.py", line 209, in execute_callable
    return self.python_callable(*self.op_args, **self.op_kwargs)
  File "/opt/airflow/dags/main.py", line 61, in main
    config = get_config('web')
  File "/opt/airflow/dags/main.py", line 23, in get_config
    return {key: value for key, value in parser.items(section)}
  File "/usr/local/lib/python3.8/configparser.py", line 849, in items
    raise NoSectionError(section)
configparser.NoSectionError: No section: 'web'
[2023-12-07T14:52:05.925+0000] {taskinstance.py:1400} INFO - Marking task as FAILED. dag_id=my_scraping_dag, task_id=main_task, execution_date=20230324T000000, start_date=20231207T145205, end_date=20231207T145205
[2023-12-07T14:52:05.930+0000] {standard_task_runner.py:104} ERROR - Failed to execute job 193 for task main_task (No section: 'web'; 926)
[2023-12-07T14:52:05.943+0000] {local_task_job_runner.py:228} INFO - Task exited with return code 1
[2023-12-07T14:52:05.957+0000] {taskinstance.py:2778} INFO - 0 downstream tasks scheduled from follow-on schedule check
[2023-12-07T15:00:16.140+0000] {taskinstance.py:1159} INFO - Dependencies all met for dep_context=non-requeueable deps ti=<TaskInstance: my_scraping_dag.main_task scheduled__2023-03-24T00:00:00+00:00 [queued]>
[2023-12-07T15:00:16.147+0000] {taskinstance.py:1159} INFO - Dependencies all met for dep_context=requeueable deps ti=<TaskInstance: my_scraping_dag.main_task scheduled__2023-03-24T00:00:00+00:00 [queued]>
[2023-12-07T15:00:16.148+0000] {taskinstance.py:1361} INFO - Starting attempt 1 of 1
[2023-12-07T15:00:16.155+0000] {taskinstance.py:1382} INFO - Executing <Task(PythonOperator): main_task> on 2023-03-24 00:00:00+00:00
[2023-12-07T15:00:16.157+0000] {standard_task_runner.py:57} INFO - Started process 1542 to run task
[2023-12-07T15:00:16.160+0000] {standard_task_runner.py:84} INFO - Running: ['***', 'tasks', 'run', 'my_scraping_dag', 'main_task', 'scheduled__2023-03-24T00:00:00+00:00', '--job-id', '398', '--raw', '--subdir', 'DAGS_FOLDER/main.py', '--cfg-path', '/tmp/tmpe4ibsqw6']
[2023-12-07T15:00:16.162+0000] {standard_task_runner.py:85} INFO - Job 398: Subtask main_task
[2023-12-07T15:00:16.187+0000] {task_command.py:416} INFO - Running <TaskInstance: my_scraping_dag.main_task scheduled__2023-03-24T00:00:00+00:00 [running]> on host 63b0c7e341c0
[2023-12-07T15:00:16.224+0000] {taskinstance.py:1662} INFO - Exporting env vars: AIRFLOW_CTX_DAG_OWNER='***' AIRFLOW_CTX_DAG_ID='my_scraping_dag' AIRFLOW_CTX_TASK_ID='main_task' AIRFLOW_CTX_EXECUTION_DATE='2023-03-24T00:00:00+00:00' AIRFLOW_CTX_TRY_NUMBER='1' AIRFLOW_CTX_DAG_RUN_ID='scheduled__2023-03-24T00:00:00+00:00'
[2023-12-07T15:00:16.225+0000] {taskinstance.py:1937} ERROR - Task failed with exception
Traceback (most recent call last):
  File "/usr/local/lib/python3.8/configparser.py", line 846, in items
    d.update(self._sections[section])
KeyError: 'web'

During handling of the above exception, another exception occurred:

Traceback (most recent call last):
  File "/home/airflow/.local/lib/python3.8/site-packages/airflow/operators/python.py", line 192, in execute
    return_value = self.execute_callable()
  File "/home/airflow/.local/lib/python3.8/site-packages/airflow/operators/python.py", line 209, in execute_callable
    return self.python_callable(*self.op_args, **self.op_kwargs)
  File "/opt/airflow/dags/main.py", line 60, in main
    config = get_config('web')
  File "/opt/airflow/dags/main.py", line 22, in get_config
    return {key: value for key, value in parser.items(section)}
  File "/usr/local/lib/python3.8/configparser.py", line 849, in items
    raise NoSectionError(section)
configparser.NoSectionError: No section: 'web'
[2023-12-07T15:00:16.232+0000] {taskinstance.py:1400} INFO - Marking task as FAILED. dag_id=my_scraping_dag, task_id=main_task, execution_date=20230324T000000, start_date=20231207T150016, end_date=20231207T150016
[2023-12-07T15:00:16.238+0000] {standard_task_runner.py:104} ERROR - Failed to execute job 398 for task main_task (No section: 'web'; 1542)
[2023-12-07T15:00:16.252+0000] {local_task_job_runner.py:228} INFO - Task exited with return code 1
[2023-12-07T15:00:16.279+0000] {taskinstance.py:2778} INFO - 0 downstream tasks scheduled from follow-on schedule check
[2023-12-07T15:11:02.585+0000] {taskinstance.py:1159} INFO - Dependencies all met for dep_context=non-requeueable deps ti=<TaskInstance: my_scraping_dag.main_task scheduled__2023-03-24T00:00:00+00:00 [queued]>
[2023-12-07T15:11:02.590+0000] {taskinstance.py:1159} INFO - Dependencies all met for dep_context=requeueable deps ti=<TaskInstance: my_scraping_dag.main_task scheduled__2023-03-24T00:00:00+00:00 [queued]>
[2023-12-07T15:11:02.590+0000] {taskinstance.py:1361} INFO - Starting attempt 1 of 1
[2023-12-07T15:11:02.597+0000] {taskinstance.py:1382} INFO - Executing <Task(PythonOperator): main_task> on 2023-03-24 00:00:00+00:00
[2023-12-07T15:11:02.601+0000] {standard_task_runner.py:57} INFO - Started process 2011 to run task
[2023-12-07T15:11:02.604+0000] {standard_task_runner.py:84} INFO - Running: ['***', 'tasks', 'run', 'my_scraping_dag', 'main_task', 'scheduled__2023-03-24T00:00:00+00:00', '--job-id', '504', '--raw', '--subdir', 'DAGS_FOLDER/main.py', '--cfg-path', '/tmp/tmpkr6mpfes']
[2023-12-07T15:11:02.606+0000] {standard_task_runner.py:85} INFO - Job 504: Subtask main_task
[2023-12-07T15:11:02.640+0000] {task_command.py:416} INFO - Running <TaskInstance: my_scraping_dag.main_task scheduled__2023-03-24T00:00:00+00:00 [running]> on host 63b0c7e341c0
[2023-12-07T15:11:02.686+0000] {taskinstance.py:1662} INFO - Exporting env vars: AIRFLOW_CTX_DAG_OWNER='***' AIRFLOW_CTX_DAG_ID='my_scraping_dag' AIRFLOW_CTX_TASK_ID='main_task' AIRFLOW_CTX_EXECUTION_DATE='2023-03-24T00:00:00+00:00' AIRFLOW_CTX_TRY_NUMBER='1' AIRFLOW_CTX_DAG_RUN_ID='scheduled__2023-03-24T00:00:00+00:00'
[2023-12-07T15:11:02.688+0000] {taskinstance.py:1937} ERROR - Task failed with exception
Traceback (most recent call last):
  File "/usr/local/lib/python3.8/configparser.py", line 846, in items
    d.update(self._sections[section])
KeyError: 'web'

During handling of the above exception, another exception occurred:

Traceback (most recent call last):
  File "/home/airflow/.local/lib/python3.8/site-packages/airflow/operators/python.py", line 192, in execute
    return_value = self.execute_callable()
  File "/home/airflow/.local/lib/python3.8/site-packages/airflow/operators/python.py", line 209, in execute_callable
    return self.python_callable(*self.op_args, **self.op_kwargs)
  File "/opt/airflow/dags/main.py", line 63, in main
    config = get_config('web')
  File "/opt/airflow/dags/main.py", line 14, in get_config
    return {key: value for key, value in parser.items(section)}
  File "/usr/local/lib/python3.8/configparser.py", line 849, in items
    raise NoSectionError(section)
configparser.NoSectionError: No section: 'web'
[2023-12-07T15:11:02.694+0000] {taskinstance.py:1400} INFO - Marking task as FAILED. dag_id=my_scraping_dag, task_id=main_task, execution_date=20230324T000000, start_date=20231207T151102, end_date=20231207T151102
[2023-12-07T15:11:02.701+0000] {standard_task_runner.py:104} ERROR - Failed to execute job 504 for task main_task (No section: 'web'; 2011)
[2023-12-07T15:11:02.737+0000] {local_task_job_runner.py:228} INFO - Task exited with return code 1
[2023-12-07T15:11:02.751+0000] {taskinstance.py:2778} INFO - 0 downstream tasks scheduled from follow-on schedule check
[2023-12-07T16:31:58.634+0000] {taskinstance.py:1159} INFO - Dependencies all met for dep_context=non-requeueable deps ti=<TaskInstance: my_scraping_dag.main_task scheduled__2023-03-24T00:00:00+00:00 [queued]>
[2023-12-07T16:31:58.638+0000] {taskinstance.py:1159} INFO - Dependencies all met for dep_context=requeueable deps ti=<TaskInstance: my_scraping_dag.main_task scheduled__2023-03-24T00:00:00+00:00 [queued]>
[2023-12-07T16:31:58.638+0000] {taskinstance.py:1361} INFO - Starting attempt 1 of 1
[2023-12-07T16:31:58.643+0000] {taskinstance.py:1382} INFO - Executing <Task(PythonOperator): main_task> on 2023-03-24 00:00:00+00:00
[2023-12-07T16:31:58.645+0000] {standard_task_runner.py:57} INFO - Started process 3688 to run task
[2023-12-07T16:31:58.647+0000] {standard_task_runner.py:84} INFO - Running: ['***', 'tasks', 'run', 'my_scraping_dag', 'main_task', 'scheduled__2023-03-24T00:00:00+00:00', '--job-id', '671', '--raw', '--subdir', 'DAGS_FOLDER/main.py', '--cfg-path', '/tmp/tmpjgjpiato']
[2023-12-07T16:31:58.649+0000] {standard_task_runner.py:85} INFO - Job 671: Subtask main_task
[2023-12-07T16:31:58.671+0000] {task_command.py:416} INFO - Running <TaskInstance: my_scraping_dag.main_task scheduled__2023-03-24T00:00:00+00:00 [running]> on host 63b0c7e341c0
[2023-12-07T16:31:58.700+0000] {taskinstance.py:1662} INFO - Exporting env vars: AIRFLOW_CTX_DAG_OWNER='***' AIRFLOW_CTX_DAG_ID='my_scraping_dag' AIRFLOW_CTX_TASK_ID='main_task' AIRFLOW_CTX_EXECUTION_DATE='2023-03-24T00:00:00+00:00' AIRFLOW_CTX_TRY_NUMBER='1' AIRFLOW_CTX_DAG_RUN_ID='scheduled__2023-03-24T00:00:00+00:00'
[2023-12-07T16:31:58.701+0000] {taskinstance.py:1937} ERROR - Task failed with exception
Traceback (most recent call last):
  File "/usr/local/lib/python3.8/configparser.py", line 846, in items
    d.update(self._sections[section])
KeyError: 'web'

During handling of the above exception, another exception occurred:

Traceback (most recent call last):
  File "/home/airflow/.local/lib/python3.8/site-packages/airflow/operators/python.py", line 192, in execute
    return_value = self.execute_callable()
  File "/home/airflow/.local/lib/python3.8/site-packages/airflow/operators/python.py", line 209, in execute_callable
    return self.python_callable(*self.op_args, **self.op_kwargs)
  File "/opt/airflow/dags/main.py", line 60, in main
    config = get_config('web')
  File "/opt/airflow/dags/main.py", line 22, in get_config
    return {key: value for key, value in parser.items(section)}
  File "/usr/local/lib/python3.8/configparser.py", line 849, in items
    raise NoSectionError(section)
configparser.NoSectionError: No section: 'web'
[2023-12-07T16:31:58.704+0000] {taskinstance.py:1400} INFO - Marking task as FAILED. dag_id=my_scraping_dag, task_id=main_task, execution_date=20230324T000000, start_date=20231207T163158, end_date=20231207T163158
[2023-12-07T16:31:58.709+0000] {standard_task_runner.py:104} ERROR - Failed to execute job 671 for task main_task (No section: 'web'; 3688)
[2023-12-07T16:31:58.741+0000] {local_task_job_runner.py:228} INFO - Task exited with return code 1
[2023-12-07T16:31:58.752+0000] {taskinstance.py:2778} INFO - 0 downstream tasks scheduled from follow-on schedule check
[2023-12-07T16:41:17.854+0000] {taskinstance.py:1159} INFO - Dependencies all met for dep_context=non-requeueable deps ti=<TaskInstance: my_scraping_dag.main_task scheduled__2023-03-24T00:00:00+00:00 [queued]>
[2023-12-07T16:41:17.858+0000] {taskinstance.py:1159} INFO - Dependencies all met for dep_context=requeueable deps ti=<TaskInstance: my_scraping_dag.main_task scheduled__2023-03-24T00:00:00+00:00 [queued]>
[2023-12-07T16:41:17.859+0000] {taskinstance.py:1361} INFO - Starting attempt 1 of 1
[2023-12-07T16:41:17.865+0000] {taskinstance.py:1382} INFO - Executing <Task(PythonOperator): main_task> on 2023-03-24 00:00:00+00:00
[2023-12-07T16:41:17.868+0000] {standard_task_runner.py:57} INFO - Started process 4597 to run task
[2023-12-07T16:41:17.870+0000] {standard_task_runner.py:84} INFO - Running: ['***', 'tasks', 'run', 'my_scraping_dag', 'main_task', 'scheduled__2023-03-24T00:00:00+00:00', '--job-id', '1013', '--raw', '--subdir', 'DAGS_FOLDER/main.py', '--cfg-path', '/tmp/tmp595aw9vi']
[2023-12-07T16:41:17.871+0000] {standard_task_runner.py:85} INFO - Job 1013: Subtask main_task
[2023-12-07T16:41:17.894+0000] {task_command.py:416} INFO - Running <TaskInstance: my_scraping_dag.main_task scheduled__2023-03-24T00:00:00+00:00 [running]> on host 63b0c7e341c0
[2023-12-07T16:41:17.924+0000] {taskinstance.py:1662} INFO - Exporting env vars: AIRFLOW_CTX_DAG_OWNER='***' AIRFLOW_CTX_DAG_ID='my_scraping_dag' AIRFLOW_CTX_TASK_ID='main_task' AIRFLOW_CTX_EXECUTION_DATE='2023-03-24T00:00:00+00:00' AIRFLOW_CTX_TRY_NUMBER='1' AIRFLOW_CTX_DAG_RUN_ID='scheduled__2023-03-24T00:00:00+00:00'
[2023-12-07T16:41:17.925+0000] {taskinstance.py:1937} ERROR - Task failed with exception
Traceback (most recent call last):
  File "/usr/local/lib/python3.8/configparser.py", line 846, in items
    d.update(self._sections[section])
KeyError: 'web'

During handling of the above exception, another exception occurred:

Traceback (most recent call last):
  File "/home/airflow/.local/lib/python3.8/site-packages/airflow/operators/python.py", line 192, in execute
    return_value = self.execute_callable()
  File "/home/airflow/.local/lib/python3.8/site-packages/airflow/operators/python.py", line 209, in execute_callable
    return self.python_callable(*self.op_args, **self.op_kwargs)
  File "/opt/airflow/dags/main.py", line 60, in main
    config = get_config('web')
  File "/opt/airflow/dags/main.py", line 22, in get_config
    return {key: value for key, value in parser.items(section)}
  File "/usr/local/lib/python3.8/configparser.py", line 849, in items
    raise NoSectionError(section)
configparser.NoSectionError: No section: 'web'
[2023-12-07T16:41:17.929+0000] {taskinstance.py:1400} INFO - Marking task as FAILED. dag_id=my_scraping_dag, task_id=main_task, execution_date=20230324T000000, start_date=20231207T164117, end_date=20231207T164117
[2023-12-07T16:41:17.933+0000] {standard_task_runner.py:104} ERROR - Failed to execute job 1013 for task main_task (No section: 'web'; 4597)
[2023-12-07T16:41:17.962+0000] {local_task_job_runner.py:228} INFO - Task exited with return code 1
[2023-12-07T16:41:17.974+0000] {taskinstance.py:2778} INFO - 0 downstream tasks scheduled from follow-on schedule check
[2023-12-07T17:00:22.298+0000] {taskinstance.py:1159} INFO - Dependencies all met for dep_context=non-requeueable deps ti=<TaskInstance: my_scraping_dag.main_task scheduled__2023-03-24T00:00:00+00:00 [queued]>
[2023-12-07T17:00:22.303+0000] {taskinstance.py:1159} INFO - Dependencies all met for dep_context=requeueable deps ti=<TaskInstance: my_scraping_dag.main_task scheduled__2023-03-24T00:00:00+00:00 [queued]>
[2023-12-07T17:00:22.304+0000] {taskinstance.py:1361} INFO - Starting attempt 1 of 1
[2023-12-07T17:00:22.315+0000] {taskinstance.py:1382} INFO - Executing <Task(PythonOperator): main_task> on 2023-03-24 00:00:00+00:00
[2023-12-07T17:00:22.318+0000] {standard_task_runner.py:57} INFO - Started process 5756 to run task
[2023-12-07T17:00:22.321+0000] {standard_task_runner.py:84} INFO - Running: ['***', 'tasks', 'run', 'my_scraping_dag', 'main_task', 'scheduled__2023-03-24T00:00:00+00:00', '--job-id', '1357', '--raw', '--subdir', 'DAGS_FOLDER/main.py', '--cfg-path', '/tmp/tmp9j3epe_h']
[2023-12-07T17:00:22.323+0000] {standard_task_runner.py:85} INFO - Job 1357: Subtask main_task
[2023-12-07T17:00:22.350+0000] {task_command.py:416} INFO - Running <TaskInstance: my_scraping_dag.main_task scheduled__2023-03-24T00:00:00+00:00 [running]> on host 63b0c7e341c0
[2023-12-07T17:00:22.387+0000] {taskinstance.py:1662} INFO - Exporting env vars: AIRFLOW_CTX_DAG_OWNER='***' AIRFLOW_CTX_DAG_ID='my_scraping_dag' AIRFLOW_CTX_TASK_ID='main_task' AIRFLOW_CTX_EXECUTION_DATE='2023-03-24T00:00:00+00:00' AIRFLOW_CTX_TRY_NUMBER='1' AIRFLOW_CTX_DAG_RUN_ID='scheduled__2023-03-24T00:00:00+00:00'
[2023-12-07T17:00:22.411+0000] {taskinstance.py:1937} ERROR - Task failed with exception
Traceback (most recent call last):
  File "/home/airflow/.local/lib/python3.8/site-packages/airflow/operators/python.py", line 192, in execute
    return_value = self.execute_callable()
  File "/home/airflow/.local/lib/python3.8/site-packages/airflow/operators/python.py", line 209, in execute_callable
    return self.python_callable(*self.op_args, **self.op_kwargs)
  File "/opt/airflow/dags/main.py", line 33, in main
    'host': get_config('localhost'),
  File "/opt/airflow/dags/main.py", line 20, in get_config
    return Variable.get(key)
  File "/home/airflow/.local/lib/python3.8/site-packages/airflow/models/variable.py", line 140, in get
    raise KeyError(f"Variable {key} does not exist")
KeyError: 'Variable localhost does not exist'
[2023-12-07T17:00:22.416+0000] {taskinstance.py:1400} INFO - Marking task as FAILED. dag_id=my_scraping_dag, task_id=main_task, execution_date=20230324T000000, start_date=20231207T170022, end_date=20231207T170022
[2023-12-07T17:00:22.442+0000] {standard_task_runner.py:104} ERROR - Failed to execute job 1357 for task main_task ('Variable localhost does not exist'; 5756)
[2023-12-07T17:00:22.454+0000] {local_task_job_runner.py:228} INFO - Task exited with return code 1
[2023-12-07T17:00:22.468+0000] {taskinstance.py:2778} INFO - 0 downstream tasks scheduled from follow-on schedule check
[2023-12-07T17:03:41.600+0000] {taskinstance.py:1159} INFO - Dependencies all met for dep_context=non-requeueable deps ti=<TaskInstance: my_scraping_dag.main_task scheduled__2023-03-24T00:00:00+00:00 [queued]>
[2023-12-07T17:03:41.608+0000] {taskinstance.py:1159} INFO - Dependencies all met for dep_context=requeueable deps ti=<TaskInstance: my_scraping_dag.main_task scheduled__2023-03-24T00:00:00+00:00 [queued]>
[2023-12-07T17:03:41.609+0000] {taskinstance.py:1361} INFO - Starting attempt 1 of 1
[2023-12-07T17:03:41.623+0000] {taskinstance.py:1382} INFO - Executing <Task(PythonOperator): main_task> on 2023-03-24 00:00:00+00:00
[2023-12-07T17:03:41.627+0000] {standard_task_runner.py:57} INFO - Started process 7133 to run task
[2023-12-07T17:03:41.634+0000] {standard_task_runner.py:84} INFO - Running: ['***', 'tasks', 'run', 'my_scraping_dag', 'main_task', 'scheduled__2023-03-24T00:00:00+00:00', '--job-id', '2003', '--raw', '--subdir', 'DAGS_FOLDER/main.py', '--cfg-path', '/tmp/tmpz79_r72p']
[2023-12-07T17:03:41.651+0000] {standard_task_runner.py:85} INFO - Job 2003: Subtask main_task
[2023-12-07T17:03:41.712+0000] {task_command.py:416} INFO - Running <TaskInstance: my_scraping_dag.main_task scheduled__2023-03-24T00:00:00+00:00 [running]> on host 63b0c7e341c0
[2023-12-07T17:03:41.786+0000] {taskinstance.py:1662} INFO - Exporting env vars: AIRFLOW_CTX_DAG_OWNER='***' AIRFLOW_CTX_DAG_ID='my_scraping_dag' AIRFLOW_CTX_TASK_ID='main_task' AIRFLOW_CTX_EXECUTION_DATE='2023-03-24T00:00:00+00:00' AIRFLOW_CTX_TRY_NUMBER='1' AIRFLOW_CTX_DAG_RUN_ID='scheduled__2023-03-24T00:00:00+00:00'
[2023-12-07T17:03:41.844+0000] {logging_mixin.py:154} INFO - base_url: https://tuncbotanik.com
[2023-12-07T17:03:41.845+0000] {python.py:194} INFO - Done. Returned value was: ('https://tuncbotanik.com', {'User-Agent': 'Mozilla/5.0 (Macintosh; Intel Mac OS X 10_15_7) AppleWebKit/537.36 (KHTML, like Gecko) Chrome/119.0.0.0 Safari/537.36', 'Accept-Language': 'tr-TR,tr;q=0.9,en-US;q=0.8,en;q=0.7'}, {'dbname': 'plant', 'user': 'aozgokme', 'password': '***', 'host': 'localhost', 'port': '5432'})
[2023-12-07T17:03:41.869+0000] {taskinstance.py:1400} INFO - Marking task as SUCCESS. dag_id=my_scraping_dag, task_id=main_task, execution_date=20230324T000000, start_date=20231207T170341, end_date=20231207T170341
[2023-12-07T17:03:41.898+0000] {local_task_job_runner.py:228} INFO - Task exited with return code 0
[2023-12-07T17:03:41.921+0000] {taskinstance.py:2778} INFO - 1 downstream tasks scheduled from follow-on schedule check
[2023-12-07T17:18:35.619+0000] {taskinstance.py:1159} INFO - Dependencies all met for dep_context=non-requeueable deps ti=<TaskInstance: my_scraping_dag.main_task scheduled__2023-03-24T00:00:00+00:00 [queued]>
[2023-12-07T17:18:35.626+0000] {taskinstance.py:1159} INFO - Dependencies all met for dep_context=requeueable deps ti=<TaskInstance: my_scraping_dag.main_task scheduled__2023-03-24T00:00:00+00:00 [queued]>
[2023-12-07T17:18:35.627+0000] {taskinstance.py:1361} INFO - Starting attempt 1 of 1
[2023-12-07T17:18:35.636+0000] {taskinstance.py:1382} INFO - Executing <Task(PythonOperator): main_task> on 2023-03-24 00:00:00+00:00
[2023-12-07T17:18:35.638+0000] {standard_task_runner.py:57} INFO - Started process 8709 to run task
[2023-12-07T17:18:35.641+0000] {standard_task_runner.py:84} INFO - Running: ['***', 'tasks', 'run', 'my_scraping_dag', 'main_task', 'scheduled__2023-03-24T00:00:00+00:00', '--job-id', '2612', '--raw', '--subdir', 'DAGS_FOLDER/main.py', '--cfg-path', '/tmp/tmpl6pmuai0']
[2023-12-07T17:18:35.644+0000] {standard_task_runner.py:85} INFO - Job 2612: Subtask main_task
[2023-12-07T17:18:35.678+0000] {task_command.py:416} INFO - Running <TaskInstance: my_scraping_dag.main_task scheduled__2023-03-24T00:00:00+00:00 [running]> on host 63b0c7e341c0
[2023-12-07T17:18:35.718+0000] {taskinstance.py:1662} INFO - Exporting env vars: AIRFLOW_CTX_DAG_OWNER='***' AIRFLOW_CTX_DAG_ID='my_scraping_dag' AIRFLOW_CTX_TASK_ID='main_task' AIRFLOW_CTX_EXECUTION_DATE='2023-03-24T00:00:00+00:00' AIRFLOW_CTX_TRY_NUMBER='1' AIRFLOW_CTX_DAG_RUN_ID='scheduled__2023-03-24T00:00:00+00:00'
[2023-12-07T17:18:36.464+0000] {taskinstance.py:1937} ERROR - Task failed with exception
Traceback (most recent call last):
  File "/home/airflow/.local/lib/python3.8/site-packages/airflow/operators/python.py", line 192, in execute
    return_value = self.execute_callable()
  File "/home/airflow/.local/lib/python3.8/site-packages/airflow/operators/python.py", line 209, in execute_callable
    return self.python_callable(*self.op_args, **self.op_kwargs)
  File "/opt/airflow/dags/main.py", line 80, in main
    insert_data_to_db(products, db_params)
  File "/opt/airflow/dags/main.py", line 43, in insert_data_to_db
    with psycopg2.connect(**db_params) as conn:
  File "/home/airflow/.local/lib/python3.8/site-packages/psycopg2/__init__.py", line 122, in connect
    conn = _connect(dsn, connection_factory=connection_factory, **kwasync)
psycopg2.OperationalError: connection to server at "localhost" (127.0.0.1), port 5432 failed: Connection refused
	Is the server running on that host and accepting TCP/IP connections?
connection to server at "localhost" (::1), port 5432 failed: Cannot assign requested address
	Is the server running on that host and accepting TCP/IP connections?

[2023-12-07T17:18:36.471+0000] {taskinstance.py:1400} INFO - Marking task as FAILED. dag_id=my_scraping_dag, task_id=main_task, execution_date=20230324T000000, start_date=20231207T171835, end_date=20231207T171836
[2023-12-07T17:18:36.479+0000] {standard_task_runner.py:104} ERROR - Failed to execute job 2612 for task main_task (connection to server at "localhost" (127.0.0.1), port 5432 failed: Connection refused
	Is the server running on that host and accepting TCP/IP connections?
connection to server at "localhost" (::1), port 5432 failed: Cannot assign requested address
	Is the server running on that host and accepting TCP/IP connections?
; 8709)
[2023-12-07T17:18:36.496+0000] {local_task_job_runner.py:228} INFO - Task exited with return code 1
[2023-12-07T17:18:36.512+0000] {taskinstance.py:2778} INFO - 0 downstream tasks scheduled from follow-on schedule check
[2023-12-07T17:22:53.627+0000] {taskinstance.py:1159} INFO - Dependencies all met for dep_context=non-requeueable deps ti=<TaskInstance: my_scraping_dag.main_task scheduled__2023-03-24T00:00:00+00:00 [queued]>
[2023-12-07T17:22:53.632+0000] {taskinstance.py:1159} INFO - Dependencies all met for dep_context=requeueable deps ti=<TaskInstance: my_scraping_dag.main_task scheduled__2023-03-24T00:00:00+00:00 [queued]>
[2023-12-07T17:22:53.633+0000] {taskinstance.py:1361} INFO - Starting attempt 1 of 1
[2023-12-07T17:22:53.641+0000] {taskinstance.py:1382} INFO - Executing <Task(PythonOperator): main_task> on 2023-03-24 00:00:00+00:00
[2023-12-07T17:22:53.644+0000] {standard_task_runner.py:57} INFO - Started process 9515 to run task
[2023-12-07T17:22:53.648+0000] {standard_task_runner.py:84} INFO - Running: ['***', 'tasks', 'run', 'my_scraping_dag', 'main_task', 'scheduled__2023-03-24T00:00:00+00:00', '--job-id', '2954', '--raw', '--subdir', 'DAGS_FOLDER/main.py', '--cfg-path', '/tmp/tmpywc5qzlq']
[2023-12-07T17:22:53.651+0000] {standard_task_runner.py:85} INFO - Job 2954: Subtask main_task
[2023-12-07T17:22:53.683+0000] {task_command.py:416} INFO - Running <TaskInstance: my_scraping_dag.main_task scheduled__2023-03-24T00:00:00+00:00 [running]> on host 63b0c7e341c0
[2023-12-07T17:22:53.725+0000] {taskinstance.py:1662} INFO - Exporting env vars: AIRFLOW_CTX_DAG_OWNER='***' AIRFLOW_CTX_DAG_ID='my_scraping_dag' AIRFLOW_CTX_TASK_ID='main_task' AIRFLOW_CTX_EXECUTION_DATE='2023-03-24T00:00:00+00:00' AIRFLOW_CTX_TRY_NUMBER='1' AIRFLOW_CTX_DAG_RUN_ID='scheduled__2023-03-24T00:00:00+00:00'
[2023-12-07T17:22:54.562+0000] {taskinstance.py:1937} ERROR - Task failed with exception
Traceback (most recent call last):
  File "/home/airflow/.local/lib/python3.8/site-packages/airflow/operators/python.py", line 192, in execute
    return_value = self.execute_callable()
  File "/home/airflow/.local/lib/python3.8/site-packages/airflow/operators/python.py", line 209, in execute_callable
    return self.python_callable(*self.op_args, **self.op_kwargs)
  File "/opt/airflow/dags/main.py", line 73, in main
    insert_data_to_db(products, db_params)
  File "/opt/airflow/dags/main.py", line 40, in insert_data_to_db
    with psycopg2.connect(**db_params) as conn:
  File "/home/airflow/.local/lib/python3.8/site-packages/psycopg2/__init__.py", line 122, in connect
    conn = _connect(dsn, connection_factory=connection_factory, **kwasync)
psycopg2.OperationalError: connection to server at "localhost" (127.0.0.1), port 5432 failed: Connection refused
	Is the server running on that host and accepting TCP/IP connections?
connection to server at "localhost" (::1), port 5432 failed: Cannot assign requested address
	Is the server running on that host and accepting TCP/IP connections?

[2023-12-07T17:22:54.572+0000] {taskinstance.py:1400} INFO - Marking task as FAILED. dag_id=my_scraping_dag, task_id=main_task, execution_date=20230324T000000, start_date=20231207T172253, end_date=20231207T172254
[2023-12-07T17:22:54.585+0000] {standard_task_runner.py:104} ERROR - Failed to execute job 2954 for task main_task (connection to server at "localhost" (127.0.0.1), port 5432 failed: Connection refused
	Is the server running on that host and accepting TCP/IP connections?
connection to server at "localhost" (::1), port 5432 failed: Cannot assign requested address
	Is the server running on that host and accepting TCP/IP connections?
; 9515)
[2023-12-07T17:22:54.626+0000] {local_task_job_runner.py:228} INFO - Task exited with return code 1
[2023-12-07T17:22:54.637+0000] {taskinstance.py:2778} INFO - 0 downstream tasks scheduled from follow-on schedule check
[2023-12-07T17:28:35.834+0000] {taskinstance.py:1159} INFO - Dependencies all met for dep_context=non-requeueable deps ti=<TaskInstance: my_scraping_dag.main_task scheduled__2023-03-24T00:00:00+00:00 [queued]>
[2023-12-07T17:28:35.839+0000] {taskinstance.py:1159} INFO - Dependencies all met for dep_context=requeueable deps ti=<TaskInstance: my_scraping_dag.main_task scheduled__2023-03-24T00:00:00+00:00 [queued]>
[2023-12-07T17:28:35.840+0000] {taskinstance.py:1361} INFO - Starting attempt 1 of 1
[2023-12-07T17:28:35.848+0000] {taskinstance.py:1382} INFO - Executing <Task(PythonOperator): main_task> on 2023-03-24 00:00:00+00:00
[2023-12-07T17:28:35.851+0000] {standard_task_runner.py:57} INFO - Started process 10345 to run task
[2023-12-07T17:28:35.854+0000] {standard_task_runner.py:84} INFO - Running: ['***', 'tasks', 'run', 'my_scraping_dag', 'main_task', 'scheduled__2023-03-24T00:00:00+00:00', '--job-id', '3296', '--raw', '--subdir', 'DAGS_FOLDER/main.py', '--cfg-path', '/tmp/tmpf25r9b3e']
[2023-12-07T17:28:35.855+0000] {standard_task_runner.py:85} INFO - Job 3296: Subtask main_task
[2023-12-07T17:28:35.887+0000] {task_command.py:416} INFO - Running <TaskInstance: my_scraping_dag.main_task scheduled__2023-03-24T00:00:00+00:00 [running]> on host 63b0c7e341c0
[2023-12-07T17:28:35.930+0000] {taskinstance.py:1662} INFO - Exporting env vars: AIRFLOW_CTX_DAG_OWNER='***' AIRFLOW_CTX_DAG_ID='my_scraping_dag' AIRFLOW_CTX_TASK_ID='main_task' AIRFLOW_CTX_EXECUTION_DATE='2023-03-24T00:00:00+00:00' AIRFLOW_CTX_TRY_NUMBER='1' AIRFLOW_CTX_DAG_RUN_ID='scheduled__2023-03-24T00:00:00+00:00'
[2023-12-07T17:28:36.681+0000] {taskinstance.py:1937} ERROR - Task failed with exception
Traceback (most recent call last):
  File "/home/airflow/.local/lib/python3.8/site-packages/airflow/operators/python.py", line 192, in execute
    return_value = self.execute_callable()
  File "/home/airflow/.local/lib/python3.8/site-packages/airflow/operators/python.py", line 209, in execute_callable
    return self.python_callable(*self.op_args, **self.op_kwargs)
  File "/opt/airflow/dags/main.py", line 73, in main
    insert_data_to_db(products, db_params)
  File "/opt/airflow/dags/main.py", line 40, in insert_data_to_db
    with psycopg2.connect(**db_params) as conn:
  File "/home/airflow/.local/lib/python3.8/site-packages/psycopg2/__init__.py", line 122, in connect
    conn = _connect(dsn, connection_factory=connection_factory, **kwasync)
psycopg2.OperationalError: connection to server at "localhost" (127.0.0.1), port 5432 failed: Connection refused
	Is the server running on that host and accepting TCP/IP connections?
connection to server at "localhost" (::1), port 5432 failed: Cannot assign requested address
	Is the server running on that host and accepting TCP/IP connections?

[2023-12-07T17:28:36.688+0000] {taskinstance.py:1400} INFO - Marking task as FAILED. dag_id=my_scraping_dag, task_id=main_task, execution_date=20230324T000000, start_date=20231207T172835, end_date=20231207T172836
[2023-12-07T17:28:36.699+0000] {standard_task_runner.py:104} ERROR - Failed to execute job 3296 for task main_task (connection to server at "localhost" (127.0.0.1), port 5432 failed: Connection refused
	Is the server running on that host and accepting TCP/IP connections?
connection to server at "localhost" (::1), port 5432 failed: Cannot assign requested address
	Is the server running on that host and accepting TCP/IP connections?
; 10345)
[2023-12-07T17:28:36.757+0000] {local_task_job_runner.py:228} INFO - Task exited with return code 1
[2023-12-07T17:28:36.768+0000] {taskinstance.py:2778} INFO - 0 downstream tasks scheduled from follow-on schedule check
[2023-12-09T07:34:29.698+0000] {taskinstance.py:1159} INFO - Dependencies all met for dep_context=non-requeueable deps ti=<TaskInstance: my_scraping_dag.main_task scheduled__2023-03-24T00:00:00+00:00 [queued]>
[2023-12-09T07:34:29.703+0000] {taskinstance.py:1159} INFO - Dependencies all met for dep_context=requeueable deps ti=<TaskInstance: my_scraping_dag.main_task scheduled__2023-03-24T00:00:00+00:00 [queued]>
[2023-12-09T07:34:29.704+0000] {taskinstance.py:1361} INFO - Starting attempt 1 of 1
[2023-12-09T07:34:29.711+0000] {taskinstance.py:1382} INFO - Executing <Task(PythonOperator): main_task> on 2023-03-24 00:00:00+00:00
[2023-12-09T07:34:29.714+0000] {standard_task_runner.py:57} INFO - Started process 758 to run task
[2023-12-09T07:34:29.716+0000] {standard_task_runner.py:84} INFO - Running: ['***', 'tasks', 'run', 'my_scraping_dag', 'main_task', 'scheduled__2023-03-24T00:00:00+00:00', '--job-id', '86', '--raw', '--subdir', 'DAGS_FOLDER/main.py', '--cfg-path', '/tmp/tmpsko6ct65']
[2023-12-09T07:34:29.718+0000] {standard_task_runner.py:85} INFO - Job 86: Subtask main_task
[2023-12-09T07:34:29.744+0000] {task_command.py:416} INFO - Running <TaskInstance: my_scraping_dag.main_task scheduled__2023-03-24T00:00:00+00:00 [running]> on host 36b5ef2505c9
[2023-12-09T07:34:29.789+0000] {taskinstance.py:1662} INFO - Exporting env vars: AIRFLOW_CTX_DAG_OWNER='***' AIRFLOW_CTX_DAG_ID='my_scraping_dag' AIRFLOW_CTX_TASK_ID='main_task' AIRFLOW_CTX_EXECUTION_DATE='2023-03-24T00:00:00+00:00' AIRFLOW_CTX_TRY_NUMBER='1' AIRFLOW_CTX_DAG_RUN_ID='scheduled__2023-03-24T00:00:00+00:00'
[2023-12-09T07:34:29.795+0000] {taskinstance.py:1937} ERROR - Task failed with exception
Traceback (most recent call last):
  File "/home/airflow/.local/lib/python3.8/site-packages/airflow/operators/python.py", line 192, in execute
    return_value = self.execute_callable()
  File "/home/airflow/.local/lib/python3.8/site-packages/airflow/operators/python.py", line 209, in execute_callable
    return self.python_callable(*self.op_args, **self.op_kwargs)
  File "/opt/airflow/dags/main.py", line 64, in main
    base_url = Variable.get('base_url')
  File "/home/airflow/.local/lib/python3.8/site-packages/airflow/models/variable.py", line 140, in get
    raise KeyError(f"Variable {key} does not exist")
KeyError: 'Variable base_url does not exist'
[2023-12-09T07:34:29.802+0000] {taskinstance.py:1400} INFO - Marking task as FAILED. dag_id=my_scraping_dag, task_id=main_task, execution_date=20230324T000000, start_date=20231209T073429, end_date=20231209T073429
[2023-12-09T07:34:29.807+0000] {standard_task_runner.py:104} ERROR - Failed to execute job 86 for task main_task ('Variable base_url does not exist'; 758)
[2023-12-09T07:34:29.849+0000] {local_task_job_runner.py:228} INFO - Task exited with return code 1
[2023-12-09T07:34:29.858+0000] {taskinstance.py:2778} INFO - 0 downstream tasks scheduled from follow-on schedule check
