[2023-12-07T16:34:10.018+0000] {taskinstance.py:1159} INFO - Dependencies all met for dep_context=non-requeueable deps ti=<TaskInstance: my_scraping_dag.main_task scheduled__2023-10-14T00:00:00+00:00 [queued]>
[2023-12-07T16:34:10.024+0000] {taskinstance.py:1159} INFO - Dependencies all met for dep_context=requeueable deps ti=<TaskInstance: my_scraping_dag.main_task scheduled__2023-10-14T00:00:00+00:00 [queued]>
[2023-12-07T16:34:10.024+0000] {taskinstance.py:1361} INFO - Starting attempt 1 of 1
[2023-12-07T16:34:10.048+0000] {taskinstance.py:1382} INFO - Executing <Task(PythonOperator): main_task> on 2023-10-14 00:00:00+00:00
[2023-12-07T16:34:10.052+0000] {standard_task_runner.py:57} INFO - Started process 4156 to run task
[2023-12-07T16:34:10.054+0000] {standard_task_runner.py:84} INFO - Running: ['***', 'tasks', 'run', 'my_scraping_dag', 'main_task', 'scheduled__2023-10-14T00:00:00+00:00', '--job-id', '875', '--raw', '--subdir', 'DAGS_FOLDER/main.py', '--cfg-path', '/tmp/tmp7jzfz11v']
[2023-12-07T16:34:10.056+0000] {standard_task_runner.py:85} INFO - Job 875: Subtask main_task
[2023-12-07T16:34:10.085+0000] {task_command.py:416} INFO - Running <TaskInstance: my_scraping_dag.main_task scheduled__2023-10-14T00:00:00+00:00 [running]> on host 63b0c7e341c0
[2023-12-07T16:34:10.129+0000] {taskinstance.py:1662} INFO - Exporting env vars: AIRFLOW_CTX_DAG_OWNER='***' AIRFLOW_CTX_DAG_ID='my_scraping_dag' AIRFLOW_CTX_TASK_ID='main_task' AIRFLOW_CTX_EXECUTION_DATE='2023-10-14T00:00:00+00:00' AIRFLOW_CTX_TRY_NUMBER='1' AIRFLOW_CTX_DAG_RUN_ID='scheduled__2023-10-14T00:00:00+00:00'
[2023-12-07T16:34:10.131+0000] {taskinstance.py:1937} ERROR - Task failed with exception
Traceback (most recent call last):
  File "/usr/local/lib/python3.8/configparser.py", line 846, in items
    d.update(self._sections[section])
KeyError: 'web'

During handling of the above exception, another exception occurred:

Traceback (most recent call last):
  File "/home/airflow/.local/lib/python3.8/site-packages/airflow/operators/python.py", line 192, in execute
    return_value = self.execute_callable()
  File "/home/airflow/.local/lib/python3.8/site-packages/airflow/operators/python.py", line 209, in execute_callable
    return self.python_callable(*self.op_args, **self.op_kwargs)
  File "/opt/airflow/dags/main.py", line 60, in main
    config = get_config('web')
  File "/opt/airflow/dags/main.py", line 22, in get_config
    return {key: value for key, value in parser.items(section)}
  File "/usr/local/lib/python3.8/configparser.py", line 849, in items
    raise NoSectionError(section)
configparser.NoSectionError: No section: 'web'
[2023-12-07T16:34:10.138+0000] {taskinstance.py:1400} INFO - Marking task as FAILED. dag_id=my_scraping_dag, task_id=main_task, execution_date=20231014T000000, start_date=20231207T163410, end_date=20231207T163410
[2023-12-07T16:34:10.147+0000] {standard_task_runner.py:104} ERROR - Failed to execute job 875 for task main_task (No section: 'web'; 4156)
[2023-12-07T16:34:10.186+0000] {local_task_job_runner.py:228} INFO - Task exited with return code 1
[2023-12-07T16:34:10.200+0000] {taskinstance.py:2778} INFO - 0 downstream tasks scheduled from follow-on schedule check
[2023-12-07T16:42:50.669+0000] {taskinstance.py:1159} INFO - Dependencies all met for dep_context=non-requeueable deps ti=<TaskInstance: my_scraping_dag.main_task scheduled__2023-10-14T00:00:00+00:00 [queued]>
[2023-12-07T16:42:50.673+0000] {taskinstance.py:1159} INFO - Dependencies all met for dep_context=requeueable deps ti=<TaskInstance: my_scraping_dag.main_task scheduled__2023-10-14T00:00:00+00:00 [queued]>
[2023-12-07T16:42:50.674+0000] {taskinstance.py:1361} INFO - Starting attempt 1 of 1
[2023-12-07T16:42:50.680+0000] {taskinstance.py:1382} INFO - Executing <Task(PythonOperator): main_task> on 2023-10-14 00:00:00+00:00
[2023-12-07T16:42:50.683+0000] {standard_task_runner.py:57} INFO - Started process 5048 to run task
[2023-12-07T16:42:50.685+0000] {standard_task_runner.py:84} INFO - Running: ['***', 'tasks', 'run', 'my_scraping_dag', 'main_task', 'scheduled__2023-10-14T00:00:00+00:00', '--job-id', '1220', '--raw', '--subdir', 'DAGS_FOLDER/main.py', '--cfg-path', '/tmp/tmpmzlx002j']
[2023-12-07T16:42:50.687+0000] {standard_task_runner.py:85} INFO - Job 1220: Subtask main_task
[2023-12-07T16:42:50.712+0000] {task_command.py:416} INFO - Running <TaskInstance: my_scraping_dag.main_task scheduled__2023-10-14T00:00:00+00:00 [running]> on host 63b0c7e341c0
[2023-12-07T16:42:50.746+0000] {taskinstance.py:1662} INFO - Exporting env vars: AIRFLOW_CTX_DAG_OWNER='***' AIRFLOW_CTX_DAG_ID='my_scraping_dag' AIRFLOW_CTX_TASK_ID='main_task' AIRFLOW_CTX_EXECUTION_DATE='2023-10-14T00:00:00+00:00' AIRFLOW_CTX_TRY_NUMBER='1' AIRFLOW_CTX_DAG_RUN_ID='scheduled__2023-10-14T00:00:00+00:00'
[2023-12-07T16:42:50.747+0000] {taskinstance.py:1937} ERROR - Task failed with exception
Traceback (most recent call last):
  File "/usr/local/lib/python3.8/configparser.py", line 846, in items
    d.update(self._sections[section])
KeyError: 'web'

During handling of the above exception, another exception occurred:

Traceback (most recent call last):
  File "/home/airflow/.local/lib/python3.8/site-packages/airflow/operators/python.py", line 192, in execute
    return_value = self.execute_callable()
  File "/home/airflow/.local/lib/python3.8/site-packages/airflow/operators/python.py", line 209, in execute_callable
    return self.python_callable(*self.op_args, **self.op_kwargs)
  File "/opt/airflow/dags/main.py", line 60, in main
    config = get_config('web')
  File "/opt/airflow/dags/main.py", line 22, in get_config
    return {key: value for key, value in parser.items(section)}
  File "/usr/local/lib/python3.8/configparser.py", line 849, in items
    raise NoSectionError(section)
configparser.NoSectionError: No section: 'web'
[2023-12-07T16:42:50.751+0000] {taskinstance.py:1400} INFO - Marking task as FAILED. dag_id=my_scraping_dag, task_id=main_task, execution_date=20231014T000000, start_date=20231207T164250, end_date=20231207T164250
[2023-12-07T16:42:50.756+0000] {standard_task_runner.py:104} ERROR - Failed to execute job 1220 for task main_task (No section: 'web'; 5048)
[2023-12-07T16:42:50.778+0000] {local_task_job_runner.py:228} INFO - Task exited with return code 1
[2023-12-07T16:42:50.795+0000] {taskinstance.py:2778} INFO - 0 downstream tasks scheduled from follow-on schedule check
[2023-12-07T17:01:35.904+0000] {taskinstance.py:1159} INFO - Dependencies all met for dep_context=non-requeueable deps ti=<TaskInstance: my_scraping_dag.main_task scheduled__2023-10-14T00:00:00+00:00 [queued]>
[2023-12-07T17:01:35.908+0000] {taskinstance.py:1159} INFO - Dependencies all met for dep_context=requeueable deps ti=<TaskInstance: my_scraping_dag.main_task scheduled__2023-10-14T00:00:00+00:00 [queued]>
[2023-12-07T17:01:35.909+0000] {taskinstance.py:1361} INFO - Starting attempt 1 of 1
[2023-12-07T17:01:35.927+0000] {taskinstance.py:1382} INFO - Executing <Task(PythonOperator): main_task> on 2023-10-14 00:00:00+00:00
[2023-12-07T17:01:35.929+0000] {standard_task_runner.py:57} INFO - Started process 6533 to run task
[2023-12-07T17:01:35.932+0000] {standard_task_runner.py:84} INFO - Running: ['***', 'tasks', 'run', 'my_scraping_dag', 'main_task', 'scheduled__2023-10-14T00:00:00+00:00', '--job-id', '1730', '--raw', '--subdir', 'DAGS_FOLDER/main.py', '--cfg-path', '/tmp/tmpryf4kz1d']
[2023-12-07T17:01:35.934+0000] {standard_task_runner.py:85} INFO - Job 1730: Subtask main_task
[2023-12-07T17:01:35.970+0000] {task_command.py:416} INFO - Running <TaskInstance: my_scraping_dag.main_task scheduled__2023-10-14T00:00:00+00:00 [running]> on host 63b0c7e341c0
[2023-12-07T17:01:36.021+0000] {taskinstance.py:1662} INFO - Exporting env vars: AIRFLOW_CTX_DAG_OWNER='***' AIRFLOW_CTX_DAG_ID='my_scraping_dag' AIRFLOW_CTX_TASK_ID='main_task' AIRFLOW_CTX_EXECUTION_DATE='2023-10-14T00:00:00+00:00' AIRFLOW_CTX_TRY_NUMBER='1' AIRFLOW_CTX_DAG_RUN_ID='scheduled__2023-10-14T00:00:00+00:00'
[2023-12-07T17:01:36.061+0000] {logging_mixin.py:154} INFO - base_url: https://tuncbotanik.com
[2023-12-07T17:01:36.063+0000] {python.py:194} INFO - Done. Returned value was: ('https://tuncbotanik.com', {'User-Agent': 'Mozilla/5.0 (Macintosh; Intel Mac OS X 10_15_7) AppleWebKit/537.36 (KHTML, like Gecko) Chrome/119.0.0.0 Safari/537.36', 'Accept-Language': 'tr-TR,tr;q=0.9,en-US;q=0.8,en;q=0.7'}, {'dbname': 'plant', 'user': 'aozgokme', 'password': '***', 'host': 'localhost', 'port': '5432'})
[2023-12-07T17:01:36.082+0000] {taskinstance.py:1400} INFO - Marking task as SUCCESS. dag_id=my_scraping_dag, task_id=main_task, execution_date=20231014T000000, start_date=20231207T170135, end_date=20231207T170136
[2023-12-07T17:01:36.108+0000] {local_task_job_runner.py:228} INFO - Task exited with return code 0
[2023-12-07T17:01:36.185+0000] {taskinstance.py:2778} INFO - 0 downstream tasks scheduled from follow-on schedule check
[2023-12-07T17:04:54.246+0000] {taskinstance.py:1159} INFO - Dependencies all met for dep_context=non-requeueable deps ti=<TaskInstance: my_scraping_dag.main_task scheduled__2023-10-14T00:00:00+00:00 [queued]>
[2023-12-07T17:04:54.255+0000] {taskinstance.py:1159} INFO - Dependencies all met for dep_context=requeueable deps ti=<TaskInstance: my_scraping_dag.main_task scheduled__2023-10-14T00:00:00+00:00 [queued]>
[2023-12-07T17:04:54.256+0000] {taskinstance.py:1361} INFO - Starting attempt 1 of 1
[2023-12-07T17:04:54.269+0000] {taskinstance.py:1382} INFO - Executing <Task(PythonOperator): main_task> on 2023-10-14 00:00:00+00:00
[2023-12-07T17:04:54.275+0000] {standard_task_runner.py:57} INFO - Started process 7975 to run task
[2023-12-07T17:04:54.279+0000] {standard_task_runner.py:84} INFO - Running: ['***', 'tasks', 'run', 'my_scraping_dag', 'main_task', 'scheduled__2023-10-14T00:00:00+00:00', '--job-id', '2412', '--raw', '--subdir', 'DAGS_FOLDER/main.py', '--cfg-path', '/tmp/tmpejue15qr']
[2023-12-07T17:04:54.282+0000] {standard_task_runner.py:85} INFO - Job 2412: Subtask main_task
[2023-12-07T17:04:54.316+0000] {task_command.py:416} INFO - Running <TaskInstance: my_scraping_dag.main_task scheduled__2023-10-14T00:00:00+00:00 [running]> on host 63b0c7e341c0
[2023-12-07T17:04:54.355+0000] {taskinstance.py:1662} INFO - Exporting env vars: AIRFLOW_CTX_DAG_OWNER='***' AIRFLOW_CTX_DAG_ID='my_scraping_dag' AIRFLOW_CTX_TASK_ID='main_task' AIRFLOW_CTX_EXECUTION_DATE='2023-10-14T00:00:00+00:00' AIRFLOW_CTX_TRY_NUMBER='1' AIRFLOW_CTX_DAG_RUN_ID='scheduled__2023-10-14T00:00:00+00:00'
[2023-12-07T17:04:54.376+0000] {logging_mixin.py:154} INFO - base_url: https://tuncbotanik.com
[2023-12-07T17:04:54.377+0000] {python.py:194} INFO - Done. Returned value was: ('https://tuncbotanik.com', {'User-Agent': 'Mozilla/5.0 (Macintosh; Intel Mac OS X 10_15_7) AppleWebKit/537.36 (KHTML, like Gecko) Chrome/119.0.0.0 Safari/537.36', 'Accept-Language': 'tr-TR,tr;q=0.9,en-US;q=0.8,en;q=0.7'}, {'dbname': 'plant', 'user': 'aozgokme', 'password': '***', 'host': 'localhost', 'port': '5432'})
[2023-12-07T17:04:54.388+0000] {taskinstance.py:1400} INFO - Marking task as SUCCESS. dag_id=my_scraping_dag, task_id=main_task, execution_date=20231014T000000, start_date=20231207T170454, end_date=20231207T170454
[2023-12-07T17:04:54.451+0000] {local_task_job_runner.py:228} INFO - Task exited with return code 0
[2023-12-07T17:04:54.484+0000] {taskinstance.py:2778} INFO - 0 downstream tasks scheduled from follow-on schedule check
[2023-12-07T17:19:18.042+0000] {taskinstance.py:1159} INFO - Dependencies all met for dep_context=non-requeueable deps ti=<TaskInstance: my_scraping_dag.main_task scheduled__2023-10-14T00:00:00+00:00 [queued]>
[2023-12-07T17:19:18.049+0000] {taskinstance.py:1159} INFO - Dependencies all met for dep_context=requeueable deps ti=<TaskInstance: my_scraping_dag.main_task scheduled__2023-10-14T00:00:00+00:00 [queued]>
[2023-12-07T17:19:18.049+0000] {taskinstance.py:1361} INFO - Starting attempt 1 of 1
[2023-12-07T17:19:18.057+0000] {taskinstance.py:1382} INFO - Executing <Task(PythonOperator): main_task> on 2023-10-14 00:00:00+00:00
[2023-12-07T17:19:18.060+0000] {standard_task_runner.py:57} INFO - Started process 9133 to run task
[2023-12-07T17:19:18.062+0000] {standard_task_runner.py:84} INFO - Running: ['***', 'tasks', 'run', 'my_scraping_dag', 'main_task', 'scheduled__2023-10-14T00:00:00+00:00', '--job-id', '2816', '--raw', '--subdir', 'DAGS_FOLDER/main.py', '--cfg-path', '/tmp/tmpb2zcpokc']
[2023-12-07T17:19:18.065+0000] {standard_task_runner.py:85} INFO - Job 2816: Subtask main_task
[2023-12-07T17:19:18.120+0000] {task_command.py:416} INFO - Running <TaskInstance: my_scraping_dag.main_task scheduled__2023-10-14T00:00:00+00:00 [running]> on host 63b0c7e341c0
[2023-12-07T17:19:18.164+0000] {taskinstance.py:1662} INFO - Exporting env vars: AIRFLOW_CTX_DAG_OWNER='***' AIRFLOW_CTX_DAG_ID='my_scraping_dag' AIRFLOW_CTX_TASK_ID='main_task' AIRFLOW_CTX_EXECUTION_DATE='2023-10-14T00:00:00+00:00' AIRFLOW_CTX_TRY_NUMBER='1' AIRFLOW_CTX_DAG_RUN_ID='scheduled__2023-10-14T00:00:00+00:00'
[2023-12-07T17:19:19.000+0000] {taskinstance.py:1937} ERROR - Task failed with exception
Traceback (most recent call last):
  File "/home/airflow/.local/lib/python3.8/site-packages/airflow/operators/python.py", line 192, in execute
    return_value = self.execute_callable()
  File "/home/airflow/.local/lib/python3.8/site-packages/airflow/operators/python.py", line 209, in execute_callable
    return self.python_callable(*self.op_args, **self.op_kwargs)
  File "/opt/airflow/dags/main.py", line 80, in main
    insert_data_to_db(products, db_params)
  File "/opt/airflow/dags/main.py", line 43, in insert_data_to_db
    with psycopg2.connect(**db_params) as conn:
  File "/home/airflow/.local/lib/python3.8/site-packages/psycopg2/__init__.py", line 122, in connect
    conn = _connect(dsn, connection_factory=connection_factory, **kwasync)
psycopg2.OperationalError: connection to server at "localhost" (127.0.0.1), port 5432 failed: Connection refused
	Is the server running on that host and accepting TCP/IP connections?
connection to server at "localhost" (::1), port 5432 failed: Cannot assign requested address
	Is the server running on that host and accepting TCP/IP connections?

[2023-12-07T17:19:19.020+0000] {taskinstance.py:1400} INFO - Marking task as FAILED. dag_id=my_scraping_dag, task_id=main_task, execution_date=20231014T000000, start_date=20231207T171918, end_date=20231207T171919
[2023-12-07T17:19:19.027+0000] {standard_task_runner.py:104} ERROR - Failed to execute job 2816 for task main_task (connection to server at "localhost" (127.0.0.1), port 5432 failed: Connection refused
	Is the server running on that host and accepting TCP/IP connections?
connection to server at "localhost" (::1), port 5432 failed: Cannot assign requested address
	Is the server running on that host and accepting TCP/IP connections?
; 9133)
[2023-12-07T17:19:19.049+0000] {local_task_job_runner.py:228} INFO - Task exited with return code 1
[2023-12-07T17:19:19.060+0000] {taskinstance.py:2778} INFO - 0 downstream tasks scheduled from follow-on schedule check
[2023-12-07T17:23:35.938+0000] {taskinstance.py:1159} INFO - Dependencies all met for dep_context=non-requeueable deps ti=<TaskInstance: my_scraping_dag.main_task scheduled__2023-10-14T00:00:00+00:00 [queued]>
[2023-12-07T17:23:35.952+0000] {taskinstance.py:1159} INFO - Dependencies all met for dep_context=requeueable deps ti=<TaskInstance: my_scraping_dag.main_task scheduled__2023-10-14T00:00:00+00:00 [queued]>
[2023-12-07T17:23:35.952+0000] {taskinstance.py:1361} INFO - Starting attempt 1 of 1
[2023-12-07T17:23:35.967+0000] {taskinstance.py:1382} INFO - Executing <Task(PythonOperator): main_task> on 2023-10-14 00:00:00+00:00
[2023-12-07T17:23:35.974+0000] {standard_task_runner.py:57} INFO - Started process 9932 to run task
[2023-12-07T17:23:35.980+0000] {standard_task_runner.py:84} INFO - Running: ['***', 'tasks', 'run', 'my_scraping_dag', 'main_task', 'scheduled__2023-10-14T00:00:00+00:00', '--job-id', '3158', '--raw', '--subdir', 'DAGS_FOLDER/main.py', '--cfg-path', '/tmp/tmp31mq13n0']
[2023-12-07T17:23:35.998+0000] {standard_task_runner.py:85} INFO - Job 3158: Subtask main_task
[2023-12-07T17:23:36.099+0000] {task_command.py:416} INFO - Running <TaskInstance: my_scraping_dag.main_task scheduled__2023-10-14T00:00:00+00:00 [running]> on host 63b0c7e341c0
[2023-12-07T17:23:36.175+0000] {taskinstance.py:1662} INFO - Exporting env vars: AIRFLOW_CTX_DAG_OWNER='***' AIRFLOW_CTX_DAG_ID='my_scraping_dag' AIRFLOW_CTX_TASK_ID='main_task' AIRFLOW_CTX_EXECUTION_DATE='2023-10-14T00:00:00+00:00' AIRFLOW_CTX_TRY_NUMBER='1' AIRFLOW_CTX_DAG_RUN_ID='scheduled__2023-10-14T00:00:00+00:00'
[2023-12-07T17:23:36.891+0000] {taskinstance.py:1937} ERROR - Task failed with exception
Traceback (most recent call last):
  File "/home/airflow/.local/lib/python3.8/site-packages/airflow/operators/python.py", line 192, in execute
    return_value = self.execute_callable()
  File "/home/airflow/.local/lib/python3.8/site-packages/airflow/operators/python.py", line 209, in execute_callable
    return self.python_callable(*self.op_args, **self.op_kwargs)
  File "/opt/airflow/dags/main.py", line 73, in main
    insert_data_to_db(products, db_params)
  File "/opt/airflow/dags/main.py", line 40, in insert_data_to_db
    with psycopg2.connect(**db_params) as conn:
  File "/home/airflow/.local/lib/python3.8/site-packages/psycopg2/__init__.py", line 122, in connect
    conn = _connect(dsn, connection_factory=connection_factory, **kwasync)
psycopg2.OperationalError: connection to server at "localhost" (127.0.0.1), port 5432 failed: Connection refused
	Is the server running on that host and accepting TCP/IP connections?
connection to server at "localhost" (::1), port 5432 failed: Cannot assign requested address
	Is the server running on that host and accepting TCP/IP connections?

[2023-12-07T17:23:36.895+0000] {taskinstance.py:1400} INFO - Marking task as FAILED. dag_id=my_scraping_dag, task_id=main_task, execution_date=20231014T000000, start_date=20231207T172335, end_date=20231207T172336
[2023-12-07T17:23:36.902+0000] {standard_task_runner.py:104} ERROR - Failed to execute job 3158 for task main_task (connection to server at "localhost" (127.0.0.1), port 5432 failed: Connection refused
	Is the server running on that host and accepting TCP/IP connections?
connection to server at "localhost" (::1), port 5432 failed: Cannot assign requested address
	Is the server running on that host and accepting TCP/IP connections?
; 9932)
[2023-12-07T17:23:36.924+0000] {local_task_job_runner.py:228} INFO - Task exited with return code 1
[2023-12-07T17:23:36.960+0000] {taskinstance.py:2778} INFO - 0 downstream tasks scheduled from follow-on schedule check
[2023-12-07T17:29:13.386+0000] {taskinstance.py:1159} INFO - Dependencies all met for dep_context=non-requeueable deps ti=<TaskInstance: my_scraping_dag.main_task scheduled__2023-10-14T00:00:00+00:00 [queued]>
[2023-12-07T17:29:13.393+0000] {taskinstance.py:1159} INFO - Dependencies all met for dep_context=requeueable deps ti=<TaskInstance: my_scraping_dag.main_task scheduled__2023-10-14T00:00:00+00:00 [queued]>
[2023-12-07T17:29:13.393+0000] {taskinstance.py:1361} INFO - Starting attempt 1 of 1
[2023-12-07T17:29:13.403+0000] {taskinstance.py:1382} INFO - Executing <Task(PythonOperator): main_task> on 2023-10-14 00:00:00+00:00
[2023-12-07T17:29:13.406+0000] {standard_task_runner.py:57} INFO - Started process 10768 to run task
[2023-12-07T17:29:13.415+0000] {standard_task_runner.py:84} INFO - Running: ['***', 'tasks', 'run', 'my_scraping_dag', 'main_task', 'scheduled__2023-10-14T00:00:00+00:00', '--job-id', '3500', '--raw', '--subdir', 'DAGS_FOLDER/main.py', '--cfg-path', '/tmp/tmpvpn4ax_r']
[2023-12-07T17:29:13.418+0000] {standard_task_runner.py:85} INFO - Job 3500: Subtask main_task
[2023-12-07T17:29:13.483+0000] {task_command.py:416} INFO - Running <TaskInstance: my_scraping_dag.main_task scheduled__2023-10-14T00:00:00+00:00 [running]> on host 63b0c7e341c0
[2023-12-07T17:29:13.536+0000] {taskinstance.py:1662} INFO - Exporting env vars: AIRFLOW_CTX_DAG_OWNER='***' AIRFLOW_CTX_DAG_ID='my_scraping_dag' AIRFLOW_CTX_TASK_ID='main_task' AIRFLOW_CTX_EXECUTION_DATE='2023-10-14T00:00:00+00:00' AIRFLOW_CTX_TRY_NUMBER='1' AIRFLOW_CTX_DAG_RUN_ID='scheduled__2023-10-14T00:00:00+00:00'
[2023-12-07T17:29:14.295+0000] {taskinstance.py:1937} ERROR - Task failed with exception
Traceback (most recent call last):
  File "/home/airflow/.local/lib/python3.8/site-packages/airflow/operators/python.py", line 192, in execute
    return_value = self.execute_callable()
  File "/home/airflow/.local/lib/python3.8/site-packages/airflow/operators/python.py", line 209, in execute_callable
    return self.python_callable(*self.op_args, **self.op_kwargs)
  File "/opt/airflow/dags/main.py", line 73, in main
    insert_data_to_db(products, db_params)
  File "/opt/airflow/dags/main.py", line 40, in insert_data_to_db
    with psycopg2.connect(**db_params) as conn:
  File "/home/airflow/.local/lib/python3.8/site-packages/psycopg2/__init__.py", line 122, in connect
    conn = _connect(dsn, connection_factory=connection_factory, **kwasync)
psycopg2.OperationalError: connection to server at "localhost" (127.0.0.1), port 5432 failed: Connection refused
	Is the server running on that host and accepting TCP/IP connections?
connection to server at "localhost" (::1), port 5432 failed: Cannot assign requested address
	Is the server running on that host and accepting TCP/IP connections?

[2023-12-07T17:29:14.299+0000] {taskinstance.py:1400} INFO - Marking task as FAILED. dag_id=my_scraping_dag, task_id=main_task, execution_date=20231014T000000, start_date=20231207T172913, end_date=20231207T172914
[2023-12-07T17:29:14.305+0000] {standard_task_runner.py:104} ERROR - Failed to execute job 3500 for task main_task (connection to server at "localhost" (127.0.0.1), port 5432 failed: Connection refused
	Is the server running on that host and accepting TCP/IP connections?
connection to server at "localhost" (::1), port 5432 failed: Cannot assign requested address
	Is the server running on that host and accepting TCP/IP connections?
; 10768)
[2023-12-07T17:29:14.316+0000] {local_task_job_runner.py:228} INFO - Task exited with return code 1
[2023-12-07T17:29:14.325+0000] {taskinstance.py:2778} INFO - 0 downstream tasks scheduled from follow-on schedule check
[2023-12-09T07:35:29.234+0000] {taskinstance.py:1159} INFO - Dependencies all met for dep_context=non-requeueable deps ti=<TaskInstance: my_scraping_dag.main_task scheduled__2023-10-14T00:00:00+00:00 [queued]>
[2023-12-09T07:35:29.239+0000] {taskinstance.py:1159} INFO - Dependencies all met for dep_context=requeueable deps ti=<TaskInstance: my_scraping_dag.main_task scheduled__2023-10-14T00:00:00+00:00 [queued]>
[2023-12-09T07:35:29.239+0000] {taskinstance.py:1361} INFO - Starting attempt 1 of 1
[2023-12-09T07:35:29.246+0000] {taskinstance.py:1382} INFO - Executing <Task(PythonOperator): main_task> on 2023-10-14 00:00:00+00:00
[2023-12-09T07:35:29.248+0000] {standard_task_runner.py:57} INFO - Started process 1187 to run task
[2023-12-09T07:35:29.250+0000] {standard_task_runner.py:84} INFO - Running: ['***', 'tasks', 'run', 'my_scraping_dag', 'main_task', 'scheduled__2023-10-14T00:00:00+00:00', '--job-id', '290', '--raw', '--subdir', 'DAGS_FOLDER/main.py', '--cfg-path', '/tmp/tmpo2ngcjcb']
[2023-12-09T07:35:29.252+0000] {standard_task_runner.py:85} INFO - Job 290: Subtask main_task
[2023-12-09T07:35:29.274+0000] {task_command.py:416} INFO - Running <TaskInstance: my_scraping_dag.main_task scheduled__2023-10-14T00:00:00+00:00 [running]> on host 36b5ef2505c9
[2023-12-09T07:35:29.305+0000] {taskinstance.py:1662} INFO - Exporting env vars: AIRFLOW_CTX_DAG_OWNER='***' AIRFLOW_CTX_DAG_ID='my_scraping_dag' AIRFLOW_CTX_TASK_ID='main_task' AIRFLOW_CTX_EXECUTION_DATE='2023-10-14T00:00:00+00:00' AIRFLOW_CTX_TRY_NUMBER='1' AIRFLOW_CTX_DAG_RUN_ID='scheduled__2023-10-14T00:00:00+00:00'
[2023-12-09T07:35:29.311+0000] {taskinstance.py:1937} ERROR - Task failed with exception
Traceback (most recent call last):
  File "/home/airflow/.local/lib/python3.8/site-packages/airflow/operators/python.py", line 192, in execute
    return_value = self.execute_callable()
  File "/home/airflow/.local/lib/python3.8/site-packages/airflow/operators/python.py", line 209, in execute_callable
    return self.python_callable(*self.op_args, **self.op_kwargs)
  File "/opt/airflow/dags/main.py", line 66, in main
    'User-Agent': Variable.get('user_agent'),
  File "/home/airflow/.local/lib/python3.8/site-packages/airflow/models/variable.py", line 140, in get
    raise KeyError(f"Variable {key} does not exist")
KeyError: 'Variable user_agent does not exist'
[2023-12-09T07:35:29.315+0000] {taskinstance.py:1400} INFO - Marking task as FAILED. dag_id=my_scraping_dag, task_id=main_task, execution_date=20231014T000000, start_date=20231209T073529, end_date=20231209T073529
[2023-12-09T07:35:29.320+0000] {standard_task_runner.py:104} ERROR - Failed to execute job 290 for task main_task ('Variable user_agent does not exist'; 1187)
[2023-12-09T07:35:29.345+0000] {local_task_job_runner.py:228} INFO - Task exited with return code 1
[2023-12-09T07:35:29.354+0000] {taskinstance.py:2778} INFO - 0 downstream tasks scheduled from follow-on schedule check
