[2023-12-07T16:34:15.002+0000] {taskinstance.py:1159} INFO - Dependencies all met for dep_context=non-requeueable deps ti=<TaskInstance: my_scraping_dag.main_task scheduled__2023-10-24T00:00:00+00:00 [queued]>
[2023-12-07T16:34:15.006+0000] {taskinstance.py:1159} INFO - Dependencies all met for dep_context=requeueable deps ti=<TaskInstance: my_scraping_dag.main_task scheduled__2023-10-24T00:00:00+00:00 [queued]>
[2023-12-07T16:34:15.006+0000] {taskinstance.py:1361} INFO - Starting attempt 1 of 1
[2023-12-07T16:34:15.012+0000] {taskinstance.py:1382} INFO - Executing <Task(PythonOperator): main_task> on 2023-10-24 00:00:00+00:00
[2023-12-07T16:34:15.015+0000] {standard_task_runner.py:57} INFO - Started process 4176 to run task
[2023-12-07T16:34:15.017+0000] {standard_task_runner.py:84} INFO - Running: ['***', 'tasks', 'run', 'my_scraping_dag', 'main_task', 'scheduled__2023-10-24T00:00:00+00:00', '--job-id', '885', '--raw', '--subdir', 'DAGS_FOLDER/main.py', '--cfg-path', '/tmp/tmpmlvmmnj8']
[2023-12-07T16:34:15.019+0000] {standard_task_runner.py:85} INFO - Job 885: Subtask main_task
[2023-12-07T16:34:15.045+0000] {task_command.py:416} INFO - Running <TaskInstance: my_scraping_dag.main_task scheduled__2023-10-24T00:00:00+00:00 [running]> on host 63b0c7e341c0
[2023-12-07T16:34:15.085+0000] {taskinstance.py:1662} INFO - Exporting env vars: AIRFLOW_CTX_DAG_OWNER='***' AIRFLOW_CTX_DAG_ID='my_scraping_dag' AIRFLOW_CTX_TASK_ID='main_task' AIRFLOW_CTX_EXECUTION_DATE='2023-10-24T00:00:00+00:00' AIRFLOW_CTX_TRY_NUMBER='1' AIRFLOW_CTX_DAG_RUN_ID='scheduled__2023-10-24T00:00:00+00:00'
[2023-12-07T16:34:15.087+0000] {taskinstance.py:1937} ERROR - Task failed with exception
Traceback (most recent call last):
  File "/usr/local/lib/python3.8/configparser.py", line 846, in items
    d.update(self._sections[section])
KeyError: 'web'

During handling of the above exception, another exception occurred:

Traceback (most recent call last):
  File "/home/airflow/.local/lib/python3.8/site-packages/airflow/operators/python.py", line 192, in execute
    return_value = self.execute_callable()
  File "/home/airflow/.local/lib/python3.8/site-packages/airflow/operators/python.py", line 209, in execute_callable
    return self.python_callable(*self.op_args, **self.op_kwargs)
  File "/opt/airflow/dags/main.py", line 60, in main
    config = get_config('web')
  File "/opt/airflow/dags/main.py", line 22, in get_config
    return {key: value for key, value in parser.items(section)}
  File "/usr/local/lib/python3.8/configparser.py", line 849, in items
    raise NoSectionError(section)
configparser.NoSectionError: No section: 'web'
[2023-12-07T16:34:15.093+0000] {taskinstance.py:1400} INFO - Marking task as FAILED. dag_id=my_scraping_dag, task_id=main_task, execution_date=20231024T000000, start_date=20231207T163415, end_date=20231207T163415
[2023-12-07T16:34:15.098+0000] {standard_task_runner.py:104} ERROR - Failed to execute job 885 for task main_task (No section: 'web'; 4176)
[2023-12-07T16:34:15.109+0000] {local_task_job_runner.py:228} INFO - Task exited with return code 1
[2023-12-07T16:34:15.123+0000] {taskinstance.py:2778} INFO - 0 downstream tasks scheduled from follow-on schedule check
[2023-12-07T16:42:54.865+0000] {taskinstance.py:1159} INFO - Dependencies all met for dep_context=non-requeueable deps ti=<TaskInstance: my_scraping_dag.main_task scheduled__2023-10-24T00:00:00+00:00 [queued]>
[2023-12-07T16:42:54.871+0000] {taskinstance.py:1159} INFO - Dependencies all met for dep_context=requeueable deps ti=<TaskInstance: my_scraping_dag.main_task scheduled__2023-10-24T00:00:00+00:00 [queued]>
[2023-12-07T16:42:54.871+0000] {taskinstance.py:1361} INFO - Starting attempt 1 of 1
[2023-12-07T16:42:54.878+0000] {taskinstance.py:1382} INFO - Executing <Task(PythonOperator): main_task> on 2023-10-24 00:00:00+00:00
[2023-12-07T16:42:54.880+0000] {standard_task_runner.py:57} INFO - Started process 5074 to run task
[2023-12-07T16:42:54.882+0000] {standard_task_runner.py:84} INFO - Running: ['***', 'tasks', 'run', 'my_scraping_dag', 'main_task', 'scheduled__2023-10-24T00:00:00+00:00', '--job-id', '1230', '--raw', '--subdir', 'DAGS_FOLDER/main.py', '--cfg-path', '/tmp/tmp4_s9lyv4']
[2023-12-07T16:42:54.884+0000] {standard_task_runner.py:85} INFO - Job 1230: Subtask main_task
[2023-12-07T16:42:54.907+0000] {task_command.py:416} INFO - Running <TaskInstance: my_scraping_dag.main_task scheduled__2023-10-24T00:00:00+00:00 [running]> on host 63b0c7e341c0
[2023-12-07T16:42:54.939+0000] {taskinstance.py:1662} INFO - Exporting env vars: AIRFLOW_CTX_DAG_OWNER='***' AIRFLOW_CTX_DAG_ID='my_scraping_dag' AIRFLOW_CTX_TASK_ID='main_task' AIRFLOW_CTX_EXECUTION_DATE='2023-10-24T00:00:00+00:00' AIRFLOW_CTX_TRY_NUMBER='1' AIRFLOW_CTX_DAG_RUN_ID='scheduled__2023-10-24T00:00:00+00:00'
[2023-12-07T16:42:54.940+0000] {taskinstance.py:1937} ERROR - Task failed with exception
Traceback (most recent call last):
  File "/usr/local/lib/python3.8/configparser.py", line 846, in items
    d.update(self._sections[section])
KeyError: 'web'

During handling of the above exception, another exception occurred:

Traceback (most recent call last):
  File "/home/airflow/.local/lib/python3.8/site-packages/airflow/operators/python.py", line 192, in execute
    return_value = self.execute_callable()
  File "/home/airflow/.local/lib/python3.8/site-packages/airflow/operators/python.py", line 209, in execute_callable
    return self.python_callable(*self.op_args, **self.op_kwargs)
  File "/opt/airflow/dags/main.py", line 60, in main
    config = get_config('web')
  File "/opt/airflow/dags/main.py", line 22, in get_config
    return {key: value for key, value in parser.items(section)}
  File "/usr/local/lib/python3.8/configparser.py", line 849, in items
    raise NoSectionError(section)
configparser.NoSectionError: No section: 'web'
[2023-12-07T16:42:54.944+0000] {taskinstance.py:1400} INFO - Marking task as FAILED. dag_id=my_scraping_dag, task_id=main_task, execution_date=20231024T000000, start_date=20231207T164254, end_date=20231207T164254
[2023-12-07T16:42:54.949+0000] {standard_task_runner.py:104} ERROR - Failed to execute job 1230 for task main_task (No section: 'web'; 5074)
[2023-12-07T16:42:54.975+0000] {local_task_job_runner.py:228} INFO - Task exited with return code 1
[2023-12-07T16:42:54.987+0000] {taskinstance.py:2778} INFO - 0 downstream tasks scheduled from follow-on schedule check
[2023-12-07T17:01:36.738+0000] {taskinstance.py:1159} INFO - Dependencies all met for dep_context=non-requeueable deps ti=<TaskInstance: my_scraping_dag.main_task scheduled__2023-10-24T00:00:00+00:00 [queued]>
[2023-12-07T17:01:36.744+0000] {taskinstance.py:1159} INFO - Dependencies all met for dep_context=requeueable deps ti=<TaskInstance: my_scraping_dag.main_task scheduled__2023-10-24T00:00:00+00:00 [queued]>
[2023-12-07T17:01:36.744+0000] {taskinstance.py:1361} INFO - Starting attempt 1 of 1
[2023-12-07T17:01:36.760+0000] {taskinstance.py:1382} INFO - Executing <Task(PythonOperator): main_task> on 2023-10-24 00:00:00+00:00
[2023-12-07T17:01:36.764+0000] {standard_task_runner.py:57} INFO - Started process 6570 to run task
[2023-12-07T17:01:36.769+0000] {standard_task_runner.py:84} INFO - Running: ['***', 'tasks', 'run', 'my_scraping_dag', 'main_task', 'scheduled__2023-10-24T00:00:00+00:00', '--job-id', '1748', '--raw', '--subdir', 'DAGS_FOLDER/main.py', '--cfg-path', '/tmp/tmp2nef79lr']
[2023-12-07T17:01:36.771+0000] {standard_task_runner.py:85} INFO - Job 1748: Subtask main_task
[2023-12-07T17:01:36.801+0000] {task_command.py:416} INFO - Running <TaskInstance: my_scraping_dag.main_task scheduled__2023-10-24T00:00:00+00:00 [running]> on host 63b0c7e341c0
[2023-12-07T17:01:36.847+0000] {taskinstance.py:1662} INFO - Exporting env vars: AIRFLOW_CTX_DAG_OWNER='***' AIRFLOW_CTX_DAG_ID='my_scraping_dag' AIRFLOW_CTX_TASK_ID='main_task' AIRFLOW_CTX_EXECUTION_DATE='2023-10-24T00:00:00+00:00' AIRFLOW_CTX_TRY_NUMBER='1' AIRFLOW_CTX_DAG_RUN_ID='scheduled__2023-10-24T00:00:00+00:00'
[2023-12-07T17:01:36.866+0000] {logging_mixin.py:154} INFO - base_url: https://tuncbotanik.com
[2023-12-07T17:01:36.867+0000] {python.py:194} INFO - Done. Returned value was: ('https://tuncbotanik.com', {'User-Agent': 'Mozilla/5.0 (Macintosh; Intel Mac OS X 10_15_7) AppleWebKit/537.36 (KHTML, like Gecko) Chrome/119.0.0.0 Safari/537.36', 'Accept-Language': 'tr-TR,tr;q=0.9,en-US;q=0.8,en;q=0.7'}, {'dbname': 'plant', 'user': 'aozgokme', 'password': '***', 'host': 'localhost', 'port': '5432'})
[2023-12-07T17:01:36.880+0000] {taskinstance.py:1400} INFO - Marking task as SUCCESS. dag_id=my_scraping_dag, task_id=main_task, execution_date=20231024T000000, start_date=20231207T170136, end_date=20231207T170136
[2023-12-07T17:01:36.903+0000] {local_task_job_runner.py:228} INFO - Task exited with return code 0
[2023-12-07T17:01:36.921+0000] {taskinstance.py:2778} INFO - 1 downstream tasks scheduled from follow-on schedule check
[2023-12-07T17:04:58.504+0000] {taskinstance.py:1159} INFO - Dependencies all met for dep_context=non-requeueable deps ti=<TaskInstance: my_scraping_dag.main_task scheduled__2023-10-24T00:00:00+00:00 [queued]>
[2023-12-07T17:04:58.511+0000] {taskinstance.py:1159} INFO - Dependencies all met for dep_context=requeueable deps ti=<TaskInstance: my_scraping_dag.main_task scheduled__2023-10-24T00:00:00+00:00 [queued]>
[2023-12-07T17:04:58.512+0000] {taskinstance.py:1361} INFO - Starting attempt 1 of 1
[2023-12-07T17:04:58.567+0000] {taskinstance.py:1382} INFO - Executing <Task(PythonOperator): main_task> on 2023-10-24 00:00:00+00:00
[2023-12-07T17:04:58.572+0000] {standard_task_runner.py:57} INFO - Started process 8017 to run task
[2023-12-07T17:04:58.575+0000] {standard_task_runner.py:84} INFO - Running: ['***', 'tasks', 'run', 'my_scraping_dag', 'main_task', 'scheduled__2023-10-24T00:00:00+00:00', '--job-id', '2432', '--raw', '--subdir', 'DAGS_FOLDER/main.py', '--cfg-path', '/tmp/tmp10h45uc3']
[2023-12-07T17:04:58.579+0000] {standard_task_runner.py:85} INFO - Job 2432: Subtask main_task
[2023-12-07T17:04:58.616+0000] {task_command.py:416} INFO - Running <TaskInstance: my_scraping_dag.main_task scheduled__2023-10-24T00:00:00+00:00 [running]> on host 63b0c7e341c0
[2023-12-07T17:04:58.689+0000] {taskinstance.py:1662} INFO - Exporting env vars: AIRFLOW_CTX_DAG_OWNER='***' AIRFLOW_CTX_DAG_ID='my_scraping_dag' AIRFLOW_CTX_TASK_ID='main_task' AIRFLOW_CTX_EXECUTION_DATE='2023-10-24T00:00:00+00:00' AIRFLOW_CTX_TRY_NUMBER='1' AIRFLOW_CTX_DAG_RUN_ID='scheduled__2023-10-24T00:00:00+00:00'
[2023-12-07T17:04:58.734+0000] {logging_mixin.py:154} INFO - base_url: https://tuncbotanik.com
[2023-12-07T17:04:58.735+0000] {python.py:194} INFO - Done. Returned value was: ('https://tuncbotanik.com', {'User-Agent': 'Mozilla/5.0 (Macintosh; Intel Mac OS X 10_15_7) AppleWebKit/537.36 (KHTML, like Gecko) Chrome/119.0.0.0 Safari/537.36', 'Accept-Language': 'tr-TR,tr;q=0.9,en-US;q=0.8,en;q=0.7'}, {'dbname': 'plant', 'user': 'aozgokme', 'password': '***', 'host': 'localhost', 'port': '5432'})
[2023-12-07T17:04:58.763+0000] {taskinstance.py:1400} INFO - Marking task as SUCCESS. dag_id=my_scraping_dag, task_id=main_task, execution_date=20231024T000000, start_date=20231207T170458, end_date=20231207T170458
[2023-12-07T17:04:58.832+0000] {local_task_job_runner.py:228} INFO - Task exited with return code 0
[2023-12-07T17:04:58.858+0000] {taskinstance.py:2778} INFO - 1 downstream tasks scheduled from follow-on schedule check
[2023-12-07T17:19:18.843+0000] {taskinstance.py:1159} INFO - Dependencies all met for dep_context=non-requeueable deps ti=<TaskInstance: my_scraping_dag.main_task scheduled__2023-10-24T00:00:00+00:00 [queued]>
[2023-12-07T17:19:18.855+0000] {taskinstance.py:1159} INFO - Dependencies all met for dep_context=requeueable deps ti=<TaskInstance: my_scraping_dag.main_task scheduled__2023-10-24T00:00:00+00:00 [queued]>
[2023-12-07T17:19:18.855+0000] {taskinstance.py:1361} INFO - Starting attempt 1 of 1
[2023-12-07T17:19:18.865+0000] {taskinstance.py:1382} INFO - Executing <Task(PythonOperator): main_task> on 2023-10-24 00:00:00+00:00
[2023-12-07T17:19:18.869+0000] {standard_task_runner.py:57} INFO - Started process 9158 to run task
[2023-12-07T17:19:18.873+0000] {standard_task_runner.py:84} INFO - Running: ['***', 'tasks', 'run', 'my_scraping_dag', 'main_task', 'scheduled__2023-10-24T00:00:00+00:00', '--job-id', '2826', '--raw', '--subdir', 'DAGS_FOLDER/main.py', '--cfg-path', '/tmp/tmpao56x7xg']
[2023-12-07T17:19:18.875+0000] {standard_task_runner.py:85} INFO - Job 2826: Subtask main_task
[2023-12-07T17:19:18.925+0000] {task_command.py:416} INFO - Running <TaskInstance: my_scraping_dag.main_task scheduled__2023-10-24T00:00:00+00:00 [running]> on host 63b0c7e341c0
[2023-12-07T17:19:18.992+0000] {taskinstance.py:1662} INFO - Exporting env vars: AIRFLOW_CTX_DAG_OWNER='***' AIRFLOW_CTX_DAG_ID='my_scraping_dag' AIRFLOW_CTX_TASK_ID='main_task' AIRFLOW_CTX_EXECUTION_DATE='2023-10-24T00:00:00+00:00' AIRFLOW_CTX_TRY_NUMBER='1' AIRFLOW_CTX_DAG_RUN_ID='scheduled__2023-10-24T00:00:00+00:00'
[2023-12-07T17:19:19.734+0000] {taskinstance.py:1937} ERROR - Task failed with exception
Traceback (most recent call last):
  File "/home/airflow/.local/lib/python3.8/site-packages/airflow/operators/python.py", line 192, in execute
    return_value = self.execute_callable()
  File "/home/airflow/.local/lib/python3.8/site-packages/airflow/operators/python.py", line 209, in execute_callable
    return self.python_callable(*self.op_args, **self.op_kwargs)
  File "/opt/airflow/dags/main.py", line 80, in main
    insert_data_to_db(products, db_params)
  File "/opt/airflow/dags/main.py", line 43, in insert_data_to_db
    with psycopg2.connect(**db_params) as conn:
  File "/home/airflow/.local/lib/python3.8/site-packages/psycopg2/__init__.py", line 122, in connect
    conn = _connect(dsn, connection_factory=connection_factory, **kwasync)
psycopg2.OperationalError: connection to server at "localhost" (127.0.0.1), port 5432 failed: Connection refused
	Is the server running on that host and accepting TCP/IP connections?
connection to server at "localhost" (::1), port 5432 failed: Cannot assign requested address
	Is the server running on that host and accepting TCP/IP connections?

[2023-12-07T17:19:19.744+0000] {taskinstance.py:1400} INFO - Marking task as FAILED. dag_id=my_scraping_dag, task_id=main_task, execution_date=20231024T000000, start_date=20231207T171918, end_date=20231207T171919
[2023-12-07T17:19:19.751+0000] {standard_task_runner.py:104} ERROR - Failed to execute job 2826 for task main_task (connection to server at "localhost" (127.0.0.1), port 5432 failed: Connection refused
	Is the server running on that host and accepting TCP/IP connections?
connection to server at "localhost" (::1), port 5432 failed: Cannot assign requested address
	Is the server running on that host and accepting TCP/IP connections?
; 9158)
[2023-12-07T17:19:19.777+0000] {local_task_job_runner.py:228} INFO - Task exited with return code 1
[2023-12-07T17:19:19.807+0000] {taskinstance.py:2778} INFO - 0 downstream tasks scheduled from follow-on schedule check
[2023-12-07T17:23:39.116+0000] {taskinstance.py:1159} INFO - Dependencies all met for dep_context=non-requeueable deps ti=<TaskInstance: my_scraping_dag.main_task scheduled__2023-10-24T00:00:00+00:00 [queued]>
[2023-12-07T17:23:39.122+0000] {taskinstance.py:1159} INFO - Dependencies all met for dep_context=requeueable deps ti=<TaskInstance: my_scraping_dag.main_task scheduled__2023-10-24T00:00:00+00:00 [queued]>
[2023-12-07T17:23:39.123+0000] {taskinstance.py:1361} INFO - Starting attempt 1 of 1
[2023-12-07T17:23:39.138+0000] {taskinstance.py:1382} INFO - Executing <Task(PythonOperator): main_task> on 2023-10-24 00:00:00+00:00
[2023-12-07T17:23:39.145+0000] {standard_task_runner.py:57} INFO - Started process 9954 to run task
[2023-12-07T17:23:39.150+0000] {standard_task_runner.py:84} INFO - Running: ['***', 'tasks', 'run', 'my_scraping_dag', 'main_task', 'scheduled__2023-10-24T00:00:00+00:00', '--job-id', '3168', '--raw', '--subdir', 'DAGS_FOLDER/main.py', '--cfg-path', '/tmp/tmp5w9op9h4']
[2023-12-07T17:23:39.163+0000] {standard_task_runner.py:85} INFO - Job 3168: Subtask main_task
[2023-12-07T17:23:39.228+0000] {task_command.py:416} INFO - Running <TaskInstance: my_scraping_dag.main_task scheduled__2023-10-24T00:00:00+00:00 [running]> on host 63b0c7e341c0
[2023-12-07T17:23:39.414+0000] {taskinstance.py:1662} INFO - Exporting env vars: AIRFLOW_CTX_DAG_OWNER='***' AIRFLOW_CTX_DAG_ID='my_scraping_dag' AIRFLOW_CTX_TASK_ID='main_task' AIRFLOW_CTX_EXECUTION_DATE='2023-10-24T00:00:00+00:00' AIRFLOW_CTX_TRY_NUMBER='1' AIRFLOW_CTX_DAG_RUN_ID='scheduled__2023-10-24T00:00:00+00:00'
[2023-12-07T17:23:40.186+0000] {taskinstance.py:1937} ERROR - Task failed with exception
Traceback (most recent call last):
  File "/home/airflow/.local/lib/python3.8/site-packages/airflow/operators/python.py", line 192, in execute
    return_value = self.execute_callable()
  File "/home/airflow/.local/lib/python3.8/site-packages/airflow/operators/python.py", line 209, in execute_callable
    return self.python_callable(*self.op_args, **self.op_kwargs)
  File "/opt/airflow/dags/main.py", line 73, in main
    insert_data_to_db(products, db_params)
  File "/opt/airflow/dags/main.py", line 40, in insert_data_to_db
    with psycopg2.connect(**db_params) as conn:
  File "/home/airflow/.local/lib/python3.8/site-packages/psycopg2/__init__.py", line 122, in connect
    conn = _connect(dsn, connection_factory=connection_factory, **kwasync)
psycopg2.OperationalError: connection to server at "localhost" (127.0.0.1), port 5432 failed: Connection refused
	Is the server running on that host and accepting TCP/IP connections?
connection to server at "localhost" (::1), port 5432 failed: Cannot assign requested address
	Is the server running on that host and accepting TCP/IP connections?

[2023-12-07T17:23:40.191+0000] {taskinstance.py:1400} INFO - Marking task as FAILED. dag_id=my_scraping_dag, task_id=main_task, execution_date=20231024T000000, start_date=20231207T172339, end_date=20231207T172340
[2023-12-07T17:23:40.197+0000] {standard_task_runner.py:104} ERROR - Failed to execute job 3168 for task main_task (connection to server at "localhost" (127.0.0.1), port 5432 failed: Connection refused
	Is the server running on that host and accepting TCP/IP connections?
connection to server at "localhost" (::1), port 5432 failed: Cannot assign requested address
	Is the server running on that host and accepting TCP/IP connections?
; 9954)
[2023-12-07T17:23:40.214+0000] {local_task_job_runner.py:228} INFO - Task exited with return code 1
[2023-12-07T17:23:40.226+0000] {taskinstance.py:2778} INFO - 0 downstream tasks scheduled from follow-on schedule check
[2023-12-07T17:29:16.584+0000] {taskinstance.py:1159} INFO - Dependencies all met for dep_context=non-requeueable deps ti=<TaskInstance: my_scraping_dag.main_task scheduled__2023-10-24T00:00:00+00:00 [queued]>
[2023-12-07T17:29:16.588+0000] {taskinstance.py:1159} INFO - Dependencies all met for dep_context=requeueable deps ti=<TaskInstance: my_scraping_dag.main_task scheduled__2023-10-24T00:00:00+00:00 [queued]>
[2023-12-07T17:29:16.588+0000] {taskinstance.py:1361} INFO - Starting attempt 1 of 1
[2023-12-07T17:29:16.595+0000] {taskinstance.py:1382} INFO - Executing <Task(PythonOperator): main_task> on 2023-10-24 00:00:00+00:00
[2023-12-07T17:29:16.597+0000] {standard_task_runner.py:57} INFO - Started process 10790 to run task
[2023-12-07T17:29:16.600+0000] {standard_task_runner.py:84} INFO - Running: ['***', 'tasks', 'run', 'my_scraping_dag', 'main_task', 'scheduled__2023-10-24T00:00:00+00:00', '--job-id', '3510', '--raw', '--subdir', 'DAGS_FOLDER/main.py', '--cfg-path', '/tmp/tmp1eofgwsf']
[2023-12-07T17:29:16.601+0000] {standard_task_runner.py:85} INFO - Job 3510: Subtask main_task
[2023-12-07T17:29:16.625+0000] {task_command.py:416} INFO - Running <TaskInstance: my_scraping_dag.main_task scheduled__2023-10-24T00:00:00+00:00 [running]> on host 63b0c7e341c0
[2023-12-07T17:29:16.666+0000] {taskinstance.py:1662} INFO - Exporting env vars: AIRFLOW_CTX_DAG_OWNER='***' AIRFLOW_CTX_DAG_ID='my_scraping_dag' AIRFLOW_CTX_TASK_ID='main_task' AIRFLOW_CTX_EXECUTION_DATE='2023-10-24T00:00:00+00:00' AIRFLOW_CTX_TRY_NUMBER='1' AIRFLOW_CTX_DAG_RUN_ID='scheduled__2023-10-24T00:00:00+00:00'
[2023-12-07T17:29:17.555+0000] {taskinstance.py:1937} ERROR - Task failed with exception
Traceback (most recent call last):
  File "/home/airflow/.local/lib/python3.8/site-packages/airflow/operators/python.py", line 192, in execute
    return_value = self.execute_callable()
  File "/home/airflow/.local/lib/python3.8/site-packages/airflow/operators/python.py", line 209, in execute_callable
    return self.python_callable(*self.op_args, **self.op_kwargs)
  File "/opt/airflow/dags/main.py", line 73, in main
    insert_data_to_db(products, db_params)
  File "/opt/airflow/dags/main.py", line 40, in insert_data_to_db
    with psycopg2.connect(**db_params) as conn:
  File "/home/airflow/.local/lib/python3.8/site-packages/psycopg2/__init__.py", line 122, in connect
    conn = _connect(dsn, connection_factory=connection_factory, **kwasync)
psycopg2.OperationalError: connection to server at "localhost" (127.0.0.1), port 5432 failed: Connection refused
	Is the server running on that host and accepting TCP/IP connections?
connection to server at "localhost" (::1), port 5432 failed: Cannot assign requested address
	Is the server running on that host and accepting TCP/IP connections?

[2023-12-07T17:29:17.560+0000] {taskinstance.py:1400} INFO - Marking task as FAILED. dag_id=my_scraping_dag, task_id=main_task, execution_date=20231024T000000, start_date=20231207T172916, end_date=20231207T172917
[2023-12-07T17:29:17.565+0000] {standard_task_runner.py:104} ERROR - Failed to execute job 3510 for task main_task (connection to server at "localhost" (127.0.0.1), port 5432 failed: Connection refused
	Is the server running on that host and accepting TCP/IP connections?
connection to server at "localhost" (::1), port 5432 failed: Cannot assign requested address
	Is the server running on that host and accepting TCP/IP connections?
; 10790)
[2023-12-07T17:29:17.576+0000] {local_task_job_runner.py:228} INFO - Task exited with return code 1
[2023-12-07T17:29:17.585+0000] {taskinstance.py:2778} INFO - 0 downstream tasks scheduled from follow-on schedule check
