[2023-12-07T16:33:39.208+0000] {taskinstance.py:1159} INFO - Dependencies all met for dep_context=non-requeueable deps ti=<TaskInstance: my_scraping_dag.main_task scheduled__2023-08-11T00:00:00+00:00 [queued]>
[2023-12-07T16:33:39.212+0000] {taskinstance.py:1159} INFO - Dependencies all met for dep_context=requeueable deps ti=<TaskInstance: my_scraping_dag.main_task scheduled__2023-08-11T00:00:00+00:00 [queued]>
[2023-12-07T16:33:39.212+0000] {taskinstance.py:1361} INFO - Starting attempt 1 of 1
[2023-12-07T16:33:39.219+0000] {taskinstance.py:1382} INFO - Executing <Task(PythonOperator): main_task> on 2023-08-11 00:00:00+00:00
[2023-12-07T16:33:39.221+0000] {standard_task_runner.py:57} INFO - Started process 4016 to run task
[2023-12-07T16:33:39.224+0000] {standard_task_runner.py:84} INFO - Running: ['***', 'tasks', 'run', 'my_scraping_dag', 'main_task', 'scheduled__2023-08-11T00:00:00+00:00', '--job-id', '811', '--raw', '--subdir', 'DAGS_FOLDER/main.py', '--cfg-path', '/tmp/tmpumlq8v9f']
[2023-12-07T16:33:39.226+0000] {standard_task_runner.py:85} INFO - Job 811: Subtask main_task
[2023-12-07T16:33:39.249+0000] {task_command.py:416} INFO - Running <TaskInstance: my_scraping_dag.main_task scheduled__2023-08-11T00:00:00+00:00 [running]> on host 63b0c7e341c0
[2023-12-07T16:33:39.291+0000] {taskinstance.py:1662} INFO - Exporting env vars: AIRFLOW_CTX_DAG_OWNER='***' AIRFLOW_CTX_DAG_ID='my_scraping_dag' AIRFLOW_CTX_TASK_ID='main_task' AIRFLOW_CTX_EXECUTION_DATE='2023-08-11T00:00:00+00:00' AIRFLOW_CTX_TRY_NUMBER='1' AIRFLOW_CTX_DAG_RUN_ID='scheduled__2023-08-11T00:00:00+00:00'
[2023-12-07T16:33:39.293+0000] {taskinstance.py:1937} ERROR - Task failed with exception
Traceback (most recent call last):
  File "/usr/local/lib/python3.8/configparser.py", line 846, in items
    d.update(self._sections[section])
KeyError: 'web'

During handling of the above exception, another exception occurred:

Traceback (most recent call last):
  File "/home/airflow/.local/lib/python3.8/site-packages/airflow/operators/python.py", line 192, in execute
    return_value = self.execute_callable()
  File "/home/airflow/.local/lib/python3.8/site-packages/airflow/operators/python.py", line 209, in execute_callable
    return self.python_callable(*self.op_args, **self.op_kwargs)
  File "/opt/airflow/dags/main.py", line 60, in main
    config = get_config('web')
  File "/opt/airflow/dags/main.py", line 22, in get_config
    return {key: value for key, value in parser.items(section)}
  File "/usr/local/lib/python3.8/configparser.py", line 849, in items
    raise NoSectionError(section)
configparser.NoSectionError: No section: 'web'
[2023-12-07T16:33:39.299+0000] {taskinstance.py:1400} INFO - Marking task as FAILED. dag_id=my_scraping_dag, task_id=main_task, execution_date=20230811T000000, start_date=20231207T163339, end_date=20231207T163339
[2023-12-07T16:33:39.304+0000] {standard_task_runner.py:104} ERROR - Failed to execute job 811 for task main_task (No section: 'web'; 4016)
[2023-12-07T16:33:39.315+0000] {local_task_job_runner.py:228} INFO - Task exited with return code 1
[2023-12-07T16:33:39.330+0000] {taskinstance.py:2778} INFO - 0 downstream tasks scheduled from follow-on schedule check
[2023-12-07T16:42:19.695+0000] {taskinstance.py:1159} INFO - Dependencies all met for dep_context=non-requeueable deps ti=<TaskInstance: my_scraping_dag.main_task scheduled__2023-08-11T00:00:00+00:00 [queued]>
[2023-12-07T16:42:19.699+0000] {taskinstance.py:1159} INFO - Dependencies all met for dep_context=requeueable deps ti=<TaskInstance: my_scraping_dag.main_task scheduled__2023-08-11T00:00:00+00:00 [queued]>
[2023-12-07T16:42:19.699+0000] {taskinstance.py:1361} INFO - Starting attempt 1 of 1
[2023-12-07T16:42:19.704+0000] {taskinstance.py:1382} INFO - Executing <Task(PythonOperator): main_task> on 2023-08-11 00:00:00+00:00
[2023-12-07T16:42:19.707+0000] {standard_task_runner.py:57} INFO - Started process 4907 to run task
[2023-12-07T16:42:19.709+0000] {standard_task_runner.py:84} INFO - Running: ['***', 'tasks', 'run', 'my_scraping_dag', 'main_task', 'scheduled__2023-08-11T00:00:00+00:00', '--job-id', '1156', '--raw', '--subdir', 'DAGS_FOLDER/main.py', '--cfg-path', '/tmp/tmpfl1mco54']
[2023-12-07T16:42:19.711+0000] {standard_task_runner.py:85} INFO - Job 1156: Subtask main_task
[2023-12-07T16:42:19.736+0000] {task_command.py:416} INFO - Running <TaskInstance: my_scraping_dag.main_task scheduled__2023-08-11T00:00:00+00:00 [running]> on host 63b0c7e341c0
[2023-12-07T16:42:19.767+0000] {taskinstance.py:1662} INFO - Exporting env vars: AIRFLOW_CTX_DAG_OWNER='***' AIRFLOW_CTX_DAG_ID='my_scraping_dag' AIRFLOW_CTX_TASK_ID='main_task' AIRFLOW_CTX_EXECUTION_DATE='2023-08-11T00:00:00+00:00' AIRFLOW_CTX_TRY_NUMBER='1' AIRFLOW_CTX_DAG_RUN_ID='scheduled__2023-08-11T00:00:00+00:00'
[2023-12-07T16:42:19.768+0000] {taskinstance.py:1937} ERROR - Task failed with exception
Traceback (most recent call last):
  File "/usr/local/lib/python3.8/configparser.py", line 846, in items
    d.update(self._sections[section])
KeyError: 'web'

During handling of the above exception, another exception occurred:

Traceback (most recent call last):
  File "/home/airflow/.local/lib/python3.8/site-packages/airflow/operators/python.py", line 192, in execute
    return_value = self.execute_callable()
  File "/home/airflow/.local/lib/python3.8/site-packages/airflow/operators/python.py", line 209, in execute_callable
    return self.python_callable(*self.op_args, **self.op_kwargs)
  File "/opt/airflow/dags/main.py", line 60, in main
    config = get_config('web')
  File "/opt/airflow/dags/main.py", line 22, in get_config
    return {key: value for key, value in parser.items(section)}
  File "/usr/local/lib/python3.8/configparser.py", line 849, in items
    raise NoSectionError(section)
configparser.NoSectionError: No section: 'web'
[2023-12-07T16:42:19.772+0000] {taskinstance.py:1400} INFO - Marking task as FAILED. dag_id=my_scraping_dag, task_id=main_task, execution_date=20230811T000000, start_date=20231207T164219, end_date=20231207T164219
[2023-12-07T16:42:19.778+0000] {standard_task_runner.py:104} ERROR - Failed to execute job 1156 for task main_task (No section: 'web'; 4907)
[2023-12-07T16:42:19.801+0000] {local_task_job_runner.py:228} INFO - Task exited with return code 1
[2023-12-07T16:42:19.813+0000] {taskinstance.py:2778} INFO - 0 downstream tasks scheduled from follow-on schedule check
[2023-12-07T17:01:11.937+0000] {taskinstance.py:1159} INFO - Dependencies all met for dep_context=non-requeueable deps ti=<TaskInstance: my_scraping_dag.main_task scheduled__2023-08-11T00:00:00+00:00 [queued]>
[2023-12-07T17:01:11.943+0000] {taskinstance.py:1159} INFO - Dependencies all met for dep_context=requeueable deps ti=<TaskInstance: my_scraping_dag.main_task scheduled__2023-08-11T00:00:00+00:00 [queued]>
[2023-12-07T17:01:11.944+0000] {taskinstance.py:1361} INFO - Starting attempt 1 of 1
[2023-12-07T17:01:11.951+0000] {taskinstance.py:1382} INFO - Executing <Task(PythonOperator): main_task> on 2023-08-11 00:00:00+00:00
[2023-12-07T17:01:11.954+0000] {standard_task_runner.py:57} INFO - Started process 6262 to run task
[2023-12-07T17:01:11.957+0000] {standard_task_runner.py:84} INFO - Running: ['***', 'tasks', 'run', 'my_scraping_dag', 'main_task', 'scheduled__2023-08-11T00:00:00+00:00', '--job-id', '1598', '--raw', '--subdir', 'DAGS_FOLDER/main.py', '--cfg-path', '/tmp/tmpdozzanjl']
[2023-12-07T17:01:11.960+0000] {standard_task_runner.py:85} INFO - Job 1598: Subtask main_task
[2023-12-07T17:01:11.997+0000] {task_command.py:416} INFO - Running <TaskInstance: my_scraping_dag.main_task scheduled__2023-08-11T00:00:00+00:00 [running]> on host 63b0c7e341c0
[2023-12-07T17:01:12.045+0000] {taskinstance.py:1662} INFO - Exporting env vars: AIRFLOW_CTX_DAG_OWNER='***' AIRFLOW_CTX_DAG_ID='my_scraping_dag' AIRFLOW_CTX_TASK_ID='main_task' AIRFLOW_CTX_EXECUTION_DATE='2023-08-11T00:00:00+00:00' AIRFLOW_CTX_TRY_NUMBER='1' AIRFLOW_CTX_DAG_RUN_ID='scheduled__2023-08-11T00:00:00+00:00'
[2023-12-07T17:01:12.084+0000] {logging_mixin.py:154} INFO - base_url: https://tuncbotanik.com
[2023-12-07T17:01:12.085+0000] {python.py:194} INFO - Done. Returned value was: ('https://tuncbotanik.com', {'User-Agent': 'Mozilla/5.0 (Macintosh; Intel Mac OS X 10_15_7) AppleWebKit/537.36 (KHTML, like Gecko) Chrome/119.0.0.0 Safari/537.36', 'Accept-Language': 'tr-TR,tr;q=0.9,en-US;q=0.8,en;q=0.7'}, {'dbname': 'plant', 'user': 'aozgokme', 'password': '***', 'host': 'localhost', 'port': '5432'})
[2023-12-07T17:01:12.104+0000] {taskinstance.py:1400} INFO - Marking task as SUCCESS. dag_id=my_scraping_dag, task_id=main_task, execution_date=20230811T000000, start_date=20231207T170111, end_date=20231207T170112
[2023-12-07T17:01:12.174+0000] {local_task_job_runner.py:228} INFO - Task exited with return code 0
[2023-12-07T17:01:12.192+0000] {taskinstance.py:2778} INFO - 1 downstream tasks scheduled from follow-on schedule check
[2023-12-07T17:04:29.608+0000] {taskinstance.py:1159} INFO - Dependencies all met for dep_context=non-requeueable deps ti=<TaskInstance: my_scraping_dag.main_task scheduled__2023-08-11T00:00:00+00:00 [queued]>
[2023-12-07T17:04:29.614+0000] {taskinstance.py:1159} INFO - Dependencies all met for dep_context=requeueable deps ti=<TaskInstance: my_scraping_dag.main_task scheduled__2023-08-11T00:00:00+00:00 [queued]>
[2023-12-07T17:04:29.615+0000] {taskinstance.py:1361} INFO - Starting attempt 1 of 1
[2023-12-07T17:04:29.660+0000] {taskinstance.py:1382} INFO - Executing <Task(PythonOperator): main_task> on 2023-08-11 00:00:00+00:00
[2023-12-07T17:04:29.669+0000] {standard_task_runner.py:57} INFO - Started process 7710 to run task
[2023-12-07T17:04:29.673+0000] {standard_task_runner.py:84} INFO - Running: ['***', 'tasks', 'run', 'my_scraping_dag', 'main_task', 'scheduled__2023-08-11T00:00:00+00:00', '--job-id', '2283', '--raw', '--subdir', 'DAGS_FOLDER/main.py', '--cfg-path', '/tmp/tmpfz8mtfx6']
[2023-12-07T17:04:29.675+0000] {standard_task_runner.py:85} INFO - Job 2283: Subtask main_task
[2023-12-07T17:04:29.712+0000] {task_command.py:416} INFO - Running <TaskInstance: my_scraping_dag.main_task scheduled__2023-08-11T00:00:00+00:00 [running]> on host 63b0c7e341c0
[2023-12-07T17:04:29.773+0000] {taskinstance.py:1662} INFO - Exporting env vars: AIRFLOW_CTX_DAG_OWNER='***' AIRFLOW_CTX_DAG_ID='my_scraping_dag' AIRFLOW_CTX_TASK_ID='main_task' AIRFLOW_CTX_EXECUTION_DATE='2023-08-11T00:00:00+00:00' AIRFLOW_CTX_TRY_NUMBER='1' AIRFLOW_CTX_DAG_RUN_ID='scheduled__2023-08-11T00:00:00+00:00'
[2023-12-07T17:04:29.808+0000] {logging_mixin.py:154} INFO - base_url: https://tuncbotanik.com
[2023-12-07T17:04:29.809+0000] {python.py:194} INFO - Done. Returned value was: ('https://tuncbotanik.com', {'User-Agent': 'Mozilla/5.0 (Macintosh; Intel Mac OS X 10_15_7) AppleWebKit/537.36 (KHTML, like Gecko) Chrome/119.0.0.0 Safari/537.36', 'Accept-Language': 'tr-TR,tr;q=0.9,en-US;q=0.8,en;q=0.7'}, {'dbname': 'plant', 'user': 'aozgokme', 'password': '***', 'host': 'localhost', 'port': '5432'})
[2023-12-07T17:04:29.823+0000] {taskinstance.py:1400} INFO - Marking task as SUCCESS. dag_id=my_scraping_dag, task_id=main_task, execution_date=20230811T000000, start_date=20231207T170429, end_date=20231207T170429
[2023-12-07T17:04:29.886+0000] {local_task_job_runner.py:228} INFO - Task exited with return code 0
[2023-12-07T17:04:29.926+0000] {taskinstance.py:2778} INFO - 0 downstream tasks scheduled from follow-on schedule check
[2023-12-07T17:19:04.462+0000] {taskinstance.py:1159} INFO - Dependencies all met for dep_context=non-requeueable deps ti=<TaskInstance: my_scraping_dag.main_task scheduled__2023-08-11T00:00:00+00:00 [queued]>
[2023-12-07T17:19:04.469+0000] {taskinstance.py:1159} INFO - Dependencies all met for dep_context=requeueable deps ti=<TaskInstance: my_scraping_dag.main_task scheduled__2023-08-11T00:00:00+00:00 [queued]>
[2023-12-07T17:19:04.469+0000] {taskinstance.py:1361} INFO - Starting attempt 1 of 1
[2023-12-07T17:19:04.487+0000] {taskinstance.py:1382} INFO - Executing <Task(PythonOperator): main_task> on 2023-08-11 00:00:00+00:00
[2023-12-07T17:19:04.492+0000] {standard_task_runner.py:57} INFO - Started process 9000 to run task
[2023-12-07T17:19:04.495+0000] {standard_task_runner.py:84} INFO - Running: ['***', 'tasks', 'run', 'my_scraping_dag', 'main_task', 'scheduled__2023-08-11T00:00:00+00:00', '--job-id', '2752', '--raw', '--subdir', 'DAGS_FOLDER/main.py', '--cfg-path', '/tmp/tmp3jhdqdej']
[2023-12-07T17:19:04.497+0000] {standard_task_runner.py:85} INFO - Job 2752: Subtask main_task
[2023-12-07T17:19:04.535+0000] {task_command.py:416} INFO - Running <TaskInstance: my_scraping_dag.main_task scheduled__2023-08-11T00:00:00+00:00 [running]> on host 63b0c7e341c0
[2023-12-07T17:19:04.578+0000] {taskinstance.py:1662} INFO - Exporting env vars: AIRFLOW_CTX_DAG_OWNER='***' AIRFLOW_CTX_DAG_ID='my_scraping_dag' AIRFLOW_CTX_TASK_ID='main_task' AIRFLOW_CTX_EXECUTION_DATE='2023-08-11T00:00:00+00:00' AIRFLOW_CTX_TRY_NUMBER='1' AIRFLOW_CTX_DAG_RUN_ID='scheduled__2023-08-11T00:00:00+00:00'
[2023-12-07T17:19:05.371+0000] {taskinstance.py:1937} ERROR - Task failed with exception
Traceback (most recent call last):
  File "/home/airflow/.local/lib/python3.8/site-packages/airflow/operators/python.py", line 192, in execute
    return_value = self.execute_callable()
  File "/home/airflow/.local/lib/python3.8/site-packages/airflow/operators/python.py", line 209, in execute_callable
    return self.python_callable(*self.op_args, **self.op_kwargs)
  File "/opt/airflow/dags/main.py", line 80, in main
    insert_data_to_db(products, db_params)
  File "/opt/airflow/dags/main.py", line 43, in insert_data_to_db
    with psycopg2.connect(**db_params) as conn:
  File "/home/airflow/.local/lib/python3.8/site-packages/psycopg2/__init__.py", line 122, in connect
    conn = _connect(dsn, connection_factory=connection_factory, **kwasync)
psycopg2.OperationalError: connection to server at "localhost" (127.0.0.1), port 5432 failed: Connection refused
	Is the server running on that host and accepting TCP/IP connections?
connection to server at "localhost" (::1), port 5432 failed: Cannot assign requested address
	Is the server running on that host and accepting TCP/IP connections?

[2023-12-07T17:19:05.385+0000] {taskinstance.py:1400} INFO - Marking task as FAILED. dag_id=my_scraping_dag, task_id=main_task, execution_date=20230811T000000, start_date=20231207T171904, end_date=20231207T171905
[2023-12-07T17:19:05.398+0000] {standard_task_runner.py:104} ERROR - Failed to execute job 2752 for task main_task (connection to server at "localhost" (127.0.0.1), port 5432 failed: Connection refused
	Is the server running on that host and accepting TCP/IP connections?
connection to server at "localhost" (::1), port 5432 failed: Cannot assign requested address
	Is the server running on that host and accepting TCP/IP connections?
; 9000)
[2023-12-07T17:19:05.441+0000] {local_task_job_runner.py:228} INFO - Task exited with return code 1
[2023-12-07T17:19:05.505+0000] {taskinstance.py:2778} INFO - 0 downstream tasks scheduled from follow-on schedule check
[2023-12-07T17:23:19.758+0000] {taskinstance.py:1159} INFO - Dependencies all met for dep_context=non-requeueable deps ti=<TaskInstance: my_scraping_dag.main_task scheduled__2023-08-11T00:00:00+00:00 [queued]>
[2023-12-07T17:23:19.765+0000] {taskinstance.py:1159} INFO - Dependencies all met for dep_context=requeueable deps ti=<TaskInstance: my_scraping_dag.main_task scheduled__2023-08-11T00:00:00+00:00 [queued]>
[2023-12-07T17:23:19.765+0000] {taskinstance.py:1361} INFO - Starting attempt 1 of 1
[2023-12-07T17:23:19.777+0000] {taskinstance.py:1382} INFO - Executing <Task(PythonOperator): main_task> on 2023-08-11 00:00:00+00:00
[2023-12-07T17:23:19.781+0000] {standard_task_runner.py:57} INFO - Started process 9792 to run task
[2023-12-07T17:23:19.783+0000] {standard_task_runner.py:84} INFO - Running: ['***', 'tasks', 'run', 'my_scraping_dag', 'main_task', 'scheduled__2023-08-11T00:00:00+00:00', '--job-id', '3094', '--raw', '--subdir', 'DAGS_FOLDER/main.py', '--cfg-path', '/tmp/tmpi49bqlht']
[2023-12-07T17:23:19.785+0000] {standard_task_runner.py:85} INFO - Job 3094: Subtask main_task
[2023-12-07T17:23:19.817+0000] {task_command.py:416} INFO - Running <TaskInstance: my_scraping_dag.main_task scheduled__2023-08-11T00:00:00+00:00 [running]> on host 63b0c7e341c0
[2023-12-07T17:23:19.859+0000] {taskinstance.py:1662} INFO - Exporting env vars: AIRFLOW_CTX_DAG_OWNER='***' AIRFLOW_CTX_DAG_ID='my_scraping_dag' AIRFLOW_CTX_TASK_ID='main_task' AIRFLOW_CTX_EXECUTION_DATE='2023-08-11T00:00:00+00:00' AIRFLOW_CTX_TRY_NUMBER='1' AIRFLOW_CTX_DAG_RUN_ID='scheduled__2023-08-11T00:00:00+00:00'
[2023-12-07T17:23:20.528+0000] {taskinstance.py:1937} ERROR - Task failed with exception
Traceback (most recent call last):
  File "/home/airflow/.local/lib/python3.8/site-packages/airflow/operators/python.py", line 192, in execute
    return_value = self.execute_callable()
  File "/home/airflow/.local/lib/python3.8/site-packages/airflow/operators/python.py", line 209, in execute_callable
    return self.python_callable(*self.op_args, **self.op_kwargs)
  File "/opt/airflow/dags/main.py", line 73, in main
    insert_data_to_db(products, db_params)
  File "/opt/airflow/dags/main.py", line 40, in insert_data_to_db
    with psycopg2.connect(**db_params) as conn:
  File "/home/airflow/.local/lib/python3.8/site-packages/psycopg2/__init__.py", line 122, in connect
    conn = _connect(dsn, connection_factory=connection_factory, **kwasync)
psycopg2.OperationalError: connection to server at "localhost" (127.0.0.1), port 5432 failed: Connection refused
	Is the server running on that host and accepting TCP/IP connections?
connection to server at "localhost" (::1), port 5432 failed: Cannot assign requested address
	Is the server running on that host and accepting TCP/IP connections?

[2023-12-07T17:23:20.533+0000] {taskinstance.py:1400} INFO - Marking task as FAILED. dag_id=my_scraping_dag, task_id=main_task, execution_date=20230811T000000, start_date=20231207T172319, end_date=20231207T172320
[2023-12-07T17:23:20.537+0000] {standard_task_runner.py:104} ERROR - Failed to execute job 3094 for task main_task (connection to server at "localhost" (127.0.0.1), port 5432 failed: Connection refused
	Is the server running on that host and accepting TCP/IP connections?
connection to server at "localhost" (::1), port 5432 failed: Cannot assign requested address
	Is the server running on that host and accepting TCP/IP connections?
; 9792)
[2023-12-07T17:23:20.563+0000] {local_task_job_runner.py:228} INFO - Task exited with return code 1
[2023-12-07T17:23:20.571+0000] {taskinstance.py:2778} INFO - 0 downstream tasks scheduled from follow-on schedule check
[2023-12-07T17:29:01.391+0000] {taskinstance.py:1159} INFO - Dependencies all met for dep_context=non-requeueable deps ti=<TaskInstance: my_scraping_dag.main_task scheduled__2023-08-11T00:00:00+00:00 [queued]>
[2023-12-07T17:29:01.396+0000] {taskinstance.py:1159} INFO - Dependencies all met for dep_context=requeueable deps ti=<TaskInstance: my_scraping_dag.main_task scheduled__2023-08-11T00:00:00+00:00 [queued]>
[2023-12-07T17:29:01.396+0000] {taskinstance.py:1361} INFO - Starting attempt 1 of 1
[2023-12-07T17:29:01.402+0000] {taskinstance.py:1382} INFO - Executing <Task(PythonOperator): main_task> on 2023-08-11 00:00:00+00:00
[2023-12-07T17:29:01.404+0000] {standard_task_runner.py:57} INFO - Started process 10635 to run task
[2023-12-07T17:29:01.406+0000] {standard_task_runner.py:84} INFO - Running: ['***', 'tasks', 'run', 'my_scraping_dag', 'main_task', 'scheduled__2023-08-11T00:00:00+00:00', '--job-id', '3436', '--raw', '--subdir', 'DAGS_FOLDER/main.py', '--cfg-path', '/tmp/tmpyw2a7i86']
[2023-12-07T17:29:01.408+0000] {standard_task_runner.py:85} INFO - Job 3436: Subtask main_task
[2023-12-07T17:29:01.434+0000] {task_command.py:416} INFO - Running <TaskInstance: my_scraping_dag.main_task scheduled__2023-08-11T00:00:00+00:00 [running]> on host 63b0c7e341c0
[2023-12-07T17:29:01.472+0000] {taskinstance.py:1662} INFO - Exporting env vars: AIRFLOW_CTX_DAG_OWNER='***' AIRFLOW_CTX_DAG_ID='my_scraping_dag' AIRFLOW_CTX_TASK_ID='main_task' AIRFLOW_CTX_EXECUTION_DATE='2023-08-11T00:00:00+00:00' AIRFLOW_CTX_TRY_NUMBER='1' AIRFLOW_CTX_DAG_RUN_ID='scheduled__2023-08-11T00:00:00+00:00'
[2023-12-07T17:29:02.124+0000] {taskinstance.py:1937} ERROR - Task failed with exception
Traceback (most recent call last):
  File "/home/airflow/.local/lib/python3.8/site-packages/airflow/operators/python.py", line 192, in execute
    return_value = self.execute_callable()
  File "/home/airflow/.local/lib/python3.8/site-packages/airflow/operators/python.py", line 209, in execute_callable
    return self.python_callable(*self.op_args, **self.op_kwargs)
  File "/opt/airflow/dags/main.py", line 73, in main
    insert_data_to_db(products, db_params)
  File "/opt/airflow/dags/main.py", line 40, in insert_data_to_db
    with psycopg2.connect(**db_params) as conn:
  File "/home/airflow/.local/lib/python3.8/site-packages/psycopg2/__init__.py", line 122, in connect
    conn = _connect(dsn, connection_factory=connection_factory, **kwasync)
psycopg2.OperationalError: connection to server at "localhost" (127.0.0.1), port 5432 failed: Connection refused
	Is the server running on that host and accepting TCP/IP connections?
connection to server at "localhost" (::1), port 5432 failed: Cannot assign requested address
	Is the server running on that host and accepting TCP/IP connections?

[2023-12-07T17:29:02.128+0000] {taskinstance.py:1400} INFO - Marking task as FAILED. dag_id=my_scraping_dag, task_id=main_task, execution_date=20230811T000000, start_date=20231207T172901, end_date=20231207T172902
[2023-12-07T17:29:02.133+0000] {standard_task_runner.py:104} ERROR - Failed to execute job 3436 for task main_task (connection to server at "localhost" (127.0.0.1), port 5432 failed: Connection refused
	Is the server running on that host and accepting TCP/IP connections?
connection to server at "localhost" (::1), port 5432 failed: Cannot assign requested address
	Is the server running on that host and accepting TCP/IP connections?
; 10635)
[2023-12-07T17:29:02.144+0000] {local_task_job_runner.py:228} INFO - Task exited with return code 1
[2023-12-07T17:29:02.152+0000] {taskinstance.py:2778} INFO - 0 downstream tasks scheduled from follow-on schedule check
