[2023-12-07T16:33:50.689+0000] {taskinstance.py:1159} INFO - Dependencies all met for dep_context=non-requeueable deps ti=<TaskInstance: my_scraping_dag.main_task scheduled__2023-09-08T00:00:00+00:00 [queued]>
[2023-12-07T16:33:50.695+0000] {taskinstance.py:1159} INFO - Dependencies all met for dep_context=requeueable deps ti=<TaskInstance: my_scraping_dag.main_task scheduled__2023-09-08T00:00:00+00:00 [queued]>
[2023-12-07T16:33:50.696+0000] {taskinstance.py:1361} INFO - Starting attempt 1 of 1
[2023-12-07T16:33:50.703+0000] {taskinstance.py:1382} INFO - Executing <Task(PythonOperator): main_task> on 2023-09-08 00:00:00+00:00
[2023-12-07T16:33:50.707+0000] {standard_task_runner.py:57} INFO - Started process 4079 to run task
[2023-12-07T16:33:50.709+0000] {standard_task_runner.py:84} INFO - Running: ['***', 'tasks', 'run', 'my_scraping_dag', 'main_task', 'scheduled__2023-09-08T00:00:00+00:00', '--job-id', '839', '--raw', '--subdir', 'DAGS_FOLDER/main.py', '--cfg-path', '/tmp/tmpu2sa0_0e']
[2023-12-07T16:33:50.711+0000] {standard_task_runner.py:85} INFO - Job 839: Subtask main_task
[2023-12-07T16:33:50.747+0000] {task_command.py:416} INFO - Running <TaskInstance: my_scraping_dag.main_task scheduled__2023-09-08T00:00:00+00:00 [running]> on host 63b0c7e341c0
[2023-12-07T16:33:50.795+0000] {taskinstance.py:1662} INFO - Exporting env vars: AIRFLOW_CTX_DAG_OWNER='***' AIRFLOW_CTX_DAG_ID='my_scraping_dag' AIRFLOW_CTX_TASK_ID='main_task' AIRFLOW_CTX_EXECUTION_DATE='2023-09-08T00:00:00+00:00' AIRFLOW_CTX_TRY_NUMBER='1' AIRFLOW_CTX_DAG_RUN_ID='scheduled__2023-09-08T00:00:00+00:00'
[2023-12-07T16:33:50.797+0000] {taskinstance.py:1937} ERROR - Task failed with exception
Traceback (most recent call last):
  File "/usr/local/lib/python3.8/configparser.py", line 846, in items
    d.update(self._sections[section])
KeyError: 'web'

During handling of the above exception, another exception occurred:

Traceback (most recent call last):
  File "/home/airflow/.local/lib/python3.8/site-packages/airflow/operators/python.py", line 192, in execute
    return_value = self.execute_callable()
  File "/home/airflow/.local/lib/python3.8/site-packages/airflow/operators/python.py", line 209, in execute_callable
    return self.python_callable(*self.op_args, **self.op_kwargs)
  File "/opt/airflow/dags/main.py", line 60, in main
    config = get_config('web')
  File "/opt/airflow/dags/main.py", line 22, in get_config
    return {key: value for key, value in parser.items(section)}
  File "/usr/local/lib/python3.8/configparser.py", line 849, in items
    raise NoSectionError(section)
configparser.NoSectionError: No section: 'web'
[2023-12-07T16:33:50.805+0000] {taskinstance.py:1400} INFO - Marking task as FAILED. dag_id=my_scraping_dag, task_id=main_task, execution_date=20230908T000000, start_date=20231207T163350, end_date=20231207T163350
[2023-12-07T16:33:50.818+0000] {standard_task_runner.py:104} ERROR - Failed to execute job 839 for task main_task (No section: 'web'; 4079)
[2023-12-07T16:33:50.854+0000] {local_task_job_runner.py:228} INFO - Task exited with return code 1
[2023-12-07T16:33:50.875+0000] {taskinstance.py:2778} INFO - 0 downstream tasks scheduled from follow-on schedule check
[2023-12-07T16:42:31.675+0000] {taskinstance.py:1159} INFO - Dependencies all met for dep_context=non-requeueable deps ti=<TaskInstance: my_scraping_dag.main_task scheduled__2023-09-08T00:00:00+00:00 [queued]>
[2023-12-07T16:42:31.679+0000] {taskinstance.py:1159} INFO - Dependencies all met for dep_context=requeueable deps ti=<TaskInstance: my_scraping_dag.main_task scheduled__2023-09-08T00:00:00+00:00 [queued]>
[2023-12-07T16:42:31.680+0000] {taskinstance.py:1361} INFO - Starting attempt 1 of 1
[2023-12-07T16:42:31.685+0000] {taskinstance.py:1382} INFO - Executing <Task(PythonOperator): main_task> on 2023-09-08 00:00:00+00:00
[2023-12-07T16:42:31.688+0000] {standard_task_runner.py:57} INFO - Started process 4970 to run task
[2023-12-07T16:42:31.690+0000] {standard_task_runner.py:84} INFO - Running: ['***', 'tasks', 'run', 'my_scraping_dag', 'main_task', 'scheduled__2023-09-08T00:00:00+00:00', '--job-id', '1184', '--raw', '--subdir', 'DAGS_FOLDER/main.py', '--cfg-path', '/tmp/tmphqc210vx']
[2023-12-07T16:42:31.692+0000] {standard_task_runner.py:85} INFO - Job 1184: Subtask main_task
[2023-12-07T16:42:31.716+0000] {task_command.py:416} INFO - Running <TaskInstance: my_scraping_dag.main_task scheduled__2023-09-08T00:00:00+00:00 [running]> on host 63b0c7e341c0
[2023-12-07T16:42:31.746+0000] {taskinstance.py:1662} INFO - Exporting env vars: AIRFLOW_CTX_DAG_OWNER='***' AIRFLOW_CTX_DAG_ID='my_scraping_dag' AIRFLOW_CTX_TASK_ID='main_task' AIRFLOW_CTX_EXECUTION_DATE='2023-09-08T00:00:00+00:00' AIRFLOW_CTX_TRY_NUMBER='1' AIRFLOW_CTX_DAG_RUN_ID='scheduled__2023-09-08T00:00:00+00:00'
[2023-12-07T16:42:31.747+0000] {taskinstance.py:1937} ERROR - Task failed with exception
Traceback (most recent call last):
  File "/usr/local/lib/python3.8/configparser.py", line 846, in items
    d.update(self._sections[section])
KeyError: 'web'

During handling of the above exception, another exception occurred:

Traceback (most recent call last):
  File "/home/airflow/.local/lib/python3.8/site-packages/airflow/operators/python.py", line 192, in execute
    return_value = self.execute_callable()
  File "/home/airflow/.local/lib/python3.8/site-packages/airflow/operators/python.py", line 209, in execute_callable
    return self.python_callable(*self.op_args, **self.op_kwargs)
  File "/opt/airflow/dags/main.py", line 60, in main
    config = get_config('web')
  File "/opt/airflow/dags/main.py", line 22, in get_config
    return {key: value for key, value in parser.items(section)}
  File "/usr/local/lib/python3.8/configparser.py", line 849, in items
    raise NoSectionError(section)
configparser.NoSectionError: No section: 'web'
[2023-12-07T16:42:31.752+0000] {taskinstance.py:1400} INFO - Marking task as FAILED. dag_id=my_scraping_dag, task_id=main_task, execution_date=20230908T000000, start_date=20231207T164231, end_date=20231207T164231
[2023-12-07T16:42:31.757+0000] {standard_task_runner.py:104} ERROR - Failed to execute job 1184 for task main_task (No section: 'web'; 4970)
[2023-12-07T16:42:31.782+0000] {local_task_job_runner.py:228} INFO - Task exited with return code 1
[2023-12-07T16:42:31.794+0000] {taskinstance.py:2778} INFO - 0 downstream tasks scheduled from follow-on schedule check
[2023-12-07T17:01:21.726+0000] {taskinstance.py:1159} INFO - Dependencies all met for dep_context=non-requeueable deps ti=<TaskInstance: my_scraping_dag.main_task scheduled__2023-09-08T00:00:00+00:00 [queued]>
[2023-12-07T17:01:21.730+0000] {taskinstance.py:1159} INFO - Dependencies all met for dep_context=requeueable deps ti=<TaskInstance: my_scraping_dag.main_task scheduled__2023-09-08T00:00:00+00:00 [queued]>
[2023-12-07T17:01:21.731+0000] {taskinstance.py:1361} INFO - Starting attempt 1 of 1
[2023-12-07T17:01:21.754+0000] {taskinstance.py:1382} INFO - Executing <Task(PythonOperator): main_task> on 2023-09-08 00:00:00+00:00
[2023-12-07T17:01:21.761+0000] {standard_task_runner.py:57} INFO - Started process 6378 to run task
[2023-12-07T17:01:21.763+0000] {standard_task_runner.py:84} INFO - Running: ['***', 'tasks', 'run', 'my_scraping_dag', 'main_task', 'scheduled__2023-09-08T00:00:00+00:00', '--job-id', '1656', '--raw', '--subdir', 'DAGS_FOLDER/main.py', '--cfg-path', '/tmp/tmpzdxhmobv']
[2023-12-07T17:01:21.765+0000] {standard_task_runner.py:85} INFO - Job 1656: Subtask main_task
[2023-12-07T17:01:21.805+0000] {task_command.py:416} INFO - Running <TaskInstance: my_scraping_dag.main_task scheduled__2023-09-08T00:00:00+00:00 [running]> on host 63b0c7e341c0
[2023-12-07T17:01:21.889+0000] {taskinstance.py:1662} INFO - Exporting env vars: AIRFLOW_CTX_DAG_OWNER='***' AIRFLOW_CTX_DAG_ID='my_scraping_dag' AIRFLOW_CTX_TASK_ID='main_task' AIRFLOW_CTX_EXECUTION_DATE='2023-09-08T00:00:00+00:00' AIRFLOW_CTX_TRY_NUMBER='1' AIRFLOW_CTX_DAG_RUN_ID='scheduled__2023-09-08T00:00:00+00:00'
[2023-12-07T17:01:21.921+0000] {logging_mixin.py:154} INFO - base_url: https://tuncbotanik.com
[2023-12-07T17:01:21.923+0000] {python.py:194} INFO - Done. Returned value was: ('https://tuncbotanik.com', {'User-Agent': 'Mozilla/5.0 (Macintosh; Intel Mac OS X 10_15_7) AppleWebKit/537.36 (KHTML, like Gecko) Chrome/119.0.0.0 Safari/537.36', 'Accept-Language': 'tr-TR,tr;q=0.9,en-US;q=0.8,en;q=0.7'}, {'dbname': 'plant', 'user': 'aozgokme', 'password': '***', 'host': 'localhost', 'port': '5432'})
[2023-12-07T17:01:21.945+0000] {taskinstance.py:1400} INFO - Marking task as SUCCESS. dag_id=my_scraping_dag, task_id=main_task, execution_date=20230908T000000, start_date=20231207T170121, end_date=20231207T170121
[2023-12-07T17:01:21.977+0000] {local_task_job_runner.py:228} INFO - Task exited with return code 0
[2023-12-07T17:01:22.063+0000] {taskinstance.py:2778} INFO - 0 downstream tasks scheduled from follow-on schedule check
[2023-12-07T17:04:43.456+0000] {taskinstance.py:1159} INFO - Dependencies all met for dep_context=non-requeueable deps ti=<TaskInstance: my_scraping_dag.main_task scheduled__2023-09-08T00:00:00+00:00 [queued]>
[2023-12-07T17:04:43.461+0000] {taskinstance.py:1159} INFO - Dependencies all met for dep_context=requeueable deps ti=<TaskInstance: my_scraping_dag.main_task scheduled__2023-09-08T00:00:00+00:00 [queued]>
[2023-12-07T17:04:43.462+0000] {taskinstance.py:1361} INFO - Starting attempt 1 of 1
[2023-12-07T17:04:43.493+0000] {taskinstance.py:1382} INFO - Executing <Task(PythonOperator): main_task> on 2023-09-08 00:00:00+00:00
[2023-12-07T17:04:43.495+0000] {standard_task_runner.py:57} INFO - Started process 7834 to run task
[2023-12-07T17:04:43.498+0000] {standard_task_runner.py:84} INFO - Running: ['***', 'tasks', 'run', 'my_scraping_dag', 'main_task', 'scheduled__2023-09-08T00:00:00+00:00', '--job-id', '2342', '--raw', '--subdir', 'DAGS_FOLDER/main.py', '--cfg-path', '/tmp/tmpu_6z4owj']
[2023-12-07T17:04:43.500+0000] {standard_task_runner.py:85} INFO - Job 2342: Subtask main_task
[2023-12-07T17:04:43.535+0000] {task_command.py:416} INFO - Running <TaskInstance: my_scraping_dag.main_task scheduled__2023-09-08T00:00:00+00:00 [running]> on host 63b0c7e341c0
[2023-12-07T17:04:43.584+0000] {taskinstance.py:1662} INFO - Exporting env vars: AIRFLOW_CTX_DAG_OWNER='***' AIRFLOW_CTX_DAG_ID='my_scraping_dag' AIRFLOW_CTX_TASK_ID='main_task' AIRFLOW_CTX_EXECUTION_DATE='2023-09-08T00:00:00+00:00' AIRFLOW_CTX_TRY_NUMBER='1' AIRFLOW_CTX_DAG_RUN_ID='scheduled__2023-09-08T00:00:00+00:00'
[2023-12-07T17:04:43.617+0000] {logging_mixin.py:154} INFO - base_url: https://tuncbotanik.com
[2023-12-07T17:04:43.619+0000] {python.py:194} INFO - Done. Returned value was: ('https://tuncbotanik.com', {'User-Agent': 'Mozilla/5.0 (Macintosh; Intel Mac OS X 10_15_7) AppleWebKit/537.36 (KHTML, like Gecko) Chrome/119.0.0.0 Safari/537.36', 'Accept-Language': 'tr-TR,tr;q=0.9,en-US;q=0.8,en;q=0.7'}, {'dbname': 'plant', 'user': 'aozgokme', 'password': '***', 'host': 'localhost', 'port': '5432'})
[2023-12-07T17:04:43.638+0000] {taskinstance.py:1400} INFO - Marking task as SUCCESS. dag_id=my_scraping_dag, task_id=main_task, execution_date=20230908T000000, start_date=20231207T170443, end_date=20231207T170443
[2023-12-07T17:04:43.672+0000] {local_task_job_runner.py:228} INFO - Task exited with return code 0
[2023-12-07T17:04:43.717+0000] {taskinstance.py:2778} INFO - 0 downstream tasks scheduled from follow-on schedule check
[2023-12-07T17:19:11.068+0000] {taskinstance.py:1159} INFO - Dependencies all met for dep_context=non-requeueable deps ti=<TaskInstance: my_scraping_dag.main_task scheduled__2023-09-08T00:00:00+00:00 [queued]>
[2023-12-07T17:19:11.072+0000] {taskinstance.py:1159} INFO - Dependencies all met for dep_context=requeueable deps ti=<TaskInstance: my_scraping_dag.main_task scheduled__2023-09-08T00:00:00+00:00 [queued]>
[2023-12-07T17:19:11.073+0000] {taskinstance.py:1361} INFO - Starting attempt 1 of 1
[2023-12-07T17:19:11.082+0000] {taskinstance.py:1382} INFO - Executing <Task(PythonOperator): main_task> on 2023-09-08 00:00:00+00:00
[2023-12-07T17:19:11.085+0000] {standard_task_runner.py:57} INFO - Started process 9061 to run task
[2023-12-07T17:19:11.087+0000] {standard_task_runner.py:84} INFO - Running: ['***', 'tasks', 'run', 'my_scraping_dag', 'main_task', 'scheduled__2023-09-08T00:00:00+00:00', '--job-id', '2780', '--raw', '--subdir', 'DAGS_FOLDER/main.py', '--cfg-path', '/tmp/tmpwlurs3cn']
[2023-12-07T17:19:11.089+0000] {standard_task_runner.py:85} INFO - Job 2780: Subtask main_task
[2023-12-07T17:19:11.114+0000] {task_command.py:416} INFO - Running <TaskInstance: my_scraping_dag.main_task scheduled__2023-09-08T00:00:00+00:00 [running]> on host 63b0c7e341c0
[2023-12-07T17:19:11.152+0000] {taskinstance.py:1662} INFO - Exporting env vars: AIRFLOW_CTX_DAG_OWNER='***' AIRFLOW_CTX_DAG_ID='my_scraping_dag' AIRFLOW_CTX_TASK_ID='main_task' AIRFLOW_CTX_EXECUTION_DATE='2023-09-08T00:00:00+00:00' AIRFLOW_CTX_TRY_NUMBER='1' AIRFLOW_CTX_DAG_RUN_ID='scheduled__2023-09-08T00:00:00+00:00'
[2023-12-07T17:19:11.880+0000] {taskinstance.py:1937} ERROR - Task failed with exception
Traceback (most recent call last):
  File "/home/airflow/.local/lib/python3.8/site-packages/airflow/operators/python.py", line 192, in execute
    return_value = self.execute_callable()
  File "/home/airflow/.local/lib/python3.8/site-packages/airflow/operators/python.py", line 209, in execute_callable
    return self.python_callable(*self.op_args, **self.op_kwargs)
  File "/opt/airflow/dags/main.py", line 80, in main
    insert_data_to_db(products, db_params)
  File "/opt/airflow/dags/main.py", line 43, in insert_data_to_db
    with psycopg2.connect(**db_params) as conn:
  File "/home/airflow/.local/lib/python3.8/site-packages/psycopg2/__init__.py", line 122, in connect
    conn = _connect(dsn, connection_factory=connection_factory, **kwasync)
psycopg2.OperationalError: connection to server at "localhost" (127.0.0.1), port 5432 failed: Connection refused
	Is the server running on that host and accepting TCP/IP connections?
connection to server at "localhost" (::1), port 5432 failed: Cannot assign requested address
	Is the server running on that host and accepting TCP/IP connections?

[2023-12-07T17:19:11.895+0000] {taskinstance.py:1400} INFO - Marking task as FAILED. dag_id=my_scraping_dag, task_id=main_task, execution_date=20230908T000000, start_date=20231207T171911, end_date=20231207T171911
[2023-12-07T17:19:11.934+0000] {standard_task_runner.py:104} ERROR - Failed to execute job 2780 for task main_task (connection to server at "localhost" (127.0.0.1), port 5432 failed: Connection refused
	Is the server running on that host and accepting TCP/IP connections?
connection to server at "localhost" (::1), port 5432 failed: Cannot assign requested address
	Is the server running on that host and accepting TCP/IP connections?
; 9061)
[2023-12-07T17:19:11.982+0000] {local_task_job_runner.py:228} INFO - Task exited with return code 1
[2023-12-07T17:19:11.995+0000] {taskinstance.py:2778} INFO - 0 downstream tasks scheduled from follow-on schedule check
[2023-12-07T17:23:28.489+0000] {taskinstance.py:1159} INFO - Dependencies all met for dep_context=non-requeueable deps ti=<TaskInstance: my_scraping_dag.main_task scheduled__2023-09-08T00:00:00+00:00 [queued]>
[2023-12-07T17:23:28.504+0000] {taskinstance.py:1159} INFO - Dependencies all met for dep_context=requeueable deps ti=<TaskInstance: my_scraping_dag.main_task scheduled__2023-09-08T00:00:00+00:00 [queued]>
[2023-12-07T17:23:28.505+0000] {taskinstance.py:1361} INFO - Starting attempt 1 of 1
[2023-12-07T17:23:28.524+0000] {taskinstance.py:1382} INFO - Executing <Task(PythonOperator): main_task> on 2023-09-08 00:00:00+00:00
[2023-12-07T17:23:28.534+0000] {standard_task_runner.py:57} INFO - Started process 9863 to run task
[2023-12-07T17:23:28.539+0000] {standard_task_runner.py:84} INFO - Running: ['***', 'tasks', 'run', 'my_scraping_dag', 'main_task', 'scheduled__2023-09-08T00:00:00+00:00', '--job-id', '3122', '--raw', '--subdir', 'DAGS_FOLDER/main.py', '--cfg-path', '/tmp/tmp8rn863wp']
[2023-12-07T17:23:28.544+0000] {standard_task_runner.py:85} INFO - Job 3122: Subtask main_task
[2023-12-07T17:23:28.591+0000] {task_command.py:416} INFO - Running <TaskInstance: my_scraping_dag.main_task scheduled__2023-09-08T00:00:00+00:00 [running]> on host 63b0c7e341c0
[2023-12-07T17:23:28.638+0000] {taskinstance.py:1662} INFO - Exporting env vars: AIRFLOW_CTX_DAG_OWNER='***' AIRFLOW_CTX_DAG_ID='my_scraping_dag' AIRFLOW_CTX_TASK_ID='main_task' AIRFLOW_CTX_EXECUTION_DATE='2023-09-08T00:00:00+00:00' AIRFLOW_CTX_TRY_NUMBER='1' AIRFLOW_CTX_DAG_RUN_ID='scheduled__2023-09-08T00:00:00+00:00'
[2023-12-07T17:23:29.318+0000] {taskinstance.py:1937} ERROR - Task failed with exception
Traceback (most recent call last):
  File "/home/airflow/.local/lib/python3.8/site-packages/airflow/operators/python.py", line 192, in execute
    return_value = self.execute_callable()
  File "/home/airflow/.local/lib/python3.8/site-packages/airflow/operators/python.py", line 209, in execute_callable
    return self.python_callable(*self.op_args, **self.op_kwargs)
  File "/opt/airflow/dags/main.py", line 73, in main
    insert_data_to_db(products, db_params)
  File "/opt/airflow/dags/main.py", line 40, in insert_data_to_db
    with psycopg2.connect(**db_params) as conn:
  File "/home/airflow/.local/lib/python3.8/site-packages/psycopg2/__init__.py", line 122, in connect
    conn = _connect(dsn, connection_factory=connection_factory, **kwasync)
psycopg2.OperationalError: connection to server at "localhost" (127.0.0.1), port 5432 failed: Connection refused
	Is the server running on that host and accepting TCP/IP connections?
connection to server at "localhost" (::1), port 5432 failed: Cannot assign requested address
	Is the server running on that host and accepting TCP/IP connections?

[2023-12-07T17:23:29.323+0000] {taskinstance.py:1400} INFO - Marking task as FAILED. dag_id=my_scraping_dag, task_id=main_task, execution_date=20230908T000000, start_date=20231207T172328, end_date=20231207T172329
[2023-12-07T17:23:29.328+0000] {standard_task_runner.py:104} ERROR - Failed to execute job 3122 for task main_task (connection to server at "localhost" (127.0.0.1), port 5432 failed: Connection refused
	Is the server running on that host and accepting TCP/IP connections?
connection to server at "localhost" (::1), port 5432 failed: Cannot assign requested address
	Is the server running on that host and accepting TCP/IP connections?
; 9863)
[2023-12-07T17:23:29.368+0000] {local_task_job_runner.py:228} INFO - Task exited with return code 1
[2023-12-07T17:23:29.376+0000] {taskinstance.py:2778} INFO - 0 downstream tasks scheduled from follow-on schedule check
[2023-12-07T17:29:07.352+0000] {taskinstance.py:1159} INFO - Dependencies all met for dep_context=non-requeueable deps ti=<TaskInstance: my_scraping_dag.main_task scheduled__2023-09-08T00:00:00+00:00 [queued]>
[2023-12-07T17:29:07.358+0000] {taskinstance.py:1159} INFO - Dependencies all met for dep_context=requeueable deps ti=<TaskInstance: my_scraping_dag.main_task scheduled__2023-09-08T00:00:00+00:00 [queued]>
[2023-12-07T17:29:07.359+0000] {taskinstance.py:1361} INFO - Starting attempt 1 of 1
[2023-12-07T17:29:07.405+0000] {taskinstance.py:1382} INFO - Executing <Task(PythonOperator): main_task> on 2023-09-08 00:00:00+00:00
[2023-12-07T17:29:07.410+0000] {standard_task_runner.py:57} INFO - Started process 10693 to run task
[2023-12-07T17:29:07.417+0000] {standard_task_runner.py:84} INFO - Running: ['***', 'tasks', 'run', 'my_scraping_dag', 'main_task', 'scheduled__2023-09-08T00:00:00+00:00', '--job-id', '3464', '--raw', '--subdir', 'DAGS_FOLDER/main.py', '--cfg-path', '/tmp/tmpbbs77oxt']
[2023-12-07T17:29:07.424+0000] {standard_task_runner.py:85} INFO - Job 3464: Subtask main_task
[2023-12-07T17:29:07.481+0000] {task_command.py:416} INFO - Running <TaskInstance: my_scraping_dag.main_task scheduled__2023-09-08T00:00:00+00:00 [running]> on host 63b0c7e341c0
[2023-12-07T17:29:07.559+0000] {taskinstance.py:1662} INFO - Exporting env vars: AIRFLOW_CTX_DAG_OWNER='***' AIRFLOW_CTX_DAG_ID='my_scraping_dag' AIRFLOW_CTX_TASK_ID='main_task' AIRFLOW_CTX_EXECUTION_DATE='2023-09-08T00:00:00+00:00' AIRFLOW_CTX_TRY_NUMBER='1' AIRFLOW_CTX_DAG_RUN_ID='scheduled__2023-09-08T00:00:00+00:00'
[2023-12-07T17:29:08.201+0000] {taskinstance.py:1937} ERROR - Task failed with exception
Traceback (most recent call last):
  File "/home/airflow/.local/lib/python3.8/site-packages/airflow/operators/python.py", line 192, in execute
    return_value = self.execute_callable()
  File "/home/airflow/.local/lib/python3.8/site-packages/airflow/operators/python.py", line 209, in execute_callable
    return self.python_callable(*self.op_args, **self.op_kwargs)
  File "/opt/airflow/dags/main.py", line 73, in main
    insert_data_to_db(products, db_params)
  File "/opt/airflow/dags/main.py", line 40, in insert_data_to_db
    with psycopg2.connect(**db_params) as conn:
  File "/home/airflow/.local/lib/python3.8/site-packages/psycopg2/__init__.py", line 122, in connect
    conn = _connect(dsn, connection_factory=connection_factory, **kwasync)
psycopg2.OperationalError: connection to server at "localhost" (127.0.0.1), port 5432 failed: Connection refused
	Is the server running on that host and accepting TCP/IP connections?
connection to server at "localhost" (::1), port 5432 failed: Cannot assign requested address
	Is the server running on that host and accepting TCP/IP connections?

[2023-12-07T17:29:08.206+0000] {taskinstance.py:1400} INFO - Marking task as FAILED. dag_id=my_scraping_dag, task_id=main_task, execution_date=20230908T000000, start_date=20231207T172907, end_date=20231207T172908
[2023-12-07T17:29:08.211+0000] {standard_task_runner.py:104} ERROR - Failed to execute job 3464 for task main_task (connection to server at "localhost" (127.0.0.1), port 5432 failed: Connection refused
	Is the server running on that host and accepting TCP/IP connections?
connection to server at "localhost" (::1), port 5432 failed: Cannot assign requested address
	Is the server running on that host and accepting TCP/IP connections?
; 10693)
[2023-12-07T17:29:08.237+0000] {local_task_job_runner.py:228} INFO - Task exited with return code 1
[2023-12-07T17:29:08.246+0000] {taskinstance.py:2778} INFO - 0 downstream tasks scheduled from follow-on schedule check
[2023-12-09T07:35:18.814+0000] {taskinstance.py:1159} INFO - Dependencies all met for dep_context=non-requeueable deps ti=<TaskInstance: my_scraping_dag.main_task scheduled__2023-09-08T00:00:00+00:00 [queued]>
[2023-12-09T07:35:18.825+0000] {taskinstance.py:1159} INFO - Dependencies all met for dep_context=requeueable deps ti=<TaskInstance: my_scraping_dag.main_task scheduled__2023-09-08T00:00:00+00:00 [queued]>
[2023-12-09T07:35:18.826+0000] {taskinstance.py:1361} INFO - Starting attempt 1 of 1
[2023-12-09T07:35:18.838+0000] {taskinstance.py:1382} INFO - Executing <Task(PythonOperator): main_task> on 2023-09-08 00:00:00+00:00
[2023-12-09T07:35:18.841+0000] {standard_task_runner.py:57} INFO - Started process 1118 to run task
[2023-12-09T07:35:18.844+0000] {standard_task_runner.py:84} INFO - Running: ['***', 'tasks', 'run', 'my_scraping_dag', 'main_task', 'scheduled__2023-09-08T00:00:00+00:00', '--job-id', '254', '--raw', '--subdir', 'DAGS_FOLDER/main.py', '--cfg-path', '/tmp/tmpp6av3d6k']
[2023-12-09T07:35:18.847+0000] {standard_task_runner.py:85} INFO - Job 254: Subtask main_task
[2023-12-09T07:35:18.895+0000] {task_command.py:416} INFO - Running <TaskInstance: my_scraping_dag.main_task scheduled__2023-09-08T00:00:00+00:00 [running]> on host 36b5ef2505c9
[2023-12-09T07:35:18.972+0000] {taskinstance.py:1662} INFO - Exporting env vars: AIRFLOW_CTX_DAG_OWNER='***' AIRFLOW_CTX_DAG_ID='my_scraping_dag' AIRFLOW_CTX_TASK_ID='main_task' AIRFLOW_CTX_EXECUTION_DATE='2023-09-08T00:00:00+00:00' AIRFLOW_CTX_TRY_NUMBER='1' AIRFLOW_CTX_DAG_RUN_ID='scheduled__2023-09-08T00:00:00+00:00'
[2023-12-09T07:35:18.981+0000] {taskinstance.py:1937} ERROR - Task failed with exception
Traceback (most recent call last):
  File "/home/airflow/.local/lib/python3.8/site-packages/airflow/operators/python.py", line 192, in execute
    return_value = self.execute_callable()
  File "/home/airflow/.local/lib/python3.8/site-packages/airflow/operators/python.py", line 209, in execute_callable
    return self.python_callable(*self.op_args, **self.op_kwargs)
  File "/opt/airflow/dags/main.py", line 64, in main
    base_url = Variable.get('base_url')
  File "/home/airflow/.local/lib/python3.8/site-packages/airflow/models/variable.py", line 140, in get
    raise KeyError(f"Variable {key} does not exist")
KeyError: 'Variable base_url does not exist'
[2023-12-09T07:35:18.993+0000] {taskinstance.py:1400} INFO - Marking task as FAILED. dag_id=my_scraping_dag, task_id=main_task, execution_date=20230908T000000, start_date=20231209T073518, end_date=20231209T073518
[2023-12-09T07:35:19.007+0000] {standard_task_runner.py:104} ERROR - Failed to execute job 254 for task main_task ('Variable base_url does not exist'; 1118)
[2023-12-09T07:35:19.020+0000] {local_task_job_runner.py:228} INFO - Task exited with return code 1
[2023-12-09T07:35:19.032+0000] {taskinstance.py:2778} INFO - 0 downstream tasks scheduled from follow-on schedule check
