[2023-12-07T14:53:02.696+0000] {taskinstance.py:1159} INFO - Dependencies all met for dep_context=non-requeueable deps ti=<TaskInstance: my_scraping_dag.main_task scheduled__2023-07-12T00:00:00+00:00 [queued]>
[2023-12-07T14:53:02.704+0000] {taskinstance.py:1159} INFO - Dependencies all met for dep_context=requeueable deps ti=<TaskInstance: my_scraping_dag.main_task scheduled__2023-07-12T00:00:00+00:00 [queued]>
[2023-12-07T14:53:02.705+0000] {taskinstance.py:1361} INFO - Starting attempt 1 of 1
[2023-12-07T14:53:02.715+0000] {taskinstance.py:1382} INFO - Executing <Task(PythonOperator): main_task> on 2023-07-12 00:00:00+00:00
[2023-12-07T14:53:02.718+0000] {standard_task_runner.py:57} INFO - Started process 1164 to run task
[2023-12-07T14:53:02.721+0000] {standard_task_runner.py:84} INFO - Running: ['***', 'tasks', 'run', 'my_scraping_dag', 'main_task', 'scheduled__2023-07-12T00:00:00+00:00', '--job-id', '303', '--raw', '--subdir', 'DAGS_FOLDER/main.py', '--cfg-path', '/tmp/tmpihorhgrx']
[2023-12-07T14:53:02.724+0000] {standard_task_runner.py:85} INFO - Job 303: Subtask main_task
[2023-12-07T14:53:02.763+0000] {task_command.py:416} INFO - Running <TaskInstance: my_scraping_dag.main_task scheduled__2023-07-12T00:00:00+00:00 [running]> on host 63b0c7e341c0
[2023-12-07T14:53:02.817+0000] {taskinstance.py:1662} INFO - Exporting env vars: AIRFLOW_CTX_DAG_OWNER='***' AIRFLOW_CTX_DAG_ID='my_scraping_dag' AIRFLOW_CTX_TASK_ID='main_task' AIRFLOW_CTX_EXECUTION_DATE='2023-07-12T00:00:00+00:00' AIRFLOW_CTX_TRY_NUMBER='1' AIRFLOW_CTX_DAG_RUN_ID='scheduled__2023-07-12T00:00:00+00:00'
[2023-12-07T14:53:02.819+0000] {taskinstance.py:1937} ERROR - Task failed with exception
Traceback (most recent call last):
  File "/usr/local/lib/python3.8/configparser.py", line 846, in items
    d.update(self._sections[section])
KeyError: 'web'

During handling of the above exception, another exception occurred:

Traceback (most recent call last):
  File "/home/airflow/.local/lib/python3.8/site-packages/airflow/operators/python.py", line 192, in execute
    return_value = self.execute_callable()
  File "/home/airflow/.local/lib/python3.8/site-packages/airflow/operators/python.py", line 209, in execute_callable
    return self.python_callable(*self.op_args, **self.op_kwargs)
  File "/opt/airflow/dags/main.py", line 61, in main
    config = get_config('web')
  File "/opt/airflow/dags/main.py", line 23, in get_config
    return {key: value for key, value in parser.items(section)}
  File "/usr/local/lib/python3.8/configparser.py", line 849, in items
    raise NoSectionError(section)
configparser.NoSectionError: No section: 'web'
[2023-12-07T14:53:02.825+0000] {taskinstance.py:1400} INFO - Marking task as FAILED. dag_id=my_scraping_dag, task_id=main_task, execution_date=20230712T000000, start_date=20231207T145302, end_date=20231207T145302
[2023-12-07T14:53:02.856+0000] {standard_task_runner.py:104} ERROR - Failed to execute job 303 for task main_task (No section: 'web'; 1164)
[2023-12-07T14:53:02.893+0000] {local_task_job_runner.py:228} INFO - Task exited with return code 1
[2023-12-07T14:53:02.913+0000] {taskinstance.py:2778} INFO - 0 downstream tasks scheduled from follow-on schedule check
[2023-12-07T16:33:01.786+0000] {taskinstance.py:1159} INFO - Dependencies all met for dep_context=non-requeueable deps ti=<TaskInstance: my_scraping_dag.main_task scheduled__2023-07-12T00:00:00+00:00 [queued]>
[2023-12-07T16:33:01.790+0000] {taskinstance.py:1159} INFO - Dependencies all met for dep_context=requeueable deps ti=<TaskInstance: my_scraping_dag.main_task scheduled__2023-07-12T00:00:00+00:00 [queued]>
[2023-12-07T16:33:01.791+0000] {taskinstance.py:1361} INFO - Starting attempt 1 of 1
[2023-12-07T16:33:01.797+0000] {taskinstance.py:1382} INFO - Executing <Task(PythonOperator): main_task> on 2023-07-12 00:00:00+00:00
[2023-12-07T16:33:01.799+0000] {standard_task_runner.py:57} INFO - Started process 3937 to run task
[2023-12-07T16:33:01.801+0000] {standard_task_runner.py:84} INFO - Running: ['***', 'tasks', 'run', 'my_scraping_dag', 'main_task', 'scheduled__2023-07-12T00:00:00+00:00', '--job-id', '781', '--raw', '--subdir', 'DAGS_FOLDER/main.py', '--cfg-path', '/tmp/tmp6m6o7pjt']
[2023-12-07T16:33:01.803+0000] {standard_task_runner.py:85} INFO - Job 781: Subtask main_task
[2023-12-07T16:33:01.825+0000] {task_command.py:416} INFO - Running <TaskInstance: my_scraping_dag.main_task scheduled__2023-07-12T00:00:00+00:00 [running]> on host 63b0c7e341c0
[2023-12-07T16:33:01.862+0000] {taskinstance.py:1662} INFO - Exporting env vars: AIRFLOW_CTX_DAG_OWNER='***' AIRFLOW_CTX_DAG_ID='my_scraping_dag' AIRFLOW_CTX_TASK_ID='main_task' AIRFLOW_CTX_EXECUTION_DATE='2023-07-12T00:00:00+00:00' AIRFLOW_CTX_TRY_NUMBER='1' AIRFLOW_CTX_DAG_RUN_ID='scheduled__2023-07-12T00:00:00+00:00'
[2023-12-07T16:33:01.863+0000] {taskinstance.py:1937} ERROR - Task failed with exception
Traceback (most recent call last):
  File "/usr/local/lib/python3.8/configparser.py", line 846, in items
    d.update(self._sections[section])
KeyError: 'web'

During handling of the above exception, another exception occurred:

Traceback (most recent call last):
  File "/home/airflow/.local/lib/python3.8/site-packages/airflow/operators/python.py", line 192, in execute
    return_value = self.execute_callable()
  File "/home/airflow/.local/lib/python3.8/site-packages/airflow/operators/python.py", line 209, in execute_callable
    return self.python_callable(*self.op_args, **self.op_kwargs)
  File "/opt/airflow/dags/main.py", line 60, in main
    config = get_config('web')
  File "/opt/airflow/dags/main.py", line 22, in get_config
    return {key: value for key, value in parser.items(section)}
  File "/usr/local/lib/python3.8/configparser.py", line 849, in items
    raise NoSectionError(section)
configparser.NoSectionError: No section: 'web'
[2023-12-07T16:33:01.867+0000] {taskinstance.py:1400} INFO - Marking task as FAILED. dag_id=my_scraping_dag, task_id=main_task, execution_date=20230712T000000, start_date=20231207T163301, end_date=20231207T163301
[2023-12-07T16:33:01.872+0000] {standard_task_runner.py:104} ERROR - Failed to execute job 781 for task main_task (No section: 'web'; 3937)
[2023-12-07T16:33:01.893+0000] {local_task_job_runner.py:228} INFO - Task exited with return code 1
[2023-12-07T16:33:01.905+0000] {taskinstance.py:2778} INFO - 0 downstream tasks scheduled from follow-on schedule check
[2023-12-07T16:42:07.311+0000] {taskinstance.py:1159} INFO - Dependencies all met for dep_context=non-requeueable deps ti=<TaskInstance: my_scraping_dag.main_task scheduled__2023-07-12T00:00:00+00:00 [queued]>
[2023-12-07T16:42:07.316+0000] {taskinstance.py:1159} INFO - Dependencies all met for dep_context=requeueable deps ti=<TaskInstance: my_scraping_dag.main_task scheduled__2023-07-12T00:00:00+00:00 [queued]>
[2023-12-07T16:42:07.316+0000] {taskinstance.py:1361} INFO - Starting attempt 1 of 1
[2023-12-07T16:42:07.323+0000] {taskinstance.py:1382} INFO - Executing <Task(PythonOperator): main_task> on 2023-07-12 00:00:00+00:00
[2023-12-07T16:42:07.326+0000] {standard_task_runner.py:57} INFO - Started process 4843 to run task
[2023-12-07T16:42:07.328+0000] {standard_task_runner.py:84} INFO - Running: ['***', 'tasks', 'run', 'my_scraping_dag', 'main_task', 'scheduled__2023-07-12T00:00:00+00:00', '--job-id', '1126', '--raw', '--subdir', 'DAGS_FOLDER/main.py', '--cfg-path', '/tmp/tmpbaxunotg']
[2023-12-07T16:42:07.330+0000] {standard_task_runner.py:85} INFO - Job 1126: Subtask main_task
[2023-12-07T16:42:07.355+0000] {task_command.py:416} INFO - Running <TaskInstance: my_scraping_dag.main_task scheduled__2023-07-12T00:00:00+00:00 [running]> on host 63b0c7e341c0
[2023-12-07T16:42:07.393+0000] {taskinstance.py:1662} INFO - Exporting env vars: AIRFLOW_CTX_DAG_OWNER='***' AIRFLOW_CTX_DAG_ID='my_scraping_dag' AIRFLOW_CTX_TASK_ID='main_task' AIRFLOW_CTX_EXECUTION_DATE='2023-07-12T00:00:00+00:00' AIRFLOW_CTX_TRY_NUMBER='1' AIRFLOW_CTX_DAG_RUN_ID='scheduled__2023-07-12T00:00:00+00:00'
[2023-12-07T16:42:07.394+0000] {taskinstance.py:1937} ERROR - Task failed with exception
Traceback (most recent call last):
  File "/usr/local/lib/python3.8/configparser.py", line 846, in items
    d.update(self._sections[section])
KeyError: 'web'

During handling of the above exception, another exception occurred:

Traceback (most recent call last):
  File "/home/airflow/.local/lib/python3.8/site-packages/airflow/operators/python.py", line 192, in execute
    return_value = self.execute_callable()
  File "/home/airflow/.local/lib/python3.8/site-packages/airflow/operators/python.py", line 209, in execute_callable
    return self.python_callable(*self.op_args, **self.op_kwargs)
  File "/opt/airflow/dags/main.py", line 60, in main
    config = get_config('web')
  File "/opt/airflow/dags/main.py", line 22, in get_config
    return {key: value for key, value in parser.items(section)}
  File "/usr/local/lib/python3.8/configparser.py", line 849, in items
    raise NoSectionError(section)
configparser.NoSectionError: No section: 'web'
[2023-12-07T16:42:07.399+0000] {taskinstance.py:1400} INFO - Marking task as FAILED. dag_id=my_scraping_dag, task_id=main_task, execution_date=20230712T000000, start_date=20231207T164207, end_date=20231207T164207
[2023-12-07T16:42:07.404+0000] {standard_task_runner.py:104} ERROR - Failed to execute job 1126 for task main_task (No section: 'web'; 4843)
[2023-12-07T16:42:07.420+0000] {local_task_job_runner.py:228} INFO - Task exited with return code 1
[2023-12-07T16:42:07.433+0000] {taskinstance.py:2778} INFO - 0 downstream tasks scheduled from follow-on schedule check
[2023-12-07T17:01:03.359+0000] {taskinstance.py:1159} INFO - Dependencies all met for dep_context=non-requeueable deps ti=<TaskInstance: my_scraping_dag.main_task scheduled__2023-07-12T00:00:00+00:00 [queued]>
[2023-12-07T17:01:03.364+0000] {taskinstance.py:1159} INFO - Dependencies all met for dep_context=requeueable deps ti=<TaskInstance: my_scraping_dag.main_task scheduled__2023-07-12T00:00:00+00:00 [queued]>
[2023-12-07T17:01:03.365+0000] {taskinstance.py:1361} INFO - Starting attempt 1 of 1
[2023-12-07T17:01:03.415+0000] {taskinstance.py:1382} INFO - Executing <Task(PythonOperator): main_task> on 2023-07-12 00:00:00+00:00
[2023-12-07T17:01:03.418+0000] {standard_task_runner.py:57} INFO - Started process 6137 to run task
[2023-12-07T17:01:03.421+0000] {standard_task_runner.py:84} INFO - Running: ['***', 'tasks', 'run', 'my_scraping_dag', 'main_task', 'scheduled__2023-07-12T00:00:00+00:00', '--job-id', '1541', '--raw', '--subdir', 'DAGS_FOLDER/main.py', '--cfg-path', '/tmp/tmp54c5p70o']
[2023-12-07T17:01:03.426+0000] {standard_task_runner.py:85} INFO - Job 1541: Subtask main_task
[2023-12-07T17:01:03.480+0000] {task_command.py:416} INFO - Running <TaskInstance: my_scraping_dag.main_task scheduled__2023-07-12T00:00:00+00:00 [running]> on host 63b0c7e341c0
[2023-12-07T17:01:03.548+0000] {taskinstance.py:1662} INFO - Exporting env vars: AIRFLOW_CTX_DAG_OWNER='***' AIRFLOW_CTX_DAG_ID='my_scraping_dag' AIRFLOW_CTX_TASK_ID='main_task' AIRFLOW_CTX_EXECUTION_DATE='2023-07-12T00:00:00+00:00' AIRFLOW_CTX_TRY_NUMBER='1' AIRFLOW_CTX_DAG_RUN_ID='scheduled__2023-07-12T00:00:00+00:00'
[2023-12-07T17:01:03.586+0000] {logging_mixin.py:154} INFO - base_url: https://tuncbotanik.com
[2023-12-07T17:01:03.588+0000] {python.py:194} INFO - Done. Returned value was: ('https://tuncbotanik.com', {'User-Agent': 'Mozilla/5.0 (Macintosh; Intel Mac OS X 10_15_7) AppleWebKit/537.36 (KHTML, like Gecko) Chrome/119.0.0.0 Safari/537.36', 'Accept-Language': 'tr-TR,tr;q=0.9,en-US;q=0.8,en;q=0.7'}, {'dbname': 'plant', 'user': 'aozgokme', 'password': '***', 'host': 'localhost', 'port': '5432'})
[2023-12-07T17:01:03.614+0000] {taskinstance.py:1400} INFO - Marking task as SUCCESS. dag_id=my_scraping_dag, task_id=main_task, execution_date=20230712T000000, start_date=20231207T170103, end_date=20231207T170103
[2023-12-07T17:01:03.639+0000] {local_task_job_runner.py:228} INFO - Task exited with return code 0
[2023-12-07T17:01:03.697+0000] {taskinstance.py:2778} INFO - 0 downstream tasks scheduled from follow-on schedule check
[2023-12-07T17:04:18.921+0000] {taskinstance.py:1159} INFO - Dependencies all met for dep_context=non-requeueable deps ti=<TaskInstance: my_scraping_dag.main_task scheduled__2023-07-12T00:00:00+00:00 [queued]>
[2023-12-07T17:04:18.925+0000] {taskinstance.py:1159} INFO - Dependencies all met for dep_context=requeueable deps ti=<TaskInstance: my_scraping_dag.main_task scheduled__2023-07-12T00:00:00+00:00 [queued]>
[2023-12-07T17:04:18.927+0000] {taskinstance.py:1361} INFO - Starting attempt 1 of 1
[2023-12-07T17:04:18.953+0000] {taskinstance.py:1382} INFO - Executing <Task(PythonOperator): main_task> on 2023-07-12 00:00:00+00:00
[2023-12-07T17:04:18.958+0000] {standard_task_runner.py:57} INFO - Started process 7588 to run task
[2023-12-07T17:04:18.960+0000] {standard_task_runner.py:84} INFO - Running: ['***', 'tasks', 'run', 'my_scraping_dag', 'main_task', 'scheduled__2023-07-12T00:00:00+00:00', '--job-id', '2224', '--raw', '--subdir', 'DAGS_FOLDER/main.py', '--cfg-path', '/tmp/tmpw0yu76eb']
[2023-12-07T17:04:18.962+0000] {standard_task_runner.py:85} INFO - Job 2224: Subtask main_task
[2023-12-07T17:04:19.000+0000] {task_command.py:416} INFO - Running <TaskInstance: my_scraping_dag.main_task scheduled__2023-07-12T00:00:00+00:00 [running]> on host 63b0c7e341c0
[2023-12-07T17:04:19.055+0000] {taskinstance.py:1662} INFO - Exporting env vars: AIRFLOW_CTX_DAG_OWNER='***' AIRFLOW_CTX_DAG_ID='my_scraping_dag' AIRFLOW_CTX_TASK_ID='main_task' AIRFLOW_CTX_EXECUTION_DATE='2023-07-12T00:00:00+00:00' AIRFLOW_CTX_TRY_NUMBER='1' AIRFLOW_CTX_DAG_RUN_ID='scheduled__2023-07-12T00:00:00+00:00'
[2023-12-07T17:04:19.091+0000] {logging_mixin.py:154} INFO - base_url: https://tuncbotanik.com
[2023-12-07T17:04:19.092+0000] {python.py:194} INFO - Done. Returned value was: ('https://tuncbotanik.com', {'User-Agent': 'Mozilla/5.0 (Macintosh; Intel Mac OS X 10_15_7) AppleWebKit/537.36 (KHTML, like Gecko) Chrome/119.0.0.0 Safari/537.36', 'Accept-Language': 'tr-TR,tr;q=0.9,en-US;q=0.8,en;q=0.7'}, {'dbname': 'plant', 'user': 'aozgokme', 'password': '***', 'host': 'localhost', 'port': '5432'})
[2023-12-07T17:04:19.105+0000] {taskinstance.py:1400} INFO - Marking task as SUCCESS. dag_id=my_scraping_dag, task_id=main_task, execution_date=20230712T000000, start_date=20231207T170418, end_date=20231207T170419
[2023-12-07T17:04:19.181+0000] {local_task_job_runner.py:228} INFO - Task exited with return code 0
[2023-12-07T17:04:19.246+0000] {taskinstance.py:2778} INFO - 0 downstream tasks scheduled from follow-on schedule check
[2023-12-07T17:18:57.923+0000] {taskinstance.py:1159} INFO - Dependencies all met for dep_context=non-requeueable deps ti=<TaskInstance: my_scraping_dag.main_task scheduled__2023-07-12T00:00:00+00:00 [queued]>
[2023-12-07T17:18:57.927+0000] {taskinstance.py:1159} INFO - Dependencies all met for dep_context=requeueable deps ti=<TaskInstance: my_scraping_dag.main_task scheduled__2023-07-12T00:00:00+00:00 [queued]>
[2023-12-07T17:18:57.928+0000] {taskinstance.py:1361} INFO - Starting attempt 1 of 1
[2023-12-07T17:18:57.957+0000] {taskinstance.py:1382} INFO - Executing <Task(PythonOperator): main_task> on 2023-07-12 00:00:00+00:00
[2023-12-07T17:18:57.960+0000] {standard_task_runner.py:57} INFO - Started process 8939 to run task
[2023-12-07T17:18:57.962+0000] {standard_task_runner.py:84} INFO - Running: ['***', 'tasks', 'run', 'my_scraping_dag', 'main_task', 'scheduled__2023-07-12T00:00:00+00:00', '--job-id', '2722', '--raw', '--subdir', 'DAGS_FOLDER/main.py', '--cfg-path', '/tmp/tmp8tyb9wle']
[2023-12-07T17:18:57.964+0000] {standard_task_runner.py:85} INFO - Job 2722: Subtask main_task
[2023-12-07T17:18:57.993+0000] {task_command.py:416} INFO - Running <TaskInstance: my_scraping_dag.main_task scheduled__2023-07-12T00:00:00+00:00 [running]> on host 63b0c7e341c0
[2023-12-07T17:18:58.028+0000] {taskinstance.py:1662} INFO - Exporting env vars: AIRFLOW_CTX_DAG_OWNER='***' AIRFLOW_CTX_DAG_ID='my_scraping_dag' AIRFLOW_CTX_TASK_ID='main_task' AIRFLOW_CTX_EXECUTION_DATE='2023-07-12T00:00:00+00:00' AIRFLOW_CTX_TRY_NUMBER='1' AIRFLOW_CTX_DAG_RUN_ID='scheduled__2023-07-12T00:00:00+00:00'
[2023-12-07T17:18:58.796+0000] {taskinstance.py:1937} ERROR - Task failed with exception
Traceback (most recent call last):
  File "/home/airflow/.local/lib/python3.8/site-packages/airflow/operators/python.py", line 192, in execute
    return_value = self.execute_callable()
  File "/home/airflow/.local/lib/python3.8/site-packages/airflow/operators/python.py", line 209, in execute_callable
    return self.python_callable(*self.op_args, **self.op_kwargs)
  File "/opt/airflow/dags/main.py", line 80, in main
    insert_data_to_db(products, db_params)
  File "/opt/airflow/dags/main.py", line 43, in insert_data_to_db
    with psycopg2.connect(**db_params) as conn:
  File "/home/airflow/.local/lib/python3.8/site-packages/psycopg2/__init__.py", line 122, in connect
    conn = _connect(dsn, connection_factory=connection_factory, **kwasync)
psycopg2.OperationalError: connection to server at "localhost" (127.0.0.1), port 5432 failed: Connection refused
	Is the server running on that host and accepting TCP/IP connections?
connection to server at "localhost" (::1), port 5432 failed: Cannot assign requested address
	Is the server running on that host and accepting TCP/IP connections?

[2023-12-07T17:18:58.801+0000] {taskinstance.py:1400} INFO - Marking task as FAILED. dag_id=my_scraping_dag, task_id=main_task, execution_date=20230712T000000, start_date=20231207T171857, end_date=20231207T171858
[2023-12-07T17:18:58.807+0000] {standard_task_runner.py:104} ERROR - Failed to execute job 2722 for task main_task (connection to server at "localhost" (127.0.0.1), port 5432 failed: Connection refused
	Is the server running on that host and accepting TCP/IP connections?
connection to server at "localhost" (::1), port 5432 failed: Cannot assign requested address
	Is the server running on that host and accepting TCP/IP connections?
; 8939)
[2023-12-07T17:18:58.819+0000] {local_task_job_runner.py:228} INFO - Task exited with return code 1
[2023-12-07T17:18:58.829+0000] {taskinstance.py:2778} INFO - 0 downstream tasks scheduled from follow-on schedule check
[2023-12-07T17:23:15.264+0000] {taskinstance.py:1159} INFO - Dependencies all met for dep_context=non-requeueable deps ti=<TaskInstance: my_scraping_dag.main_task scheduled__2023-07-12T00:00:00+00:00 [queued]>
[2023-12-07T17:23:15.268+0000] {taskinstance.py:1159} INFO - Dependencies all met for dep_context=requeueable deps ti=<TaskInstance: my_scraping_dag.main_task scheduled__2023-07-12T00:00:00+00:00 [queued]>
[2023-12-07T17:23:15.269+0000] {taskinstance.py:1361} INFO - Starting attempt 1 of 1
[2023-12-07T17:23:15.276+0000] {taskinstance.py:1382} INFO - Executing <Task(PythonOperator): main_task> on 2023-07-12 00:00:00+00:00
[2023-12-07T17:23:15.279+0000] {standard_task_runner.py:57} INFO - Started process 9735 to run task
[2023-12-07T17:23:15.281+0000] {standard_task_runner.py:84} INFO - Running: ['***', 'tasks', 'run', 'my_scraping_dag', 'main_task', 'scheduled__2023-07-12T00:00:00+00:00', '--job-id', '3064', '--raw', '--subdir', 'DAGS_FOLDER/main.py', '--cfg-path', '/tmp/tmp4wc4p1xb']
[2023-12-07T17:23:15.283+0000] {standard_task_runner.py:85} INFO - Job 3064: Subtask main_task
[2023-12-07T17:23:15.307+0000] {task_command.py:416} INFO - Running <TaskInstance: my_scraping_dag.main_task scheduled__2023-07-12T00:00:00+00:00 [running]> on host 63b0c7e341c0
[2023-12-07T17:23:15.347+0000] {taskinstance.py:1662} INFO - Exporting env vars: AIRFLOW_CTX_DAG_OWNER='***' AIRFLOW_CTX_DAG_ID='my_scraping_dag' AIRFLOW_CTX_TASK_ID='main_task' AIRFLOW_CTX_EXECUTION_DATE='2023-07-12T00:00:00+00:00' AIRFLOW_CTX_TRY_NUMBER='1' AIRFLOW_CTX_DAG_RUN_ID='scheduled__2023-07-12T00:00:00+00:00'
[2023-12-07T17:23:16.268+0000] {taskinstance.py:1937} ERROR - Task failed with exception
Traceback (most recent call last):
  File "/home/airflow/.local/lib/python3.8/site-packages/airflow/operators/python.py", line 192, in execute
    return_value = self.execute_callable()
  File "/home/airflow/.local/lib/python3.8/site-packages/airflow/operators/python.py", line 209, in execute_callable
    return self.python_callable(*self.op_args, **self.op_kwargs)
  File "/opt/airflow/dags/main.py", line 73, in main
    insert_data_to_db(products, db_params)
  File "/opt/airflow/dags/main.py", line 40, in insert_data_to_db
    with psycopg2.connect(**db_params) as conn:
  File "/home/airflow/.local/lib/python3.8/site-packages/psycopg2/__init__.py", line 122, in connect
    conn = _connect(dsn, connection_factory=connection_factory, **kwasync)
psycopg2.OperationalError: connection to server at "localhost" (127.0.0.1), port 5432 failed: Connection refused
	Is the server running on that host and accepting TCP/IP connections?
connection to server at "localhost" (::1), port 5432 failed: Cannot assign requested address
	Is the server running on that host and accepting TCP/IP connections?

[2023-12-07T17:23:16.312+0000] {taskinstance.py:1400} INFO - Marking task as FAILED. dag_id=my_scraping_dag, task_id=main_task, execution_date=20230712T000000, start_date=20231207T172315, end_date=20231207T172316
[2023-12-07T17:23:16.334+0000] {standard_task_runner.py:104} ERROR - Failed to execute job 3064 for task main_task (connection to server at "localhost" (127.0.0.1), port 5432 failed: Connection refused
	Is the server running on that host and accepting TCP/IP connections?
connection to server at "localhost" (::1), port 5432 failed: Cannot assign requested address
	Is the server running on that host and accepting TCP/IP connections?
; 9735)
[2023-12-07T17:23:16.388+0000] {local_task_job_runner.py:228} INFO - Task exited with return code 1
[2023-12-07T17:23:16.400+0000] {taskinstance.py:2778} INFO - 0 downstream tasks scheduled from follow-on schedule check
[2023-12-07T17:28:57.248+0000] {taskinstance.py:1159} INFO - Dependencies all met for dep_context=non-requeueable deps ti=<TaskInstance: my_scraping_dag.main_task scheduled__2023-07-12T00:00:00+00:00 [queued]>
[2023-12-07T17:28:57.252+0000] {taskinstance.py:1159} INFO - Dependencies all met for dep_context=requeueable deps ti=<TaskInstance: my_scraping_dag.main_task scheduled__2023-07-12T00:00:00+00:00 [queued]>
[2023-12-07T17:28:57.253+0000] {taskinstance.py:1361} INFO - Starting attempt 1 of 1
[2023-12-07T17:28:57.260+0000] {taskinstance.py:1382} INFO - Executing <Task(PythonOperator): main_task> on 2023-07-12 00:00:00+00:00
[2023-12-07T17:28:57.263+0000] {standard_task_runner.py:57} INFO - Started process 10578 to run task
[2023-12-07T17:28:57.265+0000] {standard_task_runner.py:84} INFO - Running: ['***', 'tasks', 'run', 'my_scraping_dag', 'main_task', 'scheduled__2023-07-12T00:00:00+00:00', '--job-id', '3406', '--raw', '--subdir', 'DAGS_FOLDER/main.py', '--cfg-path', '/tmp/tmp4bsl00t9']
[2023-12-07T17:28:57.267+0000] {standard_task_runner.py:85} INFO - Job 3406: Subtask main_task
[2023-12-07T17:28:57.294+0000] {task_command.py:416} INFO - Running <TaskInstance: my_scraping_dag.main_task scheduled__2023-07-12T00:00:00+00:00 [running]> on host 63b0c7e341c0
[2023-12-07T17:28:57.336+0000] {taskinstance.py:1662} INFO - Exporting env vars: AIRFLOW_CTX_DAG_OWNER='***' AIRFLOW_CTX_DAG_ID='my_scraping_dag' AIRFLOW_CTX_TASK_ID='main_task' AIRFLOW_CTX_EXECUTION_DATE='2023-07-12T00:00:00+00:00' AIRFLOW_CTX_TRY_NUMBER='1' AIRFLOW_CTX_DAG_RUN_ID='scheduled__2023-07-12T00:00:00+00:00'
[2023-12-07T17:28:58.020+0000] {taskinstance.py:1937} ERROR - Task failed with exception
Traceback (most recent call last):
  File "/home/airflow/.local/lib/python3.8/site-packages/airflow/operators/python.py", line 192, in execute
    return_value = self.execute_callable()
  File "/home/airflow/.local/lib/python3.8/site-packages/airflow/operators/python.py", line 209, in execute_callable
    return self.python_callable(*self.op_args, **self.op_kwargs)
  File "/opt/airflow/dags/main.py", line 73, in main
    insert_data_to_db(products, db_params)
  File "/opt/airflow/dags/main.py", line 40, in insert_data_to_db
    with psycopg2.connect(**db_params) as conn:
  File "/home/airflow/.local/lib/python3.8/site-packages/psycopg2/__init__.py", line 122, in connect
    conn = _connect(dsn, connection_factory=connection_factory, **kwasync)
psycopg2.OperationalError: connection to server at "localhost" (127.0.0.1), port 5432 failed: Connection refused
	Is the server running on that host and accepting TCP/IP connections?
connection to server at "localhost" (::1), port 5432 failed: Cannot assign requested address
	Is the server running on that host and accepting TCP/IP connections?

[2023-12-07T17:28:58.030+0000] {taskinstance.py:1400} INFO - Marking task as FAILED. dag_id=my_scraping_dag, task_id=main_task, execution_date=20230712T000000, start_date=20231207T172857, end_date=20231207T172858
[2023-12-07T17:28:58.045+0000] {standard_task_runner.py:104} ERROR - Failed to execute job 3406 for task main_task (connection to server at "localhost" (127.0.0.1), port 5432 failed: Connection refused
	Is the server running on that host and accepting TCP/IP connections?
connection to server at "localhost" (::1), port 5432 failed: Cannot assign requested address
	Is the server running on that host and accepting TCP/IP connections?
; 10578)
[2023-12-07T17:28:58.080+0000] {local_task_job_runner.py:228} INFO - Task exited with return code 1
[2023-12-07T17:28:58.105+0000] {taskinstance.py:2778} INFO - 0 downstream tasks scheduled from follow-on schedule check
[2023-12-09T07:35:01.511+0000] {taskinstance.py:1159} INFO - Dependencies all met for dep_context=non-requeueable deps ti=<TaskInstance: my_scraping_dag.main_task scheduled__2023-07-12T00:00:00+00:00 [queued]>
[2023-12-09T07:35:01.515+0000] {taskinstance.py:1159} INFO - Dependencies all met for dep_context=requeueable deps ti=<TaskInstance: my_scraping_dag.main_task scheduled__2023-07-12T00:00:00+00:00 [queued]>
[2023-12-09T07:35:01.516+0000] {taskinstance.py:1361} INFO - Starting attempt 1 of 1
[2023-12-09T07:35:01.523+0000] {taskinstance.py:1382} INFO - Executing <Task(PythonOperator): main_task> on 2023-07-12 00:00:00+00:00
[2023-12-09T07:35:01.526+0000] {standard_task_runner.py:57} INFO - Started process 990 to run task
[2023-12-09T07:35:01.528+0000] {standard_task_runner.py:84} INFO - Running: ['***', 'tasks', 'run', 'my_scraping_dag', 'main_task', 'scheduled__2023-07-12T00:00:00+00:00', '--job-id', '196', '--raw', '--subdir', 'DAGS_FOLDER/main.py', '--cfg-path', '/tmp/tmpub94mff8']
[2023-12-09T07:35:01.530+0000] {standard_task_runner.py:85} INFO - Job 196: Subtask main_task
[2023-12-09T07:35:01.555+0000] {task_command.py:416} INFO - Running <TaskInstance: my_scraping_dag.main_task scheduled__2023-07-12T00:00:00+00:00 [running]> on host 36b5ef2505c9
[2023-12-09T07:35:01.595+0000] {taskinstance.py:1662} INFO - Exporting env vars: AIRFLOW_CTX_DAG_OWNER='***' AIRFLOW_CTX_DAG_ID='my_scraping_dag' AIRFLOW_CTX_TASK_ID='main_task' AIRFLOW_CTX_EXECUTION_DATE='2023-07-12T00:00:00+00:00' AIRFLOW_CTX_TRY_NUMBER='1' AIRFLOW_CTX_DAG_RUN_ID='scheduled__2023-07-12T00:00:00+00:00'
[2023-12-09T07:35:01.600+0000] {taskinstance.py:1937} ERROR - Task failed with exception
Traceback (most recent call last):
  File "/home/airflow/.local/lib/python3.8/site-packages/airflow/operators/python.py", line 192, in execute
    return_value = self.execute_callable()
  File "/home/airflow/.local/lib/python3.8/site-packages/airflow/operators/python.py", line 209, in execute_callable
    return self.python_callable(*self.op_args, **self.op_kwargs)
  File "/opt/airflow/dags/main.py", line 64, in main
    base_url = Variable.get('base_url')
  File "/home/airflow/.local/lib/python3.8/site-packages/airflow/models/variable.py", line 140, in get
    raise KeyError(f"Variable {key} does not exist")
KeyError: 'Variable base_url does not exist'
[2023-12-09T07:35:01.607+0000] {taskinstance.py:1400} INFO - Marking task as FAILED. dag_id=my_scraping_dag, task_id=main_task, execution_date=20230712T000000, start_date=20231209T073501, end_date=20231209T073501
[2023-12-09T07:35:01.614+0000] {standard_task_runner.py:104} ERROR - Failed to execute job 196 for task main_task ('Variable base_url does not exist'; 990)
[2023-12-09T07:35:01.620+0000] {local_task_job_runner.py:228} INFO - Task exited with return code 1
[2023-12-09T07:35:01.630+0000] {taskinstance.py:2778} INFO - 0 downstream tasks scheduled from follow-on schedule check
