[2023-12-07T14:52:58.806+0000] {taskinstance.py:1159} INFO - Dependencies all met for dep_context=non-requeueable deps ti=<TaskInstance: my_scraping_dag.main_task scheduled__2023-07-06T00:00:00+00:00 [queued]>
[2023-12-07T14:52:58.814+0000] {taskinstance.py:1159} INFO - Dependencies all met for dep_context=requeueable deps ti=<TaskInstance: my_scraping_dag.main_task scheduled__2023-07-06T00:00:00+00:00 [queued]>
[2023-12-07T14:52:58.816+0000] {taskinstance.py:1361} INFO - Starting attempt 1 of 1
[2023-12-07T14:52:58.827+0000] {taskinstance.py:1382} INFO - Executing <Task(PythonOperator): main_task> on 2023-07-06 00:00:00+00:00
[2023-12-07T14:52:58.832+0000] {standard_task_runner.py:57} INFO - Started process 1151 to run task
[2023-12-07T14:52:58.834+0000] {standard_task_runner.py:84} INFO - Running: ['***', 'tasks', 'run', 'my_scraping_dag', 'main_task', 'scheduled__2023-07-06T00:00:00+00:00', '--job-id', '297', '--raw', '--subdir', 'DAGS_FOLDER/main.py', '--cfg-path', '/tmp/tmphcafe8lm']
[2023-12-07T14:52:58.836+0000] {standard_task_runner.py:85} INFO - Job 297: Subtask main_task
[2023-12-07T14:52:58.860+0000] {task_command.py:416} INFO - Running <TaskInstance: my_scraping_dag.main_task scheduled__2023-07-06T00:00:00+00:00 [running]> on host 63b0c7e341c0
[2023-12-07T14:52:58.896+0000] {taskinstance.py:1662} INFO - Exporting env vars: AIRFLOW_CTX_DAG_OWNER='***' AIRFLOW_CTX_DAG_ID='my_scraping_dag' AIRFLOW_CTX_TASK_ID='main_task' AIRFLOW_CTX_EXECUTION_DATE='2023-07-06T00:00:00+00:00' AIRFLOW_CTX_TRY_NUMBER='1' AIRFLOW_CTX_DAG_RUN_ID='scheduled__2023-07-06T00:00:00+00:00'
[2023-12-07T14:52:58.898+0000] {taskinstance.py:1937} ERROR - Task failed with exception
Traceback (most recent call last):
  File "/usr/local/lib/python3.8/configparser.py", line 846, in items
    d.update(self._sections[section])
KeyError: 'web'

During handling of the above exception, another exception occurred:

Traceback (most recent call last):
  File "/home/airflow/.local/lib/python3.8/site-packages/airflow/operators/python.py", line 192, in execute
    return_value = self.execute_callable()
  File "/home/airflow/.local/lib/python3.8/site-packages/airflow/operators/python.py", line 209, in execute_callable
    return self.python_callable(*self.op_args, **self.op_kwargs)
  File "/opt/airflow/dags/main.py", line 61, in main
    config = get_config('web')
  File "/opt/airflow/dags/main.py", line 23, in get_config
    return {key: value for key, value in parser.items(section)}
  File "/usr/local/lib/python3.8/configparser.py", line 849, in items
    raise NoSectionError(section)
configparser.NoSectionError: No section: 'web'
[2023-12-07T14:52:58.903+0000] {taskinstance.py:1400} INFO - Marking task as FAILED. dag_id=my_scraping_dag, task_id=main_task, execution_date=20230706T000000, start_date=20231207T145258, end_date=20231207T145258
[2023-12-07T14:52:58.936+0000] {standard_task_runner.py:104} ERROR - Failed to execute job 297 for task main_task (No section: 'web'; 1151)
[2023-12-07T14:52:58.966+0000] {local_task_job_runner.py:228} INFO - Task exited with return code 1
[2023-12-07T14:52:58.978+0000] {taskinstance.py:2778} INFO - 0 downstream tasks scheduled from follow-on schedule check
[2023-12-07T16:33:01.423+0000] {taskinstance.py:1159} INFO - Dependencies all met for dep_context=non-requeueable deps ti=<TaskInstance: my_scraping_dag.main_task scheduled__2023-07-06T00:00:00+00:00 [queued]>
[2023-12-07T16:33:01.428+0000] {taskinstance.py:1159} INFO - Dependencies all met for dep_context=requeueable deps ti=<TaskInstance: my_scraping_dag.main_task scheduled__2023-07-06T00:00:00+00:00 [queued]>
[2023-12-07T16:33:01.428+0000] {taskinstance.py:1361} INFO - Starting attempt 1 of 1
[2023-12-07T16:33:01.437+0000] {taskinstance.py:1382} INFO - Executing <Task(PythonOperator): main_task> on 2023-07-06 00:00:00+00:00
[2023-12-07T16:33:01.440+0000] {standard_task_runner.py:57} INFO - Started process 3926 to run task
[2023-12-07T16:33:01.444+0000] {standard_task_runner.py:84} INFO - Running: ['***', 'tasks', 'run', 'my_scraping_dag', 'main_task', 'scheduled__2023-07-06T00:00:00+00:00', '--job-id', '775', '--raw', '--subdir', 'DAGS_FOLDER/main.py', '--cfg-path', '/tmp/tmpx3cpn87i']
[2023-12-07T16:33:01.446+0000] {standard_task_runner.py:85} INFO - Job 775: Subtask main_task
[2023-12-07T16:33:01.488+0000] {task_command.py:416} INFO - Running <TaskInstance: my_scraping_dag.main_task scheduled__2023-07-06T00:00:00+00:00 [running]> on host 63b0c7e341c0
[2023-12-07T16:33:01.537+0000] {taskinstance.py:1662} INFO - Exporting env vars: AIRFLOW_CTX_DAG_OWNER='***' AIRFLOW_CTX_DAG_ID='my_scraping_dag' AIRFLOW_CTX_TASK_ID='main_task' AIRFLOW_CTX_EXECUTION_DATE='2023-07-06T00:00:00+00:00' AIRFLOW_CTX_TRY_NUMBER='1' AIRFLOW_CTX_DAG_RUN_ID='scheduled__2023-07-06T00:00:00+00:00'
[2023-12-07T16:33:01.538+0000] {taskinstance.py:1937} ERROR - Task failed with exception
Traceback (most recent call last):
  File "/usr/local/lib/python3.8/configparser.py", line 846, in items
    d.update(self._sections[section])
KeyError: 'web'

During handling of the above exception, another exception occurred:

Traceback (most recent call last):
  File "/home/airflow/.local/lib/python3.8/site-packages/airflow/operators/python.py", line 192, in execute
    return_value = self.execute_callable()
  File "/home/airflow/.local/lib/python3.8/site-packages/airflow/operators/python.py", line 209, in execute_callable
    return self.python_callable(*self.op_args, **self.op_kwargs)
  File "/opt/airflow/dags/main.py", line 60, in main
    config = get_config('web')
  File "/opt/airflow/dags/main.py", line 22, in get_config
    return {key: value for key, value in parser.items(section)}
  File "/usr/local/lib/python3.8/configparser.py", line 849, in items
    raise NoSectionError(section)
configparser.NoSectionError: No section: 'web'
[2023-12-07T16:33:01.546+0000] {taskinstance.py:1400} INFO - Marking task as FAILED. dag_id=my_scraping_dag, task_id=main_task, execution_date=20230706T000000, start_date=20231207T163301, end_date=20231207T163301
[2023-12-07T16:33:01.577+0000] {standard_task_runner.py:104} ERROR - Failed to execute job 775 for task main_task (No section: 'web'; 3926)
[2023-12-07T16:33:01.618+0000] {local_task_job_runner.py:228} INFO - Task exited with return code 1
[2023-12-07T16:33:01.648+0000] {taskinstance.py:2778} INFO - 0 downstream tasks scheduled from follow-on schedule check
[2023-12-07T16:42:03.633+0000] {taskinstance.py:1159} INFO - Dependencies all met for dep_context=non-requeueable deps ti=<TaskInstance: my_scraping_dag.main_task scheduled__2023-07-06T00:00:00+00:00 [queued]>
[2023-12-07T16:42:03.637+0000] {taskinstance.py:1159} INFO - Dependencies all met for dep_context=requeueable deps ti=<TaskInstance: my_scraping_dag.main_task scheduled__2023-07-06T00:00:00+00:00 [queued]>
[2023-12-07T16:42:03.637+0000] {taskinstance.py:1361} INFO - Starting attempt 1 of 1
[2023-12-07T16:42:03.642+0000] {taskinstance.py:1382} INFO - Executing <Task(PythonOperator): main_task> on 2023-07-06 00:00:00+00:00
[2023-12-07T16:42:03.645+0000] {standard_task_runner.py:57} INFO - Started process 4829 to run task
[2023-12-07T16:42:03.647+0000] {standard_task_runner.py:84} INFO - Running: ['***', 'tasks', 'run', 'my_scraping_dag', 'main_task', 'scheduled__2023-07-06T00:00:00+00:00', '--job-id', '1120', '--raw', '--subdir', 'DAGS_FOLDER/main.py', '--cfg-path', '/tmp/tmpl8q0_6wz']
[2023-12-07T16:42:03.648+0000] {standard_task_runner.py:85} INFO - Job 1120: Subtask main_task
[2023-12-07T16:42:03.670+0000] {task_command.py:416} INFO - Running <TaskInstance: my_scraping_dag.main_task scheduled__2023-07-06T00:00:00+00:00 [running]> on host 63b0c7e341c0
[2023-12-07T16:42:03.701+0000] {taskinstance.py:1662} INFO - Exporting env vars: AIRFLOW_CTX_DAG_OWNER='***' AIRFLOW_CTX_DAG_ID='my_scraping_dag' AIRFLOW_CTX_TASK_ID='main_task' AIRFLOW_CTX_EXECUTION_DATE='2023-07-06T00:00:00+00:00' AIRFLOW_CTX_TRY_NUMBER='1' AIRFLOW_CTX_DAG_RUN_ID='scheduled__2023-07-06T00:00:00+00:00'
[2023-12-07T16:42:03.702+0000] {taskinstance.py:1937} ERROR - Task failed with exception
Traceback (most recent call last):
  File "/usr/local/lib/python3.8/configparser.py", line 846, in items
    d.update(self._sections[section])
KeyError: 'web'

During handling of the above exception, another exception occurred:

Traceback (most recent call last):
  File "/home/airflow/.local/lib/python3.8/site-packages/airflow/operators/python.py", line 192, in execute
    return_value = self.execute_callable()
  File "/home/airflow/.local/lib/python3.8/site-packages/airflow/operators/python.py", line 209, in execute_callable
    return self.python_callable(*self.op_args, **self.op_kwargs)
  File "/opt/airflow/dags/main.py", line 60, in main
    config = get_config('web')
  File "/opt/airflow/dags/main.py", line 22, in get_config
    return {key: value for key, value in parser.items(section)}
  File "/usr/local/lib/python3.8/configparser.py", line 849, in items
    raise NoSectionError(section)
configparser.NoSectionError: No section: 'web'
[2023-12-07T16:42:03.706+0000] {taskinstance.py:1400} INFO - Marking task as FAILED. dag_id=my_scraping_dag, task_id=main_task, execution_date=20230706T000000, start_date=20231207T164203, end_date=20231207T164203
[2023-12-07T16:42:03.712+0000] {standard_task_runner.py:104} ERROR - Failed to execute job 1120 for task main_task (No section: 'web'; 4829)
[2023-12-07T16:42:03.743+0000] {local_task_job_runner.py:228} INFO - Task exited with return code 1
[2023-12-07T16:42:03.757+0000] {taskinstance.py:2778} INFO - 0 downstream tasks scheduled from follow-on schedule check
[2023-12-07T17:01:00.775+0000] {taskinstance.py:1159} INFO - Dependencies all met for dep_context=non-requeueable deps ti=<TaskInstance: my_scraping_dag.main_task scheduled__2023-07-06T00:00:00+00:00 [queued]>
[2023-12-07T17:01:00.791+0000] {taskinstance.py:1159} INFO - Dependencies all met for dep_context=requeueable deps ti=<TaskInstance: my_scraping_dag.main_task scheduled__2023-07-06T00:00:00+00:00 [queued]>
[2023-12-07T17:01:00.792+0000] {taskinstance.py:1361} INFO - Starting attempt 1 of 1
[2023-12-07T17:01:00.806+0000] {taskinstance.py:1382} INFO - Executing <Task(PythonOperator): main_task> on 2023-07-06 00:00:00+00:00
[2023-12-07T17:01:00.810+0000] {standard_task_runner.py:57} INFO - Started process 6113 to run task
[2023-12-07T17:01:00.813+0000] {standard_task_runner.py:84} INFO - Running: ['***', 'tasks', 'run', 'my_scraping_dag', 'main_task', 'scheduled__2023-07-06T00:00:00+00:00', '--job-id', '1529', '--raw', '--subdir', 'DAGS_FOLDER/main.py', '--cfg-path', '/tmp/tmpwbzw13lg']
[2023-12-07T17:01:00.816+0000] {standard_task_runner.py:85} INFO - Job 1529: Subtask main_task
[2023-12-07T17:01:00.851+0000] {task_command.py:416} INFO - Running <TaskInstance: my_scraping_dag.main_task scheduled__2023-07-06T00:00:00+00:00 [running]> on host 63b0c7e341c0
[2023-12-07T17:01:00.900+0000] {taskinstance.py:1662} INFO - Exporting env vars: AIRFLOW_CTX_DAG_OWNER='***' AIRFLOW_CTX_DAG_ID='my_scraping_dag' AIRFLOW_CTX_TASK_ID='main_task' AIRFLOW_CTX_EXECUTION_DATE='2023-07-06T00:00:00+00:00' AIRFLOW_CTX_TRY_NUMBER='1' AIRFLOW_CTX_DAG_RUN_ID='scheduled__2023-07-06T00:00:00+00:00'
[2023-12-07T17:01:00.931+0000] {logging_mixin.py:154} INFO - base_url: https://tuncbotanik.com
[2023-12-07T17:01:00.932+0000] {python.py:194} INFO - Done. Returned value was: ('https://tuncbotanik.com', {'User-Agent': 'Mozilla/5.0 (Macintosh; Intel Mac OS X 10_15_7) AppleWebKit/537.36 (KHTML, like Gecko) Chrome/119.0.0.0 Safari/537.36', 'Accept-Language': 'tr-TR,tr;q=0.9,en-US;q=0.8,en;q=0.7'}, {'dbname': 'plant', 'user': 'aozgokme', 'password': '***', 'host': 'localhost', 'port': '5432'})
[2023-12-07T17:01:00.943+0000] {taskinstance.py:1400} INFO - Marking task as SUCCESS. dag_id=my_scraping_dag, task_id=main_task, execution_date=20230706T000000, start_date=20231207T170100, end_date=20231207T170100
[2023-12-07T17:01:00.989+0000] {local_task_job_runner.py:228} INFO - Task exited with return code 0
[2023-12-07T17:01:01.018+0000] {taskinstance.py:2778} INFO - 0 downstream tasks scheduled from follow-on schedule check
[2023-12-07T17:04:14.631+0000] {taskinstance.py:1159} INFO - Dependencies all met for dep_context=non-requeueable deps ti=<TaskInstance: my_scraping_dag.main_task scheduled__2023-07-06T00:00:00+00:00 [queued]>
[2023-12-07T17:04:14.637+0000] {taskinstance.py:1159} INFO - Dependencies all met for dep_context=requeueable deps ti=<TaskInstance: my_scraping_dag.main_task scheduled__2023-07-06T00:00:00+00:00 [queued]>
[2023-12-07T17:04:14.638+0000] {taskinstance.py:1361} INFO - Starting attempt 1 of 1
[2023-12-07T17:04:14.649+0000] {taskinstance.py:1382} INFO - Executing <Task(PythonOperator): main_task> on 2023-07-06 00:00:00+00:00
[2023-12-07T17:04:14.655+0000] {standard_task_runner.py:57} INFO - Started process 7566 to run task
[2023-12-07T17:04:14.661+0000] {standard_task_runner.py:84} INFO - Running: ['***', 'tasks', 'run', 'my_scraping_dag', 'main_task', 'scheduled__2023-07-06T00:00:00+00:00', '--job-id', '2215', '--raw', '--subdir', 'DAGS_FOLDER/main.py', '--cfg-path', '/tmp/tmpwxv53npy']
[2023-12-07T17:04:14.664+0000] {standard_task_runner.py:85} INFO - Job 2215: Subtask main_task
[2023-12-07T17:04:14.696+0000] {task_command.py:416} INFO - Running <TaskInstance: my_scraping_dag.main_task scheduled__2023-07-06T00:00:00+00:00 [running]> on host 63b0c7e341c0
[2023-12-07T17:04:14.729+0000] {taskinstance.py:1662} INFO - Exporting env vars: AIRFLOW_CTX_DAG_OWNER='***' AIRFLOW_CTX_DAG_ID='my_scraping_dag' AIRFLOW_CTX_TASK_ID='main_task' AIRFLOW_CTX_EXECUTION_DATE='2023-07-06T00:00:00+00:00' AIRFLOW_CTX_TRY_NUMBER='1' AIRFLOW_CTX_DAG_RUN_ID='scheduled__2023-07-06T00:00:00+00:00'
[2023-12-07T17:04:14.745+0000] {logging_mixin.py:154} INFO - base_url: https://tuncbotanik.com
[2023-12-07T17:04:14.745+0000] {python.py:194} INFO - Done. Returned value was: ('https://tuncbotanik.com', {'User-Agent': 'Mozilla/5.0 (Macintosh; Intel Mac OS X 10_15_7) AppleWebKit/537.36 (KHTML, like Gecko) Chrome/119.0.0.0 Safari/537.36', 'Accept-Language': 'tr-TR,tr;q=0.9,en-US;q=0.8,en;q=0.7'}, {'dbname': 'plant', 'user': 'aozgokme', 'password': '***', 'host': 'localhost', 'port': '5432'})
[2023-12-07T17:04:14.754+0000] {taskinstance.py:1400} INFO - Marking task as SUCCESS. dag_id=my_scraping_dag, task_id=main_task, execution_date=20230706T000000, start_date=20231207T170414, end_date=20231207T170414
[2023-12-07T17:04:14.790+0000] {local_task_job_runner.py:228} INFO - Task exited with return code 0
[2023-12-07T17:04:14.802+0000] {taskinstance.py:2778} INFO - 1 downstream tasks scheduled from follow-on schedule check
[2023-12-07T17:18:57.650+0000] {taskinstance.py:1159} INFO - Dependencies all met for dep_context=non-requeueable deps ti=<TaskInstance: my_scraping_dag.main_task scheduled__2023-07-06T00:00:00+00:00 [queued]>
[2023-12-07T17:18:57.656+0000] {taskinstance.py:1159} INFO - Dependencies all met for dep_context=requeueable deps ti=<TaskInstance: my_scraping_dag.main_task scheduled__2023-07-06T00:00:00+00:00 [queued]>
[2023-12-07T17:18:57.656+0000] {taskinstance.py:1361} INFO - Starting attempt 1 of 1
[2023-12-07T17:18:57.663+0000] {taskinstance.py:1382} INFO - Executing <Task(PythonOperator): main_task> on 2023-07-06 00:00:00+00:00
[2023-12-07T17:18:57.666+0000] {standard_task_runner.py:57} INFO - Started process 8928 to run task
[2023-12-07T17:18:57.668+0000] {standard_task_runner.py:84} INFO - Running: ['***', 'tasks', 'run', 'my_scraping_dag', 'main_task', 'scheduled__2023-07-06T00:00:00+00:00', '--job-id', '2716', '--raw', '--subdir', 'DAGS_FOLDER/main.py', '--cfg-path', '/tmp/tmp4gnvjfwm']
[2023-12-07T17:18:57.670+0000] {standard_task_runner.py:85} INFO - Job 2716: Subtask main_task
[2023-12-07T17:18:57.699+0000] {task_command.py:416} INFO - Running <TaskInstance: my_scraping_dag.main_task scheduled__2023-07-06T00:00:00+00:00 [running]> on host 63b0c7e341c0
[2023-12-07T17:18:57.744+0000] {taskinstance.py:1662} INFO - Exporting env vars: AIRFLOW_CTX_DAG_OWNER='***' AIRFLOW_CTX_DAG_ID='my_scraping_dag' AIRFLOW_CTX_TASK_ID='main_task' AIRFLOW_CTX_EXECUTION_DATE='2023-07-06T00:00:00+00:00' AIRFLOW_CTX_TRY_NUMBER='1' AIRFLOW_CTX_DAG_RUN_ID='scheduled__2023-07-06T00:00:00+00:00'
[2023-12-07T17:18:58.456+0000] {taskinstance.py:1937} ERROR - Task failed with exception
Traceback (most recent call last):
  File "/home/airflow/.local/lib/python3.8/site-packages/airflow/operators/python.py", line 192, in execute
    return_value = self.execute_callable()
  File "/home/airflow/.local/lib/python3.8/site-packages/airflow/operators/python.py", line 209, in execute_callable
    return self.python_callable(*self.op_args, **self.op_kwargs)
  File "/opt/airflow/dags/main.py", line 80, in main
    insert_data_to_db(products, db_params)
  File "/opt/airflow/dags/main.py", line 43, in insert_data_to_db
    with psycopg2.connect(**db_params) as conn:
  File "/home/airflow/.local/lib/python3.8/site-packages/psycopg2/__init__.py", line 122, in connect
    conn = _connect(dsn, connection_factory=connection_factory, **kwasync)
psycopg2.OperationalError: connection to server at "localhost" (127.0.0.1), port 5432 failed: Connection refused
	Is the server running on that host and accepting TCP/IP connections?
connection to server at "localhost" (::1), port 5432 failed: Cannot assign requested address
	Is the server running on that host and accepting TCP/IP connections?

[2023-12-07T17:18:58.477+0000] {taskinstance.py:1400} INFO - Marking task as FAILED. dag_id=my_scraping_dag, task_id=main_task, execution_date=20230706T000000, start_date=20231207T171857, end_date=20231207T171858
[2023-12-07T17:18:58.495+0000] {standard_task_runner.py:104} ERROR - Failed to execute job 2716 for task main_task (connection to server at "localhost" (127.0.0.1), port 5432 failed: Connection refused
	Is the server running on that host and accepting TCP/IP connections?
connection to server at "localhost" (::1), port 5432 failed: Cannot assign requested address
	Is the server running on that host and accepting TCP/IP connections?
; 8928)
[2023-12-07T17:18:58.530+0000] {local_task_job_runner.py:228} INFO - Task exited with return code 1
[2023-12-07T17:18:58.553+0000] {taskinstance.py:2778} INFO - 0 downstream tasks scheduled from follow-on schedule check
[2023-12-07T17:23:13.270+0000] {taskinstance.py:1159} INFO - Dependencies all met for dep_context=non-requeueable deps ti=<TaskInstance: my_scraping_dag.main_task scheduled__2023-07-06T00:00:00+00:00 [queued]>
[2023-12-07T17:23:13.282+0000] {taskinstance.py:1159} INFO - Dependencies all met for dep_context=requeueable deps ti=<TaskInstance: my_scraping_dag.main_task scheduled__2023-07-06T00:00:00+00:00 [queued]>
[2023-12-07T17:23:13.283+0000] {taskinstance.py:1361} INFO - Starting attempt 1 of 1
[2023-12-07T17:23:13.319+0000] {taskinstance.py:1382} INFO - Executing <Task(PythonOperator): main_task> on 2023-07-06 00:00:00+00:00
[2023-12-07T17:23:13.324+0000] {standard_task_runner.py:57} INFO - Started process 9722 to run task
[2023-12-07T17:23:13.334+0000] {standard_task_runner.py:84} INFO - Running: ['***', 'tasks', 'run', 'my_scraping_dag', 'main_task', 'scheduled__2023-07-06T00:00:00+00:00', '--job-id', '3058', '--raw', '--subdir', 'DAGS_FOLDER/main.py', '--cfg-path', '/tmp/tmpsu458wj2']
[2023-12-07T17:23:13.337+0000] {standard_task_runner.py:85} INFO - Job 3058: Subtask main_task
[2023-12-07T17:23:13.400+0000] {task_command.py:416} INFO - Running <TaskInstance: my_scraping_dag.main_task scheduled__2023-07-06T00:00:00+00:00 [running]> on host 63b0c7e341c0
[2023-12-07T17:23:13.469+0000] {taskinstance.py:1662} INFO - Exporting env vars: AIRFLOW_CTX_DAG_OWNER='***' AIRFLOW_CTX_DAG_ID='my_scraping_dag' AIRFLOW_CTX_TASK_ID='main_task' AIRFLOW_CTX_EXECUTION_DATE='2023-07-06T00:00:00+00:00' AIRFLOW_CTX_TRY_NUMBER='1' AIRFLOW_CTX_DAG_RUN_ID='scheduled__2023-07-06T00:00:00+00:00'
[2023-12-07T17:23:14.107+0000] {taskinstance.py:1937} ERROR - Task failed with exception
Traceback (most recent call last):
  File "/home/airflow/.local/lib/python3.8/site-packages/airflow/operators/python.py", line 192, in execute
    return_value = self.execute_callable()
  File "/home/airflow/.local/lib/python3.8/site-packages/airflow/operators/python.py", line 209, in execute_callable
    return self.python_callable(*self.op_args, **self.op_kwargs)
  File "/opt/airflow/dags/main.py", line 73, in main
    insert_data_to_db(products, db_params)
  File "/opt/airflow/dags/main.py", line 40, in insert_data_to_db
    with psycopg2.connect(**db_params) as conn:
  File "/home/airflow/.local/lib/python3.8/site-packages/psycopg2/__init__.py", line 122, in connect
    conn = _connect(dsn, connection_factory=connection_factory, **kwasync)
psycopg2.OperationalError: connection to server at "localhost" (127.0.0.1), port 5432 failed: Connection refused
	Is the server running on that host and accepting TCP/IP connections?
connection to server at "localhost" (::1), port 5432 failed: Cannot assign requested address
	Is the server running on that host and accepting TCP/IP connections?

[2023-12-07T17:23:14.112+0000] {taskinstance.py:1400} INFO - Marking task as FAILED. dag_id=my_scraping_dag, task_id=main_task, execution_date=20230706T000000, start_date=20231207T172313, end_date=20231207T172314
[2023-12-07T17:23:14.117+0000] {standard_task_runner.py:104} ERROR - Failed to execute job 3058 for task main_task (connection to server at "localhost" (127.0.0.1), port 5432 failed: Connection refused
	Is the server running on that host and accepting TCP/IP connections?
connection to server at "localhost" (::1), port 5432 failed: Cannot assign requested address
	Is the server running on that host and accepting TCP/IP connections?
; 9722)
[2023-12-07T17:23:14.151+0000] {local_task_job_runner.py:228} INFO - Task exited with return code 1
[2023-12-07T17:23:14.159+0000] {taskinstance.py:2778} INFO - 0 downstream tasks scheduled from follow-on schedule check
[2023-12-07T17:28:55.434+0000] {taskinstance.py:1159} INFO - Dependencies all met for dep_context=non-requeueable deps ti=<TaskInstance: my_scraping_dag.main_task scheduled__2023-07-06T00:00:00+00:00 [queued]>
[2023-12-07T17:28:55.441+0000] {taskinstance.py:1159} INFO - Dependencies all met for dep_context=requeueable deps ti=<TaskInstance: my_scraping_dag.main_task scheduled__2023-07-06T00:00:00+00:00 [queued]>
[2023-12-07T17:28:55.451+0000] {taskinstance.py:1361} INFO - Starting attempt 1 of 1
[2023-12-07T17:28:55.469+0000] {taskinstance.py:1382} INFO - Executing <Task(PythonOperator): main_task> on 2023-07-06 00:00:00+00:00
[2023-12-07T17:28:55.480+0000] {standard_task_runner.py:57} INFO - Started process 10566 to run task
[2023-12-07T17:28:55.491+0000] {standard_task_runner.py:84} INFO - Running: ['***', 'tasks', 'run', 'my_scraping_dag', 'main_task', 'scheduled__2023-07-06T00:00:00+00:00', '--job-id', '3400', '--raw', '--subdir', 'DAGS_FOLDER/main.py', '--cfg-path', '/tmp/tmpx6gj5zp2']
[2023-12-07T17:28:55.502+0000] {standard_task_runner.py:85} INFO - Job 3400: Subtask main_task
[2023-12-07T17:28:55.547+0000] {task_command.py:416} INFO - Running <TaskInstance: my_scraping_dag.main_task scheduled__2023-07-06T00:00:00+00:00 [running]> on host 63b0c7e341c0
[2023-12-07T17:28:55.624+0000] {taskinstance.py:1662} INFO - Exporting env vars: AIRFLOW_CTX_DAG_OWNER='***' AIRFLOW_CTX_DAG_ID='my_scraping_dag' AIRFLOW_CTX_TASK_ID='main_task' AIRFLOW_CTX_EXECUTION_DATE='2023-07-06T00:00:00+00:00' AIRFLOW_CTX_TRY_NUMBER='1' AIRFLOW_CTX_DAG_RUN_ID='scheduled__2023-07-06T00:00:00+00:00'
[2023-12-07T17:28:56.237+0000] {taskinstance.py:1937} ERROR - Task failed with exception
Traceback (most recent call last):
  File "/home/airflow/.local/lib/python3.8/site-packages/airflow/operators/python.py", line 192, in execute
    return_value = self.execute_callable()
  File "/home/airflow/.local/lib/python3.8/site-packages/airflow/operators/python.py", line 209, in execute_callable
    return self.python_callable(*self.op_args, **self.op_kwargs)
  File "/opt/airflow/dags/main.py", line 73, in main
    insert_data_to_db(products, db_params)
  File "/opt/airflow/dags/main.py", line 40, in insert_data_to_db
    with psycopg2.connect(**db_params) as conn:
  File "/home/airflow/.local/lib/python3.8/site-packages/psycopg2/__init__.py", line 122, in connect
    conn = _connect(dsn, connection_factory=connection_factory, **kwasync)
psycopg2.OperationalError: connection to server at "localhost" (127.0.0.1), port 5432 failed: Connection refused
	Is the server running on that host and accepting TCP/IP connections?
connection to server at "localhost" (::1), port 5432 failed: Cannot assign requested address
	Is the server running on that host and accepting TCP/IP connections?

[2023-12-07T17:28:56.242+0000] {taskinstance.py:1400} INFO - Marking task as FAILED. dag_id=my_scraping_dag, task_id=main_task, execution_date=20230706T000000, start_date=20231207T172855, end_date=20231207T172856
[2023-12-07T17:28:56.248+0000] {standard_task_runner.py:104} ERROR - Failed to execute job 3400 for task main_task (connection to server at "localhost" (127.0.0.1), port 5432 failed: Connection refused
	Is the server running on that host and accepting TCP/IP connections?
connection to server at "localhost" (::1), port 5432 failed: Cannot assign requested address
	Is the server running on that host and accepting TCP/IP connections?
; 10566)
[2023-12-07T17:28:56.270+0000] {local_task_job_runner.py:228} INFO - Task exited with return code 1
[2023-12-07T17:28:56.278+0000] {taskinstance.py:2778} INFO - 0 downstream tasks scheduled from follow-on schedule check
