[2023-12-07T14:46:14.132+0000] {taskinstance.py:1159} INFO - Dependencies all met for dep_context=non-requeueable deps ti=<TaskInstance: my_scraping_dag.main_task scheduled__2023-03-16T00:00:00+00:00 [queued]>
[2023-12-07T14:46:14.136+0000] {taskinstance.py:1159} INFO - Dependencies all met for dep_context=requeueable deps ti=<TaskInstance: my_scraping_dag.main_task scheduled__2023-03-16T00:00:00+00:00 [queued]>
[2023-12-07T14:46:14.136+0000] {taskinstance.py:1361} INFO - Starting attempt 1 of 1
[2023-12-07T14:46:14.142+0000] {taskinstance.py:1382} INFO - Executing <Task(PythonOperator): main_task> on 2023-03-16 00:00:00+00:00
[2023-12-07T14:46:14.144+0000] {standard_task_runner.py:57} INFO - Started process 552 to run task
[2023-12-07T14:46:14.146+0000] {standard_task_runner.py:84} INFO - Running: ['***', 'tasks', 'run', 'my_scraping_dag', 'main_task', 'scheduled__2023-03-16T00:00:00+00:00', '--job-id', '86', '--raw', '--subdir', 'DAGS_FOLDER/main.py', '--cfg-path', '/tmp/tmpb8ygbcm_']
[2023-12-07T14:46:14.148+0000] {standard_task_runner.py:85} INFO - Job 86: Subtask main_task
[2023-12-07T14:46:14.169+0000] {task_command.py:416} INFO - Running <TaskInstance: my_scraping_dag.main_task scheduled__2023-03-16T00:00:00+00:00 [running]> on host 63b0c7e341c0
[2023-12-07T14:46:14.199+0000] {taskinstance.py:1662} INFO - Exporting env vars: AIRFLOW_CTX_DAG_OWNER='***' AIRFLOW_CTX_DAG_ID='my_scraping_dag' AIRFLOW_CTX_TASK_ID='main_task' AIRFLOW_CTX_EXECUTION_DATE='2023-03-16T00:00:00+00:00' AIRFLOW_CTX_TRY_NUMBER='1' AIRFLOW_CTX_DAG_RUN_ID='scheduled__2023-03-16T00:00:00+00:00'
[2023-12-07T14:46:14.200+0000] {taskinstance.py:1937} ERROR - Task failed with exception
Traceback (most recent call last):
  File "/usr/local/lib/python3.8/configparser.py", line 846, in items
    d.update(self._sections[section])
KeyError: 'web'

During handling of the above exception, another exception occurred:

Traceback (most recent call last):
  File "/home/airflow/.local/lib/python3.8/site-packages/airflow/operators/python.py", line 192, in execute
    return_value = self.execute_callable()
  File "/home/airflow/.local/lib/python3.8/site-packages/airflow/operators/python.py", line 209, in execute_callable
    return self.python_callable(*self.op_args, **self.op_kwargs)
  File "/opt/airflow/dags/main.py", line 61, in main
    config = get_config('web')
  File "/opt/airflow/dags/main.py", line 23, in get_config
    return {key: value for key, value in parser.items(section)}
  File "/usr/local/lib/python3.8/configparser.py", line 849, in items
    raise NoSectionError(section)
configparser.NoSectionError: No section: 'web'
[2023-12-07T14:46:14.203+0000] {taskinstance.py:1400} INFO - Marking task as FAILED. dag_id=my_scraping_dag, task_id=main_task, execution_date=20230316T000000, start_date=20231207T144614, end_date=20231207T144614
[2023-12-07T14:46:14.208+0000] {standard_task_runner.py:104} ERROR - Failed to execute job 86 for task main_task (No section: 'web'; 552)
[2023-12-07T14:46:14.238+0000] {local_task_job_runner.py:228} INFO - Task exited with return code 1
[2023-12-07T14:46:14.249+0000] {taskinstance.py:2778} INFO - 0 downstream tasks scheduled from follow-on schedule check
[2023-12-07T14:52:01.094+0000] {taskinstance.py:1159} INFO - Dependencies all met for dep_context=non-requeueable deps ti=<TaskInstance: my_scraping_dag.main_task scheduled__2023-03-16T00:00:00+00:00 [queued]>
[2023-12-07T14:52:01.100+0000] {taskinstance.py:1159} INFO - Dependencies all met for dep_context=requeueable deps ti=<TaskInstance: my_scraping_dag.main_task scheduled__2023-03-16T00:00:00+00:00 [queued]>
[2023-12-07T14:52:01.101+0000] {taskinstance.py:1361} INFO - Starting attempt 1 of 1
[2023-12-07T14:52:01.109+0000] {taskinstance.py:1382} INFO - Executing <Task(PythonOperator): main_task> on 2023-03-16 00:00:00+00:00
[2023-12-07T14:52:01.112+0000] {standard_task_runner.py:57} INFO - Started process 903 to run task
[2023-12-07T14:52:01.114+0000] {standard_task_runner.py:84} INFO - Running: ['***', 'tasks', 'run', 'my_scraping_dag', 'main_task', 'scheduled__2023-03-16T00:00:00+00:00', '--job-id', '185', '--raw', '--subdir', 'DAGS_FOLDER/main.py', '--cfg-path', '/tmp/tmpzwxgw7gj']
[2023-12-07T14:52:01.116+0000] {standard_task_runner.py:85} INFO - Job 185: Subtask main_task
[2023-12-07T14:52:01.140+0000] {task_command.py:416} INFO - Running <TaskInstance: my_scraping_dag.main_task scheduled__2023-03-16T00:00:00+00:00 [running]> on host 63b0c7e341c0
[2023-12-07T14:52:01.179+0000] {taskinstance.py:1662} INFO - Exporting env vars: AIRFLOW_CTX_DAG_OWNER='***' AIRFLOW_CTX_DAG_ID='my_scraping_dag' AIRFLOW_CTX_TASK_ID='main_task' AIRFLOW_CTX_EXECUTION_DATE='2023-03-16T00:00:00+00:00' AIRFLOW_CTX_TRY_NUMBER='1' AIRFLOW_CTX_DAG_RUN_ID='scheduled__2023-03-16T00:00:00+00:00'
[2023-12-07T14:52:01.180+0000] {taskinstance.py:1937} ERROR - Task failed with exception
Traceback (most recent call last):
  File "/usr/local/lib/python3.8/configparser.py", line 846, in items
    d.update(self._sections[section])
KeyError: 'web'

During handling of the above exception, another exception occurred:

Traceback (most recent call last):
  File "/home/airflow/.local/lib/python3.8/site-packages/airflow/operators/python.py", line 192, in execute
    return_value = self.execute_callable()
  File "/home/airflow/.local/lib/python3.8/site-packages/airflow/operators/python.py", line 209, in execute_callable
    return self.python_callable(*self.op_args, **self.op_kwargs)
  File "/opt/airflow/dags/main.py", line 61, in main
    config = get_config('web')
  File "/opt/airflow/dags/main.py", line 23, in get_config
    return {key: value for key, value in parser.items(section)}
  File "/usr/local/lib/python3.8/configparser.py", line 849, in items
    raise NoSectionError(section)
configparser.NoSectionError: No section: 'web'
[2023-12-07T14:52:01.185+0000] {taskinstance.py:1400} INFO - Marking task as FAILED. dag_id=my_scraping_dag, task_id=main_task, execution_date=20230316T000000, start_date=20231207T145201, end_date=20231207T145201
[2023-12-07T14:52:01.190+0000] {standard_task_runner.py:104} ERROR - Failed to execute job 185 for task main_task (No section: 'web'; 903)
[2023-12-07T14:52:01.206+0000] {local_task_job_runner.py:228} INFO - Task exited with return code 1
[2023-12-07T14:52:01.229+0000] {taskinstance.py:2778} INFO - 0 downstream tasks scheduled from follow-on schedule check
[2023-12-07T15:00:12.240+0000] {taskinstance.py:1159} INFO - Dependencies all met for dep_context=non-requeueable deps ti=<TaskInstance: my_scraping_dag.main_task scheduled__2023-03-16T00:00:00+00:00 [queued]>
[2023-12-07T15:00:12.244+0000] {taskinstance.py:1159} INFO - Dependencies all met for dep_context=requeueable deps ti=<TaskInstance: my_scraping_dag.main_task scheduled__2023-03-16T00:00:00+00:00 [queued]>
[2023-12-07T15:00:12.244+0000] {taskinstance.py:1361} INFO - Starting attempt 1 of 1
[2023-12-07T15:00:12.250+0000] {taskinstance.py:1382} INFO - Executing <Task(PythonOperator): main_task> on 2023-03-16 00:00:00+00:00
[2023-12-07T15:00:12.252+0000] {standard_task_runner.py:57} INFO - Started process 1525 to run task
[2023-12-07T15:00:12.254+0000] {standard_task_runner.py:84} INFO - Running: ['***', 'tasks', 'run', 'my_scraping_dag', 'main_task', 'scheduled__2023-03-16T00:00:00+00:00', '--job-id', '390', '--raw', '--subdir', 'DAGS_FOLDER/main.py', '--cfg-path', '/tmp/tmpa1ga64j7']
[2023-12-07T15:00:12.256+0000] {standard_task_runner.py:85} INFO - Job 390: Subtask main_task
[2023-12-07T15:00:12.280+0000] {task_command.py:416} INFO - Running <TaskInstance: my_scraping_dag.main_task scheduled__2023-03-16T00:00:00+00:00 [running]> on host 63b0c7e341c0
[2023-12-07T15:00:12.312+0000] {taskinstance.py:1662} INFO - Exporting env vars: AIRFLOW_CTX_DAG_OWNER='***' AIRFLOW_CTX_DAG_ID='my_scraping_dag' AIRFLOW_CTX_TASK_ID='main_task' AIRFLOW_CTX_EXECUTION_DATE='2023-03-16T00:00:00+00:00' AIRFLOW_CTX_TRY_NUMBER='1' AIRFLOW_CTX_DAG_RUN_ID='scheduled__2023-03-16T00:00:00+00:00'
[2023-12-07T15:00:12.313+0000] {taskinstance.py:1937} ERROR - Task failed with exception
Traceback (most recent call last):
  File "/usr/local/lib/python3.8/configparser.py", line 846, in items
    d.update(self._sections[section])
KeyError: 'web'

During handling of the above exception, another exception occurred:

Traceback (most recent call last):
  File "/home/airflow/.local/lib/python3.8/site-packages/airflow/operators/python.py", line 192, in execute
    return_value = self.execute_callable()
  File "/home/airflow/.local/lib/python3.8/site-packages/airflow/operators/python.py", line 209, in execute_callable
    return self.python_callable(*self.op_args, **self.op_kwargs)
  File "/opt/airflow/dags/main.py", line 60, in main
    config = get_config('web')
  File "/opt/airflow/dags/main.py", line 22, in get_config
    return {key: value for key, value in parser.items(section)}
  File "/usr/local/lib/python3.8/configparser.py", line 849, in items
    raise NoSectionError(section)
configparser.NoSectionError: No section: 'web'
[2023-12-07T15:00:12.318+0000] {taskinstance.py:1400} INFO - Marking task as FAILED. dag_id=my_scraping_dag, task_id=main_task, execution_date=20230316T000000, start_date=20231207T150012, end_date=20231207T150012
[2023-12-07T15:00:12.323+0000] {standard_task_runner.py:104} ERROR - Failed to execute job 390 for task main_task (No section: 'web'; 1525)
[2023-12-07T15:00:12.347+0000] {local_task_job_runner.py:228} INFO - Task exited with return code 1
[2023-12-07T15:00:12.359+0000] {taskinstance.py:2778} INFO - 0 downstream tasks scheduled from follow-on schedule check
[2023-12-07T15:11:00.079+0000] {taskinstance.py:1159} INFO - Dependencies all met for dep_context=non-requeueable deps ti=<TaskInstance: my_scraping_dag.main_task scheduled__2023-03-16T00:00:00+00:00 [queued]>
[2023-12-07T15:11:00.085+0000] {taskinstance.py:1159} INFO - Dependencies all met for dep_context=requeueable deps ti=<TaskInstance: my_scraping_dag.main_task scheduled__2023-03-16T00:00:00+00:00 [queued]>
[2023-12-07T15:11:00.086+0000] {taskinstance.py:1361} INFO - Starting attempt 1 of 1
[2023-12-07T15:11:00.099+0000] {taskinstance.py:1382} INFO - Executing <Task(PythonOperator): main_task> on 2023-03-16 00:00:00+00:00
[2023-12-07T15:11:00.105+0000] {standard_task_runner.py:57} INFO - Started process 1995 to run task
[2023-12-07T15:11:00.108+0000] {standard_task_runner.py:84} INFO - Running: ['***', 'tasks', 'run', 'my_scraping_dag', 'main_task', 'scheduled__2023-03-16T00:00:00+00:00', '--job-id', '496', '--raw', '--subdir', 'DAGS_FOLDER/main.py', '--cfg-path', '/tmp/tmpn26o_1vb']
[2023-12-07T15:11:00.111+0000] {standard_task_runner.py:85} INFO - Job 496: Subtask main_task
[2023-12-07T15:11:00.178+0000] {task_command.py:416} INFO - Running <TaskInstance: my_scraping_dag.main_task scheduled__2023-03-16T00:00:00+00:00 [running]> on host 63b0c7e341c0
[2023-12-07T15:11:00.241+0000] {taskinstance.py:1662} INFO - Exporting env vars: AIRFLOW_CTX_DAG_OWNER='***' AIRFLOW_CTX_DAG_ID='my_scraping_dag' AIRFLOW_CTX_TASK_ID='main_task' AIRFLOW_CTX_EXECUTION_DATE='2023-03-16T00:00:00+00:00' AIRFLOW_CTX_TRY_NUMBER='1' AIRFLOW_CTX_DAG_RUN_ID='scheduled__2023-03-16T00:00:00+00:00'
[2023-12-07T15:11:00.243+0000] {taskinstance.py:1937} ERROR - Task failed with exception
Traceback (most recent call last):
  File "/usr/local/lib/python3.8/configparser.py", line 846, in items
    d.update(self._sections[section])
KeyError: 'web'

During handling of the above exception, another exception occurred:

Traceback (most recent call last):
  File "/home/airflow/.local/lib/python3.8/site-packages/airflow/operators/python.py", line 192, in execute
    return_value = self.execute_callable()
  File "/home/airflow/.local/lib/python3.8/site-packages/airflow/operators/python.py", line 209, in execute_callable
    return self.python_callable(*self.op_args, **self.op_kwargs)
  File "/opt/airflow/dags/main.py", line 63, in main
    config = get_config('web')
  File "/opt/airflow/dags/main.py", line 14, in get_config
    return {key: value for key, value in parser.items(section)}
  File "/usr/local/lib/python3.8/configparser.py", line 849, in items
    raise NoSectionError(section)
configparser.NoSectionError: No section: 'web'
[2023-12-07T15:11:00.251+0000] {taskinstance.py:1400} INFO - Marking task as FAILED. dag_id=my_scraping_dag, task_id=main_task, execution_date=20230316T000000, start_date=20231207T151100, end_date=20231207T151100
[2023-12-07T15:11:00.261+0000] {standard_task_runner.py:104} ERROR - Failed to execute job 496 for task main_task (No section: 'web'; 1995)
[2023-12-07T15:11:00.282+0000] {local_task_job_runner.py:228} INFO - Task exited with return code 1
[2023-12-07T15:11:00.297+0000] {taskinstance.py:2778} INFO - 0 downstream tasks scheduled from follow-on schedule check
[2023-12-07T15:12:23.369+0000] {taskinstance.py:1159} INFO - Dependencies all met for dep_context=non-requeueable deps ti=<TaskInstance: my_scraping_dag.main_task scheduled__2023-03-16T00:00:00+00:00 [queued]>
[2023-12-07T15:12:23.375+0000] {taskinstance.py:1159} INFO - Dependencies all met for dep_context=requeueable deps ti=<TaskInstance: my_scraping_dag.main_task scheduled__2023-03-16T00:00:00+00:00 [queued]>
[2023-12-07T15:12:23.376+0000] {taskinstance.py:1361} INFO - Starting attempt 1 of 1
[2023-12-07T15:12:23.383+0000] {taskinstance.py:1382} INFO - Executing <Task(PythonOperator): main_task> on 2023-03-16 00:00:00+00:00
[2023-12-07T15:12:23.385+0000] {standard_task_runner.py:57} INFO - Started process 2218 to run task
[2023-12-07T15:12:23.387+0000] {standard_task_runner.py:84} INFO - Running: ['***', 'tasks', 'run', 'my_scraping_dag', 'main_task', 'scheduled__2023-03-16T00:00:00+00:00', '--job-id', '585', '--raw', '--subdir', 'DAGS_FOLDER/main.py', '--cfg-path', '/tmp/tmpfky2gn5d']
[2023-12-07T15:12:23.389+0000] {standard_task_runner.py:85} INFO - Job 585: Subtask main_task
[2023-12-07T15:12:23.416+0000] {task_command.py:416} INFO - Running <TaskInstance: my_scraping_dag.main_task scheduled__2023-03-16T00:00:00+00:00 [running]> on host 63b0c7e341c0
[2023-12-07T15:12:23.454+0000] {taskinstance.py:1662} INFO - Exporting env vars: AIRFLOW_CTX_DAG_OWNER='***' AIRFLOW_CTX_DAG_ID='my_scraping_dag' AIRFLOW_CTX_TASK_ID='main_task' AIRFLOW_CTX_EXECUTION_DATE='2023-03-16T00:00:00+00:00' AIRFLOW_CTX_TRY_NUMBER='1' AIRFLOW_CTX_DAG_RUN_ID='scheduled__2023-03-16T00:00:00+00:00'
[2023-12-07T15:12:23.455+0000] {taskinstance.py:1937} ERROR - Task failed with exception
Traceback (most recent call last):
  File "/usr/local/lib/python3.8/configparser.py", line 846, in items
    d.update(self._sections[section])
KeyError: 'web'

During handling of the above exception, another exception occurred:

Traceback (most recent call last):
  File "/home/airflow/.local/lib/python3.8/site-packages/airflow/operators/python.py", line 192, in execute
    return_value = self.execute_callable()
  File "/home/airflow/.local/lib/python3.8/site-packages/airflow/operators/python.py", line 209, in execute_callable
    return self.python_callable(*self.op_args, **self.op_kwargs)
  File "/opt/airflow/dags/main.py", line 63, in main
    config = get_config('web')
  File "/opt/airflow/dags/main.py", line 14, in get_config
    return {key: value for key, value in parser.items(section)}
  File "/usr/local/lib/python3.8/configparser.py", line 849, in items
    raise NoSectionError(section)
configparser.NoSectionError: No section: 'web'
[2023-12-07T15:12:23.460+0000] {taskinstance.py:1400} INFO - Marking task as FAILED. dag_id=my_scraping_dag, task_id=main_task, execution_date=20230316T000000, start_date=20231207T151223, end_date=20231207T151223
[2023-12-07T15:12:23.465+0000] {standard_task_runner.py:104} ERROR - Failed to execute job 585 for task main_task (No section: 'web'; 2218)
[2023-12-07T15:12:23.479+0000] {local_task_job_runner.py:228} INFO - Task exited with return code 1
[2023-12-07T15:12:23.487+0000] {taskinstance.py:2778} INFO - 0 downstream tasks scheduled from follow-on schedule check
[2023-12-07T16:31:50.921+0000] {taskinstance.py:1159} INFO - Dependencies all met for dep_context=non-requeueable deps ti=<TaskInstance: my_scraping_dag.main_task scheduled__2023-03-16T00:00:00+00:00 [queued]>
[2023-12-07T16:31:50.925+0000] {taskinstance.py:1159} INFO - Dependencies all met for dep_context=requeueable deps ti=<TaskInstance: my_scraping_dag.main_task scheduled__2023-03-16T00:00:00+00:00 [queued]>
[2023-12-07T16:31:50.925+0000] {taskinstance.py:1361} INFO - Starting attempt 1 of 1
[2023-12-07T16:31:50.931+0000] {taskinstance.py:1382} INFO - Executing <Task(PythonOperator): main_task> on 2023-03-16 00:00:00+00:00
[2023-12-07T16:31:50.933+0000] {standard_task_runner.py:57} INFO - Started process 3668 to run task
[2023-12-07T16:31:50.935+0000] {standard_task_runner.py:84} INFO - Running: ['***', 'tasks', 'run', 'my_scraping_dag', 'main_task', 'scheduled__2023-03-16T00:00:00+00:00', '--job-id', '663', '--raw', '--subdir', 'DAGS_FOLDER/main.py', '--cfg-path', '/tmp/tmpapwxgf_f']
[2023-12-07T16:31:50.936+0000] {standard_task_runner.py:85} INFO - Job 663: Subtask main_task
[2023-12-07T16:31:50.959+0000] {task_command.py:416} INFO - Running <TaskInstance: my_scraping_dag.main_task scheduled__2023-03-16T00:00:00+00:00 [running]> on host 63b0c7e341c0
[2023-12-07T16:31:50.989+0000] {taskinstance.py:1662} INFO - Exporting env vars: AIRFLOW_CTX_DAG_OWNER='***' AIRFLOW_CTX_DAG_ID='my_scraping_dag' AIRFLOW_CTX_TASK_ID='main_task' AIRFLOW_CTX_EXECUTION_DATE='2023-03-16T00:00:00+00:00' AIRFLOW_CTX_TRY_NUMBER='1' AIRFLOW_CTX_DAG_RUN_ID='scheduled__2023-03-16T00:00:00+00:00'
[2023-12-07T16:31:50.990+0000] {taskinstance.py:1937} ERROR - Task failed with exception
Traceback (most recent call last):
  File "/usr/local/lib/python3.8/configparser.py", line 846, in items
    d.update(self._sections[section])
KeyError: 'web'

During handling of the above exception, another exception occurred:

Traceback (most recent call last):
  File "/home/airflow/.local/lib/python3.8/site-packages/airflow/operators/python.py", line 192, in execute
    return_value = self.execute_callable()
  File "/home/airflow/.local/lib/python3.8/site-packages/airflow/operators/python.py", line 209, in execute_callable
    return self.python_callable(*self.op_args, **self.op_kwargs)
  File "/opt/airflow/dags/main.py", line 60, in main
    config = get_config('web')
  File "/opt/airflow/dags/main.py", line 22, in get_config
    return {key: value for key, value in parser.items(section)}
  File "/usr/local/lib/python3.8/configparser.py", line 849, in items
    raise NoSectionError(section)
configparser.NoSectionError: No section: 'web'
[2023-12-07T16:31:50.994+0000] {taskinstance.py:1400} INFO - Marking task as FAILED. dag_id=my_scraping_dag, task_id=main_task, execution_date=20230316T000000, start_date=20231207T163150, end_date=20231207T163150
[2023-12-07T16:31:50.998+0000] {standard_task_runner.py:104} ERROR - Failed to execute job 663 for task main_task (No section: 'web'; 3668)
[2023-12-07T16:31:51.027+0000] {local_task_job_runner.py:228} INFO - Task exited with return code 1
[2023-12-07T16:31:51.039+0000] {taskinstance.py:2778} INFO - 0 downstream tasks scheduled from follow-on schedule check
[2023-12-07T16:41:13.331+0000] {taskinstance.py:1159} INFO - Dependencies all met for dep_context=non-requeueable deps ti=<TaskInstance: my_scraping_dag.main_task scheduled__2023-03-16T00:00:00+00:00 [queued]>
[2023-12-07T16:41:13.336+0000] {taskinstance.py:1159} INFO - Dependencies all met for dep_context=requeueable deps ti=<TaskInstance: my_scraping_dag.main_task scheduled__2023-03-16T00:00:00+00:00 [queued]>
[2023-12-07T16:41:13.336+0000] {taskinstance.py:1361} INFO - Starting attempt 1 of 1
[2023-12-07T16:41:13.342+0000] {taskinstance.py:1382} INFO - Executing <Task(PythonOperator): main_task> on 2023-03-16 00:00:00+00:00
[2023-12-07T16:41:13.344+0000] {standard_task_runner.py:57} INFO - Started process 4580 to run task
[2023-12-07T16:41:13.346+0000] {standard_task_runner.py:84} INFO - Running: ['***', 'tasks', 'run', 'my_scraping_dag', 'main_task', 'scheduled__2023-03-16T00:00:00+00:00', '--job-id', '1005', '--raw', '--subdir', 'DAGS_FOLDER/main.py', '--cfg-path', '/tmp/tmpti_twpt0']
[2023-12-07T16:41:13.348+0000] {standard_task_runner.py:85} INFO - Job 1005: Subtask main_task
[2023-12-07T16:41:13.371+0000] {task_command.py:416} INFO - Running <TaskInstance: my_scraping_dag.main_task scheduled__2023-03-16T00:00:00+00:00 [running]> on host 63b0c7e341c0
[2023-12-07T16:41:13.405+0000] {taskinstance.py:1662} INFO - Exporting env vars: AIRFLOW_CTX_DAG_OWNER='***' AIRFLOW_CTX_DAG_ID='my_scraping_dag' AIRFLOW_CTX_TASK_ID='main_task' AIRFLOW_CTX_EXECUTION_DATE='2023-03-16T00:00:00+00:00' AIRFLOW_CTX_TRY_NUMBER='1' AIRFLOW_CTX_DAG_RUN_ID='scheduled__2023-03-16T00:00:00+00:00'
[2023-12-07T16:41:13.406+0000] {taskinstance.py:1937} ERROR - Task failed with exception
Traceback (most recent call last):
  File "/usr/local/lib/python3.8/configparser.py", line 846, in items
    d.update(self._sections[section])
KeyError: 'web'

During handling of the above exception, another exception occurred:

Traceback (most recent call last):
  File "/home/airflow/.local/lib/python3.8/site-packages/airflow/operators/python.py", line 192, in execute
    return_value = self.execute_callable()
  File "/home/airflow/.local/lib/python3.8/site-packages/airflow/operators/python.py", line 209, in execute_callable
    return self.python_callable(*self.op_args, **self.op_kwargs)
  File "/opt/airflow/dags/main.py", line 60, in main
    config = get_config('web')
  File "/opt/airflow/dags/main.py", line 22, in get_config
    return {key: value for key, value in parser.items(section)}
  File "/usr/local/lib/python3.8/configparser.py", line 849, in items
    raise NoSectionError(section)
configparser.NoSectionError: No section: 'web'
[2023-12-07T16:41:13.410+0000] {taskinstance.py:1400} INFO - Marking task as FAILED. dag_id=my_scraping_dag, task_id=main_task, execution_date=20230316T000000, start_date=20231207T164113, end_date=20231207T164113
[2023-12-07T16:41:13.415+0000] {standard_task_runner.py:104} ERROR - Failed to execute job 1005 for task main_task (No section: 'web'; 4580)
[2023-12-07T16:41:13.439+0000] {local_task_job_runner.py:228} INFO - Task exited with return code 1
[2023-12-07T16:41:13.452+0000] {taskinstance.py:2778} INFO - 0 downstream tasks scheduled from follow-on schedule check
[2023-12-07T17:00:18.298+0000] {taskinstance.py:1159} INFO - Dependencies all met for dep_context=non-requeueable deps ti=<TaskInstance: my_scraping_dag.main_task scheduled__2023-03-16T00:00:00+00:00 [queued]>
[2023-12-07T17:00:18.302+0000] {taskinstance.py:1159} INFO - Dependencies all met for dep_context=requeueable deps ti=<TaskInstance: my_scraping_dag.main_task scheduled__2023-03-16T00:00:00+00:00 [queued]>
[2023-12-07T17:00:18.302+0000] {taskinstance.py:1361} INFO - Starting attempt 1 of 1
[2023-12-07T17:00:18.308+0000] {taskinstance.py:1382} INFO - Executing <Task(PythonOperator): main_task> on 2023-03-16 00:00:00+00:00
[2023-12-07T17:00:18.310+0000] {standard_task_runner.py:57} INFO - Started process 5739 to run task
[2023-12-07T17:00:18.312+0000] {standard_task_runner.py:84} INFO - Running: ['***', 'tasks', 'run', 'my_scraping_dag', 'main_task', 'scheduled__2023-03-16T00:00:00+00:00', '--job-id', '1349', '--raw', '--subdir', 'DAGS_FOLDER/main.py', '--cfg-path', '/tmp/tmp65b6py_h']
[2023-12-07T17:00:18.313+0000] {standard_task_runner.py:85} INFO - Job 1349: Subtask main_task
[2023-12-07T17:00:18.338+0000] {task_command.py:416} INFO - Running <TaskInstance: my_scraping_dag.main_task scheduled__2023-03-16T00:00:00+00:00 [running]> on host 63b0c7e341c0
[2023-12-07T17:00:18.370+0000] {taskinstance.py:1662} INFO - Exporting env vars: AIRFLOW_CTX_DAG_OWNER='***' AIRFLOW_CTX_DAG_ID='my_scraping_dag' AIRFLOW_CTX_TASK_ID='main_task' AIRFLOW_CTX_EXECUTION_DATE='2023-03-16T00:00:00+00:00' AIRFLOW_CTX_TRY_NUMBER='1' AIRFLOW_CTX_DAG_RUN_ID='scheduled__2023-03-16T00:00:00+00:00'
[2023-12-07T17:00:18.395+0000] {taskinstance.py:1937} ERROR - Task failed with exception
Traceback (most recent call last):
  File "/home/airflow/.local/lib/python3.8/site-packages/airflow/operators/python.py", line 192, in execute
    return_value = self.execute_callable()
  File "/home/airflow/.local/lib/python3.8/site-packages/airflow/operators/python.py", line 209, in execute_callable
    return self.python_callable(*self.op_args, **self.op_kwargs)
  File "/opt/airflow/dags/main.py", line 33, in main
    'host': get_config('localhost'),
  File "/opt/airflow/dags/main.py", line 20, in get_config
    return Variable.get(key)
  File "/home/airflow/.local/lib/python3.8/site-packages/airflow/models/variable.py", line 140, in get
    raise KeyError(f"Variable {key} does not exist")
KeyError: 'Variable localhost does not exist'
[2023-12-07T17:00:18.399+0000] {taskinstance.py:1400} INFO - Marking task as FAILED. dag_id=my_scraping_dag, task_id=main_task, execution_date=20230316T000000, start_date=20231207T170018, end_date=20231207T170018
[2023-12-07T17:00:18.405+0000] {standard_task_runner.py:104} ERROR - Failed to execute job 1349 for task main_task ('Variable localhost does not exist'; 5739)
[2023-12-07T17:00:18.444+0000] {local_task_job_runner.py:228} INFO - Task exited with return code 1
[2023-12-07T17:00:18.456+0000] {taskinstance.py:2778} INFO - 0 downstream tasks scheduled from follow-on schedule check
[2023-12-07T17:03:40.914+0000] {taskinstance.py:1159} INFO - Dependencies all met for dep_context=non-requeueable deps ti=<TaskInstance: my_scraping_dag.main_task scheduled__2023-03-16T00:00:00+00:00 [queued]>
[2023-12-07T17:03:40.919+0000] {taskinstance.py:1159} INFO - Dependencies all met for dep_context=requeueable deps ti=<TaskInstance: my_scraping_dag.main_task scheduled__2023-03-16T00:00:00+00:00 [queued]>
[2023-12-07T17:03:40.920+0000] {taskinstance.py:1361} INFO - Starting attempt 1 of 1
[2023-12-07T17:03:40.946+0000] {taskinstance.py:1382} INFO - Executing <Task(PythonOperator): main_task> on 2023-03-16 00:00:00+00:00
[2023-12-07T17:03:40.950+0000] {standard_task_runner.py:57} INFO - Started process 7106 to run task
[2023-12-07T17:03:40.953+0000] {standard_task_runner.py:84} INFO - Running: ['***', 'tasks', 'run', 'my_scraping_dag', 'main_task', 'scheduled__2023-03-16T00:00:00+00:00', '--job-id', '1990', '--raw', '--subdir', 'DAGS_FOLDER/main.py', '--cfg-path', '/tmp/tmpvcgrb17x']
[2023-12-07T17:03:40.955+0000] {standard_task_runner.py:85} INFO - Job 1990: Subtask main_task
[2023-12-07T17:03:40.994+0000] {task_command.py:416} INFO - Running <TaskInstance: my_scraping_dag.main_task scheduled__2023-03-16T00:00:00+00:00 [running]> on host 63b0c7e341c0
[2023-12-07T17:03:41.055+0000] {taskinstance.py:1662} INFO - Exporting env vars: AIRFLOW_CTX_DAG_OWNER='***' AIRFLOW_CTX_DAG_ID='my_scraping_dag' AIRFLOW_CTX_TASK_ID='main_task' AIRFLOW_CTX_EXECUTION_DATE='2023-03-16T00:00:00+00:00' AIRFLOW_CTX_TRY_NUMBER='1' AIRFLOW_CTX_DAG_RUN_ID='scheduled__2023-03-16T00:00:00+00:00'
[2023-12-07T17:03:41.093+0000] {logging_mixin.py:154} INFO - base_url: https://tuncbotanik.com
[2023-12-07T17:03:41.098+0000] {python.py:194} INFO - Done. Returned value was: ('https://tuncbotanik.com', {'User-Agent': 'Mozilla/5.0 (Macintosh; Intel Mac OS X 10_15_7) AppleWebKit/537.36 (KHTML, like Gecko) Chrome/119.0.0.0 Safari/537.36', 'Accept-Language': 'tr-TR,tr;q=0.9,en-US;q=0.8,en;q=0.7'}, {'dbname': 'plant', 'user': 'aozgokme', 'password': '***', 'host': 'localhost', 'port': '5432'})
[2023-12-07T17:03:41.118+0000] {taskinstance.py:1400} INFO - Marking task as SUCCESS. dag_id=my_scraping_dag, task_id=main_task, execution_date=20230316T000000, start_date=20231207T170340, end_date=20231207T170341
[2023-12-07T17:03:41.166+0000] {local_task_job_runner.py:228} INFO - Task exited with return code 0
[2023-12-07T17:03:41.182+0000] {taskinstance.py:2778} INFO - 0 downstream tasks scheduled from follow-on schedule check
[2023-12-07T17:18:32.978+0000] {taskinstance.py:1159} INFO - Dependencies all met for dep_context=non-requeueable deps ti=<TaskInstance: my_scraping_dag.main_task scheduled__2023-03-16T00:00:00+00:00 [queued]>
[2023-12-07T17:18:32.984+0000] {taskinstance.py:1159} INFO - Dependencies all met for dep_context=requeueable deps ti=<TaskInstance: my_scraping_dag.main_task scheduled__2023-03-16T00:00:00+00:00 [queued]>
[2023-12-07T17:18:32.985+0000] {taskinstance.py:1361} INFO - Starting attempt 1 of 1
[2023-12-07T17:18:32.997+0000] {taskinstance.py:1382} INFO - Executing <Task(PythonOperator): main_task> on 2023-03-16 00:00:00+00:00
[2023-12-07T17:18:33.002+0000] {standard_task_runner.py:57} INFO - Started process 8691 to run task
[2023-12-07T17:18:33.010+0000] {standard_task_runner.py:84} INFO - Running: ['***', 'tasks', 'run', 'my_scraping_dag', 'main_task', 'scheduled__2023-03-16T00:00:00+00:00', '--job-id', '2604', '--raw', '--subdir', 'DAGS_FOLDER/main.py', '--cfg-path', '/tmp/tmpo9kq7382']
[2023-12-07T17:18:33.016+0000] {standard_task_runner.py:85} INFO - Job 2604: Subtask main_task
[2023-12-07T17:18:33.067+0000] {task_command.py:416} INFO - Running <TaskInstance: my_scraping_dag.main_task scheduled__2023-03-16T00:00:00+00:00 [running]> on host 63b0c7e341c0
[2023-12-07T17:18:33.124+0000] {taskinstance.py:1662} INFO - Exporting env vars: AIRFLOW_CTX_DAG_OWNER='***' AIRFLOW_CTX_DAG_ID='my_scraping_dag' AIRFLOW_CTX_TASK_ID='main_task' AIRFLOW_CTX_EXECUTION_DATE='2023-03-16T00:00:00+00:00' AIRFLOW_CTX_TRY_NUMBER='1' AIRFLOW_CTX_DAG_RUN_ID='scheduled__2023-03-16T00:00:00+00:00'
[2023-12-07T17:18:33.930+0000] {taskinstance.py:1937} ERROR - Task failed with exception
Traceback (most recent call last):
  File "/home/airflow/.local/lib/python3.8/site-packages/airflow/operators/python.py", line 192, in execute
    return_value = self.execute_callable()
  File "/home/airflow/.local/lib/python3.8/site-packages/airflow/operators/python.py", line 209, in execute_callable
    return self.python_callable(*self.op_args, **self.op_kwargs)
  File "/opt/airflow/dags/main.py", line 80, in main
    insert_data_to_db(products, db_params)
  File "/opt/airflow/dags/main.py", line 43, in insert_data_to_db
    with psycopg2.connect(**db_params) as conn:
  File "/home/airflow/.local/lib/python3.8/site-packages/psycopg2/__init__.py", line 122, in connect
    conn = _connect(dsn, connection_factory=connection_factory, **kwasync)
psycopg2.OperationalError: connection to server at "localhost" (127.0.0.1), port 5432 failed: Connection refused
	Is the server running on that host and accepting TCP/IP connections?
connection to server at "localhost" (::1), port 5432 failed: Cannot assign requested address
	Is the server running on that host and accepting TCP/IP connections?

[2023-12-07T17:18:33.935+0000] {taskinstance.py:1400} INFO - Marking task as FAILED. dag_id=my_scraping_dag, task_id=main_task, execution_date=20230316T000000, start_date=20231207T171832, end_date=20231207T171833
[2023-12-07T17:18:33.967+0000] {standard_task_runner.py:104} ERROR - Failed to execute job 2604 for task main_task (connection to server at "localhost" (127.0.0.1), port 5432 failed: Connection refused
	Is the server running on that host and accepting TCP/IP connections?
connection to server at "localhost" (::1), port 5432 failed: Cannot assign requested address
	Is the server running on that host and accepting TCP/IP connections?
; 8691)
[2023-12-07T17:18:34.009+0000] {local_task_job_runner.py:228} INFO - Task exited with return code 1
[2023-12-07T17:18:34.017+0000] {taskinstance.py:2778} INFO - 0 downstream tasks scheduled from follow-on schedule check
[2023-12-07T17:22:50.592+0000] {taskinstance.py:1159} INFO - Dependencies all met for dep_context=non-requeueable deps ti=<TaskInstance: my_scraping_dag.main_task scheduled__2023-03-16T00:00:00+00:00 [queued]>
[2023-12-07T17:22:50.602+0000] {taskinstance.py:1159} INFO - Dependencies all met for dep_context=requeueable deps ti=<TaskInstance: my_scraping_dag.main_task scheduled__2023-03-16T00:00:00+00:00 [queued]>
[2023-12-07T17:22:50.603+0000] {taskinstance.py:1361} INFO - Starting attempt 1 of 1
[2023-12-07T17:22:50.665+0000] {taskinstance.py:1382} INFO - Executing <Task(PythonOperator): main_task> on 2023-03-16 00:00:00+00:00
[2023-12-07T17:22:50.672+0000] {standard_task_runner.py:57} INFO - Started process 9486 to run task
[2023-12-07T17:22:50.675+0000] {standard_task_runner.py:84} INFO - Running: ['***', 'tasks', 'run', 'my_scraping_dag', 'main_task', 'scheduled__2023-03-16T00:00:00+00:00', '--job-id', '2946', '--raw', '--subdir', 'DAGS_FOLDER/main.py', '--cfg-path', '/tmp/tmpnb6t94pf']
[2023-12-07T17:22:50.677+0000] {standard_task_runner.py:85} INFO - Job 2946: Subtask main_task
[2023-12-07T17:22:50.719+0000] {task_command.py:416} INFO - Running <TaskInstance: my_scraping_dag.main_task scheduled__2023-03-16T00:00:00+00:00 [running]> on host 63b0c7e341c0
[2023-12-07T17:22:50.780+0000] {taskinstance.py:1662} INFO - Exporting env vars: AIRFLOW_CTX_DAG_OWNER='***' AIRFLOW_CTX_DAG_ID='my_scraping_dag' AIRFLOW_CTX_TASK_ID='main_task' AIRFLOW_CTX_EXECUTION_DATE='2023-03-16T00:00:00+00:00' AIRFLOW_CTX_TRY_NUMBER='1' AIRFLOW_CTX_DAG_RUN_ID='scheduled__2023-03-16T00:00:00+00:00'
[2023-12-07T17:22:51.471+0000] {taskinstance.py:1937} ERROR - Task failed with exception
Traceback (most recent call last):
  File "/home/airflow/.local/lib/python3.8/site-packages/airflow/operators/python.py", line 192, in execute
    return_value = self.execute_callable()
  File "/home/airflow/.local/lib/python3.8/site-packages/airflow/operators/python.py", line 209, in execute_callable
    return self.python_callable(*self.op_args, **self.op_kwargs)
  File "/opt/airflow/dags/main.py", line 73, in main
    insert_data_to_db(products, db_params)
  File "/opt/airflow/dags/main.py", line 40, in insert_data_to_db
    with psycopg2.connect(**db_params) as conn:
  File "/home/airflow/.local/lib/python3.8/site-packages/psycopg2/__init__.py", line 122, in connect
    conn = _connect(dsn, connection_factory=connection_factory, **kwasync)
psycopg2.OperationalError: connection to server at "localhost" (127.0.0.1), port 5432 failed: Connection refused
	Is the server running on that host and accepting TCP/IP connections?
connection to server at "localhost" (::1), port 5432 failed: Cannot assign requested address
	Is the server running on that host and accepting TCP/IP connections?

[2023-12-07T17:22:51.475+0000] {taskinstance.py:1400} INFO - Marking task as FAILED. dag_id=my_scraping_dag, task_id=main_task, execution_date=20230316T000000, start_date=20231207T172250, end_date=20231207T172251
[2023-12-07T17:22:51.481+0000] {standard_task_runner.py:104} ERROR - Failed to execute job 2946 for task main_task (connection to server at "localhost" (127.0.0.1), port 5432 failed: Connection refused
	Is the server running on that host and accepting TCP/IP connections?
connection to server at "localhost" (::1), port 5432 failed: Cannot assign requested address
	Is the server running on that host and accepting TCP/IP connections?
; 9486)
[2023-12-07T17:22:51.493+0000] {local_task_job_runner.py:228} INFO - Task exited with return code 1
[2023-12-07T17:22:51.502+0000] {taskinstance.py:2778} INFO - 0 downstream tasks scheduled from follow-on schedule check
[2023-12-07T17:28:32.621+0000] {taskinstance.py:1159} INFO - Dependencies all met for dep_context=non-requeueable deps ti=<TaskInstance: my_scraping_dag.main_task scheduled__2023-03-16T00:00:00+00:00 [queued]>
[2023-12-07T17:28:32.632+0000] {taskinstance.py:1159} INFO - Dependencies all met for dep_context=requeueable deps ti=<TaskInstance: my_scraping_dag.main_task scheduled__2023-03-16T00:00:00+00:00 [queued]>
[2023-12-07T17:28:32.634+0000] {taskinstance.py:1361} INFO - Starting attempt 1 of 1
[2023-12-07T17:28:32.684+0000] {taskinstance.py:1382} INFO - Executing <Task(PythonOperator): main_task> on 2023-03-16 00:00:00+00:00
[2023-12-07T17:28:32.692+0000] {standard_task_runner.py:57} INFO - Started process 10330 to run task
[2023-12-07T17:28:32.698+0000] {standard_task_runner.py:84} INFO - Running: ['***', 'tasks', 'run', 'my_scraping_dag', 'main_task', 'scheduled__2023-03-16T00:00:00+00:00', '--job-id', '3288', '--raw', '--subdir', 'DAGS_FOLDER/main.py', '--cfg-path', '/tmp/tmpcsp4y8zs']
[2023-12-07T17:28:32.702+0000] {standard_task_runner.py:85} INFO - Job 3288: Subtask main_task
[2023-12-07T17:28:32.758+0000] {task_command.py:416} INFO - Running <TaskInstance: my_scraping_dag.main_task scheduled__2023-03-16T00:00:00+00:00 [running]> on host 63b0c7e341c0
[2023-12-07T17:28:32.831+0000] {taskinstance.py:1662} INFO - Exporting env vars: AIRFLOW_CTX_DAG_OWNER='***' AIRFLOW_CTX_DAG_ID='my_scraping_dag' AIRFLOW_CTX_TASK_ID='main_task' AIRFLOW_CTX_EXECUTION_DATE='2023-03-16T00:00:00+00:00' AIRFLOW_CTX_TRY_NUMBER='1' AIRFLOW_CTX_DAG_RUN_ID='scheduled__2023-03-16T00:00:00+00:00'
[2023-12-07T17:28:33.491+0000] {taskinstance.py:1937} ERROR - Task failed with exception
Traceback (most recent call last):
  File "/home/airflow/.local/lib/python3.8/site-packages/airflow/operators/python.py", line 192, in execute
    return_value = self.execute_callable()
  File "/home/airflow/.local/lib/python3.8/site-packages/airflow/operators/python.py", line 209, in execute_callable
    return self.python_callable(*self.op_args, **self.op_kwargs)
  File "/opt/airflow/dags/main.py", line 73, in main
    insert_data_to_db(products, db_params)
  File "/opt/airflow/dags/main.py", line 40, in insert_data_to_db
    with psycopg2.connect(**db_params) as conn:
  File "/home/airflow/.local/lib/python3.8/site-packages/psycopg2/__init__.py", line 122, in connect
    conn = _connect(dsn, connection_factory=connection_factory, **kwasync)
psycopg2.OperationalError: connection to server at "localhost" (127.0.0.1), port 5432 failed: Connection refused
	Is the server running on that host and accepting TCP/IP connections?
connection to server at "localhost" (::1), port 5432 failed: Cannot assign requested address
	Is the server running on that host and accepting TCP/IP connections?

[2023-12-07T17:28:33.495+0000] {taskinstance.py:1400} INFO - Marking task as FAILED. dag_id=my_scraping_dag, task_id=main_task, execution_date=20230316T000000, start_date=20231207T172832, end_date=20231207T172833
[2023-12-07T17:28:33.501+0000] {standard_task_runner.py:104} ERROR - Failed to execute job 3288 for task main_task (connection to server at "localhost" (127.0.0.1), port 5432 failed: Connection refused
	Is the server running on that host and accepting TCP/IP connections?
connection to server at "localhost" (::1), port 5432 failed: Cannot assign requested address
	Is the server running on that host and accepting TCP/IP connections?
; 10330)
[2023-12-07T17:28:33.526+0000] {local_task_job_runner.py:228} INFO - Task exited with return code 1
[2023-12-07T17:28:33.536+0000] {taskinstance.py:2778} INFO - 0 downstream tasks scheduled from follow-on schedule check
