[2023-12-07T16:33:47.167+0000] {taskinstance.py:1159} INFO - Dependencies all met for dep_context=non-requeueable deps ti=<TaskInstance: my_scraping_dag.main_task scheduled__2023-08-31T00:00:00+00:00 [queued]>
[2023-12-07T16:33:47.172+0000] {taskinstance.py:1159} INFO - Dependencies all met for dep_context=requeueable deps ti=<TaskInstance: my_scraping_dag.main_task scheduled__2023-08-31T00:00:00+00:00 [queued]>
[2023-12-07T16:33:47.172+0000] {taskinstance.py:1361} INFO - Starting attempt 1 of 1
[2023-12-07T16:33:47.179+0000] {taskinstance.py:1382} INFO - Executing <Task(PythonOperator): main_task> on 2023-08-31 00:00:00+00:00
[2023-12-07T16:33:47.182+0000] {standard_task_runner.py:57} INFO - Started process 4062 to run task
[2023-12-07T16:33:47.185+0000] {standard_task_runner.py:84} INFO - Running: ['***', 'tasks', 'run', 'my_scraping_dag', 'main_task', 'scheduled__2023-08-31T00:00:00+00:00', '--job-id', '831', '--raw', '--subdir', 'DAGS_FOLDER/main.py', '--cfg-path', '/tmp/tmpym_incnp']
[2023-12-07T16:33:47.187+0000] {standard_task_runner.py:85} INFO - Job 831: Subtask main_task
[2023-12-07T16:33:47.217+0000] {task_command.py:416} INFO - Running <TaskInstance: my_scraping_dag.main_task scheduled__2023-08-31T00:00:00+00:00 [running]> on host 63b0c7e341c0
[2023-12-07T16:33:47.255+0000] {taskinstance.py:1662} INFO - Exporting env vars: AIRFLOW_CTX_DAG_OWNER='***' AIRFLOW_CTX_DAG_ID='my_scraping_dag' AIRFLOW_CTX_TASK_ID='main_task' AIRFLOW_CTX_EXECUTION_DATE='2023-08-31T00:00:00+00:00' AIRFLOW_CTX_TRY_NUMBER='1' AIRFLOW_CTX_DAG_RUN_ID='scheduled__2023-08-31T00:00:00+00:00'
[2023-12-07T16:33:47.257+0000] {taskinstance.py:1937} ERROR - Task failed with exception
Traceback (most recent call last):
  File "/usr/local/lib/python3.8/configparser.py", line 846, in items
    d.update(self._sections[section])
KeyError: 'web'

During handling of the above exception, another exception occurred:

Traceback (most recent call last):
  File "/home/airflow/.local/lib/python3.8/site-packages/airflow/operators/python.py", line 192, in execute
    return_value = self.execute_callable()
  File "/home/airflow/.local/lib/python3.8/site-packages/airflow/operators/python.py", line 209, in execute_callable
    return self.python_callable(*self.op_args, **self.op_kwargs)
  File "/opt/airflow/dags/main.py", line 60, in main
    config = get_config('web')
  File "/opt/airflow/dags/main.py", line 22, in get_config
    return {key: value for key, value in parser.items(section)}
  File "/usr/local/lib/python3.8/configparser.py", line 849, in items
    raise NoSectionError(section)
configparser.NoSectionError: No section: 'web'
[2023-12-07T16:33:47.264+0000] {taskinstance.py:1400} INFO - Marking task as FAILED. dag_id=my_scraping_dag, task_id=main_task, execution_date=20230831T000000, start_date=20231207T163347, end_date=20231207T163347
[2023-12-07T16:33:47.275+0000] {standard_task_runner.py:104} ERROR - Failed to execute job 831 for task main_task (No section: 'web'; 4062)
[2023-12-07T16:33:47.317+0000] {local_task_job_runner.py:228} INFO - Task exited with return code 1
[2023-12-07T16:33:47.333+0000] {taskinstance.py:2778} INFO - 0 downstream tasks scheduled from follow-on schedule check
[2023-12-07T16:42:27.730+0000] {taskinstance.py:1159} INFO - Dependencies all met for dep_context=non-requeueable deps ti=<TaskInstance: my_scraping_dag.main_task scheduled__2023-08-31T00:00:00+00:00 [queued]>
[2023-12-07T16:42:27.734+0000] {taskinstance.py:1159} INFO - Dependencies all met for dep_context=requeueable deps ti=<TaskInstance: my_scraping_dag.main_task scheduled__2023-08-31T00:00:00+00:00 [queued]>
[2023-12-07T16:42:27.735+0000] {taskinstance.py:1361} INFO - Starting attempt 1 of 1
[2023-12-07T16:42:27.740+0000] {taskinstance.py:1382} INFO - Executing <Task(PythonOperator): main_task> on 2023-08-31 00:00:00+00:00
[2023-12-07T16:42:27.742+0000] {standard_task_runner.py:57} INFO - Started process 4953 to run task
[2023-12-07T16:42:27.744+0000] {standard_task_runner.py:84} INFO - Running: ['***', 'tasks', 'run', 'my_scraping_dag', 'main_task', 'scheduled__2023-08-31T00:00:00+00:00', '--job-id', '1176', '--raw', '--subdir', 'DAGS_FOLDER/main.py', '--cfg-path', '/tmp/tmpnmyl_hcz']
[2023-12-07T16:42:27.746+0000] {standard_task_runner.py:85} INFO - Job 1176: Subtask main_task
[2023-12-07T16:42:27.767+0000] {task_command.py:416} INFO - Running <TaskInstance: my_scraping_dag.main_task scheduled__2023-08-31T00:00:00+00:00 [running]> on host 63b0c7e341c0
[2023-12-07T16:42:27.807+0000] {taskinstance.py:1662} INFO - Exporting env vars: AIRFLOW_CTX_DAG_OWNER='***' AIRFLOW_CTX_DAG_ID='my_scraping_dag' AIRFLOW_CTX_TASK_ID='main_task' AIRFLOW_CTX_EXECUTION_DATE='2023-08-31T00:00:00+00:00' AIRFLOW_CTX_TRY_NUMBER='1' AIRFLOW_CTX_DAG_RUN_ID='scheduled__2023-08-31T00:00:00+00:00'
[2023-12-07T16:42:27.808+0000] {taskinstance.py:1937} ERROR - Task failed with exception
Traceback (most recent call last):
  File "/usr/local/lib/python3.8/configparser.py", line 846, in items
    d.update(self._sections[section])
KeyError: 'web'

During handling of the above exception, another exception occurred:

Traceback (most recent call last):
  File "/home/airflow/.local/lib/python3.8/site-packages/airflow/operators/python.py", line 192, in execute
    return_value = self.execute_callable()
  File "/home/airflow/.local/lib/python3.8/site-packages/airflow/operators/python.py", line 209, in execute_callable
    return self.python_callable(*self.op_args, **self.op_kwargs)
  File "/opt/airflow/dags/main.py", line 60, in main
    config = get_config('web')
  File "/opt/airflow/dags/main.py", line 22, in get_config
    return {key: value for key, value in parser.items(section)}
  File "/usr/local/lib/python3.8/configparser.py", line 849, in items
    raise NoSectionError(section)
configparser.NoSectionError: No section: 'web'
[2023-12-07T16:42:27.817+0000] {taskinstance.py:1400} INFO - Marking task as FAILED. dag_id=my_scraping_dag, task_id=main_task, execution_date=20230831T000000, start_date=20231207T164227, end_date=20231207T164227
[2023-12-07T16:42:27.823+0000] {standard_task_runner.py:104} ERROR - Failed to execute job 1176 for task main_task (No section: 'web'; 4953)
[2023-12-07T16:42:27.836+0000] {local_task_job_runner.py:228} INFO - Task exited with return code 1
[2023-12-07T16:42:27.848+0000] {taskinstance.py:2778} INFO - 0 downstream tasks scheduled from follow-on schedule check
[2023-12-07T17:01:21.212+0000] {taskinstance.py:1159} INFO - Dependencies all met for dep_context=non-requeueable deps ti=<TaskInstance: my_scraping_dag.main_task scheduled__2023-08-31T00:00:00+00:00 [queued]>
[2023-12-07T17:01:21.216+0000] {taskinstance.py:1159} INFO - Dependencies all met for dep_context=requeueable deps ti=<TaskInstance: my_scraping_dag.main_task scheduled__2023-08-31T00:00:00+00:00 [queued]>
[2023-12-07T17:01:21.216+0000] {taskinstance.py:1361} INFO - Starting attempt 1 of 1
[2023-12-07T17:01:21.222+0000] {taskinstance.py:1382} INFO - Executing <Task(PythonOperator): main_task> on 2023-08-31 00:00:00+00:00
[2023-12-07T17:01:21.225+0000] {standard_task_runner.py:57} INFO - Started process 6354 to run task
[2023-12-07T17:01:21.227+0000] {standard_task_runner.py:84} INFO - Running: ['***', 'tasks', 'run', 'my_scraping_dag', 'main_task', 'scheduled__2023-08-31T00:00:00+00:00', '--job-id', '1644', '--raw', '--subdir', 'DAGS_FOLDER/main.py', '--cfg-path', '/tmp/tmppel_aluk']
[2023-12-07T17:01:21.229+0000] {standard_task_runner.py:85} INFO - Job 1644: Subtask main_task
[2023-12-07T17:01:21.256+0000] {task_command.py:416} INFO - Running <TaskInstance: my_scraping_dag.main_task scheduled__2023-08-31T00:00:00+00:00 [running]> on host 63b0c7e341c0
[2023-12-07T17:01:21.296+0000] {taskinstance.py:1662} INFO - Exporting env vars: AIRFLOW_CTX_DAG_OWNER='***' AIRFLOW_CTX_DAG_ID='my_scraping_dag' AIRFLOW_CTX_TASK_ID='main_task' AIRFLOW_CTX_EXECUTION_DATE='2023-08-31T00:00:00+00:00' AIRFLOW_CTX_TRY_NUMBER='1' AIRFLOW_CTX_DAG_RUN_ID='scheduled__2023-08-31T00:00:00+00:00'
[2023-12-07T17:01:21.317+0000] {logging_mixin.py:154} INFO - base_url: https://tuncbotanik.com
[2023-12-07T17:01:21.317+0000] {python.py:194} INFO - Done. Returned value was: ('https://tuncbotanik.com', {'User-Agent': 'Mozilla/5.0 (Macintosh; Intel Mac OS X 10_15_7) AppleWebKit/537.36 (KHTML, like Gecko) Chrome/119.0.0.0 Safari/537.36', 'Accept-Language': 'tr-TR,tr;q=0.9,en-US;q=0.8,en;q=0.7'}, {'dbname': 'plant', 'user': 'aozgokme', 'password': '***', 'host': 'localhost', 'port': '5432'})
[2023-12-07T17:01:21.327+0000] {taskinstance.py:1400} INFO - Marking task as SUCCESS. dag_id=my_scraping_dag, task_id=main_task, execution_date=20230831T000000, start_date=20231207T170121, end_date=20231207T170121
[2023-12-07T17:01:21.360+0000] {local_task_job_runner.py:228} INFO - Task exited with return code 0
[2023-12-07T17:01:21.400+0000] {taskinstance.py:2778} INFO - 0 downstream tasks scheduled from follow-on schedule check
[2023-12-07T17:04:38.442+0000] {taskinstance.py:1159} INFO - Dependencies all met for dep_context=non-requeueable deps ti=<TaskInstance: my_scraping_dag.main_task scheduled__2023-08-31T00:00:00+00:00 [queued]>
[2023-12-07T17:04:38.448+0000] {taskinstance.py:1159} INFO - Dependencies all met for dep_context=requeueable deps ti=<TaskInstance: my_scraping_dag.main_task scheduled__2023-08-31T00:00:00+00:00 [queued]>
[2023-12-07T17:04:38.449+0000] {taskinstance.py:1361} INFO - Starting attempt 1 of 1
[2023-12-07T17:04:38.455+0000] {taskinstance.py:1382} INFO - Executing <Task(PythonOperator): main_task> on 2023-08-31 00:00:00+00:00
[2023-12-07T17:04:38.458+0000] {standard_task_runner.py:57} INFO - Started process 7802 to run task
[2023-12-07T17:04:38.460+0000] {standard_task_runner.py:84} INFO - Running: ['***', 'tasks', 'run', 'my_scraping_dag', 'main_task', 'scheduled__2023-08-31T00:00:00+00:00', '--job-id', '2326', '--raw', '--subdir', 'DAGS_FOLDER/main.py', '--cfg-path', '/tmp/tmpvr1n_puv']
[2023-12-07T17:04:38.462+0000] {standard_task_runner.py:85} INFO - Job 2326: Subtask main_task
[2023-12-07T17:04:38.487+0000] {task_command.py:416} INFO - Running <TaskInstance: my_scraping_dag.main_task scheduled__2023-08-31T00:00:00+00:00 [running]> on host 63b0c7e341c0
[2023-12-07T17:04:38.535+0000] {taskinstance.py:1662} INFO - Exporting env vars: AIRFLOW_CTX_DAG_OWNER='***' AIRFLOW_CTX_DAG_ID='my_scraping_dag' AIRFLOW_CTX_TASK_ID='main_task' AIRFLOW_CTX_EXECUTION_DATE='2023-08-31T00:00:00+00:00' AIRFLOW_CTX_TRY_NUMBER='1' AIRFLOW_CTX_DAG_RUN_ID='scheduled__2023-08-31T00:00:00+00:00'
[2023-12-07T17:04:38.561+0000] {logging_mixin.py:154} INFO - base_url: https://tuncbotanik.com
[2023-12-07T17:04:38.561+0000] {python.py:194} INFO - Done. Returned value was: ('https://tuncbotanik.com', {'User-Agent': 'Mozilla/5.0 (Macintosh; Intel Mac OS X 10_15_7) AppleWebKit/537.36 (KHTML, like Gecko) Chrome/119.0.0.0 Safari/537.36', 'Accept-Language': 'tr-TR,tr;q=0.9,en-US;q=0.8,en;q=0.7'}, {'dbname': 'plant', 'user': 'aozgokme', 'password': '***', 'host': 'localhost', 'port': '5432'})
[2023-12-07T17:04:38.574+0000] {taskinstance.py:1400} INFO - Marking task as SUCCESS. dag_id=my_scraping_dag, task_id=main_task, execution_date=20230831T000000, start_date=20231207T170438, end_date=20231207T170438
[2023-12-07T17:04:38.593+0000] {local_task_job_runner.py:228} INFO - Task exited with return code 0
[2023-12-07T17:04:38.632+0000] {taskinstance.py:2778} INFO - 0 downstream tasks scheduled from follow-on schedule check
[2023-12-07T17:19:08.157+0000] {taskinstance.py:1159} INFO - Dependencies all met for dep_context=non-requeueable deps ti=<TaskInstance: my_scraping_dag.main_task scheduled__2023-08-31T00:00:00+00:00 [queued]>
[2023-12-07T17:19:08.163+0000] {taskinstance.py:1159} INFO - Dependencies all met for dep_context=requeueable deps ti=<TaskInstance: my_scraping_dag.main_task scheduled__2023-08-31T00:00:00+00:00 [queued]>
[2023-12-07T17:19:08.163+0000] {taskinstance.py:1361} INFO - Starting attempt 1 of 1
[2023-12-07T17:19:08.172+0000] {taskinstance.py:1382} INFO - Executing <Task(PythonOperator): main_task> on 2023-08-31 00:00:00+00:00
[2023-12-07T17:19:08.176+0000] {standard_task_runner.py:57} INFO - Started process 9039 to run task
[2023-12-07T17:19:08.178+0000] {standard_task_runner.py:84} INFO - Running: ['***', 'tasks', 'run', 'my_scraping_dag', 'main_task', 'scheduled__2023-08-31T00:00:00+00:00', '--job-id', '2772', '--raw', '--subdir', 'DAGS_FOLDER/main.py', '--cfg-path', '/tmp/tmpb8b99xba']
[2023-12-07T17:19:08.181+0000] {standard_task_runner.py:85} INFO - Job 2772: Subtask main_task
[2023-12-07T17:19:08.227+0000] {task_command.py:416} INFO - Running <TaskInstance: my_scraping_dag.main_task scheduled__2023-08-31T00:00:00+00:00 [running]> on host 63b0c7e341c0
[2023-12-07T17:19:08.324+0000] {taskinstance.py:1662} INFO - Exporting env vars: AIRFLOW_CTX_DAG_OWNER='***' AIRFLOW_CTX_DAG_ID='my_scraping_dag' AIRFLOW_CTX_TASK_ID='main_task' AIRFLOW_CTX_EXECUTION_DATE='2023-08-31T00:00:00+00:00' AIRFLOW_CTX_TRY_NUMBER='1' AIRFLOW_CTX_DAG_RUN_ID='scheduled__2023-08-31T00:00:00+00:00'
[2023-12-07T17:19:09.185+0000] {taskinstance.py:1937} ERROR - Task failed with exception
Traceback (most recent call last):
  File "/home/airflow/.local/lib/python3.8/site-packages/airflow/operators/python.py", line 192, in execute
    return_value = self.execute_callable()
  File "/home/airflow/.local/lib/python3.8/site-packages/airflow/operators/python.py", line 209, in execute_callable
    return self.python_callable(*self.op_args, **self.op_kwargs)
  File "/opt/airflow/dags/main.py", line 80, in main
    insert_data_to_db(products, db_params)
  File "/opt/airflow/dags/main.py", line 43, in insert_data_to_db
    with psycopg2.connect(**db_params) as conn:
  File "/home/airflow/.local/lib/python3.8/site-packages/psycopg2/__init__.py", line 122, in connect
    conn = _connect(dsn, connection_factory=connection_factory, **kwasync)
psycopg2.OperationalError: connection to server at "localhost" (127.0.0.1), port 5432 failed: Connection refused
	Is the server running on that host and accepting TCP/IP connections?
connection to server at "localhost" (::1), port 5432 failed: Cannot assign requested address
	Is the server running on that host and accepting TCP/IP connections?

[2023-12-07T17:19:09.191+0000] {taskinstance.py:1400} INFO - Marking task as FAILED. dag_id=my_scraping_dag, task_id=main_task, execution_date=20230831T000000, start_date=20231207T171908, end_date=20231207T171909
[2023-12-07T17:19:09.197+0000] {standard_task_runner.py:104} ERROR - Failed to execute job 2772 for task main_task (connection to server at "localhost" (127.0.0.1), port 5432 failed: Connection refused
	Is the server running on that host and accepting TCP/IP connections?
connection to server at "localhost" (::1), port 5432 failed: Cannot assign requested address
	Is the server running on that host and accepting TCP/IP connections?
; 9039)
[2023-12-07T17:19:09.237+0000] {local_task_job_runner.py:228} INFO - Task exited with return code 1
[2023-12-07T17:19:09.246+0000] {taskinstance.py:2778} INFO - 0 downstream tasks scheduled from follow-on schedule check
[2023-12-07T17:23:27.816+0000] {taskinstance.py:1159} INFO - Dependencies all met for dep_context=non-requeueable deps ti=<TaskInstance: my_scraping_dag.main_task scheduled__2023-08-31T00:00:00+00:00 [queued]>
[2023-12-07T17:23:27.820+0000] {taskinstance.py:1159} INFO - Dependencies all met for dep_context=requeueable deps ti=<TaskInstance: my_scraping_dag.main_task scheduled__2023-08-31T00:00:00+00:00 [queued]>
[2023-12-07T17:23:27.821+0000] {taskinstance.py:1361} INFO - Starting attempt 1 of 1
[2023-12-07T17:23:27.829+0000] {taskinstance.py:1382} INFO - Executing <Task(PythonOperator): main_task> on 2023-08-31 00:00:00+00:00
[2023-12-07T17:23:27.833+0000] {standard_task_runner.py:57} INFO - Started process 9847 to run task
[2023-12-07T17:23:27.835+0000] {standard_task_runner.py:84} INFO - Running: ['***', 'tasks', 'run', 'my_scraping_dag', 'main_task', 'scheduled__2023-08-31T00:00:00+00:00', '--job-id', '3114', '--raw', '--subdir', 'DAGS_FOLDER/main.py', '--cfg-path', '/tmp/tmp_01n53py']
[2023-12-07T17:23:27.838+0000] {standard_task_runner.py:85} INFO - Job 3114: Subtask main_task
[2023-12-07T17:23:27.865+0000] {task_command.py:416} INFO - Running <TaskInstance: my_scraping_dag.main_task scheduled__2023-08-31T00:00:00+00:00 [running]> on host 63b0c7e341c0
[2023-12-07T17:23:27.910+0000] {taskinstance.py:1662} INFO - Exporting env vars: AIRFLOW_CTX_DAG_OWNER='***' AIRFLOW_CTX_DAG_ID='my_scraping_dag' AIRFLOW_CTX_TASK_ID='main_task' AIRFLOW_CTX_EXECUTION_DATE='2023-08-31T00:00:00+00:00' AIRFLOW_CTX_TRY_NUMBER='1' AIRFLOW_CTX_DAG_RUN_ID='scheduled__2023-08-31T00:00:00+00:00'
[2023-12-07T17:23:28.702+0000] {taskinstance.py:1937} ERROR - Task failed with exception
Traceback (most recent call last):
  File "/home/airflow/.local/lib/python3.8/site-packages/airflow/operators/python.py", line 192, in execute
    return_value = self.execute_callable()
  File "/home/airflow/.local/lib/python3.8/site-packages/airflow/operators/python.py", line 209, in execute_callable
    return self.python_callable(*self.op_args, **self.op_kwargs)
  File "/opt/airflow/dags/main.py", line 73, in main
    insert_data_to_db(products, db_params)
  File "/opt/airflow/dags/main.py", line 40, in insert_data_to_db
    with psycopg2.connect(**db_params) as conn:
  File "/home/airflow/.local/lib/python3.8/site-packages/psycopg2/__init__.py", line 122, in connect
    conn = _connect(dsn, connection_factory=connection_factory, **kwasync)
psycopg2.OperationalError: connection to server at "localhost" (127.0.0.1), port 5432 failed: Connection refused
	Is the server running on that host and accepting TCP/IP connections?
connection to server at "localhost" (::1), port 5432 failed: Cannot assign requested address
	Is the server running on that host and accepting TCP/IP connections?

[2023-12-07T17:23:28.711+0000] {taskinstance.py:1400} INFO - Marking task as FAILED. dag_id=my_scraping_dag, task_id=main_task, execution_date=20230831T000000, start_date=20231207T172327, end_date=20231207T172328
[2023-12-07T17:23:28.721+0000] {standard_task_runner.py:104} ERROR - Failed to execute job 3114 for task main_task (connection to server at "localhost" (127.0.0.1), port 5432 failed: Connection refused
	Is the server running on that host and accepting TCP/IP connections?
connection to server at "localhost" (::1), port 5432 failed: Cannot assign requested address
	Is the server running on that host and accepting TCP/IP connections?
; 9847)
[2023-12-07T17:23:28.735+0000] {local_task_job_runner.py:228} INFO - Task exited with return code 1
[2023-12-07T17:23:28.750+0000] {taskinstance.py:2778} INFO - 0 downstream tasks scheduled from follow-on schedule check
[2023-12-07T17:29:06.896+0000] {taskinstance.py:1159} INFO - Dependencies all met for dep_context=non-requeueable deps ti=<TaskInstance: my_scraping_dag.main_task scheduled__2023-08-31T00:00:00+00:00 [queued]>
[2023-12-07T17:29:06.901+0000] {taskinstance.py:1159} INFO - Dependencies all met for dep_context=requeueable deps ti=<TaskInstance: my_scraping_dag.main_task scheduled__2023-08-31T00:00:00+00:00 [queued]>
[2023-12-07T17:29:06.902+0000] {taskinstance.py:1361} INFO - Starting attempt 1 of 1
[2023-12-07T17:29:06.910+0000] {taskinstance.py:1382} INFO - Executing <Task(PythonOperator): main_task> on 2023-08-31 00:00:00+00:00
[2023-12-07T17:29:06.913+0000] {standard_task_runner.py:57} INFO - Started process 10678 to run task
[2023-12-07T17:29:06.917+0000] {standard_task_runner.py:84} INFO - Running: ['***', 'tasks', 'run', 'my_scraping_dag', 'main_task', 'scheduled__2023-08-31T00:00:00+00:00', '--job-id', '3456', '--raw', '--subdir', 'DAGS_FOLDER/main.py', '--cfg-path', '/tmp/tmpfirqf7im']
[2023-12-07T17:29:06.919+0000] {standard_task_runner.py:85} INFO - Job 3456: Subtask main_task
[2023-12-07T17:29:06.949+0000] {task_command.py:416} INFO - Running <TaskInstance: my_scraping_dag.main_task scheduled__2023-08-31T00:00:00+00:00 [running]> on host 63b0c7e341c0
[2023-12-07T17:29:06.989+0000] {taskinstance.py:1662} INFO - Exporting env vars: AIRFLOW_CTX_DAG_OWNER='***' AIRFLOW_CTX_DAG_ID='my_scraping_dag' AIRFLOW_CTX_TASK_ID='main_task' AIRFLOW_CTX_EXECUTION_DATE='2023-08-31T00:00:00+00:00' AIRFLOW_CTX_TRY_NUMBER='1' AIRFLOW_CTX_DAG_RUN_ID='scheduled__2023-08-31T00:00:00+00:00'
[2023-12-07T17:29:07.727+0000] {taskinstance.py:1937} ERROR - Task failed with exception
Traceback (most recent call last):
  File "/home/airflow/.local/lib/python3.8/site-packages/airflow/operators/python.py", line 192, in execute
    return_value = self.execute_callable()
  File "/home/airflow/.local/lib/python3.8/site-packages/airflow/operators/python.py", line 209, in execute_callable
    return self.python_callable(*self.op_args, **self.op_kwargs)
  File "/opt/airflow/dags/main.py", line 73, in main
    insert_data_to_db(products, db_params)
  File "/opt/airflow/dags/main.py", line 40, in insert_data_to_db
    with psycopg2.connect(**db_params) as conn:
  File "/home/airflow/.local/lib/python3.8/site-packages/psycopg2/__init__.py", line 122, in connect
    conn = _connect(dsn, connection_factory=connection_factory, **kwasync)
psycopg2.OperationalError: connection to server at "localhost" (127.0.0.1), port 5432 failed: Connection refused
	Is the server running on that host and accepting TCP/IP connections?
connection to server at "localhost" (::1), port 5432 failed: Cannot assign requested address
	Is the server running on that host and accepting TCP/IP connections?

[2023-12-07T17:29:07.738+0000] {taskinstance.py:1400} INFO - Marking task as FAILED. dag_id=my_scraping_dag, task_id=main_task, execution_date=20230831T000000, start_date=20231207T172906, end_date=20231207T172907
[2023-12-07T17:29:07.745+0000] {standard_task_runner.py:104} ERROR - Failed to execute job 3456 for task main_task (connection to server at "localhost" (127.0.0.1), port 5432 failed: Connection refused
	Is the server running on that host and accepting TCP/IP connections?
connection to server at "localhost" (::1), port 5432 failed: Cannot assign requested address
	Is the server running on that host and accepting TCP/IP connections?
; 10678)
[2023-12-07T17:29:07.775+0000] {local_task_job_runner.py:228} INFO - Task exited with return code 1
[2023-12-07T17:29:07.786+0000] {taskinstance.py:2778} INFO - 0 downstream tasks scheduled from follow-on schedule check
[2023-12-09T07:35:16.276+0000] {taskinstance.py:1159} INFO - Dependencies all met for dep_context=non-requeueable deps ti=<TaskInstance: my_scraping_dag.main_task scheduled__2023-08-31T00:00:00+00:00 [queued]>
[2023-12-09T07:35:16.285+0000] {taskinstance.py:1159} INFO - Dependencies all met for dep_context=requeueable deps ti=<TaskInstance: my_scraping_dag.main_task scheduled__2023-08-31T00:00:00+00:00 [queued]>
[2023-12-09T07:35:16.286+0000] {taskinstance.py:1361} INFO - Starting attempt 1 of 1
[2023-12-09T07:35:16.295+0000] {taskinstance.py:1382} INFO - Executing <Task(PythonOperator): main_task> on 2023-08-31 00:00:00+00:00
[2023-12-09T07:35:16.299+0000] {standard_task_runner.py:57} INFO - Started process 1095 to run task
[2023-12-09T07:35:16.302+0000] {standard_task_runner.py:84} INFO - Running: ['***', 'tasks', 'run', 'my_scraping_dag', 'main_task', 'scheduled__2023-08-31T00:00:00+00:00', '--job-id', '246', '--raw', '--subdir', 'DAGS_FOLDER/main.py', '--cfg-path', '/tmp/tmpaj59t0_a']
[2023-12-09T07:35:16.304+0000] {standard_task_runner.py:85} INFO - Job 246: Subtask main_task
[2023-12-09T07:35:16.332+0000] {task_command.py:416} INFO - Running <TaskInstance: my_scraping_dag.main_task scheduled__2023-08-31T00:00:00+00:00 [running]> on host 36b5ef2505c9
[2023-12-09T07:35:16.374+0000] {taskinstance.py:1662} INFO - Exporting env vars: AIRFLOW_CTX_DAG_OWNER='***' AIRFLOW_CTX_DAG_ID='my_scraping_dag' AIRFLOW_CTX_TASK_ID='main_task' AIRFLOW_CTX_EXECUTION_DATE='2023-08-31T00:00:00+00:00' AIRFLOW_CTX_TRY_NUMBER='1' AIRFLOW_CTX_DAG_RUN_ID='scheduled__2023-08-31T00:00:00+00:00'
[2023-12-09T07:35:16.379+0000] {taskinstance.py:1937} ERROR - Task failed with exception
Traceback (most recent call last):
  File "/home/airflow/.local/lib/python3.8/site-packages/airflow/operators/python.py", line 192, in execute
    return_value = self.execute_callable()
  File "/home/airflow/.local/lib/python3.8/site-packages/airflow/operators/python.py", line 209, in execute_callable
    return self.python_callable(*self.op_args, **self.op_kwargs)
  File "/opt/airflow/dags/main.py", line 64, in main
    base_url = Variable.get('base_url')
  File "/home/airflow/.local/lib/python3.8/site-packages/airflow/models/variable.py", line 140, in get
    raise KeyError(f"Variable {key} does not exist")
KeyError: 'Variable base_url does not exist'
[2023-12-09T07:35:16.385+0000] {taskinstance.py:1400} INFO - Marking task as FAILED. dag_id=my_scraping_dag, task_id=main_task, execution_date=20230831T000000, start_date=20231209T073516, end_date=20231209T073516
[2023-12-09T07:35:16.390+0000] {standard_task_runner.py:104} ERROR - Failed to execute job 246 for task main_task ('Variable base_url does not exist'; 1095)
[2023-12-09T07:35:16.434+0000] {local_task_job_runner.py:228} INFO - Task exited with return code 1
[2023-12-09T07:35:16.442+0000] {taskinstance.py:2778} INFO - 0 downstream tasks scheduled from follow-on schedule check
