[2023-12-07T16:34:15.137+0000] {taskinstance.py:1159} INFO - Dependencies all met for dep_context=non-requeueable deps ti=<TaskInstance: my_scraping_dag.main_task scheduled__2023-10-27T00:00:00+00:00 [queued]>
[2023-12-07T16:34:15.141+0000] {taskinstance.py:1159} INFO - Dependencies all met for dep_context=requeueable deps ti=<TaskInstance: my_scraping_dag.main_task scheduled__2023-10-27T00:00:00+00:00 [queued]>
[2023-12-07T16:34:15.141+0000] {taskinstance.py:1361} INFO - Starting attempt 1 of 1
[2023-12-07T16:34:15.148+0000] {taskinstance.py:1382} INFO - Executing <Task(PythonOperator): main_task> on 2023-10-27 00:00:00+00:00
[2023-12-07T16:34:15.150+0000] {standard_task_runner.py:57} INFO - Started process 4181 to run task
[2023-12-07T16:34:15.152+0000] {standard_task_runner.py:84} INFO - Running: ['***', 'tasks', 'run', 'my_scraping_dag', 'main_task', 'scheduled__2023-10-27T00:00:00+00:00', '--job-id', '888', '--raw', '--subdir', 'DAGS_FOLDER/main.py', '--cfg-path', '/tmp/tmpy3i4hbzo']
[2023-12-07T16:34:15.154+0000] {standard_task_runner.py:85} INFO - Job 888: Subtask main_task
[2023-12-07T16:34:15.178+0000] {task_command.py:416} INFO - Running <TaskInstance: my_scraping_dag.main_task scheduled__2023-10-27T00:00:00+00:00 [running]> on host 63b0c7e341c0
[2023-12-07T16:34:15.218+0000] {taskinstance.py:1662} INFO - Exporting env vars: AIRFLOW_CTX_DAG_OWNER='***' AIRFLOW_CTX_DAG_ID='my_scraping_dag' AIRFLOW_CTX_TASK_ID='main_task' AIRFLOW_CTX_EXECUTION_DATE='2023-10-27T00:00:00+00:00' AIRFLOW_CTX_TRY_NUMBER='1' AIRFLOW_CTX_DAG_RUN_ID='scheduled__2023-10-27T00:00:00+00:00'
[2023-12-07T16:34:15.220+0000] {taskinstance.py:1937} ERROR - Task failed with exception
Traceback (most recent call last):
  File "/usr/local/lib/python3.8/configparser.py", line 846, in items
    d.update(self._sections[section])
KeyError: 'web'

During handling of the above exception, another exception occurred:

Traceback (most recent call last):
  File "/home/airflow/.local/lib/python3.8/site-packages/airflow/operators/python.py", line 192, in execute
    return_value = self.execute_callable()
  File "/home/airflow/.local/lib/python3.8/site-packages/airflow/operators/python.py", line 209, in execute_callable
    return self.python_callable(*self.op_args, **self.op_kwargs)
  File "/opt/airflow/dags/main.py", line 60, in main
    config = get_config('web')
  File "/opt/airflow/dags/main.py", line 22, in get_config
    return {key: value for key, value in parser.items(section)}
  File "/usr/local/lib/python3.8/configparser.py", line 849, in items
    raise NoSectionError(section)
configparser.NoSectionError: No section: 'web'
[2023-12-07T16:34:15.225+0000] {taskinstance.py:1400} INFO - Marking task as FAILED. dag_id=my_scraping_dag, task_id=main_task, execution_date=20231027T000000, start_date=20231207T163415, end_date=20231207T163415
[2023-12-07T16:34:15.231+0000] {standard_task_runner.py:104} ERROR - Failed to execute job 888 for task main_task (No section: 'web'; 4181)
[2023-12-07T16:34:15.245+0000] {local_task_job_runner.py:228} INFO - Task exited with return code 1
[2023-12-07T16:34:15.259+0000] {taskinstance.py:2778} INFO - 0 downstream tasks scheduled from follow-on schedule check
[2023-12-07T16:42:58.210+0000] {taskinstance.py:1159} INFO - Dependencies all met for dep_context=non-requeueable deps ti=<TaskInstance: my_scraping_dag.main_task scheduled__2023-10-27T00:00:00+00:00 [queued]>
[2023-12-07T16:42:58.215+0000] {taskinstance.py:1159} INFO - Dependencies all met for dep_context=requeueable deps ti=<TaskInstance: my_scraping_dag.main_task scheduled__2023-10-27T00:00:00+00:00 [queued]>
[2023-12-07T16:42:58.215+0000] {taskinstance.py:1361} INFO - Starting attempt 1 of 1
[2023-12-07T16:42:58.233+0000] {taskinstance.py:1382} INFO - Executing <Task(PythonOperator): main_task> on 2023-10-27 00:00:00+00:00
[2023-12-07T16:42:58.236+0000] {standard_task_runner.py:57} INFO - Started process 5081 to run task
[2023-12-07T16:42:58.239+0000] {standard_task_runner.py:84} INFO - Running: ['***', 'tasks', 'run', 'my_scraping_dag', 'main_task', 'scheduled__2023-10-27T00:00:00+00:00', '--job-id', '1233', '--raw', '--subdir', 'DAGS_FOLDER/main.py', '--cfg-path', '/tmp/tmpv60stjbm']
[2023-12-07T16:42:58.241+0000] {standard_task_runner.py:85} INFO - Job 1233: Subtask main_task
[2023-12-07T16:42:58.269+0000] {task_command.py:416} INFO - Running <TaskInstance: my_scraping_dag.main_task scheduled__2023-10-27T00:00:00+00:00 [running]> on host 63b0c7e341c0
[2023-12-07T16:42:58.314+0000] {taskinstance.py:1662} INFO - Exporting env vars: AIRFLOW_CTX_DAG_OWNER='***' AIRFLOW_CTX_DAG_ID='my_scraping_dag' AIRFLOW_CTX_TASK_ID='main_task' AIRFLOW_CTX_EXECUTION_DATE='2023-10-27T00:00:00+00:00' AIRFLOW_CTX_TRY_NUMBER='1' AIRFLOW_CTX_DAG_RUN_ID='scheduled__2023-10-27T00:00:00+00:00'
[2023-12-07T16:42:58.316+0000] {taskinstance.py:1937} ERROR - Task failed with exception
Traceback (most recent call last):
  File "/usr/local/lib/python3.8/configparser.py", line 846, in items
    d.update(self._sections[section])
KeyError: 'web'

During handling of the above exception, another exception occurred:

Traceback (most recent call last):
  File "/home/airflow/.local/lib/python3.8/site-packages/airflow/operators/python.py", line 192, in execute
    return_value = self.execute_callable()
  File "/home/airflow/.local/lib/python3.8/site-packages/airflow/operators/python.py", line 209, in execute_callable
    return self.python_callable(*self.op_args, **self.op_kwargs)
  File "/opt/airflow/dags/main.py", line 60, in main
    config = get_config('web')
  File "/opt/airflow/dags/main.py", line 22, in get_config
    return {key: value for key, value in parser.items(section)}
  File "/usr/local/lib/python3.8/configparser.py", line 849, in items
    raise NoSectionError(section)
configparser.NoSectionError: No section: 'web'
[2023-12-07T16:42:58.323+0000] {taskinstance.py:1400} INFO - Marking task as FAILED. dag_id=my_scraping_dag, task_id=main_task, execution_date=20231027T000000, start_date=20231207T164258, end_date=20231207T164258
[2023-12-07T16:42:58.366+0000] {standard_task_runner.py:104} ERROR - Failed to execute job 1233 for task main_task (No section: 'web'; 5081)
[2023-12-07T16:42:58.372+0000] {local_task_job_runner.py:228} INFO - Task exited with return code 1
[2023-12-07T16:42:58.391+0000] {taskinstance.py:2778} INFO - 0 downstream tasks scheduled from follow-on schedule check
[2023-12-07T17:01:40.369+0000] {taskinstance.py:1159} INFO - Dependencies all met for dep_context=non-requeueable deps ti=<TaskInstance: my_scraping_dag.main_task scheduled__2023-10-27T00:00:00+00:00 [queued]>
[2023-12-07T17:01:40.374+0000] {taskinstance.py:1159} INFO - Dependencies all met for dep_context=requeueable deps ti=<TaskInstance: my_scraping_dag.main_task scheduled__2023-10-27T00:00:00+00:00 [queued]>
[2023-12-07T17:01:40.374+0000] {taskinstance.py:1361} INFO - Starting attempt 1 of 1
[2023-12-07T17:01:40.385+0000] {taskinstance.py:1382} INFO - Executing <Task(PythonOperator): main_task> on 2023-10-27 00:00:00+00:00
[2023-12-07T17:01:40.387+0000] {standard_task_runner.py:57} INFO - Started process 6594 to run task
[2023-12-07T17:01:40.389+0000] {standard_task_runner.py:84} INFO - Running: ['***', 'tasks', 'run', 'my_scraping_dag', 'main_task', 'scheduled__2023-10-27T00:00:00+00:00', '--job-id', '1758', '--raw', '--subdir', 'DAGS_FOLDER/main.py', '--cfg-path', '/tmp/tmpgkzuk1cl']
[2023-12-07T17:01:40.391+0000] {standard_task_runner.py:85} INFO - Job 1758: Subtask main_task
[2023-12-07T17:01:40.427+0000] {task_command.py:416} INFO - Running <TaskInstance: my_scraping_dag.main_task scheduled__2023-10-27T00:00:00+00:00 [running]> on host 63b0c7e341c0
[2023-12-07T17:01:40.473+0000] {taskinstance.py:1662} INFO - Exporting env vars: AIRFLOW_CTX_DAG_OWNER='***' AIRFLOW_CTX_DAG_ID='my_scraping_dag' AIRFLOW_CTX_TASK_ID='main_task' AIRFLOW_CTX_EXECUTION_DATE='2023-10-27T00:00:00+00:00' AIRFLOW_CTX_TRY_NUMBER='1' AIRFLOW_CTX_DAG_RUN_ID='scheduled__2023-10-27T00:00:00+00:00'
[2023-12-07T17:01:40.496+0000] {logging_mixin.py:154} INFO - base_url: https://tuncbotanik.com
[2023-12-07T17:01:40.497+0000] {python.py:194} INFO - Done. Returned value was: ('https://tuncbotanik.com', {'User-Agent': 'Mozilla/5.0 (Macintosh; Intel Mac OS X 10_15_7) AppleWebKit/537.36 (KHTML, like Gecko) Chrome/119.0.0.0 Safari/537.36', 'Accept-Language': 'tr-TR,tr;q=0.9,en-US;q=0.8,en;q=0.7'}, {'dbname': 'plant', 'user': 'aozgokme', 'password': '***', 'host': 'localhost', 'port': '5432'})
[2023-12-07T17:01:40.510+0000] {taskinstance.py:1400} INFO - Marking task as SUCCESS. dag_id=my_scraping_dag, task_id=main_task, execution_date=20231027T000000, start_date=20231207T170140, end_date=20231207T170140
[2023-12-07T17:01:40.563+0000] {local_task_job_runner.py:228} INFO - Task exited with return code 0
[2023-12-07T17:01:40.613+0000] {taskinstance.py:2778} INFO - 0 downstream tasks scheduled from follow-on schedule check
[2023-12-07T17:04:58.789+0000] {taskinstance.py:1159} INFO - Dependencies all met for dep_context=non-requeueable deps ti=<TaskInstance: my_scraping_dag.main_task scheduled__2023-10-27T00:00:00+00:00 [queued]>
[2023-12-07T17:04:58.799+0000] {taskinstance.py:1159} INFO - Dependencies all met for dep_context=requeueable deps ti=<TaskInstance: my_scraping_dag.main_task scheduled__2023-10-27T00:00:00+00:00 [queued]>
[2023-12-07T17:04:58.800+0000] {taskinstance.py:1361} INFO - Starting attempt 1 of 1
[2023-12-07T17:04:58.809+0000] {taskinstance.py:1382} INFO - Executing <Task(PythonOperator): main_task> on 2023-10-27 00:00:00+00:00
[2023-12-07T17:04:58.813+0000] {standard_task_runner.py:57} INFO - Started process 8027 to run task
[2023-12-07T17:04:58.815+0000] {standard_task_runner.py:84} INFO - Running: ['***', 'tasks', 'run', 'my_scraping_dag', 'main_task', 'scheduled__2023-10-27T00:00:00+00:00', '--job-id', '2438', '--raw', '--subdir', 'DAGS_FOLDER/main.py', '--cfg-path', '/tmp/tmp3lvlr7dc']
[2023-12-07T17:04:58.817+0000] {standard_task_runner.py:85} INFO - Job 2438: Subtask main_task
[2023-12-07T17:04:58.849+0000] {task_command.py:416} INFO - Running <TaskInstance: my_scraping_dag.main_task scheduled__2023-10-27T00:00:00+00:00 [running]> on host 63b0c7e341c0
[2023-12-07T17:04:58.895+0000] {taskinstance.py:1662} INFO - Exporting env vars: AIRFLOW_CTX_DAG_OWNER='***' AIRFLOW_CTX_DAG_ID='my_scraping_dag' AIRFLOW_CTX_TASK_ID='main_task' AIRFLOW_CTX_EXECUTION_DATE='2023-10-27T00:00:00+00:00' AIRFLOW_CTX_TRY_NUMBER='1' AIRFLOW_CTX_DAG_RUN_ID='scheduled__2023-10-27T00:00:00+00:00'
[2023-12-07T17:04:58.917+0000] {logging_mixin.py:154} INFO - base_url: https://tuncbotanik.com
[2023-12-07T17:04:58.918+0000] {python.py:194} INFO - Done. Returned value was: ('https://tuncbotanik.com', {'User-Agent': 'Mozilla/5.0 (Macintosh; Intel Mac OS X 10_15_7) AppleWebKit/537.36 (KHTML, like Gecko) Chrome/119.0.0.0 Safari/537.36', 'Accept-Language': 'tr-TR,tr;q=0.9,en-US;q=0.8,en;q=0.7'}, {'dbname': 'plant', 'user': 'aozgokme', 'password': '***', 'host': 'localhost', 'port': '5432'})
[2023-12-07T17:04:58.930+0000] {taskinstance.py:1400} INFO - Marking task as SUCCESS. dag_id=my_scraping_dag, task_id=main_task, execution_date=20231027T000000, start_date=20231207T170458, end_date=20231207T170458
[2023-12-07T17:04:58.949+0000] {local_task_job_runner.py:228} INFO - Task exited with return code 0
[2023-12-07T17:04:58.981+0000] {taskinstance.py:2778} INFO - 0 downstream tasks scheduled from follow-on schedule check
[2023-12-07T17:19:21.826+0000] {taskinstance.py:1159} INFO - Dependencies all met for dep_context=non-requeueable deps ti=<TaskInstance: my_scraping_dag.main_task scheduled__2023-10-27T00:00:00+00:00 [queued]>
[2023-12-07T17:19:21.831+0000] {taskinstance.py:1159} INFO - Dependencies all met for dep_context=requeueable deps ti=<TaskInstance: my_scraping_dag.main_task scheduled__2023-10-27T00:00:00+00:00 [queued]>
[2023-12-07T17:19:21.831+0000] {taskinstance.py:1361} INFO - Starting attempt 1 of 1
[2023-12-07T17:19:21.852+0000] {taskinstance.py:1382} INFO - Executing <Task(PythonOperator): main_task> on 2023-10-27 00:00:00+00:00
[2023-12-07T17:19:21.855+0000] {standard_task_runner.py:57} INFO - Started process 9166 to run task
[2023-12-07T17:19:21.858+0000] {standard_task_runner.py:84} INFO - Running: ['***', 'tasks', 'run', 'my_scraping_dag', 'main_task', 'scheduled__2023-10-27T00:00:00+00:00', '--job-id', '2829', '--raw', '--subdir', 'DAGS_FOLDER/main.py', '--cfg-path', '/tmp/tmpsy65jmcx']
[2023-12-07T17:19:21.859+0000] {standard_task_runner.py:85} INFO - Job 2829: Subtask main_task
[2023-12-07T17:19:21.890+0000] {task_command.py:416} INFO - Running <TaskInstance: my_scraping_dag.main_task scheduled__2023-10-27T00:00:00+00:00 [running]> on host 63b0c7e341c0
[2023-12-07T17:19:21.944+0000] {taskinstance.py:1662} INFO - Exporting env vars: AIRFLOW_CTX_DAG_OWNER='***' AIRFLOW_CTX_DAG_ID='my_scraping_dag' AIRFLOW_CTX_TASK_ID='main_task' AIRFLOW_CTX_EXECUTION_DATE='2023-10-27T00:00:00+00:00' AIRFLOW_CTX_TRY_NUMBER='1' AIRFLOW_CTX_DAG_RUN_ID='scheduled__2023-10-27T00:00:00+00:00'
[2023-12-07T17:19:22.825+0000] {taskinstance.py:1937} ERROR - Task failed with exception
Traceback (most recent call last):
  File "/home/airflow/.local/lib/python3.8/site-packages/airflow/operators/python.py", line 192, in execute
    return_value = self.execute_callable()
  File "/home/airflow/.local/lib/python3.8/site-packages/airflow/operators/python.py", line 209, in execute_callable
    return self.python_callable(*self.op_args, **self.op_kwargs)
  File "/opt/airflow/dags/main.py", line 80, in main
    insert_data_to_db(products, db_params)
  File "/opt/airflow/dags/main.py", line 43, in insert_data_to_db
    with psycopg2.connect(**db_params) as conn:
  File "/home/airflow/.local/lib/python3.8/site-packages/psycopg2/__init__.py", line 122, in connect
    conn = _connect(dsn, connection_factory=connection_factory, **kwasync)
psycopg2.OperationalError: connection to server at "localhost" (127.0.0.1), port 5432 failed: Connection refused
	Is the server running on that host and accepting TCP/IP connections?
connection to server at "localhost" (::1), port 5432 failed: Cannot assign requested address
	Is the server running on that host and accepting TCP/IP connections?

[2023-12-07T17:19:22.834+0000] {taskinstance.py:1400} INFO - Marking task as FAILED. dag_id=my_scraping_dag, task_id=main_task, execution_date=20231027T000000, start_date=20231207T171921, end_date=20231207T171922
[2023-12-07T17:19:22.841+0000] {standard_task_runner.py:104} ERROR - Failed to execute job 2829 for task main_task (connection to server at "localhost" (127.0.0.1), port 5432 failed: Connection refused
	Is the server running on that host and accepting TCP/IP connections?
connection to server at "localhost" (::1), port 5432 failed: Cannot assign requested address
	Is the server running on that host and accepting TCP/IP connections?
; 9166)
[2023-12-07T17:19:22.876+0000] {local_task_job_runner.py:228} INFO - Task exited with return code 1
[2023-12-07T17:19:22.886+0000] {taskinstance.py:2778} INFO - 0 downstream tasks scheduled from follow-on schedule check
[2023-12-07T17:23:39.514+0000] {taskinstance.py:1159} INFO - Dependencies all met for dep_context=non-requeueable deps ti=<TaskInstance: my_scraping_dag.main_task scheduled__2023-10-27T00:00:00+00:00 [queued]>
[2023-12-07T17:23:39.525+0000] {taskinstance.py:1159} INFO - Dependencies all met for dep_context=requeueable deps ti=<TaskInstance: my_scraping_dag.main_task scheduled__2023-10-27T00:00:00+00:00 [queued]>
[2023-12-07T17:23:39.525+0000] {taskinstance.py:1361} INFO - Starting attempt 1 of 1
[2023-12-07T17:23:39.542+0000] {taskinstance.py:1382} INFO - Executing <Task(PythonOperator): main_task> on 2023-10-27 00:00:00+00:00
[2023-12-07T17:23:39.551+0000] {standard_task_runner.py:57} INFO - Started process 9960 to run task
[2023-12-07T17:23:39.563+0000] {standard_task_runner.py:84} INFO - Running: ['***', 'tasks', 'run', 'my_scraping_dag', 'main_task', 'scheduled__2023-10-27T00:00:00+00:00', '--job-id', '3171', '--raw', '--subdir', 'DAGS_FOLDER/main.py', '--cfg-path', '/tmp/tmpspmzkxa0']
[2023-12-07T17:23:39.573+0000] {standard_task_runner.py:85} INFO - Job 3171: Subtask main_task
[2023-12-07T17:23:39.621+0000] {task_command.py:416} INFO - Running <TaskInstance: my_scraping_dag.main_task scheduled__2023-10-27T00:00:00+00:00 [running]> on host 63b0c7e341c0
[2023-12-07T17:23:39.695+0000] {taskinstance.py:1662} INFO - Exporting env vars: AIRFLOW_CTX_DAG_OWNER='***' AIRFLOW_CTX_DAG_ID='my_scraping_dag' AIRFLOW_CTX_TASK_ID='main_task' AIRFLOW_CTX_EXECUTION_DATE='2023-10-27T00:00:00+00:00' AIRFLOW_CTX_TRY_NUMBER='1' AIRFLOW_CTX_DAG_RUN_ID='scheduled__2023-10-27T00:00:00+00:00'
[2023-12-07T17:23:40.387+0000] {taskinstance.py:1937} ERROR - Task failed with exception
Traceback (most recent call last):
  File "/home/airflow/.local/lib/python3.8/site-packages/airflow/operators/python.py", line 192, in execute
    return_value = self.execute_callable()
  File "/home/airflow/.local/lib/python3.8/site-packages/airflow/operators/python.py", line 209, in execute_callable
    return self.python_callable(*self.op_args, **self.op_kwargs)
  File "/opt/airflow/dags/main.py", line 73, in main
    insert_data_to_db(products, db_params)
  File "/opt/airflow/dags/main.py", line 40, in insert_data_to_db
    with psycopg2.connect(**db_params) as conn:
  File "/home/airflow/.local/lib/python3.8/site-packages/psycopg2/__init__.py", line 122, in connect
    conn = _connect(dsn, connection_factory=connection_factory, **kwasync)
psycopg2.OperationalError: connection to server at "localhost" (127.0.0.1), port 5432 failed: Connection refused
	Is the server running on that host and accepting TCP/IP connections?
connection to server at "localhost" (::1), port 5432 failed: Cannot assign requested address
	Is the server running on that host and accepting TCP/IP connections?

[2023-12-07T17:23:40.391+0000] {taskinstance.py:1400} INFO - Marking task as FAILED. dag_id=my_scraping_dag, task_id=main_task, execution_date=20231027T000000, start_date=20231207T172339, end_date=20231207T172340
[2023-12-07T17:23:40.397+0000] {standard_task_runner.py:104} ERROR - Failed to execute job 3171 for task main_task (connection to server at "localhost" (127.0.0.1), port 5432 failed: Connection refused
	Is the server running on that host and accepting TCP/IP connections?
connection to server at "localhost" (::1), port 5432 failed: Cannot assign requested address
	Is the server running on that host and accepting TCP/IP connections?
; 9960)
[2023-12-07T17:23:40.415+0000] {local_task_job_runner.py:228} INFO - Task exited with return code 1
[2023-12-07T17:23:40.423+0000] {taskinstance.py:2778} INFO - 0 downstream tasks scheduled from follow-on schedule check
[2023-12-07T17:29:16.844+0000] {taskinstance.py:1159} INFO - Dependencies all met for dep_context=non-requeueable deps ti=<TaskInstance: my_scraping_dag.main_task scheduled__2023-10-27T00:00:00+00:00 [queued]>
[2023-12-07T17:29:16.862+0000] {taskinstance.py:1159} INFO - Dependencies all met for dep_context=requeueable deps ti=<TaskInstance: my_scraping_dag.main_task scheduled__2023-10-27T00:00:00+00:00 [queued]>
[2023-12-07T17:29:16.864+0000] {taskinstance.py:1361} INFO - Starting attempt 1 of 1
[2023-12-07T17:29:17.002+0000] {taskinstance.py:1382} INFO - Executing <Task(PythonOperator): main_task> on 2023-10-27 00:00:00+00:00
[2023-12-07T17:29:17.007+0000] {standard_task_runner.py:57} INFO - Started process 10796 to run task
[2023-12-07T17:29:17.012+0000] {standard_task_runner.py:84} INFO - Running: ['***', 'tasks', 'run', 'my_scraping_dag', 'main_task', 'scheduled__2023-10-27T00:00:00+00:00', '--job-id', '3513', '--raw', '--subdir', 'DAGS_FOLDER/main.py', '--cfg-path', '/tmp/tmpd5qm20ny']
[2023-12-07T17:29:17.015+0000] {standard_task_runner.py:85} INFO - Job 3513: Subtask main_task
[2023-12-07T17:29:17.088+0000] {task_command.py:416} INFO - Running <TaskInstance: my_scraping_dag.main_task scheduled__2023-10-27T00:00:00+00:00 [running]> on host 63b0c7e341c0
[2023-12-07T17:29:17.155+0000] {taskinstance.py:1662} INFO - Exporting env vars: AIRFLOW_CTX_DAG_OWNER='***' AIRFLOW_CTX_DAG_ID='my_scraping_dag' AIRFLOW_CTX_TASK_ID='main_task' AIRFLOW_CTX_EXECUTION_DATE='2023-10-27T00:00:00+00:00' AIRFLOW_CTX_TRY_NUMBER='1' AIRFLOW_CTX_DAG_RUN_ID='scheduled__2023-10-27T00:00:00+00:00'
[2023-12-07T17:29:17.923+0000] {taskinstance.py:1937} ERROR - Task failed with exception
Traceback (most recent call last):
  File "/home/airflow/.local/lib/python3.8/site-packages/airflow/operators/python.py", line 192, in execute
    return_value = self.execute_callable()
  File "/home/airflow/.local/lib/python3.8/site-packages/airflow/operators/python.py", line 209, in execute_callable
    return self.python_callable(*self.op_args, **self.op_kwargs)
  File "/opt/airflow/dags/main.py", line 73, in main
    insert_data_to_db(products, db_params)
  File "/opt/airflow/dags/main.py", line 40, in insert_data_to_db
    with psycopg2.connect(**db_params) as conn:
  File "/home/airflow/.local/lib/python3.8/site-packages/psycopg2/__init__.py", line 122, in connect
    conn = _connect(dsn, connection_factory=connection_factory, **kwasync)
psycopg2.OperationalError: connection to server at "localhost" (127.0.0.1), port 5432 failed: Connection refused
	Is the server running on that host and accepting TCP/IP connections?
connection to server at "localhost" (::1), port 5432 failed: Cannot assign requested address
	Is the server running on that host and accepting TCP/IP connections?

[2023-12-07T17:29:17.927+0000] {taskinstance.py:1400} INFO - Marking task as FAILED. dag_id=my_scraping_dag, task_id=main_task, execution_date=20231027T000000, start_date=20231207T172916, end_date=20231207T172917
[2023-12-07T17:29:17.933+0000] {standard_task_runner.py:104} ERROR - Failed to execute job 3513 for task main_task (connection to server at "localhost" (127.0.0.1), port 5432 failed: Connection refused
	Is the server running on that host and accepting TCP/IP connections?
connection to server at "localhost" (::1), port 5432 failed: Cannot assign requested address
	Is the server running on that host and accepting TCP/IP connections?
; 10796)
[2023-12-07T17:29:17.958+0000] {local_task_job_runner.py:228} INFO - Task exited with return code 1
[2023-12-07T17:29:17.966+0000] {taskinstance.py:2778} INFO - 0 downstream tasks scheduled from follow-on schedule check
