[2023-12-07T16:34:15.094+0000] {taskinstance.py:1159} INFO - Dependencies all met for dep_context=non-requeueable deps ti=<TaskInstance: my_scraping_dag.main_task scheduled__2023-10-26T00:00:00+00:00 [queued]>
[2023-12-07T16:34:15.099+0000] {taskinstance.py:1159} INFO - Dependencies all met for dep_context=requeueable deps ti=<TaskInstance: my_scraping_dag.main_task scheduled__2023-10-26T00:00:00+00:00 [queued]>
[2023-12-07T16:34:15.099+0000] {taskinstance.py:1361} INFO - Starting attempt 1 of 1
[2023-12-07T16:34:15.116+0000] {taskinstance.py:1382} INFO - Executing <Task(PythonOperator): main_task> on 2023-10-26 00:00:00+00:00
[2023-12-07T16:34:15.118+0000] {standard_task_runner.py:57} INFO - Started process 4179 to run task
[2023-12-07T16:34:15.121+0000] {standard_task_runner.py:84} INFO - Running: ['***', 'tasks', 'run', 'my_scraping_dag', 'main_task', 'scheduled__2023-10-26T00:00:00+00:00', '--job-id', '887', '--raw', '--subdir', 'DAGS_FOLDER/main.py', '--cfg-path', '/tmp/tmpzc06l4po']
[2023-12-07T16:34:15.124+0000] {standard_task_runner.py:85} INFO - Job 887: Subtask main_task
[2023-12-07T16:34:15.153+0000] {task_command.py:416} INFO - Running <TaskInstance: my_scraping_dag.main_task scheduled__2023-10-26T00:00:00+00:00 [running]> on host 63b0c7e341c0
[2023-12-07T16:34:15.188+0000] {taskinstance.py:1662} INFO - Exporting env vars: AIRFLOW_CTX_DAG_OWNER='***' AIRFLOW_CTX_DAG_ID='my_scraping_dag' AIRFLOW_CTX_TASK_ID='main_task' AIRFLOW_CTX_EXECUTION_DATE='2023-10-26T00:00:00+00:00' AIRFLOW_CTX_TRY_NUMBER='1' AIRFLOW_CTX_DAG_RUN_ID='scheduled__2023-10-26T00:00:00+00:00'
[2023-12-07T16:34:15.189+0000] {taskinstance.py:1937} ERROR - Task failed with exception
Traceback (most recent call last):
  File "/usr/local/lib/python3.8/configparser.py", line 846, in items
    d.update(self._sections[section])
KeyError: 'web'

During handling of the above exception, another exception occurred:

Traceback (most recent call last):
  File "/home/airflow/.local/lib/python3.8/site-packages/airflow/operators/python.py", line 192, in execute
    return_value = self.execute_callable()
  File "/home/airflow/.local/lib/python3.8/site-packages/airflow/operators/python.py", line 209, in execute_callable
    return self.python_callable(*self.op_args, **self.op_kwargs)
  File "/opt/airflow/dags/main.py", line 60, in main
    config = get_config('web')
  File "/opt/airflow/dags/main.py", line 22, in get_config
    return {key: value for key, value in parser.items(section)}
  File "/usr/local/lib/python3.8/configparser.py", line 849, in items
    raise NoSectionError(section)
configparser.NoSectionError: No section: 'web'
[2023-12-07T16:34:15.197+0000] {taskinstance.py:1400} INFO - Marking task as FAILED. dag_id=my_scraping_dag, task_id=main_task, execution_date=20231026T000000, start_date=20231207T163415, end_date=20231207T163415
[2023-12-07T16:34:15.203+0000] {standard_task_runner.py:104} ERROR - Failed to execute job 887 for task main_task (No section: 'web'; 4179)
[2023-12-07T16:34:15.213+0000] {local_task_job_runner.py:228} INFO - Task exited with return code 1
[2023-12-07T16:34:15.226+0000] {taskinstance.py:2778} INFO - 0 downstream tasks scheduled from follow-on schedule check
[2023-12-07T16:42:58.196+0000] {taskinstance.py:1159} INFO - Dependencies all met for dep_context=non-requeueable deps ti=<TaskInstance: my_scraping_dag.main_task scheduled__2023-10-26T00:00:00+00:00 [queued]>
[2023-12-07T16:42:58.200+0000] {taskinstance.py:1159} INFO - Dependencies all met for dep_context=requeueable deps ti=<TaskInstance: my_scraping_dag.main_task scheduled__2023-10-26T00:00:00+00:00 [queued]>
[2023-12-07T16:42:58.200+0000] {taskinstance.py:1361} INFO - Starting attempt 1 of 1
[2023-12-07T16:42:58.207+0000] {taskinstance.py:1382} INFO - Executing <Task(PythonOperator): main_task> on 2023-10-26 00:00:00+00:00
[2023-12-07T16:42:58.210+0000] {standard_task_runner.py:57} INFO - Started process 5080 to run task
[2023-12-07T16:42:58.212+0000] {standard_task_runner.py:84} INFO - Running: ['***', 'tasks', 'run', 'my_scraping_dag', 'main_task', 'scheduled__2023-10-26T00:00:00+00:00', '--job-id', '1232', '--raw', '--subdir', 'DAGS_FOLDER/main.py', '--cfg-path', '/tmp/tmpyju4jqy6']
[2023-12-07T16:42:58.214+0000] {standard_task_runner.py:85} INFO - Job 1232: Subtask main_task
[2023-12-07T16:42:58.240+0000] {task_command.py:416} INFO - Running <TaskInstance: my_scraping_dag.main_task scheduled__2023-10-26T00:00:00+00:00 [running]> on host 63b0c7e341c0
[2023-12-07T16:42:58.281+0000] {taskinstance.py:1662} INFO - Exporting env vars: AIRFLOW_CTX_DAG_OWNER='***' AIRFLOW_CTX_DAG_ID='my_scraping_dag' AIRFLOW_CTX_TASK_ID='main_task' AIRFLOW_CTX_EXECUTION_DATE='2023-10-26T00:00:00+00:00' AIRFLOW_CTX_TRY_NUMBER='1' AIRFLOW_CTX_DAG_RUN_ID='scheduled__2023-10-26T00:00:00+00:00'
[2023-12-07T16:42:58.284+0000] {taskinstance.py:1937} ERROR - Task failed with exception
Traceback (most recent call last):
  File "/usr/local/lib/python3.8/configparser.py", line 846, in items
    d.update(self._sections[section])
KeyError: 'web'

During handling of the above exception, another exception occurred:

Traceback (most recent call last):
  File "/home/airflow/.local/lib/python3.8/site-packages/airflow/operators/python.py", line 192, in execute
    return_value = self.execute_callable()
  File "/home/airflow/.local/lib/python3.8/site-packages/airflow/operators/python.py", line 209, in execute_callable
    return self.python_callable(*self.op_args, **self.op_kwargs)
  File "/opt/airflow/dags/main.py", line 60, in main
    config = get_config('web')
  File "/opt/airflow/dags/main.py", line 22, in get_config
    return {key: value for key, value in parser.items(section)}
  File "/usr/local/lib/python3.8/configparser.py", line 849, in items
    raise NoSectionError(section)
configparser.NoSectionError: No section: 'web'
[2023-12-07T16:42:58.290+0000] {taskinstance.py:1400} INFO - Marking task as FAILED. dag_id=my_scraping_dag, task_id=main_task, execution_date=20231026T000000, start_date=20231207T164258, end_date=20231207T164258
[2023-12-07T16:42:58.296+0000] {standard_task_runner.py:104} ERROR - Failed to execute job 1232 for task main_task (No section: 'web'; 5080)
[2023-12-07T16:42:58.304+0000] {local_task_job_runner.py:228} INFO - Task exited with return code 1
[2023-12-07T16:42:58.321+0000] {taskinstance.py:2778} INFO - 0 downstream tasks scheduled from follow-on schedule check
[2023-12-07T17:01:40.328+0000] {taskinstance.py:1159} INFO - Dependencies all met for dep_context=non-requeueable deps ti=<TaskInstance: my_scraping_dag.main_task scheduled__2023-10-26T00:00:00+00:00 [queued]>
[2023-12-07T17:01:40.332+0000] {taskinstance.py:1159} INFO - Dependencies all met for dep_context=requeueable deps ti=<TaskInstance: my_scraping_dag.main_task scheduled__2023-10-26T00:00:00+00:00 [queued]>
[2023-12-07T17:01:40.333+0000] {taskinstance.py:1361} INFO - Starting attempt 1 of 1
[2023-12-07T17:01:40.340+0000] {taskinstance.py:1382} INFO - Executing <Task(PythonOperator): main_task> on 2023-10-26 00:00:00+00:00
[2023-12-07T17:01:40.343+0000] {standard_task_runner.py:57} INFO - Started process 6592 to run task
[2023-12-07T17:01:40.346+0000] {standard_task_runner.py:84} INFO - Running: ['***', 'tasks', 'run', 'my_scraping_dag', 'main_task', 'scheduled__2023-10-26T00:00:00+00:00', '--job-id', '1756', '--raw', '--subdir', 'DAGS_FOLDER/main.py', '--cfg-path', '/tmp/tmpe98gx8tb']
[2023-12-07T17:01:40.349+0000] {standard_task_runner.py:85} INFO - Job 1756: Subtask main_task
[2023-12-07T17:01:40.380+0000] {task_command.py:416} INFO - Running <TaskInstance: my_scraping_dag.main_task scheduled__2023-10-26T00:00:00+00:00 [running]> on host 63b0c7e341c0
[2023-12-07T17:01:40.429+0000] {taskinstance.py:1662} INFO - Exporting env vars: AIRFLOW_CTX_DAG_OWNER='***' AIRFLOW_CTX_DAG_ID='my_scraping_dag' AIRFLOW_CTX_TASK_ID='main_task' AIRFLOW_CTX_EXECUTION_DATE='2023-10-26T00:00:00+00:00' AIRFLOW_CTX_TRY_NUMBER='1' AIRFLOW_CTX_DAG_RUN_ID='scheduled__2023-10-26T00:00:00+00:00'
[2023-12-07T17:01:40.458+0000] {logging_mixin.py:154} INFO - base_url: https://tuncbotanik.com
[2023-12-07T17:01:40.460+0000] {python.py:194} INFO - Done. Returned value was: ('https://tuncbotanik.com', {'User-Agent': 'Mozilla/5.0 (Macintosh; Intel Mac OS X 10_15_7) AppleWebKit/537.36 (KHTML, like Gecko) Chrome/119.0.0.0 Safari/537.36', 'Accept-Language': 'tr-TR,tr;q=0.9,en-US;q=0.8,en;q=0.7'}, {'dbname': 'plant', 'user': 'aozgokme', 'password': '***', 'host': 'localhost', 'port': '5432'})
[2023-12-07T17:01:40.473+0000] {taskinstance.py:1400} INFO - Marking task as SUCCESS. dag_id=my_scraping_dag, task_id=main_task, execution_date=20231026T000000, start_date=20231207T170140, end_date=20231207T170140
[2023-12-07T17:01:40.519+0000] {local_task_job_runner.py:228} INFO - Task exited with return code 0
[2023-12-07T17:01:40.550+0000] {taskinstance.py:2778} INFO - 0 downstream tasks scheduled from follow-on schedule check
[2023-12-07T17:04:58.664+0000] {taskinstance.py:1159} INFO - Dependencies all met for dep_context=non-requeueable deps ti=<TaskInstance: my_scraping_dag.main_task scheduled__2023-10-26T00:00:00+00:00 [queued]>
[2023-12-07T17:04:58.673+0000] {taskinstance.py:1159} INFO - Dependencies all met for dep_context=requeueable deps ti=<TaskInstance: my_scraping_dag.main_task scheduled__2023-10-26T00:00:00+00:00 [queued]>
[2023-12-07T17:04:58.674+0000] {taskinstance.py:1361} INFO - Starting attempt 1 of 1
[2023-12-07T17:04:58.688+0000] {taskinstance.py:1382} INFO - Executing <Task(PythonOperator): main_task> on 2023-10-26 00:00:00+00:00
[2023-12-07T17:04:58.695+0000] {standard_task_runner.py:57} INFO - Started process 8022 to run task
[2023-12-07T17:04:58.700+0000] {standard_task_runner.py:84} INFO - Running: ['***', 'tasks', 'run', 'my_scraping_dag', 'main_task', 'scheduled__2023-10-26T00:00:00+00:00', '--job-id', '2435', '--raw', '--subdir', 'DAGS_FOLDER/main.py', '--cfg-path', '/tmp/tmpht6psdka']
[2023-12-07T17:04:58.703+0000] {standard_task_runner.py:85} INFO - Job 2435: Subtask main_task
[2023-12-07T17:04:58.749+0000] {task_command.py:416} INFO - Running <TaskInstance: my_scraping_dag.main_task scheduled__2023-10-26T00:00:00+00:00 [running]> on host 63b0c7e341c0
[2023-12-07T17:04:58.802+0000] {taskinstance.py:1662} INFO - Exporting env vars: AIRFLOW_CTX_DAG_OWNER='***' AIRFLOW_CTX_DAG_ID='my_scraping_dag' AIRFLOW_CTX_TASK_ID='main_task' AIRFLOW_CTX_EXECUTION_DATE='2023-10-26T00:00:00+00:00' AIRFLOW_CTX_TRY_NUMBER='1' AIRFLOW_CTX_DAG_RUN_ID='scheduled__2023-10-26T00:00:00+00:00'
[2023-12-07T17:04:58.833+0000] {logging_mixin.py:154} INFO - base_url: https://tuncbotanik.com
[2023-12-07T17:04:58.833+0000] {python.py:194} INFO - Done. Returned value was: ('https://tuncbotanik.com', {'User-Agent': 'Mozilla/5.0 (Macintosh; Intel Mac OS X 10_15_7) AppleWebKit/537.36 (KHTML, like Gecko) Chrome/119.0.0.0 Safari/537.36', 'Accept-Language': 'tr-TR,tr;q=0.9,en-US;q=0.8,en;q=0.7'}, {'dbname': 'plant', 'user': 'aozgokme', 'password': '***', 'host': 'localhost', 'port': '5432'})
[2023-12-07T17:04:58.851+0000] {taskinstance.py:1400} INFO - Marking task as SUCCESS. dag_id=my_scraping_dag, task_id=main_task, execution_date=20231026T000000, start_date=20231207T170458, end_date=20231207T170458
[2023-12-07T17:04:58.875+0000] {local_task_job_runner.py:228} INFO - Task exited with return code 0
[2023-12-07T17:04:58.889+0000] {taskinstance.py:2778} INFO - 1 downstream tasks scheduled from follow-on schedule check
[2023-12-07T17:19:21.804+0000] {taskinstance.py:1159} INFO - Dependencies all met for dep_context=non-requeueable deps ti=<TaskInstance: my_scraping_dag.main_task scheduled__2023-10-26T00:00:00+00:00 [queued]>
[2023-12-07T17:19:21.808+0000] {taskinstance.py:1159} INFO - Dependencies all met for dep_context=requeueable deps ti=<TaskInstance: my_scraping_dag.main_task scheduled__2023-10-26T00:00:00+00:00 [queued]>
[2023-12-07T17:19:21.808+0000] {taskinstance.py:1361} INFO - Starting attempt 1 of 1
[2023-12-07T17:19:21.815+0000] {taskinstance.py:1382} INFO - Executing <Task(PythonOperator): main_task> on 2023-10-26 00:00:00+00:00
[2023-12-07T17:19:21.817+0000] {standard_task_runner.py:57} INFO - Started process 9165 to run task
[2023-12-07T17:19:21.820+0000] {standard_task_runner.py:84} INFO - Running: ['***', 'tasks', 'run', 'my_scraping_dag', 'main_task', 'scheduled__2023-10-26T00:00:00+00:00', '--job-id', '2828', '--raw', '--subdir', 'DAGS_FOLDER/main.py', '--cfg-path', '/tmp/tmp3bbxghwo']
[2023-12-07T17:19:21.822+0000] {standard_task_runner.py:85} INFO - Job 2828: Subtask main_task
[2023-12-07T17:19:21.848+0000] {task_command.py:416} INFO - Running <TaskInstance: my_scraping_dag.main_task scheduled__2023-10-26T00:00:00+00:00 [running]> on host 63b0c7e341c0
[2023-12-07T17:19:21.893+0000] {taskinstance.py:1662} INFO - Exporting env vars: AIRFLOW_CTX_DAG_OWNER='***' AIRFLOW_CTX_DAG_ID='my_scraping_dag' AIRFLOW_CTX_TASK_ID='main_task' AIRFLOW_CTX_EXECUTION_DATE='2023-10-26T00:00:00+00:00' AIRFLOW_CTX_TRY_NUMBER='1' AIRFLOW_CTX_DAG_RUN_ID='scheduled__2023-10-26T00:00:00+00:00'
[2023-12-07T17:19:22.811+0000] {taskinstance.py:1937} ERROR - Task failed with exception
Traceback (most recent call last):
  File "/home/airflow/.local/lib/python3.8/site-packages/airflow/operators/python.py", line 192, in execute
    return_value = self.execute_callable()
  File "/home/airflow/.local/lib/python3.8/site-packages/airflow/operators/python.py", line 209, in execute_callable
    return self.python_callable(*self.op_args, **self.op_kwargs)
  File "/opt/airflow/dags/main.py", line 80, in main
    insert_data_to_db(products, db_params)
  File "/opt/airflow/dags/main.py", line 43, in insert_data_to_db
    with psycopg2.connect(**db_params) as conn:
  File "/home/airflow/.local/lib/python3.8/site-packages/psycopg2/__init__.py", line 122, in connect
    conn = _connect(dsn, connection_factory=connection_factory, **kwasync)
psycopg2.OperationalError: connection to server at "localhost" (127.0.0.1), port 5432 failed: Connection refused
	Is the server running on that host and accepting TCP/IP connections?
connection to server at "localhost" (::1), port 5432 failed: Cannot assign requested address
	Is the server running on that host and accepting TCP/IP connections?

[2023-12-07T17:19:22.819+0000] {taskinstance.py:1400} INFO - Marking task as FAILED. dag_id=my_scraping_dag, task_id=main_task, execution_date=20231026T000000, start_date=20231207T171921, end_date=20231207T171922
[2023-12-07T17:19:22.832+0000] {standard_task_runner.py:104} ERROR - Failed to execute job 2828 for task main_task (connection to server at "localhost" (127.0.0.1), port 5432 failed: Connection refused
	Is the server running on that host and accepting TCP/IP connections?
connection to server at "localhost" (::1), port 5432 failed: Cannot assign requested address
	Is the server running on that host and accepting TCP/IP connections?
; 9165)
[2023-12-07T17:19:22.876+0000] {local_task_job_runner.py:228} INFO - Task exited with return code 1
[2023-12-07T17:19:22.886+0000] {taskinstance.py:2778} INFO - 0 downstream tasks scheduled from follow-on schedule check
[2023-12-07T17:23:39.455+0000] {taskinstance.py:1159} INFO - Dependencies all met for dep_context=non-requeueable deps ti=<TaskInstance: my_scraping_dag.main_task scheduled__2023-10-26T00:00:00+00:00 [queued]>
[2023-12-07T17:23:39.475+0000] {taskinstance.py:1159} INFO - Dependencies all met for dep_context=requeueable deps ti=<TaskInstance: my_scraping_dag.main_task scheduled__2023-10-26T00:00:00+00:00 [queued]>
[2023-12-07T17:23:39.475+0000] {taskinstance.py:1361} INFO - Starting attempt 1 of 1
[2023-12-07T17:23:39.546+0000] {taskinstance.py:1382} INFO - Executing <Task(PythonOperator): main_task> on 2023-10-26 00:00:00+00:00
[2023-12-07T17:23:39.550+0000] {standard_task_runner.py:57} INFO - Started process 9959 to run task
[2023-12-07T17:23:39.557+0000] {standard_task_runner.py:84} INFO - Running: ['***', 'tasks', 'run', 'my_scraping_dag', 'main_task', 'scheduled__2023-10-26T00:00:00+00:00', '--job-id', '3170', '--raw', '--subdir', 'DAGS_FOLDER/main.py', '--cfg-path', '/tmp/tmp8g8b65a_']
[2023-12-07T17:23:39.572+0000] {standard_task_runner.py:85} INFO - Job 3170: Subtask main_task
[2023-12-07T17:23:39.640+0000] {task_command.py:416} INFO - Running <TaskInstance: my_scraping_dag.main_task scheduled__2023-10-26T00:00:00+00:00 [running]> on host 63b0c7e341c0
[2023-12-07T17:23:39.710+0000] {taskinstance.py:1662} INFO - Exporting env vars: AIRFLOW_CTX_DAG_OWNER='***' AIRFLOW_CTX_DAG_ID='my_scraping_dag' AIRFLOW_CTX_TASK_ID='main_task' AIRFLOW_CTX_EXECUTION_DATE='2023-10-26T00:00:00+00:00' AIRFLOW_CTX_TRY_NUMBER='1' AIRFLOW_CTX_DAG_RUN_ID='scheduled__2023-10-26T00:00:00+00:00'
[2023-12-07T17:23:40.448+0000] {taskinstance.py:1937} ERROR - Task failed with exception
Traceback (most recent call last):
  File "/home/airflow/.local/lib/python3.8/site-packages/airflow/operators/python.py", line 192, in execute
    return_value = self.execute_callable()
  File "/home/airflow/.local/lib/python3.8/site-packages/airflow/operators/python.py", line 209, in execute_callable
    return self.python_callable(*self.op_args, **self.op_kwargs)
  File "/opt/airflow/dags/main.py", line 73, in main
    insert_data_to_db(products, db_params)
  File "/opt/airflow/dags/main.py", line 40, in insert_data_to_db
    with psycopg2.connect(**db_params) as conn:
  File "/home/airflow/.local/lib/python3.8/site-packages/psycopg2/__init__.py", line 122, in connect
    conn = _connect(dsn, connection_factory=connection_factory, **kwasync)
psycopg2.OperationalError: connection to server at "localhost" (127.0.0.1), port 5432 failed: Connection refused
	Is the server running on that host and accepting TCP/IP connections?
connection to server at "localhost" (::1), port 5432 failed: Cannot assign requested address
	Is the server running on that host and accepting TCP/IP connections?

[2023-12-07T17:23:40.452+0000] {taskinstance.py:1400} INFO - Marking task as FAILED. dag_id=my_scraping_dag, task_id=main_task, execution_date=20231026T000000, start_date=20231207T172339, end_date=20231207T172340
[2023-12-07T17:23:40.457+0000] {standard_task_runner.py:104} ERROR - Failed to execute job 3170 for task main_task (connection to server at "localhost" (127.0.0.1), port 5432 failed: Connection refused
	Is the server running on that host and accepting TCP/IP connections?
connection to server at "localhost" (::1), port 5432 failed: Cannot assign requested address
	Is the server running on that host and accepting TCP/IP connections?
; 9959)
[2023-12-07T17:23:40.478+0000] {local_task_job_runner.py:228} INFO - Task exited with return code 1
[2023-12-07T17:23:40.534+0000] {taskinstance.py:2778} INFO - 0 downstream tasks scheduled from follow-on schedule check
[2023-12-07T17:29:16.727+0000] {taskinstance.py:1159} INFO - Dependencies all met for dep_context=non-requeueable deps ti=<TaskInstance: my_scraping_dag.main_task scheduled__2023-10-26T00:00:00+00:00 [queued]>
[2023-12-07T17:29:16.736+0000] {taskinstance.py:1159} INFO - Dependencies all met for dep_context=requeueable deps ti=<TaskInstance: my_scraping_dag.main_task scheduled__2023-10-26T00:00:00+00:00 [queued]>
[2023-12-07T17:29:16.737+0000] {taskinstance.py:1361} INFO - Starting attempt 1 of 1
[2023-12-07T17:29:16.780+0000] {taskinstance.py:1382} INFO - Executing <Task(PythonOperator): main_task> on 2023-10-26 00:00:00+00:00
[2023-12-07T17:29:16.786+0000] {standard_task_runner.py:57} INFO - Started process 10794 to run task
[2023-12-07T17:29:16.791+0000] {standard_task_runner.py:84} INFO - Running: ['***', 'tasks', 'run', 'my_scraping_dag', 'main_task', 'scheduled__2023-10-26T00:00:00+00:00', '--job-id', '3512', '--raw', '--subdir', 'DAGS_FOLDER/main.py', '--cfg-path', '/tmp/tmpw14jhzjd']
[2023-12-07T17:29:16.796+0000] {standard_task_runner.py:85} INFO - Job 3512: Subtask main_task
[2023-12-07T17:29:16.885+0000] {task_command.py:416} INFO - Running <TaskInstance: my_scraping_dag.main_task scheduled__2023-10-26T00:00:00+00:00 [running]> on host 63b0c7e341c0
[2023-12-07T17:29:16.999+0000] {taskinstance.py:1662} INFO - Exporting env vars: AIRFLOW_CTX_DAG_OWNER='***' AIRFLOW_CTX_DAG_ID='my_scraping_dag' AIRFLOW_CTX_TASK_ID='main_task' AIRFLOW_CTX_EXECUTION_DATE='2023-10-26T00:00:00+00:00' AIRFLOW_CTX_TRY_NUMBER='1' AIRFLOW_CTX_DAG_RUN_ID='scheduled__2023-10-26T00:00:00+00:00'
[2023-12-07T17:29:17.959+0000] {taskinstance.py:1937} ERROR - Task failed with exception
Traceback (most recent call last):
  File "/home/airflow/.local/lib/python3.8/site-packages/airflow/operators/python.py", line 192, in execute
    return_value = self.execute_callable()
  File "/home/airflow/.local/lib/python3.8/site-packages/airflow/operators/python.py", line 209, in execute_callable
    return self.python_callable(*self.op_args, **self.op_kwargs)
  File "/opt/airflow/dags/main.py", line 73, in main
    insert_data_to_db(products, db_params)
  File "/opt/airflow/dags/main.py", line 40, in insert_data_to_db
    with psycopg2.connect(**db_params) as conn:
  File "/home/airflow/.local/lib/python3.8/site-packages/psycopg2/__init__.py", line 122, in connect
    conn = _connect(dsn, connection_factory=connection_factory, **kwasync)
psycopg2.OperationalError: connection to server at "localhost" (127.0.0.1), port 5432 failed: Connection refused
	Is the server running on that host and accepting TCP/IP connections?
connection to server at "localhost" (::1), port 5432 failed: Cannot assign requested address
	Is the server running on that host and accepting TCP/IP connections?

[2023-12-07T17:29:17.964+0000] {taskinstance.py:1400} INFO - Marking task as FAILED. dag_id=my_scraping_dag, task_id=main_task, execution_date=20231026T000000, start_date=20231207T172916, end_date=20231207T172917
[2023-12-07T17:29:17.969+0000] {standard_task_runner.py:104} ERROR - Failed to execute job 3512 for task main_task (connection to server at "localhost" (127.0.0.1), port 5432 failed: Connection refused
	Is the server running on that host and accepting TCP/IP connections?
connection to server at "localhost" (::1), port 5432 failed: Cannot assign requested address
	Is the server running on that host and accepting TCP/IP connections?
; 10794)
[2023-12-07T17:29:17.983+0000] {local_task_job_runner.py:228} INFO - Task exited with return code 1
[2023-12-07T17:29:17.991+0000] {taskinstance.py:2778} INFO - 0 downstream tasks scheduled from follow-on schedule check
[2023-12-09T07:35:34.348+0000] {taskinstance.py:1159} INFO - Dependencies all met for dep_context=non-requeueable deps ti=<TaskInstance: my_scraping_dag.main_task scheduled__2023-10-26T00:00:00+00:00 [queued]>
[2023-12-09T07:35:34.354+0000] {taskinstance.py:1159} INFO - Dependencies all met for dep_context=requeueable deps ti=<TaskInstance: my_scraping_dag.main_task scheduled__2023-10-26T00:00:00+00:00 [queued]>
[2023-12-09T07:35:34.355+0000] {taskinstance.py:1361} INFO - Starting attempt 1 of 1
[2023-12-09T07:35:34.364+0000] {taskinstance.py:1382} INFO - Executing <Task(PythonOperator): main_task> on 2023-10-26 00:00:00+00:00
[2023-12-09T07:35:34.367+0000] {standard_task_runner.py:57} INFO - Started process 1219 to run task
[2023-12-09T07:35:34.370+0000] {standard_task_runner.py:84} INFO - Running: ['***', 'tasks', 'run', 'my_scraping_dag', 'main_task', 'scheduled__2023-10-26T00:00:00+00:00', '--job-id', '302', '--raw', '--subdir', 'DAGS_FOLDER/main.py', '--cfg-path', '/tmp/tmpqgy4es8f']
[2023-12-09T07:35:34.372+0000] {standard_task_runner.py:85} INFO - Job 302: Subtask main_task
[2023-12-09T07:35:34.397+0000] {task_command.py:416} INFO - Running <TaskInstance: my_scraping_dag.main_task scheduled__2023-10-26T00:00:00+00:00 [running]> on host 36b5ef2505c9
[2023-12-09T07:35:34.444+0000] {taskinstance.py:1662} INFO - Exporting env vars: AIRFLOW_CTX_DAG_OWNER='***' AIRFLOW_CTX_DAG_ID='my_scraping_dag' AIRFLOW_CTX_TASK_ID='main_task' AIRFLOW_CTX_EXECUTION_DATE='2023-10-26T00:00:00+00:00' AIRFLOW_CTX_TRY_NUMBER='1' AIRFLOW_CTX_DAG_RUN_ID='scheduled__2023-10-26T00:00:00+00:00'
[2023-12-09T07:35:34.456+0000] {taskinstance.py:1937} ERROR - Task failed with exception
Traceback (most recent call last):
  File "/home/airflow/.local/lib/python3.8/site-packages/airflow/operators/python.py", line 192, in execute
    return_value = self.execute_callable()
  File "/home/airflow/.local/lib/python3.8/site-packages/airflow/operators/python.py", line 209, in execute_callable
    return self.python_callable(*self.op_args, **self.op_kwargs)
  File "/opt/airflow/dags/main.py", line 66, in main
    'User-Agent': Variable.get('user_agent'),
  File "/home/airflow/.local/lib/python3.8/site-packages/airflow/models/variable.py", line 140, in get
    raise KeyError(f"Variable {key} does not exist")
KeyError: 'Variable user_agent does not exist'
[2023-12-09T07:35:34.464+0000] {taskinstance.py:1400} INFO - Marking task as FAILED. dag_id=my_scraping_dag, task_id=main_task, execution_date=20231026T000000, start_date=20231209T073534, end_date=20231209T073534
[2023-12-09T07:35:34.473+0000] {standard_task_runner.py:104} ERROR - Failed to execute job 302 for task main_task ('Variable user_agent does not exist'; 1219)
[2023-12-09T07:35:34.503+0000] {local_task_job_runner.py:228} INFO - Task exited with return code 1
[2023-12-09T07:35:34.514+0000] {taskinstance.py:2778} INFO - 0 downstream tasks scheduled from follow-on schedule check
