[2023-12-07T14:46:10.299+0000] {taskinstance.py:1159} INFO - Dependencies all met for dep_context=non-requeueable deps ti=<TaskInstance: my_scraping_dag.main_task scheduled__2023-03-11T00:00:00+00:00 [queued]>
[2023-12-07T14:46:10.302+0000] {taskinstance.py:1159} INFO - Dependencies all met for dep_context=requeueable deps ti=<TaskInstance: my_scraping_dag.main_task scheduled__2023-03-11T00:00:00+00:00 [queued]>
[2023-12-07T14:46:10.303+0000] {taskinstance.py:1361} INFO - Starting attempt 1 of 1
[2023-12-07T14:46:10.309+0000] {taskinstance.py:1382} INFO - Executing <Task(PythonOperator): main_task> on 2023-03-11 00:00:00+00:00
[2023-12-07T14:46:10.311+0000] {standard_task_runner.py:57} INFO - Started process 543 to run task
[2023-12-07T14:46:10.313+0000] {standard_task_runner.py:84} INFO - Running: ['***', 'tasks', 'run', 'my_scraping_dag', 'main_task', 'scheduled__2023-03-11T00:00:00+00:00', '--job-id', '81', '--raw', '--subdir', 'DAGS_FOLDER/main.py', '--cfg-path', '/tmp/tmpc6nyi68o']
[2023-12-07T14:46:10.315+0000] {standard_task_runner.py:85} INFO - Job 81: Subtask main_task
[2023-12-07T14:46:10.336+0000] {task_command.py:416} INFO - Running <TaskInstance: my_scraping_dag.main_task scheduled__2023-03-11T00:00:00+00:00 [running]> on host 63b0c7e341c0
[2023-12-07T14:46:10.368+0000] {taskinstance.py:1662} INFO - Exporting env vars: AIRFLOW_CTX_DAG_OWNER='***' AIRFLOW_CTX_DAG_ID='my_scraping_dag' AIRFLOW_CTX_TASK_ID='main_task' AIRFLOW_CTX_EXECUTION_DATE='2023-03-11T00:00:00+00:00' AIRFLOW_CTX_TRY_NUMBER='1' AIRFLOW_CTX_DAG_RUN_ID='scheduled__2023-03-11T00:00:00+00:00'
[2023-12-07T14:46:10.369+0000] {taskinstance.py:1937} ERROR - Task failed with exception
Traceback (most recent call last):
  File "/usr/local/lib/python3.8/configparser.py", line 846, in items
    d.update(self._sections[section])
KeyError: 'web'

During handling of the above exception, another exception occurred:

Traceback (most recent call last):
  File "/home/airflow/.local/lib/python3.8/site-packages/airflow/operators/python.py", line 192, in execute
    return_value = self.execute_callable()
  File "/home/airflow/.local/lib/python3.8/site-packages/airflow/operators/python.py", line 209, in execute_callable
    return self.python_callable(*self.op_args, **self.op_kwargs)
  File "/opt/airflow/dags/main.py", line 61, in main
    config = get_config('web')
  File "/opt/airflow/dags/main.py", line 23, in get_config
    return {key: value for key, value in parser.items(section)}
  File "/usr/local/lib/python3.8/configparser.py", line 849, in items
    raise NoSectionError(section)
configparser.NoSectionError: No section: 'web'
[2023-12-07T14:46:10.373+0000] {taskinstance.py:1400} INFO - Marking task as FAILED. dag_id=my_scraping_dag, task_id=main_task, execution_date=20230311T000000, start_date=20231207T144610, end_date=20231207T144610
[2023-12-07T14:46:10.378+0000] {standard_task_runner.py:104} ERROR - Failed to execute job 81 for task main_task (No section: 'web'; 543)
[2023-12-07T14:46:10.405+0000] {local_task_job_runner.py:228} INFO - Task exited with return code 1
[2023-12-07T14:46:10.417+0000] {taskinstance.py:2778} INFO - 0 downstream tasks scheduled from follow-on schedule check
[2023-12-07T14:52:00.867+0000] {taskinstance.py:1159} INFO - Dependencies all met for dep_context=non-requeueable deps ti=<TaskInstance: my_scraping_dag.main_task scheduled__2023-03-11T00:00:00+00:00 [queued]>
[2023-12-07T14:52:00.872+0000] {taskinstance.py:1159} INFO - Dependencies all met for dep_context=requeueable deps ti=<TaskInstance: my_scraping_dag.main_task scheduled__2023-03-11T00:00:00+00:00 [queued]>
[2023-12-07T14:52:00.872+0000] {taskinstance.py:1361} INFO - Starting attempt 1 of 1
[2023-12-07T14:52:00.878+0000] {taskinstance.py:1382} INFO - Executing <Task(PythonOperator): main_task> on 2023-03-11 00:00:00+00:00
[2023-12-07T14:52:00.881+0000] {standard_task_runner.py:57} INFO - Started process 894 to run task
[2023-12-07T14:52:00.883+0000] {standard_task_runner.py:84} INFO - Running: ['***', 'tasks', 'run', 'my_scraping_dag', 'main_task', 'scheduled__2023-03-11T00:00:00+00:00', '--job-id', '180', '--raw', '--subdir', 'DAGS_FOLDER/main.py', '--cfg-path', '/tmp/tmpw_mar5bu']
[2023-12-07T14:52:00.885+0000] {standard_task_runner.py:85} INFO - Job 180: Subtask main_task
[2023-12-07T14:52:00.909+0000] {task_command.py:416} INFO - Running <TaskInstance: my_scraping_dag.main_task scheduled__2023-03-11T00:00:00+00:00 [running]> on host 63b0c7e341c0
[2023-12-07T14:52:00.948+0000] {taskinstance.py:1662} INFO - Exporting env vars: AIRFLOW_CTX_DAG_OWNER='***' AIRFLOW_CTX_DAG_ID='my_scraping_dag' AIRFLOW_CTX_TASK_ID='main_task' AIRFLOW_CTX_EXECUTION_DATE='2023-03-11T00:00:00+00:00' AIRFLOW_CTX_TRY_NUMBER='1' AIRFLOW_CTX_DAG_RUN_ID='scheduled__2023-03-11T00:00:00+00:00'
[2023-12-07T14:52:00.949+0000] {taskinstance.py:1937} ERROR - Task failed with exception
Traceback (most recent call last):
  File "/usr/local/lib/python3.8/configparser.py", line 846, in items
    d.update(self._sections[section])
KeyError: 'web'

During handling of the above exception, another exception occurred:

Traceback (most recent call last):
  File "/home/airflow/.local/lib/python3.8/site-packages/airflow/operators/python.py", line 192, in execute
    return_value = self.execute_callable()
  File "/home/airflow/.local/lib/python3.8/site-packages/airflow/operators/python.py", line 209, in execute_callable
    return self.python_callable(*self.op_args, **self.op_kwargs)
  File "/opt/airflow/dags/main.py", line 61, in main
    config = get_config('web')
  File "/opt/airflow/dags/main.py", line 23, in get_config
    return {key: value for key, value in parser.items(section)}
  File "/usr/local/lib/python3.8/configparser.py", line 849, in items
    raise NoSectionError(section)
configparser.NoSectionError: No section: 'web'
[2023-12-07T14:52:00.954+0000] {taskinstance.py:1400} INFO - Marking task as FAILED. dag_id=my_scraping_dag, task_id=main_task, execution_date=20230311T000000, start_date=20231207T145200, end_date=20231207T145200
[2023-12-07T14:52:00.959+0000] {standard_task_runner.py:104} ERROR - Failed to execute job 180 for task main_task (No section: 'web'; 894)
[2023-12-07T14:52:00.975+0000] {local_task_job_runner.py:228} INFO - Task exited with return code 1
[2023-12-07T14:52:00.989+0000] {taskinstance.py:2778} INFO - 0 downstream tasks scheduled from follow-on schedule check
[2023-12-07T15:00:11.965+0000] {taskinstance.py:1159} INFO - Dependencies all met for dep_context=non-requeueable deps ti=<TaskInstance: my_scraping_dag.main_task scheduled__2023-03-11T00:00:00+00:00 [queued]>
[2023-12-07T15:00:11.969+0000] {taskinstance.py:1159} INFO - Dependencies all met for dep_context=requeueable deps ti=<TaskInstance: my_scraping_dag.main_task scheduled__2023-03-11T00:00:00+00:00 [queued]>
[2023-12-07T15:00:11.969+0000] {taskinstance.py:1361} INFO - Starting attempt 1 of 1
[2023-12-07T15:00:11.992+0000] {taskinstance.py:1382} INFO - Executing <Task(PythonOperator): main_task> on 2023-03-11 00:00:00+00:00
[2023-12-07T15:00:11.994+0000] {standard_task_runner.py:57} INFO - Started process 1516 to run task
[2023-12-07T15:00:11.996+0000] {standard_task_runner.py:84} INFO - Running: ['***', 'tasks', 'run', 'my_scraping_dag', 'main_task', 'scheduled__2023-03-11T00:00:00+00:00', '--job-id', '385', '--raw', '--subdir', 'DAGS_FOLDER/main.py', '--cfg-path', '/tmp/tmp5wdo5_oq']
[2023-12-07T15:00:11.998+0000] {standard_task_runner.py:85} INFO - Job 385: Subtask main_task
[2023-12-07T15:00:12.029+0000] {task_command.py:416} INFO - Running <TaskInstance: my_scraping_dag.main_task scheduled__2023-03-11T00:00:00+00:00 [running]> on host 63b0c7e341c0
[2023-12-07T15:00:12.066+0000] {taskinstance.py:1662} INFO - Exporting env vars: AIRFLOW_CTX_DAG_OWNER='***' AIRFLOW_CTX_DAG_ID='my_scraping_dag' AIRFLOW_CTX_TASK_ID='main_task' AIRFLOW_CTX_EXECUTION_DATE='2023-03-11T00:00:00+00:00' AIRFLOW_CTX_TRY_NUMBER='1' AIRFLOW_CTX_DAG_RUN_ID='scheduled__2023-03-11T00:00:00+00:00'
[2023-12-07T15:00:12.067+0000] {taskinstance.py:1937} ERROR - Task failed with exception
Traceback (most recent call last):
  File "/usr/local/lib/python3.8/configparser.py", line 846, in items
    d.update(self._sections[section])
KeyError: 'web'

During handling of the above exception, another exception occurred:

Traceback (most recent call last):
  File "/home/airflow/.local/lib/python3.8/site-packages/airflow/operators/python.py", line 192, in execute
    return_value = self.execute_callable()
  File "/home/airflow/.local/lib/python3.8/site-packages/airflow/operators/python.py", line 209, in execute_callable
    return self.python_callable(*self.op_args, **self.op_kwargs)
  File "/opt/airflow/dags/main.py", line 60, in main
    config = get_config('web')
  File "/opt/airflow/dags/main.py", line 22, in get_config
    return {key: value for key, value in parser.items(section)}
  File "/usr/local/lib/python3.8/configparser.py", line 849, in items
    raise NoSectionError(section)
configparser.NoSectionError: No section: 'web'
[2023-12-07T15:00:12.072+0000] {taskinstance.py:1400} INFO - Marking task as FAILED. dag_id=my_scraping_dag, task_id=main_task, execution_date=20230311T000000, start_date=20231207T150011, end_date=20231207T150012
[2023-12-07T15:00:12.079+0000] {standard_task_runner.py:104} ERROR - Failed to execute job 385 for task main_task (No section: 'web'; 1516)
[2023-12-07T15:00:12.089+0000] {local_task_job_runner.py:228} INFO - Task exited with return code 1
[2023-12-07T15:00:12.122+0000] {taskinstance.py:2778} INFO - 0 downstream tasks scheduled from follow-on schedule check
[2023-12-07T15:10:57.709+0000] {taskinstance.py:1159} INFO - Dependencies all met for dep_context=non-requeueable deps ti=<TaskInstance: my_scraping_dag.main_task scheduled__2023-03-11T00:00:00+00:00 [queued]>
[2023-12-07T15:10:57.714+0000] {taskinstance.py:1159} INFO - Dependencies all met for dep_context=requeueable deps ti=<TaskInstance: my_scraping_dag.main_task scheduled__2023-03-11T00:00:00+00:00 [queued]>
[2023-12-07T15:10:57.715+0000] {taskinstance.py:1361} INFO - Starting attempt 1 of 1
[2023-12-07T15:10:57.723+0000] {taskinstance.py:1382} INFO - Executing <Task(PythonOperator): main_task> on 2023-03-11 00:00:00+00:00
[2023-12-07T15:10:57.727+0000] {standard_task_runner.py:57} INFO - Started process 1984 to run task
[2023-12-07T15:10:57.731+0000] {standard_task_runner.py:84} INFO - Running: ['***', 'tasks', 'run', 'my_scraping_dag', 'main_task', 'scheduled__2023-03-11T00:00:00+00:00', '--job-id', '491', '--raw', '--subdir', 'DAGS_FOLDER/main.py', '--cfg-path', '/tmp/tmpm92lckti']
[2023-12-07T15:10:57.734+0000] {standard_task_runner.py:85} INFO - Job 491: Subtask main_task
[2023-12-07T15:10:57.796+0000] {task_command.py:416} INFO - Running <TaskInstance: my_scraping_dag.main_task scheduled__2023-03-11T00:00:00+00:00 [running]> on host 63b0c7e341c0
[2023-12-07T15:10:57.849+0000] {taskinstance.py:1662} INFO - Exporting env vars: AIRFLOW_CTX_DAG_OWNER='***' AIRFLOW_CTX_DAG_ID='my_scraping_dag' AIRFLOW_CTX_TASK_ID='main_task' AIRFLOW_CTX_EXECUTION_DATE='2023-03-11T00:00:00+00:00' AIRFLOW_CTX_TRY_NUMBER='1' AIRFLOW_CTX_DAG_RUN_ID='scheduled__2023-03-11T00:00:00+00:00'
[2023-12-07T15:10:57.854+0000] {taskinstance.py:1937} ERROR - Task failed with exception
Traceback (most recent call last):
  File "/usr/local/lib/python3.8/configparser.py", line 846, in items
    d.update(self._sections[section])
KeyError: 'web'

During handling of the above exception, another exception occurred:

Traceback (most recent call last):
  File "/home/airflow/.local/lib/python3.8/site-packages/airflow/operators/python.py", line 192, in execute
    return_value = self.execute_callable()
  File "/home/airflow/.local/lib/python3.8/site-packages/airflow/operators/python.py", line 209, in execute_callable
    return self.python_callable(*self.op_args, **self.op_kwargs)
  File "/opt/airflow/dags/main.py", line 63, in main
    config = get_config('web')
  File "/opt/airflow/dags/main.py", line 14, in get_config
    return {key: value for key, value in parser.items(section)}
  File "/usr/local/lib/python3.8/configparser.py", line 849, in items
    raise NoSectionError(section)
configparser.NoSectionError: No section: 'web'
[2023-12-07T15:10:57.866+0000] {taskinstance.py:1400} INFO - Marking task as FAILED. dag_id=my_scraping_dag, task_id=main_task, execution_date=20230311T000000, start_date=20231207T151057, end_date=20231207T151057
[2023-12-07T15:10:57.871+0000] {standard_task_runner.py:104} ERROR - Failed to execute job 491 for task main_task (No section: 'web'; 1984)
[2023-12-07T15:10:57.906+0000] {local_task_job_runner.py:228} INFO - Task exited with return code 1
[2023-12-07T15:10:57.917+0000] {taskinstance.py:2778} INFO - 0 downstream tasks scheduled from follow-on schedule check
[2023-12-07T15:12:21.074+0000] {taskinstance.py:1159} INFO - Dependencies all met for dep_context=non-requeueable deps ti=<TaskInstance: my_scraping_dag.main_task scheduled__2023-03-11T00:00:00+00:00 [queued]>
[2023-12-07T15:12:21.078+0000] {taskinstance.py:1159} INFO - Dependencies all met for dep_context=requeueable deps ti=<TaskInstance: my_scraping_dag.main_task scheduled__2023-03-11T00:00:00+00:00 [queued]>
[2023-12-07T15:12:21.078+0000] {taskinstance.py:1361} INFO - Starting attempt 1 of 1
[2023-12-07T15:12:21.084+0000] {taskinstance.py:1382} INFO - Executing <Task(PythonOperator): main_task> on 2023-03-11 00:00:00+00:00
[2023-12-07T15:12:21.086+0000] {standard_task_runner.py:57} INFO - Started process 2206 to run task
[2023-12-07T15:12:21.088+0000] {standard_task_runner.py:84} INFO - Running: ['***', 'tasks', 'run', 'my_scraping_dag', 'main_task', 'scheduled__2023-03-11T00:00:00+00:00', '--job-id', '580', '--raw', '--subdir', 'DAGS_FOLDER/main.py', '--cfg-path', '/tmp/tmp2n4rr6zg']
[2023-12-07T15:12:21.089+0000] {standard_task_runner.py:85} INFO - Job 580: Subtask main_task
[2023-12-07T15:12:21.112+0000] {task_command.py:416} INFO - Running <TaskInstance: my_scraping_dag.main_task scheduled__2023-03-11T00:00:00+00:00 [running]> on host 63b0c7e341c0
[2023-12-07T15:12:21.141+0000] {taskinstance.py:1662} INFO - Exporting env vars: AIRFLOW_CTX_DAG_OWNER='***' AIRFLOW_CTX_DAG_ID='my_scraping_dag' AIRFLOW_CTX_TASK_ID='main_task' AIRFLOW_CTX_EXECUTION_DATE='2023-03-11T00:00:00+00:00' AIRFLOW_CTX_TRY_NUMBER='1' AIRFLOW_CTX_DAG_RUN_ID='scheduled__2023-03-11T00:00:00+00:00'
[2023-12-07T15:12:21.142+0000] {taskinstance.py:1937} ERROR - Task failed with exception
Traceback (most recent call last):
  File "/usr/local/lib/python3.8/configparser.py", line 846, in items
    d.update(self._sections[section])
KeyError: 'web'

During handling of the above exception, another exception occurred:

Traceback (most recent call last):
  File "/home/airflow/.local/lib/python3.8/site-packages/airflow/operators/python.py", line 192, in execute
    return_value = self.execute_callable()
  File "/home/airflow/.local/lib/python3.8/site-packages/airflow/operators/python.py", line 209, in execute_callable
    return self.python_callable(*self.op_args, **self.op_kwargs)
  File "/opt/airflow/dags/main.py", line 63, in main
    config = get_config('web')
  File "/opt/airflow/dags/main.py", line 14, in get_config
    return {key: value for key, value in parser.items(section)}
  File "/usr/local/lib/python3.8/configparser.py", line 849, in items
    raise NoSectionError(section)
configparser.NoSectionError: No section: 'web'
[2023-12-07T15:12:21.146+0000] {taskinstance.py:1400} INFO - Marking task as FAILED. dag_id=my_scraping_dag, task_id=main_task, execution_date=20230311T000000, start_date=20231207T151221, end_date=20231207T151221
[2023-12-07T15:12:21.150+0000] {standard_task_runner.py:104} ERROR - Failed to execute job 580 for task main_task (No section: 'web'; 2206)
[2023-12-07T15:12:21.180+0000] {local_task_job_runner.py:228} INFO - Task exited with return code 1
[2023-12-07T15:12:21.189+0000] {taskinstance.py:2778} INFO - 0 downstream tasks scheduled from follow-on schedule check
[2023-12-07T16:31:44.572+0000] {taskinstance.py:1159} INFO - Dependencies all met for dep_context=non-requeueable deps ti=<TaskInstance: my_scraping_dag.main_task scheduled__2023-03-11T00:00:00+00:00 [queued]>
[2023-12-07T16:31:44.576+0000] {taskinstance.py:1159} INFO - Dependencies all met for dep_context=requeueable deps ti=<TaskInstance: my_scraping_dag.main_task scheduled__2023-03-11T00:00:00+00:00 [queued]>
[2023-12-07T16:31:44.576+0000] {taskinstance.py:1361} INFO - Starting attempt 1 of 1
[2023-12-07T16:31:44.581+0000] {taskinstance.py:1382} INFO - Executing <Task(PythonOperator): main_task> on 2023-03-11 00:00:00+00:00
[2023-12-07T16:31:44.584+0000] {standard_task_runner.py:57} INFO - Started process 3657 to run task
[2023-12-07T16:31:44.586+0000] {standard_task_runner.py:84} INFO - Running: ['***', 'tasks', 'run', 'my_scraping_dag', 'main_task', 'scheduled__2023-03-11T00:00:00+00:00', '--job-id', '658', '--raw', '--subdir', 'DAGS_FOLDER/main.py', '--cfg-path', '/tmp/tmpq0uahdfd']
[2023-12-07T16:31:44.587+0000] {standard_task_runner.py:85} INFO - Job 658: Subtask main_task
[2023-12-07T16:31:44.608+0000] {task_command.py:416} INFO - Running <TaskInstance: my_scraping_dag.main_task scheduled__2023-03-11T00:00:00+00:00 [running]> on host 63b0c7e341c0
[2023-12-07T16:31:44.650+0000] {taskinstance.py:1662} INFO - Exporting env vars: AIRFLOW_CTX_DAG_OWNER='***' AIRFLOW_CTX_DAG_ID='my_scraping_dag' AIRFLOW_CTX_TASK_ID='main_task' AIRFLOW_CTX_EXECUTION_DATE='2023-03-11T00:00:00+00:00' AIRFLOW_CTX_TRY_NUMBER='1' AIRFLOW_CTX_DAG_RUN_ID='scheduled__2023-03-11T00:00:00+00:00'
[2023-12-07T16:31:44.651+0000] {taskinstance.py:1937} ERROR - Task failed with exception
Traceback (most recent call last):
  File "/usr/local/lib/python3.8/configparser.py", line 846, in items
    d.update(self._sections[section])
KeyError: 'web'

During handling of the above exception, another exception occurred:

Traceback (most recent call last):
  File "/home/airflow/.local/lib/python3.8/site-packages/airflow/operators/python.py", line 192, in execute
    return_value = self.execute_callable()
  File "/home/airflow/.local/lib/python3.8/site-packages/airflow/operators/python.py", line 209, in execute_callable
    return self.python_callable(*self.op_args, **self.op_kwargs)
  File "/opt/airflow/dags/main.py", line 60, in main
    config = get_config('web')
  File "/opt/airflow/dags/main.py", line 22, in get_config
    return {key: value for key, value in parser.items(section)}
  File "/usr/local/lib/python3.8/configparser.py", line 849, in items
    raise NoSectionError(section)
configparser.NoSectionError: No section: 'web'
[2023-12-07T16:31:44.656+0000] {taskinstance.py:1400} INFO - Marking task as FAILED. dag_id=my_scraping_dag, task_id=main_task, execution_date=20230311T000000, start_date=20231207T163144, end_date=20231207T163144
[2023-12-07T16:31:44.661+0000] {standard_task_runner.py:104} ERROR - Failed to execute job 658 for task main_task (No section: 'web'; 3657)
[2023-12-07T16:31:44.678+0000] {local_task_job_runner.py:228} INFO - Task exited with return code 1
[2023-12-07T16:31:44.690+0000] {taskinstance.py:2778} INFO - 0 downstream tasks scheduled from follow-on schedule check
[2023-12-07T16:41:13.060+0000] {taskinstance.py:1159} INFO - Dependencies all met for dep_context=non-requeueable deps ti=<TaskInstance: my_scraping_dag.main_task scheduled__2023-03-11T00:00:00+00:00 [queued]>
[2023-12-07T16:41:13.064+0000] {taskinstance.py:1159} INFO - Dependencies all met for dep_context=requeueable deps ti=<TaskInstance: my_scraping_dag.main_task scheduled__2023-03-11T00:00:00+00:00 [queued]>
[2023-12-07T16:41:13.065+0000] {taskinstance.py:1361} INFO - Starting attempt 1 of 1
[2023-12-07T16:41:13.071+0000] {taskinstance.py:1382} INFO - Executing <Task(PythonOperator): main_task> on 2023-03-11 00:00:00+00:00
[2023-12-07T16:41:13.073+0000] {standard_task_runner.py:57} INFO - Started process 4573 to run task
[2023-12-07T16:41:13.075+0000] {standard_task_runner.py:84} INFO - Running: ['***', 'tasks', 'run', 'my_scraping_dag', 'main_task', 'scheduled__2023-03-11T00:00:00+00:00', '--job-id', '1000', '--raw', '--subdir', 'DAGS_FOLDER/main.py', '--cfg-path', '/tmp/tmpvj_bjgdd']
[2023-12-07T16:41:13.077+0000] {standard_task_runner.py:85} INFO - Job 1000: Subtask main_task
[2023-12-07T16:41:13.101+0000] {task_command.py:416} INFO - Running <TaskInstance: my_scraping_dag.main_task scheduled__2023-03-11T00:00:00+00:00 [running]> on host 63b0c7e341c0
[2023-12-07T16:41:13.139+0000] {taskinstance.py:1662} INFO - Exporting env vars: AIRFLOW_CTX_DAG_OWNER='***' AIRFLOW_CTX_DAG_ID='my_scraping_dag' AIRFLOW_CTX_TASK_ID='main_task' AIRFLOW_CTX_EXECUTION_DATE='2023-03-11T00:00:00+00:00' AIRFLOW_CTX_TRY_NUMBER='1' AIRFLOW_CTX_DAG_RUN_ID='scheduled__2023-03-11T00:00:00+00:00'
[2023-12-07T16:41:13.140+0000] {taskinstance.py:1937} ERROR - Task failed with exception
Traceback (most recent call last):
  File "/usr/local/lib/python3.8/configparser.py", line 846, in items
    d.update(self._sections[section])
KeyError: 'web'

During handling of the above exception, another exception occurred:

Traceback (most recent call last):
  File "/home/airflow/.local/lib/python3.8/site-packages/airflow/operators/python.py", line 192, in execute
    return_value = self.execute_callable()
  File "/home/airflow/.local/lib/python3.8/site-packages/airflow/operators/python.py", line 209, in execute_callable
    return self.python_callable(*self.op_args, **self.op_kwargs)
  File "/opt/airflow/dags/main.py", line 60, in main
    config = get_config('web')
  File "/opt/airflow/dags/main.py", line 22, in get_config
    return {key: value for key, value in parser.items(section)}
  File "/usr/local/lib/python3.8/configparser.py", line 849, in items
    raise NoSectionError(section)
configparser.NoSectionError: No section: 'web'
[2023-12-07T16:41:13.145+0000] {taskinstance.py:1400} INFO - Marking task as FAILED. dag_id=my_scraping_dag, task_id=main_task, execution_date=20230311T000000, start_date=20231207T164113, end_date=20231207T164113
[2023-12-07T16:41:13.179+0000] {standard_task_runner.py:104} ERROR - Failed to execute job 1000 for task main_task (No section: 'web'; 4573)
[2023-12-07T16:41:13.208+0000] {local_task_job_runner.py:228} INFO - Task exited with return code 1
[2023-12-07T16:41:13.236+0000] {taskinstance.py:2778} INFO - 0 downstream tasks scheduled from follow-on schedule check
[2023-12-07T17:00:18.028+0000] {taskinstance.py:1159} INFO - Dependencies all met for dep_context=non-requeueable deps ti=<TaskInstance: my_scraping_dag.main_task scheduled__2023-03-11T00:00:00+00:00 [queued]>
[2023-12-07T17:00:18.033+0000] {taskinstance.py:1159} INFO - Dependencies all met for dep_context=requeueable deps ti=<TaskInstance: my_scraping_dag.main_task scheduled__2023-03-11T00:00:00+00:00 [queued]>
[2023-12-07T17:00:18.033+0000] {taskinstance.py:1361} INFO - Starting attempt 1 of 1
[2023-12-07T17:00:18.050+0000] {taskinstance.py:1382} INFO - Executing <Task(PythonOperator): main_task> on 2023-03-11 00:00:00+00:00
[2023-12-07T17:00:18.053+0000] {standard_task_runner.py:57} INFO - Started process 5730 to run task
[2023-12-07T17:00:18.055+0000] {standard_task_runner.py:84} INFO - Running: ['***', 'tasks', 'run', 'my_scraping_dag', 'main_task', 'scheduled__2023-03-11T00:00:00+00:00', '--job-id', '1344', '--raw', '--subdir', 'DAGS_FOLDER/main.py', '--cfg-path', '/tmp/tmprb8u5rhg']
[2023-12-07T17:00:18.057+0000] {standard_task_runner.py:85} INFO - Job 1344: Subtask main_task
[2023-12-07T17:00:18.088+0000] {task_command.py:416} INFO - Running <TaskInstance: my_scraping_dag.main_task scheduled__2023-03-11T00:00:00+00:00 [running]> on host 63b0c7e341c0
[2023-12-07T17:00:18.129+0000] {taskinstance.py:1662} INFO - Exporting env vars: AIRFLOW_CTX_DAG_OWNER='***' AIRFLOW_CTX_DAG_ID='my_scraping_dag' AIRFLOW_CTX_TASK_ID='main_task' AIRFLOW_CTX_EXECUTION_DATE='2023-03-11T00:00:00+00:00' AIRFLOW_CTX_TRY_NUMBER='1' AIRFLOW_CTX_DAG_RUN_ID='scheduled__2023-03-11T00:00:00+00:00'
[2023-12-07T17:00:18.151+0000] {taskinstance.py:1937} ERROR - Task failed with exception
Traceback (most recent call last):
  File "/home/airflow/.local/lib/python3.8/site-packages/airflow/operators/python.py", line 192, in execute
    return_value = self.execute_callable()
  File "/home/airflow/.local/lib/python3.8/site-packages/airflow/operators/python.py", line 209, in execute_callable
    return self.python_callable(*self.op_args, **self.op_kwargs)
  File "/opt/airflow/dags/main.py", line 33, in main
    'host': get_config('localhost'),
  File "/opt/airflow/dags/main.py", line 20, in get_config
    return Variable.get(key)
  File "/home/airflow/.local/lib/python3.8/site-packages/airflow/models/variable.py", line 140, in get
    raise KeyError(f"Variable {key} does not exist")
KeyError: 'Variable localhost does not exist'
[2023-12-07T17:00:18.155+0000] {taskinstance.py:1400} INFO - Marking task as FAILED. dag_id=my_scraping_dag, task_id=main_task, execution_date=20230311T000000, start_date=20231207T170018, end_date=20231207T170018
[2023-12-07T17:00:18.167+0000] {standard_task_runner.py:104} ERROR - Failed to execute job 1344 for task main_task ('Variable localhost does not exist'; 5730)
[2023-12-07T17:00:18.188+0000] {local_task_job_runner.py:228} INFO - Task exited with return code 1
[2023-12-07T17:00:18.203+0000] {taskinstance.py:2778} INFO - 0 downstream tasks scheduled from follow-on schedule check
[2023-12-07T17:03:36.815+0000] {taskinstance.py:1159} INFO - Dependencies all met for dep_context=non-requeueable deps ti=<TaskInstance: my_scraping_dag.main_task scheduled__2023-03-11T00:00:00+00:00 [queued]>
[2023-12-07T17:03:36.819+0000] {taskinstance.py:1159} INFO - Dependencies all met for dep_context=requeueable deps ti=<TaskInstance: my_scraping_dag.main_task scheduled__2023-03-11T00:00:00+00:00 [queued]>
[2023-12-07T17:03:36.819+0000] {taskinstance.py:1361} INFO - Starting attempt 1 of 1
[2023-12-07T17:03:36.838+0000] {taskinstance.py:1382} INFO - Executing <Task(PythonOperator): main_task> on 2023-03-11 00:00:00+00:00
[2023-12-07T17:03:36.842+0000] {standard_task_runner.py:57} INFO - Started process 7075 to run task
[2023-12-07T17:03:36.844+0000] {standard_task_runner.py:84} INFO - Running: ['***', 'tasks', 'run', 'my_scraping_dag', 'main_task', 'scheduled__2023-03-11T00:00:00+00:00', '--job-id', '1975', '--raw', '--subdir', 'DAGS_FOLDER/main.py', '--cfg-path', '/tmp/tmphd20hjm5']
[2023-12-07T17:03:36.846+0000] {standard_task_runner.py:85} INFO - Job 1975: Subtask main_task
[2023-12-07T17:03:36.888+0000] {task_command.py:416} INFO - Running <TaskInstance: my_scraping_dag.main_task scheduled__2023-03-11T00:00:00+00:00 [running]> on host 63b0c7e341c0
[2023-12-07T17:03:36.943+0000] {taskinstance.py:1662} INFO - Exporting env vars: AIRFLOW_CTX_DAG_OWNER='***' AIRFLOW_CTX_DAG_ID='my_scraping_dag' AIRFLOW_CTX_TASK_ID='main_task' AIRFLOW_CTX_EXECUTION_DATE='2023-03-11T00:00:00+00:00' AIRFLOW_CTX_TRY_NUMBER='1' AIRFLOW_CTX_DAG_RUN_ID='scheduled__2023-03-11T00:00:00+00:00'
[2023-12-07T17:03:36.976+0000] {logging_mixin.py:154} INFO - base_url: https://tuncbotanik.com
[2023-12-07T17:03:36.976+0000] {python.py:194} INFO - Done. Returned value was: ('https://tuncbotanik.com', {'User-Agent': 'Mozilla/5.0 (Macintosh; Intel Mac OS X 10_15_7) AppleWebKit/537.36 (KHTML, like Gecko) Chrome/119.0.0.0 Safari/537.36', 'Accept-Language': 'tr-TR,tr;q=0.9,en-US;q=0.8,en;q=0.7'}, {'dbname': 'plant', 'user': 'aozgokme', 'password': '***', 'host': 'localhost', 'port': '5432'})
[2023-12-07T17:03:36.991+0000] {taskinstance.py:1400} INFO - Marking task as SUCCESS. dag_id=my_scraping_dag, task_id=main_task, execution_date=20230311T000000, start_date=20231207T170336, end_date=20231207T170336
[2023-12-07T17:03:37.018+0000] {local_task_job_runner.py:228} INFO - Task exited with return code 0
[2023-12-07T17:03:37.036+0000] {taskinstance.py:2778} INFO - 1 downstream tasks scheduled from follow-on schedule check
[2023-12-07T17:18:32.550+0000] {taskinstance.py:1159} INFO - Dependencies all met for dep_context=non-requeueable deps ti=<TaskInstance: my_scraping_dag.main_task scheduled__2023-03-11T00:00:00+00:00 [queued]>
[2023-12-07T17:18:32.556+0000] {taskinstance.py:1159} INFO - Dependencies all met for dep_context=requeueable deps ti=<TaskInstance: my_scraping_dag.main_task scheduled__2023-03-11T00:00:00+00:00 [queued]>
[2023-12-07T17:18:32.557+0000] {taskinstance.py:1361} INFO - Starting attempt 1 of 1
[2023-12-07T17:18:32.581+0000] {taskinstance.py:1382} INFO - Executing <Task(PythonOperator): main_task> on 2023-03-11 00:00:00+00:00
[2023-12-07T17:18:32.583+0000] {standard_task_runner.py:57} INFO - Started process 8682 to run task
[2023-12-07T17:18:32.586+0000] {standard_task_runner.py:84} INFO - Running: ['***', 'tasks', 'run', 'my_scraping_dag', 'main_task', 'scheduled__2023-03-11T00:00:00+00:00', '--job-id', '2599', '--raw', '--subdir', 'DAGS_FOLDER/main.py', '--cfg-path', '/tmp/tmp2hzlh3m8']
[2023-12-07T17:18:32.588+0000] {standard_task_runner.py:85} INFO - Job 2599: Subtask main_task
[2023-12-07T17:18:32.618+0000] {task_command.py:416} INFO - Running <TaskInstance: my_scraping_dag.main_task scheduled__2023-03-11T00:00:00+00:00 [running]> on host 63b0c7e341c0
[2023-12-07T17:18:32.660+0000] {taskinstance.py:1662} INFO - Exporting env vars: AIRFLOW_CTX_DAG_OWNER='***' AIRFLOW_CTX_DAG_ID='my_scraping_dag' AIRFLOW_CTX_TASK_ID='main_task' AIRFLOW_CTX_EXECUTION_DATE='2023-03-11T00:00:00+00:00' AIRFLOW_CTX_TRY_NUMBER='1' AIRFLOW_CTX_DAG_RUN_ID='scheduled__2023-03-11T00:00:00+00:00'
[2023-12-07T17:18:33.429+0000] {taskinstance.py:1937} ERROR - Task failed with exception
Traceback (most recent call last):
  File "/home/airflow/.local/lib/python3.8/site-packages/airflow/operators/python.py", line 192, in execute
    return_value = self.execute_callable()
  File "/home/airflow/.local/lib/python3.8/site-packages/airflow/operators/python.py", line 209, in execute_callable
    return self.python_callable(*self.op_args, **self.op_kwargs)
  File "/opt/airflow/dags/main.py", line 80, in main
    insert_data_to_db(products, db_params)
  File "/opt/airflow/dags/main.py", line 43, in insert_data_to_db
    with psycopg2.connect(**db_params) as conn:
  File "/home/airflow/.local/lib/python3.8/site-packages/psycopg2/__init__.py", line 122, in connect
    conn = _connect(dsn, connection_factory=connection_factory, **kwasync)
psycopg2.OperationalError: connection to server at "localhost" (127.0.0.1), port 5432 failed: Connection refused
	Is the server running on that host and accepting TCP/IP connections?
connection to server at "localhost" (::1), port 5432 failed: Cannot assign requested address
	Is the server running on that host and accepting TCP/IP connections?

[2023-12-07T17:18:33.443+0000] {taskinstance.py:1400} INFO - Marking task as FAILED. dag_id=my_scraping_dag, task_id=main_task, execution_date=20230311T000000, start_date=20231207T171832, end_date=20231207T171833
[2023-12-07T17:18:33.453+0000] {standard_task_runner.py:104} ERROR - Failed to execute job 2599 for task main_task (connection to server at "localhost" (127.0.0.1), port 5432 failed: Connection refused
	Is the server running on that host and accepting TCP/IP connections?
connection to server at "localhost" (::1), port 5432 failed: Cannot assign requested address
	Is the server running on that host and accepting TCP/IP connections?
; 8682)
[2023-12-07T17:18:33.484+0000] {local_task_job_runner.py:228} INFO - Task exited with return code 1
[2023-12-07T17:18:33.505+0000] {taskinstance.py:2778} INFO - 0 downstream tasks scheduled from follow-on schedule check
[2023-12-07T17:22:50.235+0000] {taskinstance.py:1159} INFO - Dependencies all met for dep_context=non-requeueable deps ti=<TaskInstance: my_scraping_dag.main_task scheduled__2023-03-11T00:00:00+00:00 [queued]>
[2023-12-07T17:22:50.240+0000] {taskinstance.py:1159} INFO - Dependencies all met for dep_context=requeueable deps ti=<TaskInstance: my_scraping_dag.main_task scheduled__2023-03-11T00:00:00+00:00 [queued]>
[2023-12-07T17:22:50.240+0000] {taskinstance.py:1361} INFO - Starting attempt 1 of 1
[2023-12-07T17:22:50.256+0000] {taskinstance.py:1382} INFO - Executing <Task(PythonOperator): main_task> on 2023-03-11 00:00:00+00:00
[2023-12-07T17:22:50.258+0000] {standard_task_runner.py:57} INFO - Started process 9476 to run task
[2023-12-07T17:22:50.261+0000] {standard_task_runner.py:84} INFO - Running: ['***', 'tasks', 'run', 'my_scraping_dag', 'main_task', 'scheduled__2023-03-11T00:00:00+00:00', '--job-id', '2941', '--raw', '--subdir', 'DAGS_FOLDER/main.py', '--cfg-path', '/tmp/tmpy5fkpqsz']
[2023-12-07T17:22:50.263+0000] {standard_task_runner.py:85} INFO - Job 2941: Subtask main_task
[2023-12-07T17:22:50.290+0000] {task_command.py:416} INFO - Running <TaskInstance: my_scraping_dag.main_task scheduled__2023-03-11T00:00:00+00:00 [running]> on host 63b0c7e341c0
[2023-12-07T17:22:50.328+0000] {taskinstance.py:1662} INFO - Exporting env vars: AIRFLOW_CTX_DAG_OWNER='***' AIRFLOW_CTX_DAG_ID='my_scraping_dag' AIRFLOW_CTX_TASK_ID='main_task' AIRFLOW_CTX_EXECUTION_DATE='2023-03-11T00:00:00+00:00' AIRFLOW_CTX_TRY_NUMBER='1' AIRFLOW_CTX_DAG_RUN_ID='scheduled__2023-03-11T00:00:00+00:00'
[2023-12-07T17:22:51.101+0000] {taskinstance.py:1937} ERROR - Task failed with exception
Traceback (most recent call last):
  File "/home/airflow/.local/lib/python3.8/site-packages/airflow/operators/python.py", line 192, in execute
    return_value = self.execute_callable()
  File "/home/airflow/.local/lib/python3.8/site-packages/airflow/operators/python.py", line 209, in execute_callable
    return self.python_callable(*self.op_args, **self.op_kwargs)
  File "/opt/airflow/dags/main.py", line 73, in main
    insert_data_to_db(products, db_params)
  File "/opt/airflow/dags/main.py", line 40, in insert_data_to_db
    with psycopg2.connect(**db_params) as conn:
  File "/home/airflow/.local/lib/python3.8/site-packages/psycopg2/__init__.py", line 122, in connect
    conn = _connect(dsn, connection_factory=connection_factory, **kwasync)
psycopg2.OperationalError: connection to server at "localhost" (127.0.0.1), port 5432 failed: Connection refused
	Is the server running on that host and accepting TCP/IP connections?
connection to server at "localhost" (::1), port 5432 failed: Cannot assign requested address
	Is the server running on that host and accepting TCP/IP connections?

[2023-12-07T17:22:51.106+0000] {taskinstance.py:1400} INFO - Marking task as FAILED. dag_id=my_scraping_dag, task_id=main_task, execution_date=20230311T000000, start_date=20231207T172250, end_date=20231207T172251
[2023-12-07T17:22:51.110+0000] {standard_task_runner.py:104} ERROR - Failed to execute job 2941 for task main_task (connection to server at "localhost" (127.0.0.1), port 5432 failed: Connection refused
	Is the server running on that host and accepting TCP/IP connections?
connection to server at "localhost" (::1), port 5432 failed: Cannot assign requested address
	Is the server running on that host and accepting TCP/IP connections?
; 9476)
[2023-12-07T17:22:51.119+0000] {local_task_job_runner.py:228} INFO - Task exited with return code 1
[2023-12-07T17:22:51.128+0000] {taskinstance.py:2778} INFO - 0 downstream tasks scheduled from follow-on schedule check
[2023-12-07T17:28:32.069+0000] {taskinstance.py:1159} INFO - Dependencies all met for dep_context=non-requeueable deps ti=<TaskInstance: my_scraping_dag.main_task scheduled__2023-03-11T00:00:00+00:00 [queued]>
[2023-12-07T17:28:32.076+0000] {taskinstance.py:1159} INFO - Dependencies all met for dep_context=requeueable deps ti=<TaskInstance: my_scraping_dag.main_task scheduled__2023-03-11T00:00:00+00:00 [queued]>
[2023-12-07T17:28:32.077+0000] {taskinstance.py:1361} INFO - Starting attempt 1 of 1
[2023-12-07T17:28:32.121+0000] {taskinstance.py:1382} INFO - Executing <Task(PythonOperator): main_task> on 2023-03-11 00:00:00+00:00
[2023-12-07T17:28:32.125+0000] {standard_task_runner.py:57} INFO - Started process 10319 to run task
[2023-12-07T17:28:32.128+0000] {standard_task_runner.py:84} INFO - Running: ['***', 'tasks', 'run', 'my_scraping_dag', 'main_task', 'scheduled__2023-03-11T00:00:00+00:00', '--job-id', '3283', '--raw', '--subdir', 'DAGS_FOLDER/main.py', '--cfg-path', '/tmp/tmprgt1qi6k']
[2023-12-07T17:28:32.131+0000] {standard_task_runner.py:85} INFO - Job 3283: Subtask main_task
[2023-12-07T17:28:32.167+0000] {task_command.py:416} INFO - Running <TaskInstance: my_scraping_dag.main_task scheduled__2023-03-11T00:00:00+00:00 [running]> on host 63b0c7e341c0
[2023-12-07T17:28:32.258+0000] {taskinstance.py:1662} INFO - Exporting env vars: AIRFLOW_CTX_DAG_OWNER='***' AIRFLOW_CTX_DAG_ID='my_scraping_dag' AIRFLOW_CTX_TASK_ID='main_task' AIRFLOW_CTX_EXECUTION_DATE='2023-03-11T00:00:00+00:00' AIRFLOW_CTX_TRY_NUMBER='1' AIRFLOW_CTX_DAG_RUN_ID='scheduled__2023-03-11T00:00:00+00:00'
[2023-12-07T17:28:32.986+0000] {taskinstance.py:1937} ERROR - Task failed with exception
Traceback (most recent call last):
  File "/home/airflow/.local/lib/python3.8/site-packages/airflow/operators/python.py", line 192, in execute
    return_value = self.execute_callable()
  File "/home/airflow/.local/lib/python3.8/site-packages/airflow/operators/python.py", line 209, in execute_callable
    return self.python_callable(*self.op_args, **self.op_kwargs)
  File "/opt/airflow/dags/main.py", line 73, in main
    insert_data_to_db(products, db_params)
  File "/opt/airflow/dags/main.py", line 40, in insert_data_to_db
    with psycopg2.connect(**db_params) as conn:
  File "/home/airflow/.local/lib/python3.8/site-packages/psycopg2/__init__.py", line 122, in connect
    conn = _connect(dsn, connection_factory=connection_factory, **kwasync)
psycopg2.OperationalError: connection to server at "localhost" (127.0.0.1), port 5432 failed: Connection refused
	Is the server running on that host and accepting TCP/IP connections?
connection to server at "localhost" (::1), port 5432 failed: Cannot assign requested address
	Is the server running on that host and accepting TCP/IP connections?

[2023-12-07T17:28:32.990+0000] {taskinstance.py:1400} INFO - Marking task as FAILED. dag_id=my_scraping_dag, task_id=main_task, execution_date=20230311T000000, start_date=20231207T172832, end_date=20231207T172832
[2023-12-07T17:28:32.996+0000] {standard_task_runner.py:104} ERROR - Failed to execute job 3283 for task main_task (connection to server at "localhost" (127.0.0.1), port 5432 failed: Connection refused
	Is the server running on that host and accepting TCP/IP connections?
connection to server at "localhost" (::1), port 5432 failed: Cannot assign requested address
	Is the server running on that host and accepting TCP/IP connections?
; 10319)
[2023-12-07T17:28:33.029+0000] {local_task_job_runner.py:228} INFO - Task exited with return code 1
[2023-12-07T17:28:33.039+0000] {taskinstance.py:2778} INFO - 0 downstream tasks scheduled from follow-on schedule check
