[2023-12-07T16:33:47.442+0000] {taskinstance.py:1159} INFO - Dependencies all met for dep_context=non-requeueable deps ti=<TaskInstance: my_scraping_dag.main_task scheduled__2023-09-05T00:00:00+00:00 [queued]>
[2023-12-07T16:33:47.447+0000] {taskinstance.py:1159} INFO - Dependencies all met for dep_context=requeueable deps ti=<TaskInstance: my_scraping_dag.main_task scheduled__2023-09-05T00:00:00+00:00 [queued]>
[2023-12-07T16:33:47.447+0000] {taskinstance.py:1361} INFO - Starting attempt 1 of 1
[2023-12-07T16:33:47.454+0000] {taskinstance.py:1382} INFO - Executing <Task(PythonOperator): main_task> on 2023-09-05 00:00:00+00:00
[2023-12-07T16:33:47.456+0000] {standard_task_runner.py:57} INFO - Started process 4071 to run task
[2023-12-07T16:33:47.458+0000] {standard_task_runner.py:84} INFO - Running: ['***', 'tasks', 'run', 'my_scraping_dag', 'main_task', 'scheduled__2023-09-05T00:00:00+00:00', '--job-id', '836', '--raw', '--subdir', 'DAGS_FOLDER/main.py', '--cfg-path', '/tmp/tmpxj0zmh6a']
[2023-12-07T16:33:47.460+0000] {standard_task_runner.py:85} INFO - Job 836: Subtask main_task
[2023-12-07T16:33:47.484+0000] {task_command.py:416} INFO - Running <TaskInstance: my_scraping_dag.main_task scheduled__2023-09-05T00:00:00+00:00 [running]> on host 63b0c7e341c0
[2023-12-07T16:33:47.516+0000] {taskinstance.py:1662} INFO - Exporting env vars: AIRFLOW_CTX_DAG_OWNER='***' AIRFLOW_CTX_DAG_ID='my_scraping_dag' AIRFLOW_CTX_TASK_ID='main_task' AIRFLOW_CTX_EXECUTION_DATE='2023-09-05T00:00:00+00:00' AIRFLOW_CTX_TRY_NUMBER='1' AIRFLOW_CTX_DAG_RUN_ID='scheduled__2023-09-05T00:00:00+00:00'
[2023-12-07T16:33:47.517+0000] {taskinstance.py:1937} ERROR - Task failed with exception
Traceback (most recent call last):
  File "/usr/local/lib/python3.8/configparser.py", line 846, in items
    d.update(self._sections[section])
KeyError: 'web'

During handling of the above exception, another exception occurred:

Traceback (most recent call last):
  File "/home/airflow/.local/lib/python3.8/site-packages/airflow/operators/python.py", line 192, in execute
    return_value = self.execute_callable()
  File "/home/airflow/.local/lib/python3.8/site-packages/airflow/operators/python.py", line 209, in execute_callable
    return self.python_callable(*self.op_args, **self.op_kwargs)
  File "/opt/airflow/dags/main.py", line 60, in main
    config = get_config('web')
  File "/opt/airflow/dags/main.py", line 22, in get_config
    return {key: value for key, value in parser.items(section)}
  File "/usr/local/lib/python3.8/configparser.py", line 849, in items
    raise NoSectionError(section)
configparser.NoSectionError: No section: 'web'
[2023-12-07T16:33:47.522+0000] {taskinstance.py:1400} INFO - Marking task as FAILED. dag_id=my_scraping_dag, task_id=main_task, execution_date=20230905T000000, start_date=20231207T163347, end_date=20231207T163347
[2023-12-07T16:33:47.526+0000] {standard_task_runner.py:104} ERROR - Failed to execute job 836 for task main_task (No section: 'web'; 4071)
[2023-12-07T16:33:47.551+0000] {local_task_job_runner.py:228} INFO - Task exited with return code 1
[2023-12-07T16:33:47.563+0000] {taskinstance.py:2778} INFO - 0 downstream tasks scheduled from follow-on schedule check
[2023-12-07T16:42:31.503+0000] {taskinstance.py:1159} INFO - Dependencies all met for dep_context=non-requeueable deps ti=<TaskInstance: my_scraping_dag.main_task scheduled__2023-09-05T00:00:00+00:00 [queued]>
[2023-12-07T16:42:31.508+0000] {taskinstance.py:1159} INFO - Dependencies all met for dep_context=requeueable deps ti=<TaskInstance: my_scraping_dag.main_task scheduled__2023-09-05T00:00:00+00:00 [queued]>
[2023-12-07T16:42:31.509+0000] {taskinstance.py:1361} INFO - Starting attempt 1 of 1
[2023-12-07T16:42:31.515+0000] {taskinstance.py:1382} INFO - Executing <Task(PythonOperator): main_task> on 2023-09-05 00:00:00+00:00
[2023-12-07T16:42:31.518+0000] {standard_task_runner.py:57} INFO - Started process 4965 to run task
[2023-12-07T16:42:31.520+0000] {standard_task_runner.py:84} INFO - Running: ['***', 'tasks', 'run', 'my_scraping_dag', 'main_task', 'scheduled__2023-09-05T00:00:00+00:00', '--job-id', '1181', '--raw', '--subdir', 'DAGS_FOLDER/main.py', '--cfg-path', '/tmp/tmplzuj98yg']
[2023-12-07T16:42:31.522+0000] {standard_task_runner.py:85} INFO - Job 1181: Subtask main_task
[2023-12-07T16:42:31.547+0000] {task_command.py:416} INFO - Running <TaskInstance: my_scraping_dag.main_task scheduled__2023-09-05T00:00:00+00:00 [running]> on host 63b0c7e341c0
[2023-12-07T16:42:31.584+0000] {taskinstance.py:1662} INFO - Exporting env vars: AIRFLOW_CTX_DAG_OWNER='***' AIRFLOW_CTX_DAG_ID='my_scraping_dag' AIRFLOW_CTX_TASK_ID='main_task' AIRFLOW_CTX_EXECUTION_DATE='2023-09-05T00:00:00+00:00' AIRFLOW_CTX_TRY_NUMBER='1' AIRFLOW_CTX_DAG_RUN_ID='scheduled__2023-09-05T00:00:00+00:00'
[2023-12-07T16:42:31.585+0000] {taskinstance.py:1937} ERROR - Task failed with exception
Traceback (most recent call last):
  File "/usr/local/lib/python3.8/configparser.py", line 846, in items
    d.update(self._sections[section])
KeyError: 'web'

During handling of the above exception, another exception occurred:

Traceback (most recent call last):
  File "/home/airflow/.local/lib/python3.8/site-packages/airflow/operators/python.py", line 192, in execute
    return_value = self.execute_callable()
  File "/home/airflow/.local/lib/python3.8/site-packages/airflow/operators/python.py", line 209, in execute_callable
    return self.python_callable(*self.op_args, **self.op_kwargs)
  File "/opt/airflow/dags/main.py", line 60, in main
    config = get_config('web')
  File "/opt/airflow/dags/main.py", line 22, in get_config
    return {key: value for key, value in parser.items(section)}
  File "/usr/local/lib/python3.8/configparser.py", line 849, in items
    raise NoSectionError(section)
configparser.NoSectionError: No section: 'web'
[2023-12-07T16:42:31.590+0000] {taskinstance.py:1400} INFO - Marking task as FAILED. dag_id=my_scraping_dag, task_id=main_task, execution_date=20230905T000000, start_date=20231207T164231, end_date=20231207T164231
[2023-12-07T16:42:31.595+0000] {standard_task_runner.py:104} ERROR - Failed to execute job 1181 for task main_task (No section: 'web'; 4965)
[2023-12-07T16:42:31.613+0000] {local_task_job_runner.py:228} INFO - Task exited with return code 1
[2023-12-07T16:42:31.626+0000] {taskinstance.py:2778} INFO - 0 downstream tasks scheduled from follow-on schedule check
[2023-12-07T17:01:21.476+0000] {taskinstance.py:1159} INFO - Dependencies all met for dep_context=non-requeueable deps ti=<TaskInstance: my_scraping_dag.main_task scheduled__2023-09-05T00:00:00+00:00 [queued]>
[2023-12-07T17:01:21.482+0000] {taskinstance.py:1159} INFO - Dependencies all met for dep_context=requeueable deps ti=<TaskInstance: my_scraping_dag.main_task scheduled__2023-09-05T00:00:00+00:00 [queued]>
[2023-12-07T17:01:21.482+0000] {taskinstance.py:1361} INFO - Starting attempt 1 of 1
[2023-12-07T17:01:21.489+0000] {taskinstance.py:1382} INFO - Executing <Task(PythonOperator): main_task> on 2023-09-05 00:00:00+00:00
[2023-12-07T17:01:21.496+0000] {standard_task_runner.py:57} INFO - Started process 6367 to run task
[2023-12-07T17:01:21.498+0000] {standard_task_runner.py:84} INFO - Running: ['***', 'tasks', 'run', 'my_scraping_dag', 'main_task', 'scheduled__2023-09-05T00:00:00+00:00', '--job-id', '1649', '--raw', '--subdir', 'DAGS_FOLDER/main.py', '--cfg-path', '/tmp/tmpkxhkx_te']
[2023-12-07T17:01:21.499+0000] {standard_task_runner.py:85} INFO - Job 1649: Subtask main_task
[2023-12-07T17:01:21.539+0000] {task_command.py:416} INFO - Running <TaskInstance: my_scraping_dag.main_task scheduled__2023-09-05T00:00:00+00:00 [running]> on host 63b0c7e341c0
[2023-12-07T17:01:21.601+0000] {taskinstance.py:1662} INFO - Exporting env vars: AIRFLOW_CTX_DAG_OWNER='***' AIRFLOW_CTX_DAG_ID='my_scraping_dag' AIRFLOW_CTX_TASK_ID='main_task' AIRFLOW_CTX_EXECUTION_DATE='2023-09-05T00:00:00+00:00' AIRFLOW_CTX_TRY_NUMBER='1' AIRFLOW_CTX_DAG_RUN_ID='scheduled__2023-09-05T00:00:00+00:00'
[2023-12-07T17:01:21.639+0000] {logging_mixin.py:154} INFO - base_url: https://tuncbotanik.com
[2023-12-07T17:01:21.639+0000] {python.py:194} INFO - Done. Returned value was: ('https://tuncbotanik.com', {'User-Agent': 'Mozilla/5.0 (Macintosh; Intel Mac OS X 10_15_7) AppleWebKit/537.36 (KHTML, like Gecko) Chrome/119.0.0.0 Safari/537.36', 'Accept-Language': 'tr-TR,tr;q=0.9,en-US;q=0.8,en;q=0.7'}, {'dbname': 'plant', 'user': 'aozgokme', 'password': '***', 'host': 'localhost', 'port': '5432'})
[2023-12-07T17:01:21.660+0000] {taskinstance.py:1400} INFO - Marking task as SUCCESS. dag_id=my_scraping_dag, task_id=main_task, execution_date=20230905T000000, start_date=20231207T170121, end_date=20231207T170121
[2023-12-07T17:01:21.676+0000] {local_task_job_runner.py:228} INFO - Task exited with return code 0
[2023-12-07T17:01:21.696+0000] {taskinstance.py:2778} INFO - 1 downstream tasks scheduled from follow-on schedule check
[2023-12-07T17:04:43.351+0000] {taskinstance.py:1159} INFO - Dependencies all met for dep_context=non-requeueable deps ti=<TaskInstance: my_scraping_dag.main_task scheduled__2023-09-05T00:00:00+00:00 [queued]>
[2023-12-07T17:04:43.356+0000] {taskinstance.py:1159} INFO - Dependencies all met for dep_context=requeueable deps ti=<TaskInstance: my_scraping_dag.main_task scheduled__2023-09-05T00:00:00+00:00 [queued]>
[2023-12-07T17:04:43.356+0000] {taskinstance.py:1361} INFO - Starting attempt 1 of 1
[2023-12-07T17:04:43.379+0000] {taskinstance.py:1382} INFO - Executing <Task(PythonOperator): main_task> on 2023-09-05 00:00:00+00:00
[2023-12-07T17:04:43.382+0000] {standard_task_runner.py:57} INFO - Started process 7829 to run task
[2023-12-07T17:04:43.384+0000] {standard_task_runner.py:84} INFO - Running: ['***', 'tasks', 'run', 'my_scraping_dag', 'main_task', 'scheduled__2023-09-05T00:00:00+00:00', '--job-id', '2339', '--raw', '--subdir', 'DAGS_FOLDER/main.py', '--cfg-path', '/tmp/tmpz3a8ma_q']
[2023-12-07T17:04:43.386+0000] {standard_task_runner.py:85} INFO - Job 2339: Subtask main_task
[2023-12-07T17:04:43.413+0000] {task_command.py:416} INFO - Running <TaskInstance: my_scraping_dag.main_task scheduled__2023-09-05T00:00:00+00:00 [running]> on host 63b0c7e341c0
[2023-12-07T17:04:43.448+0000] {taskinstance.py:1662} INFO - Exporting env vars: AIRFLOW_CTX_DAG_OWNER='***' AIRFLOW_CTX_DAG_ID='my_scraping_dag' AIRFLOW_CTX_TASK_ID='main_task' AIRFLOW_CTX_EXECUTION_DATE='2023-09-05T00:00:00+00:00' AIRFLOW_CTX_TRY_NUMBER='1' AIRFLOW_CTX_DAG_RUN_ID='scheduled__2023-09-05T00:00:00+00:00'
[2023-12-07T17:04:43.471+0000] {logging_mixin.py:154} INFO - base_url: https://tuncbotanik.com
[2023-12-07T17:04:43.471+0000] {python.py:194} INFO - Done. Returned value was: ('https://tuncbotanik.com', {'User-Agent': 'Mozilla/5.0 (Macintosh; Intel Mac OS X 10_15_7) AppleWebKit/537.36 (KHTML, like Gecko) Chrome/119.0.0.0 Safari/537.36', 'Accept-Language': 'tr-TR,tr;q=0.9,en-US;q=0.8,en;q=0.7'}, {'dbname': 'plant', 'user': 'aozgokme', 'password': '***', 'host': 'localhost', 'port': '5432'})
[2023-12-07T17:04:43.482+0000] {taskinstance.py:1400} INFO - Marking task as SUCCESS. dag_id=my_scraping_dag, task_id=main_task, execution_date=20230905T000000, start_date=20231207T170443, end_date=20231207T170443
[2023-12-07T17:04:43.517+0000] {local_task_job_runner.py:228} INFO - Task exited with return code 0
[2023-12-07T17:04:43.560+0000] {taskinstance.py:2778} INFO - 0 downstream tasks scheduled from follow-on schedule check
[2023-12-07T17:19:08.758+0000] {taskinstance.py:1159} INFO - Dependencies all met for dep_context=non-requeueable deps ti=<TaskInstance: my_scraping_dag.main_task scheduled__2023-09-05T00:00:00+00:00 [queued]>
[2023-12-07T17:19:08.766+0000] {taskinstance.py:1159} INFO - Dependencies all met for dep_context=requeueable deps ti=<TaskInstance: my_scraping_dag.main_task scheduled__2023-09-05T00:00:00+00:00 [queued]>
[2023-12-07T17:19:08.766+0000] {taskinstance.py:1361} INFO - Starting attempt 1 of 1
[2023-12-07T17:19:08.828+0000] {taskinstance.py:1382} INFO - Executing <Task(PythonOperator): main_task> on 2023-09-05 00:00:00+00:00
[2023-12-07T17:19:08.840+0000] {standard_task_runner.py:57} INFO - Started process 9049 to run task
[2023-12-07T17:19:08.846+0000] {standard_task_runner.py:84} INFO - Running: ['***', 'tasks', 'run', 'my_scraping_dag', 'main_task', 'scheduled__2023-09-05T00:00:00+00:00', '--job-id', '2777', '--raw', '--subdir', 'DAGS_FOLDER/main.py', '--cfg-path', '/tmp/tmp3qwbxhnq']
[2023-12-07T17:19:08.851+0000] {standard_task_runner.py:85} INFO - Job 2777: Subtask main_task
[2023-12-07T17:19:08.894+0000] {task_command.py:416} INFO - Running <TaskInstance: my_scraping_dag.main_task scheduled__2023-09-05T00:00:00+00:00 [running]> on host 63b0c7e341c0
[2023-12-07T17:19:08.943+0000] {taskinstance.py:1662} INFO - Exporting env vars: AIRFLOW_CTX_DAG_OWNER='***' AIRFLOW_CTX_DAG_ID='my_scraping_dag' AIRFLOW_CTX_TASK_ID='main_task' AIRFLOW_CTX_EXECUTION_DATE='2023-09-05T00:00:00+00:00' AIRFLOW_CTX_TRY_NUMBER='1' AIRFLOW_CTX_DAG_RUN_ID='scheduled__2023-09-05T00:00:00+00:00'
[2023-12-07T17:19:09.590+0000] {taskinstance.py:1937} ERROR - Task failed with exception
Traceback (most recent call last):
  File "/home/airflow/.local/lib/python3.8/site-packages/airflow/operators/python.py", line 192, in execute
    return_value = self.execute_callable()
  File "/home/airflow/.local/lib/python3.8/site-packages/airflow/operators/python.py", line 209, in execute_callable
    return self.python_callable(*self.op_args, **self.op_kwargs)
  File "/opt/airflow/dags/main.py", line 80, in main
    insert_data_to_db(products, db_params)
  File "/opt/airflow/dags/main.py", line 43, in insert_data_to_db
    with psycopg2.connect(**db_params) as conn:
  File "/home/airflow/.local/lib/python3.8/site-packages/psycopg2/__init__.py", line 122, in connect
    conn = _connect(dsn, connection_factory=connection_factory, **kwasync)
psycopg2.OperationalError: connection to server at "localhost" (127.0.0.1), port 5432 failed: Connection refused
	Is the server running on that host and accepting TCP/IP connections?
connection to server at "localhost" (::1), port 5432 failed: Cannot assign requested address
	Is the server running on that host and accepting TCP/IP connections?

[2023-12-07T17:19:09.594+0000] {taskinstance.py:1400} INFO - Marking task as FAILED. dag_id=my_scraping_dag, task_id=main_task, execution_date=20230905T000000, start_date=20231207T171908, end_date=20231207T171909
[2023-12-07T17:19:09.599+0000] {standard_task_runner.py:104} ERROR - Failed to execute job 2777 for task main_task (connection to server at "localhost" (127.0.0.1), port 5432 failed: Connection refused
	Is the server running on that host and accepting TCP/IP connections?
connection to server at "localhost" (::1), port 5432 failed: Cannot assign requested address
	Is the server running on that host and accepting TCP/IP connections?
; 9049)
[2023-12-07T17:19:09.626+0000] {local_task_job_runner.py:228} INFO - Task exited with return code 1
[2023-12-07T17:19:09.634+0000] {taskinstance.py:2778} INFO - 0 downstream tasks scheduled from follow-on schedule check
[2023-12-07T17:23:28.076+0000] {taskinstance.py:1159} INFO - Dependencies all met for dep_context=non-requeueable deps ti=<TaskInstance: my_scraping_dag.main_task scheduled__2023-09-05T00:00:00+00:00 [queued]>
[2023-12-07T17:23:28.083+0000] {taskinstance.py:1159} INFO - Dependencies all met for dep_context=requeueable deps ti=<TaskInstance: my_scraping_dag.main_task scheduled__2023-09-05T00:00:00+00:00 [queued]>
[2023-12-07T17:23:28.083+0000] {taskinstance.py:1361} INFO - Starting attempt 1 of 1
[2023-12-07T17:23:28.128+0000] {taskinstance.py:1382} INFO - Executing <Task(PythonOperator): main_task> on 2023-09-05 00:00:00+00:00
[2023-12-07T17:23:28.131+0000] {standard_task_runner.py:57} INFO - Started process 9856 to run task
[2023-12-07T17:23:28.134+0000] {standard_task_runner.py:84} INFO - Running: ['***', 'tasks', 'run', 'my_scraping_dag', 'main_task', 'scheduled__2023-09-05T00:00:00+00:00', '--job-id', '3119', '--raw', '--subdir', 'DAGS_FOLDER/main.py', '--cfg-path', '/tmp/tmp0pgty__j']
[2023-12-07T17:23:28.137+0000] {standard_task_runner.py:85} INFO - Job 3119: Subtask main_task
[2023-12-07T17:23:28.192+0000] {task_command.py:416} INFO - Running <TaskInstance: my_scraping_dag.main_task scheduled__2023-09-05T00:00:00+00:00 [running]> on host 63b0c7e341c0
[2023-12-07T17:23:28.280+0000] {taskinstance.py:1662} INFO - Exporting env vars: AIRFLOW_CTX_DAG_OWNER='***' AIRFLOW_CTX_DAG_ID='my_scraping_dag' AIRFLOW_CTX_TASK_ID='main_task' AIRFLOW_CTX_EXECUTION_DATE='2023-09-05T00:00:00+00:00' AIRFLOW_CTX_TRY_NUMBER='1' AIRFLOW_CTX_DAG_RUN_ID='scheduled__2023-09-05T00:00:00+00:00'
[2023-12-07T17:23:29.045+0000] {taskinstance.py:1937} ERROR - Task failed with exception
Traceback (most recent call last):
  File "/home/airflow/.local/lib/python3.8/site-packages/airflow/operators/python.py", line 192, in execute
    return_value = self.execute_callable()
  File "/home/airflow/.local/lib/python3.8/site-packages/airflow/operators/python.py", line 209, in execute_callable
    return self.python_callable(*self.op_args, **self.op_kwargs)
  File "/opt/airflow/dags/main.py", line 73, in main
    insert_data_to_db(products, db_params)
  File "/opt/airflow/dags/main.py", line 40, in insert_data_to_db
    with psycopg2.connect(**db_params) as conn:
  File "/home/airflow/.local/lib/python3.8/site-packages/psycopg2/__init__.py", line 122, in connect
    conn = _connect(dsn, connection_factory=connection_factory, **kwasync)
psycopg2.OperationalError: connection to server at "localhost" (127.0.0.1), port 5432 failed: Connection refused
	Is the server running on that host and accepting TCP/IP connections?
connection to server at "localhost" (::1), port 5432 failed: Cannot assign requested address
	Is the server running on that host and accepting TCP/IP connections?

[2023-12-07T17:23:29.050+0000] {taskinstance.py:1400} INFO - Marking task as FAILED. dag_id=my_scraping_dag, task_id=main_task, execution_date=20230905T000000, start_date=20231207T172328, end_date=20231207T172329
[2023-12-07T17:23:29.056+0000] {standard_task_runner.py:104} ERROR - Failed to execute job 3119 for task main_task (connection to server at "localhost" (127.0.0.1), port 5432 failed: Connection refused
	Is the server running on that host and accepting TCP/IP connections?
connection to server at "localhost" (::1), port 5432 failed: Cannot assign requested address
	Is the server running on that host and accepting TCP/IP connections?
; 9856)
[2023-12-07T17:23:29.077+0000] {local_task_job_runner.py:228} INFO - Task exited with return code 1
[2023-12-07T17:23:29.087+0000] {taskinstance.py:2778} INFO - 0 downstream tasks scheduled from follow-on schedule check
[2023-12-07T17:29:07.125+0000] {taskinstance.py:1159} INFO - Dependencies all met for dep_context=non-requeueable deps ti=<TaskInstance: my_scraping_dag.main_task scheduled__2023-09-05T00:00:00+00:00 [queued]>
[2023-12-07T17:29:07.130+0000] {taskinstance.py:1159} INFO - Dependencies all met for dep_context=requeueable deps ti=<TaskInstance: my_scraping_dag.main_task scheduled__2023-09-05T00:00:00+00:00 [queued]>
[2023-12-07T17:29:07.131+0000] {taskinstance.py:1361} INFO - Starting attempt 1 of 1
[2023-12-07T17:29:07.139+0000] {taskinstance.py:1382} INFO - Executing <Task(PythonOperator): main_task> on 2023-09-05 00:00:00+00:00
[2023-12-07T17:29:07.142+0000] {standard_task_runner.py:57} INFO - Started process 10687 to run task
[2023-12-07T17:29:07.145+0000] {standard_task_runner.py:84} INFO - Running: ['***', 'tasks', 'run', 'my_scraping_dag', 'main_task', 'scheduled__2023-09-05T00:00:00+00:00', '--job-id', '3461', '--raw', '--subdir', 'DAGS_FOLDER/main.py', '--cfg-path', '/tmp/tmp_gfwluyo']
[2023-12-07T17:29:07.146+0000] {standard_task_runner.py:85} INFO - Job 3461: Subtask main_task
[2023-12-07T17:29:07.174+0000] {task_command.py:416} INFO - Running <TaskInstance: my_scraping_dag.main_task scheduled__2023-09-05T00:00:00+00:00 [running]> on host 63b0c7e341c0
[2023-12-07T17:29:07.219+0000] {taskinstance.py:1662} INFO - Exporting env vars: AIRFLOW_CTX_DAG_OWNER='***' AIRFLOW_CTX_DAG_ID='my_scraping_dag' AIRFLOW_CTX_TASK_ID='main_task' AIRFLOW_CTX_EXECUTION_DATE='2023-09-05T00:00:00+00:00' AIRFLOW_CTX_TRY_NUMBER='1' AIRFLOW_CTX_DAG_RUN_ID='scheduled__2023-09-05T00:00:00+00:00'
[2023-12-07T17:29:07.897+0000] {taskinstance.py:1937} ERROR - Task failed with exception
Traceback (most recent call last):
  File "/home/airflow/.local/lib/python3.8/site-packages/airflow/operators/python.py", line 192, in execute
    return_value = self.execute_callable()
  File "/home/airflow/.local/lib/python3.8/site-packages/airflow/operators/python.py", line 209, in execute_callable
    return self.python_callable(*self.op_args, **self.op_kwargs)
  File "/opt/airflow/dags/main.py", line 73, in main
    insert_data_to_db(products, db_params)
  File "/opt/airflow/dags/main.py", line 40, in insert_data_to_db
    with psycopg2.connect(**db_params) as conn:
  File "/home/airflow/.local/lib/python3.8/site-packages/psycopg2/__init__.py", line 122, in connect
    conn = _connect(dsn, connection_factory=connection_factory, **kwasync)
psycopg2.OperationalError: connection to server at "localhost" (127.0.0.1), port 5432 failed: Connection refused
	Is the server running on that host and accepting TCP/IP connections?
connection to server at "localhost" (::1), port 5432 failed: Cannot assign requested address
	Is the server running on that host and accepting TCP/IP connections?

[2023-12-07T17:29:07.902+0000] {taskinstance.py:1400} INFO - Marking task as FAILED. dag_id=my_scraping_dag, task_id=main_task, execution_date=20230905T000000, start_date=20231207T172907, end_date=20231207T172907
[2023-12-07T17:29:07.907+0000] {standard_task_runner.py:104} ERROR - Failed to execute job 3461 for task main_task (connection to server at "localhost" (127.0.0.1), port 5432 failed: Connection refused
	Is the server running on that host and accepting TCP/IP connections?
connection to server at "localhost" (::1), port 5432 failed: Cannot assign requested address
	Is the server running on that host and accepting TCP/IP connections?
; 10687)
[2023-12-07T17:29:07.919+0000] {local_task_job_runner.py:228} INFO - Task exited with return code 1
[2023-12-07T17:29:07.929+0000] {taskinstance.py:2778} INFO - 0 downstream tasks scheduled from follow-on schedule check
