[2023-12-07T16:34:35.457+0000] {taskinstance.py:1159} INFO - Dependencies all met for dep_context=non-requeueable deps ti=<TaskInstance: my_scraping_dag.main_task scheduled__2023-12-05T00:00:00+00:00 [queued]>
[2023-12-07T16:34:35.461+0000] {taskinstance.py:1159} INFO - Dependencies all met for dep_context=requeueable deps ti=<TaskInstance: my_scraping_dag.main_task scheduled__2023-12-05T00:00:00+00:00 [queued]>
[2023-12-07T16:34:35.461+0000] {taskinstance.py:1361} INFO - Starting attempt 1 of 1
[2023-12-07T16:34:35.467+0000] {taskinstance.py:1382} INFO - Executing <Task(PythonOperator): main_task> on 2023-12-05 00:00:00+00:00
[2023-12-07T16:34:35.469+0000] {standard_task_runner.py:57} INFO - Started process 4270 to run task
[2023-12-07T16:34:35.471+0000] {standard_task_runner.py:84} INFO - Running: ['***', 'tasks', 'run', 'my_scraping_dag', 'main_task', 'scheduled__2023-12-05T00:00:00+00:00', '--job-id', '927', '--raw', '--subdir', 'DAGS_FOLDER/main.py', '--cfg-path', '/tmp/tmp8ppxpw4r']
[2023-12-07T16:34:35.473+0000] {standard_task_runner.py:85} INFO - Job 927: Subtask main_task
[2023-12-07T16:34:35.495+0000] {task_command.py:416} INFO - Running <TaskInstance: my_scraping_dag.main_task scheduled__2023-12-05T00:00:00+00:00 [running]> on host 63b0c7e341c0
[2023-12-07T16:34:35.525+0000] {taskinstance.py:1662} INFO - Exporting env vars: AIRFLOW_CTX_DAG_OWNER='***' AIRFLOW_CTX_DAG_ID='my_scraping_dag' AIRFLOW_CTX_TASK_ID='main_task' AIRFLOW_CTX_EXECUTION_DATE='2023-12-05T00:00:00+00:00' AIRFLOW_CTX_TRY_NUMBER='1' AIRFLOW_CTX_DAG_RUN_ID='scheduled__2023-12-05T00:00:00+00:00'
[2023-12-07T16:34:35.526+0000] {taskinstance.py:1937} ERROR - Task failed with exception
Traceback (most recent call last):
  File "/usr/local/lib/python3.8/configparser.py", line 846, in items
    d.update(self._sections[section])
KeyError: 'web'

During handling of the above exception, another exception occurred:

Traceback (most recent call last):
  File "/home/airflow/.local/lib/python3.8/site-packages/airflow/operators/python.py", line 192, in execute
    return_value = self.execute_callable()
  File "/home/airflow/.local/lib/python3.8/site-packages/airflow/operators/python.py", line 209, in execute_callable
    return self.python_callable(*self.op_args, **self.op_kwargs)
  File "/opt/airflow/dags/main.py", line 60, in main
    config = get_config('web')
  File "/opt/airflow/dags/main.py", line 22, in get_config
    return {key: value for key, value in parser.items(section)}
  File "/usr/local/lib/python3.8/configparser.py", line 849, in items
    raise NoSectionError(section)
configparser.NoSectionError: No section: 'web'
[2023-12-07T16:34:35.530+0000] {taskinstance.py:1400} INFO - Marking task as FAILED. dag_id=my_scraping_dag, task_id=main_task, execution_date=20231205T000000, start_date=20231207T163435, end_date=20231207T163435
[2023-12-07T16:34:35.534+0000] {standard_task_runner.py:104} ERROR - Failed to execute job 927 for task main_task (No section: 'web'; 4270)
[2023-12-07T16:34:35.565+0000] {local_task_job_runner.py:228} INFO - Task exited with return code 1
[2023-12-07T16:34:35.576+0000] {taskinstance.py:2778} INFO - 0 downstream tasks scheduled from follow-on schedule check
[2023-12-07T16:43:13.685+0000] {taskinstance.py:1159} INFO - Dependencies all met for dep_context=non-requeueable deps ti=<TaskInstance: my_scraping_dag.main_task scheduled__2023-12-05T00:00:00+00:00 [queued]>
[2023-12-07T16:43:13.689+0000] {taskinstance.py:1159} INFO - Dependencies all met for dep_context=requeueable deps ti=<TaskInstance: my_scraping_dag.main_task scheduled__2023-12-05T00:00:00+00:00 [queued]>
[2023-12-07T16:43:13.689+0000] {taskinstance.py:1361} INFO - Starting attempt 1 of 1
[2023-12-07T16:43:13.694+0000] {taskinstance.py:1382} INFO - Executing <Task(PythonOperator): main_task> on 2023-12-05 00:00:00+00:00
[2023-12-07T16:43:13.696+0000] {standard_task_runner.py:57} INFO - Started process 5163 to run task
[2023-12-07T16:43:13.699+0000] {standard_task_runner.py:84} INFO - Running: ['***', 'tasks', 'run', 'my_scraping_dag', 'main_task', 'scheduled__2023-12-05T00:00:00+00:00', '--job-id', '1272', '--raw', '--subdir', 'DAGS_FOLDER/main.py', '--cfg-path', '/tmp/tmpso7y2d76']
[2023-12-07T16:43:13.700+0000] {standard_task_runner.py:85} INFO - Job 1272: Subtask main_task
[2023-12-07T16:43:13.723+0000] {task_command.py:416} INFO - Running <TaskInstance: my_scraping_dag.main_task scheduled__2023-12-05T00:00:00+00:00 [running]> on host 63b0c7e341c0
[2023-12-07T16:43:13.753+0000] {taskinstance.py:1662} INFO - Exporting env vars: AIRFLOW_CTX_DAG_OWNER='***' AIRFLOW_CTX_DAG_ID='my_scraping_dag' AIRFLOW_CTX_TASK_ID='main_task' AIRFLOW_CTX_EXECUTION_DATE='2023-12-05T00:00:00+00:00' AIRFLOW_CTX_TRY_NUMBER='1' AIRFLOW_CTX_DAG_RUN_ID='scheduled__2023-12-05T00:00:00+00:00'
[2023-12-07T16:43:13.754+0000] {taskinstance.py:1937} ERROR - Task failed with exception
Traceback (most recent call last):
  File "/usr/local/lib/python3.8/configparser.py", line 846, in items
    d.update(self._sections[section])
KeyError: 'web'

During handling of the above exception, another exception occurred:

Traceback (most recent call last):
  File "/home/airflow/.local/lib/python3.8/site-packages/airflow/operators/python.py", line 192, in execute
    return_value = self.execute_callable()
  File "/home/airflow/.local/lib/python3.8/site-packages/airflow/operators/python.py", line 209, in execute_callable
    return self.python_callable(*self.op_args, **self.op_kwargs)
  File "/opt/airflow/dags/main.py", line 60, in main
    config = get_config('web')
  File "/opt/airflow/dags/main.py", line 22, in get_config
    return {key: value for key, value in parser.items(section)}
  File "/usr/local/lib/python3.8/configparser.py", line 849, in items
    raise NoSectionError(section)
configparser.NoSectionError: No section: 'web'
[2023-12-07T16:43:13.758+0000] {taskinstance.py:1400} INFO - Marking task as FAILED. dag_id=my_scraping_dag, task_id=main_task, execution_date=20231205T000000, start_date=20231207T164313, end_date=20231207T164313
[2023-12-07T16:43:13.762+0000] {standard_task_runner.py:104} ERROR - Failed to execute job 1272 for task main_task (No section: 'web'; 5163)
[2023-12-07T16:43:13.790+0000] {local_task_job_runner.py:228} INFO - Task exited with return code 1
[2023-12-07T16:43:13.801+0000] {taskinstance.py:2778} INFO - 0 downstream tasks scheduled from follow-on schedule check
[2023-12-07T17:01:52.242+0000] {taskinstance.py:1159} INFO - Dependencies all met for dep_context=non-requeueable deps ti=<TaskInstance: my_scraping_dag.main_task scheduled__2023-12-05T00:00:00+00:00 [queued]>
[2023-12-07T17:01:52.249+0000] {taskinstance.py:1159} INFO - Dependencies all met for dep_context=requeueable deps ti=<TaskInstance: my_scraping_dag.main_task scheduled__2023-12-05T00:00:00+00:00 [queued]>
[2023-12-07T17:01:52.249+0000] {taskinstance.py:1361} INFO - Starting attempt 1 of 1
[2023-12-07T17:01:52.278+0000] {taskinstance.py:1382} INFO - Executing <Task(PythonOperator): main_task> on 2023-12-05 00:00:00+00:00
[2023-12-07T17:01:52.282+0000] {standard_task_runner.py:57} INFO - Started process 6743 to run task
[2023-12-07T17:01:52.284+0000] {standard_task_runner.py:84} INFO - Running: ['***', 'tasks', 'run', 'my_scraping_dag', 'main_task', 'scheduled__2023-12-05T00:00:00+00:00', '--job-id', '1832', '--raw', '--subdir', 'DAGS_FOLDER/main.py', '--cfg-path', '/tmp/tmpwkrrcdcc']
[2023-12-07T17:01:52.288+0000] {standard_task_runner.py:85} INFO - Job 1832: Subtask main_task
[2023-12-07T17:01:52.323+0000] {task_command.py:416} INFO - Running <TaskInstance: my_scraping_dag.main_task scheduled__2023-12-05T00:00:00+00:00 [running]> on host 63b0c7e341c0
[2023-12-07T17:01:52.367+0000] {taskinstance.py:1662} INFO - Exporting env vars: AIRFLOW_CTX_DAG_OWNER='***' AIRFLOW_CTX_DAG_ID='my_scraping_dag' AIRFLOW_CTX_TASK_ID='main_task' AIRFLOW_CTX_EXECUTION_DATE='2023-12-05T00:00:00+00:00' AIRFLOW_CTX_TRY_NUMBER='1' AIRFLOW_CTX_DAG_RUN_ID='scheduled__2023-12-05T00:00:00+00:00'
[2023-12-07T17:01:52.394+0000] {logging_mixin.py:154} INFO - base_url: https://tuncbotanik.com
[2023-12-07T17:01:52.395+0000] {python.py:194} INFO - Done. Returned value was: ('https://tuncbotanik.com', {'User-Agent': 'Mozilla/5.0 (Macintosh; Intel Mac OS X 10_15_7) AppleWebKit/537.36 (KHTML, like Gecko) Chrome/119.0.0.0 Safari/537.36', 'Accept-Language': 'tr-TR,tr;q=0.9,en-US;q=0.8,en;q=0.7'}, {'dbname': 'plant', 'user': 'aozgokme', 'password': '***', 'host': 'localhost', 'port': '5432'})
[2023-12-07T17:01:52.411+0000] {taskinstance.py:1400} INFO - Marking task as SUCCESS. dag_id=my_scraping_dag, task_id=main_task, execution_date=20231205T000000, start_date=20231207T170152, end_date=20231207T170152
[2023-12-07T17:01:52.459+0000] {local_task_job_runner.py:228} INFO - Task exited with return code 0
[2023-12-07T17:01:52.477+0000] {taskinstance.py:2778} INFO - 0 downstream tasks scheduled from follow-on schedule check
[2023-12-07T17:05:16.494+0000] {taskinstance.py:1159} INFO - Dependencies all met for dep_context=non-requeueable deps ti=<TaskInstance: my_scraping_dag.main_task scheduled__2023-12-05T00:00:00+00:00 [queued]>
[2023-12-07T17:05:16.498+0000] {taskinstance.py:1159} INFO - Dependencies all met for dep_context=requeueable deps ti=<TaskInstance: my_scraping_dag.main_task scheduled__2023-12-05T00:00:00+00:00 [queued]>
[2023-12-07T17:05:16.498+0000] {taskinstance.py:1361} INFO - Starting attempt 1 of 1
[2023-12-07T17:05:16.504+0000] {taskinstance.py:1382} INFO - Executing <Task(PythonOperator): main_task> on 2023-12-05 00:00:00+00:00
[2023-12-07T17:05:16.506+0000] {standard_task_runner.py:57} INFO - Started process 8199 to run task
[2023-12-07T17:05:16.508+0000] {standard_task_runner.py:84} INFO - Running: ['***', 'tasks', 'run', 'my_scraping_dag', 'main_task', 'scheduled__2023-12-05T00:00:00+00:00', '--job-id', '2519', '--raw', '--subdir', 'DAGS_FOLDER/main.py', '--cfg-path', '/tmp/tmp81ayhlup']
[2023-12-07T17:05:16.510+0000] {standard_task_runner.py:85} INFO - Job 2519: Subtask main_task
[2023-12-07T17:05:16.530+0000] {task_command.py:416} INFO - Running <TaskInstance: my_scraping_dag.main_task scheduled__2023-12-05T00:00:00+00:00 [running]> on host 63b0c7e341c0
[2023-12-07T17:05:16.564+0000] {taskinstance.py:1662} INFO - Exporting env vars: AIRFLOW_CTX_DAG_OWNER='***' AIRFLOW_CTX_DAG_ID='my_scraping_dag' AIRFLOW_CTX_TASK_ID='main_task' AIRFLOW_CTX_EXECUTION_DATE='2023-12-05T00:00:00+00:00' AIRFLOW_CTX_TRY_NUMBER='1' AIRFLOW_CTX_DAG_RUN_ID='scheduled__2023-12-05T00:00:00+00:00'
[2023-12-07T17:05:16.579+0000] {logging_mixin.py:154} INFO - base_url: https://tuncbotanik.com
[2023-12-07T17:05:16.580+0000] {python.py:194} INFO - Done. Returned value was: ('https://tuncbotanik.com', {'User-Agent': 'Mozilla/5.0 (Macintosh; Intel Mac OS X 10_15_7) AppleWebKit/537.36 (KHTML, like Gecko) Chrome/119.0.0.0 Safari/537.36', 'Accept-Language': 'tr-TR,tr;q=0.9,en-US;q=0.8,en;q=0.7'}, {'dbname': 'plant', 'user': 'aozgokme', 'password': '***', 'host': 'localhost', 'port': '5432'})
[2023-12-07T17:05:16.589+0000] {taskinstance.py:1400} INFO - Marking task as SUCCESS. dag_id=my_scraping_dag, task_id=main_task, execution_date=20231205T000000, start_date=20231207T170516, end_date=20231207T170516
[2023-12-07T17:05:16.600+0000] {local_task_job_runner.py:228} INFO - Task exited with return code 0
[2023-12-07T17:05:16.613+0000] {taskinstance.py:2778} INFO - 1 downstream tasks scheduled from follow-on schedule check
[2023-12-07T17:19:28.381+0000] {taskinstance.py:1159} INFO - Dependencies all met for dep_context=non-requeueable deps ti=<TaskInstance: my_scraping_dag.main_task scheduled__2023-12-05T00:00:00+00:00 [queued]>
[2023-12-07T17:19:28.386+0000] {taskinstance.py:1159} INFO - Dependencies all met for dep_context=requeueable deps ti=<TaskInstance: my_scraping_dag.main_task scheduled__2023-12-05T00:00:00+00:00 [queued]>
[2023-12-07T17:19:28.386+0000] {taskinstance.py:1361} INFO - Starting attempt 1 of 1
[2023-12-07T17:19:28.393+0000] {taskinstance.py:1382} INFO - Executing <Task(PythonOperator): main_task> on 2023-12-05 00:00:00+00:00
[2023-12-07T17:19:28.395+0000] {standard_task_runner.py:57} INFO - Started process 9242 to run task
[2023-12-07T17:19:28.397+0000] {standard_task_runner.py:84} INFO - Running: ['***', 'tasks', 'run', 'my_scraping_dag', 'main_task', 'scheduled__2023-12-05T00:00:00+00:00', '--job-id', '2868', '--raw', '--subdir', 'DAGS_FOLDER/main.py', '--cfg-path', '/tmp/tmpv2xx4o_i']
[2023-12-07T17:19:28.400+0000] {standard_task_runner.py:85} INFO - Job 2868: Subtask main_task
[2023-12-07T17:19:28.425+0000] {task_command.py:416} INFO - Running <TaskInstance: my_scraping_dag.main_task scheduled__2023-12-05T00:00:00+00:00 [running]> on host 63b0c7e341c0
[2023-12-07T17:19:28.468+0000] {taskinstance.py:1662} INFO - Exporting env vars: AIRFLOW_CTX_DAG_OWNER='***' AIRFLOW_CTX_DAG_ID='my_scraping_dag' AIRFLOW_CTX_TASK_ID='main_task' AIRFLOW_CTX_EXECUTION_DATE='2023-12-05T00:00:00+00:00' AIRFLOW_CTX_TRY_NUMBER='1' AIRFLOW_CTX_DAG_RUN_ID='scheduled__2023-12-05T00:00:00+00:00'
[2023-12-07T17:19:29.119+0000] {taskinstance.py:1937} ERROR - Task failed with exception
Traceback (most recent call last):
  File "/home/airflow/.local/lib/python3.8/site-packages/airflow/operators/python.py", line 192, in execute
    return_value = self.execute_callable()
  File "/home/airflow/.local/lib/python3.8/site-packages/airflow/operators/python.py", line 209, in execute_callable
    return self.python_callable(*self.op_args, **self.op_kwargs)
  File "/opt/airflow/dags/main.py", line 80, in main
    insert_data_to_db(products, db_params)
  File "/opt/airflow/dags/main.py", line 43, in insert_data_to_db
    with psycopg2.connect(**db_params) as conn:
  File "/home/airflow/.local/lib/python3.8/site-packages/psycopg2/__init__.py", line 122, in connect
    conn = _connect(dsn, connection_factory=connection_factory, **kwasync)
psycopg2.OperationalError: connection to server at "localhost" (127.0.0.1), port 5432 failed: Connection refused
	Is the server running on that host and accepting TCP/IP connections?
connection to server at "localhost" (::1), port 5432 failed: Cannot assign requested address
	Is the server running on that host and accepting TCP/IP connections?

[2023-12-07T17:19:29.123+0000] {taskinstance.py:1400} INFO - Marking task as FAILED. dag_id=my_scraping_dag, task_id=main_task, execution_date=20231205T000000, start_date=20231207T171928, end_date=20231207T171929
[2023-12-07T17:19:29.130+0000] {standard_task_runner.py:104} ERROR - Failed to execute job 2868 for task main_task (connection to server at "localhost" (127.0.0.1), port 5432 failed: Connection refused
	Is the server running on that host and accepting TCP/IP connections?
connection to server at "localhost" (::1), port 5432 failed: Cannot assign requested address
	Is the server running on that host and accepting TCP/IP connections?
; 9242)
[2023-12-07T17:19:29.176+0000] {local_task_job_runner.py:228} INFO - Task exited with return code 1
[2023-12-07T17:19:29.185+0000] {taskinstance.py:2778} INFO - 0 downstream tasks scheduled from follow-on schedule check
[2023-12-07T17:23:52.720+0000] {taskinstance.py:1159} INFO - Dependencies all met for dep_context=non-requeueable deps ti=<TaskInstance: my_scraping_dag.main_task scheduled__2023-12-05T00:00:00+00:00 [queued]>
[2023-12-07T17:23:52.724+0000] {taskinstance.py:1159} INFO - Dependencies all met for dep_context=requeueable deps ti=<TaskInstance: my_scraping_dag.main_task scheduled__2023-12-05T00:00:00+00:00 [queued]>
[2023-12-07T17:23:52.725+0000] {taskinstance.py:1361} INFO - Starting attempt 1 of 1
[2023-12-07T17:23:52.731+0000] {taskinstance.py:1382} INFO - Executing <Task(PythonOperator): main_task> on 2023-12-05 00:00:00+00:00
[2023-12-07T17:23:52.733+0000] {standard_task_runner.py:57} INFO - Started process 10044 to run task
[2023-12-07T17:23:52.736+0000] {standard_task_runner.py:84} INFO - Running: ['***', 'tasks', 'run', 'my_scraping_dag', 'main_task', 'scheduled__2023-12-05T00:00:00+00:00', '--job-id', '3210', '--raw', '--subdir', 'DAGS_FOLDER/main.py', '--cfg-path', '/tmp/tmpghz9cgjt']
[2023-12-07T17:23:52.737+0000] {standard_task_runner.py:85} INFO - Job 3210: Subtask main_task
[2023-12-07T17:23:52.761+0000] {task_command.py:416} INFO - Running <TaskInstance: my_scraping_dag.main_task scheduled__2023-12-05T00:00:00+00:00 [running]> on host 63b0c7e341c0
[2023-12-07T17:23:52.792+0000] {taskinstance.py:1662} INFO - Exporting env vars: AIRFLOW_CTX_DAG_OWNER='***' AIRFLOW_CTX_DAG_ID='my_scraping_dag' AIRFLOW_CTX_TASK_ID='main_task' AIRFLOW_CTX_EXECUTION_DATE='2023-12-05T00:00:00+00:00' AIRFLOW_CTX_TRY_NUMBER='1' AIRFLOW_CTX_DAG_RUN_ID='scheduled__2023-12-05T00:00:00+00:00'
[2023-12-07T17:23:53.428+0000] {taskinstance.py:1937} ERROR - Task failed with exception
Traceback (most recent call last):
  File "/home/airflow/.local/lib/python3.8/site-packages/airflow/operators/python.py", line 192, in execute
    return_value = self.execute_callable()
  File "/home/airflow/.local/lib/python3.8/site-packages/airflow/operators/python.py", line 209, in execute_callable
    return self.python_callable(*self.op_args, **self.op_kwargs)
  File "/opt/airflow/dags/main.py", line 73, in main
    insert_data_to_db(products, db_params)
  File "/opt/airflow/dags/main.py", line 40, in insert_data_to_db
    with psycopg2.connect(**db_params) as conn:
  File "/home/airflow/.local/lib/python3.8/site-packages/psycopg2/__init__.py", line 122, in connect
    conn = _connect(dsn, connection_factory=connection_factory, **kwasync)
psycopg2.OperationalError: connection to server at "localhost" (127.0.0.1), port 5432 failed: Connection refused
	Is the server running on that host and accepting TCP/IP connections?
connection to server at "localhost" (::1), port 5432 failed: Cannot assign requested address
	Is the server running on that host and accepting TCP/IP connections?

[2023-12-07T17:23:53.433+0000] {taskinstance.py:1400} INFO - Marking task as FAILED. dag_id=my_scraping_dag, task_id=main_task, execution_date=20231205T000000, start_date=20231207T172352, end_date=20231207T172353
[2023-12-07T17:23:53.437+0000] {standard_task_runner.py:104} ERROR - Failed to execute job 3210 for task main_task (connection to server at "localhost" (127.0.0.1), port 5432 failed: Connection refused
	Is the server running on that host and accepting TCP/IP connections?
connection to server at "localhost" (::1), port 5432 failed: Cannot assign requested address
	Is the server running on that host and accepting TCP/IP connections?
; 10044)
[2023-12-07T17:23:53.450+0000] {local_task_job_runner.py:228} INFO - Task exited with return code 1
[2023-12-07T17:23:53.459+0000] {taskinstance.py:2778} INFO - 0 downstream tasks scheduled from follow-on schedule check
[2023-12-07T17:29:26.434+0000] {taskinstance.py:1159} INFO - Dependencies all met for dep_context=non-requeueable deps ti=<TaskInstance: my_scraping_dag.main_task scheduled__2023-12-05T00:00:00+00:00 [queued]>
[2023-12-07T17:29:26.439+0000] {taskinstance.py:1159} INFO - Dependencies all met for dep_context=requeueable deps ti=<TaskInstance: my_scraping_dag.main_task scheduled__2023-12-05T00:00:00+00:00 [queued]>
[2023-12-07T17:29:26.439+0000] {taskinstance.py:1361} INFO - Starting attempt 1 of 1
[2023-12-07T17:29:26.446+0000] {taskinstance.py:1382} INFO - Executing <Task(PythonOperator): main_task> on 2023-12-05 00:00:00+00:00
[2023-12-07T17:29:26.449+0000] {standard_task_runner.py:57} INFO - Started process 10880 to run task
[2023-12-07T17:29:26.451+0000] {standard_task_runner.py:84} INFO - Running: ['***', 'tasks', 'run', 'my_scraping_dag', 'main_task', 'scheduled__2023-12-05T00:00:00+00:00', '--job-id', '3552', '--raw', '--subdir', 'DAGS_FOLDER/main.py', '--cfg-path', '/tmp/tmpq5x0ioa3']
[2023-12-07T17:29:26.453+0000] {standard_task_runner.py:85} INFO - Job 3552: Subtask main_task
[2023-12-07T17:29:26.478+0000] {task_command.py:416} INFO - Running <TaskInstance: my_scraping_dag.main_task scheduled__2023-12-05T00:00:00+00:00 [running]> on host 63b0c7e341c0
[2023-12-07T17:29:26.518+0000] {taskinstance.py:1662} INFO - Exporting env vars: AIRFLOW_CTX_DAG_OWNER='***' AIRFLOW_CTX_DAG_ID='my_scraping_dag' AIRFLOW_CTX_TASK_ID='main_task' AIRFLOW_CTX_EXECUTION_DATE='2023-12-05T00:00:00+00:00' AIRFLOW_CTX_TRY_NUMBER='1' AIRFLOW_CTX_DAG_RUN_ID='scheduled__2023-12-05T00:00:00+00:00'
[2023-12-07T17:29:27.380+0000] {taskinstance.py:1937} ERROR - Task failed with exception
Traceback (most recent call last):
  File "/home/airflow/.local/lib/python3.8/site-packages/airflow/operators/python.py", line 192, in execute
    return_value = self.execute_callable()
  File "/home/airflow/.local/lib/python3.8/site-packages/airflow/operators/python.py", line 209, in execute_callable
    return self.python_callable(*self.op_args, **self.op_kwargs)
  File "/opt/airflow/dags/main.py", line 73, in main
    insert_data_to_db(products, db_params)
  File "/opt/airflow/dags/main.py", line 40, in insert_data_to_db
    with psycopg2.connect(**db_params) as conn:
  File "/home/airflow/.local/lib/python3.8/site-packages/psycopg2/__init__.py", line 122, in connect
    conn = _connect(dsn, connection_factory=connection_factory, **kwasync)
psycopg2.OperationalError: connection to server at "localhost" (127.0.0.1), port 5432 failed: Connection refused
	Is the server running on that host and accepting TCP/IP connections?
connection to server at "localhost" (::1), port 5432 failed: Cannot assign requested address
	Is the server running on that host and accepting TCP/IP connections?

[2023-12-07T17:29:27.385+0000] {taskinstance.py:1400} INFO - Marking task as FAILED. dag_id=my_scraping_dag, task_id=main_task, execution_date=20231205T000000, start_date=20231207T172926, end_date=20231207T172927
[2023-12-07T17:29:27.390+0000] {standard_task_runner.py:104} ERROR - Failed to execute job 3552 for task main_task (connection to server at "localhost" (127.0.0.1), port 5432 failed: Connection refused
	Is the server running on that host and accepting TCP/IP connections?
connection to server at "localhost" (::1), port 5432 failed: Cannot assign requested address
	Is the server running on that host and accepting TCP/IP connections?
; 10880)
[2023-12-07T17:29:27.396+0000] {local_task_job_runner.py:228} INFO - Task exited with return code 1
[2023-12-07T17:29:27.405+0000] {taskinstance.py:2778} INFO - 0 downstream tasks scheduled from follow-on schedule check
[2023-12-09T07:35:46.484+0000] {taskinstance.py:1159} INFO - Dependencies all met for dep_context=non-requeueable deps ti=<TaskInstance: my_scraping_dag.main_task scheduled__2023-12-05T00:00:00+00:00 [queued]>
[2023-12-09T07:35:46.488+0000] {taskinstance.py:1159} INFO - Dependencies all met for dep_context=requeueable deps ti=<TaskInstance: my_scraping_dag.main_task scheduled__2023-12-05T00:00:00+00:00 [queued]>
[2023-12-09T07:35:46.488+0000] {taskinstance.py:1361} INFO - Starting attempt 1 of 1
[2023-12-09T07:35:46.498+0000] {taskinstance.py:1382} INFO - Executing <Task(PythonOperator): main_task> on 2023-12-05 00:00:00+00:00
[2023-12-09T07:35:46.500+0000] {standard_task_runner.py:57} INFO - Started process 1299 to run task
[2023-12-09T07:35:46.503+0000] {standard_task_runner.py:84} INFO - Running: ['***', 'tasks', 'run', 'my_scraping_dag', 'main_task', 'scheduled__2023-12-05T00:00:00+00:00', '--job-id', '342', '--raw', '--subdir', 'DAGS_FOLDER/main.py', '--cfg-path', '/tmp/tmpjznb7ntw']
[2023-12-09T07:35:46.505+0000] {standard_task_runner.py:85} INFO - Job 342: Subtask main_task
[2023-12-09T07:35:46.533+0000] {task_command.py:416} INFO - Running <TaskInstance: my_scraping_dag.main_task scheduled__2023-12-05T00:00:00+00:00 [running]> on host 36b5ef2505c9
[2023-12-09T07:35:46.571+0000] {taskinstance.py:1662} INFO - Exporting env vars: AIRFLOW_CTX_DAG_OWNER='***' AIRFLOW_CTX_DAG_ID='my_scraping_dag' AIRFLOW_CTX_TASK_ID='main_task' AIRFLOW_CTX_EXECUTION_DATE='2023-12-05T00:00:00+00:00' AIRFLOW_CTX_TRY_NUMBER='1' AIRFLOW_CTX_DAG_RUN_ID='scheduled__2023-12-05T00:00:00+00:00'
[2023-12-09T07:35:46.577+0000] {taskinstance.py:1937} ERROR - Task failed with exception
Traceback (most recent call last):
  File "/home/airflow/.local/lib/python3.8/site-packages/airflow/operators/python.py", line 192, in execute
    return_value = self.execute_callable()
  File "/home/airflow/.local/lib/python3.8/site-packages/airflow/operators/python.py", line 209, in execute_callable
    return self.python_callable(*self.op_args, **self.op_kwargs)
  File "/opt/airflow/dags/main.py", line 66, in main
    'User-Agent': Variable.get('user_agent'),
  File "/home/airflow/.local/lib/python3.8/site-packages/airflow/models/variable.py", line 140, in get
    raise KeyError(f"Variable {key} does not exist")
KeyError: 'Variable user_agent does not exist'
[2023-12-09T07:35:46.581+0000] {taskinstance.py:1400} INFO - Marking task as FAILED. dag_id=my_scraping_dag, task_id=main_task, execution_date=20231205T000000, start_date=20231209T073546, end_date=20231209T073546
[2023-12-09T07:35:46.587+0000] {standard_task_runner.py:104} ERROR - Failed to execute job 342 for task main_task ('Variable user_agent does not exist'; 1299)
[2023-12-09T07:35:46.595+0000] {local_task_job_runner.py:228} INFO - Task exited with return code 1
[2023-12-09T07:35:46.621+0000] {taskinstance.py:2778} INFO - 0 downstream tasks scheduled from follow-on schedule check
