[2023-12-07T14:45:32.339+0000] {taskinstance.py:1159} INFO - Dependencies all met for dep_context=non-requeueable deps ti=<TaskInstance: my_scraping_dag.main_task scheduled__2023-01-24T00:00:00+00:00 [queued]>
[2023-12-07T14:45:32.344+0000] {taskinstance.py:1159} INFO - Dependencies all met for dep_context=requeueable deps ti=<TaskInstance: my_scraping_dag.main_task scheduled__2023-01-24T00:00:00+00:00 [queued]>
[2023-12-07T14:45:32.344+0000] {taskinstance.py:1361} INFO - Starting attempt 1 of 1
[2023-12-07T14:45:32.352+0000] {taskinstance.py:1382} INFO - Executing <Task(PythonOperator): main_task> on 2023-01-24 00:00:00+00:00
[2023-12-07T14:45:32.356+0000] {standard_task_runner.py:57} INFO - Started process 434 to run task
[2023-12-07T14:45:32.359+0000] {standard_task_runner.py:84} INFO - Running: ['***', 'tasks', 'run', 'my_scraping_dag', 'main_task', 'scheduled__2023-01-24T00:00:00+00:00', '--job-id', '35', '--raw', '--subdir', 'DAGS_FOLDER/main.py', '--cfg-path', '/tmp/tmpboa3ldkt']
[2023-12-07T14:45:32.361+0000] {standard_task_runner.py:85} INFO - Job 35: Subtask main_task
[2023-12-07T14:45:32.388+0000] {task_command.py:416} INFO - Running <TaskInstance: my_scraping_dag.main_task scheduled__2023-01-24T00:00:00+00:00 [running]> on host 63b0c7e341c0
[2023-12-07T14:45:32.422+0000] {taskinstance.py:1662} INFO - Exporting env vars: AIRFLOW_CTX_DAG_OWNER='***' AIRFLOW_CTX_DAG_ID='my_scraping_dag' AIRFLOW_CTX_TASK_ID='main_task' AIRFLOW_CTX_EXECUTION_DATE='2023-01-24T00:00:00+00:00' AIRFLOW_CTX_TRY_NUMBER='1' AIRFLOW_CTX_DAG_RUN_ID='scheduled__2023-01-24T00:00:00+00:00'
[2023-12-07T14:45:32.423+0000] {taskinstance.py:1937} ERROR - Task failed with exception
Traceback (most recent call last):
  File "/usr/local/lib/python3.8/configparser.py", line 846, in items
    d.update(self._sections[section])
KeyError: 'web'

During handling of the above exception, another exception occurred:

Traceback (most recent call last):
  File "/home/airflow/.local/lib/python3.8/site-packages/airflow/operators/python.py", line 192, in execute
    return_value = self.execute_callable()
  File "/home/airflow/.local/lib/python3.8/site-packages/airflow/operators/python.py", line 209, in execute_callable
    return self.python_callable(*self.op_args, **self.op_kwargs)
  File "/opt/airflow/dags/main.py", line 61, in main
    config = get_config('web')
  File "/opt/airflow/dags/main.py", line 23, in get_config
    return {key: value for key, value in parser.items(section)}
  File "/usr/local/lib/python3.8/configparser.py", line 849, in items
    raise NoSectionError(section)
configparser.NoSectionError: No section: 'web'
[2023-12-07T14:45:32.429+0000] {taskinstance.py:1400} INFO - Marking task as FAILED. dag_id=my_scraping_dag, task_id=main_task, execution_date=20230124T000000, start_date=20231207T144532, end_date=20231207T144532
[2023-12-07T14:45:32.435+0000] {standard_task_runner.py:104} ERROR - Failed to execute job 35 for task main_task (No section: 'web'; 434)
[2023-12-07T14:45:32.451+0000] {local_task_job_runner.py:228} INFO - Task exited with return code 1
[2023-12-07T14:45:32.463+0000] {taskinstance.py:2778} INFO - 0 downstream tasks scheduled from follow-on schedule check
[2023-12-07T14:51:25.254+0000] {taskinstance.py:1159} INFO - Dependencies all met for dep_context=non-requeueable deps ti=<TaskInstance: my_scraping_dag.main_task scheduled__2023-01-24T00:00:00+00:00 [queued]>
[2023-12-07T14:51:25.258+0000] {taskinstance.py:1159} INFO - Dependencies all met for dep_context=requeueable deps ti=<TaskInstance: my_scraping_dag.main_task scheduled__2023-01-24T00:00:00+00:00 [queued]>
[2023-12-07T14:51:25.259+0000] {taskinstance.py:1361} INFO - Starting attempt 1 of 1
[2023-12-07T14:51:25.279+0000] {taskinstance.py:1382} INFO - Executing <Task(PythonOperator): main_task> on 2023-01-24 00:00:00+00:00
[2023-12-07T14:51:25.282+0000] {standard_task_runner.py:57} INFO - Started process 779 to run task
[2023-12-07T14:51:25.289+0000] {standard_task_runner.py:84} INFO - Running: ['***', 'tasks', 'run', 'my_scraping_dag', 'main_task', 'scheduled__2023-01-24T00:00:00+00:00', '--job-id', '134', '--raw', '--subdir', 'DAGS_FOLDER/main.py', '--cfg-path', '/tmp/tmpru10f4s8']
[2023-12-07T14:51:25.291+0000] {standard_task_runner.py:85} INFO - Job 134: Subtask main_task
[2023-12-07T14:51:25.319+0000] {task_command.py:416} INFO - Running <TaskInstance: my_scraping_dag.main_task scheduled__2023-01-24T00:00:00+00:00 [running]> on host 63b0c7e341c0
[2023-12-07T14:51:25.352+0000] {taskinstance.py:1662} INFO - Exporting env vars: AIRFLOW_CTX_DAG_OWNER='***' AIRFLOW_CTX_DAG_ID='my_scraping_dag' AIRFLOW_CTX_TASK_ID='main_task' AIRFLOW_CTX_EXECUTION_DATE='2023-01-24T00:00:00+00:00' AIRFLOW_CTX_TRY_NUMBER='1' AIRFLOW_CTX_DAG_RUN_ID='scheduled__2023-01-24T00:00:00+00:00'
[2023-12-07T14:51:25.353+0000] {taskinstance.py:1937} ERROR - Task failed with exception
Traceback (most recent call last):
  File "/usr/local/lib/python3.8/configparser.py", line 846, in items
    d.update(self._sections[section])
KeyError: 'web'

During handling of the above exception, another exception occurred:

Traceback (most recent call last):
  File "/home/airflow/.local/lib/python3.8/site-packages/airflow/operators/python.py", line 192, in execute
    return_value = self.execute_callable()
  File "/home/airflow/.local/lib/python3.8/site-packages/airflow/operators/python.py", line 209, in execute_callable
    return self.python_callable(*self.op_args, **self.op_kwargs)
  File "/opt/airflow/dags/main.py", line 61, in main
    config = get_config('web')
  File "/opt/airflow/dags/main.py", line 23, in get_config
    return {key: value for key, value in parser.items(section)}
  File "/usr/local/lib/python3.8/configparser.py", line 849, in items
    raise NoSectionError(section)
configparser.NoSectionError: No section: 'web'
[2023-12-07T14:51:25.357+0000] {taskinstance.py:1400} INFO - Marking task as FAILED. dag_id=my_scraping_dag, task_id=main_task, execution_date=20230124T000000, start_date=20231207T145125, end_date=20231207T145125
[2023-12-07T14:51:25.363+0000] {standard_task_runner.py:104} ERROR - Failed to execute job 134 for task main_task (No section: 'web'; 779)
[2023-12-07T14:51:25.377+0000] {local_task_job_runner.py:228} INFO - Task exited with return code 1
[2023-12-07T14:51:25.429+0000] {taskinstance.py:2778} INFO - 0 downstream tasks scheduled from follow-on schedule check
[2023-12-07T14:59:52.882+0000] {taskinstance.py:1159} INFO - Dependencies all met for dep_context=non-requeueable deps ti=<TaskInstance: my_scraping_dag.main_task scheduled__2023-01-24T00:00:00+00:00 [queued]>
[2023-12-07T14:59:52.887+0000] {taskinstance.py:1159} INFO - Dependencies all met for dep_context=requeueable deps ti=<TaskInstance: my_scraping_dag.main_task scheduled__2023-01-24T00:00:00+00:00 [queued]>
[2023-12-07T14:59:52.887+0000] {taskinstance.py:1361} INFO - Starting attempt 1 of 1
[2023-12-07T14:59:52.911+0000] {taskinstance.py:1382} INFO - Executing <Task(PythonOperator): main_task> on 2023-01-24 00:00:00+00:00
[2023-12-07T14:59:52.914+0000] {standard_task_runner.py:57} INFO - Started process 1410 to run task
[2023-12-07T14:59:52.917+0000] {standard_task_runner.py:84} INFO - Running: ['***', 'tasks', 'run', 'my_scraping_dag', 'main_task', 'scheduled__2023-01-24T00:00:00+00:00', '--job-id', '338', '--raw', '--subdir', 'DAGS_FOLDER/main.py', '--cfg-path', '/tmp/tmpdreq7kcq']
[2023-12-07T14:59:52.919+0000] {standard_task_runner.py:85} INFO - Job 338: Subtask main_task
[2023-12-07T14:59:52.949+0000] {task_command.py:416} INFO - Running <TaskInstance: my_scraping_dag.main_task scheduled__2023-01-24T00:00:00+00:00 [running]> on host 63b0c7e341c0
[2023-12-07T14:59:52.991+0000] {taskinstance.py:1662} INFO - Exporting env vars: AIRFLOW_CTX_DAG_OWNER='***' AIRFLOW_CTX_DAG_ID='my_scraping_dag' AIRFLOW_CTX_TASK_ID='main_task' AIRFLOW_CTX_EXECUTION_DATE='2023-01-24T00:00:00+00:00' AIRFLOW_CTX_TRY_NUMBER='1' AIRFLOW_CTX_DAG_RUN_ID='scheduled__2023-01-24T00:00:00+00:00'
[2023-12-07T14:59:52.992+0000] {taskinstance.py:1937} ERROR - Task failed with exception
Traceback (most recent call last):
  File "/usr/local/lib/python3.8/configparser.py", line 846, in items
    d.update(self._sections[section])
KeyError: 'web'

During handling of the above exception, another exception occurred:

Traceback (most recent call last):
  File "/home/airflow/.local/lib/python3.8/site-packages/airflow/operators/python.py", line 192, in execute
    return_value = self.execute_callable()
  File "/home/airflow/.local/lib/python3.8/site-packages/airflow/operators/python.py", line 209, in execute_callable
    return self.python_callable(*self.op_args, **self.op_kwargs)
  File "/opt/airflow/dags/main.py", line 60, in main
    config = get_config('web')
  File "/opt/airflow/dags/main.py", line 22, in get_config
    return {key: value for key, value in parser.items(section)}
  File "/usr/local/lib/python3.8/configparser.py", line 849, in items
    raise NoSectionError(section)
configparser.NoSectionError: No section: 'web'
[2023-12-07T14:59:52.998+0000] {taskinstance.py:1400} INFO - Marking task as FAILED. dag_id=my_scraping_dag, task_id=main_task, execution_date=20230124T000000, start_date=20231207T145952, end_date=20231207T145952
[2023-12-07T14:59:53.005+0000] {standard_task_runner.py:104} ERROR - Failed to execute job 338 for task main_task (No section: 'web'; 1410)
[2023-12-07T14:59:53.050+0000] {local_task_job_runner.py:228} INFO - Task exited with return code 1
[2023-12-07T14:59:53.081+0000] {taskinstance.py:2778} INFO - 0 downstream tasks scheduled from follow-on schedule check
[2023-12-07T15:10:44.116+0000] {taskinstance.py:1159} INFO - Dependencies all met for dep_context=non-requeueable deps ti=<TaskInstance: my_scraping_dag.main_task scheduled__2023-01-24T00:00:00+00:00 [queued]>
[2023-12-07T15:10:44.120+0000] {taskinstance.py:1159} INFO - Dependencies all met for dep_context=requeueable deps ti=<TaskInstance: my_scraping_dag.main_task scheduled__2023-01-24T00:00:00+00:00 [queued]>
[2023-12-07T15:10:44.121+0000] {taskinstance.py:1361} INFO - Starting attempt 1 of 1
[2023-12-07T15:10:44.127+0000] {taskinstance.py:1382} INFO - Executing <Task(PythonOperator): main_task> on 2023-01-24 00:00:00+00:00
[2023-12-07T15:10:44.130+0000] {standard_task_runner.py:57} INFO - Started process 1891 to run task
[2023-12-07T15:10:44.132+0000] {standard_task_runner.py:84} INFO - Running: ['***', 'tasks', 'run', 'my_scraping_dag', 'main_task', 'scheduled__2023-01-24T00:00:00+00:00', '--job-id', '445', '--raw', '--subdir', 'DAGS_FOLDER/main.py', '--cfg-path', '/tmp/tmp2xjnt4vs']
[2023-12-07T15:10:44.134+0000] {standard_task_runner.py:85} INFO - Job 445: Subtask main_task
[2023-12-07T15:10:44.158+0000] {task_command.py:416} INFO - Running <TaskInstance: my_scraping_dag.main_task scheduled__2023-01-24T00:00:00+00:00 [running]> on host 63b0c7e341c0
[2023-12-07T15:10:44.188+0000] {taskinstance.py:1662} INFO - Exporting env vars: AIRFLOW_CTX_DAG_OWNER='***' AIRFLOW_CTX_DAG_ID='my_scraping_dag' AIRFLOW_CTX_TASK_ID='main_task' AIRFLOW_CTX_EXECUTION_DATE='2023-01-24T00:00:00+00:00' AIRFLOW_CTX_TRY_NUMBER='1' AIRFLOW_CTX_DAG_RUN_ID='scheduled__2023-01-24T00:00:00+00:00'
[2023-12-07T15:10:44.189+0000] {taskinstance.py:1937} ERROR - Task failed with exception
Traceback (most recent call last):
  File "/usr/local/lib/python3.8/configparser.py", line 846, in items
    d.update(self._sections[section])
KeyError: 'web'

During handling of the above exception, another exception occurred:

Traceback (most recent call last):
  File "/home/airflow/.local/lib/python3.8/site-packages/airflow/operators/python.py", line 192, in execute
    return_value = self.execute_callable()
  File "/home/airflow/.local/lib/python3.8/site-packages/airflow/operators/python.py", line 209, in execute_callable
    return self.python_callable(*self.op_args, **self.op_kwargs)
  File "/opt/airflow/dags/main.py", line 63, in main
    config = get_config('web')
  File "/opt/airflow/dags/main.py", line 14, in get_config
    return {key: value for key, value in parser.items(section)}
  File "/usr/local/lib/python3.8/configparser.py", line 849, in items
    raise NoSectionError(section)
configparser.NoSectionError: No section: 'web'
[2023-12-07T15:10:44.193+0000] {taskinstance.py:1400} INFO - Marking task as FAILED. dag_id=my_scraping_dag, task_id=main_task, execution_date=20230124T000000, start_date=20231207T151044, end_date=20231207T151044
[2023-12-07T15:10:44.198+0000] {standard_task_runner.py:104} ERROR - Failed to execute job 445 for task main_task (No section: 'web'; 1891)
[2023-12-07T15:10:44.224+0000] {local_task_job_runner.py:228} INFO - Task exited with return code 1
[2023-12-07T15:10:44.231+0000] {taskinstance.py:2778} INFO - 0 downstream tasks scheduled from follow-on schedule check
[2023-12-07T15:12:05.862+0000] {taskinstance.py:1159} INFO - Dependencies all met for dep_context=non-requeueable deps ti=<TaskInstance: my_scraping_dag.main_task scheduled__2023-01-24T00:00:00+00:00 [queued]>
[2023-12-07T15:12:05.867+0000] {taskinstance.py:1159} INFO - Dependencies all met for dep_context=requeueable deps ti=<TaskInstance: my_scraping_dag.main_task scheduled__2023-01-24T00:00:00+00:00 [queued]>
[2023-12-07T15:12:05.867+0000] {taskinstance.py:1361} INFO - Starting attempt 1 of 1
[2023-12-07T15:12:05.873+0000] {taskinstance.py:1382} INFO - Executing <Task(PythonOperator): main_task> on 2023-01-24 00:00:00+00:00
[2023-12-07T15:12:05.875+0000] {standard_task_runner.py:57} INFO - Started process 2110 to run task
[2023-12-07T15:12:05.877+0000] {standard_task_runner.py:84} INFO - Running: ['***', 'tasks', 'run', 'my_scraping_dag', 'main_task', 'scheduled__2023-01-24T00:00:00+00:00', '--job-id', '534', '--raw', '--subdir', 'DAGS_FOLDER/main.py', '--cfg-path', '/tmp/tmp6njp7w0p']
[2023-12-07T15:12:05.878+0000] {standard_task_runner.py:85} INFO - Job 534: Subtask main_task
[2023-12-07T15:12:05.902+0000] {task_command.py:416} INFO - Running <TaskInstance: my_scraping_dag.main_task scheduled__2023-01-24T00:00:00+00:00 [running]> on host 63b0c7e341c0
[2023-12-07T15:12:05.932+0000] {taskinstance.py:1662} INFO - Exporting env vars: AIRFLOW_CTX_DAG_OWNER='***' AIRFLOW_CTX_DAG_ID='my_scraping_dag' AIRFLOW_CTX_TASK_ID='main_task' AIRFLOW_CTX_EXECUTION_DATE='2023-01-24T00:00:00+00:00' AIRFLOW_CTX_TRY_NUMBER='1' AIRFLOW_CTX_DAG_RUN_ID='scheduled__2023-01-24T00:00:00+00:00'
[2023-12-07T15:12:05.933+0000] {taskinstance.py:1937} ERROR - Task failed with exception
Traceback (most recent call last):
  File "/usr/local/lib/python3.8/configparser.py", line 846, in items
    d.update(self._sections[section])
KeyError: 'web'

During handling of the above exception, another exception occurred:

Traceback (most recent call last):
  File "/home/airflow/.local/lib/python3.8/site-packages/airflow/operators/python.py", line 192, in execute
    return_value = self.execute_callable()
  File "/home/airflow/.local/lib/python3.8/site-packages/airflow/operators/python.py", line 209, in execute_callable
    return self.python_callable(*self.op_args, **self.op_kwargs)
  File "/opt/airflow/dags/main.py", line 63, in main
    config = get_config('web')
  File "/opt/airflow/dags/main.py", line 14, in get_config
    return {key: value for key, value in parser.items(section)}
  File "/usr/local/lib/python3.8/configparser.py", line 849, in items
    raise NoSectionError(section)
configparser.NoSectionError: No section: 'web'
[2023-12-07T15:12:05.937+0000] {taskinstance.py:1400} INFO - Marking task as FAILED. dag_id=my_scraping_dag, task_id=main_task, execution_date=20230124T000000, start_date=20231207T151205, end_date=20231207T151205
[2023-12-07T15:12:05.942+0000] {standard_task_runner.py:104} ERROR - Failed to execute job 534 for task main_task (No section: 'web'; 2110)
[2023-12-07T15:12:05.969+0000] {local_task_job_runner.py:228} INFO - Task exited with return code 1
[2023-12-07T15:12:05.976+0000] {taskinstance.py:2778} INFO - 0 downstream tasks scheduled from follow-on schedule check
[2023-12-07T16:30:54.226+0000] {taskinstance.py:1159} INFO - Dependencies all met for dep_context=non-requeueable deps ti=<TaskInstance: my_scraping_dag.main_task scheduled__2023-01-24T00:00:00+00:00 [queued]>
[2023-12-07T16:30:54.231+0000] {taskinstance.py:1159} INFO - Dependencies all met for dep_context=requeueable deps ti=<TaskInstance: my_scraping_dag.main_task scheduled__2023-01-24T00:00:00+00:00 [queued]>
[2023-12-07T16:30:54.232+0000] {taskinstance.py:1361} INFO - Starting attempt 1 of 1
[2023-12-07T16:30:54.245+0000] {taskinstance.py:1382} INFO - Executing <Task(PythonOperator): main_task> on 2023-01-24 00:00:00+00:00
[2023-12-07T16:30:54.251+0000] {standard_task_runner.py:57} INFO - Started process 3545 to run task
[2023-12-07T16:30:54.256+0000] {standard_task_runner.py:84} INFO - Running: ['***', 'tasks', 'run', 'my_scraping_dag', 'main_task', 'scheduled__2023-01-24T00:00:00+00:00', '--job-id', '612', '--raw', '--subdir', 'DAGS_FOLDER/main.py', '--cfg-path', '/tmp/tmppgv__t6i']
[2023-12-07T16:30:54.258+0000] {standard_task_runner.py:85} INFO - Job 612: Subtask main_task
[2023-12-07T16:30:54.294+0000] {task_command.py:416} INFO - Running <TaskInstance: my_scraping_dag.main_task scheduled__2023-01-24T00:00:00+00:00 [running]> on host 63b0c7e341c0
[2023-12-07T16:30:54.350+0000] {taskinstance.py:1662} INFO - Exporting env vars: AIRFLOW_CTX_DAG_OWNER='***' AIRFLOW_CTX_DAG_ID='my_scraping_dag' AIRFLOW_CTX_TASK_ID='main_task' AIRFLOW_CTX_EXECUTION_DATE='2023-01-24T00:00:00+00:00' AIRFLOW_CTX_TRY_NUMBER='1' AIRFLOW_CTX_DAG_RUN_ID='scheduled__2023-01-24T00:00:00+00:00'
[2023-12-07T16:30:54.351+0000] {taskinstance.py:1937} ERROR - Task failed with exception
Traceback (most recent call last):
  File "/usr/local/lib/python3.8/configparser.py", line 846, in items
    d.update(self._sections[section])
KeyError: 'web'

During handling of the above exception, another exception occurred:

Traceback (most recent call last):
  File "/home/airflow/.local/lib/python3.8/site-packages/airflow/operators/python.py", line 192, in execute
    return_value = self.execute_callable()
  File "/home/airflow/.local/lib/python3.8/site-packages/airflow/operators/python.py", line 209, in execute_callable
    return self.python_callable(*self.op_args, **self.op_kwargs)
  File "/opt/airflow/dags/main.py", line 60, in main
    config = get_config('web')
  File "/opt/airflow/dags/main.py", line 22, in get_config
    return {key: value for key, value in parser.items(section)}
  File "/usr/local/lib/python3.8/configparser.py", line 849, in items
    raise NoSectionError(section)
configparser.NoSectionError: No section: 'web'
[2023-12-07T16:30:54.356+0000] {taskinstance.py:1400} INFO - Marking task as FAILED. dag_id=my_scraping_dag, task_id=main_task, execution_date=20230124T000000, start_date=20231207T163054, end_date=20231207T163054
[2023-12-07T16:30:54.361+0000] {standard_task_runner.py:104} ERROR - Failed to execute job 612 for task main_task (No section: 'web'; 3545)
[2023-12-07T16:30:54.390+0000] {local_task_job_runner.py:228} INFO - Task exited with return code 1
[2023-12-07T16:30:54.403+0000] {taskinstance.py:2778} INFO - 0 downstream tasks scheduled from follow-on schedule check
[2023-12-07T16:40:51.275+0000] {taskinstance.py:1159} INFO - Dependencies all met for dep_context=non-requeueable deps ti=<TaskInstance: my_scraping_dag.main_task scheduled__2023-01-24T00:00:00+00:00 [queued]>
[2023-12-07T16:40:51.280+0000] {taskinstance.py:1159} INFO - Dependencies all met for dep_context=requeueable deps ti=<TaskInstance: my_scraping_dag.main_task scheduled__2023-01-24T00:00:00+00:00 [queued]>
[2023-12-07T16:40:51.281+0000] {taskinstance.py:1361} INFO - Starting attempt 1 of 1
[2023-12-07T16:40:51.297+0000] {taskinstance.py:1382} INFO - Executing <Task(PythonOperator): main_task> on 2023-01-24 00:00:00+00:00
[2023-12-07T16:40:51.301+0000] {standard_task_runner.py:57} INFO - Started process 4475 to run task
[2023-12-07T16:40:51.304+0000] {standard_task_runner.py:84} INFO - Running: ['***', 'tasks', 'run', 'my_scraping_dag', 'main_task', 'scheduled__2023-01-24T00:00:00+00:00', '--job-id', '954', '--raw', '--subdir', 'DAGS_FOLDER/main.py', '--cfg-path', '/tmp/tmppxwrjx20']
[2023-12-07T16:40:51.307+0000] {standard_task_runner.py:85} INFO - Job 954: Subtask main_task
[2023-12-07T16:40:51.337+0000] {task_command.py:416} INFO - Running <TaskInstance: my_scraping_dag.main_task scheduled__2023-01-24T00:00:00+00:00 [running]> on host 63b0c7e341c0
[2023-12-07T16:40:51.383+0000] {taskinstance.py:1662} INFO - Exporting env vars: AIRFLOW_CTX_DAG_OWNER='***' AIRFLOW_CTX_DAG_ID='my_scraping_dag' AIRFLOW_CTX_TASK_ID='main_task' AIRFLOW_CTX_EXECUTION_DATE='2023-01-24T00:00:00+00:00' AIRFLOW_CTX_TRY_NUMBER='1' AIRFLOW_CTX_DAG_RUN_ID='scheduled__2023-01-24T00:00:00+00:00'
[2023-12-07T16:40:51.384+0000] {taskinstance.py:1937} ERROR - Task failed with exception
Traceback (most recent call last):
  File "/usr/local/lib/python3.8/configparser.py", line 846, in items
    d.update(self._sections[section])
KeyError: 'web'

During handling of the above exception, another exception occurred:

Traceback (most recent call last):
  File "/home/airflow/.local/lib/python3.8/site-packages/airflow/operators/python.py", line 192, in execute
    return_value = self.execute_callable()
  File "/home/airflow/.local/lib/python3.8/site-packages/airflow/operators/python.py", line 209, in execute_callable
    return self.python_callable(*self.op_args, **self.op_kwargs)
  File "/opt/airflow/dags/main.py", line 60, in main
    config = get_config('web')
  File "/opt/airflow/dags/main.py", line 22, in get_config
    return {key: value for key, value in parser.items(section)}
  File "/usr/local/lib/python3.8/configparser.py", line 849, in items
    raise NoSectionError(section)
configparser.NoSectionError: No section: 'web'
[2023-12-07T16:40:51.390+0000] {taskinstance.py:1400} INFO - Marking task as FAILED. dag_id=my_scraping_dag, task_id=main_task, execution_date=20230124T000000, start_date=20231207T164051, end_date=20231207T164051
[2023-12-07T16:40:51.399+0000] {standard_task_runner.py:104} ERROR - Failed to execute job 954 for task main_task (No section: 'web'; 4475)
[2023-12-07T16:40:51.438+0000] {local_task_job_runner.py:228} INFO - Task exited with return code 1
[2023-12-07T16:40:51.454+0000] {taskinstance.py:2778} INFO - 0 downstream tasks scheduled from follow-on schedule check
[2023-12-07T16:59:56.478+0000] {taskinstance.py:1159} INFO - Dependencies all met for dep_context=non-requeueable deps ti=<TaskInstance: my_scraping_dag.main_task scheduled__2023-01-24T00:00:00+00:00 [queued]>
[2023-12-07T16:59:56.482+0000] {taskinstance.py:1159} INFO - Dependencies all met for dep_context=requeueable deps ti=<TaskInstance: my_scraping_dag.main_task scheduled__2023-01-24T00:00:00+00:00 [queued]>
[2023-12-07T16:59:56.483+0000] {taskinstance.py:1361} INFO - Starting attempt 1 of 1
[2023-12-07T16:59:56.491+0000] {taskinstance.py:1382} INFO - Executing <Task(PythonOperator): main_task> on 2023-01-24 00:00:00+00:00
[2023-12-07T16:59:56.494+0000] {standard_task_runner.py:57} INFO - Started process 5627 to run task
[2023-12-07T16:59:56.499+0000] {standard_task_runner.py:84} INFO - Running: ['***', 'tasks', 'run', 'my_scraping_dag', 'main_task', 'scheduled__2023-01-24T00:00:00+00:00', '--job-id', '1298', '--raw', '--subdir', 'DAGS_FOLDER/main.py', '--cfg-path', '/tmp/tmpfe5mkqpy']
[2023-12-07T16:59:56.501+0000] {standard_task_runner.py:85} INFO - Job 1298: Subtask main_task
[2023-12-07T16:59:56.533+0000] {task_command.py:416} INFO - Running <TaskInstance: my_scraping_dag.main_task scheduled__2023-01-24T00:00:00+00:00 [running]> on host 63b0c7e341c0
[2023-12-07T16:59:56.580+0000] {taskinstance.py:1662} INFO - Exporting env vars: AIRFLOW_CTX_DAG_OWNER='***' AIRFLOW_CTX_DAG_ID='my_scraping_dag' AIRFLOW_CTX_TASK_ID='main_task' AIRFLOW_CTX_EXECUTION_DATE='2023-01-24T00:00:00+00:00' AIRFLOW_CTX_TRY_NUMBER='1' AIRFLOW_CTX_DAG_RUN_ID='scheduled__2023-01-24T00:00:00+00:00'
[2023-12-07T16:59:56.616+0000] {taskinstance.py:1937} ERROR - Task failed with exception
Traceback (most recent call last):
  File "/home/airflow/.local/lib/python3.8/site-packages/airflow/operators/python.py", line 192, in execute
    return_value = self.execute_callable()
  File "/home/airflow/.local/lib/python3.8/site-packages/airflow/operators/python.py", line 209, in execute_callable
    return self.python_callable(*self.op_args, **self.op_kwargs)
  File "/opt/airflow/dags/main.py", line 33, in main
    'host': get_config('localhost'),
  File "/opt/airflow/dags/main.py", line 20, in get_config
    return Variable.get(key)
  File "/home/airflow/.local/lib/python3.8/site-packages/airflow/models/variable.py", line 140, in get
    raise KeyError(f"Variable {key} does not exist")
KeyError: 'Variable localhost does not exist'
[2023-12-07T16:59:56.622+0000] {taskinstance.py:1400} INFO - Marking task as FAILED. dag_id=my_scraping_dag, task_id=main_task, execution_date=20230124T000000, start_date=20231207T165956, end_date=20231207T165956
[2023-12-07T16:59:56.634+0000] {standard_task_runner.py:104} ERROR - Failed to execute job 1298 for task main_task ('Variable localhost does not exist'; 5627)
[2023-12-07T16:59:56.671+0000] {local_task_job_runner.py:228} INFO - Task exited with return code 1
[2023-12-07T16:59:56.701+0000] {taskinstance.py:2778} INFO - 0 downstream tasks scheduled from follow-on schedule check
[2023-12-07T17:03:19.369+0000] {taskinstance.py:1159} INFO - Dependencies all met for dep_context=non-requeueable deps ti=<TaskInstance: my_scraping_dag.main_task scheduled__2023-01-24T00:00:00+00:00 [queued]>
[2023-12-07T17:03:19.377+0000] {taskinstance.py:1159} INFO - Dependencies all met for dep_context=requeueable deps ti=<TaskInstance: my_scraping_dag.main_task scheduled__2023-01-24T00:00:00+00:00 [queued]>
[2023-12-07T17:03:19.377+0000] {taskinstance.py:1361} INFO - Starting attempt 1 of 1
[2023-12-07T17:03:19.384+0000] {taskinstance.py:1382} INFO - Executing <Task(PythonOperator): main_task> on 2023-01-24 00:00:00+00:00
[2023-12-07T17:03:19.388+0000] {standard_task_runner.py:57} INFO - Started process 6884 to run task
[2023-12-07T17:03:19.391+0000] {standard_task_runner.py:84} INFO - Running: ['***', 'tasks', 'run', 'my_scraping_dag', 'main_task', 'scheduled__2023-01-24T00:00:00+00:00', '--job-id', '1884', '--raw', '--subdir', 'DAGS_FOLDER/main.py', '--cfg-path', '/tmp/tmp6coxbly4']
[2023-12-07T17:03:19.394+0000] {standard_task_runner.py:85} INFO - Job 1884: Subtask main_task
[2023-12-07T17:03:19.429+0000] {task_command.py:416} INFO - Running <TaskInstance: my_scraping_dag.main_task scheduled__2023-01-24T00:00:00+00:00 [running]> on host 63b0c7e341c0
[2023-12-07T17:03:19.490+0000] {taskinstance.py:1662} INFO - Exporting env vars: AIRFLOW_CTX_DAG_OWNER='***' AIRFLOW_CTX_DAG_ID='my_scraping_dag' AIRFLOW_CTX_TASK_ID='main_task' AIRFLOW_CTX_EXECUTION_DATE='2023-01-24T00:00:00+00:00' AIRFLOW_CTX_TRY_NUMBER='1' AIRFLOW_CTX_DAG_RUN_ID='scheduled__2023-01-24T00:00:00+00:00'
[2023-12-07T17:03:19.529+0000] {logging_mixin.py:154} INFO - base_url: https://tuncbotanik.com
[2023-12-07T17:03:19.530+0000] {python.py:194} INFO - Done. Returned value was: ('https://tuncbotanik.com', {'User-Agent': 'Mozilla/5.0 (Macintosh; Intel Mac OS X 10_15_7) AppleWebKit/537.36 (KHTML, like Gecko) Chrome/119.0.0.0 Safari/537.36', 'Accept-Language': 'tr-TR,tr;q=0.9,en-US;q=0.8,en;q=0.7'}, {'dbname': 'plant', 'user': 'aozgokme', 'password': '***', 'host': 'localhost', 'port': '5432'})
[2023-12-07T17:03:19.547+0000] {taskinstance.py:1400} INFO - Marking task as SUCCESS. dag_id=my_scraping_dag, task_id=main_task, execution_date=20230124T000000, start_date=20231207T170319, end_date=20231207T170319
[2023-12-07T17:03:19.567+0000] {local_task_job_runner.py:228} INFO - Task exited with return code 0
[2023-12-07T17:03:19.591+0000] {taskinstance.py:2778} INFO - 1 downstream tasks scheduled from follow-on schedule check
[2023-12-07T17:18:22.501+0000] {taskinstance.py:1159} INFO - Dependencies all met for dep_context=non-requeueable deps ti=<TaskInstance: my_scraping_dag.main_task scheduled__2023-01-24T00:00:00+00:00 [queued]>
[2023-12-07T17:18:22.506+0000] {taskinstance.py:1159} INFO - Dependencies all met for dep_context=requeueable deps ti=<TaskInstance: my_scraping_dag.main_task scheduled__2023-01-24T00:00:00+00:00 [queued]>
[2023-12-07T17:18:22.506+0000] {taskinstance.py:1361} INFO - Starting attempt 1 of 1
[2023-12-07T17:18:22.529+0000] {taskinstance.py:1382} INFO - Executing <Task(PythonOperator): main_task> on 2023-01-24 00:00:00+00:00
[2023-12-07T17:18:22.533+0000] {standard_task_runner.py:57} INFO - Started process 8590 to run task
[2023-12-07T17:18:22.536+0000] {standard_task_runner.py:84} INFO - Running: ['***', 'tasks', 'run', 'my_scraping_dag', 'main_task', 'scheduled__2023-01-24T00:00:00+00:00', '--job-id', '2553', '--raw', '--subdir', 'DAGS_FOLDER/main.py', '--cfg-path', '/tmp/tmprxgzf4zg']
[2023-12-07T17:18:22.538+0000] {standard_task_runner.py:85} INFO - Job 2553: Subtask main_task
[2023-12-07T17:18:22.575+0000] {task_command.py:416} INFO - Running <TaskInstance: my_scraping_dag.main_task scheduled__2023-01-24T00:00:00+00:00 [running]> on host 63b0c7e341c0
[2023-12-07T17:18:22.634+0000] {taskinstance.py:1662} INFO - Exporting env vars: AIRFLOW_CTX_DAG_OWNER='***' AIRFLOW_CTX_DAG_ID='my_scraping_dag' AIRFLOW_CTX_TASK_ID='main_task' AIRFLOW_CTX_EXECUTION_DATE='2023-01-24T00:00:00+00:00' AIRFLOW_CTX_TRY_NUMBER='1' AIRFLOW_CTX_DAG_RUN_ID='scheduled__2023-01-24T00:00:00+00:00'
[2023-12-07T17:18:23.697+0000] {taskinstance.py:1937} ERROR - Task failed with exception
Traceback (most recent call last):
  File "/home/airflow/.local/lib/python3.8/site-packages/airflow/operators/python.py", line 192, in execute
    return_value = self.execute_callable()
  File "/home/airflow/.local/lib/python3.8/site-packages/airflow/operators/python.py", line 209, in execute_callable
    return self.python_callable(*self.op_args, **self.op_kwargs)
  File "/opt/airflow/dags/main.py", line 80, in main
    insert_data_to_db(products, db_params)
  File "/opt/airflow/dags/main.py", line 43, in insert_data_to_db
    with psycopg2.connect(**db_params) as conn:
  File "/home/airflow/.local/lib/python3.8/site-packages/psycopg2/__init__.py", line 122, in connect
    conn = _connect(dsn, connection_factory=connection_factory, **kwasync)
psycopg2.OperationalError: connection to server at "localhost" (127.0.0.1), port 5432 failed: Connection refused
	Is the server running on that host and accepting TCP/IP connections?
connection to server at "localhost" (::1), port 5432 failed: Cannot assign requested address
	Is the server running on that host and accepting TCP/IP connections?

[2023-12-07T17:18:23.702+0000] {taskinstance.py:1400} INFO - Marking task as FAILED. dag_id=my_scraping_dag, task_id=main_task, execution_date=20230124T000000, start_date=20231207T171822, end_date=20231207T171823
[2023-12-07T17:18:23.708+0000] {standard_task_runner.py:104} ERROR - Failed to execute job 2553 for task main_task (connection to server at "localhost" (127.0.0.1), port 5432 failed: Connection refused
	Is the server running on that host and accepting TCP/IP connections?
connection to server at "localhost" (::1), port 5432 failed: Cannot assign requested address
	Is the server running on that host and accepting TCP/IP connections?
; 8590)
[2023-12-07T17:18:23.726+0000] {local_task_job_runner.py:228} INFO - Task exited with return code 1
[2023-12-07T17:18:23.735+0000] {taskinstance.py:2778} INFO - 0 downstream tasks scheduled from follow-on schedule check
[2023-12-07T17:22:41.331+0000] {taskinstance.py:1159} INFO - Dependencies all met for dep_context=non-requeueable deps ti=<TaskInstance: my_scraping_dag.main_task scheduled__2023-01-24T00:00:00+00:00 [queued]>
[2023-12-07T17:22:41.336+0000] {taskinstance.py:1159} INFO - Dependencies all met for dep_context=requeueable deps ti=<TaskInstance: my_scraping_dag.main_task scheduled__2023-01-24T00:00:00+00:00 [queued]>
[2023-12-07T17:22:41.336+0000] {taskinstance.py:1361} INFO - Starting attempt 1 of 1
[2023-12-07T17:22:41.373+0000] {taskinstance.py:1382} INFO - Executing <Task(PythonOperator): main_task> on 2023-01-24 00:00:00+00:00
[2023-12-07T17:22:41.376+0000] {standard_task_runner.py:57} INFO - Started process 9384 to run task
[2023-12-07T17:22:41.378+0000] {standard_task_runner.py:84} INFO - Running: ['***', 'tasks', 'run', 'my_scraping_dag', 'main_task', 'scheduled__2023-01-24T00:00:00+00:00', '--job-id', '2895', '--raw', '--subdir', 'DAGS_FOLDER/main.py', '--cfg-path', '/tmp/tmpvvqsgk1o']
[2023-12-07T17:22:41.381+0000] {standard_task_runner.py:85} INFO - Job 2895: Subtask main_task
[2023-12-07T17:22:41.412+0000] {task_command.py:416} INFO - Running <TaskInstance: my_scraping_dag.main_task scheduled__2023-01-24T00:00:00+00:00 [running]> on host 63b0c7e341c0
[2023-12-07T17:22:41.452+0000] {taskinstance.py:1662} INFO - Exporting env vars: AIRFLOW_CTX_DAG_OWNER='***' AIRFLOW_CTX_DAG_ID='my_scraping_dag' AIRFLOW_CTX_TASK_ID='main_task' AIRFLOW_CTX_EXECUTION_DATE='2023-01-24T00:00:00+00:00' AIRFLOW_CTX_TRY_NUMBER='1' AIRFLOW_CTX_DAG_RUN_ID='scheduled__2023-01-24T00:00:00+00:00'
[2023-12-07T17:22:42.177+0000] {taskinstance.py:1937} ERROR - Task failed with exception
Traceback (most recent call last):
  File "/home/airflow/.local/lib/python3.8/site-packages/airflow/operators/python.py", line 192, in execute
    return_value = self.execute_callable()
  File "/home/airflow/.local/lib/python3.8/site-packages/airflow/operators/python.py", line 209, in execute_callable
    return self.python_callable(*self.op_args, **self.op_kwargs)
  File "/opt/airflow/dags/main.py", line 73, in main
    insert_data_to_db(products, db_params)
  File "/opt/airflow/dags/main.py", line 40, in insert_data_to_db
    with psycopg2.connect(**db_params) as conn:
  File "/home/airflow/.local/lib/python3.8/site-packages/psycopg2/__init__.py", line 122, in connect
    conn = _connect(dsn, connection_factory=connection_factory, **kwasync)
psycopg2.OperationalError: connection to server at "localhost" (127.0.0.1), port 5432 failed: Connection refused
	Is the server running on that host and accepting TCP/IP connections?
connection to server at "localhost" (::1), port 5432 failed: Cannot assign requested address
	Is the server running on that host and accepting TCP/IP connections?

[2023-12-07T17:22:42.182+0000] {taskinstance.py:1400} INFO - Marking task as FAILED. dag_id=my_scraping_dag, task_id=main_task, execution_date=20230124T000000, start_date=20231207T172241, end_date=20231207T172242
[2023-12-07T17:22:42.187+0000] {standard_task_runner.py:104} ERROR - Failed to execute job 2895 for task main_task (connection to server at "localhost" (127.0.0.1), port 5432 failed: Connection refused
	Is the server running on that host and accepting TCP/IP connections?
connection to server at "localhost" (::1), port 5432 failed: Cannot assign requested address
	Is the server running on that host and accepting TCP/IP connections?
; 9384)
[2023-12-07T17:22:42.194+0000] {local_task_job_runner.py:228} INFO - Task exited with return code 1
[2023-12-07T17:22:42.204+0000] {taskinstance.py:2778} INFO - 0 downstream tasks scheduled from follow-on schedule check
[2023-12-07T17:28:21.997+0000] {taskinstance.py:1159} INFO - Dependencies all met for dep_context=non-requeueable deps ti=<TaskInstance: my_scraping_dag.main_task scheduled__2023-01-24T00:00:00+00:00 [queued]>
[2023-12-07T17:28:22.002+0000] {taskinstance.py:1159} INFO - Dependencies all met for dep_context=requeueable deps ti=<TaskInstance: my_scraping_dag.main_task scheduled__2023-01-24T00:00:00+00:00 [queued]>
[2023-12-07T17:28:22.002+0000] {taskinstance.py:1361} INFO - Starting attempt 1 of 1
[2023-12-07T17:28:22.034+0000] {taskinstance.py:1382} INFO - Executing <Task(PythonOperator): main_task> on 2023-01-24 00:00:00+00:00
[2023-12-07T17:28:22.037+0000] {standard_task_runner.py:57} INFO - Started process 10220 to run task
[2023-12-07T17:28:22.039+0000] {standard_task_runner.py:84} INFO - Running: ['***', 'tasks', 'run', 'my_scraping_dag', 'main_task', 'scheduled__2023-01-24T00:00:00+00:00', '--job-id', '3237', '--raw', '--subdir', 'DAGS_FOLDER/main.py', '--cfg-path', '/tmp/tmpfki4qh79']
[2023-12-07T17:28:22.041+0000] {standard_task_runner.py:85} INFO - Job 3237: Subtask main_task
[2023-12-07T17:28:22.077+0000] {task_command.py:416} INFO - Running <TaskInstance: my_scraping_dag.main_task scheduled__2023-01-24T00:00:00+00:00 [running]> on host 63b0c7e341c0
[2023-12-07T17:28:22.135+0000] {taskinstance.py:1662} INFO - Exporting env vars: AIRFLOW_CTX_DAG_OWNER='***' AIRFLOW_CTX_DAG_ID='my_scraping_dag' AIRFLOW_CTX_TASK_ID='main_task' AIRFLOW_CTX_EXECUTION_DATE='2023-01-24T00:00:00+00:00' AIRFLOW_CTX_TRY_NUMBER='1' AIRFLOW_CTX_DAG_RUN_ID='scheduled__2023-01-24T00:00:00+00:00'
[2023-12-07T17:28:22.826+0000] {taskinstance.py:1937} ERROR - Task failed with exception
Traceback (most recent call last):
  File "/home/airflow/.local/lib/python3.8/site-packages/airflow/operators/python.py", line 192, in execute
    return_value = self.execute_callable()
  File "/home/airflow/.local/lib/python3.8/site-packages/airflow/operators/python.py", line 209, in execute_callable
    return self.python_callable(*self.op_args, **self.op_kwargs)
  File "/opt/airflow/dags/main.py", line 73, in main
    insert_data_to_db(products, db_params)
  File "/opt/airflow/dags/main.py", line 40, in insert_data_to_db
    with psycopg2.connect(**db_params) as conn:
  File "/home/airflow/.local/lib/python3.8/site-packages/psycopg2/__init__.py", line 122, in connect
    conn = _connect(dsn, connection_factory=connection_factory, **kwasync)
psycopg2.OperationalError: connection to server at "localhost" (127.0.0.1), port 5432 failed: Connection refused
	Is the server running on that host and accepting TCP/IP connections?
connection to server at "localhost" (::1), port 5432 failed: Cannot assign requested address
	Is the server running on that host and accepting TCP/IP connections?

[2023-12-07T17:28:22.831+0000] {taskinstance.py:1400} INFO - Marking task as FAILED. dag_id=my_scraping_dag, task_id=main_task, execution_date=20230124T000000, start_date=20231207T172821, end_date=20231207T172822
[2023-12-07T17:28:22.837+0000] {standard_task_runner.py:104} ERROR - Failed to execute job 3237 for task main_task (connection to server at "localhost" (127.0.0.1), port 5432 failed: Connection refused
	Is the server running on that host and accepting TCP/IP connections?
connection to server at "localhost" (::1), port 5432 failed: Cannot assign requested address
	Is the server running on that host and accepting TCP/IP connections?
; 10220)
[2023-12-07T17:28:22.853+0000] {local_task_job_runner.py:228} INFO - Task exited with return code 1
[2023-12-07T17:28:22.866+0000] {taskinstance.py:2778} INFO - 0 downstream tasks scheduled from follow-on schedule check
