[2023-12-07T16:33:43.168+0000] {taskinstance.py:1159} INFO - Dependencies all met for dep_context=non-requeueable deps ti=<TaskInstance: my_scraping_dag.main_task scheduled__2023-08-28T00:00:00+00:00 [queued]>
[2023-12-07T16:33:43.172+0000] {taskinstance.py:1159} INFO - Dependencies all met for dep_context=requeueable deps ti=<TaskInstance: my_scraping_dag.main_task scheduled__2023-08-28T00:00:00+00:00 [queued]>
[2023-12-07T16:33:43.172+0000] {taskinstance.py:1361} INFO - Starting attempt 1 of 1
[2023-12-07T16:33:43.177+0000] {taskinstance.py:1382} INFO - Executing <Task(PythonOperator): main_task> on 2023-08-28 00:00:00+00:00
[2023-12-07T16:33:43.180+0000] {standard_task_runner.py:57} INFO - Started process 4047 to run task
[2023-12-07T16:33:43.182+0000] {standard_task_runner.py:84} INFO - Running: ['***', 'tasks', 'run', 'my_scraping_dag', 'main_task', 'scheduled__2023-08-28T00:00:00+00:00', '--job-id', '828', '--raw', '--subdir', 'DAGS_FOLDER/main.py', '--cfg-path', '/tmp/tmp5509ot5w']
[2023-12-07T16:33:43.183+0000] {standard_task_runner.py:85} INFO - Job 828: Subtask main_task
[2023-12-07T16:33:43.205+0000] {task_command.py:416} INFO - Running <TaskInstance: my_scraping_dag.main_task scheduled__2023-08-28T00:00:00+00:00 [running]> on host 63b0c7e341c0
[2023-12-07T16:33:43.234+0000] {taskinstance.py:1662} INFO - Exporting env vars: AIRFLOW_CTX_DAG_OWNER='***' AIRFLOW_CTX_DAG_ID='my_scraping_dag' AIRFLOW_CTX_TASK_ID='main_task' AIRFLOW_CTX_EXECUTION_DATE='2023-08-28T00:00:00+00:00' AIRFLOW_CTX_TRY_NUMBER='1' AIRFLOW_CTX_DAG_RUN_ID='scheduled__2023-08-28T00:00:00+00:00'
[2023-12-07T16:33:43.234+0000] {taskinstance.py:1937} ERROR - Task failed with exception
Traceback (most recent call last):
  File "/usr/local/lib/python3.8/configparser.py", line 846, in items
    d.update(self._sections[section])
KeyError: 'web'

During handling of the above exception, another exception occurred:

Traceback (most recent call last):
  File "/home/airflow/.local/lib/python3.8/site-packages/airflow/operators/python.py", line 192, in execute
    return_value = self.execute_callable()
  File "/home/airflow/.local/lib/python3.8/site-packages/airflow/operators/python.py", line 209, in execute_callable
    return self.python_callable(*self.op_args, **self.op_kwargs)
  File "/opt/airflow/dags/main.py", line 60, in main
    config = get_config('web')
  File "/opt/airflow/dags/main.py", line 22, in get_config
    return {key: value for key, value in parser.items(section)}
  File "/usr/local/lib/python3.8/configparser.py", line 849, in items
    raise NoSectionError(section)
configparser.NoSectionError: No section: 'web'
[2023-12-07T16:33:43.238+0000] {taskinstance.py:1400} INFO - Marking task as FAILED. dag_id=my_scraping_dag, task_id=main_task, execution_date=20230828T000000, start_date=20231207T163343, end_date=20231207T163343
[2023-12-07T16:33:43.242+0000] {standard_task_runner.py:104} ERROR - Failed to execute job 828 for task main_task (No section: 'web'; 4047)
[2023-12-07T16:33:43.276+0000] {local_task_job_runner.py:228} INFO - Task exited with return code 1
[2023-12-07T16:33:43.289+0000] {taskinstance.py:2778} INFO - 0 downstream tasks scheduled from follow-on schedule check
[2023-12-07T16:42:27.542+0000] {taskinstance.py:1159} INFO - Dependencies all met for dep_context=non-requeueable deps ti=<TaskInstance: my_scraping_dag.main_task scheduled__2023-08-28T00:00:00+00:00 [queued]>
[2023-12-07T16:42:27.546+0000] {taskinstance.py:1159} INFO - Dependencies all met for dep_context=requeueable deps ti=<TaskInstance: my_scraping_dag.main_task scheduled__2023-08-28T00:00:00+00:00 [queued]>
[2023-12-07T16:42:27.547+0000] {taskinstance.py:1361} INFO - Starting attempt 1 of 1
[2023-12-07T16:42:27.554+0000] {taskinstance.py:1382} INFO - Executing <Task(PythonOperator): main_task> on 2023-08-28 00:00:00+00:00
[2023-12-07T16:42:27.557+0000] {standard_task_runner.py:57} INFO - Started process 4949 to run task
[2023-12-07T16:42:27.559+0000] {standard_task_runner.py:84} INFO - Running: ['***', 'tasks', 'run', 'my_scraping_dag', 'main_task', 'scheduled__2023-08-28T00:00:00+00:00', '--job-id', '1173', '--raw', '--subdir', 'DAGS_FOLDER/main.py', '--cfg-path', '/tmp/tmp7ncb5o4y']
[2023-12-07T16:42:27.561+0000] {standard_task_runner.py:85} INFO - Job 1173: Subtask main_task
[2023-12-07T16:42:27.587+0000] {task_command.py:416} INFO - Running <TaskInstance: my_scraping_dag.main_task scheduled__2023-08-28T00:00:00+00:00 [running]> on host 63b0c7e341c0
[2023-12-07T16:42:27.620+0000] {taskinstance.py:1662} INFO - Exporting env vars: AIRFLOW_CTX_DAG_OWNER='***' AIRFLOW_CTX_DAG_ID='my_scraping_dag' AIRFLOW_CTX_TASK_ID='main_task' AIRFLOW_CTX_EXECUTION_DATE='2023-08-28T00:00:00+00:00' AIRFLOW_CTX_TRY_NUMBER='1' AIRFLOW_CTX_DAG_RUN_ID='scheduled__2023-08-28T00:00:00+00:00'
[2023-12-07T16:42:27.621+0000] {taskinstance.py:1937} ERROR - Task failed with exception
Traceback (most recent call last):
  File "/usr/local/lib/python3.8/configparser.py", line 846, in items
    d.update(self._sections[section])
KeyError: 'web'

During handling of the above exception, another exception occurred:

Traceback (most recent call last):
  File "/home/airflow/.local/lib/python3.8/site-packages/airflow/operators/python.py", line 192, in execute
    return_value = self.execute_callable()
  File "/home/airflow/.local/lib/python3.8/site-packages/airflow/operators/python.py", line 209, in execute_callable
    return self.python_callable(*self.op_args, **self.op_kwargs)
  File "/opt/airflow/dags/main.py", line 60, in main
    config = get_config('web')
  File "/opt/airflow/dags/main.py", line 22, in get_config
    return {key: value for key, value in parser.items(section)}
  File "/usr/local/lib/python3.8/configparser.py", line 849, in items
    raise NoSectionError(section)
configparser.NoSectionError: No section: 'web'
[2023-12-07T16:42:27.627+0000] {taskinstance.py:1400} INFO - Marking task as FAILED. dag_id=my_scraping_dag, task_id=main_task, execution_date=20230828T000000, start_date=20231207T164227, end_date=20231207T164227
[2023-12-07T16:42:27.632+0000] {standard_task_runner.py:104} ERROR - Failed to execute job 1173 for task main_task (No section: 'web'; 4949)
[2023-12-07T16:42:27.651+0000] {local_task_job_runner.py:228} INFO - Task exited with return code 1
[2023-12-07T16:42:27.678+0000] {taskinstance.py:2778} INFO - 0 downstream tasks scheduled from follow-on schedule check
[2023-12-07T17:01:17.514+0000] {taskinstance.py:1159} INFO - Dependencies all met for dep_context=non-requeueable deps ti=<TaskInstance: my_scraping_dag.main_task scheduled__2023-08-28T00:00:00+00:00 [queued]>
[2023-12-07T17:01:17.519+0000] {taskinstance.py:1159} INFO - Dependencies all met for dep_context=requeueable deps ti=<TaskInstance: my_scraping_dag.main_task scheduled__2023-08-28T00:00:00+00:00 [queued]>
[2023-12-07T17:01:17.520+0000] {taskinstance.py:1361} INFO - Starting attempt 1 of 1
[2023-12-07T17:01:17.527+0000] {taskinstance.py:1382} INFO - Executing <Task(PythonOperator): main_task> on 2023-08-28 00:00:00+00:00
[2023-12-07T17:01:17.533+0000] {standard_task_runner.py:57} INFO - Started process 6335 to run task
[2023-12-07T17:01:17.537+0000] {standard_task_runner.py:84} INFO - Running: ['***', 'tasks', 'run', 'my_scraping_dag', 'main_task', 'scheduled__2023-08-28T00:00:00+00:00', '--job-id', '1634', '--raw', '--subdir', 'DAGS_FOLDER/main.py', '--cfg-path', '/tmp/tmpvzg7h_bt']
[2023-12-07T17:01:17.539+0000] {standard_task_runner.py:85} INFO - Job 1634: Subtask main_task
[2023-12-07T17:01:17.574+0000] {task_command.py:416} INFO - Running <TaskInstance: my_scraping_dag.main_task scheduled__2023-08-28T00:00:00+00:00 [running]> on host 63b0c7e341c0
[2023-12-07T17:01:17.615+0000] {taskinstance.py:1662} INFO - Exporting env vars: AIRFLOW_CTX_DAG_OWNER='***' AIRFLOW_CTX_DAG_ID='my_scraping_dag' AIRFLOW_CTX_TASK_ID='main_task' AIRFLOW_CTX_EXECUTION_DATE='2023-08-28T00:00:00+00:00' AIRFLOW_CTX_TRY_NUMBER='1' AIRFLOW_CTX_DAG_RUN_ID='scheduled__2023-08-28T00:00:00+00:00'
[2023-12-07T17:01:17.657+0000] {logging_mixin.py:154} INFO - base_url: https://tuncbotanik.com
[2023-12-07T17:01:17.658+0000] {python.py:194} INFO - Done. Returned value was: ('https://tuncbotanik.com', {'User-Agent': 'Mozilla/5.0 (Macintosh; Intel Mac OS X 10_15_7) AppleWebKit/537.36 (KHTML, like Gecko) Chrome/119.0.0.0 Safari/537.36', 'Accept-Language': 'tr-TR,tr;q=0.9,en-US;q=0.8,en;q=0.7'}, {'dbname': 'plant', 'user': 'aozgokme', 'password': '***', 'host': 'localhost', 'port': '5432'})
[2023-12-07T17:01:17.672+0000] {taskinstance.py:1400} INFO - Marking task as SUCCESS. dag_id=my_scraping_dag, task_id=main_task, execution_date=20230828T000000, start_date=20231207T170117, end_date=20231207T170117
[2023-12-07T17:01:17.749+0000] {local_task_job_runner.py:228} INFO - Task exited with return code 0
[2023-12-07T17:01:17.784+0000] {taskinstance.py:2778} INFO - 0 downstream tasks scheduled from follow-on schedule check
[2023-12-07T17:04:38.311+0000] {taskinstance.py:1159} INFO - Dependencies all met for dep_context=non-requeueable deps ti=<TaskInstance: my_scraping_dag.main_task scheduled__2023-08-28T00:00:00+00:00 [queued]>
[2023-12-07T17:04:38.316+0000] {taskinstance.py:1159} INFO - Dependencies all met for dep_context=requeueable deps ti=<TaskInstance: my_scraping_dag.main_task scheduled__2023-08-28T00:00:00+00:00 [queued]>
[2023-12-07T17:04:38.316+0000] {taskinstance.py:1361} INFO - Starting attempt 1 of 1
[2023-12-07T17:04:38.323+0000] {taskinstance.py:1382} INFO - Executing <Task(PythonOperator): main_task> on 2023-08-28 00:00:00+00:00
[2023-12-07T17:04:38.325+0000] {standard_task_runner.py:57} INFO - Started process 7797 to run task
[2023-12-07T17:04:38.331+0000] {standard_task_runner.py:84} INFO - Running: ['***', 'tasks', 'run', 'my_scraping_dag', 'main_task', 'scheduled__2023-08-28T00:00:00+00:00', '--job-id', '2323', '--raw', '--subdir', 'DAGS_FOLDER/main.py', '--cfg-path', '/tmp/tmp1ddcba53']
[2023-12-07T17:04:38.333+0000] {standard_task_runner.py:85} INFO - Job 2323: Subtask main_task
[2023-12-07T17:04:38.359+0000] {task_command.py:416} INFO - Running <TaskInstance: my_scraping_dag.main_task scheduled__2023-08-28T00:00:00+00:00 [running]> on host 63b0c7e341c0
[2023-12-07T17:04:38.399+0000] {taskinstance.py:1662} INFO - Exporting env vars: AIRFLOW_CTX_DAG_OWNER='***' AIRFLOW_CTX_DAG_ID='my_scraping_dag' AIRFLOW_CTX_TASK_ID='main_task' AIRFLOW_CTX_EXECUTION_DATE='2023-08-28T00:00:00+00:00' AIRFLOW_CTX_TRY_NUMBER='1' AIRFLOW_CTX_DAG_RUN_ID='scheduled__2023-08-28T00:00:00+00:00'
[2023-12-07T17:04:38.420+0000] {logging_mixin.py:154} INFO - base_url: https://tuncbotanik.com
[2023-12-07T17:04:38.421+0000] {python.py:194} INFO - Done. Returned value was: ('https://tuncbotanik.com', {'User-Agent': 'Mozilla/5.0 (Macintosh; Intel Mac OS X 10_15_7) AppleWebKit/537.36 (KHTML, like Gecko) Chrome/119.0.0.0 Safari/537.36', 'Accept-Language': 'tr-TR,tr;q=0.9,en-US;q=0.8,en;q=0.7'}, {'dbname': 'plant', 'user': 'aozgokme', 'password': '***', 'host': 'localhost', 'port': '5432'})
[2023-12-07T17:04:38.436+0000] {taskinstance.py:1400} INFO - Marking task as SUCCESS. dag_id=my_scraping_dag, task_id=main_task, execution_date=20230828T000000, start_date=20231207T170438, end_date=20231207T170438
[2023-12-07T17:04:38.460+0000] {local_task_job_runner.py:228} INFO - Task exited with return code 0
[2023-12-07T17:04:38.499+0000] {taskinstance.py:2778} INFO - 0 downstream tasks scheduled from follow-on schedule check
[2023-12-07T17:19:07.981+0000] {taskinstance.py:1159} INFO - Dependencies all met for dep_context=non-requeueable deps ti=<TaskInstance: my_scraping_dag.main_task scheduled__2023-08-28T00:00:00+00:00 [queued]>
[2023-12-07T17:19:07.988+0000] {taskinstance.py:1159} INFO - Dependencies all met for dep_context=requeueable deps ti=<TaskInstance: my_scraping_dag.main_task scheduled__2023-08-28T00:00:00+00:00 [queued]>
[2023-12-07T17:19:07.990+0000] {taskinstance.py:1361} INFO - Starting attempt 1 of 1
[2023-12-07T17:19:08.013+0000] {taskinstance.py:1382} INFO - Executing <Task(PythonOperator): main_task> on 2023-08-28 00:00:00+00:00
[2023-12-07T17:19:08.016+0000] {standard_task_runner.py:57} INFO - Started process 9033 to run task
[2023-12-07T17:19:08.019+0000] {standard_task_runner.py:84} INFO - Running: ['***', 'tasks', 'run', 'my_scraping_dag', 'main_task', 'scheduled__2023-08-28T00:00:00+00:00', '--job-id', '2769', '--raw', '--subdir', 'DAGS_FOLDER/main.py', '--cfg-path', '/tmp/tmpi3z8mf20']
[2023-12-07T17:19:08.021+0000] {standard_task_runner.py:85} INFO - Job 2769: Subtask main_task
[2023-12-07T17:19:08.050+0000] {task_command.py:416} INFO - Running <TaskInstance: my_scraping_dag.main_task scheduled__2023-08-28T00:00:00+00:00 [running]> on host 63b0c7e341c0
[2023-12-07T17:19:08.093+0000] {taskinstance.py:1662} INFO - Exporting env vars: AIRFLOW_CTX_DAG_OWNER='***' AIRFLOW_CTX_DAG_ID='my_scraping_dag' AIRFLOW_CTX_TASK_ID='main_task' AIRFLOW_CTX_EXECUTION_DATE='2023-08-28T00:00:00+00:00' AIRFLOW_CTX_TRY_NUMBER='1' AIRFLOW_CTX_DAG_RUN_ID='scheduled__2023-08-28T00:00:00+00:00'
[2023-12-07T17:19:08.945+0000] {taskinstance.py:1937} ERROR - Task failed with exception
Traceback (most recent call last):
  File "/home/airflow/.local/lib/python3.8/site-packages/airflow/operators/python.py", line 192, in execute
    return_value = self.execute_callable()
  File "/home/airflow/.local/lib/python3.8/site-packages/airflow/operators/python.py", line 209, in execute_callable
    return self.python_callable(*self.op_args, **self.op_kwargs)
  File "/opt/airflow/dags/main.py", line 80, in main
    insert_data_to_db(products, db_params)
  File "/opt/airflow/dags/main.py", line 43, in insert_data_to_db
    with psycopg2.connect(**db_params) as conn:
  File "/home/airflow/.local/lib/python3.8/site-packages/psycopg2/__init__.py", line 122, in connect
    conn = _connect(dsn, connection_factory=connection_factory, **kwasync)
psycopg2.OperationalError: connection to server at "localhost" (127.0.0.1), port 5432 failed: Connection refused
	Is the server running on that host and accepting TCP/IP connections?
connection to server at "localhost" (::1), port 5432 failed: Cannot assign requested address
	Is the server running on that host and accepting TCP/IP connections?

[2023-12-07T17:19:08.956+0000] {taskinstance.py:1400} INFO - Marking task as FAILED. dag_id=my_scraping_dag, task_id=main_task, execution_date=20230828T000000, start_date=20231207T171907, end_date=20231207T171908
[2023-12-07T17:19:08.962+0000] {standard_task_runner.py:104} ERROR - Failed to execute job 2769 for task main_task (connection to server at "localhost" (127.0.0.1), port 5432 failed: Connection refused
	Is the server running on that host and accepting TCP/IP connections?
connection to server at "localhost" (::1), port 5432 failed: Cannot assign requested address
	Is the server running on that host and accepting TCP/IP connections?
; 9033)
[2023-12-07T17:19:08.995+0000] {local_task_job_runner.py:228} INFO - Task exited with return code 1
[2023-12-07T17:19:09.005+0000] {taskinstance.py:2778} INFO - 0 downstream tasks scheduled from follow-on schedule check
[2023-12-07T17:23:27.705+0000] {taskinstance.py:1159} INFO - Dependencies all met for dep_context=non-requeueable deps ti=<TaskInstance: my_scraping_dag.main_task scheduled__2023-08-28T00:00:00+00:00 [queued]>
[2023-12-07T17:23:27.709+0000] {taskinstance.py:1159} INFO - Dependencies all met for dep_context=requeueable deps ti=<TaskInstance: my_scraping_dag.main_task scheduled__2023-08-28T00:00:00+00:00 [queued]>
[2023-12-07T17:23:27.709+0000] {taskinstance.py:1361} INFO - Starting attempt 1 of 1
[2023-12-07T17:23:27.721+0000] {taskinstance.py:1382} INFO - Executing <Task(PythonOperator): main_task> on 2023-08-28 00:00:00+00:00
[2023-12-07T17:23:27.723+0000] {standard_task_runner.py:57} INFO - Started process 9841 to run task
[2023-12-07T17:23:27.726+0000] {standard_task_runner.py:84} INFO - Running: ['***', 'tasks', 'run', 'my_scraping_dag', 'main_task', 'scheduled__2023-08-28T00:00:00+00:00', '--job-id', '3111', '--raw', '--subdir', 'DAGS_FOLDER/main.py', '--cfg-path', '/tmp/tmpqw6aadgw']
[2023-12-07T17:23:27.728+0000] {standard_task_runner.py:85} INFO - Job 3111: Subtask main_task
[2023-12-07T17:23:27.754+0000] {task_command.py:416} INFO - Running <TaskInstance: my_scraping_dag.main_task scheduled__2023-08-28T00:00:00+00:00 [running]> on host 63b0c7e341c0
[2023-12-07T17:23:27.796+0000] {taskinstance.py:1662} INFO - Exporting env vars: AIRFLOW_CTX_DAG_OWNER='***' AIRFLOW_CTX_DAG_ID='my_scraping_dag' AIRFLOW_CTX_TASK_ID='main_task' AIRFLOW_CTX_EXECUTION_DATE='2023-08-28T00:00:00+00:00' AIRFLOW_CTX_TRY_NUMBER='1' AIRFLOW_CTX_DAG_RUN_ID='scheduled__2023-08-28T00:00:00+00:00'
[2023-12-07T17:23:28.517+0000] {taskinstance.py:1937} ERROR - Task failed with exception
Traceback (most recent call last):
  File "/home/airflow/.local/lib/python3.8/site-packages/airflow/operators/python.py", line 192, in execute
    return_value = self.execute_callable()
  File "/home/airflow/.local/lib/python3.8/site-packages/airflow/operators/python.py", line 209, in execute_callable
    return self.python_callable(*self.op_args, **self.op_kwargs)
  File "/opt/airflow/dags/main.py", line 73, in main
    insert_data_to_db(products, db_params)
  File "/opt/airflow/dags/main.py", line 40, in insert_data_to_db
    with psycopg2.connect(**db_params) as conn:
  File "/home/airflow/.local/lib/python3.8/site-packages/psycopg2/__init__.py", line 122, in connect
    conn = _connect(dsn, connection_factory=connection_factory, **kwasync)
psycopg2.OperationalError: connection to server at "localhost" (127.0.0.1), port 5432 failed: Connection refused
	Is the server running on that host and accepting TCP/IP connections?
connection to server at "localhost" (::1), port 5432 failed: Cannot assign requested address
	Is the server running on that host and accepting TCP/IP connections?

[2023-12-07T17:23:28.528+0000] {taskinstance.py:1400} INFO - Marking task as FAILED. dag_id=my_scraping_dag, task_id=main_task, execution_date=20230828T000000, start_date=20231207T172327, end_date=20231207T172328
[2023-12-07T17:23:28.544+0000] {standard_task_runner.py:104} ERROR - Failed to execute job 3111 for task main_task (connection to server at "localhost" (127.0.0.1), port 5432 failed: Connection refused
	Is the server running on that host and accepting TCP/IP connections?
connection to server at "localhost" (::1), port 5432 failed: Cannot assign requested address
	Is the server running on that host and accepting TCP/IP connections?
; 9841)
[2023-12-07T17:23:28.581+0000] {local_task_job_runner.py:228} INFO - Task exited with return code 1
[2023-12-07T17:23:28.595+0000] {taskinstance.py:2778} INFO - 0 downstream tasks scheduled from follow-on schedule check
[2023-12-07T17:29:06.787+0000] {taskinstance.py:1159} INFO - Dependencies all met for dep_context=non-requeueable deps ti=<TaskInstance: my_scraping_dag.main_task scheduled__2023-08-28T00:00:00+00:00 [queued]>
[2023-12-07T17:29:06.791+0000] {taskinstance.py:1159} INFO - Dependencies all met for dep_context=requeueable deps ti=<TaskInstance: my_scraping_dag.main_task scheduled__2023-08-28T00:00:00+00:00 [queued]>
[2023-12-07T17:29:06.791+0000] {taskinstance.py:1361} INFO - Starting attempt 1 of 1
[2023-12-07T17:29:06.801+0000] {taskinstance.py:1382} INFO - Executing <Task(PythonOperator): main_task> on 2023-08-28 00:00:00+00:00
[2023-12-07T17:29:06.803+0000] {standard_task_runner.py:57} INFO - Started process 10672 to run task
[2023-12-07T17:29:06.806+0000] {standard_task_runner.py:84} INFO - Running: ['***', 'tasks', 'run', 'my_scraping_dag', 'main_task', 'scheduled__2023-08-28T00:00:00+00:00', '--job-id', '3453', '--raw', '--subdir', 'DAGS_FOLDER/main.py', '--cfg-path', '/tmp/tmp8b_th5_h']
[2023-12-07T17:29:06.808+0000] {standard_task_runner.py:85} INFO - Job 3453: Subtask main_task
[2023-12-07T17:29:06.838+0000] {task_command.py:416} INFO - Running <TaskInstance: my_scraping_dag.main_task scheduled__2023-08-28T00:00:00+00:00 [running]> on host 63b0c7e341c0
[2023-12-07T17:29:06.879+0000] {taskinstance.py:1662} INFO - Exporting env vars: AIRFLOW_CTX_DAG_OWNER='***' AIRFLOW_CTX_DAG_ID='my_scraping_dag' AIRFLOW_CTX_TASK_ID='main_task' AIRFLOW_CTX_EXECUTION_DATE='2023-08-28T00:00:00+00:00' AIRFLOW_CTX_TRY_NUMBER='1' AIRFLOW_CTX_DAG_RUN_ID='scheduled__2023-08-28T00:00:00+00:00'
[2023-12-07T17:29:07.610+0000] {taskinstance.py:1937} ERROR - Task failed with exception
Traceback (most recent call last):
  File "/home/airflow/.local/lib/python3.8/site-packages/airflow/operators/python.py", line 192, in execute
    return_value = self.execute_callable()
  File "/home/airflow/.local/lib/python3.8/site-packages/airflow/operators/python.py", line 209, in execute_callable
    return self.python_callable(*self.op_args, **self.op_kwargs)
  File "/opt/airflow/dags/main.py", line 73, in main
    insert_data_to_db(products, db_params)
  File "/opt/airflow/dags/main.py", line 40, in insert_data_to_db
    with psycopg2.connect(**db_params) as conn:
  File "/home/airflow/.local/lib/python3.8/site-packages/psycopg2/__init__.py", line 122, in connect
    conn = _connect(dsn, connection_factory=connection_factory, **kwasync)
psycopg2.OperationalError: connection to server at "localhost" (127.0.0.1), port 5432 failed: Connection refused
	Is the server running on that host and accepting TCP/IP connections?
connection to server at "localhost" (::1), port 5432 failed: Cannot assign requested address
	Is the server running on that host and accepting TCP/IP connections?

[2023-12-07T17:29:07.627+0000] {taskinstance.py:1400} INFO - Marking task as FAILED. dag_id=my_scraping_dag, task_id=main_task, execution_date=20230828T000000, start_date=20231207T172906, end_date=20231207T172907
[2023-12-07T17:29:07.636+0000] {standard_task_runner.py:104} ERROR - Failed to execute job 3453 for task main_task (connection to server at "localhost" (127.0.0.1), port 5432 failed: Connection refused
	Is the server running on that host and accepting TCP/IP connections?
connection to server at "localhost" (::1), port 5432 failed: Cannot assign requested address
	Is the server running on that host and accepting TCP/IP connections?
; 10672)
[2023-12-07T17:29:07.660+0000] {local_task_job_runner.py:228} INFO - Task exited with return code 1
[2023-12-07T17:29:07.674+0000] {taskinstance.py:2778} INFO - 0 downstream tasks scheduled from follow-on schedule check
[2023-12-09T07:35:16.171+0000] {taskinstance.py:1159} INFO - Dependencies all met for dep_context=non-requeueable deps ti=<TaskInstance: my_scraping_dag.main_task scheduled__2023-08-28T00:00:00+00:00 [queued]>
[2023-12-09T07:35:16.175+0000] {taskinstance.py:1159} INFO - Dependencies all met for dep_context=requeueable deps ti=<TaskInstance: my_scraping_dag.main_task scheduled__2023-08-28T00:00:00+00:00 [queued]>
[2023-12-09T07:35:16.175+0000] {taskinstance.py:1361} INFO - Starting attempt 1 of 1
[2023-12-09T07:35:16.182+0000] {taskinstance.py:1382} INFO - Executing <Task(PythonOperator): main_task> on 2023-08-28 00:00:00+00:00
[2023-12-09T07:35:16.184+0000] {standard_task_runner.py:57} INFO - Started process 1090 to run task
[2023-12-09T07:35:16.187+0000] {standard_task_runner.py:84} INFO - Running: ['***', 'tasks', 'run', 'my_scraping_dag', 'main_task', 'scheduled__2023-08-28T00:00:00+00:00', '--job-id', '243', '--raw', '--subdir', 'DAGS_FOLDER/main.py', '--cfg-path', '/tmp/tmptusj_060']
[2023-12-09T07:35:16.188+0000] {standard_task_runner.py:85} INFO - Job 243: Subtask main_task
[2023-12-09T07:35:16.216+0000] {task_command.py:416} INFO - Running <TaskInstance: my_scraping_dag.main_task scheduled__2023-08-28T00:00:00+00:00 [running]> on host 36b5ef2505c9
[2023-12-09T07:35:16.260+0000] {taskinstance.py:1662} INFO - Exporting env vars: AIRFLOW_CTX_DAG_OWNER='***' AIRFLOW_CTX_DAG_ID='my_scraping_dag' AIRFLOW_CTX_TASK_ID='main_task' AIRFLOW_CTX_EXECUTION_DATE='2023-08-28T00:00:00+00:00' AIRFLOW_CTX_TRY_NUMBER='1' AIRFLOW_CTX_DAG_RUN_ID='scheduled__2023-08-28T00:00:00+00:00'
[2023-12-09T07:35:16.267+0000] {taskinstance.py:1937} ERROR - Task failed with exception
Traceback (most recent call last):
  File "/home/airflow/.local/lib/python3.8/site-packages/airflow/operators/python.py", line 192, in execute
    return_value = self.execute_callable()
  File "/home/airflow/.local/lib/python3.8/site-packages/airflow/operators/python.py", line 209, in execute_callable
    return self.python_callable(*self.op_args, **self.op_kwargs)
  File "/opt/airflow/dags/main.py", line 64, in main
    base_url = Variable.get('base_url')
  File "/home/airflow/.local/lib/python3.8/site-packages/airflow/models/variable.py", line 140, in get
    raise KeyError(f"Variable {key} does not exist")
KeyError: 'Variable base_url does not exist'
[2023-12-09T07:35:16.274+0000] {taskinstance.py:1400} INFO - Marking task as FAILED. dag_id=my_scraping_dag, task_id=main_task, execution_date=20230828T000000, start_date=20231209T073516, end_date=20231209T073516
[2023-12-09T07:35:16.281+0000] {standard_task_runner.py:104} ERROR - Failed to execute job 243 for task main_task ('Variable base_url does not exist'; 1090)
[2023-12-09T07:35:16.319+0000] {local_task_job_runner.py:228} INFO - Task exited with return code 1
[2023-12-09T07:35:16.340+0000] {taskinstance.py:2778} INFO - 0 downstream tasks scheduled from follow-on schedule check
