[2023-12-07T14:45:23.001+0000] {taskinstance.py:1159} INFO - Dependencies all met for dep_context=non-requeueable deps ti=<TaskInstance: my_scraping_dag.main_task scheduled__2023-01-08T00:00:00+00:00 [queued]>
[2023-12-07T14:45:23.004+0000] {taskinstance.py:1159} INFO - Dependencies all met for dep_context=requeueable deps ti=<TaskInstance: my_scraping_dag.main_task scheduled__2023-01-08T00:00:00+00:00 [queued]>
[2023-12-07T14:45:23.005+0000] {taskinstance.py:1361} INFO - Starting attempt 1 of 1
[2023-12-07T14:45:23.010+0000] {taskinstance.py:1382} INFO - Executing <Task(PythonOperator): main_task> on 2023-01-08 00:00:00+00:00
[2023-12-07T14:45:23.012+0000] {standard_task_runner.py:57} INFO - Started process 393 to run task
[2023-12-07T14:45:23.014+0000] {standard_task_runner.py:84} INFO - Running: ['***', 'tasks', 'run', 'my_scraping_dag', 'main_task', 'scheduled__2023-01-08T00:00:00+00:00', '--job-id', '19', '--raw', '--subdir', 'DAGS_FOLDER/main.py', '--cfg-path', '/tmp/tmpv4w1z1o3']
[2023-12-07T14:45:23.015+0000] {standard_task_runner.py:85} INFO - Job 19: Subtask main_task
[2023-12-07T14:45:23.035+0000] {task_command.py:416} INFO - Running <TaskInstance: my_scraping_dag.main_task scheduled__2023-01-08T00:00:00+00:00 [running]> on host 63b0c7e341c0
[2023-12-07T14:45:23.066+0000] {taskinstance.py:1662} INFO - Exporting env vars: AIRFLOW_CTX_DAG_OWNER='***' AIRFLOW_CTX_DAG_ID='my_scraping_dag' AIRFLOW_CTX_TASK_ID='main_task' AIRFLOW_CTX_EXECUTION_DATE='2023-01-08T00:00:00+00:00' AIRFLOW_CTX_TRY_NUMBER='1' AIRFLOW_CTX_DAG_RUN_ID='scheduled__2023-01-08T00:00:00+00:00'
[2023-12-07T14:45:23.066+0000] {taskinstance.py:1937} ERROR - Task failed with exception
Traceback (most recent call last):
  File "/usr/local/lib/python3.8/configparser.py", line 846, in items
    d.update(self._sections[section])
KeyError: 'web'

During handling of the above exception, another exception occurred:

Traceback (most recent call last):
  File "/home/airflow/.local/lib/python3.8/site-packages/airflow/operators/python.py", line 192, in execute
    return_value = self.execute_callable()
  File "/home/airflow/.local/lib/python3.8/site-packages/airflow/operators/python.py", line 209, in execute_callable
    return self.python_callable(*self.op_args, **self.op_kwargs)
  File "/opt/airflow/dags/main.py", line 61, in main
    config = get_config('web')
  File "/opt/airflow/dags/main.py", line 23, in get_config
    return {key: value for key, value in parser.items(section)}
  File "/usr/local/lib/python3.8/configparser.py", line 849, in items
    raise NoSectionError(section)
configparser.NoSectionError: No section: 'web'
[2023-12-07T14:45:23.070+0000] {taskinstance.py:1400} INFO - Marking task as FAILED. dag_id=my_scraping_dag, task_id=main_task, execution_date=20230108T000000, start_date=20231207T144523, end_date=20231207T144523
[2023-12-07T14:45:23.075+0000] {standard_task_runner.py:104} ERROR - Failed to execute job 19 for task main_task (No section: 'web'; 393)
[2023-12-07T14:45:23.108+0000] {local_task_job_runner.py:228} INFO - Task exited with return code 1
[2023-12-07T14:45:23.120+0000] {taskinstance.py:2778} INFO - 0 downstream tasks scheduled from follow-on schedule check
[2023-12-07T14:49:06.897+0000] {taskinstance.py:1159} INFO - Dependencies all met for dep_context=non-requeueable deps ti=<TaskInstance: my_scraping_dag.main_task scheduled__2023-01-08T00:00:00+00:00 [queued]>
[2023-12-07T14:49:06.902+0000] {taskinstance.py:1159} INFO - Dependencies all met for dep_context=requeueable deps ti=<TaskInstance: my_scraping_dag.main_task scheduled__2023-01-08T00:00:00+00:00 [queued]>
[2023-12-07T14:49:06.902+0000] {taskinstance.py:1361} INFO - Starting attempt 1 of 1
[2023-12-07T14:49:06.911+0000] {taskinstance.py:1382} INFO - Executing <Task(PythonOperator): main_task> on 2023-01-08 00:00:00+00:00
[2023-12-07T14:49:06.913+0000] {standard_task_runner.py:57} INFO - Started process 670 to run task
[2023-12-07T14:49:06.915+0000] {standard_task_runner.py:84} INFO - Running: ['***', 'tasks', 'run', 'my_scraping_dag', 'main_task', 'scheduled__2023-01-08T00:00:00+00:00', '--job-id', '106', '--raw', '--subdir', 'DAGS_FOLDER/main.py', '--cfg-path', '/tmp/tmp8is0h72y']
[2023-12-07T14:49:06.917+0000] {standard_task_runner.py:85} INFO - Job 106: Subtask main_task
[2023-12-07T14:49:06.941+0000] {task_command.py:416} INFO - Running <TaskInstance: my_scraping_dag.main_task scheduled__2023-01-08T00:00:00+00:00 [running]> on host 63b0c7e341c0
[2023-12-07T14:49:06.976+0000] {taskinstance.py:1662} INFO - Exporting env vars: AIRFLOW_CTX_DAG_OWNER='***' AIRFLOW_CTX_DAG_ID='my_scraping_dag' AIRFLOW_CTX_TASK_ID='main_task' AIRFLOW_CTX_EXECUTION_DATE='2023-01-08T00:00:00+00:00' AIRFLOW_CTX_TRY_NUMBER='1' AIRFLOW_CTX_DAG_RUN_ID='scheduled__2023-01-08T00:00:00+00:00'
[2023-12-07T14:49:06.977+0000] {taskinstance.py:1937} ERROR - Task failed with exception
Traceback (most recent call last):
  File "/usr/local/lib/python3.8/configparser.py", line 846, in items
    d.update(self._sections[section])
KeyError: 'web'

During handling of the above exception, another exception occurred:

Traceback (most recent call last):
  File "/home/airflow/.local/lib/python3.8/site-packages/airflow/operators/python.py", line 192, in execute
    return_value = self.execute_callable()
  File "/home/airflow/.local/lib/python3.8/site-packages/airflow/operators/python.py", line 209, in execute_callable
    return self.python_callable(*self.op_args, **self.op_kwargs)
  File "/opt/airflow/dags/main.py", line 61, in main
    config = get_config('web')
  File "/opt/airflow/dags/main.py", line 23, in get_config
    return {key: value for key, value in parser.items(section)}
  File "/usr/local/lib/python3.8/configparser.py", line 849, in items
    raise NoSectionError(section)
configparser.NoSectionError: No section: 'web'
[2023-12-07T14:49:06.983+0000] {taskinstance.py:1400} INFO - Marking task as FAILED. dag_id=my_scraping_dag, task_id=main_task, execution_date=20230108T000000, start_date=20231207T144906, end_date=20231207T144906
[2023-12-07T14:49:06.988+0000] {standard_task_runner.py:104} ERROR - Failed to execute job 106 for task main_task (No section: 'web'; 670)
[2023-12-07T14:49:07.008+0000] {local_task_job_runner.py:228} INFO - Task exited with return code 1
[2023-12-07T14:49:07.020+0000] {taskinstance.py:2778} INFO - 0 downstream tasks scheduled from follow-on schedule check
[2023-12-07T14:51:16.901+0000] {taskinstance.py:1159} INFO - Dependencies all met for dep_context=non-requeueable deps ti=<TaskInstance: my_scraping_dag.main_task scheduled__2023-01-08T00:00:00+00:00 [queued]>
[2023-12-07T14:51:16.906+0000] {taskinstance.py:1159} INFO - Dependencies all met for dep_context=requeueable deps ti=<TaskInstance: my_scraping_dag.main_task scheduled__2023-01-08T00:00:00+00:00 [queued]>
[2023-12-07T14:51:16.906+0000] {taskinstance.py:1361} INFO - Starting attempt 1 of 1
[2023-12-07T14:51:16.912+0000] {taskinstance.py:1382} INFO - Executing <Task(PythonOperator): main_task> on 2023-01-08 00:00:00+00:00
[2023-12-07T14:51:16.915+0000] {standard_task_runner.py:57} INFO - Started process 741 to run task
[2023-12-07T14:51:16.917+0000] {standard_task_runner.py:84} INFO - Running: ['***', 'tasks', 'run', 'my_scraping_dag', 'main_task', 'scheduled__2023-01-08T00:00:00+00:00', '--job-id', '118', '--raw', '--subdir', 'DAGS_FOLDER/main.py', '--cfg-path', '/tmp/tmp7p__x080']
[2023-12-07T14:51:16.919+0000] {standard_task_runner.py:85} INFO - Job 118: Subtask main_task
[2023-12-07T14:51:16.942+0000] {task_command.py:416} INFO - Running <TaskInstance: my_scraping_dag.main_task scheduled__2023-01-08T00:00:00+00:00 [running]> on host 63b0c7e341c0
[2023-12-07T14:51:16.974+0000] {taskinstance.py:1662} INFO - Exporting env vars: AIRFLOW_CTX_DAG_OWNER='***' AIRFLOW_CTX_DAG_ID='my_scraping_dag' AIRFLOW_CTX_TASK_ID='main_task' AIRFLOW_CTX_EXECUTION_DATE='2023-01-08T00:00:00+00:00' AIRFLOW_CTX_TRY_NUMBER='1' AIRFLOW_CTX_DAG_RUN_ID='scheduled__2023-01-08T00:00:00+00:00'
[2023-12-07T14:51:16.975+0000] {taskinstance.py:1937} ERROR - Task failed with exception
Traceback (most recent call last):
  File "/usr/local/lib/python3.8/configparser.py", line 846, in items
    d.update(self._sections[section])
KeyError: 'web'

During handling of the above exception, another exception occurred:

Traceback (most recent call last):
  File "/home/airflow/.local/lib/python3.8/site-packages/airflow/operators/python.py", line 192, in execute
    return_value = self.execute_callable()
  File "/home/airflow/.local/lib/python3.8/site-packages/airflow/operators/python.py", line 209, in execute_callable
    return self.python_callable(*self.op_args, **self.op_kwargs)
  File "/opt/airflow/dags/main.py", line 61, in main
    config = get_config('web')
  File "/opt/airflow/dags/main.py", line 23, in get_config
    return {key: value for key, value in parser.items(section)}
  File "/usr/local/lib/python3.8/configparser.py", line 849, in items
    raise NoSectionError(section)
configparser.NoSectionError: No section: 'web'
[2023-12-07T14:51:16.980+0000] {taskinstance.py:1400} INFO - Marking task as FAILED. dag_id=my_scraping_dag, task_id=main_task, execution_date=20230108T000000, start_date=20231207T145116, end_date=20231207T145116
[2023-12-07T14:51:16.985+0000] {standard_task_runner.py:104} ERROR - Failed to execute job 118 for task main_task (No section: 'web'; 741)
[2023-12-07T14:51:17.010+0000] {local_task_job_runner.py:228} INFO - Task exited with return code 1
[2023-12-07T14:51:17.021+0000] {taskinstance.py:2778} INFO - 0 downstream tasks scheduled from follow-on schedule check
[2023-12-07T14:59:44.377+0000] {taskinstance.py:1159} INFO - Dependencies all met for dep_context=non-requeueable deps ti=<TaskInstance: my_scraping_dag.main_task scheduled__2023-01-08T00:00:00+00:00 [queued]>
[2023-12-07T14:59:44.383+0000] {taskinstance.py:1159} INFO - Dependencies all met for dep_context=requeueable deps ti=<TaskInstance: my_scraping_dag.main_task scheduled__2023-01-08T00:00:00+00:00 [queued]>
[2023-12-07T14:59:44.383+0000] {taskinstance.py:1361} INFO - Starting attempt 1 of 1
[2023-12-07T14:59:44.392+0000] {taskinstance.py:1382} INFO - Executing <Task(PythonOperator): main_task> on 2023-01-08 00:00:00+00:00
[2023-12-07T14:59:44.395+0000] {standard_task_runner.py:57} INFO - Started process 1378 to run task
[2023-12-07T14:59:44.397+0000] {standard_task_runner.py:84} INFO - Running: ['***', 'tasks', 'run', 'my_scraping_dag', 'main_task', 'scheduled__2023-01-08T00:00:00+00:00', '--job-id', '322', '--raw', '--subdir', 'DAGS_FOLDER/main.py', '--cfg-path', '/tmp/tmpjch_qs75']
[2023-12-07T14:59:44.399+0000] {standard_task_runner.py:85} INFO - Job 322: Subtask main_task
[2023-12-07T14:59:44.425+0000] {task_command.py:416} INFO - Running <TaskInstance: my_scraping_dag.main_task scheduled__2023-01-08T00:00:00+00:00 [running]> on host 63b0c7e341c0
[2023-12-07T14:59:44.462+0000] {taskinstance.py:1662} INFO - Exporting env vars: AIRFLOW_CTX_DAG_OWNER='***' AIRFLOW_CTX_DAG_ID='my_scraping_dag' AIRFLOW_CTX_TASK_ID='main_task' AIRFLOW_CTX_EXECUTION_DATE='2023-01-08T00:00:00+00:00' AIRFLOW_CTX_TRY_NUMBER='1' AIRFLOW_CTX_DAG_RUN_ID='scheduled__2023-01-08T00:00:00+00:00'
[2023-12-07T14:59:44.462+0000] {taskinstance.py:1937} ERROR - Task failed with exception
Traceback (most recent call last):
  File "/usr/local/lib/python3.8/configparser.py", line 846, in items
    d.update(self._sections[section])
KeyError: 'web'

During handling of the above exception, another exception occurred:

Traceback (most recent call last):
  File "/home/airflow/.local/lib/python3.8/site-packages/airflow/operators/python.py", line 192, in execute
    return_value = self.execute_callable()
  File "/home/airflow/.local/lib/python3.8/site-packages/airflow/operators/python.py", line 209, in execute_callable
    return self.python_callable(*self.op_args, **self.op_kwargs)
  File "/opt/airflow/dags/main.py", line 60, in main
    config = get_config('web')
  File "/opt/airflow/dags/main.py", line 22, in get_config
    return {key: value for key, value in parser.items(section)}
  File "/usr/local/lib/python3.8/configparser.py", line 849, in items
    raise NoSectionError(section)
configparser.NoSectionError: No section: 'web'
[2023-12-07T14:59:44.467+0000] {taskinstance.py:1400} INFO - Marking task as FAILED. dag_id=my_scraping_dag, task_id=main_task, execution_date=20230108T000000, start_date=20231207T145944, end_date=20231207T145944
[2023-12-07T14:59:44.472+0000] {standard_task_runner.py:104} ERROR - Failed to execute job 322 for task main_task (No section: 'web'; 1378)
[2023-12-07T14:59:44.490+0000] {local_task_job_runner.py:228} INFO - Task exited with return code 1
[2023-12-07T14:59:44.501+0000] {taskinstance.py:2778} INFO - 0 downstream tasks scheduled from follow-on schedule check
[2023-12-07T15:10:39.677+0000] {taskinstance.py:1159} INFO - Dependencies all met for dep_context=non-requeueable deps ti=<TaskInstance: my_scraping_dag.main_task scheduled__2023-01-08T00:00:00+00:00 [queued]>
[2023-12-07T15:10:39.681+0000] {taskinstance.py:1159} INFO - Dependencies all met for dep_context=requeueable deps ti=<TaskInstance: my_scraping_dag.main_task scheduled__2023-01-08T00:00:00+00:00 [queued]>
[2023-12-07T15:10:39.682+0000] {taskinstance.py:1361} INFO - Starting attempt 1 of 1
[2023-12-07T15:10:39.690+0000] {taskinstance.py:1382} INFO - Executing <Task(PythonOperator): main_task> on 2023-01-08 00:00:00+00:00
[2023-12-07T15:10:39.692+0000] {standard_task_runner.py:57} INFO - Started process 1859 to run task
[2023-12-07T15:10:39.695+0000] {standard_task_runner.py:84} INFO - Running: ['***', 'tasks', 'run', 'my_scraping_dag', 'main_task', 'scheduled__2023-01-08T00:00:00+00:00', '--job-id', '429', '--raw', '--subdir', 'DAGS_FOLDER/main.py', '--cfg-path', '/tmp/tmp0ncp9_73']
[2023-12-07T15:10:39.697+0000] {standard_task_runner.py:85} INFO - Job 429: Subtask main_task
[2023-12-07T15:10:39.720+0000] {task_command.py:416} INFO - Running <TaskInstance: my_scraping_dag.main_task scheduled__2023-01-08T00:00:00+00:00 [running]> on host 63b0c7e341c0
[2023-12-07T15:10:39.751+0000] {taskinstance.py:1662} INFO - Exporting env vars: AIRFLOW_CTX_DAG_OWNER='***' AIRFLOW_CTX_DAG_ID='my_scraping_dag' AIRFLOW_CTX_TASK_ID='main_task' AIRFLOW_CTX_EXECUTION_DATE='2023-01-08T00:00:00+00:00' AIRFLOW_CTX_TRY_NUMBER='1' AIRFLOW_CTX_DAG_RUN_ID='scheduled__2023-01-08T00:00:00+00:00'
[2023-12-07T15:10:39.752+0000] {taskinstance.py:1937} ERROR - Task failed with exception
Traceback (most recent call last):
  File "/usr/local/lib/python3.8/configparser.py", line 846, in items
    d.update(self._sections[section])
KeyError: 'web'

During handling of the above exception, another exception occurred:

Traceback (most recent call last):
  File "/home/airflow/.local/lib/python3.8/site-packages/airflow/operators/python.py", line 192, in execute
    return_value = self.execute_callable()
  File "/home/airflow/.local/lib/python3.8/site-packages/airflow/operators/python.py", line 209, in execute_callable
    return self.python_callable(*self.op_args, **self.op_kwargs)
  File "/opt/airflow/dags/main.py", line 63, in main
    config = get_config('web')
  File "/opt/airflow/dags/main.py", line 14, in get_config
    return {key: value for key, value in parser.items(section)}
  File "/usr/local/lib/python3.8/configparser.py", line 849, in items
    raise NoSectionError(section)
configparser.NoSectionError: No section: 'web'
[2023-12-07T15:10:39.755+0000] {taskinstance.py:1400} INFO - Marking task as FAILED. dag_id=my_scraping_dag, task_id=main_task, execution_date=20230108T000000, start_date=20231207T151039, end_date=20231207T151039
[2023-12-07T15:10:39.759+0000] {standard_task_runner.py:104} ERROR - Failed to execute job 429 for task main_task (No section: 'web'; 1859)
[2023-12-07T15:10:39.787+0000] {local_task_job_runner.py:228} INFO - Task exited with return code 1
[2023-12-07T15:10:39.800+0000] {taskinstance.py:2778} INFO - 0 downstream tasks scheduled from follow-on schedule check
[2023-12-07T15:12:01.568+0000] {taskinstance.py:1159} INFO - Dependencies all met for dep_context=non-requeueable deps ti=<TaskInstance: my_scraping_dag.main_task scheduled__2023-01-08T00:00:00+00:00 [queued]>
[2023-12-07T15:12:01.573+0000] {taskinstance.py:1159} INFO - Dependencies all met for dep_context=requeueable deps ti=<TaskInstance: my_scraping_dag.main_task scheduled__2023-01-08T00:00:00+00:00 [queued]>
[2023-12-07T15:12:01.573+0000] {taskinstance.py:1361} INFO - Starting attempt 1 of 1
[2023-12-07T15:12:01.580+0000] {taskinstance.py:1382} INFO - Executing <Task(PythonOperator): main_task> on 2023-01-08 00:00:00+00:00
[2023-12-07T15:12:01.582+0000] {standard_task_runner.py:57} INFO - Started process 2071 to run task
[2023-12-07T15:12:01.584+0000] {standard_task_runner.py:84} INFO - Running: ['***', 'tasks', 'run', 'my_scraping_dag', 'main_task', 'scheduled__2023-01-08T00:00:00+00:00', '--job-id', '518', '--raw', '--subdir', 'DAGS_FOLDER/main.py', '--cfg-path', '/tmp/tmp_0eb3lzz']
[2023-12-07T15:12:01.586+0000] {standard_task_runner.py:85} INFO - Job 518: Subtask main_task
[2023-12-07T15:12:01.613+0000] {task_command.py:416} INFO - Running <TaskInstance: my_scraping_dag.main_task scheduled__2023-01-08T00:00:00+00:00 [running]> on host 63b0c7e341c0
[2023-12-07T15:12:01.644+0000] {taskinstance.py:1662} INFO - Exporting env vars: AIRFLOW_CTX_DAG_OWNER='***' AIRFLOW_CTX_DAG_ID='my_scraping_dag' AIRFLOW_CTX_TASK_ID='main_task' AIRFLOW_CTX_EXECUTION_DATE='2023-01-08T00:00:00+00:00' AIRFLOW_CTX_TRY_NUMBER='1' AIRFLOW_CTX_DAG_RUN_ID='scheduled__2023-01-08T00:00:00+00:00'
[2023-12-07T15:12:01.645+0000] {taskinstance.py:1937} ERROR - Task failed with exception
Traceback (most recent call last):
  File "/usr/local/lib/python3.8/configparser.py", line 846, in items
    d.update(self._sections[section])
KeyError: 'web'

During handling of the above exception, another exception occurred:

Traceback (most recent call last):
  File "/home/airflow/.local/lib/python3.8/site-packages/airflow/operators/python.py", line 192, in execute
    return_value = self.execute_callable()
  File "/home/airflow/.local/lib/python3.8/site-packages/airflow/operators/python.py", line 209, in execute_callable
    return self.python_callable(*self.op_args, **self.op_kwargs)
  File "/opt/airflow/dags/main.py", line 63, in main
    config = get_config('web')
  File "/opt/airflow/dags/main.py", line 14, in get_config
    return {key: value for key, value in parser.items(section)}
  File "/usr/local/lib/python3.8/configparser.py", line 849, in items
    raise NoSectionError(section)
configparser.NoSectionError: No section: 'web'
[2023-12-07T15:12:01.650+0000] {taskinstance.py:1400} INFO - Marking task as FAILED. dag_id=my_scraping_dag, task_id=main_task, execution_date=20230108T000000, start_date=20231207T151201, end_date=20231207T151201
[2023-12-07T15:12:01.654+0000] {standard_task_runner.py:104} ERROR - Failed to execute job 518 for task main_task (No section: 'web'; 2071)
[2023-12-07T15:12:01.677+0000] {local_task_job_runner.py:228} INFO - Task exited with return code 1
[2023-12-07T15:12:01.684+0000] {taskinstance.py:2778} INFO - 0 downstream tasks scheduled from follow-on schedule check
[2023-12-07T16:30:46.630+0000] {taskinstance.py:1159} INFO - Dependencies all met for dep_context=non-requeueable deps ti=<TaskInstance: my_scraping_dag.main_task scheduled__2023-01-08T00:00:00+00:00 [queued]>
[2023-12-07T16:30:46.635+0000] {taskinstance.py:1159} INFO - Dependencies all met for dep_context=requeueable deps ti=<TaskInstance: my_scraping_dag.main_task scheduled__2023-01-08T00:00:00+00:00 [queued]>
[2023-12-07T16:30:46.636+0000] {taskinstance.py:1361} INFO - Starting attempt 1 of 1
[2023-12-07T16:30:46.647+0000] {taskinstance.py:1382} INFO - Executing <Task(PythonOperator): main_task> on 2023-01-08 00:00:00+00:00
[2023-12-07T16:30:46.651+0000] {standard_task_runner.py:57} INFO - Started process 3510 to run task
[2023-12-07T16:30:46.653+0000] {standard_task_runner.py:84} INFO - Running: ['***', 'tasks', 'run', 'my_scraping_dag', 'main_task', 'scheduled__2023-01-08T00:00:00+00:00', '--job-id', '596', '--raw', '--subdir', 'DAGS_FOLDER/main.py', '--cfg-path', '/tmp/tmpridlrnag']
[2023-12-07T16:30:46.655+0000] {standard_task_runner.py:85} INFO - Job 596: Subtask main_task
[2023-12-07T16:30:46.682+0000] {task_command.py:416} INFO - Running <TaskInstance: my_scraping_dag.main_task scheduled__2023-01-08T00:00:00+00:00 [running]> on host 63b0c7e341c0
[2023-12-07T16:30:46.718+0000] {taskinstance.py:1662} INFO - Exporting env vars: AIRFLOW_CTX_DAG_OWNER='***' AIRFLOW_CTX_DAG_ID='my_scraping_dag' AIRFLOW_CTX_TASK_ID='main_task' AIRFLOW_CTX_EXECUTION_DATE='2023-01-08T00:00:00+00:00' AIRFLOW_CTX_TRY_NUMBER='1' AIRFLOW_CTX_DAG_RUN_ID='scheduled__2023-01-08T00:00:00+00:00'
[2023-12-07T16:30:46.719+0000] {taskinstance.py:1937} ERROR - Task failed with exception
Traceback (most recent call last):
  File "/usr/local/lib/python3.8/configparser.py", line 846, in items
    d.update(self._sections[section])
KeyError: 'web'

During handling of the above exception, another exception occurred:

Traceback (most recent call last):
  File "/home/airflow/.local/lib/python3.8/site-packages/airflow/operators/python.py", line 192, in execute
    return_value = self.execute_callable()
  File "/home/airflow/.local/lib/python3.8/site-packages/airflow/operators/python.py", line 209, in execute_callable
    return self.python_callable(*self.op_args, **self.op_kwargs)
  File "/opt/airflow/dags/main.py", line 60, in main
    config = get_config('web')
  File "/opt/airflow/dags/main.py", line 22, in get_config
    return {key: value for key, value in parser.items(section)}
  File "/usr/local/lib/python3.8/configparser.py", line 849, in items
    raise NoSectionError(section)
configparser.NoSectionError: No section: 'web'
[2023-12-07T16:30:46.723+0000] {taskinstance.py:1400} INFO - Marking task as FAILED. dag_id=my_scraping_dag, task_id=main_task, execution_date=20230108T000000, start_date=20231207T163046, end_date=20231207T163046
[2023-12-07T16:30:46.728+0000] {standard_task_runner.py:104} ERROR - Failed to execute job 596 for task main_task (No section: 'web'; 3510)
[2023-12-07T16:30:46.747+0000] {local_task_job_runner.py:228} INFO - Task exited with return code 1
[2023-12-07T16:30:46.760+0000] {taskinstance.py:2778} INFO - 0 downstream tasks scheduled from follow-on schedule check
[2023-12-07T16:40:43.123+0000] {taskinstance.py:1159} INFO - Dependencies all met for dep_context=non-requeueable deps ti=<TaskInstance: my_scraping_dag.main_task scheduled__2023-01-08T00:00:00+00:00 [queued]>
[2023-12-07T16:40:43.129+0000] {taskinstance.py:1159} INFO - Dependencies all met for dep_context=requeueable deps ti=<TaskInstance: my_scraping_dag.main_task scheduled__2023-01-08T00:00:00+00:00 [queued]>
[2023-12-07T16:40:43.129+0000] {taskinstance.py:1361} INFO - Starting attempt 1 of 1
[2023-12-07T16:40:43.135+0000] {taskinstance.py:1382} INFO - Executing <Task(PythonOperator): main_task> on 2023-01-08 00:00:00+00:00
[2023-12-07T16:40:43.138+0000] {standard_task_runner.py:57} INFO - Started process 4435 to run task
[2023-12-07T16:40:43.140+0000] {standard_task_runner.py:84} INFO - Running: ['***', 'tasks', 'run', 'my_scraping_dag', 'main_task', 'scheduled__2023-01-08T00:00:00+00:00', '--job-id', '938', '--raw', '--subdir', 'DAGS_FOLDER/main.py', '--cfg-path', '/tmp/tmpitoo7w37']
[2023-12-07T16:40:43.142+0000] {standard_task_runner.py:85} INFO - Job 938: Subtask main_task
[2023-12-07T16:40:43.169+0000] {task_command.py:416} INFO - Running <TaskInstance: my_scraping_dag.main_task scheduled__2023-01-08T00:00:00+00:00 [running]> on host 63b0c7e341c0
[2023-12-07T16:40:43.202+0000] {taskinstance.py:1662} INFO - Exporting env vars: AIRFLOW_CTX_DAG_OWNER='***' AIRFLOW_CTX_DAG_ID='my_scraping_dag' AIRFLOW_CTX_TASK_ID='main_task' AIRFLOW_CTX_EXECUTION_DATE='2023-01-08T00:00:00+00:00' AIRFLOW_CTX_TRY_NUMBER='1' AIRFLOW_CTX_DAG_RUN_ID='scheduled__2023-01-08T00:00:00+00:00'
[2023-12-07T16:40:43.203+0000] {taskinstance.py:1937} ERROR - Task failed with exception
Traceback (most recent call last):
  File "/usr/local/lib/python3.8/configparser.py", line 846, in items
    d.update(self._sections[section])
KeyError: 'web'

During handling of the above exception, another exception occurred:

Traceback (most recent call last):
  File "/home/airflow/.local/lib/python3.8/site-packages/airflow/operators/python.py", line 192, in execute
    return_value = self.execute_callable()
  File "/home/airflow/.local/lib/python3.8/site-packages/airflow/operators/python.py", line 209, in execute_callable
    return self.python_callable(*self.op_args, **self.op_kwargs)
  File "/opt/airflow/dags/main.py", line 60, in main
    config = get_config('web')
  File "/opt/airflow/dags/main.py", line 22, in get_config
    return {key: value for key, value in parser.items(section)}
  File "/usr/local/lib/python3.8/configparser.py", line 849, in items
    raise NoSectionError(section)
configparser.NoSectionError: No section: 'web'
[2023-12-07T16:40:43.208+0000] {taskinstance.py:1400} INFO - Marking task as FAILED. dag_id=my_scraping_dag, task_id=main_task, execution_date=20230108T000000, start_date=20231207T164043, end_date=20231207T164043
[2023-12-07T16:40:43.213+0000] {standard_task_runner.py:104} ERROR - Failed to execute job 938 for task main_task (No section: 'web'; 4435)
[2023-12-07T16:40:43.233+0000] {local_task_job_runner.py:228} INFO - Task exited with return code 1
[2023-12-07T16:40:43.246+0000] {taskinstance.py:2778} INFO - 0 downstream tasks scheduled from follow-on schedule check
[2023-12-07T16:59:48.938+0000] {taskinstance.py:1159} INFO - Dependencies all met for dep_context=non-requeueable deps ti=<TaskInstance: my_scraping_dag.main_task scheduled__2023-01-08T00:00:00+00:00 [queued]>
[2023-12-07T16:59:48.943+0000] {taskinstance.py:1159} INFO - Dependencies all met for dep_context=requeueable deps ti=<TaskInstance: my_scraping_dag.main_task scheduled__2023-01-08T00:00:00+00:00 [queued]>
[2023-12-07T16:59:48.943+0000] {taskinstance.py:1361} INFO - Starting attempt 1 of 1
[2023-12-07T16:59:48.953+0000] {taskinstance.py:1382} INFO - Executing <Task(PythonOperator): main_task> on 2023-01-08 00:00:00+00:00
[2023-12-07T16:59:48.956+0000] {standard_task_runner.py:57} INFO - Started process 5594 to run task
[2023-12-07T16:59:48.958+0000] {standard_task_runner.py:84} INFO - Running: ['***', 'tasks', 'run', 'my_scraping_dag', 'main_task', 'scheduled__2023-01-08T00:00:00+00:00', '--job-id', '1282', '--raw', '--subdir', 'DAGS_FOLDER/main.py', '--cfg-path', '/tmp/tmpretmp9_4']
[2023-12-07T16:59:48.960+0000] {standard_task_runner.py:85} INFO - Job 1282: Subtask main_task
[2023-12-07T16:59:48.986+0000] {task_command.py:416} INFO - Running <TaskInstance: my_scraping_dag.main_task scheduled__2023-01-08T00:00:00+00:00 [running]> on host 63b0c7e341c0
[2023-12-07T16:59:49.020+0000] {taskinstance.py:1662} INFO - Exporting env vars: AIRFLOW_CTX_DAG_OWNER='***' AIRFLOW_CTX_DAG_ID='my_scraping_dag' AIRFLOW_CTX_TASK_ID='main_task' AIRFLOW_CTX_EXECUTION_DATE='2023-01-08T00:00:00+00:00' AIRFLOW_CTX_TRY_NUMBER='1' AIRFLOW_CTX_DAG_RUN_ID='scheduled__2023-01-08T00:00:00+00:00'
[2023-12-07T16:59:49.038+0000] {taskinstance.py:1937} ERROR - Task failed with exception
Traceback (most recent call last):
  File "/home/airflow/.local/lib/python3.8/site-packages/airflow/operators/python.py", line 192, in execute
    return_value = self.execute_callable()
  File "/home/airflow/.local/lib/python3.8/site-packages/airflow/operators/python.py", line 209, in execute_callable
    return self.python_callable(*self.op_args, **self.op_kwargs)
  File "/opt/airflow/dags/main.py", line 33, in main
    'host': get_config('localhost'),
  File "/opt/airflow/dags/main.py", line 20, in get_config
    return Variable.get(key)
  File "/home/airflow/.local/lib/python3.8/site-packages/airflow/models/variable.py", line 140, in get
    raise KeyError(f"Variable {key} does not exist")
KeyError: 'Variable localhost does not exist'
[2023-12-07T16:59:49.042+0000] {taskinstance.py:1400} INFO - Marking task as FAILED. dag_id=my_scraping_dag, task_id=main_task, execution_date=20230108T000000, start_date=20231207T165948, end_date=20231207T165949
[2023-12-07T16:59:49.049+0000] {standard_task_runner.py:104} ERROR - Failed to execute job 1282 for task main_task ('Variable localhost does not exist'; 5594)
[2023-12-07T16:59:49.092+0000] {local_task_job_runner.py:228} INFO - Task exited with return code 1
[2023-12-07T16:59:49.104+0000] {taskinstance.py:2778} INFO - 0 downstream tasks scheduled from follow-on schedule check
[2023-12-07T17:03:12.211+0000] {taskinstance.py:1159} INFO - Dependencies all met for dep_context=non-requeueable deps ti=<TaskInstance: my_scraping_dag.main_task scheduled__2023-01-08T00:00:00+00:00 [queued]>
[2023-12-07T17:03:12.219+0000] {taskinstance.py:1159} INFO - Dependencies all met for dep_context=requeueable deps ti=<TaskInstance: my_scraping_dag.main_task scheduled__2023-01-08T00:00:00+00:00 [queued]>
[2023-12-07T17:03:12.221+0000] {taskinstance.py:1361} INFO - Starting attempt 1 of 1
[2023-12-07T17:03:12.238+0000] {taskinstance.py:1382} INFO - Executing <Task(PythonOperator): main_task> on 2023-01-08 00:00:00+00:00
[2023-12-07T17:03:12.242+0000] {standard_task_runner.py:57} INFO - Started process 6821 to run task
[2023-12-07T17:03:12.247+0000] {standard_task_runner.py:84} INFO - Running: ['***', 'tasks', 'run', 'my_scraping_dag', 'main_task', 'scheduled__2023-01-08T00:00:00+00:00', '--job-id', '1851', '--raw', '--subdir', 'DAGS_FOLDER/main.py', '--cfg-path', '/tmp/tmpdk0_2af_']
[2023-12-07T17:03:12.251+0000] {standard_task_runner.py:85} INFO - Job 1851: Subtask main_task
[2023-12-07T17:03:12.318+0000] {task_command.py:416} INFO - Running <TaskInstance: my_scraping_dag.main_task scheduled__2023-01-08T00:00:00+00:00 [running]> on host 63b0c7e341c0
[2023-12-07T17:03:12.401+0000] {taskinstance.py:1662} INFO - Exporting env vars: AIRFLOW_CTX_DAG_OWNER='***' AIRFLOW_CTX_DAG_ID='my_scraping_dag' AIRFLOW_CTX_TASK_ID='main_task' AIRFLOW_CTX_EXECUTION_DATE='2023-01-08T00:00:00+00:00' AIRFLOW_CTX_TRY_NUMBER='1' AIRFLOW_CTX_DAG_RUN_ID='scheduled__2023-01-08T00:00:00+00:00'
[2023-12-07T17:03:12.458+0000] {logging_mixin.py:154} INFO - base_url: https://tuncbotanik.com
[2023-12-07T17:03:12.459+0000] {python.py:194} INFO - Done. Returned value was: ('https://tuncbotanik.com', {'User-Agent': 'Mozilla/5.0 (Macintosh; Intel Mac OS X 10_15_7) AppleWebKit/537.36 (KHTML, like Gecko) Chrome/119.0.0.0 Safari/537.36', 'Accept-Language': 'tr-TR,tr;q=0.9,en-US;q=0.8,en;q=0.7'}, {'dbname': 'plant', 'user': 'aozgokme', 'password': '***', 'host': 'localhost', 'port': '5432'})
[2023-12-07T17:03:12.485+0000] {taskinstance.py:1400} INFO - Marking task as SUCCESS. dag_id=my_scraping_dag, task_id=main_task, execution_date=20230108T000000, start_date=20231207T170312, end_date=20231207T170312
[2023-12-07T17:03:12.579+0000] {local_task_job_runner.py:228} INFO - Task exited with return code 0
[2023-12-07T17:03:12.602+0000] {taskinstance.py:2778} INFO - 1 downstream tasks scheduled from follow-on schedule check
[2023-12-07T17:18:19.582+0000] {taskinstance.py:1159} INFO - Dependencies all met for dep_context=non-requeueable deps ti=<TaskInstance: my_scraping_dag.main_task scheduled__2023-01-08T00:00:00+00:00 [queued]>
[2023-12-07T17:18:19.589+0000] {taskinstance.py:1159} INFO - Dependencies all met for dep_context=requeueable deps ti=<TaskInstance: my_scraping_dag.main_task scheduled__2023-01-08T00:00:00+00:00 [queued]>
[2023-12-07T17:18:19.590+0000] {taskinstance.py:1361} INFO - Starting attempt 1 of 1
[2023-12-07T17:18:19.631+0000] {taskinstance.py:1382} INFO - Executing <Task(PythonOperator): main_task> on 2023-01-08 00:00:00+00:00
[2023-12-07T17:18:19.641+0000] {standard_task_runner.py:57} INFO - Started process 8559 to run task
[2023-12-07T17:18:19.644+0000] {standard_task_runner.py:84} INFO - Running: ['***', 'tasks', 'run', 'my_scraping_dag', 'main_task', 'scheduled__2023-01-08T00:00:00+00:00', '--job-id', '2537', '--raw', '--subdir', 'DAGS_FOLDER/main.py', '--cfg-path', '/tmp/tmpo99yyklg']
[2023-12-07T17:18:19.648+0000] {standard_task_runner.py:85} INFO - Job 2537: Subtask main_task
[2023-12-07T17:18:19.714+0000] {task_command.py:416} INFO - Running <TaskInstance: my_scraping_dag.main_task scheduled__2023-01-08T00:00:00+00:00 [running]> on host 63b0c7e341c0
[2023-12-07T17:18:19.845+0000] {taskinstance.py:1662} INFO - Exporting env vars: AIRFLOW_CTX_DAG_OWNER='***' AIRFLOW_CTX_DAG_ID='my_scraping_dag' AIRFLOW_CTX_TASK_ID='main_task' AIRFLOW_CTX_EXECUTION_DATE='2023-01-08T00:00:00+00:00' AIRFLOW_CTX_TRY_NUMBER='1' AIRFLOW_CTX_DAG_RUN_ID='scheduled__2023-01-08T00:00:00+00:00'
[2023-12-07T17:18:20.718+0000] {taskinstance.py:1937} ERROR - Task failed with exception
Traceback (most recent call last):
  File "/home/airflow/.local/lib/python3.8/site-packages/airflow/operators/python.py", line 192, in execute
    return_value = self.execute_callable()
  File "/home/airflow/.local/lib/python3.8/site-packages/airflow/operators/python.py", line 209, in execute_callable
    return self.python_callable(*self.op_args, **self.op_kwargs)
  File "/opt/airflow/dags/main.py", line 80, in main
    insert_data_to_db(products, db_params)
  File "/opt/airflow/dags/main.py", line 43, in insert_data_to_db
    with psycopg2.connect(**db_params) as conn:
  File "/home/airflow/.local/lib/python3.8/site-packages/psycopg2/__init__.py", line 122, in connect
    conn = _connect(dsn, connection_factory=connection_factory, **kwasync)
psycopg2.OperationalError: connection to server at "localhost" (127.0.0.1), port 5432 failed: Connection refused
	Is the server running on that host and accepting TCP/IP connections?
connection to server at "localhost" (::1), port 5432 failed: Cannot assign requested address
	Is the server running on that host and accepting TCP/IP connections?

[2023-12-07T17:18:20.724+0000] {taskinstance.py:1400} INFO - Marking task as FAILED. dag_id=my_scraping_dag, task_id=main_task, execution_date=20230108T000000, start_date=20231207T171819, end_date=20231207T171820
[2023-12-07T17:18:20.730+0000] {standard_task_runner.py:104} ERROR - Failed to execute job 2537 for task main_task (connection to server at "localhost" (127.0.0.1), port 5432 failed: Connection refused
	Is the server running on that host and accepting TCP/IP connections?
connection to server at "localhost" (::1), port 5432 failed: Cannot assign requested address
	Is the server running on that host and accepting TCP/IP connections?
; 8559)
[2023-12-07T17:18:20.750+0000] {local_task_job_runner.py:228} INFO - Task exited with return code 1
[2023-12-07T17:18:20.758+0000] {taskinstance.py:2778} INFO - 0 downstream tasks scheduled from follow-on schedule check
[2023-12-07T17:22:37.856+0000] {taskinstance.py:1159} INFO - Dependencies all met for dep_context=non-requeueable deps ti=<TaskInstance: my_scraping_dag.main_task scheduled__2023-01-08T00:00:00+00:00 [queued]>
[2023-12-07T17:22:37.863+0000] {taskinstance.py:1159} INFO - Dependencies all met for dep_context=requeueable deps ti=<TaskInstance: my_scraping_dag.main_task scheduled__2023-01-08T00:00:00+00:00 [queued]>
[2023-12-07T17:22:37.864+0000] {taskinstance.py:1361} INFO - Starting attempt 1 of 1
[2023-12-07T17:22:37.898+0000] {taskinstance.py:1382} INFO - Executing <Task(PythonOperator): main_task> on 2023-01-08 00:00:00+00:00
[2023-12-07T17:22:37.902+0000] {standard_task_runner.py:57} INFO - Started process 9353 to run task
[2023-12-07T17:22:37.907+0000] {standard_task_runner.py:84} INFO - Running: ['***', 'tasks', 'run', 'my_scraping_dag', 'main_task', 'scheduled__2023-01-08T00:00:00+00:00', '--job-id', '2879', '--raw', '--subdir', 'DAGS_FOLDER/main.py', '--cfg-path', '/tmp/tmpvisrwxgw']
[2023-12-07T17:22:37.911+0000] {standard_task_runner.py:85} INFO - Job 2879: Subtask main_task
[2023-12-07T17:22:37.977+0000] {task_command.py:416} INFO - Running <TaskInstance: my_scraping_dag.main_task scheduled__2023-01-08T00:00:00+00:00 [running]> on host 63b0c7e341c0
[2023-12-07T17:22:38.057+0000] {taskinstance.py:1662} INFO - Exporting env vars: AIRFLOW_CTX_DAG_OWNER='***' AIRFLOW_CTX_DAG_ID='my_scraping_dag' AIRFLOW_CTX_TASK_ID='main_task' AIRFLOW_CTX_EXECUTION_DATE='2023-01-08T00:00:00+00:00' AIRFLOW_CTX_TRY_NUMBER='1' AIRFLOW_CTX_DAG_RUN_ID='scheduled__2023-01-08T00:00:00+00:00'
[2023-12-07T17:22:38.961+0000] {taskinstance.py:1937} ERROR - Task failed with exception
Traceback (most recent call last):
  File "/home/airflow/.local/lib/python3.8/site-packages/airflow/operators/python.py", line 192, in execute
    return_value = self.execute_callable()
  File "/home/airflow/.local/lib/python3.8/site-packages/airflow/operators/python.py", line 209, in execute_callable
    return self.python_callable(*self.op_args, **self.op_kwargs)
  File "/opt/airflow/dags/main.py", line 73, in main
    insert_data_to_db(products, db_params)
  File "/opt/airflow/dags/main.py", line 40, in insert_data_to_db
    with psycopg2.connect(**db_params) as conn:
  File "/home/airflow/.local/lib/python3.8/site-packages/psycopg2/__init__.py", line 122, in connect
    conn = _connect(dsn, connection_factory=connection_factory, **kwasync)
psycopg2.OperationalError: connection to server at "localhost" (127.0.0.1), port 5432 failed: Connection refused
	Is the server running on that host and accepting TCP/IP connections?
connection to server at "localhost" (::1), port 5432 failed: Cannot assign requested address
	Is the server running on that host and accepting TCP/IP connections?

[2023-12-07T17:22:38.966+0000] {taskinstance.py:1400} INFO - Marking task as FAILED. dag_id=my_scraping_dag, task_id=main_task, execution_date=20230108T000000, start_date=20231207T172237, end_date=20231207T172238
[2023-12-07T17:22:38.971+0000] {standard_task_runner.py:104} ERROR - Failed to execute job 2879 for task main_task (connection to server at "localhost" (127.0.0.1), port 5432 failed: Connection refused
	Is the server running on that host and accepting TCP/IP connections?
connection to server at "localhost" (::1), port 5432 failed: Cannot assign requested address
	Is the server running on that host and accepting TCP/IP connections?
; 9353)
[2023-12-07T17:22:39.015+0000] {local_task_job_runner.py:228} INFO - Task exited with return code 1
[2023-12-07T17:22:39.024+0000] {taskinstance.py:2778} INFO - 0 downstream tasks scheduled from follow-on schedule check
[2023-12-07T17:28:18.926+0000] {taskinstance.py:1159} INFO - Dependencies all met for dep_context=non-requeueable deps ti=<TaskInstance: my_scraping_dag.main_task scheduled__2023-01-08T00:00:00+00:00 [queued]>
[2023-12-07T17:28:18.934+0000] {taskinstance.py:1159} INFO - Dependencies all met for dep_context=requeueable deps ti=<TaskInstance: my_scraping_dag.main_task scheduled__2023-01-08T00:00:00+00:00 [queued]>
[2023-12-07T17:28:18.937+0000] {taskinstance.py:1361} INFO - Starting attempt 1 of 1
[2023-12-07T17:28:18.978+0000] {taskinstance.py:1382} INFO - Executing <Task(PythonOperator): main_task> on 2023-01-08 00:00:00+00:00
[2023-12-07T17:28:18.997+0000] {standard_task_runner.py:84} INFO - Running: ['***', 'tasks', 'run', 'my_scraping_dag', 'main_task', 'scheduled__2023-01-08T00:00:00+00:00', '--job-id', '3221', '--raw', '--subdir', 'DAGS_FOLDER/main.py', '--cfg-path', '/tmp/tmp4f5br763']
[2023-12-07T17:28:19.001+0000] {standard_task_runner.py:57} INFO - Started process 10189 to run task
[2023-12-07T17:28:19.003+0000] {standard_task_runner.py:85} INFO - Job 3221: Subtask main_task
[2023-12-07T17:28:19.062+0000] {task_command.py:416} INFO - Running <TaskInstance: my_scraping_dag.main_task scheduled__2023-01-08T00:00:00+00:00 [running]> on host 63b0c7e341c0
[2023-12-07T17:28:19.219+0000] {taskinstance.py:1662} INFO - Exporting env vars: AIRFLOW_CTX_DAG_OWNER='***' AIRFLOW_CTX_DAG_ID='my_scraping_dag' AIRFLOW_CTX_TASK_ID='main_task' AIRFLOW_CTX_EXECUTION_DATE='2023-01-08T00:00:00+00:00' AIRFLOW_CTX_TRY_NUMBER='1' AIRFLOW_CTX_DAG_RUN_ID='scheduled__2023-01-08T00:00:00+00:00'
[2023-12-07T17:28:20.063+0000] {taskinstance.py:1937} ERROR - Task failed with exception
Traceback (most recent call last):
  File "/home/airflow/.local/lib/python3.8/site-packages/airflow/operators/python.py", line 192, in execute
    return_value = self.execute_callable()
  File "/home/airflow/.local/lib/python3.8/site-packages/airflow/operators/python.py", line 209, in execute_callable
    return self.python_callable(*self.op_args, **self.op_kwargs)
  File "/opt/airflow/dags/main.py", line 73, in main
    insert_data_to_db(products, db_params)
  File "/opt/airflow/dags/main.py", line 40, in insert_data_to_db
    with psycopg2.connect(**db_params) as conn:
  File "/home/airflow/.local/lib/python3.8/site-packages/psycopg2/__init__.py", line 122, in connect
    conn = _connect(dsn, connection_factory=connection_factory, **kwasync)
psycopg2.OperationalError: connection to server at "localhost" (127.0.0.1), port 5432 failed: Connection refused
	Is the server running on that host and accepting TCP/IP connections?
connection to server at "localhost" (::1), port 5432 failed: Cannot assign requested address
	Is the server running on that host and accepting TCP/IP connections?

[2023-12-07T17:28:20.069+0000] {taskinstance.py:1400} INFO - Marking task as FAILED. dag_id=my_scraping_dag, task_id=main_task, execution_date=20230108T000000, start_date=20231207T172818, end_date=20231207T172820
[2023-12-07T17:28:20.075+0000] {standard_task_runner.py:104} ERROR - Failed to execute job 3221 for task main_task (connection to server at "localhost" (127.0.0.1), port 5432 failed: Connection refused
	Is the server running on that host and accepting TCP/IP connections?
connection to server at "localhost" (::1), port 5432 failed: Cannot assign requested address
	Is the server running on that host and accepting TCP/IP connections?
; 10189)
[2023-12-07T17:28:20.114+0000] {local_task_job_runner.py:228} INFO - Task exited with return code 1
[2023-12-07T17:28:20.123+0000] {taskinstance.py:2778} INFO - 0 downstream tasks scheduled from follow-on schedule check
