[2023-12-07T14:52:19.486+0000] {taskinstance.py:1159} INFO - Dependencies all met for dep_context=non-requeueable deps ti=<TaskInstance: my_scraping_dag.main_task scheduled__2023-04-26T00:00:00+00:00 [queued]>
[2023-12-07T14:52:19.490+0000] {taskinstance.py:1159} INFO - Dependencies all met for dep_context=requeueable deps ti=<TaskInstance: my_scraping_dag.main_task scheduled__2023-04-26T00:00:00+00:00 [queued]>
[2023-12-07T14:52:19.491+0000] {taskinstance.py:1361} INFO - Starting attempt 1 of 1
[2023-12-07T14:52:19.498+0000] {taskinstance.py:1382} INFO - Executing <Task(PythonOperator): main_task> on 2023-04-26 00:00:00+00:00
[2023-12-07T14:52:19.501+0000] {standard_task_runner.py:57} INFO - Started process 991 to run task
[2023-12-07T14:52:19.504+0000] {standard_task_runner.py:84} INFO - Running: ['***', 'tasks', 'run', 'my_scraping_dag', 'main_task', 'scheduled__2023-04-26T00:00:00+00:00', '--job-id', '226', '--raw', '--subdir', 'DAGS_FOLDER/main.py', '--cfg-path', '/tmp/tmpeok4gmrx']
[2023-12-07T14:52:19.505+0000] {standard_task_runner.py:85} INFO - Job 226: Subtask main_task
[2023-12-07T14:52:19.531+0000] {task_command.py:416} INFO - Running <TaskInstance: my_scraping_dag.main_task scheduled__2023-04-26T00:00:00+00:00 [running]> on host 63b0c7e341c0
[2023-12-07T14:52:19.565+0000] {taskinstance.py:1662} INFO - Exporting env vars: AIRFLOW_CTX_DAG_OWNER='***' AIRFLOW_CTX_DAG_ID='my_scraping_dag' AIRFLOW_CTX_TASK_ID='main_task' AIRFLOW_CTX_EXECUTION_DATE='2023-04-26T00:00:00+00:00' AIRFLOW_CTX_TRY_NUMBER='1' AIRFLOW_CTX_DAG_RUN_ID='scheduled__2023-04-26T00:00:00+00:00'
[2023-12-07T14:52:19.565+0000] {taskinstance.py:1937} ERROR - Task failed with exception
Traceback (most recent call last):
  File "/usr/local/lib/python3.8/configparser.py", line 846, in items
    d.update(self._sections[section])
KeyError: 'web'

During handling of the above exception, another exception occurred:

Traceback (most recent call last):
  File "/home/airflow/.local/lib/python3.8/site-packages/airflow/operators/python.py", line 192, in execute
    return_value = self.execute_callable()
  File "/home/airflow/.local/lib/python3.8/site-packages/airflow/operators/python.py", line 209, in execute_callable
    return self.python_callable(*self.op_args, **self.op_kwargs)
  File "/opt/airflow/dags/main.py", line 61, in main
    config = get_config('web')
  File "/opt/airflow/dags/main.py", line 23, in get_config
    return {key: value for key, value in parser.items(section)}
  File "/usr/local/lib/python3.8/configparser.py", line 849, in items
    raise NoSectionError(section)
configparser.NoSectionError: No section: 'web'
[2023-12-07T14:52:19.570+0000] {taskinstance.py:1400} INFO - Marking task as FAILED. dag_id=my_scraping_dag, task_id=main_task, execution_date=20230426T000000, start_date=20231207T145219, end_date=20231207T145219
[2023-12-07T14:52:19.574+0000] {standard_task_runner.py:104} ERROR - Failed to execute job 226 for task main_task (No section: 'web'; 991)
[2023-12-07T14:52:19.596+0000] {local_task_job_runner.py:228} INFO - Task exited with return code 1
[2023-12-07T14:52:19.609+0000] {taskinstance.py:2778} INFO - 0 downstream tasks scheduled from follow-on schedule check
[2023-12-07T16:32:14.417+0000] {taskinstance.py:1159} INFO - Dependencies all met for dep_context=non-requeueable deps ti=<TaskInstance: my_scraping_dag.main_task scheduled__2023-04-26T00:00:00+00:00 [queued]>
[2023-12-07T16:32:14.423+0000] {taskinstance.py:1159} INFO - Dependencies all met for dep_context=requeueable deps ti=<TaskInstance: my_scraping_dag.main_task scheduled__2023-04-26T00:00:00+00:00 [queued]>
[2023-12-07T16:32:14.424+0000] {taskinstance.py:1361} INFO - Starting attempt 1 of 1
[2023-12-07T16:32:14.434+0000] {taskinstance.py:1382} INFO - Executing <Task(PythonOperator): main_task> on 2023-04-26 00:00:00+00:00
[2023-12-07T16:32:14.438+0000] {standard_task_runner.py:57} INFO - Started process 3770 to run task
[2023-12-07T16:32:14.440+0000] {standard_task_runner.py:84} INFO - Running: ['***', 'tasks', 'run', 'my_scraping_dag', 'main_task', 'scheduled__2023-04-26T00:00:00+00:00', '--job-id', '704', '--raw', '--subdir', 'DAGS_FOLDER/main.py', '--cfg-path', '/tmp/tmpww_163bl']
[2023-12-07T16:32:14.443+0000] {standard_task_runner.py:85} INFO - Job 704: Subtask main_task
[2023-12-07T16:32:14.472+0000] {task_command.py:416} INFO - Running <TaskInstance: my_scraping_dag.main_task scheduled__2023-04-26T00:00:00+00:00 [running]> on host 63b0c7e341c0
[2023-12-07T16:32:14.511+0000] {taskinstance.py:1662} INFO - Exporting env vars: AIRFLOW_CTX_DAG_OWNER='***' AIRFLOW_CTX_DAG_ID='my_scraping_dag' AIRFLOW_CTX_TASK_ID='main_task' AIRFLOW_CTX_EXECUTION_DATE='2023-04-26T00:00:00+00:00' AIRFLOW_CTX_TRY_NUMBER='1' AIRFLOW_CTX_DAG_RUN_ID='scheduled__2023-04-26T00:00:00+00:00'
[2023-12-07T16:32:14.512+0000] {taskinstance.py:1937} ERROR - Task failed with exception
Traceback (most recent call last):
  File "/usr/local/lib/python3.8/configparser.py", line 846, in items
    d.update(self._sections[section])
KeyError: 'web'

During handling of the above exception, another exception occurred:

Traceback (most recent call last):
  File "/home/airflow/.local/lib/python3.8/site-packages/airflow/operators/python.py", line 192, in execute
    return_value = self.execute_callable()
  File "/home/airflow/.local/lib/python3.8/site-packages/airflow/operators/python.py", line 209, in execute_callable
    return self.python_callable(*self.op_args, **self.op_kwargs)
  File "/opt/airflow/dags/main.py", line 60, in main
    config = get_config('web')
  File "/opt/airflow/dags/main.py", line 22, in get_config
    return {key: value for key, value in parser.items(section)}
  File "/usr/local/lib/python3.8/configparser.py", line 849, in items
    raise NoSectionError(section)
configparser.NoSectionError: No section: 'web'
[2023-12-07T16:32:14.517+0000] {taskinstance.py:1400} INFO - Marking task as FAILED. dag_id=my_scraping_dag, task_id=main_task, execution_date=20230426T000000, start_date=20231207T163214, end_date=20231207T163214
[2023-12-07T16:32:14.522+0000] {standard_task_runner.py:104} ERROR - Failed to execute job 704 for task main_task (No section: 'web'; 3770)
[2023-12-07T16:32:14.536+0000] {local_task_job_runner.py:228} INFO - Task exited with return code 1
[2023-12-07T16:32:14.550+0000] {taskinstance.py:2778} INFO - 0 downstream tasks scheduled from follow-on schedule check
[2023-12-07T16:41:34.709+0000] {taskinstance.py:1159} INFO - Dependencies all met for dep_context=non-requeueable deps ti=<TaskInstance: my_scraping_dag.main_task scheduled__2023-04-26T00:00:00+00:00 [queued]>
[2023-12-07T16:41:34.714+0000] {taskinstance.py:1159} INFO - Dependencies all met for dep_context=requeueable deps ti=<TaskInstance: my_scraping_dag.main_task scheduled__2023-04-26T00:00:00+00:00 [queued]>
[2023-12-07T16:41:34.714+0000] {taskinstance.py:1361} INFO - Starting attempt 1 of 1
[2023-12-07T16:41:34.746+0000] {taskinstance.py:1382} INFO - Executing <Task(PythonOperator): main_task> on 2023-04-26 00:00:00+00:00
[2023-12-07T16:41:34.750+0000] {standard_task_runner.py:57} INFO - Started process 4671 to run task
[2023-12-07T16:41:34.753+0000] {standard_task_runner.py:84} INFO - Running: ['***', 'tasks', 'run', 'my_scraping_dag', 'main_task', 'scheduled__2023-04-26T00:00:00+00:00', '--job-id', '1046', '--raw', '--subdir', 'DAGS_FOLDER/main.py', '--cfg-path', '/tmp/tmpf238zq6o']
[2023-12-07T16:41:34.755+0000] {standard_task_runner.py:85} INFO - Job 1046: Subtask main_task
[2023-12-07T16:41:34.786+0000] {task_command.py:416} INFO - Running <TaskInstance: my_scraping_dag.main_task scheduled__2023-04-26T00:00:00+00:00 [running]> on host 63b0c7e341c0
[2023-12-07T16:41:34.825+0000] {taskinstance.py:1662} INFO - Exporting env vars: AIRFLOW_CTX_DAG_OWNER='***' AIRFLOW_CTX_DAG_ID='my_scraping_dag' AIRFLOW_CTX_TASK_ID='main_task' AIRFLOW_CTX_EXECUTION_DATE='2023-04-26T00:00:00+00:00' AIRFLOW_CTX_TRY_NUMBER='1' AIRFLOW_CTX_DAG_RUN_ID='scheduled__2023-04-26T00:00:00+00:00'
[2023-12-07T16:41:34.826+0000] {taskinstance.py:1937} ERROR - Task failed with exception
Traceback (most recent call last):
  File "/usr/local/lib/python3.8/configparser.py", line 846, in items
    d.update(self._sections[section])
KeyError: 'web'

During handling of the above exception, another exception occurred:

Traceback (most recent call last):
  File "/home/airflow/.local/lib/python3.8/site-packages/airflow/operators/python.py", line 192, in execute
    return_value = self.execute_callable()
  File "/home/airflow/.local/lib/python3.8/site-packages/airflow/operators/python.py", line 209, in execute_callable
    return self.python_callable(*self.op_args, **self.op_kwargs)
  File "/opt/airflow/dags/main.py", line 60, in main
    config = get_config('web')
  File "/opt/airflow/dags/main.py", line 22, in get_config
    return {key: value for key, value in parser.items(section)}
  File "/usr/local/lib/python3.8/configparser.py", line 849, in items
    raise NoSectionError(section)
configparser.NoSectionError: No section: 'web'
[2023-12-07T16:41:34.832+0000] {taskinstance.py:1400} INFO - Marking task as FAILED. dag_id=my_scraping_dag, task_id=main_task, execution_date=20230426T000000, start_date=20231207T164134, end_date=20231207T164134
[2023-12-07T16:41:34.841+0000] {standard_task_runner.py:104} ERROR - Failed to execute job 1046 for task main_task (No section: 'web'; 4671)
[2023-12-07T16:41:34.887+0000] {local_task_job_runner.py:228} INFO - Task exited with return code 1
[2023-12-07T16:41:34.909+0000] {taskinstance.py:2778} INFO - 0 downstream tasks scheduled from follow-on schedule check
[2023-12-07T17:00:38.734+0000] {taskinstance.py:1159} INFO - Dependencies all met for dep_context=non-requeueable deps ti=<TaskInstance: my_scraping_dag.main_task scheduled__2023-04-26T00:00:00+00:00 [queued]>
[2023-12-07T17:00:38.738+0000] {taskinstance.py:1159} INFO - Dependencies all met for dep_context=requeueable deps ti=<TaskInstance: my_scraping_dag.main_task scheduled__2023-04-26T00:00:00+00:00 [queued]>
[2023-12-07T17:00:38.738+0000] {taskinstance.py:1361} INFO - Starting attempt 1 of 1
[2023-12-07T17:00:38.744+0000] {taskinstance.py:1382} INFO - Executing <Task(PythonOperator): main_task> on 2023-04-26 00:00:00+00:00
[2023-12-07T17:00:38.747+0000] {standard_task_runner.py:57} INFO - Started process 5835 to run task
[2023-12-07T17:00:38.749+0000] {standard_task_runner.py:84} INFO - Running: ['***', 'tasks', 'run', 'my_scraping_dag', 'main_task', 'scheduled__2023-04-26T00:00:00+00:00', '--job-id', '1390', '--raw', '--subdir', 'DAGS_FOLDER/main.py', '--cfg-path', '/tmp/tmpj79m126k']
[2023-12-07T17:00:38.751+0000] {standard_task_runner.py:85} INFO - Job 1390: Subtask main_task
[2023-12-07T17:00:38.776+0000] {task_command.py:416} INFO - Running <TaskInstance: my_scraping_dag.main_task scheduled__2023-04-26T00:00:00+00:00 [running]> on host 63b0c7e341c0
[2023-12-07T17:00:38.812+0000] {taskinstance.py:1662} INFO - Exporting env vars: AIRFLOW_CTX_DAG_OWNER='***' AIRFLOW_CTX_DAG_ID='my_scraping_dag' AIRFLOW_CTX_TASK_ID='main_task' AIRFLOW_CTX_EXECUTION_DATE='2023-04-26T00:00:00+00:00' AIRFLOW_CTX_TRY_NUMBER='1' AIRFLOW_CTX_DAG_RUN_ID='scheduled__2023-04-26T00:00:00+00:00'
[2023-12-07T17:00:38.837+0000] {logging_mixin.py:154} INFO - base_url: https://tuncbotanik.com
[2023-12-07T17:00:38.837+0000] {python.py:194} INFO - Done. Returned value was: ('https://tuncbotanik.com', {'User-Agent': 'Mozilla/5.0 (Macintosh; Intel Mac OS X 10_15_7) AppleWebKit/537.36 (KHTML, like Gecko) Chrome/119.0.0.0 Safari/537.36', 'Accept-Language': 'tr-TR,tr;q=0.9,en-US;q=0.8,en;q=0.7'}, {'dbname': 'plant', 'user': 'aozgokme', 'password': '***', 'host': 'localhost', 'port': '5432'})
[2023-12-07T17:00:38.848+0000] {taskinstance.py:1400} INFO - Marking task as SUCCESS. dag_id=my_scraping_dag, task_id=main_task, execution_date=20230426T000000, start_date=20231207T170038, end_date=20231207T170038
[2023-12-07T17:00:38.882+0000] {local_task_job_runner.py:228} INFO - Task exited with return code 0
[2023-12-07T17:00:38.921+0000] {taskinstance.py:2778} INFO - 0 downstream tasks scheduled from follow-on schedule check
[2023-12-07T17:03:54.861+0000] {taskinstance.py:1159} INFO - Dependencies all met for dep_context=non-requeueable deps ti=<TaskInstance: my_scraping_dag.main_task scheduled__2023-04-26T00:00:00+00:00 [queued]>
[2023-12-07T17:03:54.868+0000] {taskinstance.py:1159} INFO - Dependencies all met for dep_context=requeueable deps ti=<TaskInstance: my_scraping_dag.main_task scheduled__2023-04-26T00:00:00+00:00 [queued]>
[2023-12-07T17:03:54.869+0000] {taskinstance.py:1361} INFO - Starting attempt 1 of 1
[2023-12-07T17:03:54.880+0000] {taskinstance.py:1382} INFO - Executing <Task(PythonOperator): main_task> on 2023-04-26 00:00:00+00:00
[2023-12-07T17:03:54.885+0000] {standard_task_runner.py:57} INFO - Started process 7267 to run task
[2023-12-07T17:03:54.900+0000] {standard_task_runner.py:84} INFO - Running: ['***', 'tasks', 'run', 'my_scraping_dag', 'main_task', 'scheduled__2023-04-26T00:00:00+00:00', '--job-id', '2069', '--raw', '--subdir', 'DAGS_FOLDER/main.py', '--cfg-path', '/tmp/tmp916y_bdy']
[2023-12-07T17:03:54.903+0000] {standard_task_runner.py:85} INFO - Job 2069: Subtask main_task
[2023-12-07T17:03:54.951+0000] {task_command.py:416} INFO - Running <TaskInstance: my_scraping_dag.main_task scheduled__2023-04-26T00:00:00+00:00 [running]> on host 63b0c7e341c0
[2023-12-07T17:03:55.017+0000] {taskinstance.py:1662} INFO - Exporting env vars: AIRFLOW_CTX_DAG_OWNER='***' AIRFLOW_CTX_DAG_ID='my_scraping_dag' AIRFLOW_CTX_TASK_ID='main_task' AIRFLOW_CTX_EXECUTION_DATE='2023-04-26T00:00:00+00:00' AIRFLOW_CTX_TRY_NUMBER='1' AIRFLOW_CTX_DAG_RUN_ID='scheduled__2023-04-26T00:00:00+00:00'
[2023-12-07T17:03:55.070+0000] {logging_mixin.py:154} INFO - base_url: https://tuncbotanik.com
[2023-12-07T17:03:55.071+0000] {python.py:194} INFO - Done. Returned value was: ('https://tuncbotanik.com', {'User-Agent': 'Mozilla/5.0 (Macintosh; Intel Mac OS X 10_15_7) AppleWebKit/537.36 (KHTML, like Gecko) Chrome/119.0.0.0 Safari/537.36', 'Accept-Language': 'tr-TR,tr;q=0.9,en-US;q=0.8,en;q=0.7'}, {'dbname': 'plant', 'user': 'aozgokme', 'password': '***', 'host': 'localhost', 'port': '5432'})
[2023-12-07T17:03:55.102+0000] {taskinstance.py:1400} INFO - Marking task as SUCCESS. dag_id=my_scraping_dag, task_id=main_task, execution_date=20230426T000000, start_date=20231207T170354, end_date=20231207T170355
[2023-12-07T17:03:55.150+0000] {local_task_job_runner.py:228} INFO - Task exited with return code 0
[2023-12-07T17:03:55.173+0000] {taskinstance.py:2778} INFO - 1 downstream tasks scheduled from follow-on schedule check
[2023-12-07T17:18:42.489+0000] {taskinstance.py:1159} INFO - Dependencies all met for dep_context=non-requeueable deps ti=<TaskInstance: my_scraping_dag.main_task scheduled__2023-04-26T00:00:00+00:00 [queued]>
[2023-12-07T17:18:42.494+0000] {taskinstance.py:1159} INFO - Dependencies all met for dep_context=requeueable deps ti=<TaskInstance: my_scraping_dag.main_task scheduled__2023-04-26T00:00:00+00:00 [queued]>
[2023-12-07T17:18:42.494+0000] {taskinstance.py:1361} INFO - Starting attempt 1 of 1
[2023-12-07T17:18:42.502+0000] {taskinstance.py:1382} INFO - Executing <Task(PythonOperator): main_task> on 2023-04-26 00:00:00+00:00
[2023-12-07T17:18:42.504+0000] {standard_task_runner.py:57} INFO - Started process 8779 to run task
[2023-12-07T17:18:42.507+0000] {standard_task_runner.py:84} INFO - Running: ['***', 'tasks', 'run', 'my_scraping_dag', 'main_task', 'scheduled__2023-04-26T00:00:00+00:00', '--job-id', '2645', '--raw', '--subdir', 'DAGS_FOLDER/main.py', '--cfg-path', '/tmp/tmph2lzn67r']
[2023-12-07T17:18:42.510+0000] {standard_task_runner.py:85} INFO - Job 2645: Subtask main_task
[2023-12-07T17:18:42.539+0000] {task_command.py:416} INFO - Running <TaskInstance: my_scraping_dag.main_task scheduled__2023-04-26T00:00:00+00:00 [running]> on host 63b0c7e341c0
[2023-12-07T17:18:42.582+0000] {taskinstance.py:1662} INFO - Exporting env vars: AIRFLOW_CTX_DAG_OWNER='***' AIRFLOW_CTX_DAG_ID='my_scraping_dag' AIRFLOW_CTX_TASK_ID='main_task' AIRFLOW_CTX_EXECUTION_DATE='2023-04-26T00:00:00+00:00' AIRFLOW_CTX_TRY_NUMBER='1' AIRFLOW_CTX_DAG_RUN_ID='scheduled__2023-04-26T00:00:00+00:00'
[2023-12-07T17:18:43.269+0000] {taskinstance.py:1937} ERROR - Task failed with exception
Traceback (most recent call last):
  File "/home/airflow/.local/lib/python3.8/site-packages/airflow/operators/python.py", line 192, in execute
    return_value = self.execute_callable()
  File "/home/airflow/.local/lib/python3.8/site-packages/airflow/operators/python.py", line 209, in execute_callable
    return self.python_callable(*self.op_args, **self.op_kwargs)
  File "/opt/airflow/dags/main.py", line 80, in main
    insert_data_to_db(products, db_params)
  File "/opt/airflow/dags/main.py", line 43, in insert_data_to_db
    with psycopg2.connect(**db_params) as conn:
  File "/home/airflow/.local/lib/python3.8/site-packages/psycopg2/__init__.py", line 122, in connect
    conn = _connect(dsn, connection_factory=connection_factory, **kwasync)
psycopg2.OperationalError: connection to server at "localhost" (127.0.0.1), port 5432 failed: Connection refused
	Is the server running on that host and accepting TCP/IP connections?
connection to server at "localhost" (::1), port 5432 failed: Cannot assign requested address
	Is the server running on that host and accepting TCP/IP connections?

[2023-12-07T17:18:43.275+0000] {taskinstance.py:1400} INFO - Marking task as FAILED. dag_id=my_scraping_dag, task_id=main_task, execution_date=20230426T000000, start_date=20231207T171842, end_date=20231207T171843
[2023-12-07T17:18:43.280+0000] {standard_task_runner.py:104} ERROR - Failed to execute job 2645 for task main_task (connection to server at "localhost" (127.0.0.1), port 5432 failed: Connection refused
	Is the server running on that host and accepting TCP/IP connections?
connection to server at "localhost" (::1), port 5432 failed: Cannot assign requested address
	Is the server running on that host and accepting TCP/IP connections?
; 8779)
[2023-12-07T17:18:43.325+0000] {local_task_job_runner.py:228} INFO - Task exited with return code 1
[2023-12-07T17:18:43.334+0000] {taskinstance.py:2778} INFO - 0 downstream tasks scheduled from follow-on schedule check
[2023-12-07T17:23:00.289+0000] {taskinstance.py:1159} INFO - Dependencies all met for dep_context=non-requeueable deps ti=<TaskInstance: my_scraping_dag.main_task scheduled__2023-04-26T00:00:00+00:00 [queued]>
[2023-12-07T17:23:00.293+0000] {taskinstance.py:1159} INFO - Dependencies all met for dep_context=requeueable deps ti=<TaskInstance: my_scraping_dag.main_task scheduled__2023-04-26T00:00:00+00:00 [queued]>
[2023-12-07T17:23:00.294+0000] {taskinstance.py:1361} INFO - Starting attempt 1 of 1
[2023-12-07T17:23:00.303+0000] {taskinstance.py:1382} INFO - Executing <Task(PythonOperator): main_task> on 2023-04-26 00:00:00+00:00
[2023-12-07T17:23:00.306+0000] {standard_task_runner.py:57} INFO - Started process 9581 to run task
[2023-12-07T17:23:00.309+0000] {standard_task_runner.py:84} INFO - Running: ['***', 'tasks', 'run', 'my_scraping_dag', 'main_task', 'scheduled__2023-04-26T00:00:00+00:00', '--job-id', '2987', '--raw', '--subdir', 'DAGS_FOLDER/main.py', '--cfg-path', '/tmp/tmpekwjn4zf']
[2023-12-07T17:23:00.312+0000] {standard_task_runner.py:85} INFO - Job 2987: Subtask main_task
[2023-12-07T17:23:00.344+0000] {task_command.py:416} INFO - Running <TaskInstance: my_scraping_dag.main_task scheduled__2023-04-26T00:00:00+00:00 [running]> on host 63b0c7e341c0
[2023-12-07T17:23:00.390+0000] {taskinstance.py:1662} INFO - Exporting env vars: AIRFLOW_CTX_DAG_OWNER='***' AIRFLOW_CTX_DAG_ID='my_scraping_dag' AIRFLOW_CTX_TASK_ID='main_task' AIRFLOW_CTX_EXECUTION_DATE='2023-04-26T00:00:00+00:00' AIRFLOW_CTX_TRY_NUMBER='1' AIRFLOW_CTX_DAG_RUN_ID='scheduled__2023-04-26T00:00:00+00:00'
[2023-12-07T17:23:01.235+0000] {taskinstance.py:1937} ERROR - Task failed with exception
Traceback (most recent call last):
  File "/home/airflow/.local/lib/python3.8/site-packages/airflow/operators/python.py", line 192, in execute
    return_value = self.execute_callable()
  File "/home/airflow/.local/lib/python3.8/site-packages/airflow/operators/python.py", line 209, in execute_callable
    return self.python_callable(*self.op_args, **self.op_kwargs)
  File "/opt/airflow/dags/main.py", line 73, in main
    insert_data_to_db(products, db_params)
  File "/opt/airflow/dags/main.py", line 40, in insert_data_to_db
    with psycopg2.connect(**db_params) as conn:
  File "/home/airflow/.local/lib/python3.8/site-packages/psycopg2/__init__.py", line 122, in connect
    conn = _connect(dsn, connection_factory=connection_factory, **kwasync)
psycopg2.OperationalError: connection to server at "localhost" (127.0.0.1), port 5432 failed: Connection refused
	Is the server running on that host and accepting TCP/IP connections?
connection to server at "localhost" (::1), port 5432 failed: Cannot assign requested address
	Is the server running on that host and accepting TCP/IP connections?

[2023-12-07T17:23:01.240+0000] {taskinstance.py:1400} INFO - Marking task as FAILED. dag_id=my_scraping_dag, task_id=main_task, execution_date=20230426T000000, start_date=20231207T172300, end_date=20231207T172301
[2023-12-07T17:23:01.245+0000] {standard_task_runner.py:104} ERROR - Failed to execute job 2987 for task main_task (connection to server at "localhost" (127.0.0.1), port 5432 failed: Connection refused
	Is the server running on that host and accepting TCP/IP connections?
connection to server at "localhost" (::1), port 5432 failed: Cannot assign requested address
	Is the server running on that host and accepting TCP/IP connections?
; 9581)
[2023-12-07T17:23:01.291+0000] {local_task_job_runner.py:228} INFO - Task exited with return code 1
[2023-12-07T17:23:01.302+0000] {taskinstance.py:2778} INFO - 0 downstream tasks scheduled from follow-on schedule check
[2023-12-07T17:28:42.851+0000] {taskinstance.py:1159} INFO - Dependencies all met for dep_context=non-requeueable deps ti=<TaskInstance: my_scraping_dag.main_task scheduled__2023-04-26T00:00:00+00:00 [queued]>
[2023-12-07T17:28:42.855+0000] {taskinstance.py:1159} INFO - Dependencies all met for dep_context=requeueable deps ti=<TaskInstance: my_scraping_dag.main_task scheduled__2023-04-26T00:00:00+00:00 [queued]>
[2023-12-07T17:28:42.856+0000] {taskinstance.py:1361} INFO - Starting attempt 1 of 1
[2023-12-07T17:28:42.878+0000] {taskinstance.py:1382} INFO - Executing <Task(PythonOperator): main_task> on 2023-04-26 00:00:00+00:00
[2023-12-07T17:28:42.880+0000] {standard_task_runner.py:57} INFO - Started process 10416 to run task
[2023-12-07T17:28:42.882+0000] {standard_task_runner.py:84} INFO - Running: ['***', 'tasks', 'run', 'my_scraping_dag', 'main_task', 'scheduled__2023-04-26T00:00:00+00:00', '--job-id', '3329', '--raw', '--subdir', 'DAGS_FOLDER/main.py', '--cfg-path', '/tmp/tmp0il2k74e']
[2023-12-07T17:28:42.884+0000] {standard_task_runner.py:85} INFO - Job 3329: Subtask main_task
[2023-12-07T17:28:42.911+0000] {task_command.py:416} INFO - Running <TaskInstance: my_scraping_dag.main_task scheduled__2023-04-26T00:00:00+00:00 [running]> on host 63b0c7e341c0
[2023-12-07T17:28:42.945+0000] {taskinstance.py:1662} INFO - Exporting env vars: AIRFLOW_CTX_DAG_OWNER='***' AIRFLOW_CTX_DAG_ID='my_scraping_dag' AIRFLOW_CTX_TASK_ID='main_task' AIRFLOW_CTX_EXECUTION_DATE='2023-04-26T00:00:00+00:00' AIRFLOW_CTX_TRY_NUMBER='1' AIRFLOW_CTX_DAG_RUN_ID='scheduled__2023-04-26T00:00:00+00:00'
[2023-12-07T17:28:43.683+0000] {taskinstance.py:1937} ERROR - Task failed with exception
Traceback (most recent call last):
  File "/home/airflow/.local/lib/python3.8/site-packages/airflow/operators/python.py", line 192, in execute
    return_value = self.execute_callable()
  File "/home/airflow/.local/lib/python3.8/site-packages/airflow/operators/python.py", line 209, in execute_callable
    return self.python_callable(*self.op_args, **self.op_kwargs)
  File "/opt/airflow/dags/main.py", line 73, in main
    insert_data_to_db(products, db_params)
  File "/opt/airflow/dags/main.py", line 40, in insert_data_to_db
    with psycopg2.connect(**db_params) as conn:
  File "/home/airflow/.local/lib/python3.8/site-packages/psycopg2/__init__.py", line 122, in connect
    conn = _connect(dsn, connection_factory=connection_factory, **kwasync)
psycopg2.OperationalError: connection to server at "localhost" (127.0.0.1), port 5432 failed: Connection refused
	Is the server running on that host and accepting TCP/IP connections?
connection to server at "localhost" (::1), port 5432 failed: Cannot assign requested address
	Is the server running on that host and accepting TCP/IP connections?

[2023-12-07T17:28:43.691+0000] {taskinstance.py:1400} INFO - Marking task as FAILED. dag_id=my_scraping_dag, task_id=main_task, execution_date=20230426T000000, start_date=20231207T172842, end_date=20231207T172843
[2023-12-07T17:28:43.703+0000] {standard_task_runner.py:104} ERROR - Failed to execute job 3329 for task main_task (connection to server at "localhost" (127.0.0.1), port 5432 failed: Connection refused
	Is the server running on that host and accepting TCP/IP connections?
connection to server at "localhost" (::1), port 5432 failed: Cannot assign requested address
	Is the server running on that host and accepting TCP/IP connections?
; 10416)
[2023-12-07T17:28:43.739+0000] {local_task_job_runner.py:228} INFO - Task exited with return code 1
[2023-12-07T17:28:43.748+0000] {taskinstance.py:2778} INFO - 0 downstream tasks scheduled from follow-on schedule check
