[2023-12-07T14:45:37.036+0000] {taskinstance.py:1159} INFO - Dependencies all met for dep_context=non-requeueable deps ti=<TaskInstance: my_scraping_dag.main_task scheduled__2023-02-01T00:00:00+00:00 [queued]>
[2023-12-07T14:45:37.041+0000] {taskinstance.py:1159} INFO - Dependencies all met for dep_context=requeueable deps ti=<TaskInstance: my_scraping_dag.main_task scheduled__2023-02-01T00:00:00+00:00 [queued]>
[2023-12-07T14:45:37.042+0000] {taskinstance.py:1361} INFO - Starting attempt 1 of 1
[2023-12-07T14:45:37.062+0000] {taskinstance.py:1382} INFO - Executing <Task(PythonOperator): main_task> on 2023-02-01 00:00:00+00:00
[2023-12-07T14:45:37.065+0000] {standard_task_runner.py:57} INFO - Started process 450 to run task
[2023-12-07T14:45:37.068+0000] {standard_task_runner.py:84} INFO - Running: ['***', 'tasks', 'run', 'my_scraping_dag', 'main_task', 'scheduled__2023-02-01T00:00:00+00:00', '--job-id', '43', '--raw', '--subdir', 'DAGS_FOLDER/main.py', '--cfg-path', '/tmp/tmpsno3fkld']
[2023-12-07T14:45:37.070+0000] {standard_task_runner.py:85} INFO - Job 43: Subtask main_task
[2023-12-07T14:45:37.099+0000] {task_command.py:416} INFO - Running <TaskInstance: my_scraping_dag.main_task scheduled__2023-02-01T00:00:00+00:00 [running]> on host 63b0c7e341c0
[2023-12-07T14:45:37.135+0000] {taskinstance.py:1662} INFO - Exporting env vars: AIRFLOW_CTX_DAG_OWNER='***' AIRFLOW_CTX_DAG_ID='my_scraping_dag' AIRFLOW_CTX_TASK_ID='main_task' AIRFLOW_CTX_EXECUTION_DATE='2023-02-01T00:00:00+00:00' AIRFLOW_CTX_TRY_NUMBER='1' AIRFLOW_CTX_DAG_RUN_ID='scheduled__2023-02-01T00:00:00+00:00'
[2023-12-07T14:45:37.136+0000] {taskinstance.py:1937} ERROR - Task failed with exception
Traceback (most recent call last):
  File "/usr/local/lib/python3.8/configparser.py", line 846, in items
    d.update(self._sections[section])
KeyError: 'web'

During handling of the above exception, another exception occurred:

Traceback (most recent call last):
  File "/home/airflow/.local/lib/python3.8/site-packages/airflow/operators/python.py", line 192, in execute
    return_value = self.execute_callable()
  File "/home/airflow/.local/lib/python3.8/site-packages/airflow/operators/python.py", line 209, in execute_callable
    return self.python_callable(*self.op_args, **self.op_kwargs)
  File "/opt/airflow/dags/main.py", line 61, in main
    config = get_config('web')
  File "/opt/airflow/dags/main.py", line 23, in get_config
    return {key: value for key, value in parser.items(section)}
  File "/usr/local/lib/python3.8/configparser.py", line 849, in items
    raise NoSectionError(section)
configparser.NoSectionError: No section: 'web'
[2023-12-07T14:45:37.143+0000] {taskinstance.py:1400} INFO - Marking task as FAILED. dag_id=my_scraping_dag, task_id=main_task, execution_date=20230201T000000, start_date=20231207T144537, end_date=20231207T144537
[2023-12-07T14:45:37.151+0000] {standard_task_runner.py:104} ERROR - Failed to execute job 43 for task main_task (No section: 'web'; 450)
[2023-12-07T14:45:37.160+0000] {local_task_job_runner.py:228} INFO - Task exited with return code 1
[2023-12-07T14:45:37.206+0000] {taskinstance.py:2778} INFO - 0 downstream tasks scheduled from follow-on schedule check
[2023-12-07T14:51:30.034+0000] {taskinstance.py:1159} INFO - Dependencies all met for dep_context=non-requeueable deps ti=<TaskInstance: my_scraping_dag.main_task scheduled__2023-02-01T00:00:00+00:00 [queued]>
[2023-12-07T14:51:30.040+0000] {taskinstance.py:1159} INFO - Dependencies all met for dep_context=requeueable deps ti=<TaskInstance: my_scraping_dag.main_task scheduled__2023-02-01T00:00:00+00:00 [queued]>
[2023-12-07T14:51:30.040+0000] {taskinstance.py:1361} INFO - Starting attempt 1 of 1
[2023-12-07T14:51:30.048+0000] {taskinstance.py:1382} INFO - Executing <Task(PythonOperator): main_task> on 2023-02-01 00:00:00+00:00
[2023-12-07T14:51:30.051+0000] {standard_task_runner.py:57} INFO - Started process 796 to run task
[2023-12-07T14:51:30.055+0000] {standard_task_runner.py:84} INFO - Running: ['***', 'tasks', 'run', 'my_scraping_dag', 'main_task', 'scheduled__2023-02-01T00:00:00+00:00', '--job-id', '142', '--raw', '--subdir', 'DAGS_FOLDER/main.py', '--cfg-path', '/tmp/tmphgcj_daq']
[2023-12-07T14:51:30.057+0000] {standard_task_runner.py:85} INFO - Job 142: Subtask main_task
[2023-12-07T14:51:30.084+0000] {task_command.py:416} INFO - Running <TaskInstance: my_scraping_dag.main_task scheduled__2023-02-01T00:00:00+00:00 [running]> on host 63b0c7e341c0
[2023-12-07T14:51:30.128+0000] {taskinstance.py:1662} INFO - Exporting env vars: AIRFLOW_CTX_DAG_OWNER='***' AIRFLOW_CTX_DAG_ID='my_scraping_dag' AIRFLOW_CTX_TASK_ID='main_task' AIRFLOW_CTX_EXECUTION_DATE='2023-02-01T00:00:00+00:00' AIRFLOW_CTX_TRY_NUMBER='1' AIRFLOW_CTX_DAG_RUN_ID='scheduled__2023-02-01T00:00:00+00:00'
[2023-12-07T14:51:30.129+0000] {taskinstance.py:1937} ERROR - Task failed with exception
Traceback (most recent call last):
  File "/usr/local/lib/python3.8/configparser.py", line 846, in items
    d.update(self._sections[section])
KeyError: 'web'

During handling of the above exception, another exception occurred:

Traceback (most recent call last):
  File "/home/airflow/.local/lib/python3.8/site-packages/airflow/operators/python.py", line 192, in execute
    return_value = self.execute_callable()
  File "/home/airflow/.local/lib/python3.8/site-packages/airflow/operators/python.py", line 209, in execute_callable
    return self.python_callable(*self.op_args, **self.op_kwargs)
  File "/opt/airflow/dags/main.py", line 61, in main
    config = get_config('web')
  File "/opt/airflow/dags/main.py", line 23, in get_config
    return {key: value for key, value in parser.items(section)}
  File "/usr/local/lib/python3.8/configparser.py", line 849, in items
    raise NoSectionError(section)
configparser.NoSectionError: No section: 'web'
[2023-12-07T14:51:30.134+0000] {taskinstance.py:1400} INFO - Marking task as FAILED. dag_id=my_scraping_dag, task_id=main_task, execution_date=20230201T000000, start_date=20231207T145130, end_date=20231207T145130
[2023-12-07T14:51:30.139+0000] {standard_task_runner.py:104} ERROR - Failed to execute job 142 for task main_task (No section: 'web'; 796)
[2023-12-07T14:51:30.148+0000] {local_task_job_runner.py:228} INFO - Task exited with return code 1
[2023-12-07T14:51:30.161+0000] {taskinstance.py:2778} INFO - 0 downstream tasks scheduled from follow-on schedule check
[2023-12-07T14:59:55.823+0000] {taskinstance.py:1159} INFO - Dependencies all met for dep_context=non-requeueable deps ti=<TaskInstance: my_scraping_dag.main_task scheduled__2023-02-01T00:00:00+00:00 [queued]>
[2023-12-07T14:59:55.827+0000] {taskinstance.py:1159} INFO - Dependencies all met for dep_context=requeueable deps ti=<TaskInstance: my_scraping_dag.main_task scheduled__2023-02-01T00:00:00+00:00 [queued]>
[2023-12-07T14:59:55.828+0000] {taskinstance.py:1361} INFO - Starting attempt 1 of 1
[2023-12-07T14:59:55.834+0000] {taskinstance.py:1382} INFO - Executing <Task(PythonOperator): main_task> on 2023-02-01 00:00:00+00:00
[2023-12-07T14:59:55.836+0000] {standard_task_runner.py:57} INFO - Started process 1426 to run task
[2023-12-07T14:59:55.838+0000] {standard_task_runner.py:84} INFO - Running: ['***', 'tasks', 'run', 'my_scraping_dag', 'main_task', 'scheduled__2023-02-01T00:00:00+00:00', '--job-id', '346', '--raw', '--subdir', 'DAGS_FOLDER/main.py', '--cfg-path', '/tmp/tmpygsni98s']
[2023-12-07T14:59:55.840+0000] {standard_task_runner.py:85} INFO - Job 346: Subtask main_task
[2023-12-07T14:59:55.865+0000] {task_command.py:416} INFO - Running <TaskInstance: my_scraping_dag.main_task scheduled__2023-02-01T00:00:00+00:00 [running]> on host 63b0c7e341c0
[2023-12-07T14:59:55.900+0000] {taskinstance.py:1662} INFO - Exporting env vars: AIRFLOW_CTX_DAG_OWNER='***' AIRFLOW_CTX_DAG_ID='my_scraping_dag' AIRFLOW_CTX_TASK_ID='main_task' AIRFLOW_CTX_EXECUTION_DATE='2023-02-01T00:00:00+00:00' AIRFLOW_CTX_TRY_NUMBER='1' AIRFLOW_CTX_DAG_RUN_ID='scheduled__2023-02-01T00:00:00+00:00'
[2023-12-07T14:59:55.901+0000] {taskinstance.py:1937} ERROR - Task failed with exception
Traceback (most recent call last):
  File "/usr/local/lib/python3.8/configparser.py", line 846, in items
    d.update(self._sections[section])
KeyError: 'web'

During handling of the above exception, another exception occurred:

Traceback (most recent call last):
  File "/home/airflow/.local/lib/python3.8/site-packages/airflow/operators/python.py", line 192, in execute
    return_value = self.execute_callable()
  File "/home/airflow/.local/lib/python3.8/site-packages/airflow/operators/python.py", line 209, in execute_callable
    return self.python_callable(*self.op_args, **self.op_kwargs)
  File "/opt/airflow/dags/main.py", line 60, in main
    config = get_config('web')
  File "/opt/airflow/dags/main.py", line 22, in get_config
    return {key: value for key, value in parser.items(section)}
  File "/usr/local/lib/python3.8/configparser.py", line 849, in items
    raise NoSectionError(section)
configparser.NoSectionError: No section: 'web'
[2023-12-07T14:59:55.907+0000] {taskinstance.py:1400} INFO - Marking task as FAILED. dag_id=my_scraping_dag, task_id=main_task, execution_date=20230201T000000, start_date=20231207T145955, end_date=20231207T145955
[2023-12-07T14:59:55.913+0000] {standard_task_runner.py:104} ERROR - Failed to execute job 346 for task main_task (No section: 'web'; 1426)
[2023-12-07T14:59:55.931+0000] {local_task_job_runner.py:228} INFO - Task exited with return code 1
[2023-12-07T14:59:55.945+0000] {taskinstance.py:2778} INFO - 0 downstream tasks scheduled from follow-on schedule check
[2023-12-07T15:10:46.337+0000] {taskinstance.py:1159} INFO - Dependencies all met for dep_context=non-requeueable deps ti=<TaskInstance: my_scraping_dag.main_task scheduled__2023-02-01T00:00:00+00:00 [queued]>
[2023-12-07T15:10:46.341+0000] {taskinstance.py:1159} INFO - Dependencies all met for dep_context=requeueable deps ti=<TaskInstance: my_scraping_dag.main_task scheduled__2023-02-01T00:00:00+00:00 [queued]>
[2023-12-07T15:10:46.341+0000] {taskinstance.py:1361} INFO - Starting attempt 1 of 1
[2023-12-07T15:10:46.346+0000] {taskinstance.py:1382} INFO - Executing <Task(PythonOperator): main_task> on 2023-02-01 00:00:00+00:00
[2023-12-07T15:10:46.349+0000] {standard_task_runner.py:57} INFO - Started process 1907 to run task
[2023-12-07T15:10:46.351+0000] {standard_task_runner.py:84} INFO - Running: ['***', 'tasks', 'run', 'my_scraping_dag', 'main_task', 'scheduled__2023-02-01T00:00:00+00:00', '--job-id', '453', '--raw', '--subdir', 'DAGS_FOLDER/main.py', '--cfg-path', '/tmp/tmpzqelk1qi']
[2023-12-07T15:10:46.353+0000] {standard_task_runner.py:85} INFO - Job 453: Subtask main_task
[2023-12-07T15:10:46.378+0000] {task_command.py:416} INFO - Running <TaskInstance: my_scraping_dag.main_task scheduled__2023-02-01T00:00:00+00:00 [running]> on host 63b0c7e341c0
[2023-12-07T15:10:46.411+0000] {taskinstance.py:1662} INFO - Exporting env vars: AIRFLOW_CTX_DAG_OWNER='***' AIRFLOW_CTX_DAG_ID='my_scraping_dag' AIRFLOW_CTX_TASK_ID='main_task' AIRFLOW_CTX_EXECUTION_DATE='2023-02-01T00:00:00+00:00' AIRFLOW_CTX_TRY_NUMBER='1' AIRFLOW_CTX_DAG_RUN_ID='scheduled__2023-02-01T00:00:00+00:00'
[2023-12-07T15:10:46.412+0000] {taskinstance.py:1937} ERROR - Task failed with exception
Traceback (most recent call last):
  File "/usr/local/lib/python3.8/configparser.py", line 846, in items
    d.update(self._sections[section])
KeyError: 'web'

During handling of the above exception, another exception occurred:

Traceback (most recent call last):
  File "/home/airflow/.local/lib/python3.8/site-packages/airflow/operators/python.py", line 192, in execute
    return_value = self.execute_callable()
  File "/home/airflow/.local/lib/python3.8/site-packages/airflow/operators/python.py", line 209, in execute_callable
    return self.python_callable(*self.op_args, **self.op_kwargs)
  File "/opt/airflow/dags/main.py", line 63, in main
    config = get_config('web')
  File "/opt/airflow/dags/main.py", line 14, in get_config
    return {key: value for key, value in parser.items(section)}
  File "/usr/local/lib/python3.8/configparser.py", line 849, in items
    raise NoSectionError(section)
configparser.NoSectionError: No section: 'web'
[2023-12-07T15:10:46.417+0000] {taskinstance.py:1400} INFO - Marking task as FAILED. dag_id=my_scraping_dag, task_id=main_task, execution_date=20230201T000000, start_date=20231207T151046, end_date=20231207T151046
[2023-12-07T15:10:46.422+0000] {standard_task_runner.py:104} ERROR - Failed to execute job 453 for task main_task (No section: 'web'; 1907)
[2023-12-07T15:10:46.444+0000] {local_task_job_runner.py:228} INFO - Task exited with return code 1
[2023-12-07T15:10:46.451+0000] {taskinstance.py:2778} INFO - 0 downstream tasks scheduled from follow-on schedule check
[2023-12-07T15:12:07.892+0000] {taskinstance.py:1159} INFO - Dependencies all met for dep_context=non-requeueable deps ti=<TaskInstance: my_scraping_dag.main_task scheduled__2023-02-01T00:00:00+00:00 [queued]>
[2023-12-07T15:12:07.897+0000] {taskinstance.py:1159} INFO - Dependencies all met for dep_context=requeueable deps ti=<TaskInstance: my_scraping_dag.main_task scheduled__2023-02-01T00:00:00+00:00 [queued]>
[2023-12-07T15:12:07.898+0000] {taskinstance.py:1361} INFO - Starting attempt 1 of 1
[2023-12-07T15:12:07.905+0000] {taskinstance.py:1382} INFO - Executing <Task(PythonOperator): main_task> on 2023-02-01 00:00:00+00:00
[2023-12-07T15:12:07.908+0000] {standard_task_runner.py:57} INFO - Started process 2126 to run task
[2023-12-07T15:12:07.910+0000] {standard_task_runner.py:84} INFO - Running: ['***', 'tasks', 'run', 'my_scraping_dag', 'main_task', 'scheduled__2023-02-01T00:00:00+00:00', '--job-id', '542', '--raw', '--subdir', 'DAGS_FOLDER/main.py', '--cfg-path', '/tmp/tmp71cibkqe']
[2023-12-07T15:12:07.912+0000] {standard_task_runner.py:85} INFO - Job 542: Subtask main_task
[2023-12-07T15:12:07.936+0000] {task_command.py:416} INFO - Running <TaskInstance: my_scraping_dag.main_task scheduled__2023-02-01T00:00:00+00:00 [running]> on host 63b0c7e341c0
[2023-12-07T15:12:07.968+0000] {taskinstance.py:1662} INFO - Exporting env vars: AIRFLOW_CTX_DAG_OWNER='***' AIRFLOW_CTX_DAG_ID='my_scraping_dag' AIRFLOW_CTX_TASK_ID='main_task' AIRFLOW_CTX_EXECUTION_DATE='2023-02-01T00:00:00+00:00' AIRFLOW_CTX_TRY_NUMBER='1' AIRFLOW_CTX_DAG_RUN_ID='scheduled__2023-02-01T00:00:00+00:00'
[2023-12-07T15:12:07.969+0000] {taskinstance.py:1937} ERROR - Task failed with exception
Traceback (most recent call last):
  File "/usr/local/lib/python3.8/configparser.py", line 846, in items
    d.update(self._sections[section])
KeyError: 'web'

During handling of the above exception, another exception occurred:

Traceback (most recent call last):
  File "/home/airflow/.local/lib/python3.8/site-packages/airflow/operators/python.py", line 192, in execute
    return_value = self.execute_callable()
  File "/home/airflow/.local/lib/python3.8/site-packages/airflow/operators/python.py", line 209, in execute_callable
    return self.python_callable(*self.op_args, **self.op_kwargs)
  File "/opt/airflow/dags/main.py", line 63, in main
    config = get_config('web')
  File "/opt/airflow/dags/main.py", line 14, in get_config
    return {key: value for key, value in parser.items(section)}
  File "/usr/local/lib/python3.8/configparser.py", line 849, in items
    raise NoSectionError(section)
configparser.NoSectionError: No section: 'web'
[2023-12-07T15:12:07.973+0000] {taskinstance.py:1400} INFO - Marking task as FAILED. dag_id=my_scraping_dag, task_id=main_task, execution_date=20230201T000000, start_date=20231207T151207, end_date=20231207T151207
[2023-12-07T15:12:07.977+0000] {standard_task_runner.py:104} ERROR - Failed to execute job 542 for task main_task (No section: 'web'; 2126)
[2023-12-07T15:12:08.002+0000] {local_task_job_runner.py:228} INFO - Task exited with return code 1
[2023-12-07T15:12:08.010+0000] {taskinstance.py:2778} INFO - 0 downstream tasks scheduled from follow-on schedule check
[2023-12-07T16:31:04.263+0000] {taskinstance.py:1159} INFO - Dependencies all met for dep_context=non-requeueable deps ti=<TaskInstance: my_scraping_dag.main_task scheduled__2023-02-01T00:00:00+00:00 [queued]>
[2023-12-07T16:31:04.267+0000] {taskinstance.py:1159} INFO - Dependencies all met for dep_context=requeueable deps ti=<TaskInstance: my_scraping_dag.main_task scheduled__2023-02-01T00:00:00+00:00 [queued]>
[2023-12-07T16:31:04.267+0000] {taskinstance.py:1361} INFO - Starting attempt 1 of 1
[2023-12-07T16:31:04.273+0000] {taskinstance.py:1382} INFO - Executing <Task(PythonOperator): main_task> on 2023-02-01 00:00:00+00:00
[2023-12-07T16:31:04.276+0000] {standard_task_runner.py:57} INFO - Started process 3561 to run task
[2023-12-07T16:31:04.278+0000] {standard_task_runner.py:84} INFO - Running: ['***', 'tasks', 'run', 'my_scraping_dag', 'main_task', 'scheduled__2023-02-01T00:00:00+00:00', '--job-id', '620', '--raw', '--subdir', 'DAGS_FOLDER/main.py', '--cfg-path', '/tmp/tmpf_q7hf4q']
[2023-12-07T16:31:04.281+0000] {standard_task_runner.py:85} INFO - Job 620: Subtask main_task
[2023-12-07T16:31:04.306+0000] {task_command.py:416} INFO - Running <TaskInstance: my_scraping_dag.main_task scheduled__2023-02-01T00:00:00+00:00 [running]> on host 63b0c7e341c0
[2023-12-07T16:31:04.340+0000] {taskinstance.py:1662} INFO - Exporting env vars: AIRFLOW_CTX_DAG_OWNER='***' AIRFLOW_CTX_DAG_ID='my_scraping_dag' AIRFLOW_CTX_TASK_ID='main_task' AIRFLOW_CTX_EXECUTION_DATE='2023-02-01T00:00:00+00:00' AIRFLOW_CTX_TRY_NUMBER='1' AIRFLOW_CTX_DAG_RUN_ID='scheduled__2023-02-01T00:00:00+00:00'
[2023-12-07T16:31:04.341+0000] {taskinstance.py:1937} ERROR - Task failed with exception
Traceback (most recent call last):
  File "/usr/local/lib/python3.8/configparser.py", line 846, in items
    d.update(self._sections[section])
KeyError: 'web'

During handling of the above exception, another exception occurred:

Traceback (most recent call last):
  File "/home/airflow/.local/lib/python3.8/site-packages/airflow/operators/python.py", line 192, in execute
    return_value = self.execute_callable()
  File "/home/airflow/.local/lib/python3.8/site-packages/airflow/operators/python.py", line 209, in execute_callable
    return self.python_callable(*self.op_args, **self.op_kwargs)
  File "/opt/airflow/dags/main.py", line 60, in main
    config = get_config('web')
  File "/opt/airflow/dags/main.py", line 22, in get_config
    return {key: value for key, value in parser.items(section)}
  File "/usr/local/lib/python3.8/configparser.py", line 849, in items
    raise NoSectionError(section)
configparser.NoSectionError: No section: 'web'
[2023-12-07T16:31:04.345+0000] {taskinstance.py:1400} INFO - Marking task as FAILED. dag_id=my_scraping_dag, task_id=main_task, execution_date=20230201T000000, start_date=20231207T163104, end_date=20231207T163104
[2023-12-07T16:31:04.349+0000] {standard_task_runner.py:104} ERROR - Failed to execute job 620 for task main_task (No section: 'web'; 3561)
[2023-12-07T16:31:04.375+0000] {local_task_job_runner.py:228} INFO - Task exited with return code 1
[2023-12-07T16:31:04.386+0000] {taskinstance.py:2778} INFO - 0 downstream tasks scheduled from follow-on schedule check
[2023-12-07T16:40:55.142+0000] {taskinstance.py:1159} INFO - Dependencies all met for dep_context=non-requeueable deps ti=<TaskInstance: my_scraping_dag.main_task scheduled__2023-02-01T00:00:00+00:00 [queued]>
[2023-12-07T16:40:55.147+0000] {taskinstance.py:1159} INFO - Dependencies all met for dep_context=requeueable deps ti=<TaskInstance: my_scraping_dag.main_task scheduled__2023-02-01T00:00:00+00:00 [queued]>
[2023-12-07T16:40:55.147+0000] {taskinstance.py:1361} INFO - Starting attempt 1 of 1
[2023-12-07T16:40:55.153+0000] {taskinstance.py:1382} INFO - Executing <Task(PythonOperator): main_task> on 2023-02-01 00:00:00+00:00
[2023-12-07T16:40:55.156+0000] {standard_task_runner.py:57} INFO - Started process 4492 to run task
[2023-12-07T16:40:55.158+0000] {standard_task_runner.py:84} INFO - Running: ['***', 'tasks', 'run', 'my_scraping_dag', 'main_task', 'scheduled__2023-02-01T00:00:00+00:00', '--job-id', '962', '--raw', '--subdir', 'DAGS_FOLDER/main.py', '--cfg-path', '/tmp/tmpby6gag39']
[2023-12-07T16:40:55.160+0000] {standard_task_runner.py:85} INFO - Job 962: Subtask main_task
[2023-12-07T16:40:55.188+0000] {task_command.py:416} INFO - Running <TaskInstance: my_scraping_dag.main_task scheduled__2023-02-01T00:00:00+00:00 [running]> on host 63b0c7e341c0
[2023-12-07T16:40:55.227+0000] {taskinstance.py:1662} INFO - Exporting env vars: AIRFLOW_CTX_DAG_OWNER='***' AIRFLOW_CTX_DAG_ID='my_scraping_dag' AIRFLOW_CTX_TASK_ID='main_task' AIRFLOW_CTX_EXECUTION_DATE='2023-02-01T00:00:00+00:00' AIRFLOW_CTX_TRY_NUMBER='1' AIRFLOW_CTX_DAG_RUN_ID='scheduled__2023-02-01T00:00:00+00:00'
[2023-12-07T16:40:55.228+0000] {taskinstance.py:1937} ERROR - Task failed with exception
Traceback (most recent call last):
  File "/usr/local/lib/python3.8/configparser.py", line 846, in items
    d.update(self._sections[section])
KeyError: 'web'

During handling of the above exception, another exception occurred:

Traceback (most recent call last):
  File "/home/airflow/.local/lib/python3.8/site-packages/airflow/operators/python.py", line 192, in execute
    return_value = self.execute_callable()
  File "/home/airflow/.local/lib/python3.8/site-packages/airflow/operators/python.py", line 209, in execute_callable
    return self.python_callable(*self.op_args, **self.op_kwargs)
  File "/opt/airflow/dags/main.py", line 60, in main
    config = get_config('web')
  File "/opt/airflow/dags/main.py", line 22, in get_config
    return {key: value for key, value in parser.items(section)}
  File "/usr/local/lib/python3.8/configparser.py", line 849, in items
    raise NoSectionError(section)
configparser.NoSectionError: No section: 'web'
[2023-12-07T16:40:55.234+0000] {taskinstance.py:1400} INFO - Marking task as FAILED. dag_id=my_scraping_dag, task_id=main_task, execution_date=20230201T000000, start_date=20231207T164055, end_date=20231207T164055
[2023-12-07T16:40:55.239+0000] {standard_task_runner.py:104} ERROR - Failed to execute job 962 for task main_task (No section: 'web'; 4492)
[2023-12-07T16:40:55.250+0000] {local_task_job_runner.py:228} INFO - Task exited with return code 1
[2023-12-07T16:40:55.268+0000] {taskinstance.py:2778} INFO - 0 downstream tasks scheduled from follow-on schedule check
[2023-12-07T17:00:00.012+0000] {taskinstance.py:1159} INFO - Dependencies all met for dep_context=non-requeueable deps ti=<TaskInstance: my_scraping_dag.main_task scheduled__2023-02-01T00:00:00+00:00 [queued]>
[2023-12-07T17:00:00.019+0000] {taskinstance.py:1159} INFO - Dependencies all met for dep_context=requeueable deps ti=<TaskInstance: my_scraping_dag.main_task scheduled__2023-02-01T00:00:00+00:00 [queued]>
[2023-12-07T17:00:00.020+0000] {taskinstance.py:1361} INFO - Starting attempt 1 of 1
[2023-12-07T17:00:00.046+0000] {taskinstance.py:1382} INFO - Executing <Task(PythonOperator): main_task> on 2023-02-01 00:00:00+00:00
[2023-12-07T17:00:00.051+0000] {standard_task_runner.py:57} INFO - Started process 5642 to run task
[2023-12-07T17:00:00.054+0000] {standard_task_runner.py:84} INFO - Running: ['***', 'tasks', 'run', 'my_scraping_dag', 'main_task', 'scheduled__2023-02-01T00:00:00+00:00', '--job-id', '1306', '--raw', '--subdir', 'DAGS_FOLDER/main.py', '--cfg-path', '/tmp/tmpxowrs1fe']
[2023-12-07T17:00:00.058+0000] {standard_task_runner.py:85} INFO - Job 1306: Subtask main_task
[2023-12-07T17:00:00.098+0000] {task_command.py:416} INFO - Running <TaskInstance: my_scraping_dag.main_task scheduled__2023-02-01T00:00:00+00:00 [running]> on host 63b0c7e341c0
[2023-12-07T17:00:00.147+0000] {taskinstance.py:1662} INFO - Exporting env vars: AIRFLOW_CTX_DAG_OWNER='***' AIRFLOW_CTX_DAG_ID='my_scraping_dag' AIRFLOW_CTX_TASK_ID='main_task' AIRFLOW_CTX_EXECUTION_DATE='2023-02-01T00:00:00+00:00' AIRFLOW_CTX_TRY_NUMBER='1' AIRFLOW_CTX_DAG_RUN_ID='scheduled__2023-02-01T00:00:00+00:00'
[2023-12-07T17:00:00.182+0000] {taskinstance.py:1937} ERROR - Task failed with exception
Traceback (most recent call last):
  File "/home/airflow/.local/lib/python3.8/site-packages/airflow/operators/python.py", line 192, in execute
    return_value = self.execute_callable()
  File "/home/airflow/.local/lib/python3.8/site-packages/airflow/operators/python.py", line 209, in execute_callable
    return self.python_callable(*self.op_args, **self.op_kwargs)
  File "/opt/airflow/dags/main.py", line 33, in main
    'host': get_config('localhost'),
  File "/opt/airflow/dags/main.py", line 20, in get_config
    return Variable.get(key)
  File "/home/airflow/.local/lib/python3.8/site-packages/airflow/models/variable.py", line 140, in get
    raise KeyError(f"Variable {key} does not exist")
KeyError: 'Variable localhost does not exist'
[2023-12-07T17:00:00.188+0000] {taskinstance.py:1400} INFO - Marking task as FAILED. dag_id=my_scraping_dag, task_id=main_task, execution_date=20230201T000000, start_date=20231207T170000, end_date=20231207T170000
[2023-12-07T17:00:00.207+0000] {standard_task_runner.py:104} ERROR - Failed to execute job 1306 for task main_task ('Variable localhost does not exist'; 5642)
[2023-12-07T17:00:00.228+0000] {local_task_job_runner.py:228} INFO - Task exited with return code 1
[2023-12-07T17:00:00.246+0000] {taskinstance.py:2778} INFO - 0 downstream tasks scheduled from follow-on schedule check
[2023-12-07T17:03:24.070+0000] {taskinstance.py:1159} INFO - Dependencies all met for dep_context=non-requeueable deps ti=<TaskInstance: my_scraping_dag.main_task scheduled__2023-02-01T00:00:00+00:00 [queued]>
[2023-12-07T17:03:24.075+0000] {taskinstance.py:1159} INFO - Dependencies all met for dep_context=requeueable deps ti=<TaskInstance: my_scraping_dag.main_task scheduled__2023-02-01T00:00:00+00:00 [queued]>
[2023-12-07T17:03:24.077+0000] {taskinstance.py:1361} INFO - Starting attempt 1 of 1
[2023-12-07T17:03:24.093+0000] {taskinstance.py:1382} INFO - Executing <Task(PythonOperator): main_task> on 2023-02-01 00:00:00+00:00
[2023-12-07T17:03:24.096+0000] {standard_task_runner.py:57} INFO - Started process 6924 to run task
[2023-12-07T17:03:24.098+0000] {standard_task_runner.py:84} INFO - Running: ['***', 'tasks', 'run', 'my_scraping_dag', 'main_task', 'scheduled__2023-02-01T00:00:00+00:00', '--job-id', '1905', '--raw', '--subdir', 'DAGS_FOLDER/main.py', '--cfg-path', '/tmp/tmpxkh7uyvn']
[2023-12-07T17:03:24.101+0000] {standard_task_runner.py:85} INFO - Job 1905: Subtask main_task
[2023-12-07T17:03:24.135+0000] {task_command.py:416} INFO - Running <TaskInstance: my_scraping_dag.main_task scheduled__2023-02-01T00:00:00+00:00 [running]> on host 63b0c7e341c0
[2023-12-07T17:03:24.176+0000] {taskinstance.py:1662} INFO - Exporting env vars: AIRFLOW_CTX_DAG_OWNER='***' AIRFLOW_CTX_DAG_ID='my_scraping_dag' AIRFLOW_CTX_TASK_ID='main_task' AIRFLOW_CTX_EXECUTION_DATE='2023-02-01T00:00:00+00:00' AIRFLOW_CTX_TRY_NUMBER='1' AIRFLOW_CTX_DAG_RUN_ID='scheduled__2023-02-01T00:00:00+00:00'
[2023-12-07T17:03:24.204+0000] {logging_mixin.py:154} INFO - base_url: https://tuncbotanik.com
[2023-12-07T17:03:24.205+0000] {python.py:194} INFO - Done. Returned value was: ('https://tuncbotanik.com', {'User-Agent': 'Mozilla/5.0 (Macintosh; Intel Mac OS X 10_15_7) AppleWebKit/537.36 (KHTML, like Gecko) Chrome/119.0.0.0 Safari/537.36', 'Accept-Language': 'tr-TR,tr;q=0.9,en-US;q=0.8,en;q=0.7'}, {'dbname': 'plant', 'user': 'aozgokme', 'password': '***', 'host': 'localhost', 'port': '5432'})
[2023-12-07T17:03:24.219+0000] {taskinstance.py:1400} INFO - Marking task as SUCCESS. dag_id=my_scraping_dag, task_id=main_task, execution_date=20230201T000000, start_date=20231207T170324, end_date=20231207T170324
[2023-12-07T17:03:24.232+0000] {local_task_job_runner.py:228} INFO - Task exited with return code 0
[2023-12-07T17:03:24.251+0000] {taskinstance.py:2778} INFO - 1 downstream tasks scheduled from follow-on schedule check
[2023-12-07T17:18:26.179+0000] {taskinstance.py:1159} INFO - Dependencies all met for dep_context=non-requeueable deps ti=<TaskInstance: my_scraping_dag.main_task scheduled__2023-02-01T00:00:00+00:00 [queued]>
[2023-12-07T17:18:26.184+0000] {taskinstance.py:1159} INFO - Dependencies all met for dep_context=requeueable deps ti=<TaskInstance: my_scraping_dag.main_task scheduled__2023-02-01T00:00:00+00:00 [queued]>
[2023-12-07T17:18:26.184+0000] {taskinstance.py:1361} INFO - Starting attempt 1 of 1
[2023-12-07T17:18:26.192+0000] {taskinstance.py:1382} INFO - Executing <Task(PythonOperator): main_task> on 2023-02-01 00:00:00+00:00
[2023-12-07T17:18:26.195+0000] {standard_task_runner.py:57} INFO - Started process 8608 to run task
[2023-12-07T17:18:26.197+0000] {standard_task_runner.py:84} INFO - Running: ['***', 'tasks', 'run', 'my_scraping_dag', 'main_task', 'scheduled__2023-02-01T00:00:00+00:00', '--job-id', '2561', '--raw', '--subdir', 'DAGS_FOLDER/main.py', '--cfg-path', '/tmp/tmp30a92l3g']
[2023-12-07T17:18:26.199+0000] {standard_task_runner.py:85} INFO - Job 2561: Subtask main_task
[2023-12-07T17:18:26.225+0000] {task_command.py:416} INFO - Running <TaskInstance: my_scraping_dag.main_task scheduled__2023-02-01T00:00:00+00:00 [running]> on host 63b0c7e341c0
[2023-12-07T17:18:26.268+0000] {taskinstance.py:1662} INFO - Exporting env vars: AIRFLOW_CTX_DAG_OWNER='***' AIRFLOW_CTX_DAG_ID='my_scraping_dag' AIRFLOW_CTX_TASK_ID='main_task' AIRFLOW_CTX_EXECUTION_DATE='2023-02-01T00:00:00+00:00' AIRFLOW_CTX_TRY_NUMBER='1' AIRFLOW_CTX_DAG_RUN_ID='scheduled__2023-02-01T00:00:00+00:00'
[2023-12-07T17:18:27.034+0000] {taskinstance.py:1937} ERROR - Task failed with exception
Traceback (most recent call last):
  File "/home/airflow/.local/lib/python3.8/site-packages/airflow/operators/python.py", line 192, in execute
    return_value = self.execute_callable()
  File "/home/airflow/.local/lib/python3.8/site-packages/airflow/operators/python.py", line 209, in execute_callable
    return self.python_callable(*self.op_args, **self.op_kwargs)
  File "/opt/airflow/dags/main.py", line 80, in main
    insert_data_to_db(products, db_params)
  File "/opt/airflow/dags/main.py", line 43, in insert_data_to_db
    with psycopg2.connect(**db_params) as conn:
  File "/home/airflow/.local/lib/python3.8/site-packages/psycopg2/__init__.py", line 122, in connect
    conn = _connect(dsn, connection_factory=connection_factory, **kwasync)
psycopg2.OperationalError: connection to server at "localhost" (127.0.0.1), port 5432 failed: Connection refused
	Is the server running on that host and accepting TCP/IP connections?
connection to server at "localhost" (::1), port 5432 failed: Cannot assign requested address
	Is the server running on that host and accepting TCP/IP connections?

[2023-12-07T17:18:27.059+0000] {taskinstance.py:1400} INFO - Marking task as FAILED. dag_id=my_scraping_dag, task_id=main_task, execution_date=20230201T000000, start_date=20231207T171826, end_date=20231207T171827
[2023-12-07T17:18:27.085+0000] {standard_task_runner.py:104} ERROR - Failed to execute job 2561 for task main_task (connection to server at "localhost" (127.0.0.1), port 5432 failed: Connection refused
	Is the server running on that host and accepting TCP/IP connections?
connection to server at "localhost" (::1), port 5432 failed: Cannot assign requested address
	Is the server running on that host and accepting TCP/IP connections?
; 8608)
[2023-12-07T17:18:27.134+0000] {local_task_job_runner.py:228} INFO - Task exited with return code 1
[2023-12-07T17:18:27.166+0000] {taskinstance.py:2778} INFO - 0 downstream tasks scheduled from follow-on schedule check
[2023-12-07T17:22:44.107+0000] {taskinstance.py:1159} INFO - Dependencies all met for dep_context=non-requeueable deps ti=<TaskInstance: my_scraping_dag.main_task scheduled__2023-02-01T00:00:00+00:00 [queued]>
[2023-12-07T17:22:44.112+0000] {taskinstance.py:1159} INFO - Dependencies all met for dep_context=requeueable deps ti=<TaskInstance: my_scraping_dag.main_task scheduled__2023-02-01T00:00:00+00:00 [queued]>
[2023-12-07T17:22:44.112+0000] {taskinstance.py:1361} INFO - Starting attempt 1 of 1
[2023-12-07T17:22:44.118+0000] {taskinstance.py:1382} INFO - Executing <Task(PythonOperator): main_task> on 2023-02-01 00:00:00+00:00
[2023-12-07T17:22:44.121+0000] {standard_task_runner.py:57} INFO - Started process 9402 to run task
[2023-12-07T17:22:44.123+0000] {standard_task_runner.py:84} INFO - Running: ['***', 'tasks', 'run', 'my_scraping_dag', 'main_task', 'scheduled__2023-02-01T00:00:00+00:00', '--job-id', '2903', '--raw', '--subdir', 'DAGS_FOLDER/main.py', '--cfg-path', '/tmp/tmplpx6sxkj']
[2023-12-07T17:22:44.125+0000] {standard_task_runner.py:85} INFO - Job 2903: Subtask main_task
[2023-12-07T17:22:44.149+0000] {task_command.py:416} INFO - Running <TaskInstance: my_scraping_dag.main_task scheduled__2023-02-01T00:00:00+00:00 [running]> on host 63b0c7e341c0
[2023-12-07T17:22:44.192+0000] {taskinstance.py:1662} INFO - Exporting env vars: AIRFLOW_CTX_DAG_OWNER='***' AIRFLOW_CTX_DAG_ID='my_scraping_dag' AIRFLOW_CTX_TASK_ID='main_task' AIRFLOW_CTX_EXECUTION_DATE='2023-02-01T00:00:00+00:00' AIRFLOW_CTX_TRY_NUMBER='1' AIRFLOW_CTX_DAG_RUN_ID='scheduled__2023-02-01T00:00:00+00:00'
[2023-12-07T17:22:44.877+0000] {taskinstance.py:1937} ERROR - Task failed with exception
Traceback (most recent call last):
  File "/home/airflow/.local/lib/python3.8/site-packages/airflow/operators/python.py", line 192, in execute
    return_value = self.execute_callable()
  File "/home/airflow/.local/lib/python3.8/site-packages/airflow/operators/python.py", line 209, in execute_callable
    return self.python_callable(*self.op_args, **self.op_kwargs)
  File "/opt/airflow/dags/main.py", line 73, in main
    insert_data_to_db(products, db_params)
  File "/opt/airflow/dags/main.py", line 40, in insert_data_to_db
    with psycopg2.connect(**db_params) as conn:
  File "/home/airflow/.local/lib/python3.8/site-packages/psycopg2/__init__.py", line 122, in connect
    conn = _connect(dsn, connection_factory=connection_factory, **kwasync)
psycopg2.OperationalError: connection to server at "localhost" (127.0.0.1), port 5432 failed: Connection refused
	Is the server running on that host and accepting TCP/IP connections?
connection to server at "localhost" (::1), port 5432 failed: Cannot assign requested address
	Is the server running on that host and accepting TCP/IP connections?

[2023-12-07T17:22:44.905+0000] {taskinstance.py:1400} INFO - Marking task as FAILED. dag_id=my_scraping_dag, task_id=main_task, execution_date=20230201T000000, start_date=20231207T172244, end_date=20231207T172244
[2023-12-07T17:22:44.944+0000] {standard_task_runner.py:104} ERROR - Failed to execute job 2903 for task main_task (connection to server at "localhost" (127.0.0.1), port 5432 failed: Connection refused
	Is the server running on that host and accepting TCP/IP connections?
connection to server at "localhost" (::1), port 5432 failed: Cannot assign requested address
	Is the server running on that host and accepting TCP/IP connections?
; 9402)
[2023-12-07T17:22:44.978+0000] {local_task_job_runner.py:228} INFO - Task exited with return code 1
[2023-12-07T17:22:45.001+0000] {taskinstance.py:2778} INFO - 0 downstream tasks scheduled from follow-on schedule check
[2023-12-07T17:28:25.563+0000] {taskinstance.py:1159} INFO - Dependencies all met for dep_context=non-requeueable deps ti=<TaskInstance: my_scraping_dag.main_task scheduled__2023-02-01T00:00:00+00:00 [queued]>
[2023-12-07T17:28:25.567+0000] {taskinstance.py:1159} INFO - Dependencies all met for dep_context=requeueable deps ti=<TaskInstance: my_scraping_dag.main_task scheduled__2023-02-01T00:00:00+00:00 [queued]>
[2023-12-07T17:28:25.568+0000] {taskinstance.py:1361} INFO - Starting attempt 1 of 1
[2023-12-07T17:28:25.574+0000] {taskinstance.py:1382} INFO - Executing <Task(PythonOperator): main_task> on 2023-02-01 00:00:00+00:00
[2023-12-07T17:28:25.577+0000] {standard_task_runner.py:57} INFO - Started process 10245 to run task
[2023-12-07T17:28:25.579+0000] {standard_task_runner.py:84} INFO - Running: ['***', 'tasks', 'run', 'my_scraping_dag', 'main_task', 'scheduled__2023-02-01T00:00:00+00:00', '--job-id', '3245', '--raw', '--subdir', 'DAGS_FOLDER/main.py', '--cfg-path', '/tmp/tmp3s14u5_3']
[2023-12-07T17:28:25.580+0000] {standard_task_runner.py:85} INFO - Job 3245: Subtask main_task
[2023-12-07T17:28:25.606+0000] {task_command.py:416} INFO - Running <TaskInstance: my_scraping_dag.main_task scheduled__2023-02-01T00:00:00+00:00 [running]> on host 63b0c7e341c0
[2023-12-07T17:28:25.648+0000] {taskinstance.py:1662} INFO - Exporting env vars: AIRFLOW_CTX_DAG_OWNER='***' AIRFLOW_CTX_DAG_ID='my_scraping_dag' AIRFLOW_CTX_TASK_ID='main_task' AIRFLOW_CTX_EXECUTION_DATE='2023-02-01T00:00:00+00:00' AIRFLOW_CTX_TRY_NUMBER='1' AIRFLOW_CTX_DAG_RUN_ID='scheduled__2023-02-01T00:00:00+00:00'
[2023-12-07T17:28:26.376+0000] {taskinstance.py:1937} ERROR - Task failed with exception
Traceback (most recent call last):
  File "/home/airflow/.local/lib/python3.8/site-packages/airflow/operators/python.py", line 192, in execute
    return_value = self.execute_callable()
  File "/home/airflow/.local/lib/python3.8/site-packages/airflow/operators/python.py", line 209, in execute_callable
    return self.python_callable(*self.op_args, **self.op_kwargs)
  File "/opt/airflow/dags/main.py", line 73, in main
    insert_data_to_db(products, db_params)
  File "/opt/airflow/dags/main.py", line 40, in insert_data_to_db
    with psycopg2.connect(**db_params) as conn:
  File "/home/airflow/.local/lib/python3.8/site-packages/psycopg2/__init__.py", line 122, in connect
    conn = _connect(dsn, connection_factory=connection_factory, **kwasync)
psycopg2.OperationalError: connection to server at "localhost" (127.0.0.1), port 5432 failed: Connection refused
	Is the server running on that host and accepting TCP/IP connections?
connection to server at "localhost" (::1), port 5432 failed: Cannot assign requested address
	Is the server running on that host and accepting TCP/IP connections?

[2023-12-07T17:28:26.395+0000] {taskinstance.py:1400} INFO - Marking task as FAILED. dag_id=my_scraping_dag, task_id=main_task, execution_date=20230201T000000, start_date=20231207T172825, end_date=20231207T172826
[2023-12-07T17:28:26.406+0000] {standard_task_runner.py:104} ERROR - Failed to execute job 3245 for task main_task (connection to server at "localhost" (127.0.0.1), port 5432 failed: Connection refused
	Is the server running on that host and accepting TCP/IP connections?
connection to server at "localhost" (::1), port 5432 failed: Cannot assign requested address
	Is the server running on that host and accepting TCP/IP connections?
; 10245)
[2023-12-07T17:28:26.433+0000] {local_task_job_runner.py:228} INFO - Task exited with return code 1
[2023-12-07T17:28:26.442+0000] {taskinstance.py:2778} INFO - 0 downstream tasks scheduled from follow-on schedule check
