[2023-12-07T16:33:39.244+0000] {taskinstance.py:1159} INFO - Dependencies all met for dep_context=non-requeueable deps ti=<TaskInstance: my_scraping_dag.main_task scheduled__2023-08-12T00:00:00+00:00 [queued]>
[2023-12-07T16:33:39.248+0000] {taskinstance.py:1159} INFO - Dependencies all met for dep_context=requeueable deps ti=<TaskInstance: my_scraping_dag.main_task scheduled__2023-08-12T00:00:00+00:00 [queued]>
[2023-12-07T16:33:39.248+0000] {taskinstance.py:1361} INFO - Starting attempt 1 of 1
[2023-12-07T16:33:39.260+0000] {taskinstance.py:1382} INFO - Executing <Task(PythonOperator): main_task> on 2023-08-12 00:00:00+00:00
[2023-12-07T16:33:39.262+0000] {standard_task_runner.py:57} INFO - Started process 4017 to run task
[2023-12-07T16:33:39.264+0000] {standard_task_runner.py:84} INFO - Running: ['***', 'tasks', 'run', 'my_scraping_dag', 'main_task', 'scheduled__2023-08-12T00:00:00+00:00', '--job-id', '812', '--raw', '--subdir', 'DAGS_FOLDER/main.py', '--cfg-path', '/tmp/tmpp80dlql5']
[2023-12-07T16:33:39.266+0000] {standard_task_runner.py:85} INFO - Job 812: Subtask main_task
[2023-12-07T16:33:39.294+0000] {task_command.py:416} INFO - Running <TaskInstance: my_scraping_dag.main_task scheduled__2023-08-12T00:00:00+00:00 [running]> on host 63b0c7e341c0
[2023-12-07T16:33:39.335+0000] {taskinstance.py:1662} INFO - Exporting env vars: AIRFLOW_CTX_DAG_OWNER='***' AIRFLOW_CTX_DAG_ID='my_scraping_dag' AIRFLOW_CTX_TASK_ID='main_task' AIRFLOW_CTX_EXECUTION_DATE='2023-08-12T00:00:00+00:00' AIRFLOW_CTX_TRY_NUMBER='1' AIRFLOW_CTX_DAG_RUN_ID='scheduled__2023-08-12T00:00:00+00:00'
[2023-12-07T16:33:39.336+0000] {taskinstance.py:1937} ERROR - Task failed with exception
Traceback (most recent call last):
  File "/usr/local/lib/python3.8/configparser.py", line 846, in items
    d.update(self._sections[section])
KeyError: 'web'

During handling of the above exception, another exception occurred:

Traceback (most recent call last):
  File "/home/airflow/.local/lib/python3.8/site-packages/airflow/operators/python.py", line 192, in execute
    return_value = self.execute_callable()
  File "/home/airflow/.local/lib/python3.8/site-packages/airflow/operators/python.py", line 209, in execute_callable
    return self.python_callable(*self.op_args, **self.op_kwargs)
  File "/opt/airflow/dags/main.py", line 60, in main
    config = get_config('web')
  File "/opt/airflow/dags/main.py", line 22, in get_config
    return {key: value for key, value in parser.items(section)}
  File "/usr/local/lib/python3.8/configparser.py", line 849, in items
    raise NoSectionError(section)
configparser.NoSectionError: No section: 'web'
[2023-12-07T16:33:39.343+0000] {taskinstance.py:1400} INFO - Marking task as FAILED. dag_id=my_scraping_dag, task_id=main_task, execution_date=20230812T000000, start_date=20231207T163339, end_date=20231207T163339
[2023-12-07T16:33:39.349+0000] {standard_task_runner.py:104} ERROR - Failed to execute job 812 for task main_task (No section: 'web'; 4017)
[2023-12-07T16:33:39.357+0000] {local_task_job_runner.py:228} INFO - Task exited with return code 1
[2023-12-07T16:33:39.394+0000] {taskinstance.py:2778} INFO - 0 downstream tasks scheduled from follow-on schedule check
[2023-12-07T16:42:19.759+0000] {taskinstance.py:1159} INFO - Dependencies all met for dep_context=non-requeueable deps ti=<TaskInstance: my_scraping_dag.main_task scheduled__2023-08-12T00:00:00+00:00 [queued]>
[2023-12-07T16:42:19.763+0000] {taskinstance.py:1159} INFO - Dependencies all met for dep_context=requeueable deps ti=<TaskInstance: my_scraping_dag.main_task scheduled__2023-08-12T00:00:00+00:00 [queued]>
[2023-12-07T16:42:19.763+0000] {taskinstance.py:1361} INFO - Starting attempt 1 of 1
[2023-12-07T16:42:19.770+0000] {taskinstance.py:1382} INFO - Executing <Task(PythonOperator): main_task> on 2023-08-12 00:00:00+00:00
[2023-12-07T16:42:19.772+0000] {standard_task_runner.py:57} INFO - Started process 4909 to run task
[2023-12-07T16:42:19.774+0000] {standard_task_runner.py:84} INFO - Running: ['***', 'tasks', 'run', 'my_scraping_dag', 'main_task', 'scheduled__2023-08-12T00:00:00+00:00', '--job-id', '1157', '--raw', '--subdir', 'DAGS_FOLDER/main.py', '--cfg-path', '/tmp/tmpvkk7rnyh']
[2023-12-07T16:42:19.776+0000] {standard_task_runner.py:85} INFO - Job 1157: Subtask main_task
[2023-12-07T16:42:19.798+0000] {task_command.py:416} INFO - Running <TaskInstance: my_scraping_dag.main_task scheduled__2023-08-12T00:00:00+00:00 [running]> on host 63b0c7e341c0
[2023-12-07T16:42:19.829+0000] {taskinstance.py:1662} INFO - Exporting env vars: AIRFLOW_CTX_DAG_OWNER='***' AIRFLOW_CTX_DAG_ID='my_scraping_dag' AIRFLOW_CTX_TASK_ID='main_task' AIRFLOW_CTX_EXECUTION_DATE='2023-08-12T00:00:00+00:00' AIRFLOW_CTX_TRY_NUMBER='1' AIRFLOW_CTX_DAG_RUN_ID='scheduled__2023-08-12T00:00:00+00:00'
[2023-12-07T16:42:19.830+0000] {taskinstance.py:1937} ERROR - Task failed with exception
Traceback (most recent call last):
  File "/usr/local/lib/python3.8/configparser.py", line 846, in items
    d.update(self._sections[section])
KeyError: 'web'

During handling of the above exception, another exception occurred:

Traceback (most recent call last):
  File "/home/airflow/.local/lib/python3.8/site-packages/airflow/operators/python.py", line 192, in execute
    return_value = self.execute_callable()
  File "/home/airflow/.local/lib/python3.8/site-packages/airflow/operators/python.py", line 209, in execute_callable
    return self.python_callable(*self.op_args, **self.op_kwargs)
  File "/opt/airflow/dags/main.py", line 60, in main
    config = get_config('web')
  File "/opt/airflow/dags/main.py", line 22, in get_config
    return {key: value for key, value in parser.items(section)}
  File "/usr/local/lib/python3.8/configparser.py", line 849, in items
    raise NoSectionError(section)
configparser.NoSectionError: No section: 'web'
[2023-12-07T16:42:19.834+0000] {taskinstance.py:1400} INFO - Marking task as FAILED. dag_id=my_scraping_dag, task_id=main_task, execution_date=20230812T000000, start_date=20231207T164219, end_date=20231207T164219
[2023-12-07T16:42:19.838+0000] {standard_task_runner.py:104} ERROR - Failed to execute job 1157 for task main_task (No section: 'web'; 4909)
[2023-12-07T16:42:19.867+0000] {local_task_job_runner.py:228} INFO - Task exited with return code 1
[2023-12-07T16:42:19.878+0000] {taskinstance.py:2778} INFO - 0 downstream tasks scheduled from follow-on schedule check
[2023-12-07T17:01:12.123+0000] {taskinstance.py:1159} INFO - Dependencies all met for dep_context=non-requeueable deps ti=<TaskInstance: my_scraping_dag.main_task scheduled__2023-08-12T00:00:00+00:00 [queued]>
[2023-12-07T17:01:12.129+0000] {taskinstance.py:1159} INFO - Dependencies all met for dep_context=requeueable deps ti=<TaskInstance: my_scraping_dag.main_task scheduled__2023-08-12T00:00:00+00:00 [queued]>
[2023-12-07T17:01:12.130+0000] {taskinstance.py:1361} INFO - Starting attempt 1 of 1
[2023-12-07T17:01:12.139+0000] {taskinstance.py:1382} INFO - Executing <Task(PythonOperator): main_task> on 2023-08-12 00:00:00+00:00
[2023-12-07T17:01:12.146+0000] {standard_task_runner.py:57} INFO - Started process 6271 to run task
[2023-12-07T17:01:12.150+0000] {standard_task_runner.py:84} INFO - Running: ['***', 'tasks', 'run', 'my_scraping_dag', 'main_task', 'scheduled__2023-08-12T00:00:00+00:00', '--job-id', '1601', '--raw', '--subdir', 'DAGS_FOLDER/main.py', '--cfg-path', '/tmp/tmp26iwerlw']
[2023-12-07T17:01:12.153+0000] {standard_task_runner.py:85} INFO - Job 1601: Subtask main_task
[2023-12-07T17:01:12.207+0000] {task_command.py:416} INFO - Running <TaskInstance: my_scraping_dag.main_task scheduled__2023-08-12T00:00:00+00:00 [running]> on host 63b0c7e341c0
[2023-12-07T17:01:12.265+0000] {taskinstance.py:1662} INFO - Exporting env vars: AIRFLOW_CTX_DAG_OWNER='***' AIRFLOW_CTX_DAG_ID='my_scraping_dag' AIRFLOW_CTX_TASK_ID='main_task' AIRFLOW_CTX_EXECUTION_DATE='2023-08-12T00:00:00+00:00' AIRFLOW_CTX_TRY_NUMBER='1' AIRFLOW_CTX_DAG_RUN_ID='scheduled__2023-08-12T00:00:00+00:00'
[2023-12-07T17:01:12.303+0000] {logging_mixin.py:154} INFO - base_url: https://tuncbotanik.com
[2023-12-07T17:01:12.305+0000] {python.py:194} INFO - Done. Returned value was: ('https://tuncbotanik.com', {'User-Agent': 'Mozilla/5.0 (Macintosh; Intel Mac OS X 10_15_7) AppleWebKit/537.36 (KHTML, like Gecko) Chrome/119.0.0.0 Safari/537.36', 'Accept-Language': 'tr-TR,tr;q=0.9,en-US;q=0.8,en;q=0.7'}, {'dbname': 'plant', 'user': 'aozgokme', 'password': '***', 'host': 'localhost', 'port': '5432'})
[2023-12-07T17:01:12.322+0000] {taskinstance.py:1400} INFO - Marking task as SUCCESS. dag_id=my_scraping_dag, task_id=main_task, execution_date=20230812T000000, start_date=20231207T170112, end_date=20231207T170112
[2023-12-07T17:01:12.360+0000] {local_task_job_runner.py:228} INFO - Task exited with return code 0
[2023-12-07T17:01:12.377+0000] {taskinstance.py:2778} INFO - 1 downstream tasks scheduled from follow-on schedule check
[2023-12-07T17:04:29.752+0000] {taskinstance.py:1159} INFO - Dependencies all met for dep_context=non-requeueable deps ti=<TaskInstance: my_scraping_dag.main_task scheduled__2023-08-12T00:00:00+00:00 [queued]>
[2023-12-07T17:04:29.757+0000] {taskinstance.py:1159} INFO - Dependencies all met for dep_context=requeueable deps ti=<TaskInstance: my_scraping_dag.main_task scheduled__2023-08-12T00:00:00+00:00 [queued]>
[2023-12-07T17:04:29.758+0000] {taskinstance.py:1361} INFO - Starting attempt 1 of 1
[2023-12-07T17:04:29.770+0000] {taskinstance.py:1382} INFO - Executing <Task(PythonOperator): main_task> on 2023-08-12 00:00:00+00:00
[2023-12-07T17:04:29.773+0000] {standard_task_runner.py:57} INFO - Started process 7712 to run task
[2023-12-07T17:04:29.775+0000] {standard_task_runner.py:84} INFO - Running: ['***', 'tasks', 'run', 'my_scraping_dag', 'main_task', 'scheduled__2023-08-12T00:00:00+00:00', '--job-id', '2287', '--raw', '--subdir', 'DAGS_FOLDER/main.py', '--cfg-path', '/tmp/tmppomzqw57']
[2023-12-07T17:04:29.777+0000] {standard_task_runner.py:85} INFO - Job 2287: Subtask main_task
[2023-12-07T17:04:29.810+0000] {task_command.py:416} INFO - Running <TaskInstance: my_scraping_dag.main_task scheduled__2023-08-12T00:00:00+00:00 [running]> on host 63b0c7e341c0
[2023-12-07T17:04:29.847+0000] {taskinstance.py:1662} INFO - Exporting env vars: AIRFLOW_CTX_DAG_OWNER='***' AIRFLOW_CTX_DAG_ID='my_scraping_dag' AIRFLOW_CTX_TASK_ID='main_task' AIRFLOW_CTX_EXECUTION_DATE='2023-08-12T00:00:00+00:00' AIRFLOW_CTX_TRY_NUMBER='1' AIRFLOW_CTX_DAG_RUN_ID='scheduled__2023-08-12T00:00:00+00:00'
[2023-12-07T17:04:29.874+0000] {logging_mixin.py:154} INFO - base_url: https://tuncbotanik.com
[2023-12-07T17:04:29.875+0000] {python.py:194} INFO - Done. Returned value was: ('https://tuncbotanik.com', {'User-Agent': 'Mozilla/5.0 (Macintosh; Intel Mac OS X 10_15_7) AppleWebKit/537.36 (KHTML, like Gecko) Chrome/119.0.0.0 Safari/537.36', 'Accept-Language': 'tr-TR,tr;q=0.9,en-US;q=0.8,en;q=0.7'}, {'dbname': 'plant', 'user': 'aozgokme', 'password': '***', 'host': 'localhost', 'port': '5432'})
[2023-12-07T17:04:29.886+0000] {taskinstance.py:1400} INFO - Marking task as SUCCESS. dag_id=my_scraping_dag, task_id=main_task, execution_date=20230812T000000, start_date=20231207T170429, end_date=20231207T170429
[2023-12-07T17:04:29.949+0000] {local_task_job_runner.py:228} INFO - Task exited with return code 0
[2023-12-07T17:04:29.977+0000] {taskinstance.py:2778} INFO - 0 downstream tasks scheduled from follow-on schedule check
[2023-12-07T17:19:04.516+0000] {taskinstance.py:1159} INFO - Dependencies all met for dep_context=non-requeueable deps ti=<TaskInstance: my_scraping_dag.main_task scheduled__2023-08-12T00:00:00+00:00 [queued]>
[2023-12-07T17:19:04.520+0000] {taskinstance.py:1159} INFO - Dependencies all met for dep_context=requeueable deps ti=<TaskInstance: my_scraping_dag.main_task scheduled__2023-08-12T00:00:00+00:00 [queued]>
[2023-12-07T17:19:04.521+0000] {taskinstance.py:1361} INFO - Starting attempt 1 of 1
[2023-12-07T17:19:04.529+0000] {taskinstance.py:1382} INFO - Executing <Task(PythonOperator): main_task> on 2023-08-12 00:00:00+00:00
[2023-12-07T17:19:04.532+0000] {standard_task_runner.py:57} INFO - Started process 9002 to run task
[2023-12-07T17:19:04.535+0000] {standard_task_runner.py:84} INFO - Running: ['***', 'tasks', 'run', 'my_scraping_dag', 'main_task', 'scheduled__2023-08-12T00:00:00+00:00', '--job-id', '2753', '--raw', '--subdir', 'DAGS_FOLDER/main.py', '--cfg-path', '/tmp/tmpn0imhtt4']
[2023-12-07T17:19:04.537+0000] {standard_task_runner.py:85} INFO - Job 2753: Subtask main_task
[2023-12-07T17:19:04.570+0000] {task_command.py:416} INFO - Running <TaskInstance: my_scraping_dag.main_task scheduled__2023-08-12T00:00:00+00:00 [running]> on host 63b0c7e341c0
[2023-12-07T17:19:04.617+0000] {taskinstance.py:1662} INFO - Exporting env vars: AIRFLOW_CTX_DAG_OWNER='***' AIRFLOW_CTX_DAG_ID='my_scraping_dag' AIRFLOW_CTX_TASK_ID='main_task' AIRFLOW_CTX_EXECUTION_DATE='2023-08-12T00:00:00+00:00' AIRFLOW_CTX_TRY_NUMBER='1' AIRFLOW_CTX_DAG_RUN_ID='scheduled__2023-08-12T00:00:00+00:00'
[2023-12-07T17:19:05.410+0000] {taskinstance.py:1937} ERROR - Task failed with exception
Traceback (most recent call last):
  File "/home/airflow/.local/lib/python3.8/site-packages/airflow/operators/python.py", line 192, in execute
    return_value = self.execute_callable()
  File "/home/airflow/.local/lib/python3.8/site-packages/airflow/operators/python.py", line 209, in execute_callable
    return self.python_callable(*self.op_args, **self.op_kwargs)
  File "/opt/airflow/dags/main.py", line 80, in main
    insert_data_to_db(products, db_params)
  File "/opt/airflow/dags/main.py", line 43, in insert_data_to_db
    with psycopg2.connect(**db_params) as conn:
  File "/home/airflow/.local/lib/python3.8/site-packages/psycopg2/__init__.py", line 122, in connect
    conn = _connect(dsn, connection_factory=connection_factory, **kwasync)
psycopg2.OperationalError: connection to server at "localhost" (127.0.0.1), port 5432 failed: Connection refused
	Is the server running on that host and accepting TCP/IP connections?
connection to server at "localhost" (::1), port 5432 failed: Cannot assign requested address
	Is the server running on that host and accepting TCP/IP connections?

[2023-12-07T17:19:05.420+0000] {taskinstance.py:1400} INFO - Marking task as FAILED. dag_id=my_scraping_dag, task_id=main_task, execution_date=20230812T000000, start_date=20231207T171904, end_date=20231207T171905
[2023-12-07T17:19:05.430+0000] {standard_task_runner.py:104} ERROR - Failed to execute job 2753 for task main_task (connection to server at "localhost" (127.0.0.1), port 5432 failed: Connection refused
	Is the server running on that host and accepting TCP/IP connections?
connection to server at "localhost" (::1), port 5432 failed: Cannot assign requested address
	Is the server running on that host and accepting TCP/IP connections?
; 9002)
[2023-12-07T17:19:05.473+0000] {local_task_job_runner.py:228} INFO - Task exited with return code 1
[2023-12-07T17:19:05.506+0000] {taskinstance.py:2778} INFO - 0 downstream tasks scheduled from follow-on schedule check
[2023-12-07T17:23:23.496+0000] {taskinstance.py:1159} INFO - Dependencies all met for dep_context=non-requeueable deps ti=<TaskInstance: my_scraping_dag.main_task scheduled__2023-08-12T00:00:00+00:00 [queued]>
[2023-12-07T17:23:23.501+0000] {taskinstance.py:1159} INFO - Dependencies all met for dep_context=requeueable deps ti=<TaskInstance: my_scraping_dag.main_task scheduled__2023-08-12T00:00:00+00:00 [queued]>
[2023-12-07T17:23:23.501+0000] {taskinstance.py:1361} INFO - Starting attempt 1 of 1
[2023-12-07T17:23:23.508+0000] {taskinstance.py:1382} INFO - Executing <Task(PythonOperator): main_task> on 2023-08-12 00:00:00+00:00
[2023-12-07T17:23:23.511+0000] {standard_task_runner.py:57} INFO - Started process 9809 to run task
[2023-12-07T17:23:23.513+0000] {standard_task_runner.py:84} INFO - Running: ['***', 'tasks', 'run', 'my_scraping_dag', 'main_task', 'scheduled__2023-08-12T00:00:00+00:00', '--job-id', '3095', '--raw', '--subdir', 'DAGS_FOLDER/main.py', '--cfg-path', '/tmp/tmpc_a8jebs']
[2023-12-07T17:23:23.515+0000] {standard_task_runner.py:85} INFO - Job 3095: Subtask main_task
[2023-12-07T17:23:23.541+0000] {task_command.py:416} INFO - Running <TaskInstance: my_scraping_dag.main_task scheduled__2023-08-12T00:00:00+00:00 [running]> on host 63b0c7e341c0
[2023-12-07T17:23:23.585+0000] {taskinstance.py:1662} INFO - Exporting env vars: AIRFLOW_CTX_DAG_OWNER='***' AIRFLOW_CTX_DAG_ID='my_scraping_dag' AIRFLOW_CTX_TASK_ID='main_task' AIRFLOW_CTX_EXECUTION_DATE='2023-08-12T00:00:00+00:00' AIRFLOW_CTX_TRY_NUMBER='1' AIRFLOW_CTX_DAG_RUN_ID='scheduled__2023-08-12T00:00:00+00:00'
[2023-12-07T17:23:24.451+0000] {taskinstance.py:1937} ERROR - Task failed with exception
Traceback (most recent call last):
  File "/home/airflow/.local/lib/python3.8/site-packages/airflow/operators/python.py", line 192, in execute
    return_value = self.execute_callable()
  File "/home/airflow/.local/lib/python3.8/site-packages/airflow/operators/python.py", line 209, in execute_callable
    return self.python_callable(*self.op_args, **self.op_kwargs)
  File "/opt/airflow/dags/main.py", line 73, in main
    insert_data_to_db(products, db_params)
  File "/opt/airflow/dags/main.py", line 40, in insert_data_to_db
    with psycopg2.connect(**db_params) as conn:
  File "/home/airflow/.local/lib/python3.8/site-packages/psycopg2/__init__.py", line 122, in connect
    conn = _connect(dsn, connection_factory=connection_factory, **kwasync)
psycopg2.OperationalError: connection to server at "localhost" (127.0.0.1), port 5432 failed: Connection refused
	Is the server running on that host and accepting TCP/IP connections?
connection to server at "localhost" (::1), port 5432 failed: Cannot assign requested address
	Is the server running on that host and accepting TCP/IP connections?

[2023-12-07T17:23:24.462+0000] {taskinstance.py:1400} INFO - Marking task as FAILED. dag_id=my_scraping_dag, task_id=main_task, execution_date=20230812T000000, start_date=20231207T172323, end_date=20231207T172324
[2023-12-07T17:23:24.494+0000] {standard_task_runner.py:104} ERROR - Failed to execute job 3095 for task main_task (connection to server at "localhost" (127.0.0.1), port 5432 failed: Connection refused
	Is the server running on that host and accepting TCP/IP connections?
connection to server at "localhost" (::1), port 5432 failed: Cannot assign requested address
	Is the server running on that host and accepting TCP/IP connections?
; 9809)
[2023-12-07T17:23:24.533+0000] {local_task_job_runner.py:228} INFO - Task exited with return code 1
[2023-12-07T17:23:24.549+0000] {taskinstance.py:2778} INFO - 0 downstream tasks scheduled from follow-on schedule check
[2023-12-07T17:29:03.624+0000] {taskinstance.py:1159} INFO - Dependencies all met for dep_context=non-requeueable deps ti=<TaskInstance: my_scraping_dag.main_task scheduled__2023-08-12T00:00:00+00:00 [queued]>
[2023-12-07T17:29:03.629+0000] {taskinstance.py:1159} INFO - Dependencies all met for dep_context=requeueable deps ti=<TaskInstance: my_scraping_dag.main_task scheduled__2023-08-12T00:00:00+00:00 [queued]>
[2023-12-07T17:29:03.629+0000] {taskinstance.py:1361} INFO - Starting attempt 1 of 1
[2023-12-07T17:29:03.637+0000] {taskinstance.py:1382} INFO - Executing <Task(PythonOperator): main_task> on 2023-08-12 00:00:00+00:00
[2023-12-07T17:29:03.640+0000] {standard_task_runner.py:57} INFO - Started process 10641 to run task
[2023-12-07T17:29:03.642+0000] {standard_task_runner.py:84} INFO - Running: ['***', 'tasks', 'run', 'my_scraping_dag', 'main_task', 'scheduled__2023-08-12T00:00:00+00:00', '--job-id', '3437', '--raw', '--subdir', 'DAGS_FOLDER/main.py', '--cfg-path', '/tmp/tmpcbm1jiq1']
[2023-12-07T17:29:03.644+0000] {standard_task_runner.py:85} INFO - Job 3437: Subtask main_task
[2023-12-07T17:29:03.671+0000] {task_command.py:416} INFO - Running <TaskInstance: my_scraping_dag.main_task scheduled__2023-08-12T00:00:00+00:00 [running]> on host 63b0c7e341c0
[2023-12-07T17:29:03.713+0000] {taskinstance.py:1662} INFO - Exporting env vars: AIRFLOW_CTX_DAG_OWNER='***' AIRFLOW_CTX_DAG_ID='my_scraping_dag' AIRFLOW_CTX_TASK_ID='main_task' AIRFLOW_CTX_EXECUTION_DATE='2023-08-12T00:00:00+00:00' AIRFLOW_CTX_TRY_NUMBER='1' AIRFLOW_CTX_DAG_RUN_ID='scheduled__2023-08-12T00:00:00+00:00'
[2023-12-07T17:29:04.479+0000] {taskinstance.py:1937} ERROR - Task failed with exception
Traceback (most recent call last):
  File "/home/airflow/.local/lib/python3.8/site-packages/airflow/operators/python.py", line 192, in execute
    return_value = self.execute_callable()
  File "/home/airflow/.local/lib/python3.8/site-packages/airflow/operators/python.py", line 209, in execute_callable
    return self.python_callable(*self.op_args, **self.op_kwargs)
  File "/opt/airflow/dags/main.py", line 73, in main
    insert_data_to_db(products, db_params)
  File "/opt/airflow/dags/main.py", line 40, in insert_data_to_db
    with psycopg2.connect(**db_params) as conn:
  File "/home/airflow/.local/lib/python3.8/site-packages/psycopg2/__init__.py", line 122, in connect
    conn = _connect(dsn, connection_factory=connection_factory, **kwasync)
psycopg2.OperationalError: connection to server at "localhost" (127.0.0.1), port 5432 failed: Connection refused
	Is the server running on that host and accepting TCP/IP connections?
connection to server at "localhost" (::1), port 5432 failed: Cannot assign requested address
	Is the server running on that host and accepting TCP/IP connections?

[2023-12-07T17:29:04.487+0000] {taskinstance.py:1400} INFO - Marking task as FAILED. dag_id=my_scraping_dag, task_id=main_task, execution_date=20230812T000000, start_date=20231207T172903, end_date=20231207T172904
[2023-12-07T17:29:04.502+0000] {standard_task_runner.py:104} ERROR - Failed to execute job 3437 for task main_task (connection to server at "localhost" (127.0.0.1), port 5432 failed: Connection refused
	Is the server running on that host and accepting TCP/IP connections?
connection to server at "localhost" (::1), port 5432 failed: Cannot assign requested address
	Is the server running on that host and accepting TCP/IP connections?
; 10641)
[2023-12-07T17:29:04.543+0000] {local_task_job_runner.py:228} INFO - Task exited with return code 1
[2023-12-07T17:29:04.575+0000] {taskinstance.py:2778} INFO - 0 downstream tasks scheduled from follow-on schedule check
[2023-12-09T07:35:11.180+0000] {taskinstance.py:1159} INFO - Dependencies all met for dep_context=non-requeueable deps ti=<TaskInstance: my_scraping_dag.main_task scheduled__2023-08-12T00:00:00+00:00 [queued]>
[2023-12-09T07:35:11.184+0000] {taskinstance.py:1159} INFO - Dependencies all met for dep_context=requeueable deps ti=<TaskInstance: my_scraping_dag.main_task scheduled__2023-08-12T00:00:00+00:00 [queued]>
[2023-12-09T07:35:11.184+0000] {taskinstance.py:1361} INFO - Starting attempt 1 of 1
[2023-12-09T07:35:11.192+0000] {taskinstance.py:1382} INFO - Executing <Task(PythonOperator): main_task> on 2023-08-12 00:00:00+00:00
[2023-12-09T07:35:11.194+0000] {standard_task_runner.py:57} INFO - Started process 1058 to run task
[2023-12-09T07:35:11.196+0000] {standard_task_runner.py:84} INFO - Running: ['***', 'tasks', 'run', 'my_scraping_dag', 'main_task', 'scheduled__2023-08-12T00:00:00+00:00', '--job-id', '227', '--raw', '--subdir', 'DAGS_FOLDER/main.py', '--cfg-path', '/tmp/tmpp4f0kah5']
[2023-12-09T07:35:11.197+0000] {standard_task_runner.py:85} INFO - Job 227: Subtask main_task
[2023-12-09T07:35:11.222+0000] {task_command.py:416} INFO - Running <TaskInstance: my_scraping_dag.main_task scheduled__2023-08-12T00:00:00+00:00 [running]> on host 36b5ef2505c9
[2023-12-09T07:35:11.262+0000] {taskinstance.py:1662} INFO - Exporting env vars: AIRFLOW_CTX_DAG_OWNER='***' AIRFLOW_CTX_DAG_ID='my_scraping_dag' AIRFLOW_CTX_TASK_ID='main_task' AIRFLOW_CTX_EXECUTION_DATE='2023-08-12T00:00:00+00:00' AIRFLOW_CTX_TRY_NUMBER='1' AIRFLOW_CTX_DAG_RUN_ID='scheduled__2023-08-12T00:00:00+00:00'
[2023-12-09T07:35:11.268+0000] {taskinstance.py:1937} ERROR - Task failed with exception
Traceback (most recent call last):
  File "/home/airflow/.local/lib/python3.8/site-packages/airflow/operators/python.py", line 192, in execute
    return_value = self.execute_callable()
  File "/home/airflow/.local/lib/python3.8/site-packages/airflow/operators/python.py", line 209, in execute_callable
    return self.python_callable(*self.op_args, **self.op_kwargs)
  File "/opt/airflow/dags/main.py", line 64, in main
    base_url = Variable.get('base_url')
  File "/home/airflow/.local/lib/python3.8/site-packages/airflow/models/variable.py", line 140, in get
    raise KeyError(f"Variable {key} does not exist")
KeyError: 'Variable base_url does not exist'
[2023-12-09T07:35:11.275+0000] {taskinstance.py:1400} INFO - Marking task as FAILED. dag_id=my_scraping_dag, task_id=main_task, execution_date=20230812T000000, start_date=20231209T073511, end_date=20231209T073511
[2023-12-09T07:35:11.280+0000] {standard_task_runner.py:104} ERROR - Failed to execute job 227 for task main_task ('Variable base_url does not exist'; 1058)
[2023-12-09T07:35:11.288+0000] {local_task_job_runner.py:228} INFO - Task exited with return code 1
[2023-12-09T07:35:11.299+0000] {taskinstance.py:2778} INFO - 0 downstream tasks scheduled from follow-on schedule check
