[2023-12-07T16:33:28.711+0000] {taskinstance.py:1159} INFO - Dependencies all met for dep_context=non-requeueable deps ti=<TaskInstance: my_scraping_dag.main_task scheduled__2023-08-02T00:00:00+00:00 [queued]>
[2023-12-07T16:33:28.715+0000] {taskinstance.py:1159} INFO - Dependencies all met for dep_context=requeueable deps ti=<TaskInstance: my_scraping_dag.main_task scheduled__2023-08-02T00:00:00+00:00 [queued]>
[2023-12-07T16:33:28.715+0000] {taskinstance.py:1361} INFO - Starting attempt 1 of 1
[2023-12-07T16:33:28.721+0000] {taskinstance.py:1382} INFO - Executing <Task(PythonOperator): main_task> on 2023-08-02 00:00:00+00:00
[2023-12-07T16:33:28.723+0000] {standard_task_runner.py:57} INFO - Started process 3991 to run task
[2023-12-07T16:33:28.725+0000] {standard_task_runner.py:84} INFO - Running: ['***', 'tasks', 'run', 'my_scraping_dag', 'main_task', 'scheduled__2023-08-02T00:00:00+00:00', '--job-id', '802', '--raw', '--subdir', 'DAGS_FOLDER/main.py', '--cfg-path', '/tmp/tmpx7kyymi1']
[2023-12-07T16:33:28.726+0000] {standard_task_runner.py:85} INFO - Job 802: Subtask main_task
[2023-12-07T16:33:28.748+0000] {task_command.py:416} INFO - Running <TaskInstance: my_scraping_dag.main_task scheduled__2023-08-02T00:00:00+00:00 [running]> on host 63b0c7e341c0
[2023-12-07T16:33:28.777+0000] {taskinstance.py:1662} INFO - Exporting env vars: AIRFLOW_CTX_DAG_OWNER='***' AIRFLOW_CTX_DAG_ID='my_scraping_dag' AIRFLOW_CTX_TASK_ID='main_task' AIRFLOW_CTX_EXECUTION_DATE='2023-08-02T00:00:00+00:00' AIRFLOW_CTX_TRY_NUMBER='1' AIRFLOW_CTX_DAG_RUN_ID='scheduled__2023-08-02T00:00:00+00:00'
[2023-12-07T16:33:28.778+0000] {taskinstance.py:1937} ERROR - Task failed with exception
Traceback (most recent call last):
  File "/usr/local/lib/python3.8/configparser.py", line 846, in items
    d.update(self._sections[section])
KeyError: 'web'

During handling of the above exception, another exception occurred:

Traceback (most recent call last):
  File "/home/airflow/.local/lib/python3.8/site-packages/airflow/operators/python.py", line 192, in execute
    return_value = self.execute_callable()
  File "/home/airflow/.local/lib/python3.8/site-packages/airflow/operators/python.py", line 209, in execute_callable
    return self.python_callable(*self.op_args, **self.op_kwargs)
  File "/opt/airflow/dags/main.py", line 60, in main
    config = get_config('web')
  File "/opt/airflow/dags/main.py", line 22, in get_config
    return {key: value for key, value in parser.items(section)}
  File "/usr/local/lib/python3.8/configparser.py", line 849, in items
    raise NoSectionError(section)
configparser.NoSectionError: No section: 'web'
[2023-12-07T16:33:28.781+0000] {taskinstance.py:1400} INFO - Marking task as FAILED. dag_id=my_scraping_dag, task_id=main_task, execution_date=20230802T000000, start_date=20231207T163328, end_date=20231207T163328
[2023-12-07T16:33:28.786+0000] {standard_task_runner.py:104} ERROR - Failed to execute job 802 for task main_task (No section: 'web'; 3991)
[2023-12-07T16:33:28.819+0000] {local_task_job_runner.py:228} INFO - Task exited with return code 1
[2023-12-07T16:33:28.831+0000] {taskinstance.py:2778} INFO - 0 downstream tasks scheduled from follow-on schedule check
[2023-12-07T16:42:14.781+0000] {taskinstance.py:1159} INFO - Dependencies all met for dep_context=non-requeueable deps ti=<TaskInstance: my_scraping_dag.main_task scheduled__2023-08-02T00:00:00+00:00 [queued]>
[2023-12-07T16:42:14.786+0000] {taskinstance.py:1159} INFO - Dependencies all met for dep_context=requeueable deps ti=<TaskInstance: my_scraping_dag.main_task scheduled__2023-08-02T00:00:00+00:00 [queued]>
[2023-12-07T16:42:14.786+0000] {taskinstance.py:1361} INFO - Starting attempt 1 of 1
[2023-12-07T16:42:14.793+0000] {taskinstance.py:1382} INFO - Executing <Task(PythonOperator): main_task> on 2023-08-02 00:00:00+00:00
[2023-12-07T16:42:14.796+0000] {standard_task_runner.py:57} INFO - Started process 4889 to run task
[2023-12-07T16:42:14.799+0000] {standard_task_runner.py:84} INFO - Running: ['***', 'tasks', 'run', 'my_scraping_dag', 'main_task', 'scheduled__2023-08-02T00:00:00+00:00', '--job-id', '1147', '--raw', '--subdir', 'DAGS_FOLDER/main.py', '--cfg-path', '/tmp/tmpks1sskf4']
[2023-12-07T16:42:14.801+0000] {standard_task_runner.py:85} INFO - Job 1147: Subtask main_task
[2023-12-07T16:42:14.826+0000] {task_command.py:416} INFO - Running <TaskInstance: my_scraping_dag.main_task scheduled__2023-08-02T00:00:00+00:00 [running]> on host 63b0c7e341c0
[2023-12-07T16:42:14.859+0000] {taskinstance.py:1662} INFO - Exporting env vars: AIRFLOW_CTX_DAG_OWNER='***' AIRFLOW_CTX_DAG_ID='my_scraping_dag' AIRFLOW_CTX_TASK_ID='main_task' AIRFLOW_CTX_EXECUTION_DATE='2023-08-02T00:00:00+00:00' AIRFLOW_CTX_TRY_NUMBER='1' AIRFLOW_CTX_DAG_RUN_ID='scheduled__2023-08-02T00:00:00+00:00'
[2023-12-07T16:42:14.860+0000] {taskinstance.py:1937} ERROR - Task failed with exception
Traceback (most recent call last):
  File "/usr/local/lib/python3.8/configparser.py", line 846, in items
    d.update(self._sections[section])
KeyError: 'web'

During handling of the above exception, another exception occurred:

Traceback (most recent call last):
  File "/home/airflow/.local/lib/python3.8/site-packages/airflow/operators/python.py", line 192, in execute
    return_value = self.execute_callable()
  File "/home/airflow/.local/lib/python3.8/site-packages/airflow/operators/python.py", line 209, in execute_callable
    return self.python_callable(*self.op_args, **self.op_kwargs)
  File "/opt/airflow/dags/main.py", line 60, in main
    config = get_config('web')
  File "/opt/airflow/dags/main.py", line 22, in get_config
    return {key: value for key, value in parser.items(section)}
  File "/usr/local/lib/python3.8/configparser.py", line 849, in items
    raise NoSectionError(section)
configparser.NoSectionError: No section: 'web'
[2023-12-07T16:42:14.865+0000] {taskinstance.py:1400} INFO - Marking task as FAILED. dag_id=my_scraping_dag, task_id=main_task, execution_date=20230802T000000, start_date=20231207T164214, end_date=20231207T164214
[2023-12-07T16:42:14.870+0000] {standard_task_runner.py:104} ERROR - Failed to execute job 1147 for task main_task (No section: 'web'; 4889)
[2023-12-07T16:42:14.891+0000] {local_task_job_runner.py:228} INFO - Task exited with return code 1
[2023-12-07T16:42:14.903+0000] {taskinstance.py:2778} INFO - 0 downstream tasks scheduled from follow-on schedule check
[2023-12-07T17:01:08.355+0000] {taskinstance.py:1159} INFO - Dependencies all met for dep_context=non-requeueable deps ti=<TaskInstance: my_scraping_dag.main_task scheduled__2023-08-02T00:00:00+00:00 [queued]>
[2023-12-07T17:01:08.362+0000] {taskinstance.py:1159} INFO - Dependencies all met for dep_context=requeueable deps ti=<TaskInstance: my_scraping_dag.main_task scheduled__2023-08-02T00:00:00+00:00 [queued]>
[2023-12-07T17:01:08.363+0000] {taskinstance.py:1361} INFO - Starting attempt 1 of 1
[2023-12-07T17:01:08.373+0000] {taskinstance.py:1382} INFO - Executing <Task(PythonOperator): main_task> on 2023-08-02 00:00:00+00:00
[2023-12-07T17:01:08.380+0000] {standard_task_runner.py:57} INFO - Started process 6232 to run task
[2023-12-07T17:01:08.383+0000] {standard_task_runner.py:84} INFO - Running: ['***', 'tasks', 'run', 'my_scraping_dag', 'main_task', 'scheduled__2023-08-02T00:00:00+00:00', '--job-id', '1582', '--raw', '--subdir', 'DAGS_FOLDER/main.py', '--cfg-path', '/tmp/tmp1s0zi_tw']
[2023-12-07T17:01:08.385+0000] {standard_task_runner.py:85} INFO - Job 1582: Subtask main_task
[2023-12-07T17:01:08.427+0000] {task_command.py:416} INFO - Running <TaskInstance: my_scraping_dag.main_task scheduled__2023-08-02T00:00:00+00:00 [running]> on host 63b0c7e341c0
[2023-12-07T17:01:08.479+0000] {taskinstance.py:1662} INFO - Exporting env vars: AIRFLOW_CTX_DAG_OWNER='***' AIRFLOW_CTX_DAG_ID='my_scraping_dag' AIRFLOW_CTX_TASK_ID='main_task' AIRFLOW_CTX_EXECUTION_DATE='2023-08-02T00:00:00+00:00' AIRFLOW_CTX_TRY_NUMBER='1' AIRFLOW_CTX_DAG_RUN_ID='scheduled__2023-08-02T00:00:00+00:00'
[2023-12-07T17:01:08.510+0000] {logging_mixin.py:154} INFO - base_url: https://tuncbotanik.com
[2023-12-07T17:01:08.510+0000] {python.py:194} INFO - Done. Returned value was: ('https://tuncbotanik.com', {'User-Agent': 'Mozilla/5.0 (Macintosh; Intel Mac OS X 10_15_7) AppleWebKit/537.36 (KHTML, like Gecko) Chrome/119.0.0.0 Safari/537.36', 'Accept-Language': 'tr-TR,tr;q=0.9,en-US;q=0.8,en;q=0.7'}, {'dbname': 'plant', 'user': 'aozgokme', 'password': '***', 'host': 'localhost', 'port': '5432'})
[2023-12-07T17:01:08.526+0000] {taskinstance.py:1400} INFO - Marking task as SUCCESS. dag_id=my_scraping_dag, task_id=main_task, execution_date=20230802T000000, start_date=20231207T170108, end_date=20231207T170108
[2023-12-07T17:01:08.564+0000] {local_task_job_runner.py:228} INFO - Task exited with return code 0
[2023-12-07T17:01:08.577+0000] {taskinstance.py:2778} INFO - 1 downstream tasks scheduled from follow-on schedule check
[2023-12-07T17:04:28.903+0000] {taskinstance.py:1159} INFO - Dependencies all met for dep_context=non-requeueable deps ti=<TaskInstance: my_scraping_dag.main_task scheduled__2023-08-02T00:00:00+00:00 [queued]>
[2023-12-07T17:04:28.908+0000] {taskinstance.py:1159} INFO - Dependencies all met for dep_context=requeueable deps ti=<TaskInstance: my_scraping_dag.main_task scheduled__2023-08-02T00:00:00+00:00 [queued]>
[2023-12-07T17:04:28.908+0000] {taskinstance.py:1361} INFO - Starting attempt 1 of 1
[2023-12-07T17:04:28.927+0000] {taskinstance.py:1382} INFO - Executing <Task(PythonOperator): main_task> on 2023-08-02 00:00:00+00:00
[2023-12-07T17:04:28.931+0000] {standard_task_runner.py:57} INFO - Started process 7675 to run task
[2023-12-07T17:04:28.933+0000] {standard_task_runner.py:84} INFO - Running: ['***', 'tasks', 'run', 'my_scraping_dag', 'main_task', 'scheduled__2023-08-02T00:00:00+00:00', '--job-id', '2268', '--raw', '--subdir', 'DAGS_FOLDER/main.py', '--cfg-path', '/tmp/tmppbcb1h6q']
[2023-12-07T17:04:28.935+0000] {standard_task_runner.py:85} INFO - Job 2268: Subtask main_task
[2023-12-07T17:04:28.965+0000] {task_command.py:416} INFO - Running <TaskInstance: my_scraping_dag.main_task scheduled__2023-08-02T00:00:00+00:00 [running]> on host 63b0c7e341c0
[2023-12-07T17:04:29.014+0000] {taskinstance.py:1662} INFO - Exporting env vars: AIRFLOW_CTX_DAG_OWNER='***' AIRFLOW_CTX_DAG_ID='my_scraping_dag' AIRFLOW_CTX_TASK_ID='main_task' AIRFLOW_CTX_EXECUTION_DATE='2023-08-02T00:00:00+00:00' AIRFLOW_CTX_TRY_NUMBER='1' AIRFLOW_CTX_DAG_RUN_ID='scheduled__2023-08-02T00:00:00+00:00'
[2023-12-07T17:04:29.046+0000] {logging_mixin.py:154} INFO - base_url: https://tuncbotanik.com
[2023-12-07T17:04:29.047+0000] {python.py:194} INFO - Done. Returned value was: ('https://tuncbotanik.com', {'User-Agent': 'Mozilla/5.0 (Macintosh; Intel Mac OS X 10_15_7) AppleWebKit/537.36 (KHTML, like Gecko) Chrome/119.0.0.0 Safari/537.36', 'Accept-Language': 'tr-TR,tr;q=0.9,en-US;q=0.8,en;q=0.7'}, {'dbname': 'plant', 'user': 'aozgokme', 'password': '***', 'host': 'localhost', 'port': '5432'})
[2023-12-07T17:04:29.074+0000] {taskinstance.py:1400} INFO - Marking task as SUCCESS. dag_id=my_scraping_dag, task_id=main_task, execution_date=20230802T000000, start_date=20231207T170428, end_date=20231207T170429
[2023-12-07T17:04:29.107+0000] {local_task_job_runner.py:228} INFO - Task exited with return code 0
[2023-12-07T17:04:29.148+0000] {taskinstance.py:2778} INFO - 0 downstream tasks scheduled from follow-on schedule check
[2023-12-07T17:19:01.550+0000] {taskinstance.py:1159} INFO - Dependencies all met for dep_context=non-requeueable deps ti=<TaskInstance: my_scraping_dag.main_task scheduled__2023-08-02T00:00:00+00:00 [queued]>
[2023-12-07T17:19:01.564+0000] {taskinstance.py:1159} INFO - Dependencies all met for dep_context=requeueable deps ti=<TaskInstance: my_scraping_dag.main_task scheduled__2023-08-02T00:00:00+00:00 [queued]>
[2023-12-07T17:19:01.565+0000] {taskinstance.py:1361} INFO - Starting attempt 1 of 1
[2023-12-07T17:19:01.593+0000] {taskinstance.py:1382} INFO - Executing <Task(PythonOperator): main_task> on 2023-08-02 00:00:00+00:00
[2023-12-07T17:19:01.599+0000] {standard_task_runner.py:57} INFO - Started process 8981 to run task
[2023-12-07T17:19:01.603+0000] {standard_task_runner.py:84} INFO - Running: ['***', 'tasks', 'run', 'my_scraping_dag', 'main_task', 'scheduled__2023-08-02T00:00:00+00:00', '--job-id', '2743', '--raw', '--subdir', 'DAGS_FOLDER/main.py', '--cfg-path', '/tmp/tmpp3ej55l0']
[2023-12-07T17:19:01.605+0000] {standard_task_runner.py:85} INFO - Job 2743: Subtask main_task
[2023-12-07T17:19:01.647+0000] {task_command.py:416} INFO - Running <TaskInstance: my_scraping_dag.main_task scheduled__2023-08-02T00:00:00+00:00 [running]> on host 63b0c7e341c0
[2023-12-07T17:19:01.729+0000] {taskinstance.py:1662} INFO - Exporting env vars: AIRFLOW_CTX_DAG_OWNER='***' AIRFLOW_CTX_DAG_ID='my_scraping_dag' AIRFLOW_CTX_TASK_ID='main_task' AIRFLOW_CTX_EXECUTION_DATE='2023-08-02T00:00:00+00:00' AIRFLOW_CTX_TRY_NUMBER='1' AIRFLOW_CTX_DAG_RUN_ID='scheduled__2023-08-02T00:00:00+00:00'
[2023-12-07T17:19:02.466+0000] {taskinstance.py:1937} ERROR - Task failed with exception
Traceback (most recent call last):
  File "/home/airflow/.local/lib/python3.8/site-packages/airflow/operators/python.py", line 192, in execute
    return_value = self.execute_callable()
  File "/home/airflow/.local/lib/python3.8/site-packages/airflow/operators/python.py", line 209, in execute_callable
    return self.python_callable(*self.op_args, **self.op_kwargs)
  File "/opt/airflow/dags/main.py", line 80, in main
    insert_data_to_db(products, db_params)
  File "/opt/airflow/dags/main.py", line 43, in insert_data_to_db
    with psycopg2.connect(**db_params) as conn:
  File "/home/airflow/.local/lib/python3.8/site-packages/psycopg2/__init__.py", line 122, in connect
    conn = _connect(dsn, connection_factory=connection_factory, **kwasync)
psycopg2.OperationalError: connection to server at "localhost" (127.0.0.1), port 5432 failed: Connection refused
	Is the server running on that host and accepting TCP/IP connections?
connection to server at "localhost" (::1), port 5432 failed: Cannot assign requested address
	Is the server running on that host and accepting TCP/IP connections?

[2023-12-07T17:19:02.471+0000] {taskinstance.py:1400} INFO - Marking task as FAILED. dag_id=my_scraping_dag, task_id=main_task, execution_date=20230802T000000, start_date=20231207T171901, end_date=20231207T171902
[2023-12-07T17:19:02.475+0000] {standard_task_runner.py:104} ERROR - Failed to execute job 2743 for task main_task (connection to server at "localhost" (127.0.0.1), port 5432 failed: Connection refused
	Is the server running on that host and accepting TCP/IP connections?
connection to server at "localhost" (::1), port 5432 failed: Cannot assign requested address
	Is the server running on that host and accepting TCP/IP connections?
; 8981)
[2023-12-07T17:19:02.502+0000] {local_task_job_runner.py:228} INFO - Task exited with return code 1
[2023-12-07T17:19:02.510+0000] {taskinstance.py:2778} INFO - 0 downstream tasks scheduled from follow-on schedule check
[2023-12-07T17:23:18.831+0000] {taskinstance.py:1159} INFO - Dependencies all met for dep_context=non-requeueable deps ti=<TaskInstance: my_scraping_dag.main_task scheduled__2023-08-02T00:00:00+00:00 [queued]>
[2023-12-07T17:23:18.836+0000] {taskinstance.py:1159} INFO - Dependencies all met for dep_context=requeueable deps ti=<TaskInstance: my_scraping_dag.main_task scheduled__2023-08-02T00:00:00+00:00 [queued]>
[2023-12-07T17:23:18.836+0000] {taskinstance.py:1361} INFO - Starting attempt 1 of 1
[2023-12-07T17:23:18.843+0000] {taskinstance.py:1382} INFO - Executing <Task(PythonOperator): main_task> on 2023-08-02 00:00:00+00:00
[2023-12-07T17:23:18.846+0000] {standard_task_runner.py:57} INFO - Started process 9776 to run task
[2023-12-07T17:23:18.849+0000] {standard_task_runner.py:84} INFO - Running: ['***', 'tasks', 'run', 'my_scraping_dag', 'main_task', 'scheduled__2023-08-02T00:00:00+00:00', '--job-id', '3085', '--raw', '--subdir', 'DAGS_FOLDER/main.py', '--cfg-path', '/tmp/tmpq46pt6dx']
[2023-12-07T17:23:18.851+0000] {standard_task_runner.py:85} INFO - Job 3085: Subtask main_task
[2023-12-07T17:23:18.880+0000] {task_command.py:416} INFO - Running <TaskInstance: my_scraping_dag.main_task scheduled__2023-08-02T00:00:00+00:00 [running]> on host 63b0c7e341c0
[2023-12-07T17:23:18.918+0000] {taskinstance.py:1662} INFO - Exporting env vars: AIRFLOW_CTX_DAG_OWNER='***' AIRFLOW_CTX_DAG_ID='my_scraping_dag' AIRFLOW_CTX_TASK_ID='main_task' AIRFLOW_CTX_EXECUTION_DATE='2023-08-02T00:00:00+00:00' AIRFLOW_CTX_TRY_NUMBER='1' AIRFLOW_CTX_DAG_RUN_ID='scheduled__2023-08-02T00:00:00+00:00'
[2023-12-07T17:23:19.808+0000] {taskinstance.py:1937} ERROR - Task failed with exception
Traceback (most recent call last):
  File "/home/airflow/.local/lib/python3.8/site-packages/airflow/operators/python.py", line 192, in execute
    return_value = self.execute_callable()
  File "/home/airflow/.local/lib/python3.8/site-packages/airflow/operators/python.py", line 209, in execute_callable
    return self.python_callable(*self.op_args, **self.op_kwargs)
  File "/opt/airflow/dags/main.py", line 73, in main
    insert_data_to_db(products, db_params)
  File "/opt/airflow/dags/main.py", line 40, in insert_data_to_db
    with psycopg2.connect(**db_params) as conn:
  File "/home/airflow/.local/lib/python3.8/site-packages/psycopg2/__init__.py", line 122, in connect
    conn = _connect(dsn, connection_factory=connection_factory, **kwasync)
psycopg2.OperationalError: connection to server at "localhost" (127.0.0.1), port 5432 failed: Connection refused
	Is the server running on that host and accepting TCP/IP connections?
connection to server at "localhost" (::1), port 5432 failed: Cannot assign requested address
	Is the server running on that host and accepting TCP/IP connections?

[2023-12-07T17:23:19.815+0000] {taskinstance.py:1400} INFO - Marking task as FAILED. dag_id=my_scraping_dag, task_id=main_task, execution_date=20230802T000000, start_date=20231207T172318, end_date=20231207T172319
[2023-12-07T17:23:19.825+0000] {standard_task_runner.py:104} ERROR - Failed to execute job 3085 for task main_task (connection to server at "localhost" (127.0.0.1), port 5432 failed: Connection refused
	Is the server running on that host and accepting TCP/IP connections?
connection to server at "localhost" (::1), port 5432 failed: Cannot assign requested address
	Is the server running on that host and accepting TCP/IP connections?
; 9776)
[2023-12-07T17:23:19.874+0000] {local_task_job_runner.py:228} INFO - Task exited with return code 1
[2023-12-07T17:23:19.887+0000] {taskinstance.py:2778} INFO - 0 downstream tasks scheduled from follow-on schedule check
[2023-12-07T17:29:00.564+0000] {taskinstance.py:1159} INFO - Dependencies all met for dep_context=non-requeueable deps ti=<TaskInstance: my_scraping_dag.main_task scheduled__2023-08-02T00:00:00+00:00 [queued]>
[2023-12-07T17:29:00.569+0000] {taskinstance.py:1159} INFO - Dependencies all met for dep_context=requeueable deps ti=<TaskInstance: my_scraping_dag.main_task scheduled__2023-08-02T00:00:00+00:00 [queued]>
[2023-12-07T17:29:00.569+0000] {taskinstance.py:1361} INFO - Starting attempt 1 of 1
[2023-12-07T17:29:00.581+0000] {taskinstance.py:1382} INFO - Executing <Task(PythonOperator): main_task> on 2023-08-02 00:00:00+00:00
[2023-12-07T17:29:00.585+0000] {standard_task_runner.py:57} INFO - Started process 10619 to run task
[2023-12-07T17:29:00.587+0000] {standard_task_runner.py:84} INFO - Running: ['***', 'tasks', 'run', 'my_scraping_dag', 'main_task', 'scheduled__2023-08-02T00:00:00+00:00', '--job-id', '3427', '--raw', '--subdir', 'DAGS_FOLDER/main.py', '--cfg-path', '/tmp/tmpzniarvud']
[2023-12-07T17:29:00.590+0000] {standard_task_runner.py:85} INFO - Job 3427: Subtask main_task
[2023-12-07T17:29:00.623+0000] {task_command.py:416} INFO - Running <TaskInstance: my_scraping_dag.main_task scheduled__2023-08-02T00:00:00+00:00 [running]> on host 63b0c7e341c0
[2023-12-07T17:29:00.684+0000] {taskinstance.py:1662} INFO - Exporting env vars: AIRFLOW_CTX_DAG_OWNER='***' AIRFLOW_CTX_DAG_ID='my_scraping_dag' AIRFLOW_CTX_TASK_ID='main_task' AIRFLOW_CTX_EXECUTION_DATE='2023-08-02T00:00:00+00:00' AIRFLOW_CTX_TRY_NUMBER='1' AIRFLOW_CTX_DAG_RUN_ID='scheduled__2023-08-02T00:00:00+00:00'
[2023-12-07T17:29:01.559+0000] {taskinstance.py:1937} ERROR - Task failed with exception
Traceback (most recent call last):
  File "/home/airflow/.local/lib/python3.8/site-packages/airflow/operators/python.py", line 192, in execute
    return_value = self.execute_callable()
  File "/home/airflow/.local/lib/python3.8/site-packages/airflow/operators/python.py", line 209, in execute_callable
    return self.python_callable(*self.op_args, **self.op_kwargs)
  File "/opt/airflow/dags/main.py", line 73, in main
    insert_data_to_db(products, db_params)
  File "/opt/airflow/dags/main.py", line 40, in insert_data_to_db
    with psycopg2.connect(**db_params) as conn:
  File "/home/airflow/.local/lib/python3.8/site-packages/psycopg2/__init__.py", line 122, in connect
    conn = _connect(dsn, connection_factory=connection_factory, **kwasync)
psycopg2.OperationalError: connection to server at "localhost" (127.0.0.1), port 5432 failed: Connection refused
	Is the server running on that host and accepting TCP/IP connections?
connection to server at "localhost" (::1), port 5432 failed: Cannot assign requested address
	Is the server running on that host and accepting TCP/IP connections?

[2023-12-07T17:29:01.571+0000] {taskinstance.py:1400} INFO - Marking task as FAILED. dag_id=my_scraping_dag, task_id=main_task, execution_date=20230802T000000, start_date=20231207T172900, end_date=20231207T172901
[2023-12-07T17:29:01.585+0000] {standard_task_runner.py:104} ERROR - Failed to execute job 3427 for task main_task (connection to server at "localhost" (127.0.0.1), port 5432 failed: Connection refused
	Is the server running on that host and accepting TCP/IP connections?
connection to server at "localhost" (::1), port 5432 failed: Cannot assign requested address
	Is the server running on that host and accepting TCP/IP connections?
; 10619)
[2023-12-07T17:29:01.605+0000] {local_task_job_runner.py:228} INFO - Task exited with return code 1
[2023-12-07T17:29:01.623+0000] {taskinstance.py:2778} INFO - 0 downstream tasks scheduled from follow-on schedule check
[2023-12-09T07:35:06.773+0000] {taskinstance.py:1159} INFO - Dependencies all met for dep_context=non-requeueable deps ti=<TaskInstance: my_scraping_dag.main_task scheduled__2023-08-02T00:00:00+00:00 [queued]>
[2023-12-09T07:35:06.780+0000] {taskinstance.py:1159} INFO - Dependencies all met for dep_context=requeueable deps ti=<TaskInstance: my_scraping_dag.main_task scheduled__2023-08-02T00:00:00+00:00 [queued]>
[2023-12-09T07:35:06.781+0000] {taskinstance.py:1361} INFO - Starting attempt 1 of 1
[2023-12-09T07:35:06.789+0000] {taskinstance.py:1382} INFO - Executing <Task(PythonOperator): main_task> on 2023-08-02 00:00:00+00:00
[2023-12-09T07:35:06.792+0000] {standard_task_runner.py:57} INFO - Started process 1035 to run task
[2023-12-09T07:35:06.795+0000] {standard_task_runner.py:84} INFO - Running: ['***', 'tasks', 'run', 'my_scraping_dag', 'main_task', 'scheduled__2023-08-02T00:00:00+00:00', '--job-id', '217', '--raw', '--subdir', 'DAGS_FOLDER/main.py', '--cfg-path', '/tmp/tmpra_2rpo9']
[2023-12-09T07:35:06.797+0000] {standard_task_runner.py:85} INFO - Job 217: Subtask main_task
[2023-12-09T07:35:06.821+0000] {task_command.py:416} INFO - Running <TaskInstance: my_scraping_dag.main_task scheduled__2023-08-02T00:00:00+00:00 [running]> on host 36b5ef2505c9
[2023-12-09T07:35:06.854+0000] {taskinstance.py:1662} INFO - Exporting env vars: AIRFLOW_CTX_DAG_OWNER='***' AIRFLOW_CTX_DAG_ID='my_scraping_dag' AIRFLOW_CTX_TASK_ID='main_task' AIRFLOW_CTX_EXECUTION_DATE='2023-08-02T00:00:00+00:00' AIRFLOW_CTX_TRY_NUMBER='1' AIRFLOW_CTX_DAG_RUN_ID='scheduled__2023-08-02T00:00:00+00:00'
[2023-12-09T07:35:06.858+0000] {taskinstance.py:1937} ERROR - Task failed with exception
Traceback (most recent call last):
  File "/home/airflow/.local/lib/python3.8/site-packages/airflow/operators/python.py", line 192, in execute
    return_value = self.execute_callable()
  File "/home/airflow/.local/lib/python3.8/site-packages/airflow/operators/python.py", line 209, in execute_callable
    return self.python_callable(*self.op_args, **self.op_kwargs)
  File "/opt/airflow/dags/main.py", line 64, in main
    base_url = Variable.get('base_url')
  File "/home/airflow/.local/lib/python3.8/site-packages/airflow/models/variable.py", line 140, in get
    raise KeyError(f"Variable {key} does not exist")
KeyError: 'Variable base_url does not exist'
[2023-12-09T07:35:06.863+0000] {taskinstance.py:1400} INFO - Marking task as FAILED. dag_id=my_scraping_dag, task_id=main_task, execution_date=20230802T000000, start_date=20231209T073506, end_date=20231209T073506
[2023-12-09T07:35:06.867+0000] {standard_task_runner.py:104} ERROR - Failed to execute job 217 for task main_task ('Variable base_url does not exist'; 1035)
[2023-12-09T07:35:06.887+0000] {local_task_job_runner.py:228} INFO - Task exited with return code 1
[2023-12-09T07:35:06.896+0000] {taskinstance.py:2778} INFO - 0 downstream tasks scheduled from follow-on schedule check
