[2023-12-07T16:34:32.076+0000] {taskinstance.py:1159} INFO - Dependencies all met for dep_context=non-requeueable deps ti=<TaskInstance: my_scraping_dag.main_task scheduled__2023-11-29T00:00:00+00:00 [queued]>
[2023-12-07T16:34:32.080+0000] {taskinstance.py:1159} INFO - Dependencies all met for dep_context=requeueable deps ti=<TaskInstance: my_scraping_dag.main_task scheduled__2023-11-29T00:00:00+00:00 [queued]>
[2023-12-07T16:34:32.080+0000] {taskinstance.py:1361} INFO - Starting attempt 1 of 1
[2023-12-07T16:34:32.106+0000] {taskinstance.py:1382} INFO - Executing <Task(PythonOperator): main_task> on 2023-11-29 00:00:00+00:00
[2023-12-07T16:34:32.109+0000] {standard_task_runner.py:57} INFO - Started process 4254 to run task
[2023-12-07T16:34:32.113+0000] {standard_task_runner.py:84} INFO - Running: ['***', 'tasks', 'run', 'my_scraping_dag', 'main_task', 'scheduled__2023-11-29T00:00:00+00:00', '--job-id', '921', '--raw', '--subdir', 'DAGS_FOLDER/main.py', '--cfg-path', '/tmp/tmpdx91hbk6']
[2023-12-07T16:34:32.115+0000] {standard_task_runner.py:85} INFO - Job 921: Subtask main_task
[2023-12-07T16:34:32.153+0000] {task_command.py:416} INFO - Running <TaskInstance: my_scraping_dag.main_task scheduled__2023-11-29T00:00:00+00:00 [running]> on host 63b0c7e341c0
[2023-12-07T16:34:32.191+0000] {taskinstance.py:1662} INFO - Exporting env vars: AIRFLOW_CTX_DAG_OWNER='***' AIRFLOW_CTX_DAG_ID='my_scraping_dag' AIRFLOW_CTX_TASK_ID='main_task' AIRFLOW_CTX_EXECUTION_DATE='2023-11-29T00:00:00+00:00' AIRFLOW_CTX_TRY_NUMBER='1' AIRFLOW_CTX_DAG_RUN_ID='scheduled__2023-11-29T00:00:00+00:00'
[2023-12-07T16:34:32.193+0000] {taskinstance.py:1937} ERROR - Task failed with exception
Traceback (most recent call last):
  File "/usr/local/lib/python3.8/configparser.py", line 846, in items
    d.update(self._sections[section])
KeyError: 'web'

During handling of the above exception, another exception occurred:

Traceback (most recent call last):
  File "/home/airflow/.local/lib/python3.8/site-packages/airflow/operators/python.py", line 192, in execute
    return_value = self.execute_callable()
  File "/home/airflow/.local/lib/python3.8/site-packages/airflow/operators/python.py", line 209, in execute_callable
    return self.python_callable(*self.op_args, **self.op_kwargs)
  File "/opt/airflow/dags/main.py", line 60, in main
    config = get_config('web')
  File "/opt/airflow/dags/main.py", line 22, in get_config
    return {key: value for key, value in parser.items(section)}
  File "/usr/local/lib/python3.8/configparser.py", line 849, in items
    raise NoSectionError(section)
configparser.NoSectionError: No section: 'web'
[2023-12-07T16:34:32.198+0000] {taskinstance.py:1400} INFO - Marking task as FAILED. dag_id=my_scraping_dag, task_id=main_task, execution_date=20231129T000000, start_date=20231207T163432, end_date=20231207T163432
[2023-12-07T16:34:32.205+0000] {standard_task_runner.py:104} ERROR - Failed to execute job 921 for task main_task (No section: 'web'; 4254)
[2023-12-07T16:34:32.246+0000] {local_task_job_runner.py:228} INFO - Task exited with return code 1
[2023-12-07T16:34:32.269+0000] {taskinstance.py:2778} INFO - 0 downstream tasks scheduled from follow-on schedule check
[2023-12-07T16:43:10.875+0000] {taskinstance.py:1159} INFO - Dependencies all met for dep_context=non-requeueable deps ti=<TaskInstance: my_scraping_dag.main_task scheduled__2023-11-29T00:00:00+00:00 [queued]>
[2023-12-07T16:43:10.880+0000] {taskinstance.py:1159} INFO - Dependencies all met for dep_context=requeueable deps ti=<TaskInstance: my_scraping_dag.main_task scheduled__2023-11-29T00:00:00+00:00 [queued]>
[2023-12-07T16:43:10.880+0000] {taskinstance.py:1361} INFO - Starting attempt 1 of 1
[2023-12-07T16:43:10.888+0000] {taskinstance.py:1382} INFO - Executing <Task(PythonOperator): main_task> on 2023-11-29 00:00:00+00:00
[2023-12-07T16:43:10.892+0000] {standard_task_runner.py:57} INFO - Started process 5152 to run task
[2023-12-07T16:43:10.894+0000] {standard_task_runner.py:84} INFO - Running: ['***', 'tasks', 'run', 'my_scraping_dag', 'main_task', 'scheduled__2023-11-29T00:00:00+00:00', '--job-id', '1266', '--raw', '--subdir', 'DAGS_FOLDER/main.py', '--cfg-path', '/tmp/tmpugjmpclt']
[2023-12-07T16:43:10.896+0000] {standard_task_runner.py:85} INFO - Job 1266: Subtask main_task
[2023-12-07T16:43:10.921+0000] {task_command.py:416} INFO - Running <TaskInstance: my_scraping_dag.main_task scheduled__2023-11-29T00:00:00+00:00 [running]> on host 63b0c7e341c0
[2023-12-07T16:43:10.961+0000] {taskinstance.py:1662} INFO - Exporting env vars: AIRFLOW_CTX_DAG_OWNER='***' AIRFLOW_CTX_DAG_ID='my_scraping_dag' AIRFLOW_CTX_TASK_ID='main_task' AIRFLOW_CTX_EXECUTION_DATE='2023-11-29T00:00:00+00:00' AIRFLOW_CTX_TRY_NUMBER='1' AIRFLOW_CTX_DAG_RUN_ID='scheduled__2023-11-29T00:00:00+00:00'
[2023-12-07T16:43:10.962+0000] {taskinstance.py:1937} ERROR - Task failed with exception
Traceback (most recent call last):
  File "/usr/local/lib/python3.8/configparser.py", line 846, in items
    d.update(self._sections[section])
KeyError: 'web'

During handling of the above exception, another exception occurred:

Traceback (most recent call last):
  File "/home/airflow/.local/lib/python3.8/site-packages/airflow/operators/python.py", line 192, in execute
    return_value = self.execute_callable()
  File "/home/airflow/.local/lib/python3.8/site-packages/airflow/operators/python.py", line 209, in execute_callable
    return self.python_callable(*self.op_args, **self.op_kwargs)
  File "/opt/airflow/dags/main.py", line 60, in main
    config = get_config('web')
  File "/opt/airflow/dags/main.py", line 22, in get_config
    return {key: value for key, value in parser.items(section)}
  File "/usr/local/lib/python3.8/configparser.py", line 849, in items
    raise NoSectionError(section)
configparser.NoSectionError: No section: 'web'
[2023-12-07T16:43:10.967+0000] {taskinstance.py:1400} INFO - Marking task as FAILED. dag_id=my_scraping_dag, task_id=main_task, execution_date=20231129T000000, start_date=20231207T164310, end_date=20231207T164310
[2023-12-07T16:43:10.973+0000] {standard_task_runner.py:104} ERROR - Failed to execute job 1266 for task main_task (No section: 'web'; 5152)
[2023-12-07T16:43:10.986+0000] {local_task_job_runner.py:228} INFO - Task exited with return code 1
[2023-12-07T16:43:11.006+0000] {taskinstance.py:2778} INFO - 0 downstream tasks scheduled from follow-on schedule check
[2023-12-07T17:01:49.145+0000] {taskinstance.py:1159} INFO - Dependencies all met for dep_context=non-requeueable deps ti=<TaskInstance: my_scraping_dag.main_task scheduled__2023-11-29T00:00:00+00:00 [queued]>
[2023-12-07T17:01:49.152+0000] {taskinstance.py:1159} INFO - Dependencies all met for dep_context=requeueable deps ti=<TaskInstance: my_scraping_dag.main_task scheduled__2023-11-29T00:00:00+00:00 [queued]>
[2023-12-07T17:01:49.152+0000] {taskinstance.py:1361} INFO - Starting attempt 1 of 1
[2023-12-07T17:01:49.167+0000] {taskinstance.py:1382} INFO - Executing <Task(PythonOperator): main_task> on 2023-11-29 00:00:00+00:00
[2023-12-07T17:01:49.171+0000] {standard_task_runner.py:57} INFO - Started process 6717 to run task
[2023-12-07T17:01:49.173+0000] {standard_task_runner.py:84} INFO - Running: ['***', 'tasks', 'run', 'my_scraping_dag', 'main_task', 'scheduled__2023-11-29T00:00:00+00:00', '--job-id', '1819', '--raw', '--subdir', 'DAGS_FOLDER/main.py', '--cfg-path', '/tmp/tmp1s3ufihe']
[2023-12-07T17:01:49.176+0000] {standard_task_runner.py:85} INFO - Job 1819: Subtask main_task
[2023-12-07T17:01:49.211+0000] {task_command.py:416} INFO - Running <TaskInstance: my_scraping_dag.main_task scheduled__2023-11-29T00:00:00+00:00 [running]> on host 63b0c7e341c0
[2023-12-07T17:01:49.254+0000] {taskinstance.py:1662} INFO - Exporting env vars: AIRFLOW_CTX_DAG_OWNER='***' AIRFLOW_CTX_DAG_ID='my_scraping_dag' AIRFLOW_CTX_TASK_ID='main_task' AIRFLOW_CTX_EXECUTION_DATE='2023-11-29T00:00:00+00:00' AIRFLOW_CTX_TRY_NUMBER='1' AIRFLOW_CTX_DAG_RUN_ID='scheduled__2023-11-29T00:00:00+00:00'
[2023-12-07T17:01:49.285+0000] {logging_mixin.py:154} INFO - base_url: https://tuncbotanik.com
[2023-12-07T17:01:49.287+0000] {python.py:194} INFO - Done. Returned value was: ('https://tuncbotanik.com', {'User-Agent': 'Mozilla/5.0 (Macintosh; Intel Mac OS X 10_15_7) AppleWebKit/537.36 (KHTML, like Gecko) Chrome/119.0.0.0 Safari/537.36', 'Accept-Language': 'tr-TR,tr;q=0.9,en-US;q=0.8,en;q=0.7'}, {'dbname': 'plant', 'user': 'aozgokme', 'password': '***', 'host': 'localhost', 'port': '5432'})
[2023-12-07T17:01:49.299+0000] {taskinstance.py:1400} INFO - Marking task as SUCCESS. dag_id=my_scraping_dag, task_id=main_task, execution_date=20231129T000000, start_date=20231207T170149, end_date=20231207T170149
[2023-12-07T17:01:49.350+0000] {local_task_job_runner.py:228} INFO - Task exited with return code 0
[2023-12-07T17:01:49.365+0000] {taskinstance.py:2778} INFO - 0 downstream tasks scheduled from follow-on schedule check
[2023-12-07T17:05:12.651+0000] {taskinstance.py:1159} INFO - Dependencies all met for dep_context=non-requeueable deps ti=<TaskInstance: my_scraping_dag.main_task scheduled__2023-11-29T00:00:00+00:00 [queued]>
[2023-12-07T17:05:12.657+0000] {taskinstance.py:1159} INFO - Dependencies all met for dep_context=requeueable deps ti=<TaskInstance: my_scraping_dag.main_task scheduled__2023-11-29T00:00:00+00:00 [queued]>
[2023-12-07T17:05:12.658+0000] {taskinstance.py:1361} INFO - Starting attempt 1 of 1
[2023-12-07T17:05:12.667+0000] {taskinstance.py:1382} INFO - Executing <Task(PythonOperator): main_task> on 2023-11-29 00:00:00+00:00
[2023-12-07T17:05:12.670+0000] {standard_task_runner.py:57} INFO - Started process 8173 to run task
[2023-12-07T17:05:12.674+0000] {standard_task_runner.py:84} INFO - Running: ['***', 'tasks', 'run', 'my_scraping_dag', 'main_task', 'scheduled__2023-11-29T00:00:00+00:00', '--job-id', '2505', '--raw', '--subdir', 'DAGS_FOLDER/main.py', '--cfg-path', '/tmp/tmphed2q59f']
[2023-12-07T17:05:12.676+0000] {standard_task_runner.py:85} INFO - Job 2505: Subtask main_task
[2023-12-07T17:05:12.707+0000] {task_command.py:416} INFO - Running <TaskInstance: my_scraping_dag.main_task scheduled__2023-11-29T00:00:00+00:00 [running]> on host 63b0c7e341c0
[2023-12-07T17:05:12.765+0000] {taskinstance.py:1662} INFO - Exporting env vars: AIRFLOW_CTX_DAG_OWNER='***' AIRFLOW_CTX_DAG_ID='my_scraping_dag' AIRFLOW_CTX_TASK_ID='main_task' AIRFLOW_CTX_EXECUTION_DATE='2023-11-29T00:00:00+00:00' AIRFLOW_CTX_TRY_NUMBER='1' AIRFLOW_CTX_DAG_RUN_ID='scheduled__2023-11-29T00:00:00+00:00'
[2023-12-07T17:05:12.797+0000] {logging_mixin.py:154} INFO - base_url: https://tuncbotanik.com
[2023-12-07T17:05:12.797+0000] {python.py:194} INFO - Done. Returned value was: ('https://tuncbotanik.com', {'User-Agent': 'Mozilla/5.0 (Macintosh; Intel Mac OS X 10_15_7) AppleWebKit/537.36 (KHTML, like Gecko) Chrome/119.0.0.0 Safari/537.36', 'Accept-Language': 'tr-TR,tr;q=0.9,en-US;q=0.8,en;q=0.7'}, {'dbname': 'plant', 'user': 'aozgokme', 'password': '***', 'host': 'localhost', 'port': '5432'})
[2023-12-07T17:05:12.814+0000] {taskinstance.py:1400} INFO - Marking task as SUCCESS. dag_id=my_scraping_dag, task_id=main_task, execution_date=20231129T000000, start_date=20231207T170512, end_date=20231207T170512
[2023-12-07T17:05:12.845+0000] {local_task_job_runner.py:228} INFO - Task exited with return code 0
[2023-12-07T17:05:12.864+0000] {taskinstance.py:2778} INFO - 1 downstream tasks scheduled from follow-on schedule check
[2023-12-07T17:19:28.099+0000] {taskinstance.py:1159} INFO - Dependencies all met for dep_context=non-requeueable deps ti=<TaskInstance: my_scraping_dag.main_task scheduled__2023-11-29T00:00:00+00:00 [queued]>
[2023-12-07T17:19:28.105+0000] {taskinstance.py:1159} INFO - Dependencies all met for dep_context=requeueable deps ti=<TaskInstance: my_scraping_dag.main_task scheduled__2023-11-29T00:00:00+00:00 [queued]>
[2023-12-07T17:19:28.106+0000] {taskinstance.py:1361} INFO - Starting attempt 1 of 1
[2023-12-07T17:19:28.117+0000] {taskinstance.py:1382} INFO - Executing <Task(PythonOperator): main_task> on 2023-11-29 00:00:00+00:00
[2023-12-07T17:19:28.120+0000] {standard_task_runner.py:57} INFO - Started process 9232 to run task
[2023-12-07T17:19:28.123+0000] {standard_task_runner.py:84} INFO - Running: ['***', 'tasks', 'run', 'my_scraping_dag', 'main_task', 'scheduled__2023-11-29T00:00:00+00:00', '--job-id', '2862', '--raw', '--subdir', 'DAGS_FOLDER/main.py', '--cfg-path', '/tmp/tmpj7ggdmvq']
[2023-12-07T17:19:28.125+0000] {standard_task_runner.py:85} INFO - Job 2862: Subtask main_task
[2023-12-07T17:19:28.152+0000] {task_command.py:416} INFO - Running <TaskInstance: my_scraping_dag.main_task scheduled__2023-11-29T00:00:00+00:00 [running]> on host 63b0c7e341c0
[2023-12-07T17:19:28.193+0000] {taskinstance.py:1662} INFO - Exporting env vars: AIRFLOW_CTX_DAG_OWNER='***' AIRFLOW_CTX_DAG_ID='my_scraping_dag' AIRFLOW_CTX_TASK_ID='main_task' AIRFLOW_CTX_EXECUTION_DATE='2023-11-29T00:00:00+00:00' AIRFLOW_CTX_TRY_NUMBER='1' AIRFLOW_CTX_DAG_RUN_ID='scheduled__2023-11-29T00:00:00+00:00'
[2023-12-07T17:19:28.967+0000] {taskinstance.py:1937} ERROR - Task failed with exception
Traceback (most recent call last):
  File "/home/airflow/.local/lib/python3.8/site-packages/airflow/operators/python.py", line 192, in execute
    return_value = self.execute_callable()
  File "/home/airflow/.local/lib/python3.8/site-packages/airflow/operators/python.py", line 209, in execute_callable
    return self.python_callable(*self.op_args, **self.op_kwargs)
  File "/opt/airflow/dags/main.py", line 80, in main
    insert_data_to_db(products, db_params)
  File "/opt/airflow/dags/main.py", line 43, in insert_data_to_db
    with psycopg2.connect(**db_params) as conn:
  File "/home/airflow/.local/lib/python3.8/site-packages/psycopg2/__init__.py", line 122, in connect
    conn = _connect(dsn, connection_factory=connection_factory, **kwasync)
psycopg2.OperationalError: connection to server at "localhost" (127.0.0.1), port 5432 failed: Connection refused
	Is the server running on that host and accepting TCP/IP connections?
connection to server at "localhost" (::1), port 5432 failed: Cannot assign requested address
	Is the server running on that host and accepting TCP/IP connections?

[2023-12-07T17:19:28.972+0000] {taskinstance.py:1400} INFO - Marking task as FAILED. dag_id=my_scraping_dag, task_id=main_task, execution_date=20231129T000000, start_date=20231207T171928, end_date=20231207T171928
[2023-12-07T17:19:28.977+0000] {standard_task_runner.py:104} ERROR - Failed to execute job 2862 for task main_task (connection to server at "localhost" (127.0.0.1), port 5432 failed: Connection refused
	Is the server running on that host and accepting TCP/IP connections?
connection to server at "localhost" (::1), port 5432 failed: Cannot assign requested address
	Is the server running on that host and accepting TCP/IP connections?
; 9232)
[2023-12-07T17:19:28.985+0000] {local_task_job_runner.py:228} INFO - Task exited with return code 1
[2023-12-07T17:19:28.994+0000] {taskinstance.py:2778} INFO - 0 downstream tasks scheduled from follow-on schedule check
[2023-12-07T17:23:49.813+0000] {taskinstance.py:1159} INFO - Dependencies all met for dep_context=non-requeueable deps ti=<TaskInstance: my_scraping_dag.main_task scheduled__2023-11-29T00:00:00+00:00 [queued]>
[2023-12-07T17:23:49.825+0000] {taskinstance.py:1159} INFO - Dependencies all met for dep_context=requeueable deps ti=<TaskInstance: my_scraping_dag.main_task scheduled__2023-11-29T00:00:00+00:00 [queued]>
[2023-12-07T17:23:49.826+0000] {taskinstance.py:1361} INFO - Starting attempt 1 of 1
[2023-12-07T17:23:49.843+0000] {taskinstance.py:1382} INFO - Executing <Task(PythonOperator): main_task> on 2023-11-29 00:00:00+00:00
[2023-12-07T17:23:49.850+0000] {standard_task_runner.py:57} INFO - Started process 10026 to run task
[2023-12-07T17:23:49.858+0000] {standard_task_runner.py:84} INFO - Running: ['***', 'tasks', 'run', 'my_scraping_dag', 'main_task', 'scheduled__2023-11-29T00:00:00+00:00', '--job-id', '3204', '--raw', '--subdir', 'DAGS_FOLDER/main.py', '--cfg-path', '/tmp/tmpil25rzi4']
[2023-12-07T17:23:49.865+0000] {standard_task_runner.py:85} INFO - Job 3204: Subtask main_task
[2023-12-07T17:23:49.941+0000] {task_command.py:416} INFO - Running <TaskInstance: my_scraping_dag.main_task scheduled__2023-11-29T00:00:00+00:00 [running]> on host 63b0c7e341c0
[2023-12-07T17:23:50.001+0000] {taskinstance.py:1662} INFO - Exporting env vars: AIRFLOW_CTX_DAG_OWNER='***' AIRFLOW_CTX_DAG_ID='my_scraping_dag' AIRFLOW_CTX_TASK_ID='main_task' AIRFLOW_CTX_EXECUTION_DATE='2023-11-29T00:00:00+00:00' AIRFLOW_CTX_TRY_NUMBER='1' AIRFLOW_CTX_DAG_RUN_ID='scheduled__2023-11-29T00:00:00+00:00'
[2023-12-07T17:23:50.648+0000] {taskinstance.py:1937} ERROR - Task failed with exception
Traceback (most recent call last):
  File "/home/airflow/.local/lib/python3.8/site-packages/airflow/operators/python.py", line 192, in execute
    return_value = self.execute_callable()
  File "/home/airflow/.local/lib/python3.8/site-packages/airflow/operators/python.py", line 209, in execute_callable
    return self.python_callable(*self.op_args, **self.op_kwargs)
  File "/opt/airflow/dags/main.py", line 73, in main
    insert_data_to_db(products, db_params)
  File "/opt/airflow/dags/main.py", line 40, in insert_data_to_db
    with psycopg2.connect(**db_params) as conn:
  File "/home/airflow/.local/lib/python3.8/site-packages/psycopg2/__init__.py", line 122, in connect
    conn = _connect(dsn, connection_factory=connection_factory, **kwasync)
psycopg2.OperationalError: connection to server at "localhost" (127.0.0.1), port 5432 failed: Connection refused
	Is the server running on that host and accepting TCP/IP connections?
connection to server at "localhost" (::1), port 5432 failed: Cannot assign requested address
	Is the server running on that host and accepting TCP/IP connections?

[2023-12-07T17:23:50.653+0000] {taskinstance.py:1400} INFO - Marking task as FAILED. dag_id=my_scraping_dag, task_id=main_task, execution_date=20231129T000000, start_date=20231207T172349, end_date=20231207T172350
[2023-12-07T17:23:50.658+0000] {standard_task_runner.py:104} ERROR - Failed to execute job 3204 for task main_task (connection to server at "localhost" (127.0.0.1), port 5432 failed: Connection refused
	Is the server running on that host and accepting TCP/IP connections?
connection to server at "localhost" (::1), port 5432 failed: Cannot assign requested address
	Is the server running on that host and accepting TCP/IP connections?
; 10026)
[2023-12-07T17:23:50.686+0000] {local_task_job_runner.py:228} INFO - Task exited with return code 1
[2023-12-07T17:23:50.694+0000] {taskinstance.py:2778} INFO - 0 downstream tasks scheduled from follow-on schedule check
[2023-12-07T17:29:23.494+0000] {taskinstance.py:1159} INFO - Dependencies all met for dep_context=non-requeueable deps ti=<TaskInstance: my_scraping_dag.main_task scheduled__2023-11-29T00:00:00+00:00 [queued]>
[2023-12-07T17:29:23.507+0000] {taskinstance.py:1159} INFO - Dependencies all met for dep_context=requeueable deps ti=<TaskInstance: my_scraping_dag.main_task scheduled__2023-11-29T00:00:00+00:00 [queued]>
[2023-12-07T17:29:23.508+0000] {taskinstance.py:1361} INFO - Starting attempt 1 of 1
[2023-12-07T17:29:23.524+0000] {taskinstance.py:1382} INFO - Executing <Task(PythonOperator): main_task> on 2023-11-29 00:00:00+00:00
[2023-12-07T17:29:23.528+0000] {standard_task_runner.py:57} INFO - Started process 10862 to run task
[2023-12-07T17:29:23.535+0000] {standard_task_runner.py:84} INFO - Running: ['***', 'tasks', 'run', 'my_scraping_dag', 'main_task', 'scheduled__2023-11-29T00:00:00+00:00', '--job-id', '3546', '--raw', '--subdir', 'DAGS_FOLDER/main.py', '--cfg-path', '/tmp/tmproqbhtms']
[2023-12-07T17:29:23.543+0000] {standard_task_runner.py:85} INFO - Job 3546: Subtask main_task
[2023-12-07T17:29:23.612+0000] {task_command.py:416} INFO - Running <TaskInstance: my_scraping_dag.main_task scheduled__2023-11-29T00:00:00+00:00 [running]> on host 63b0c7e341c0
[2023-12-07T17:29:23.688+0000] {taskinstance.py:1662} INFO - Exporting env vars: AIRFLOW_CTX_DAG_OWNER='***' AIRFLOW_CTX_DAG_ID='my_scraping_dag' AIRFLOW_CTX_TASK_ID='main_task' AIRFLOW_CTX_EXECUTION_DATE='2023-11-29T00:00:00+00:00' AIRFLOW_CTX_TRY_NUMBER='1' AIRFLOW_CTX_DAG_RUN_ID='scheduled__2023-11-29T00:00:00+00:00'
[2023-12-07T17:29:24.460+0000] {taskinstance.py:1937} ERROR - Task failed with exception
Traceback (most recent call last):
  File "/home/airflow/.local/lib/python3.8/site-packages/airflow/operators/python.py", line 192, in execute
    return_value = self.execute_callable()
  File "/home/airflow/.local/lib/python3.8/site-packages/airflow/operators/python.py", line 209, in execute_callable
    return self.python_callable(*self.op_args, **self.op_kwargs)
  File "/opt/airflow/dags/main.py", line 73, in main
    insert_data_to_db(products, db_params)
  File "/opt/airflow/dags/main.py", line 40, in insert_data_to_db
    with psycopg2.connect(**db_params) as conn:
  File "/home/airflow/.local/lib/python3.8/site-packages/psycopg2/__init__.py", line 122, in connect
    conn = _connect(dsn, connection_factory=connection_factory, **kwasync)
psycopg2.OperationalError: connection to server at "localhost" (127.0.0.1), port 5432 failed: Connection refused
	Is the server running on that host and accepting TCP/IP connections?
connection to server at "localhost" (::1), port 5432 failed: Cannot assign requested address
	Is the server running on that host and accepting TCP/IP connections?

[2023-12-07T17:29:24.465+0000] {taskinstance.py:1400} INFO - Marking task as FAILED. dag_id=my_scraping_dag, task_id=main_task, execution_date=20231129T000000, start_date=20231207T172923, end_date=20231207T172924
[2023-12-07T17:29:24.471+0000] {standard_task_runner.py:104} ERROR - Failed to execute job 3546 for task main_task (connection to server at "localhost" (127.0.0.1), port 5432 failed: Connection refused
	Is the server running on that host and accepting TCP/IP connections?
connection to server at "localhost" (::1), port 5432 failed: Cannot assign requested address
	Is the server running on that host and accepting TCP/IP connections?
; 10862)
[2023-12-07T17:29:24.496+0000] {local_task_job_runner.py:228} INFO - Task exited with return code 1
[2023-12-07T17:29:24.504+0000] {taskinstance.py:2778} INFO - 0 downstream tasks scheduled from follow-on schedule check
[2023-12-09T07:35:44.096+0000] {taskinstance.py:1159} INFO - Dependencies all met for dep_context=non-requeueable deps ti=<TaskInstance: my_scraping_dag.main_task scheduled__2023-11-29T00:00:00+00:00 [queued]>
[2023-12-09T07:35:44.102+0000] {taskinstance.py:1159} INFO - Dependencies all met for dep_context=requeueable deps ti=<TaskInstance: my_scraping_dag.main_task scheduled__2023-11-29T00:00:00+00:00 [queued]>
[2023-12-09T07:35:44.102+0000] {taskinstance.py:1361} INFO - Starting attempt 1 of 1
[2023-12-09T07:35:44.111+0000] {taskinstance.py:1382} INFO - Executing <Task(PythonOperator): main_task> on 2023-11-29 00:00:00+00:00
[2023-12-09T07:35:44.114+0000] {standard_task_runner.py:57} INFO - Started process 1286 to run task
[2023-12-09T07:35:44.117+0000] {standard_task_runner.py:84} INFO - Running: ['***', 'tasks', 'run', 'my_scraping_dag', 'main_task', 'scheduled__2023-11-29T00:00:00+00:00', '--job-id', '336', '--raw', '--subdir', 'DAGS_FOLDER/main.py', '--cfg-path', '/tmp/tmp955bv_xn']
[2023-12-09T07:35:44.119+0000] {standard_task_runner.py:85} INFO - Job 336: Subtask main_task
[2023-12-09T07:35:44.147+0000] {task_command.py:416} INFO - Running <TaskInstance: my_scraping_dag.main_task scheduled__2023-11-29T00:00:00+00:00 [running]> on host 36b5ef2505c9
[2023-12-09T07:35:44.187+0000] {taskinstance.py:1662} INFO - Exporting env vars: AIRFLOW_CTX_DAG_OWNER='***' AIRFLOW_CTX_DAG_ID='my_scraping_dag' AIRFLOW_CTX_TASK_ID='main_task' AIRFLOW_CTX_EXECUTION_DATE='2023-11-29T00:00:00+00:00' AIRFLOW_CTX_TRY_NUMBER='1' AIRFLOW_CTX_DAG_RUN_ID='scheduled__2023-11-29T00:00:00+00:00'
[2023-12-09T07:35:44.193+0000] {taskinstance.py:1937} ERROR - Task failed with exception
Traceback (most recent call last):
  File "/home/airflow/.local/lib/python3.8/site-packages/airflow/operators/python.py", line 192, in execute
    return_value = self.execute_callable()
  File "/home/airflow/.local/lib/python3.8/site-packages/airflow/operators/python.py", line 209, in execute_callable
    return self.python_callable(*self.op_args, **self.op_kwargs)
  File "/opt/airflow/dags/main.py", line 66, in main
    'User-Agent': Variable.get('user_agent'),
  File "/home/airflow/.local/lib/python3.8/site-packages/airflow/models/variable.py", line 140, in get
    raise KeyError(f"Variable {key} does not exist")
KeyError: 'Variable user_agent does not exist'
[2023-12-09T07:35:44.197+0000] {taskinstance.py:1400} INFO - Marking task as FAILED. dag_id=my_scraping_dag, task_id=main_task, execution_date=20231129T000000, start_date=20231209T073544, end_date=20231209T073544
[2023-12-09T07:35:44.202+0000] {standard_task_runner.py:104} ERROR - Failed to execute job 336 for task main_task ('Variable user_agent does not exist'; 1286)
[2023-12-09T07:35:44.212+0000] {local_task_job_runner.py:228} INFO - Task exited with return code 1
[2023-12-09T07:35:44.221+0000] {taskinstance.py:2778} INFO - 0 downstream tasks scheduled from follow-on schedule check
