[2023-12-07T16:34:20.113+0000] {taskinstance.py:1159} INFO - Dependencies all met for dep_context=non-requeueable deps ti=<TaskInstance: my_scraping_dag.main_task scheduled__2023-11-07T00:00:00+00:00 [queued]>
[2023-12-07T16:34:20.117+0000] {taskinstance.py:1159} INFO - Dependencies all met for dep_context=requeueable deps ti=<TaskInstance: my_scraping_dag.main_task scheduled__2023-11-07T00:00:00+00:00 [queued]>
[2023-12-07T16:34:20.118+0000] {taskinstance.py:1361} INFO - Starting attempt 1 of 1
[2023-12-07T16:34:20.125+0000] {taskinstance.py:1382} INFO - Executing <Task(PythonOperator): main_task> on 2023-11-07 00:00:00+00:00
[2023-12-07T16:34:20.129+0000] {standard_task_runner.py:57} INFO - Started process 4210 to run task
[2023-12-07T16:34:20.132+0000] {standard_task_runner.py:84} INFO - Running: ['***', 'tasks', 'run', 'my_scraping_dag', 'main_task', 'scheduled__2023-11-07T00:00:00+00:00', '--job-id', '899', '--raw', '--subdir', 'DAGS_FOLDER/main.py', '--cfg-path', '/tmp/tmpgqpdt8mu']
[2023-12-07T16:34:20.134+0000] {standard_task_runner.py:85} INFO - Job 899: Subtask main_task
[2023-12-07T16:34:20.163+0000] {task_command.py:416} INFO - Running <TaskInstance: my_scraping_dag.main_task scheduled__2023-11-07T00:00:00+00:00 [running]> on host 63b0c7e341c0
[2023-12-07T16:34:20.199+0000] {taskinstance.py:1662} INFO - Exporting env vars: AIRFLOW_CTX_DAG_OWNER='***' AIRFLOW_CTX_DAG_ID='my_scraping_dag' AIRFLOW_CTX_TASK_ID='main_task' AIRFLOW_CTX_EXECUTION_DATE='2023-11-07T00:00:00+00:00' AIRFLOW_CTX_TRY_NUMBER='1' AIRFLOW_CTX_DAG_RUN_ID='scheduled__2023-11-07T00:00:00+00:00'
[2023-12-07T16:34:20.200+0000] {taskinstance.py:1937} ERROR - Task failed with exception
Traceback (most recent call last):
  File "/usr/local/lib/python3.8/configparser.py", line 846, in items
    d.update(self._sections[section])
KeyError: 'web'

During handling of the above exception, another exception occurred:

Traceback (most recent call last):
  File "/home/airflow/.local/lib/python3.8/site-packages/airflow/operators/python.py", line 192, in execute
    return_value = self.execute_callable()
  File "/home/airflow/.local/lib/python3.8/site-packages/airflow/operators/python.py", line 209, in execute_callable
    return self.python_callable(*self.op_args, **self.op_kwargs)
  File "/opt/airflow/dags/main.py", line 60, in main
    config = get_config('web')
  File "/opt/airflow/dags/main.py", line 22, in get_config
    return {key: value for key, value in parser.items(section)}
  File "/usr/local/lib/python3.8/configparser.py", line 849, in items
    raise NoSectionError(section)
configparser.NoSectionError: No section: 'web'
[2023-12-07T16:34:20.205+0000] {taskinstance.py:1400} INFO - Marking task as FAILED. dag_id=my_scraping_dag, task_id=main_task, execution_date=20231107T000000, start_date=20231207T163420, end_date=20231207T163420
[2023-12-07T16:34:20.210+0000] {standard_task_runner.py:104} ERROR - Failed to execute job 899 for task main_task (No section: 'web'; 4210)
[2023-12-07T16:34:20.224+0000] {local_task_job_runner.py:228} INFO - Task exited with return code 1
[2023-12-07T16:34:20.237+0000] {taskinstance.py:2778} INFO - 0 downstream tasks scheduled from follow-on schedule check
[2023-12-07T16:43:02.795+0000] {taskinstance.py:1159} INFO - Dependencies all met for dep_context=non-requeueable deps ti=<TaskInstance: my_scraping_dag.main_task scheduled__2023-11-07T00:00:00+00:00 [queued]>
[2023-12-07T16:43:02.800+0000] {taskinstance.py:1159} INFO - Dependencies all met for dep_context=requeueable deps ti=<TaskInstance: my_scraping_dag.main_task scheduled__2023-11-07T00:00:00+00:00 [queued]>
[2023-12-07T16:43:02.800+0000] {taskinstance.py:1361} INFO - Starting attempt 1 of 1
[2023-12-07T16:43:02.808+0000] {taskinstance.py:1382} INFO - Executing <Task(PythonOperator): main_task> on 2023-11-07 00:00:00+00:00
[2023-12-07T16:43:02.811+0000] {standard_task_runner.py:57} INFO - Started process 5103 to run task
[2023-12-07T16:43:02.814+0000] {standard_task_runner.py:84} INFO - Running: ['***', 'tasks', 'run', 'my_scraping_dag', 'main_task', 'scheduled__2023-11-07T00:00:00+00:00', '--job-id', '1244', '--raw', '--subdir', 'DAGS_FOLDER/main.py', '--cfg-path', '/tmp/tmpur67gavx']
[2023-12-07T16:43:02.818+0000] {standard_task_runner.py:85} INFO - Job 1244: Subtask main_task
[2023-12-07T16:43:02.859+0000] {task_command.py:416} INFO - Running <TaskInstance: my_scraping_dag.main_task scheduled__2023-11-07T00:00:00+00:00 [running]> on host 63b0c7e341c0
[2023-12-07T16:43:02.903+0000] {taskinstance.py:1662} INFO - Exporting env vars: AIRFLOW_CTX_DAG_OWNER='***' AIRFLOW_CTX_DAG_ID='my_scraping_dag' AIRFLOW_CTX_TASK_ID='main_task' AIRFLOW_CTX_EXECUTION_DATE='2023-11-07T00:00:00+00:00' AIRFLOW_CTX_TRY_NUMBER='1' AIRFLOW_CTX_DAG_RUN_ID='scheduled__2023-11-07T00:00:00+00:00'
[2023-12-07T16:43:02.905+0000] {taskinstance.py:1937} ERROR - Task failed with exception
Traceback (most recent call last):
  File "/usr/local/lib/python3.8/configparser.py", line 846, in items
    d.update(self._sections[section])
KeyError: 'web'

During handling of the above exception, another exception occurred:

Traceback (most recent call last):
  File "/home/airflow/.local/lib/python3.8/site-packages/airflow/operators/python.py", line 192, in execute
    return_value = self.execute_callable()
  File "/home/airflow/.local/lib/python3.8/site-packages/airflow/operators/python.py", line 209, in execute_callable
    return self.python_callable(*self.op_args, **self.op_kwargs)
  File "/opt/airflow/dags/main.py", line 60, in main
    config = get_config('web')
  File "/opt/airflow/dags/main.py", line 22, in get_config
    return {key: value for key, value in parser.items(section)}
  File "/usr/local/lib/python3.8/configparser.py", line 849, in items
    raise NoSectionError(section)
configparser.NoSectionError: No section: 'web'
[2023-12-07T16:43:02.912+0000] {taskinstance.py:1400} INFO - Marking task as FAILED. dag_id=my_scraping_dag, task_id=main_task, execution_date=20231107T000000, start_date=20231207T164302, end_date=20231207T164302
[2023-12-07T16:43:02.951+0000] {standard_task_runner.py:104} ERROR - Failed to execute job 1244 for task main_task (No section: 'web'; 5103)
[2023-12-07T16:43:02.988+0000] {local_task_job_runner.py:228} INFO - Task exited with return code 1
[2023-12-07T16:43:03.028+0000] {taskinstance.py:2778} INFO - 0 downstream tasks scheduled from follow-on schedule check
[2023-12-07T17:01:44.215+0000] {taskinstance.py:1159} INFO - Dependencies all met for dep_context=non-requeueable deps ti=<TaskInstance: my_scraping_dag.main_task scheduled__2023-11-07T00:00:00+00:00 [queued]>
[2023-12-07T17:01:44.221+0000] {taskinstance.py:1159} INFO - Dependencies all met for dep_context=requeueable deps ti=<TaskInstance: my_scraping_dag.main_task scheduled__2023-11-07T00:00:00+00:00 [queued]>
[2023-12-07T17:01:44.222+0000] {taskinstance.py:1361} INFO - Starting attempt 1 of 1
[2023-12-07T17:01:44.231+0000] {taskinstance.py:1382} INFO - Executing <Task(PythonOperator): main_task> on 2023-11-07 00:00:00+00:00
[2023-12-07T17:01:44.234+0000] {standard_task_runner.py:57} INFO - Started process 6633 to run task
[2023-12-07T17:01:44.238+0000] {standard_task_runner.py:84} INFO - Running: ['***', 'tasks', 'run', 'my_scraping_dag', 'main_task', 'scheduled__2023-11-07T00:00:00+00:00', '--job-id', '1777', '--raw', '--subdir', 'DAGS_FOLDER/main.py', '--cfg-path', '/tmp/tmpt3r94c67']
[2023-12-07T17:01:44.239+0000] {standard_task_runner.py:85} INFO - Job 1777: Subtask main_task
[2023-12-07T17:01:44.272+0000] {task_command.py:416} INFO - Running <TaskInstance: my_scraping_dag.main_task scheduled__2023-11-07T00:00:00+00:00 [running]> on host 63b0c7e341c0
[2023-12-07T17:01:44.343+0000] {taskinstance.py:1662} INFO - Exporting env vars: AIRFLOW_CTX_DAG_OWNER='***' AIRFLOW_CTX_DAG_ID='my_scraping_dag' AIRFLOW_CTX_TASK_ID='main_task' AIRFLOW_CTX_EXECUTION_DATE='2023-11-07T00:00:00+00:00' AIRFLOW_CTX_TRY_NUMBER='1' AIRFLOW_CTX_DAG_RUN_ID='scheduled__2023-11-07T00:00:00+00:00'
[2023-12-07T17:01:44.392+0000] {logging_mixin.py:154} INFO - base_url: https://tuncbotanik.com
[2023-12-07T17:01:44.394+0000] {python.py:194} INFO - Done. Returned value was: ('https://tuncbotanik.com', {'User-Agent': 'Mozilla/5.0 (Macintosh; Intel Mac OS X 10_15_7) AppleWebKit/537.36 (KHTML, like Gecko) Chrome/119.0.0.0 Safari/537.36', 'Accept-Language': 'tr-TR,tr;q=0.9,en-US;q=0.8,en;q=0.7'}, {'dbname': 'plant', 'user': 'aozgokme', 'password': '***', 'host': 'localhost', 'port': '5432'})
[2023-12-07T17:01:44.415+0000] {taskinstance.py:1400} INFO - Marking task as SUCCESS. dag_id=my_scraping_dag, task_id=main_task, execution_date=20231107T000000, start_date=20231207T170144, end_date=20231207T170144
[2023-12-07T17:01:44.449+0000] {local_task_job_runner.py:228} INFO - Task exited with return code 0
[2023-12-07T17:01:44.492+0000] {taskinstance.py:2778} INFO - 0 downstream tasks scheduled from follow-on schedule check
[2023-12-07T17:05:02.905+0000] {taskinstance.py:1159} INFO - Dependencies all met for dep_context=non-requeueable deps ti=<TaskInstance: my_scraping_dag.main_task scheduled__2023-11-07T00:00:00+00:00 [queued]>
[2023-12-07T17:05:02.911+0000] {taskinstance.py:1159} INFO - Dependencies all met for dep_context=requeueable deps ti=<TaskInstance: my_scraping_dag.main_task scheduled__2023-11-07T00:00:00+00:00 [queued]>
[2023-12-07T17:05:02.912+0000] {taskinstance.py:1361} INFO - Starting attempt 1 of 1
[2023-12-07T17:05:02.923+0000] {taskinstance.py:1382} INFO - Executing <Task(PythonOperator): main_task> on 2023-11-07 00:00:00+00:00
[2023-12-07T17:05:02.933+0000] {standard_task_runner.py:57} INFO - Started process 8073 to run task
[2023-12-07T17:05:02.940+0000] {standard_task_runner.py:84} INFO - Running: ['***', 'tasks', 'run', 'my_scraping_dag', 'main_task', 'scheduled__2023-11-07T00:00:00+00:00', '--job-id', '2460', '--raw', '--subdir', 'DAGS_FOLDER/main.py', '--cfg-path', '/tmp/tmpe8wjfe1i']
[2023-12-07T17:05:02.943+0000] {standard_task_runner.py:85} INFO - Job 2460: Subtask main_task
[2023-12-07T17:05:03.003+0000] {task_command.py:416} INFO - Running <TaskInstance: my_scraping_dag.main_task scheduled__2023-11-07T00:00:00+00:00 [running]> on host 63b0c7e341c0
[2023-12-07T17:05:03.093+0000] {taskinstance.py:1662} INFO - Exporting env vars: AIRFLOW_CTX_DAG_OWNER='***' AIRFLOW_CTX_DAG_ID='my_scraping_dag' AIRFLOW_CTX_TASK_ID='main_task' AIRFLOW_CTX_EXECUTION_DATE='2023-11-07T00:00:00+00:00' AIRFLOW_CTX_TRY_NUMBER='1' AIRFLOW_CTX_DAG_RUN_ID='scheduled__2023-11-07T00:00:00+00:00'
[2023-12-07T17:05:03.124+0000] {logging_mixin.py:154} INFO - base_url: https://tuncbotanik.com
[2023-12-07T17:05:03.126+0000] {python.py:194} INFO - Done. Returned value was: ('https://tuncbotanik.com', {'User-Agent': 'Mozilla/5.0 (Macintosh; Intel Mac OS X 10_15_7) AppleWebKit/537.36 (KHTML, like Gecko) Chrome/119.0.0.0 Safari/537.36', 'Accept-Language': 'tr-TR,tr;q=0.9,en-US;q=0.8,en;q=0.7'}, {'dbname': 'plant', 'user': 'aozgokme', 'password': '***', 'host': 'localhost', 'port': '5432'})
[2023-12-07T17:05:03.153+0000] {taskinstance.py:1400} INFO - Marking task as SUCCESS. dag_id=my_scraping_dag, task_id=main_task, execution_date=20231107T000000, start_date=20231207T170502, end_date=20231207T170503
[2023-12-07T17:05:03.190+0000] {local_task_job_runner.py:228} INFO - Task exited with return code 0
[2023-12-07T17:05:03.263+0000] {taskinstance.py:2778} INFO - 0 downstream tasks scheduled from follow-on schedule check
[2023-12-07T17:19:22.550+0000] {taskinstance.py:1159} INFO - Dependencies all met for dep_context=non-requeueable deps ti=<TaskInstance: my_scraping_dag.main_task scheduled__2023-11-07T00:00:00+00:00 [queued]>
[2023-12-07T17:19:22.561+0000] {taskinstance.py:1159} INFO - Dependencies all met for dep_context=requeueable deps ti=<TaskInstance: my_scraping_dag.main_task scheduled__2023-11-07T00:00:00+00:00 [queued]>
[2023-12-07T17:19:22.562+0000] {taskinstance.py:1361} INFO - Starting attempt 1 of 1
[2023-12-07T17:19:22.577+0000] {taskinstance.py:1382} INFO - Executing <Task(PythonOperator): main_task> on 2023-11-07 00:00:00+00:00
[2023-12-07T17:19:22.583+0000] {standard_task_runner.py:57} INFO - Started process 9187 to run task
[2023-12-07T17:19:22.586+0000] {standard_task_runner.py:84} INFO - Running: ['***', 'tasks', 'run', 'my_scraping_dag', 'main_task', 'scheduled__2023-11-07T00:00:00+00:00', '--job-id', '2840', '--raw', '--subdir', 'DAGS_FOLDER/main.py', '--cfg-path', '/tmp/tmpgh0tlp_2']
[2023-12-07T17:19:22.589+0000] {standard_task_runner.py:85} INFO - Job 2840: Subtask main_task
[2023-12-07T17:19:22.637+0000] {task_command.py:416} INFO - Running <TaskInstance: my_scraping_dag.main_task scheduled__2023-11-07T00:00:00+00:00 [running]> on host 63b0c7e341c0
[2023-12-07T17:19:22.697+0000] {taskinstance.py:1662} INFO - Exporting env vars: AIRFLOW_CTX_DAG_OWNER='***' AIRFLOW_CTX_DAG_ID='my_scraping_dag' AIRFLOW_CTX_TASK_ID='main_task' AIRFLOW_CTX_EXECUTION_DATE='2023-11-07T00:00:00+00:00' AIRFLOW_CTX_TRY_NUMBER='1' AIRFLOW_CTX_DAG_RUN_ID='scheduled__2023-11-07T00:00:00+00:00'
[2023-12-07T17:19:23.388+0000] {taskinstance.py:1937} ERROR - Task failed with exception
Traceback (most recent call last):
  File "/home/airflow/.local/lib/python3.8/site-packages/airflow/operators/python.py", line 192, in execute
    return_value = self.execute_callable()
  File "/home/airflow/.local/lib/python3.8/site-packages/airflow/operators/python.py", line 209, in execute_callable
    return self.python_callable(*self.op_args, **self.op_kwargs)
  File "/opt/airflow/dags/main.py", line 80, in main
    insert_data_to_db(products, db_params)
  File "/opt/airflow/dags/main.py", line 43, in insert_data_to_db
    with psycopg2.connect(**db_params) as conn:
  File "/home/airflow/.local/lib/python3.8/site-packages/psycopg2/__init__.py", line 122, in connect
    conn = _connect(dsn, connection_factory=connection_factory, **kwasync)
psycopg2.OperationalError: connection to server at "localhost" (127.0.0.1), port 5432 failed: Connection refused
	Is the server running on that host and accepting TCP/IP connections?
connection to server at "localhost" (::1), port 5432 failed: Cannot assign requested address
	Is the server running on that host and accepting TCP/IP connections?

[2023-12-07T17:19:23.393+0000] {taskinstance.py:1400} INFO - Marking task as FAILED. dag_id=my_scraping_dag, task_id=main_task, execution_date=20231107T000000, start_date=20231207T171922, end_date=20231207T171923
[2023-12-07T17:19:23.398+0000] {standard_task_runner.py:104} ERROR - Failed to execute job 2840 for task main_task (connection to server at "localhost" (127.0.0.1), port 5432 failed: Connection refused
	Is the server running on that host and accepting TCP/IP connections?
connection to server at "localhost" (::1), port 5432 failed: Cannot assign requested address
	Is the server running on that host and accepting TCP/IP connections?
; 9187)
[2023-12-07T17:19:23.420+0000] {local_task_job_runner.py:228} INFO - Task exited with return code 1
[2023-12-07T17:19:23.430+0000] {taskinstance.py:2778} INFO - 0 downstream tasks scheduled from follow-on schedule check
[2023-12-07T17:23:44.194+0000] {taskinstance.py:1159} INFO - Dependencies all met for dep_context=non-requeueable deps ti=<TaskInstance: my_scraping_dag.main_task scheduled__2023-11-07T00:00:00+00:00 [queued]>
[2023-12-07T17:23:44.200+0000] {taskinstance.py:1159} INFO - Dependencies all met for dep_context=requeueable deps ti=<TaskInstance: my_scraping_dag.main_task scheduled__2023-11-07T00:00:00+00:00 [queued]>
[2023-12-07T17:23:44.201+0000] {taskinstance.py:1361} INFO - Starting attempt 1 of 1
[2023-12-07T17:23:44.213+0000] {taskinstance.py:1382} INFO - Executing <Task(PythonOperator): main_task> on 2023-11-07 00:00:00+00:00
[2023-12-07T17:23:44.215+0000] {standard_task_runner.py:57} INFO - Started process 9982 to run task
[2023-12-07T17:23:44.218+0000] {standard_task_runner.py:84} INFO - Running: ['***', 'tasks', 'run', 'my_scraping_dag', 'main_task', 'scheduled__2023-11-07T00:00:00+00:00', '--job-id', '3182', '--raw', '--subdir', 'DAGS_FOLDER/main.py', '--cfg-path', '/tmp/tmpu91gm9p1']
[2023-12-07T17:23:44.221+0000] {standard_task_runner.py:85} INFO - Job 3182: Subtask main_task
[2023-12-07T17:23:44.248+0000] {task_command.py:416} INFO - Running <TaskInstance: my_scraping_dag.main_task scheduled__2023-11-07T00:00:00+00:00 [running]> on host 63b0c7e341c0
[2023-12-07T17:23:44.300+0000] {taskinstance.py:1662} INFO - Exporting env vars: AIRFLOW_CTX_DAG_OWNER='***' AIRFLOW_CTX_DAG_ID='my_scraping_dag' AIRFLOW_CTX_TASK_ID='main_task' AIRFLOW_CTX_EXECUTION_DATE='2023-11-07T00:00:00+00:00' AIRFLOW_CTX_TRY_NUMBER='1' AIRFLOW_CTX_DAG_RUN_ID='scheduled__2023-11-07T00:00:00+00:00'
[2023-12-07T17:23:45.124+0000] {taskinstance.py:1937} ERROR - Task failed with exception
Traceback (most recent call last):
  File "/home/airflow/.local/lib/python3.8/site-packages/airflow/operators/python.py", line 192, in execute
    return_value = self.execute_callable()
  File "/home/airflow/.local/lib/python3.8/site-packages/airflow/operators/python.py", line 209, in execute_callable
    return self.python_callable(*self.op_args, **self.op_kwargs)
  File "/opt/airflow/dags/main.py", line 73, in main
    insert_data_to_db(products, db_params)
  File "/opt/airflow/dags/main.py", line 40, in insert_data_to_db
    with psycopg2.connect(**db_params) as conn:
  File "/home/airflow/.local/lib/python3.8/site-packages/psycopg2/__init__.py", line 122, in connect
    conn = _connect(dsn, connection_factory=connection_factory, **kwasync)
psycopg2.OperationalError: connection to server at "localhost" (127.0.0.1), port 5432 failed: Connection refused
	Is the server running on that host and accepting TCP/IP connections?
connection to server at "localhost" (::1), port 5432 failed: Cannot assign requested address
	Is the server running on that host and accepting TCP/IP connections?

[2023-12-07T17:23:45.128+0000] {taskinstance.py:1400} INFO - Marking task as FAILED. dag_id=my_scraping_dag, task_id=main_task, execution_date=20231107T000000, start_date=20231207T172344, end_date=20231207T172345
[2023-12-07T17:23:45.134+0000] {standard_task_runner.py:104} ERROR - Failed to execute job 3182 for task main_task (connection to server at "localhost" (127.0.0.1), port 5432 failed: Connection refused
	Is the server running on that host and accepting TCP/IP connections?
connection to server at "localhost" (::1), port 5432 failed: Cannot assign requested address
	Is the server running on that host and accepting TCP/IP connections?
; 9982)
[2023-12-07T17:23:45.177+0000] {local_task_job_runner.py:228} INFO - Task exited with return code 1
[2023-12-07T17:23:45.188+0000] {taskinstance.py:2778} INFO - 0 downstream tasks scheduled from follow-on schedule check
[2023-12-07T17:29:20.308+0000] {taskinstance.py:1159} INFO - Dependencies all met for dep_context=non-requeueable deps ti=<TaskInstance: my_scraping_dag.main_task scheduled__2023-11-07T00:00:00+00:00 [queued]>
[2023-12-07T17:29:20.316+0000] {taskinstance.py:1159} INFO - Dependencies all met for dep_context=requeueable deps ti=<TaskInstance: my_scraping_dag.main_task scheduled__2023-11-07T00:00:00+00:00 [queued]>
[2023-12-07T17:29:20.319+0000] {taskinstance.py:1361} INFO - Starting attempt 1 of 1
[2023-12-07T17:29:20.338+0000] {taskinstance.py:1382} INFO - Executing <Task(PythonOperator): main_task> on 2023-11-07 00:00:00+00:00
[2023-12-07T17:29:20.343+0000] {standard_task_runner.py:57} INFO - Started process 10818 to run task
[2023-12-07T17:29:20.346+0000] {standard_task_runner.py:84} INFO - Running: ['***', 'tasks', 'run', 'my_scraping_dag', 'main_task', 'scheduled__2023-11-07T00:00:00+00:00', '--job-id', '3524', '--raw', '--subdir', 'DAGS_FOLDER/main.py', '--cfg-path', '/tmp/tmpv870oqx2']
[2023-12-07T17:29:20.358+0000] {standard_task_runner.py:85} INFO - Job 3524: Subtask main_task
[2023-12-07T17:29:20.456+0000] {task_command.py:416} INFO - Running <TaskInstance: my_scraping_dag.main_task scheduled__2023-11-07T00:00:00+00:00 [running]> on host 63b0c7e341c0
[2023-12-07T17:29:20.698+0000] {taskinstance.py:1662} INFO - Exporting env vars: AIRFLOW_CTX_DAG_OWNER='***' AIRFLOW_CTX_DAG_ID='my_scraping_dag' AIRFLOW_CTX_TASK_ID='main_task' AIRFLOW_CTX_EXECUTION_DATE='2023-11-07T00:00:00+00:00' AIRFLOW_CTX_TRY_NUMBER='1' AIRFLOW_CTX_DAG_RUN_ID='scheduled__2023-11-07T00:00:00+00:00'
[2023-12-07T17:29:21.672+0000] {taskinstance.py:1937} ERROR - Task failed with exception
Traceback (most recent call last):
  File "/home/airflow/.local/lib/python3.8/site-packages/airflow/operators/python.py", line 192, in execute
    return_value = self.execute_callable()
  File "/home/airflow/.local/lib/python3.8/site-packages/airflow/operators/python.py", line 209, in execute_callable
    return self.python_callable(*self.op_args, **self.op_kwargs)
  File "/opt/airflow/dags/main.py", line 73, in main
    insert_data_to_db(products, db_params)
  File "/opt/airflow/dags/main.py", line 40, in insert_data_to_db
    with psycopg2.connect(**db_params) as conn:
  File "/home/airflow/.local/lib/python3.8/site-packages/psycopg2/__init__.py", line 122, in connect
    conn = _connect(dsn, connection_factory=connection_factory, **kwasync)
psycopg2.OperationalError: connection to server at "localhost" (127.0.0.1), port 5432 failed: Connection refused
	Is the server running on that host and accepting TCP/IP connections?
connection to server at "localhost" (::1), port 5432 failed: Cannot assign requested address
	Is the server running on that host and accepting TCP/IP connections?

[2023-12-07T17:29:21.682+0000] {taskinstance.py:1400} INFO - Marking task as FAILED. dag_id=my_scraping_dag, task_id=main_task, execution_date=20231107T000000, start_date=20231207T172920, end_date=20231207T172921
[2023-12-07T17:29:21.689+0000] {standard_task_runner.py:104} ERROR - Failed to execute job 3524 for task main_task (connection to server at "localhost" (127.0.0.1), port 5432 failed: Connection refused
	Is the server running on that host and accepting TCP/IP connections?
connection to server at "localhost" (::1), port 5432 failed: Cannot assign requested address
	Is the server running on that host and accepting TCP/IP connections?
; 10818)
[2023-12-07T17:29:21.721+0000] {local_task_job_runner.py:228} INFO - Task exited with return code 1
[2023-12-07T17:29:21.736+0000] {taskinstance.py:2778} INFO - 0 downstream tasks scheduled from follow-on schedule check
[2023-12-09T07:35:36.908+0000] {taskinstance.py:1159} INFO - Dependencies all met for dep_context=non-requeueable deps ti=<TaskInstance: my_scraping_dag.main_task scheduled__2023-11-07T00:00:00+00:00 [queued]>
[2023-12-09T07:35:36.911+0000] {taskinstance.py:1159} INFO - Dependencies all met for dep_context=requeueable deps ti=<TaskInstance: my_scraping_dag.main_task scheduled__2023-11-07T00:00:00+00:00 [queued]>
[2023-12-09T07:35:36.912+0000] {taskinstance.py:1361} INFO - Starting attempt 1 of 1
[2023-12-09T07:35:36.918+0000] {taskinstance.py:1382} INFO - Executing <Task(PythonOperator): main_task> on 2023-11-07 00:00:00+00:00
[2023-12-09T07:35:36.920+0000] {standard_task_runner.py:57} INFO - Started process 1240 to run task
[2023-12-09T07:35:36.922+0000] {standard_task_runner.py:84} INFO - Running: ['***', 'tasks', 'run', 'my_scraping_dag', 'main_task', 'scheduled__2023-11-07T00:00:00+00:00', '--job-id', '314', '--raw', '--subdir', 'DAGS_FOLDER/main.py', '--cfg-path', '/tmp/tmpqhp5vrdq']
[2023-12-09T07:35:36.924+0000] {standard_task_runner.py:85} INFO - Job 314: Subtask main_task
[2023-12-09T07:35:36.944+0000] {task_command.py:416} INFO - Running <TaskInstance: my_scraping_dag.main_task scheduled__2023-11-07T00:00:00+00:00 [running]> on host 36b5ef2505c9
[2023-12-09T07:35:36.974+0000] {taskinstance.py:1662} INFO - Exporting env vars: AIRFLOW_CTX_DAG_OWNER='***' AIRFLOW_CTX_DAG_ID='my_scraping_dag' AIRFLOW_CTX_TASK_ID='main_task' AIRFLOW_CTX_EXECUTION_DATE='2023-11-07T00:00:00+00:00' AIRFLOW_CTX_TRY_NUMBER='1' AIRFLOW_CTX_DAG_RUN_ID='scheduled__2023-11-07T00:00:00+00:00'
[2023-12-09T07:35:36.982+0000] {taskinstance.py:1937} ERROR - Task failed with exception
Traceback (most recent call last):
  File "/home/airflow/.local/lib/python3.8/site-packages/airflow/operators/python.py", line 192, in execute
    return_value = self.execute_callable()
  File "/home/airflow/.local/lib/python3.8/site-packages/airflow/operators/python.py", line 209, in execute_callable
    return self.python_callable(*self.op_args, **self.op_kwargs)
  File "/opt/airflow/dags/main.py", line 66, in main
    'User-Agent': Variable.get('user_agent'),
  File "/home/airflow/.local/lib/python3.8/site-packages/airflow/models/variable.py", line 140, in get
    raise KeyError(f"Variable {key} does not exist")
KeyError: 'Variable user_agent does not exist'
[2023-12-09T07:35:36.989+0000] {taskinstance.py:1400} INFO - Marking task as FAILED. dag_id=my_scraping_dag, task_id=main_task, execution_date=20231107T000000, start_date=20231209T073536, end_date=20231209T073536
[2023-12-09T07:35:36.996+0000] {standard_task_runner.py:104} ERROR - Failed to execute job 314 for task main_task ('Variable user_agent does not exist'; 1240)
[2023-12-09T07:35:37.016+0000] {local_task_job_runner.py:228} INFO - Task exited with return code 1
[2023-12-09T07:35:37.025+0000] {taskinstance.py:2778} INFO - 0 downstream tasks scheduled from follow-on schedule check
