[2023-12-07T14:52:10.659+0000] {taskinstance.py:1159} INFO - Dependencies all met for dep_context=non-requeueable deps ti=<TaskInstance: my_scraping_dag.main_task scheduled__2023-04-05T00:00:00+00:00 [queued]>
[2023-12-07T14:52:10.665+0000] {taskinstance.py:1159} INFO - Dependencies all met for dep_context=requeueable deps ti=<TaskInstance: my_scraping_dag.main_task scheduled__2023-04-05T00:00:00+00:00 [queued]>
[2023-12-07T14:52:10.665+0000] {taskinstance.py:1361} INFO - Starting attempt 1 of 1
[2023-12-07T14:52:10.674+0000] {taskinstance.py:1382} INFO - Executing <Task(PythonOperator): main_task> on 2023-04-05 00:00:00+00:00
[2023-12-07T14:52:10.678+0000] {standard_task_runner.py:57} INFO - Started process 950 to run task
[2023-12-07T14:52:10.680+0000] {standard_task_runner.py:84} INFO - Running: ['***', 'tasks', 'run', 'my_scraping_dag', 'main_task', 'scheduled__2023-04-05T00:00:00+00:00', '--job-id', '205', '--raw', '--subdir', 'DAGS_FOLDER/main.py', '--cfg-path', '/tmp/tmp1nlh5p_7']
[2023-12-07T14:52:10.682+0000] {standard_task_runner.py:85} INFO - Job 205: Subtask main_task
[2023-12-07T14:52:10.706+0000] {task_command.py:416} INFO - Running <TaskInstance: my_scraping_dag.main_task scheduled__2023-04-05T00:00:00+00:00 [running]> on host 63b0c7e341c0
[2023-12-07T14:52:10.742+0000] {taskinstance.py:1662} INFO - Exporting env vars: AIRFLOW_CTX_DAG_OWNER='***' AIRFLOW_CTX_DAG_ID='my_scraping_dag' AIRFLOW_CTX_TASK_ID='main_task' AIRFLOW_CTX_EXECUTION_DATE='2023-04-05T00:00:00+00:00' AIRFLOW_CTX_TRY_NUMBER='1' AIRFLOW_CTX_DAG_RUN_ID='scheduled__2023-04-05T00:00:00+00:00'
[2023-12-07T14:52:10.743+0000] {taskinstance.py:1937} ERROR - Task failed with exception
Traceback (most recent call last):
  File "/usr/local/lib/python3.8/configparser.py", line 846, in items
    d.update(self._sections[section])
KeyError: 'web'

During handling of the above exception, another exception occurred:

Traceback (most recent call last):
  File "/home/airflow/.local/lib/python3.8/site-packages/airflow/operators/python.py", line 192, in execute
    return_value = self.execute_callable()
  File "/home/airflow/.local/lib/python3.8/site-packages/airflow/operators/python.py", line 209, in execute_callable
    return self.python_callable(*self.op_args, **self.op_kwargs)
  File "/opt/airflow/dags/main.py", line 61, in main
    config = get_config('web')
  File "/opt/airflow/dags/main.py", line 23, in get_config
    return {key: value for key, value in parser.items(section)}
  File "/usr/local/lib/python3.8/configparser.py", line 849, in items
    raise NoSectionError(section)
configparser.NoSectionError: No section: 'web'
[2023-12-07T14:52:10.748+0000] {taskinstance.py:1400} INFO - Marking task as FAILED. dag_id=my_scraping_dag, task_id=main_task, execution_date=20230405T000000, start_date=20231207T145210, end_date=20231207T145210
[2023-12-07T14:52:10.754+0000] {standard_task_runner.py:104} ERROR - Failed to execute job 205 for task main_task (No section: 'web'; 950)
[2023-12-07T14:52:10.772+0000] {local_task_job_runner.py:228} INFO - Task exited with return code 1
[2023-12-07T14:52:10.802+0000] {taskinstance.py:2778} INFO - 0 downstream tasks scheduled from follow-on schedule check
[2023-12-07T15:00:21.136+0000] {taskinstance.py:1159} INFO - Dependencies all met for dep_context=non-requeueable deps ti=<TaskInstance: my_scraping_dag.main_task scheduled__2023-04-05T00:00:00+00:00 [queued]>
[2023-12-07T15:00:21.141+0000] {taskinstance.py:1159} INFO - Dependencies all met for dep_context=requeueable deps ti=<TaskInstance: my_scraping_dag.main_task scheduled__2023-04-05T00:00:00+00:00 [queued]>
[2023-12-07T15:00:21.141+0000] {taskinstance.py:1361} INFO - Starting attempt 1 of 1
[2023-12-07T15:00:21.146+0000] {taskinstance.py:1382} INFO - Executing <Task(PythonOperator): main_task> on 2023-04-05 00:00:00+00:00
[2023-12-07T15:00:21.149+0000] {standard_task_runner.py:57} INFO - Started process 1564 to run task
[2023-12-07T15:00:21.151+0000] {standard_task_runner.py:84} INFO - Running: ['***', 'tasks', 'run', 'my_scraping_dag', 'main_task', 'scheduled__2023-04-05T00:00:00+00:00', '--job-id', '410', '--raw', '--subdir', 'DAGS_FOLDER/main.py', '--cfg-path', '/tmp/tmpozz8y70m']
[2023-12-07T15:00:21.152+0000] {standard_task_runner.py:85} INFO - Job 410: Subtask main_task
[2023-12-07T15:00:21.174+0000] {task_command.py:416} INFO - Running <TaskInstance: my_scraping_dag.main_task scheduled__2023-04-05T00:00:00+00:00 [running]> on host 63b0c7e341c0
[2023-12-07T15:00:21.203+0000] {taskinstance.py:1662} INFO - Exporting env vars: AIRFLOW_CTX_DAG_OWNER='***' AIRFLOW_CTX_DAG_ID='my_scraping_dag' AIRFLOW_CTX_TASK_ID='main_task' AIRFLOW_CTX_EXECUTION_DATE='2023-04-05T00:00:00+00:00' AIRFLOW_CTX_TRY_NUMBER='1' AIRFLOW_CTX_DAG_RUN_ID='scheduled__2023-04-05T00:00:00+00:00'
[2023-12-07T15:00:21.204+0000] {taskinstance.py:1937} ERROR - Task failed with exception
Traceback (most recent call last):
  File "/usr/local/lib/python3.8/configparser.py", line 846, in items
    d.update(self._sections[section])
KeyError: 'web'

During handling of the above exception, another exception occurred:

Traceback (most recent call last):
  File "/home/airflow/.local/lib/python3.8/site-packages/airflow/operators/python.py", line 192, in execute
    return_value = self.execute_callable()
  File "/home/airflow/.local/lib/python3.8/site-packages/airflow/operators/python.py", line 209, in execute_callable
    return self.python_callable(*self.op_args, **self.op_kwargs)
  File "/opt/airflow/dags/main.py", line 60, in main
    config = get_config('web')
  File "/opt/airflow/dags/main.py", line 22, in get_config
    return {key: value for key, value in parser.items(section)}
  File "/usr/local/lib/python3.8/configparser.py", line 849, in items
    raise NoSectionError(section)
configparser.NoSectionError: No section: 'web'
[2023-12-07T15:00:21.208+0000] {taskinstance.py:1400} INFO - Marking task as FAILED. dag_id=my_scraping_dag, task_id=main_task, execution_date=20230405T000000, start_date=20231207T150021, end_date=20231207T150021
[2023-12-07T15:00:21.212+0000] {standard_task_runner.py:104} ERROR - Failed to execute job 410 for task main_task (No section: 'web'; 1564)
[2023-12-07T15:00:21.243+0000] {local_task_job_runner.py:228} INFO - Task exited with return code 1
[2023-12-07T15:00:21.255+0000] {taskinstance.py:2778} INFO - 0 downstream tasks scheduled from follow-on schedule check
[2023-12-07T16:32:07.059+0000] {taskinstance.py:1159} INFO - Dependencies all met for dep_context=non-requeueable deps ti=<TaskInstance: my_scraping_dag.main_task scheduled__2023-04-05T00:00:00+00:00 [queued]>
[2023-12-07T16:32:07.065+0000] {taskinstance.py:1159} INFO - Dependencies all met for dep_context=requeueable deps ti=<TaskInstance: my_scraping_dag.main_task scheduled__2023-04-05T00:00:00+00:00 [queued]>
[2023-12-07T16:32:07.065+0000] {taskinstance.py:1361} INFO - Starting attempt 1 of 1
[2023-12-07T16:32:07.072+0000] {taskinstance.py:1382} INFO - Executing <Task(PythonOperator): main_task> on 2023-04-05 00:00:00+00:00
[2023-12-07T16:32:07.074+0000] {standard_task_runner.py:57} INFO - Started process 3722 to run task
[2023-12-07T16:32:07.076+0000] {standard_task_runner.py:84} INFO - Running: ['***', 'tasks', 'run', 'my_scraping_dag', 'main_task', 'scheduled__2023-04-05T00:00:00+00:00', '--job-id', '683', '--raw', '--subdir', 'DAGS_FOLDER/main.py', '--cfg-path', '/tmp/tmpc64fq91h']
[2023-12-07T16:32:07.078+0000] {standard_task_runner.py:85} INFO - Job 683: Subtask main_task
[2023-12-07T16:32:07.102+0000] {task_command.py:416} INFO - Running <TaskInstance: my_scraping_dag.main_task scheduled__2023-04-05T00:00:00+00:00 [running]> on host 63b0c7e341c0
[2023-12-07T16:32:07.136+0000] {taskinstance.py:1662} INFO - Exporting env vars: AIRFLOW_CTX_DAG_OWNER='***' AIRFLOW_CTX_DAG_ID='my_scraping_dag' AIRFLOW_CTX_TASK_ID='main_task' AIRFLOW_CTX_EXECUTION_DATE='2023-04-05T00:00:00+00:00' AIRFLOW_CTX_TRY_NUMBER='1' AIRFLOW_CTX_DAG_RUN_ID='scheduled__2023-04-05T00:00:00+00:00'
[2023-12-07T16:32:07.137+0000] {taskinstance.py:1937} ERROR - Task failed with exception
Traceback (most recent call last):
  File "/usr/local/lib/python3.8/configparser.py", line 846, in items
    d.update(self._sections[section])
KeyError: 'web'

During handling of the above exception, another exception occurred:

Traceback (most recent call last):
  File "/home/airflow/.local/lib/python3.8/site-packages/airflow/operators/python.py", line 192, in execute
    return_value = self.execute_callable()
  File "/home/airflow/.local/lib/python3.8/site-packages/airflow/operators/python.py", line 209, in execute_callable
    return self.python_callable(*self.op_args, **self.op_kwargs)
  File "/opt/airflow/dags/main.py", line 60, in main
    config = get_config('web')
  File "/opt/airflow/dags/main.py", line 22, in get_config
    return {key: value for key, value in parser.items(section)}
  File "/usr/local/lib/python3.8/configparser.py", line 849, in items
    raise NoSectionError(section)
configparser.NoSectionError: No section: 'web'
[2023-12-07T16:32:07.142+0000] {taskinstance.py:1400} INFO - Marking task as FAILED. dag_id=my_scraping_dag, task_id=main_task, execution_date=20230405T000000, start_date=20231207T163207, end_date=20231207T163207
[2023-12-07T16:32:07.147+0000] {standard_task_runner.py:104} ERROR - Failed to execute job 683 for task main_task (No section: 'web'; 3722)
[2023-12-07T16:32:07.169+0000] {local_task_job_runner.py:228} INFO - Task exited with return code 1
[2023-12-07T16:32:07.183+0000] {taskinstance.py:2778} INFO - 0 downstream tasks scheduled from follow-on schedule check
[2023-12-07T16:41:26.585+0000] {taskinstance.py:1159} INFO - Dependencies all met for dep_context=non-requeueable deps ti=<TaskInstance: my_scraping_dag.main_task scheduled__2023-04-05T00:00:00+00:00 [queued]>
[2023-12-07T16:41:26.590+0000] {taskinstance.py:1159} INFO - Dependencies all met for dep_context=requeueable deps ti=<TaskInstance: my_scraping_dag.main_task scheduled__2023-04-05T00:00:00+00:00 [queued]>
[2023-12-07T16:41:26.591+0000] {taskinstance.py:1361} INFO - Starting attempt 1 of 1
[2023-12-07T16:41:26.600+0000] {taskinstance.py:1382} INFO - Executing <Task(PythonOperator): main_task> on 2023-04-05 00:00:00+00:00
[2023-12-07T16:41:26.603+0000] {standard_task_runner.py:57} INFO - Started process 4630 to run task
[2023-12-07T16:41:26.606+0000] {standard_task_runner.py:84} INFO - Running: ['***', 'tasks', 'run', 'my_scraping_dag', 'main_task', 'scheduled__2023-04-05T00:00:00+00:00', '--job-id', '1025', '--raw', '--subdir', 'DAGS_FOLDER/main.py', '--cfg-path', '/tmp/tmpziglsoa1']
[2023-12-07T16:41:26.608+0000] {standard_task_runner.py:85} INFO - Job 1025: Subtask main_task
[2023-12-07T16:41:26.636+0000] {task_command.py:416} INFO - Running <TaskInstance: my_scraping_dag.main_task scheduled__2023-04-05T00:00:00+00:00 [running]> on host 63b0c7e341c0
[2023-12-07T16:41:26.683+0000] {taskinstance.py:1662} INFO - Exporting env vars: AIRFLOW_CTX_DAG_OWNER='***' AIRFLOW_CTX_DAG_ID='my_scraping_dag' AIRFLOW_CTX_TASK_ID='main_task' AIRFLOW_CTX_EXECUTION_DATE='2023-04-05T00:00:00+00:00' AIRFLOW_CTX_TRY_NUMBER='1' AIRFLOW_CTX_DAG_RUN_ID='scheduled__2023-04-05T00:00:00+00:00'
[2023-12-07T16:41:26.685+0000] {taskinstance.py:1937} ERROR - Task failed with exception
Traceback (most recent call last):
  File "/usr/local/lib/python3.8/configparser.py", line 846, in items
    d.update(self._sections[section])
KeyError: 'web'

During handling of the above exception, another exception occurred:

Traceback (most recent call last):
  File "/home/airflow/.local/lib/python3.8/site-packages/airflow/operators/python.py", line 192, in execute
    return_value = self.execute_callable()
  File "/home/airflow/.local/lib/python3.8/site-packages/airflow/operators/python.py", line 209, in execute_callable
    return self.python_callable(*self.op_args, **self.op_kwargs)
  File "/opt/airflow/dags/main.py", line 60, in main
    config = get_config('web')
  File "/opt/airflow/dags/main.py", line 22, in get_config
    return {key: value for key, value in parser.items(section)}
  File "/usr/local/lib/python3.8/configparser.py", line 849, in items
    raise NoSectionError(section)
configparser.NoSectionError: No section: 'web'
[2023-12-07T16:41:26.691+0000] {taskinstance.py:1400} INFO - Marking task as FAILED. dag_id=my_scraping_dag, task_id=main_task, execution_date=20230405T000000, start_date=20231207T164126, end_date=20231207T164126
[2023-12-07T16:41:26.696+0000] {standard_task_runner.py:104} ERROR - Failed to execute job 1025 for task main_task (No section: 'web'; 4630)
[2023-12-07T16:41:26.739+0000] {local_task_job_runner.py:228} INFO - Task exited with return code 1
[2023-12-07T16:41:26.786+0000] {taskinstance.py:2778} INFO - 0 downstream tasks scheduled from follow-on schedule check
[2023-12-07T17:00:26.406+0000] {taskinstance.py:1159} INFO - Dependencies all met for dep_context=non-requeueable deps ti=<TaskInstance: my_scraping_dag.main_task scheduled__2023-04-05T00:00:00+00:00 [queued]>
[2023-12-07T17:00:26.410+0000] {taskinstance.py:1159} INFO - Dependencies all met for dep_context=requeueable deps ti=<TaskInstance: my_scraping_dag.main_task scheduled__2023-04-05T00:00:00+00:00 [queued]>
[2023-12-07T17:00:26.410+0000] {taskinstance.py:1361} INFO - Starting attempt 1 of 1
[2023-12-07T17:00:26.416+0000] {taskinstance.py:1382} INFO - Executing <Task(PythonOperator): main_task> on 2023-04-05 00:00:00+00:00
[2023-12-07T17:00:26.418+0000] {standard_task_runner.py:57} INFO - Started process 5779 to run task
[2023-12-07T17:00:26.420+0000] {standard_task_runner.py:84} INFO - Running: ['***', 'tasks', 'run', 'my_scraping_dag', 'main_task', 'scheduled__2023-04-05T00:00:00+00:00', '--job-id', '1369', '--raw', '--subdir', 'DAGS_FOLDER/main.py', '--cfg-path', '/tmp/tmp16y1tile']
[2023-12-07T17:00:26.422+0000] {standard_task_runner.py:85} INFO - Job 1369: Subtask main_task
[2023-12-07T17:00:26.445+0000] {task_command.py:416} INFO - Running <TaskInstance: my_scraping_dag.main_task scheduled__2023-04-05T00:00:00+00:00 [running]> on host 63b0c7e341c0
[2023-12-07T17:00:26.476+0000] {taskinstance.py:1662} INFO - Exporting env vars: AIRFLOW_CTX_DAG_OWNER='***' AIRFLOW_CTX_DAG_ID='my_scraping_dag' AIRFLOW_CTX_TASK_ID='main_task' AIRFLOW_CTX_EXECUTION_DATE='2023-04-05T00:00:00+00:00' AIRFLOW_CTX_TRY_NUMBER='1' AIRFLOW_CTX_DAG_RUN_ID='scheduled__2023-04-05T00:00:00+00:00'
[2023-12-07T17:00:26.493+0000] {taskinstance.py:1937} ERROR - Task failed with exception
Traceback (most recent call last):
  File "/home/airflow/.local/lib/python3.8/site-packages/airflow/operators/python.py", line 192, in execute
    return_value = self.execute_callable()
  File "/home/airflow/.local/lib/python3.8/site-packages/airflow/operators/python.py", line 209, in execute_callable
    return self.python_callable(*self.op_args, **self.op_kwargs)
  File "/opt/airflow/dags/main.py", line 33, in main
    'host': get_config('localhost'),
  File "/opt/airflow/dags/main.py", line 20, in get_config
    return Variable.get(key)
  File "/home/airflow/.local/lib/python3.8/site-packages/airflow/models/variable.py", line 140, in get
    raise KeyError(f"Variable {key} does not exist")
KeyError: 'Variable localhost does not exist'
[2023-12-07T17:00:26.497+0000] {taskinstance.py:1400} INFO - Marking task as FAILED. dag_id=my_scraping_dag, task_id=main_task, execution_date=20230405T000000, start_date=20231207T170026, end_date=20231207T170026
[2023-12-07T17:00:26.502+0000] {standard_task_runner.py:104} ERROR - Failed to execute job 1369 for task main_task ('Variable localhost does not exist'; 5779)
[2023-12-07T17:00:26.512+0000] {local_task_job_runner.py:228} INFO - Task exited with return code 1
[2023-12-07T17:00:26.525+0000] {taskinstance.py:2778} INFO - 0 downstream tasks scheduled from follow-on schedule check
[2023-12-07T17:03:46.942+0000] {taskinstance.py:1159} INFO - Dependencies all met for dep_context=non-requeueable deps ti=<TaskInstance: my_scraping_dag.main_task scheduled__2023-04-05T00:00:00+00:00 [queued]>
[2023-12-07T17:03:46.952+0000] {taskinstance.py:1159} INFO - Dependencies all met for dep_context=requeueable deps ti=<TaskInstance: my_scraping_dag.main_task scheduled__2023-04-05T00:00:00+00:00 [queued]>
[2023-12-07T17:03:46.953+0000] {taskinstance.py:1361} INFO - Starting attempt 1 of 1
[2023-12-07T17:03:46.995+0000] {taskinstance.py:1382} INFO - Executing <Task(PythonOperator): main_task> on 2023-04-05 00:00:00+00:00
[2023-12-07T17:03:47.001+0000] {standard_task_runner.py:57} INFO - Started process 7184 to run task
[2023-12-07T17:03:47.005+0000] {standard_task_runner.py:84} INFO - Running: ['***', 'tasks', 'run', 'my_scraping_dag', 'main_task', 'scheduled__2023-04-05T00:00:00+00:00', '--job-id', '2028', '--raw', '--subdir', 'DAGS_FOLDER/main.py', '--cfg-path', '/tmp/tmpxmlgf0_9']
[2023-12-07T17:03:47.008+0000] {standard_task_runner.py:85} INFO - Job 2028: Subtask main_task
[2023-12-07T17:03:47.042+0000] {task_command.py:416} INFO - Running <TaskInstance: my_scraping_dag.main_task scheduled__2023-04-05T00:00:00+00:00 [running]> on host 63b0c7e341c0
[2023-12-07T17:03:47.105+0000] {taskinstance.py:1662} INFO - Exporting env vars: AIRFLOW_CTX_DAG_OWNER='***' AIRFLOW_CTX_DAG_ID='my_scraping_dag' AIRFLOW_CTX_TASK_ID='main_task' AIRFLOW_CTX_EXECUTION_DATE='2023-04-05T00:00:00+00:00' AIRFLOW_CTX_TRY_NUMBER='1' AIRFLOW_CTX_DAG_RUN_ID='scheduled__2023-04-05T00:00:00+00:00'
[2023-12-07T17:03:47.144+0000] {logging_mixin.py:154} INFO - base_url: https://tuncbotanik.com
[2023-12-07T17:03:47.145+0000] {python.py:194} INFO - Done. Returned value was: ('https://tuncbotanik.com', {'User-Agent': 'Mozilla/5.0 (Macintosh; Intel Mac OS X 10_15_7) AppleWebKit/537.36 (KHTML, like Gecko) Chrome/119.0.0.0 Safari/537.36', 'Accept-Language': 'tr-TR,tr;q=0.9,en-US;q=0.8,en;q=0.7'}, {'dbname': 'plant', 'user': 'aozgokme', 'password': '***', 'host': 'localhost', 'port': '5432'})
[2023-12-07T17:03:47.173+0000] {taskinstance.py:1400} INFO - Marking task as SUCCESS. dag_id=my_scraping_dag, task_id=main_task, execution_date=20230405T000000, start_date=20231207T170346, end_date=20231207T170347
[2023-12-07T17:03:47.258+0000] {local_task_job_runner.py:228} INFO - Task exited with return code 0
[2023-12-07T17:03:47.297+0000] {taskinstance.py:2778} INFO - 0 downstream tasks scheduled from follow-on schedule check
[2023-12-07T17:18:36.484+0000] {taskinstance.py:1159} INFO - Dependencies all met for dep_context=non-requeueable deps ti=<TaskInstance: my_scraping_dag.main_task scheduled__2023-04-05T00:00:00+00:00 [queued]>
[2023-12-07T17:18:36.492+0000] {taskinstance.py:1159} INFO - Dependencies all met for dep_context=requeueable deps ti=<TaskInstance: my_scraping_dag.main_task scheduled__2023-04-05T00:00:00+00:00 [queued]>
[2023-12-07T17:18:36.493+0000] {taskinstance.py:1361} INFO - Starting attempt 1 of 1
[2023-12-07T17:18:36.501+0000] {taskinstance.py:1382} INFO - Executing <Task(PythonOperator): main_task> on 2023-04-05 00:00:00+00:00
[2023-12-07T17:18:36.504+0000] {standard_task_runner.py:57} INFO - Started process 8730 to run task
[2023-12-07T17:18:36.509+0000] {standard_task_runner.py:84} INFO - Running: ['***', 'tasks', 'run', 'my_scraping_dag', 'main_task', 'scheduled__2023-04-05T00:00:00+00:00', '--job-id', '2624', '--raw', '--subdir', 'DAGS_FOLDER/main.py', '--cfg-path', '/tmp/tmpxi5pqwp5']
[2023-12-07T17:18:36.512+0000] {standard_task_runner.py:85} INFO - Job 2624: Subtask main_task
[2023-12-07T17:18:36.541+0000] {task_command.py:416} INFO - Running <TaskInstance: my_scraping_dag.main_task scheduled__2023-04-05T00:00:00+00:00 [running]> on host 63b0c7e341c0
[2023-12-07T17:18:36.581+0000] {taskinstance.py:1662} INFO - Exporting env vars: AIRFLOW_CTX_DAG_OWNER='***' AIRFLOW_CTX_DAG_ID='my_scraping_dag' AIRFLOW_CTX_TASK_ID='main_task' AIRFLOW_CTX_EXECUTION_DATE='2023-04-05T00:00:00+00:00' AIRFLOW_CTX_TRY_NUMBER='1' AIRFLOW_CTX_DAG_RUN_ID='scheduled__2023-04-05T00:00:00+00:00'
[2023-12-07T17:18:37.196+0000] {taskinstance.py:1937} ERROR - Task failed with exception
Traceback (most recent call last):
  File "/home/airflow/.local/lib/python3.8/site-packages/airflow/operators/python.py", line 192, in execute
    return_value = self.execute_callable()
  File "/home/airflow/.local/lib/python3.8/site-packages/airflow/operators/python.py", line 209, in execute_callable
    return self.python_callable(*self.op_args, **self.op_kwargs)
  File "/opt/airflow/dags/main.py", line 80, in main
    insert_data_to_db(products, db_params)
  File "/opt/airflow/dags/main.py", line 43, in insert_data_to_db
    with psycopg2.connect(**db_params) as conn:
  File "/home/airflow/.local/lib/python3.8/site-packages/psycopg2/__init__.py", line 122, in connect
    conn = _connect(dsn, connection_factory=connection_factory, **kwasync)
psycopg2.OperationalError: connection to server at "localhost" (127.0.0.1), port 5432 failed: Connection refused
	Is the server running on that host and accepting TCP/IP connections?
connection to server at "localhost" (::1), port 5432 failed: Cannot assign requested address
	Is the server running on that host and accepting TCP/IP connections?

[2023-12-07T17:18:37.201+0000] {taskinstance.py:1400} INFO - Marking task as FAILED. dag_id=my_scraping_dag, task_id=main_task, execution_date=20230405T000000, start_date=20231207T171836, end_date=20231207T171837
[2023-12-07T17:18:37.205+0000] {standard_task_runner.py:104} ERROR - Failed to execute job 2624 for task main_task (connection to server at "localhost" (127.0.0.1), port 5432 failed: Connection refused
	Is the server running on that host and accepting TCP/IP connections?
connection to server at "localhost" (::1), port 5432 failed: Cannot assign requested address
	Is the server running on that host and accepting TCP/IP connections?
; 8730)
[2023-12-07T17:18:37.251+0000] {local_task_job_runner.py:228} INFO - Task exited with return code 1
[2023-12-07T17:18:37.260+0000] {taskinstance.py:2778} INFO - 0 downstream tasks scheduled from follow-on schedule check
[2023-12-07T17:22:54.618+0000] {taskinstance.py:1159} INFO - Dependencies all met for dep_context=non-requeueable deps ti=<TaskInstance: my_scraping_dag.main_task scheduled__2023-04-05T00:00:00+00:00 [queued]>
[2023-12-07T17:22:54.623+0000] {taskinstance.py:1159} INFO - Dependencies all met for dep_context=requeueable deps ti=<TaskInstance: my_scraping_dag.main_task scheduled__2023-04-05T00:00:00+00:00 [queued]>
[2023-12-07T17:22:54.623+0000] {taskinstance.py:1361} INFO - Starting attempt 1 of 1
[2023-12-07T17:22:54.636+0000] {taskinstance.py:1382} INFO - Executing <Task(PythonOperator): main_task> on 2023-04-05 00:00:00+00:00
[2023-12-07T17:22:54.639+0000] {standard_task_runner.py:57} INFO - Started process 9536 to run task
[2023-12-07T17:22:54.641+0000] {standard_task_runner.py:84} INFO - Running: ['***', 'tasks', 'run', 'my_scraping_dag', 'main_task', 'scheduled__2023-04-05T00:00:00+00:00', '--job-id', '2966', '--raw', '--subdir', 'DAGS_FOLDER/main.py', '--cfg-path', '/tmp/tmpplztip90']
[2023-12-07T17:22:54.643+0000] {standard_task_runner.py:85} INFO - Job 2966: Subtask main_task
[2023-12-07T17:22:54.677+0000] {task_command.py:416} INFO - Running <TaskInstance: my_scraping_dag.main_task scheduled__2023-04-05T00:00:00+00:00 [running]> on host 63b0c7e341c0
[2023-12-07T17:22:54.713+0000] {taskinstance.py:1662} INFO - Exporting env vars: AIRFLOW_CTX_DAG_OWNER='***' AIRFLOW_CTX_DAG_ID='my_scraping_dag' AIRFLOW_CTX_TASK_ID='main_task' AIRFLOW_CTX_EXECUTION_DATE='2023-04-05T00:00:00+00:00' AIRFLOW_CTX_TRY_NUMBER='1' AIRFLOW_CTX_DAG_RUN_ID='scheduled__2023-04-05T00:00:00+00:00'
[2023-12-07T17:22:55.397+0000] {taskinstance.py:1937} ERROR - Task failed with exception
Traceback (most recent call last):
  File "/home/airflow/.local/lib/python3.8/site-packages/airflow/operators/python.py", line 192, in execute
    return_value = self.execute_callable()
  File "/home/airflow/.local/lib/python3.8/site-packages/airflow/operators/python.py", line 209, in execute_callable
    return self.python_callable(*self.op_args, **self.op_kwargs)
  File "/opt/airflow/dags/main.py", line 73, in main
    insert_data_to_db(products, db_params)
  File "/opt/airflow/dags/main.py", line 40, in insert_data_to_db
    with psycopg2.connect(**db_params) as conn:
  File "/home/airflow/.local/lib/python3.8/site-packages/psycopg2/__init__.py", line 122, in connect
    conn = _connect(dsn, connection_factory=connection_factory, **kwasync)
psycopg2.OperationalError: connection to server at "localhost" (127.0.0.1), port 5432 failed: Connection refused
	Is the server running on that host and accepting TCP/IP connections?
connection to server at "localhost" (::1), port 5432 failed: Cannot assign requested address
	Is the server running on that host and accepting TCP/IP connections?

[2023-12-07T17:22:55.401+0000] {taskinstance.py:1400} INFO - Marking task as FAILED. dag_id=my_scraping_dag, task_id=main_task, execution_date=20230405T000000, start_date=20231207T172254, end_date=20231207T172255
[2023-12-07T17:22:55.405+0000] {standard_task_runner.py:104} ERROR - Failed to execute job 2966 for task main_task (connection to server at "localhost" (127.0.0.1), port 5432 failed: Connection refused
	Is the server running on that host and accepting TCP/IP connections?
connection to server at "localhost" (::1), port 5432 failed: Cannot assign requested address
	Is the server running on that host and accepting TCP/IP connections?
; 9536)
[2023-12-07T17:22:55.424+0000] {local_task_job_runner.py:228} INFO - Task exited with return code 1
[2023-12-07T17:22:55.431+0000] {taskinstance.py:2778} INFO - 0 downstream tasks scheduled from follow-on schedule check
[2023-12-07T17:28:36.721+0000] {taskinstance.py:1159} INFO - Dependencies all met for dep_context=non-requeueable deps ti=<TaskInstance: my_scraping_dag.main_task scheduled__2023-04-05T00:00:00+00:00 [queued]>
[2023-12-07T17:28:36.727+0000] {taskinstance.py:1159} INFO - Dependencies all met for dep_context=requeueable deps ti=<TaskInstance: my_scraping_dag.main_task scheduled__2023-04-05T00:00:00+00:00 [queued]>
[2023-12-07T17:28:36.727+0000] {taskinstance.py:1361} INFO - Starting attempt 1 of 1
[2023-12-07T17:28:36.734+0000] {taskinstance.py:1382} INFO - Executing <Task(PythonOperator): main_task> on 2023-04-05 00:00:00+00:00
[2023-12-07T17:28:36.738+0000] {standard_task_runner.py:57} INFO - Started process 10367 to run task
[2023-12-07T17:28:36.755+0000] {standard_task_runner.py:84} INFO - Running: ['***', 'tasks', 'run', 'my_scraping_dag', 'main_task', 'scheduled__2023-04-05T00:00:00+00:00', '--job-id', '3308', '--raw', '--subdir', 'DAGS_FOLDER/main.py', '--cfg-path', '/tmp/tmplow451cg']
[2023-12-07T17:28:36.758+0000] {standard_task_runner.py:85} INFO - Job 3308: Subtask main_task
[2023-12-07T17:28:36.800+0000] {task_command.py:416} INFO - Running <TaskInstance: my_scraping_dag.main_task scheduled__2023-04-05T00:00:00+00:00 [running]> on host 63b0c7e341c0
[2023-12-07T17:28:36.846+0000] {taskinstance.py:1662} INFO - Exporting env vars: AIRFLOW_CTX_DAG_OWNER='***' AIRFLOW_CTX_DAG_ID='my_scraping_dag' AIRFLOW_CTX_TASK_ID='main_task' AIRFLOW_CTX_EXECUTION_DATE='2023-04-05T00:00:00+00:00' AIRFLOW_CTX_TRY_NUMBER='1' AIRFLOW_CTX_DAG_RUN_ID='scheduled__2023-04-05T00:00:00+00:00'
[2023-12-07T17:28:37.477+0000] {taskinstance.py:1937} ERROR - Task failed with exception
Traceback (most recent call last):
  File "/home/airflow/.local/lib/python3.8/site-packages/airflow/operators/python.py", line 192, in execute
    return_value = self.execute_callable()
  File "/home/airflow/.local/lib/python3.8/site-packages/airflow/operators/python.py", line 209, in execute_callable
    return self.python_callable(*self.op_args, **self.op_kwargs)
  File "/opt/airflow/dags/main.py", line 73, in main
    insert_data_to_db(products, db_params)
  File "/opt/airflow/dags/main.py", line 40, in insert_data_to_db
    with psycopg2.connect(**db_params) as conn:
  File "/home/airflow/.local/lib/python3.8/site-packages/psycopg2/__init__.py", line 122, in connect
    conn = _connect(dsn, connection_factory=connection_factory, **kwasync)
psycopg2.OperationalError: connection to server at "localhost" (127.0.0.1), port 5432 failed: Connection refused
	Is the server running on that host and accepting TCP/IP connections?
connection to server at "localhost" (::1), port 5432 failed: Cannot assign requested address
	Is the server running on that host and accepting TCP/IP connections?

[2023-12-07T17:28:37.481+0000] {taskinstance.py:1400} INFO - Marking task as FAILED. dag_id=my_scraping_dag, task_id=main_task, execution_date=20230405T000000, start_date=20231207T172836, end_date=20231207T172837
[2023-12-07T17:28:37.486+0000] {standard_task_runner.py:104} ERROR - Failed to execute job 3308 for task main_task (connection to server at "localhost" (127.0.0.1), port 5432 failed: Connection refused
	Is the server running on that host and accepting TCP/IP connections?
connection to server at "localhost" (::1), port 5432 failed: Cannot assign requested address
	Is the server running on that host and accepting TCP/IP connections?
; 10367)
[2023-12-07T17:28:37.520+0000] {local_task_job_runner.py:228} INFO - Task exited with return code 1
[2023-12-07T17:28:37.528+0000] {taskinstance.py:2778} INFO - 0 downstream tasks scheduled from follow-on schedule check
