[2023-12-07T14:52:45.998+0000] {taskinstance.py:1159} INFO - Dependencies all met for dep_context=non-requeueable deps ti=<TaskInstance: my_scraping_dag.main_task scheduled__2023-06-08T00:00:00+00:00 [queued]>
[2023-12-07T14:52:46.002+0000] {taskinstance.py:1159} INFO - Dependencies all met for dep_context=requeueable deps ti=<TaskInstance: my_scraping_dag.main_task scheduled__2023-06-08T00:00:00+00:00 [queued]>
[2023-12-07T14:52:46.003+0000] {taskinstance.py:1361} INFO - Starting attempt 1 of 1
[2023-12-07T14:52:46.010+0000] {taskinstance.py:1382} INFO - Executing <Task(PythonOperator): main_task> on 2023-06-08 00:00:00+00:00
[2023-12-07T14:52:46.013+0000] {standard_task_runner.py:57} INFO - Started process 1090 to run task
[2023-12-07T14:52:46.015+0000] {standard_task_runner.py:84} INFO - Running: ['***', 'tasks', 'run', 'my_scraping_dag', 'main_task', 'scheduled__2023-06-08T00:00:00+00:00', '--job-id', '269', '--raw', '--subdir', 'DAGS_FOLDER/main.py', '--cfg-path', '/tmp/tmpi4xjdc15']
[2023-12-07T14:52:46.017+0000] {standard_task_runner.py:85} INFO - Job 269: Subtask main_task
[2023-12-07T14:52:46.042+0000] {task_command.py:416} INFO - Running <TaskInstance: my_scraping_dag.main_task scheduled__2023-06-08T00:00:00+00:00 [running]> on host 63b0c7e341c0
[2023-12-07T14:52:46.081+0000] {taskinstance.py:1662} INFO - Exporting env vars: AIRFLOW_CTX_DAG_OWNER='***' AIRFLOW_CTX_DAG_ID='my_scraping_dag' AIRFLOW_CTX_TASK_ID='main_task' AIRFLOW_CTX_EXECUTION_DATE='2023-06-08T00:00:00+00:00' AIRFLOW_CTX_TRY_NUMBER='1' AIRFLOW_CTX_DAG_RUN_ID='scheduled__2023-06-08T00:00:00+00:00'
[2023-12-07T14:52:46.082+0000] {taskinstance.py:1937} ERROR - Task failed with exception
Traceback (most recent call last):
  File "/usr/local/lib/python3.8/configparser.py", line 846, in items
    d.update(self._sections[section])
KeyError: 'web'

During handling of the above exception, another exception occurred:

Traceback (most recent call last):
  File "/home/airflow/.local/lib/python3.8/site-packages/airflow/operators/python.py", line 192, in execute
    return_value = self.execute_callable()
  File "/home/airflow/.local/lib/python3.8/site-packages/airflow/operators/python.py", line 209, in execute_callable
    return self.python_callable(*self.op_args, **self.op_kwargs)
  File "/opt/airflow/dags/main.py", line 61, in main
    config = get_config('web')
  File "/opt/airflow/dags/main.py", line 23, in get_config
    return {key: value for key, value in parser.items(section)}
  File "/usr/local/lib/python3.8/configparser.py", line 849, in items
    raise NoSectionError(section)
configparser.NoSectionError: No section: 'web'
[2023-12-07T14:52:46.086+0000] {taskinstance.py:1400} INFO - Marking task as FAILED. dag_id=my_scraping_dag, task_id=main_task, execution_date=20230608T000000, start_date=20231207T145245, end_date=20231207T145246
[2023-12-07T14:52:46.091+0000] {standard_task_runner.py:104} ERROR - Failed to execute job 269 for task main_task (No section: 'web'; 1090)
[2023-12-07T14:52:46.108+0000] {local_task_job_runner.py:228} INFO - Task exited with return code 1
[2023-12-07T14:52:46.120+0000] {taskinstance.py:2778} INFO - 0 downstream tasks scheduled from follow-on schedule check
[2023-12-07T16:32:35.101+0000] {taskinstance.py:1159} INFO - Dependencies all met for dep_context=non-requeueable deps ti=<TaskInstance: my_scraping_dag.main_task scheduled__2023-06-08T00:00:00+00:00 [queued]>
[2023-12-07T16:32:35.104+0000] {taskinstance.py:1159} INFO - Dependencies all met for dep_context=requeueable deps ti=<TaskInstance: my_scraping_dag.main_task scheduled__2023-06-08T00:00:00+00:00 [queued]>
[2023-12-07T16:32:35.105+0000] {taskinstance.py:1361} INFO - Starting attempt 1 of 1
[2023-12-07T16:32:35.110+0000] {taskinstance.py:1382} INFO - Executing <Task(PythonOperator): main_task> on 2023-06-08 00:00:00+00:00
[2023-12-07T16:32:35.112+0000] {standard_task_runner.py:57} INFO - Started process 3861 to run task
[2023-12-07T16:32:35.114+0000] {standard_task_runner.py:84} INFO - Running: ['***', 'tasks', 'run', 'my_scraping_dag', 'main_task', 'scheduled__2023-06-08T00:00:00+00:00', '--job-id', '747', '--raw', '--subdir', 'DAGS_FOLDER/main.py', '--cfg-path', '/tmp/tmp4drce1_6']
[2023-12-07T16:32:35.115+0000] {standard_task_runner.py:85} INFO - Job 747: Subtask main_task
[2023-12-07T16:32:35.135+0000] {task_command.py:416} INFO - Running <TaskInstance: my_scraping_dag.main_task scheduled__2023-06-08T00:00:00+00:00 [running]> on host 63b0c7e341c0
[2023-12-07T16:32:35.165+0000] {taskinstance.py:1662} INFO - Exporting env vars: AIRFLOW_CTX_DAG_OWNER='***' AIRFLOW_CTX_DAG_ID='my_scraping_dag' AIRFLOW_CTX_TASK_ID='main_task' AIRFLOW_CTX_EXECUTION_DATE='2023-06-08T00:00:00+00:00' AIRFLOW_CTX_TRY_NUMBER='1' AIRFLOW_CTX_DAG_RUN_ID='scheduled__2023-06-08T00:00:00+00:00'
[2023-12-07T16:32:35.166+0000] {taskinstance.py:1937} ERROR - Task failed with exception
Traceback (most recent call last):
  File "/usr/local/lib/python3.8/configparser.py", line 846, in items
    d.update(self._sections[section])
KeyError: 'web'

During handling of the above exception, another exception occurred:

Traceback (most recent call last):
  File "/home/airflow/.local/lib/python3.8/site-packages/airflow/operators/python.py", line 192, in execute
    return_value = self.execute_callable()
  File "/home/airflow/.local/lib/python3.8/site-packages/airflow/operators/python.py", line 209, in execute_callable
    return self.python_callable(*self.op_args, **self.op_kwargs)
  File "/opt/airflow/dags/main.py", line 60, in main
    config = get_config('web')
  File "/opt/airflow/dags/main.py", line 22, in get_config
    return {key: value for key, value in parser.items(section)}
  File "/usr/local/lib/python3.8/configparser.py", line 849, in items
    raise NoSectionError(section)
configparser.NoSectionError: No section: 'web'
[2023-12-07T16:32:35.170+0000] {taskinstance.py:1400} INFO - Marking task as FAILED. dag_id=my_scraping_dag, task_id=main_task, execution_date=20230608T000000, start_date=20231207T163235, end_date=20231207T163235
[2023-12-07T16:32:35.174+0000] {standard_task_runner.py:104} ERROR - Failed to execute job 747 for task main_task (No section: 'web'; 3861)
[2023-12-07T16:32:35.206+0000] {local_task_job_runner.py:228} INFO - Task exited with return code 1
[2023-12-07T16:32:35.217+0000] {taskinstance.py:2778} INFO - 0 downstream tasks scheduled from follow-on schedule check
[2023-12-07T16:41:51.273+0000] {taskinstance.py:1159} INFO - Dependencies all met for dep_context=non-requeueable deps ti=<TaskInstance: my_scraping_dag.main_task scheduled__2023-06-08T00:00:00+00:00 [queued]>
[2023-12-07T16:41:51.277+0000] {taskinstance.py:1159} INFO - Dependencies all met for dep_context=requeueable deps ti=<TaskInstance: my_scraping_dag.main_task scheduled__2023-06-08T00:00:00+00:00 [queued]>
[2023-12-07T16:41:51.277+0000] {taskinstance.py:1361} INFO - Starting attempt 1 of 1
[2023-12-07T16:41:51.282+0000] {taskinstance.py:1382} INFO - Executing <Task(PythonOperator): main_task> on 2023-06-08 00:00:00+00:00
[2023-12-07T16:41:51.284+0000] {standard_task_runner.py:57} INFO - Started process 4773 to run task
[2023-12-07T16:41:51.286+0000] {standard_task_runner.py:84} INFO - Running: ['***', 'tasks', 'run', 'my_scraping_dag', 'main_task', 'scheduled__2023-06-08T00:00:00+00:00', '--job-id', '1092', '--raw', '--subdir', 'DAGS_FOLDER/main.py', '--cfg-path', '/tmp/tmp4_1yvtuj']
[2023-12-07T16:41:51.288+0000] {standard_task_runner.py:85} INFO - Job 1092: Subtask main_task
[2023-12-07T16:41:51.310+0000] {task_command.py:416} INFO - Running <TaskInstance: my_scraping_dag.main_task scheduled__2023-06-08T00:00:00+00:00 [running]> on host 63b0c7e341c0
[2023-12-07T16:41:51.339+0000] {taskinstance.py:1662} INFO - Exporting env vars: AIRFLOW_CTX_DAG_OWNER='***' AIRFLOW_CTX_DAG_ID='my_scraping_dag' AIRFLOW_CTX_TASK_ID='main_task' AIRFLOW_CTX_EXECUTION_DATE='2023-06-08T00:00:00+00:00' AIRFLOW_CTX_TRY_NUMBER='1' AIRFLOW_CTX_DAG_RUN_ID='scheduled__2023-06-08T00:00:00+00:00'
[2023-12-07T16:41:51.340+0000] {taskinstance.py:1937} ERROR - Task failed with exception
Traceback (most recent call last):
  File "/usr/local/lib/python3.8/configparser.py", line 846, in items
    d.update(self._sections[section])
KeyError: 'web'

During handling of the above exception, another exception occurred:

Traceback (most recent call last):
  File "/home/airflow/.local/lib/python3.8/site-packages/airflow/operators/python.py", line 192, in execute
    return_value = self.execute_callable()
  File "/home/airflow/.local/lib/python3.8/site-packages/airflow/operators/python.py", line 209, in execute_callable
    return self.python_callable(*self.op_args, **self.op_kwargs)
  File "/opt/airflow/dags/main.py", line 60, in main
    config = get_config('web')
  File "/opt/airflow/dags/main.py", line 22, in get_config
    return {key: value for key, value in parser.items(section)}
  File "/usr/local/lib/python3.8/configparser.py", line 849, in items
    raise NoSectionError(section)
configparser.NoSectionError: No section: 'web'
[2023-12-07T16:41:51.344+0000] {taskinstance.py:1400} INFO - Marking task as FAILED. dag_id=my_scraping_dag, task_id=main_task, execution_date=20230608T000000, start_date=20231207T164151, end_date=20231207T164151
[2023-12-07T16:41:51.348+0000] {standard_task_runner.py:104} ERROR - Failed to execute job 1092 for task main_task (No section: 'web'; 4773)
[2023-12-07T16:41:51.382+0000] {local_task_job_runner.py:228} INFO - Task exited with return code 1
[2023-12-07T16:41:51.395+0000] {taskinstance.py:2778} INFO - 0 downstream tasks scheduled from follow-on schedule check
[2023-12-07T17:00:52.099+0000] {taskinstance.py:1159} INFO - Dependencies all met for dep_context=non-requeueable deps ti=<TaskInstance: my_scraping_dag.main_task scheduled__2023-06-08T00:00:00+00:00 [queued]>
[2023-12-07T17:00:52.104+0000] {taskinstance.py:1159} INFO - Dependencies all met for dep_context=requeueable deps ti=<TaskInstance: my_scraping_dag.main_task scheduled__2023-06-08T00:00:00+00:00 [queued]>
[2023-12-07T17:00:52.105+0000] {taskinstance.py:1361} INFO - Starting attempt 1 of 1
[2023-12-07T17:00:52.123+0000] {taskinstance.py:1382} INFO - Executing <Task(PythonOperator): main_task> on 2023-06-08 00:00:00+00:00
[2023-12-07T17:00:52.127+0000] {standard_task_runner.py:57} INFO - Started process 5998 to run task
[2023-12-07T17:00:52.131+0000] {standard_task_runner.py:84} INFO - Running: ['***', 'tasks', 'run', 'my_scraping_dag', 'main_task', 'scheduled__2023-06-08T00:00:00+00:00', '--job-id', '1472', '--raw', '--subdir', 'DAGS_FOLDER/main.py', '--cfg-path', '/tmp/tmp8ctbjtht']
[2023-12-07T17:00:52.137+0000] {standard_task_runner.py:85} INFO - Job 1472: Subtask main_task
[2023-12-07T17:00:52.191+0000] {task_command.py:416} INFO - Running <TaskInstance: my_scraping_dag.main_task scheduled__2023-06-08T00:00:00+00:00 [running]> on host 63b0c7e341c0
[2023-12-07T17:00:52.273+0000] {taskinstance.py:1662} INFO - Exporting env vars: AIRFLOW_CTX_DAG_OWNER='***' AIRFLOW_CTX_DAG_ID='my_scraping_dag' AIRFLOW_CTX_TASK_ID='main_task' AIRFLOW_CTX_EXECUTION_DATE='2023-06-08T00:00:00+00:00' AIRFLOW_CTX_TRY_NUMBER='1' AIRFLOW_CTX_DAG_RUN_ID='scheduled__2023-06-08T00:00:00+00:00'
[2023-12-07T17:00:52.321+0000] {logging_mixin.py:154} INFO - base_url: https://tuncbotanik.com
[2023-12-07T17:00:52.323+0000] {python.py:194} INFO - Done. Returned value was: ('https://tuncbotanik.com', {'User-Agent': 'Mozilla/5.0 (Macintosh; Intel Mac OS X 10_15_7) AppleWebKit/537.36 (KHTML, like Gecko) Chrome/119.0.0.0 Safari/537.36', 'Accept-Language': 'tr-TR,tr;q=0.9,en-US;q=0.8,en;q=0.7'}, {'dbname': 'plant', 'user': 'aozgokme', 'password': '***', 'host': 'localhost', 'port': '5432'})
[2023-12-07T17:00:52.344+0000] {taskinstance.py:1400} INFO - Marking task as SUCCESS. dag_id=my_scraping_dag, task_id=main_task, execution_date=20230608T000000, start_date=20231207T170052, end_date=20231207T170052
[2023-12-07T17:00:52.390+0000] {local_task_job_runner.py:228} INFO - Task exited with return code 0
[2023-12-07T17:00:52.424+0000] {taskinstance.py:2778} INFO - 0 downstream tasks scheduled from follow-on schedule check
[2023-12-07T17:04:07.444+0000] {taskinstance.py:1159} INFO - Dependencies all met for dep_context=non-requeueable deps ti=<TaskInstance: my_scraping_dag.main_task scheduled__2023-06-08T00:00:00+00:00 [queued]>
[2023-12-07T17:04:07.448+0000] {taskinstance.py:1159} INFO - Dependencies all met for dep_context=requeueable deps ti=<TaskInstance: my_scraping_dag.main_task scheduled__2023-06-08T00:00:00+00:00 [queued]>
[2023-12-07T17:04:07.448+0000] {taskinstance.py:1361} INFO - Starting attempt 1 of 1
[2023-12-07T17:04:07.457+0000] {taskinstance.py:1382} INFO - Executing <Task(PythonOperator): main_task> on 2023-06-08 00:00:00+00:00
[2023-12-07T17:04:07.460+0000] {standard_task_runner.py:57} INFO - Started process 7453 to run task
[2023-12-07T17:04:07.463+0000] {standard_task_runner.py:84} INFO - Running: ['***', 'tasks', 'run', 'my_scraping_dag', 'main_task', 'scheduled__2023-06-08T00:00:00+00:00', '--job-id', '2157', '--raw', '--subdir', 'DAGS_FOLDER/main.py', '--cfg-path', '/tmp/tmp3yd84n_e']
[2023-12-07T17:04:07.464+0000] {standard_task_runner.py:85} INFO - Job 2157: Subtask main_task
[2023-12-07T17:04:07.491+0000] {task_command.py:416} INFO - Running <TaskInstance: my_scraping_dag.main_task scheduled__2023-06-08T00:00:00+00:00 [running]> on host 63b0c7e341c0
[2023-12-07T17:04:07.534+0000] {taskinstance.py:1662} INFO - Exporting env vars: AIRFLOW_CTX_DAG_OWNER='***' AIRFLOW_CTX_DAG_ID='my_scraping_dag' AIRFLOW_CTX_TASK_ID='main_task' AIRFLOW_CTX_EXECUTION_DATE='2023-06-08T00:00:00+00:00' AIRFLOW_CTX_TRY_NUMBER='1' AIRFLOW_CTX_DAG_RUN_ID='scheduled__2023-06-08T00:00:00+00:00'
[2023-12-07T17:04:07.559+0000] {logging_mixin.py:154} INFO - base_url: https://tuncbotanik.com
[2023-12-07T17:04:07.559+0000] {python.py:194} INFO - Done. Returned value was: ('https://tuncbotanik.com', {'User-Agent': 'Mozilla/5.0 (Macintosh; Intel Mac OS X 10_15_7) AppleWebKit/537.36 (KHTML, like Gecko) Chrome/119.0.0.0 Safari/537.36', 'Accept-Language': 'tr-TR,tr;q=0.9,en-US;q=0.8,en;q=0.7'}, {'dbname': 'plant', 'user': 'aozgokme', 'password': '***', 'host': 'localhost', 'port': '5432'})
[2023-12-07T17:04:07.574+0000] {taskinstance.py:1400} INFO - Marking task as SUCCESS. dag_id=my_scraping_dag, task_id=main_task, execution_date=20230608T000000, start_date=20231207T170407, end_date=20231207T170407
[2023-12-07T17:04:07.594+0000] {local_task_job_runner.py:228} INFO - Task exited with return code 0
[2023-12-07T17:04:07.649+0000] {taskinstance.py:2778} INFO - 0 downstream tasks scheduled from follow-on schedule check
[2023-12-07T17:18:50.749+0000] {taskinstance.py:1159} INFO - Dependencies all met for dep_context=non-requeueable deps ti=<TaskInstance: my_scraping_dag.main_task scheduled__2023-06-08T00:00:00+00:00 [queued]>
[2023-12-07T17:18:50.754+0000] {taskinstance.py:1159} INFO - Dependencies all met for dep_context=requeueable deps ti=<TaskInstance: my_scraping_dag.main_task scheduled__2023-06-08T00:00:00+00:00 [queued]>
[2023-12-07T17:18:50.755+0000] {taskinstance.py:1361} INFO - Starting attempt 1 of 1
[2023-12-07T17:18:50.765+0000] {taskinstance.py:1382} INFO - Executing <Task(PythonOperator): main_task> on 2023-06-08 00:00:00+00:00
[2023-12-07T17:18:50.769+0000] {standard_task_runner.py:57} INFO - Started process 8872 to run task
[2023-12-07T17:18:50.773+0000] {standard_task_runner.py:84} INFO - Running: ['***', 'tasks', 'run', 'my_scraping_dag', 'main_task', 'scheduled__2023-06-08T00:00:00+00:00', '--job-id', '2688', '--raw', '--subdir', 'DAGS_FOLDER/main.py', '--cfg-path', '/tmp/tmpji8djyy6']
[2023-12-07T17:18:50.775+0000] {standard_task_runner.py:85} INFO - Job 2688: Subtask main_task
[2023-12-07T17:18:50.811+0000] {task_command.py:416} INFO - Running <TaskInstance: my_scraping_dag.main_task scheduled__2023-06-08T00:00:00+00:00 [running]> on host 63b0c7e341c0
[2023-12-07T17:18:50.860+0000] {taskinstance.py:1662} INFO - Exporting env vars: AIRFLOW_CTX_DAG_OWNER='***' AIRFLOW_CTX_DAG_ID='my_scraping_dag' AIRFLOW_CTX_TASK_ID='main_task' AIRFLOW_CTX_EXECUTION_DATE='2023-06-08T00:00:00+00:00' AIRFLOW_CTX_TRY_NUMBER='1' AIRFLOW_CTX_DAG_RUN_ID='scheduled__2023-06-08T00:00:00+00:00'
[2023-12-07T17:18:51.824+0000] {taskinstance.py:1937} ERROR - Task failed with exception
Traceback (most recent call last):
  File "/home/airflow/.local/lib/python3.8/site-packages/airflow/operators/python.py", line 192, in execute
    return_value = self.execute_callable()
  File "/home/airflow/.local/lib/python3.8/site-packages/airflow/operators/python.py", line 209, in execute_callable
    return self.python_callable(*self.op_args, **self.op_kwargs)
  File "/opt/airflow/dags/main.py", line 80, in main
    insert_data_to_db(products, db_params)
  File "/opt/airflow/dags/main.py", line 43, in insert_data_to_db
    with psycopg2.connect(**db_params) as conn:
  File "/home/airflow/.local/lib/python3.8/site-packages/psycopg2/__init__.py", line 122, in connect
    conn = _connect(dsn, connection_factory=connection_factory, **kwasync)
psycopg2.OperationalError: connection to server at "localhost" (127.0.0.1), port 5432 failed: Connection refused
	Is the server running on that host and accepting TCP/IP connections?
connection to server at "localhost" (::1), port 5432 failed: Cannot assign requested address
	Is the server running on that host and accepting TCP/IP connections?

[2023-12-07T17:18:51.881+0000] {taskinstance.py:1400} INFO - Marking task as FAILED. dag_id=my_scraping_dag, task_id=main_task, execution_date=20230608T000000, start_date=20231207T171850, end_date=20231207T171851
[2023-12-07T17:18:51.897+0000] {standard_task_runner.py:104} ERROR - Failed to execute job 2688 for task main_task (connection to server at "localhost" (127.0.0.1), port 5432 failed: Connection refused
	Is the server running on that host and accepting TCP/IP connections?
connection to server at "localhost" (::1), port 5432 failed: Cannot assign requested address
	Is the server running on that host and accepting TCP/IP connections?
; 8872)
[2023-12-07T17:18:51.952+0000] {local_task_job_runner.py:228} INFO - Task exited with return code 1
[2023-12-07T17:18:51.986+0000] {taskinstance.py:2778} INFO - 0 downstream tasks scheduled from follow-on schedule check
[2023-12-07T17:23:07.354+0000] {taskinstance.py:1159} INFO - Dependencies all met for dep_context=non-requeueable deps ti=<TaskInstance: my_scraping_dag.main_task scheduled__2023-06-08T00:00:00+00:00 [queued]>
[2023-12-07T17:23:07.360+0000] {taskinstance.py:1159} INFO - Dependencies all met for dep_context=requeueable deps ti=<TaskInstance: my_scraping_dag.main_task scheduled__2023-06-08T00:00:00+00:00 [queued]>
[2023-12-07T17:23:07.360+0000] {taskinstance.py:1361} INFO - Starting attempt 1 of 1
[2023-12-07T17:23:07.368+0000] {taskinstance.py:1382} INFO - Executing <Task(PythonOperator): main_task> on 2023-06-08 00:00:00+00:00
[2023-12-07T17:23:07.372+0000] {standard_task_runner.py:57} INFO - Started process 9664 to run task
[2023-12-07T17:23:07.374+0000] {standard_task_runner.py:84} INFO - Running: ['***', 'tasks', 'run', 'my_scraping_dag', 'main_task', 'scheduled__2023-06-08T00:00:00+00:00', '--job-id', '3030', '--raw', '--subdir', 'DAGS_FOLDER/main.py', '--cfg-path', '/tmp/tmpcr29497r']
[2023-12-07T17:23:07.376+0000] {standard_task_runner.py:85} INFO - Job 3030: Subtask main_task
[2023-12-07T17:23:07.416+0000] {task_command.py:416} INFO - Running <TaskInstance: my_scraping_dag.main_task scheduled__2023-06-08T00:00:00+00:00 [running]> on host 63b0c7e341c0
[2023-12-07T17:23:07.470+0000] {taskinstance.py:1662} INFO - Exporting env vars: AIRFLOW_CTX_DAG_OWNER='***' AIRFLOW_CTX_DAG_ID='my_scraping_dag' AIRFLOW_CTX_TASK_ID='main_task' AIRFLOW_CTX_EXECUTION_DATE='2023-06-08T00:00:00+00:00' AIRFLOW_CTX_TRY_NUMBER='1' AIRFLOW_CTX_DAG_RUN_ID='scheduled__2023-06-08T00:00:00+00:00'
[2023-12-07T17:23:08.093+0000] {taskinstance.py:1937} ERROR - Task failed with exception
Traceback (most recent call last):
  File "/home/airflow/.local/lib/python3.8/site-packages/airflow/operators/python.py", line 192, in execute
    return_value = self.execute_callable()
  File "/home/airflow/.local/lib/python3.8/site-packages/airflow/operators/python.py", line 209, in execute_callable
    return self.python_callable(*self.op_args, **self.op_kwargs)
  File "/opt/airflow/dags/main.py", line 73, in main
    insert_data_to_db(products, db_params)
  File "/opt/airflow/dags/main.py", line 40, in insert_data_to_db
    with psycopg2.connect(**db_params) as conn:
  File "/home/airflow/.local/lib/python3.8/site-packages/psycopg2/__init__.py", line 122, in connect
    conn = _connect(dsn, connection_factory=connection_factory, **kwasync)
psycopg2.OperationalError: connection to server at "localhost" (127.0.0.1), port 5432 failed: Connection refused
	Is the server running on that host and accepting TCP/IP connections?
connection to server at "localhost" (::1), port 5432 failed: Cannot assign requested address
	Is the server running on that host and accepting TCP/IP connections?

[2023-12-07T17:23:08.098+0000] {taskinstance.py:1400} INFO - Marking task as FAILED. dag_id=my_scraping_dag, task_id=main_task, execution_date=20230608T000000, start_date=20231207T172307, end_date=20231207T172308
[2023-12-07T17:23:08.102+0000] {standard_task_runner.py:104} ERROR - Failed to execute job 3030 for task main_task (connection to server at "localhost" (127.0.0.1), port 5432 failed: Connection refused
	Is the server running on that host and accepting TCP/IP connections?
connection to server at "localhost" (::1), port 5432 failed: Cannot assign requested address
	Is the server running on that host and accepting TCP/IP connections?
; 9664)
[2023-12-07T17:23:08.113+0000] {local_task_job_runner.py:228} INFO - Task exited with return code 1
[2023-12-07T17:23:08.121+0000] {taskinstance.py:2778} INFO - 0 downstream tasks scheduled from follow-on schedule check
[2023-12-07T17:28:49.695+0000] {taskinstance.py:1159} INFO - Dependencies all met for dep_context=non-requeueable deps ti=<TaskInstance: my_scraping_dag.main_task scheduled__2023-06-08T00:00:00+00:00 [queued]>
[2023-12-07T17:28:49.700+0000] {taskinstance.py:1159} INFO - Dependencies all met for dep_context=requeueable deps ti=<TaskInstance: my_scraping_dag.main_task scheduled__2023-06-08T00:00:00+00:00 [queued]>
[2023-12-07T17:28:49.701+0000] {taskinstance.py:1361} INFO - Starting attempt 1 of 1
[2023-12-07T17:28:49.714+0000] {taskinstance.py:1382} INFO - Executing <Task(PythonOperator): main_task> on 2023-06-08 00:00:00+00:00
[2023-12-07T17:28:49.721+0000] {standard_task_runner.py:57} INFO - Started process 10500 to run task
[2023-12-07T17:28:49.728+0000] {standard_task_runner.py:84} INFO - Running: ['***', 'tasks', 'run', 'my_scraping_dag', 'main_task', 'scheduled__2023-06-08T00:00:00+00:00', '--job-id', '3372', '--raw', '--subdir', 'DAGS_FOLDER/main.py', '--cfg-path', '/tmp/tmpz85v9snk']
[2023-12-07T17:28:49.730+0000] {standard_task_runner.py:85} INFO - Job 3372: Subtask main_task
[2023-12-07T17:28:49.786+0000] {task_command.py:416} INFO - Running <TaskInstance: my_scraping_dag.main_task scheduled__2023-06-08T00:00:00+00:00 [running]> on host 63b0c7e341c0
[2023-12-07T17:28:49.854+0000] {taskinstance.py:1662} INFO - Exporting env vars: AIRFLOW_CTX_DAG_OWNER='***' AIRFLOW_CTX_DAG_ID='my_scraping_dag' AIRFLOW_CTX_TASK_ID='main_task' AIRFLOW_CTX_EXECUTION_DATE='2023-06-08T00:00:00+00:00' AIRFLOW_CTX_TRY_NUMBER='1' AIRFLOW_CTX_DAG_RUN_ID='scheduled__2023-06-08T00:00:00+00:00'
[2023-12-07T17:28:50.480+0000] {taskinstance.py:1937} ERROR - Task failed with exception
Traceback (most recent call last):
  File "/home/airflow/.local/lib/python3.8/site-packages/airflow/operators/python.py", line 192, in execute
    return_value = self.execute_callable()
  File "/home/airflow/.local/lib/python3.8/site-packages/airflow/operators/python.py", line 209, in execute_callable
    return self.python_callable(*self.op_args, **self.op_kwargs)
  File "/opt/airflow/dags/main.py", line 73, in main
    insert_data_to_db(products, db_params)
  File "/opt/airflow/dags/main.py", line 40, in insert_data_to_db
    with psycopg2.connect(**db_params) as conn:
  File "/home/airflow/.local/lib/python3.8/site-packages/psycopg2/__init__.py", line 122, in connect
    conn = _connect(dsn, connection_factory=connection_factory, **kwasync)
psycopg2.OperationalError: connection to server at "localhost" (127.0.0.1), port 5432 failed: Connection refused
	Is the server running on that host and accepting TCP/IP connections?
connection to server at "localhost" (::1), port 5432 failed: Cannot assign requested address
	Is the server running on that host and accepting TCP/IP connections?

[2023-12-07T17:28:50.484+0000] {taskinstance.py:1400} INFO - Marking task as FAILED. dag_id=my_scraping_dag, task_id=main_task, execution_date=20230608T000000, start_date=20231207T172849, end_date=20231207T172850
[2023-12-07T17:28:50.489+0000] {standard_task_runner.py:104} ERROR - Failed to execute job 3372 for task main_task (connection to server at "localhost" (127.0.0.1), port 5432 failed: Connection refused
	Is the server running on that host and accepting TCP/IP connections?
connection to server at "localhost" (::1), port 5432 failed: Cannot assign requested address
	Is the server running on that host and accepting TCP/IP connections?
; 10500)
[2023-12-07T17:28:50.501+0000] {local_task_job_runner.py:228} INFO - Task exited with return code 1
[2023-12-07T17:28:50.509+0000] {taskinstance.py:2778} INFO - 0 downstream tasks scheduled from follow-on schedule check
