[2023-12-07T14:52:41.120+0000] {taskinstance.py:1159} INFO - Dependencies all met for dep_context=non-requeueable deps ti=<TaskInstance: my_scraping_dag.main_task scheduled__2023-05-28T00:00:00+00:00 [queued]>
[2023-12-07T14:52:41.125+0000] {taskinstance.py:1159} INFO - Dependencies all met for dep_context=requeueable deps ti=<TaskInstance: my_scraping_dag.main_task scheduled__2023-05-28T00:00:00+00:00 [queued]>
[2023-12-07T14:52:41.125+0000] {taskinstance.py:1361} INFO - Starting attempt 1 of 1
[2023-12-07T14:52:41.133+0000] {taskinstance.py:1382} INFO - Executing <Task(PythonOperator): main_task> on 2023-05-28 00:00:00+00:00
[2023-12-07T14:52:41.135+0000] {standard_task_runner.py:57} INFO - Started process 1068 to run task
[2023-12-07T14:52:41.137+0000] {standard_task_runner.py:84} INFO - Running: ['***', 'tasks', 'run', 'my_scraping_dag', 'main_task', 'scheduled__2023-05-28T00:00:00+00:00', '--job-id', '258', '--raw', '--subdir', 'DAGS_FOLDER/main.py', '--cfg-path', '/tmp/tmpuzk67uyn']
[2023-12-07T14:52:41.139+0000] {standard_task_runner.py:85} INFO - Job 258: Subtask main_task
[2023-12-07T14:52:41.166+0000] {task_command.py:416} INFO - Running <TaskInstance: my_scraping_dag.main_task scheduled__2023-05-28T00:00:00+00:00 [running]> on host 63b0c7e341c0
[2023-12-07T14:52:41.201+0000] {taskinstance.py:1662} INFO - Exporting env vars: AIRFLOW_CTX_DAG_OWNER='***' AIRFLOW_CTX_DAG_ID='my_scraping_dag' AIRFLOW_CTX_TASK_ID='main_task' AIRFLOW_CTX_EXECUTION_DATE='2023-05-28T00:00:00+00:00' AIRFLOW_CTX_TRY_NUMBER='1' AIRFLOW_CTX_DAG_RUN_ID='scheduled__2023-05-28T00:00:00+00:00'
[2023-12-07T14:52:41.202+0000] {taskinstance.py:1937} ERROR - Task failed with exception
Traceback (most recent call last):
  File "/usr/local/lib/python3.8/configparser.py", line 846, in items
    d.update(self._sections[section])
KeyError: 'web'

During handling of the above exception, another exception occurred:

Traceback (most recent call last):
  File "/home/airflow/.local/lib/python3.8/site-packages/airflow/operators/python.py", line 192, in execute
    return_value = self.execute_callable()
  File "/home/airflow/.local/lib/python3.8/site-packages/airflow/operators/python.py", line 209, in execute_callable
    return self.python_callable(*self.op_args, **self.op_kwargs)
  File "/opt/airflow/dags/main.py", line 61, in main
    config = get_config('web')
  File "/opt/airflow/dags/main.py", line 23, in get_config
    return {key: value for key, value in parser.items(section)}
  File "/usr/local/lib/python3.8/configparser.py", line 849, in items
    raise NoSectionError(section)
configparser.NoSectionError: No section: 'web'
[2023-12-07T14:52:41.219+0000] {taskinstance.py:1400} INFO - Marking task as FAILED. dag_id=my_scraping_dag, task_id=main_task, execution_date=20230528T000000, start_date=20231207T145241, end_date=20231207T145241
[2023-12-07T14:52:41.260+0000] {standard_task_runner.py:104} ERROR - Failed to execute job 258 for task main_task (No section: 'web'; 1068)
[2023-12-07T14:52:41.270+0000] {local_task_job_runner.py:228} INFO - Task exited with return code 1
[2023-12-07T14:52:41.285+0000] {taskinstance.py:2778} INFO - 0 downstream tasks scheduled from follow-on schedule check
[2023-12-07T16:32:31.193+0000] {taskinstance.py:1159} INFO - Dependencies all met for dep_context=non-requeueable deps ti=<TaskInstance: my_scraping_dag.main_task scheduled__2023-05-28T00:00:00+00:00 [queued]>
[2023-12-07T16:32:31.197+0000] {taskinstance.py:1159} INFO - Dependencies all met for dep_context=requeueable deps ti=<TaskInstance: my_scraping_dag.main_task scheduled__2023-05-28T00:00:00+00:00 [queued]>
[2023-12-07T16:32:31.198+0000] {taskinstance.py:1361} INFO - Starting attempt 1 of 1
[2023-12-07T16:32:31.208+0000] {taskinstance.py:1382} INFO - Executing <Task(PythonOperator): main_task> on 2023-05-28 00:00:00+00:00
[2023-12-07T16:32:31.211+0000] {standard_task_runner.py:57} INFO - Started process 3836 to run task
[2023-12-07T16:32:31.213+0000] {standard_task_runner.py:84} INFO - Running: ['***', 'tasks', 'run', 'my_scraping_dag', 'main_task', 'scheduled__2023-05-28T00:00:00+00:00', '--job-id', '736', '--raw', '--subdir', 'DAGS_FOLDER/main.py', '--cfg-path', '/tmp/tmpmwi4mr3a']
[2023-12-07T16:32:31.215+0000] {standard_task_runner.py:85} INFO - Job 736: Subtask main_task
[2023-12-07T16:32:31.245+0000] {task_command.py:416} INFO - Running <TaskInstance: my_scraping_dag.main_task scheduled__2023-05-28T00:00:00+00:00 [running]> on host 63b0c7e341c0
[2023-12-07T16:32:31.284+0000] {taskinstance.py:1662} INFO - Exporting env vars: AIRFLOW_CTX_DAG_OWNER='***' AIRFLOW_CTX_DAG_ID='my_scraping_dag' AIRFLOW_CTX_TASK_ID='main_task' AIRFLOW_CTX_EXECUTION_DATE='2023-05-28T00:00:00+00:00' AIRFLOW_CTX_TRY_NUMBER='1' AIRFLOW_CTX_DAG_RUN_ID='scheduled__2023-05-28T00:00:00+00:00'
[2023-12-07T16:32:31.286+0000] {taskinstance.py:1937} ERROR - Task failed with exception
Traceback (most recent call last):
  File "/usr/local/lib/python3.8/configparser.py", line 846, in items
    d.update(self._sections[section])
KeyError: 'web'

During handling of the above exception, another exception occurred:

Traceback (most recent call last):
  File "/home/airflow/.local/lib/python3.8/site-packages/airflow/operators/python.py", line 192, in execute
    return_value = self.execute_callable()
  File "/home/airflow/.local/lib/python3.8/site-packages/airflow/operators/python.py", line 209, in execute_callable
    return self.python_callable(*self.op_args, **self.op_kwargs)
  File "/opt/airflow/dags/main.py", line 60, in main
    config = get_config('web')
  File "/opt/airflow/dags/main.py", line 22, in get_config
    return {key: value for key, value in parser.items(section)}
  File "/usr/local/lib/python3.8/configparser.py", line 849, in items
    raise NoSectionError(section)
configparser.NoSectionError: No section: 'web'
[2023-12-07T16:32:31.292+0000] {taskinstance.py:1400} INFO - Marking task as FAILED. dag_id=my_scraping_dag, task_id=main_task, execution_date=20230528T000000, start_date=20231207T163231, end_date=20231207T163231
[2023-12-07T16:32:31.302+0000] {standard_task_runner.py:104} ERROR - Failed to execute job 736 for task main_task (No section: 'web'; 3836)
[2023-12-07T16:32:31.346+0000] {local_task_job_runner.py:228} INFO - Task exited with return code 1
[2023-12-07T16:32:31.361+0000] {taskinstance.py:2778} INFO - 0 downstream tasks scheduled from follow-on schedule check
[2023-12-07T16:41:47.275+0000] {taskinstance.py:1159} INFO - Dependencies all met for dep_context=non-requeueable deps ti=<TaskInstance: my_scraping_dag.main_task scheduled__2023-05-28T00:00:00+00:00 [queued]>
[2023-12-07T16:41:47.279+0000] {taskinstance.py:1159} INFO - Dependencies all met for dep_context=requeueable deps ti=<TaskInstance: my_scraping_dag.main_task scheduled__2023-05-28T00:00:00+00:00 [queued]>
[2023-12-07T16:41:47.279+0000] {taskinstance.py:1361} INFO - Starting attempt 1 of 1
[2023-12-07T16:41:47.285+0000] {taskinstance.py:1382} INFO - Executing <Task(PythonOperator): main_task> on 2023-05-28 00:00:00+00:00
[2023-12-07T16:41:47.287+0000] {standard_task_runner.py:57} INFO - Started process 4745 to run task
[2023-12-07T16:41:47.289+0000] {standard_task_runner.py:84} INFO - Running: ['***', 'tasks', 'run', 'my_scraping_dag', 'main_task', 'scheduled__2023-05-28T00:00:00+00:00', '--job-id', '1081', '--raw', '--subdir', 'DAGS_FOLDER/main.py', '--cfg-path', '/tmp/tmp9nv87yv7']
[2023-12-07T16:41:47.291+0000] {standard_task_runner.py:85} INFO - Job 1081: Subtask main_task
[2023-12-07T16:41:47.313+0000] {task_command.py:416} INFO - Running <TaskInstance: my_scraping_dag.main_task scheduled__2023-05-28T00:00:00+00:00 [running]> on host 63b0c7e341c0
[2023-12-07T16:41:47.344+0000] {taskinstance.py:1662} INFO - Exporting env vars: AIRFLOW_CTX_DAG_OWNER='***' AIRFLOW_CTX_DAG_ID='my_scraping_dag' AIRFLOW_CTX_TASK_ID='main_task' AIRFLOW_CTX_EXECUTION_DATE='2023-05-28T00:00:00+00:00' AIRFLOW_CTX_TRY_NUMBER='1' AIRFLOW_CTX_DAG_RUN_ID='scheduled__2023-05-28T00:00:00+00:00'
[2023-12-07T16:41:47.344+0000] {taskinstance.py:1937} ERROR - Task failed with exception
Traceback (most recent call last):
  File "/usr/local/lib/python3.8/configparser.py", line 846, in items
    d.update(self._sections[section])
KeyError: 'web'

During handling of the above exception, another exception occurred:

Traceback (most recent call last):
  File "/home/airflow/.local/lib/python3.8/site-packages/airflow/operators/python.py", line 192, in execute
    return_value = self.execute_callable()
  File "/home/airflow/.local/lib/python3.8/site-packages/airflow/operators/python.py", line 209, in execute_callable
    return self.python_callable(*self.op_args, **self.op_kwargs)
  File "/opt/airflow/dags/main.py", line 60, in main
    config = get_config('web')
  File "/opt/airflow/dags/main.py", line 22, in get_config
    return {key: value for key, value in parser.items(section)}
  File "/usr/local/lib/python3.8/configparser.py", line 849, in items
    raise NoSectionError(section)
configparser.NoSectionError: No section: 'web'
[2023-12-07T16:41:47.348+0000] {taskinstance.py:1400} INFO - Marking task as FAILED. dag_id=my_scraping_dag, task_id=main_task, execution_date=20230528T000000, start_date=20231207T164147, end_date=20231207T164147
[2023-12-07T16:41:47.353+0000] {standard_task_runner.py:104} ERROR - Failed to execute job 1081 for task main_task (No section: 'web'; 4745)
[2023-12-07T16:41:47.383+0000] {local_task_job_runner.py:228} INFO - Task exited with return code 1
[2023-12-07T16:41:47.394+0000] {taskinstance.py:2778} INFO - 0 downstream tasks scheduled from follow-on schedule check
[2023-12-07T17:00:51.334+0000] {taskinstance.py:1159} INFO - Dependencies all met for dep_context=non-requeueable deps ti=<TaskInstance: my_scraping_dag.main_task scheduled__2023-05-28T00:00:00+00:00 [queued]>
[2023-12-07T17:00:51.339+0000] {taskinstance.py:1159} INFO - Dependencies all met for dep_context=requeueable deps ti=<TaskInstance: my_scraping_dag.main_task scheduled__2023-05-28T00:00:00+00:00 [queued]>
[2023-12-07T17:00:51.339+0000] {taskinstance.py:1361} INFO - Starting attempt 1 of 1
[2023-12-07T17:00:51.346+0000] {taskinstance.py:1382} INFO - Executing <Task(PythonOperator): main_task> on 2023-05-28 00:00:00+00:00
[2023-12-07T17:00:51.349+0000] {standard_task_runner.py:57} INFO - Started process 5965 to run task
[2023-12-07T17:00:51.351+0000] {standard_task_runner.py:84} INFO - Running: ['***', 'tasks', 'run', 'my_scraping_dag', 'main_task', 'scheduled__2023-05-28T00:00:00+00:00', '--job-id', '1455', '--raw', '--subdir', 'DAGS_FOLDER/main.py', '--cfg-path', '/tmp/tmp5lal29ls']
[2023-12-07T17:00:51.353+0000] {standard_task_runner.py:85} INFO - Job 1455: Subtask main_task
[2023-12-07T17:00:51.377+0000] {task_command.py:416} INFO - Running <TaskInstance: my_scraping_dag.main_task scheduled__2023-05-28T00:00:00+00:00 [running]> on host 63b0c7e341c0
[2023-12-07T17:00:51.416+0000] {taskinstance.py:1662} INFO - Exporting env vars: AIRFLOW_CTX_DAG_OWNER='***' AIRFLOW_CTX_DAG_ID='my_scraping_dag' AIRFLOW_CTX_TASK_ID='main_task' AIRFLOW_CTX_EXECUTION_DATE='2023-05-28T00:00:00+00:00' AIRFLOW_CTX_TRY_NUMBER='1' AIRFLOW_CTX_DAG_RUN_ID='scheduled__2023-05-28T00:00:00+00:00'
[2023-12-07T17:00:51.441+0000] {logging_mixin.py:154} INFO - base_url: https://tuncbotanik.com
[2023-12-07T17:00:51.441+0000] {python.py:194} INFO - Done. Returned value was: ('https://tuncbotanik.com', {'User-Agent': 'Mozilla/5.0 (Macintosh; Intel Mac OS X 10_15_7) AppleWebKit/537.36 (KHTML, like Gecko) Chrome/119.0.0.0 Safari/537.36', 'Accept-Language': 'tr-TR,tr;q=0.9,en-US;q=0.8,en;q=0.7'}, {'dbname': 'plant', 'user': 'aozgokme', 'password': '***', 'host': 'localhost', 'port': '5432'})
[2023-12-07T17:00:51.456+0000] {taskinstance.py:1400} INFO - Marking task as SUCCESS. dag_id=my_scraping_dag, task_id=main_task, execution_date=20230528T000000, start_date=20231207T170051, end_date=20231207T170051
[2023-12-07T17:00:51.483+0000] {local_task_job_runner.py:228} INFO - Task exited with return code 0
[2023-12-07T17:00:51.504+0000] {taskinstance.py:2778} INFO - 1 downstream tasks scheduled from follow-on schedule check
[2023-12-07T17:04:03.262+0000] {taskinstance.py:1159} INFO - Dependencies all met for dep_context=non-requeueable deps ti=<TaskInstance: my_scraping_dag.main_task scheduled__2023-05-28T00:00:00+00:00 [queued]>
[2023-12-07T17:04:03.268+0000] {taskinstance.py:1159} INFO - Dependencies all met for dep_context=requeueable deps ti=<TaskInstance: my_scraping_dag.main_task scheduled__2023-05-28T00:00:00+00:00 [queued]>
[2023-12-07T17:04:03.269+0000] {taskinstance.py:1361} INFO - Starting attempt 1 of 1
[2023-12-07T17:04:03.280+0000] {taskinstance.py:1382} INFO - Executing <Task(PythonOperator): main_task> on 2023-05-28 00:00:00+00:00
[2023-12-07T17:04:03.285+0000] {standard_task_runner.py:57} INFO - Started process 7396 to run task
[2023-12-07T17:04:03.289+0000] {standard_task_runner.py:84} INFO - Running: ['***', 'tasks', 'run', 'my_scraping_dag', 'main_task', 'scheduled__2023-05-28T00:00:00+00:00', '--job-id', '2134', '--raw', '--subdir', 'DAGS_FOLDER/main.py', '--cfg-path', '/tmp/tmp5rx47jjw']
[2023-12-07T17:04:03.291+0000] {standard_task_runner.py:85} INFO - Job 2134: Subtask main_task
[2023-12-07T17:04:03.326+0000] {task_command.py:416} INFO - Running <TaskInstance: my_scraping_dag.main_task scheduled__2023-05-28T00:00:00+00:00 [running]> on host 63b0c7e341c0
[2023-12-07T17:04:03.395+0000] {taskinstance.py:1662} INFO - Exporting env vars: AIRFLOW_CTX_DAG_OWNER='***' AIRFLOW_CTX_DAG_ID='my_scraping_dag' AIRFLOW_CTX_TASK_ID='main_task' AIRFLOW_CTX_EXECUTION_DATE='2023-05-28T00:00:00+00:00' AIRFLOW_CTX_TRY_NUMBER='1' AIRFLOW_CTX_DAG_RUN_ID='scheduled__2023-05-28T00:00:00+00:00'
[2023-12-07T17:04:03.434+0000] {logging_mixin.py:154} INFO - base_url: https://tuncbotanik.com
[2023-12-07T17:04:03.436+0000] {python.py:194} INFO - Done. Returned value was: ('https://tuncbotanik.com', {'User-Agent': 'Mozilla/5.0 (Macintosh; Intel Mac OS X 10_15_7) AppleWebKit/537.36 (KHTML, like Gecko) Chrome/119.0.0.0 Safari/537.36', 'Accept-Language': 'tr-TR,tr;q=0.9,en-US;q=0.8,en;q=0.7'}, {'dbname': 'plant', 'user': 'aozgokme', 'password': '***', 'host': 'localhost', 'port': '5432'})
[2023-12-07T17:04:03.455+0000] {taskinstance.py:1400} INFO - Marking task as SUCCESS. dag_id=my_scraping_dag, task_id=main_task, execution_date=20230528T000000, start_date=20231207T170403, end_date=20231207T170403
[2023-12-07T17:04:03.500+0000] {local_task_job_runner.py:228} INFO - Task exited with return code 0
[2023-12-07T17:04:03.519+0000] {taskinstance.py:2778} INFO - 1 downstream tasks scheduled from follow-on schedule check
[2023-12-07T17:18:47.752+0000] {taskinstance.py:1159} INFO - Dependencies all met for dep_context=non-requeueable deps ti=<TaskInstance: my_scraping_dag.main_task scheduled__2023-05-28T00:00:00+00:00 [queued]>
[2023-12-07T17:18:47.760+0000] {taskinstance.py:1159} INFO - Dependencies all met for dep_context=requeueable deps ti=<TaskInstance: my_scraping_dag.main_task scheduled__2023-05-28T00:00:00+00:00 [queued]>
[2023-12-07T17:18:47.760+0000] {taskinstance.py:1361} INFO - Starting attempt 1 of 1
[2023-12-07T17:18:47.769+0000] {taskinstance.py:1382} INFO - Executing <Task(PythonOperator): main_task> on 2023-05-28 00:00:00+00:00
[2023-12-07T17:18:47.773+0000] {standard_task_runner.py:57} INFO - Started process 8843 to run task
[2023-12-07T17:18:47.776+0000] {standard_task_runner.py:84} INFO - Running: ['***', 'tasks', 'run', 'my_scraping_dag', 'main_task', 'scheduled__2023-05-28T00:00:00+00:00', '--job-id', '2677', '--raw', '--subdir', 'DAGS_FOLDER/main.py', '--cfg-path', '/tmp/tmpbsrq9emq']
[2023-12-07T17:18:47.779+0000] {standard_task_runner.py:85} INFO - Job 2677: Subtask main_task
[2023-12-07T17:18:47.824+0000] {task_command.py:416} INFO - Running <TaskInstance: my_scraping_dag.main_task scheduled__2023-05-28T00:00:00+00:00 [running]> on host 63b0c7e341c0
[2023-12-07T17:18:47.934+0000] {taskinstance.py:1662} INFO - Exporting env vars: AIRFLOW_CTX_DAG_OWNER='***' AIRFLOW_CTX_DAG_ID='my_scraping_dag' AIRFLOW_CTX_TASK_ID='main_task' AIRFLOW_CTX_EXECUTION_DATE='2023-05-28T00:00:00+00:00' AIRFLOW_CTX_TRY_NUMBER='1' AIRFLOW_CTX_DAG_RUN_ID='scheduled__2023-05-28T00:00:00+00:00'
[2023-12-07T17:18:48.767+0000] {taskinstance.py:1937} ERROR - Task failed with exception
Traceback (most recent call last):
  File "/home/airflow/.local/lib/python3.8/site-packages/airflow/operators/python.py", line 192, in execute
    return_value = self.execute_callable()
  File "/home/airflow/.local/lib/python3.8/site-packages/airflow/operators/python.py", line 209, in execute_callable
    return self.python_callable(*self.op_args, **self.op_kwargs)
  File "/opt/airflow/dags/main.py", line 80, in main
    insert_data_to_db(products, db_params)
  File "/opt/airflow/dags/main.py", line 43, in insert_data_to_db
    with psycopg2.connect(**db_params) as conn:
  File "/home/airflow/.local/lib/python3.8/site-packages/psycopg2/__init__.py", line 122, in connect
    conn = _connect(dsn, connection_factory=connection_factory, **kwasync)
psycopg2.OperationalError: connection to server at "localhost" (127.0.0.1), port 5432 failed: Connection refused
	Is the server running on that host and accepting TCP/IP connections?
connection to server at "localhost" (::1), port 5432 failed: Cannot assign requested address
	Is the server running on that host and accepting TCP/IP connections?

[2023-12-07T17:18:48.772+0000] {taskinstance.py:1400} INFO - Marking task as FAILED. dag_id=my_scraping_dag, task_id=main_task, execution_date=20230528T000000, start_date=20231207T171847, end_date=20231207T171848
[2023-12-07T17:18:48.778+0000] {standard_task_runner.py:104} ERROR - Failed to execute job 2677 for task main_task (connection to server at "localhost" (127.0.0.1), port 5432 failed: Connection refused
	Is the server running on that host and accepting TCP/IP connections?
connection to server at "localhost" (::1), port 5432 failed: Cannot assign requested address
	Is the server running on that host and accepting TCP/IP connections?
; 8843)
[2023-12-07T17:18:48.799+0000] {local_task_job_runner.py:228} INFO - Task exited with return code 1
[2023-12-07T17:18:48.808+0000] {taskinstance.py:2778} INFO - 0 downstream tasks scheduled from follow-on schedule check
[2023-12-07T17:23:06.558+0000] {taskinstance.py:1159} INFO - Dependencies all met for dep_context=non-requeueable deps ti=<TaskInstance: my_scraping_dag.main_task scheduled__2023-05-28T00:00:00+00:00 [queued]>
[2023-12-07T17:23:06.563+0000] {taskinstance.py:1159} INFO - Dependencies all met for dep_context=requeueable deps ti=<TaskInstance: my_scraping_dag.main_task scheduled__2023-05-28T00:00:00+00:00 [queued]>
[2023-12-07T17:23:06.564+0000] {taskinstance.py:1361} INFO - Starting attempt 1 of 1
[2023-12-07T17:23:06.571+0000] {taskinstance.py:1382} INFO - Executing <Task(PythonOperator): main_task> on 2023-05-28 00:00:00+00:00
[2023-12-07T17:23:06.574+0000] {standard_task_runner.py:57} INFO - Started process 9645 to run task
[2023-12-07T17:23:06.577+0000] {standard_task_runner.py:84} INFO - Running: ['***', 'tasks', 'run', 'my_scraping_dag', 'main_task', 'scheduled__2023-05-28T00:00:00+00:00', '--job-id', '3019', '--raw', '--subdir', 'DAGS_FOLDER/main.py', '--cfg-path', '/tmp/tmpi1hm4a_n']
[2023-12-07T17:23:06.579+0000] {standard_task_runner.py:85} INFO - Job 3019: Subtask main_task
[2023-12-07T17:23:06.612+0000] {task_command.py:416} INFO - Running <TaskInstance: my_scraping_dag.main_task scheduled__2023-05-28T00:00:00+00:00 [running]> on host 63b0c7e341c0
[2023-12-07T17:23:06.655+0000] {taskinstance.py:1662} INFO - Exporting env vars: AIRFLOW_CTX_DAG_OWNER='***' AIRFLOW_CTX_DAG_ID='my_scraping_dag' AIRFLOW_CTX_TASK_ID='main_task' AIRFLOW_CTX_EXECUTION_DATE='2023-05-28T00:00:00+00:00' AIRFLOW_CTX_TRY_NUMBER='1' AIRFLOW_CTX_DAG_RUN_ID='scheduled__2023-05-28T00:00:00+00:00'
[2023-12-07T17:23:07.468+0000] {taskinstance.py:1937} ERROR - Task failed with exception
Traceback (most recent call last):
  File "/home/airflow/.local/lib/python3.8/site-packages/airflow/operators/python.py", line 192, in execute
    return_value = self.execute_callable()
  File "/home/airflow/.local/lib/python3.8/site-packages/airflow/operators/python.py", line 209, in execute_callable
    return self.python_callable(*self.op_args, **self.op_kwargs)
  File "/opt/airflow/dags/main.py", line 73, in main
    insert_data_to_db(products, db_params)
  File "/opt/airflow/dags/main.py", line 40, in insert_data_to_db
    with psycopg2.connect(**db_params) as conn:
  File "/home/airflow/.local/lib/python3.8/site-packages/psycopg2/__init__.py", line 122, in connect
    conn = _connect(dsn, connection_factory=connection_factory, **kwasync)
psycopg2.OperationalError: connection to server at "localhost" (127.0.0.1), port 5432 failed: Connection refused
	Is the server running on that host and accepting TCP/IP connections?
connection to server at "localhost" (::1), port 5432 failed: Cannot assign requested address
	Is the server running on that host and accepting TCP/IP connections?

[2023-12-07T17:23:07.473+0000] {taskinstance.py:1400} INFO - Marking task as FAILED. dag_id=my_scraping_dag, task_id=main_task, execution_date=20230528T000000, start_date=20231207T172306, end_date=20231207T172307
[2023-12-07T17:23:07.479+0000] {standard_task_runner.py:104} ERROR - Failed to execute job 3019 for task main_task (connection to server at "localhost" (127.0.0.1), port 5432 failed: Connection refused
	Is the server running on that host and accepting TCP/IP connections?
connection to server at "localhost" (::1), port 5432 failed: Cannot assign requested address
	Is the server running on that host and accepting TCP/IP connections?
; 9645)
[2023-12-07T17:23:07.516+0000] {local_task_job_runner.py:228} INFO - Task exited with return code 1
[2023-12-07T17:23:07.525+0000] {taskinstance.py:2778} INFO - 0 downstream tasks scheduled from follow-on schedule check
[2023-12-07T17:28:48.858+0000] {taskinstance.py:1159} INFO - Dependencies all met for dep_context=non-requeueable deps ti=<TaskInstance: my_scraping_dag.main_task scheduled__2023-05-28T00:00:00+00:00 [queued]>
[2023-12-07T17:28:48.864+0000] {taskinstance.py:1159} INFO - Dependencies all met for dep_context=requeueable deps ti=<TaskInstance: my_scraping_dag.main_task scheduled__2023-05-28T00:00:00+00:00 [queued]>
[2023-12-07T17:28:48.865+0000] {taskinstance.py:1361} INFO - Starting attempt 1 of 1
[2023-12-07T17:28:48.872+0000] {taskinstance.py:1382} INFO - Executing <Task(PythonOperator): main_task> on 2023-05-28 00:00:00+00:00
[2023-12-07T17:28:48.875+0000] {standard_task_runner.py:57} INFO - Started process 10480 to run task
[2023-12-07T17:28:48.877+0000] {standard_task_runner.py:84} INFO - Running: ['***', 'tasks', 'run', 'my_scraping_dag', 'main_task', 'scheduled__2023-05-28T00:00:00+00:00', '--job-id', '3361', '--raw', '--subdir', 'DAGS_FOLDER/main.py', '--cfg-path', '/tmp/tmppzighkep']
[2023-12-07T17:28:48.879+0000] {standard_task_runner.py:85} INFO - Job 3361: Subtask main_task
[2023-12-07T17:28:48.908+0000] {task_command.py:416} INFO - Running <TaskInstance: my_scraping_dag.main_task scheduled__2023-05-28T00:00:00+00:00 [running]> on host 63b0c7e341c0
[2023-12-07T17:28:48.942+0000] {taskinstance.py:1662} INFO - Exporting env vars: AIRFLOW_CTX_DAG_OWNER='***' AIRFLOW_CTX_DAG_ID='my_scraping_dag' AIRFLOW_CTX_TASK_ID='main_task' AIRFLOW_CTX_EXECUTION_DATE='2023-05-28T00:00:00+00:00' AIRFLOW_CTX_TRY_NUMBER='1' AIRFLOW_CTX_DAG_RUN_ID='scheduled__2023-05-28T00:00:00+00:00'
[2023-12-07T17:28:49.686+0000] {taskinstance.py:1937} ERROR - Task failed with exception
Traceback (most recent call last):
  File "/home/airflow/.local/lib/python3.8/site-packages/airflow/operators/python.py", line 192, in execute
    return_value = self.execute_callable()
  File "/home/airflow/.local/lib/python3.8/site-packages/airflow/operators/python.py", line 209, in execute_callable
    return self.python_callable(*self.op_args, **self.op_kwargs)
  File "/opt/airflow/dags/main.py", line 73, in main
    insert_data_to_db(products, db_params)
  File "/opt/airflow/dags/main.py", line 40, in insert_data_to_db
    with psycopg2.connect(**db_params) as conn:
  File "/home/airflow/.local/lib/python3.8/site-packages/psycopg2/__init__.py", line 122, in connect
    conn = _connect(dsn, connection_factory=connection_factory, **kwasync)
psycopg2.OperationalError: connection to server at "localhost" (127.0.0.1), port 5432 failed: Connection refused
	Is the server running on that host and accepting TCP/IP connections?
connection to server at "localhost" (::1), port 5432 failed: Cannot assign requested address
	Is the server running on that host and accepting TCP/IP connections?

[2023-12-07T17:28:49.703+0000] {taskinstance.py:1400} INFO - Marking task as FAILED. dag_id=my_scraping_dag, task_id=main_task, execution_date=20230528T000000, start_date=20231207T172848, end_date=20231207T172849
[2023-12-07T17:28:49.713+0000] {standard_task_runner.py:104} ERROR - Failed to execute job 3361 for task main_task (connection to server at "localhost" (127.0.0.1), port 5432 failed: Connection refused
	Is the server running on that host and accepting TCP/IP connections?
connection to server at "localhost" (::1), port 5432 failed: Cannot assign requested address
	Is the server running on that host and accepting TCP/IP connections?
; 10480)
[2023-12-07T17:28:49.736+0000] {local_task_job_runner.py:228} INFO - Task exited with return code 1
[2023-12-07T17:28:49.749+0000] {taskinstance.py:2778} INFO - 0 downstream tasks scheduled from follow-on schedule check
[2023-12-09T07:34:48.697+0000] {taskinstance.py:1159} INFO - Dependencies all met for dep_context=non-requeueable deps ti=<TaskInstance: my_scraping_dag.main_task scheduled__2023-05-28T00:00:00+00:00 [queued]>
[2023-12-09T07:34:48.702+0000] {taskinstance.py:1159} INFO - Dependencies all met for dep_context=requeueable deps ti=<TaskInstance: my_scraping_dag.main_task scheduled__2023-05-28T00:00:00+00:00 [queued]>
[2023-12-09T07:34:48.702+0000] {taskinstance.py:1361} INFO - Starting attempt 1 of 1
[2023-12-09T07:34:48.717+0000] {taskinstance.py:1382} INFO - Executing <Task(PythonOperator): main_task> on 2023-05-28 00:00:00+00:00
[2023-12-09T07:34:48.720+0000] {standard_task_runner.py:57} INFO - Started process 899 to run task
[2023-12-09T07:34:48.722+0000] {standard_task_runner.py:84} INFO - Running: ['***', 'tasks', 'run', 'my_scraping_dag', 'main_task', 'scheduled__2023-05-28T00:00:00+00:00', '--job-id', '151', '--raw', '--subdir', 'DAGS_FOLDER/main.py', '--cfg-path', '/tmp/tmp1r2k6u_a']
[2023-12-09T07:34:48.724+0000] {standard_task_runner.py:85} INFO - Job 151: Subtask main_task
[2023-12-09T07:34:48.749+0000] {task_command.py:416} INFO - Running <TaskInstance: my_scraping_dag.main_task scheduled__2023-05-28T00:00:00+00:00 [running]> on host 36b5ef2505c9
[2023-12-09T07:34:48.789+0000] {taskinstance.py:1662} INFO - Exporting env vars: AIRFLOW_CTX_DAG_OWNER='***' AIRFLOW_CTX_DAG_ID='my_scraping_dag' AIRFLOW_CTX_TASK_ID='main_task' AIRFLOW_CTX_EXECUTION_DATE='2023-05-28T00:00:00+00:00' AIRFLOW_CTX_TRY_NUMBER='1' AIRFLOW_CTX_DAG_RUN_ID='scheduled__2023-05-28T00:00:00+00:00'
[2023-12-09T07:34:48.794+0000] {taskinstance.py:1937} ERROR - Task failed with exception
Traceback (most recent call last):
  File "/home/airflow/.local/lib/python3.8/site-packages/airflow/operators/python.py", line 192, in execute
    return_value = self.execute_callable()
  File "/home/airflow/.local/lib/python3.8/site-packages/airflow/operators/python.py", line 209, in execute_callable
    return self.python_callable(*self.op_args, **self.op_kwargs)
  File "/opt/airflow/dags/main.py", line 64, in main
    base_url = Variable.get('base_url')
  File "/home/airflow/.local/lib/python3.8/site-packages/airflow/models/variable.py", line 140, in get
    raise KeyError(f"Variable {key} does not exist")
KeyError: 'Variable base_url does not exist'
[2023-12-09T07:34:48.798+0000] {taskinstance.py:1400} INFO - Marking task as FAILED. dag_id=my_scraping_dag, task_id=main_task, execution_date=20230528T000000, start_date=20231209T073448, end_date=20231209T073448
[2023-12-09T07:34:48.803+0000] {standard_task_runner.py:104} ERROR - Failed to execute job 151 for task main_task ('Variable base_url does not exist'; 899)
[2023-12-09T07:34:48.815+0000] {local_task_job_runner.py:228} INFO - Task exited with return code 1
[2023-12-09T07:34:48.824+0000] {taskinstance.py:2778} INFO - 0 downstream tasks scheduled from follow-on schedule check
