[2023-12-07T14:52:19.211+0000] {taskinstance.py:1159} INFO - Dependencies all met for dep_context=non-requeueable deps ti=<TaskInstance: my_scraping_dag.main_task scheduled__2023-04-22T00:00:00+00:00 [queued]>
[2023-12-07T14:52:19.218+0000] {taskinstance.py:1159} INFO - Dependencies all met for dep_context=requeueable deps ti=<TaskInstance: my_scraping_dag.main_task scheduled__2023-04-22T00:00:00+00:00 [queued]>
[2023-12-07T14:52:19.219+0000] {taskinstance.py:1361} INFO - Starting attempt 1 of 1
[2023-12-07T14:52:19.258+0000] {taskinstance.py:1382} INFO - Executing <Task(PythonOperator): main_task> on 2023-04-22 00:00:00+00:00
[2023-12-07T14:52:19.261+0000] {standard_task_runner.py:57} INFO - Started process 984 to run task
[2023-12-07T14:52:19.264+0000] {standard_task_runner.py:84} INFO - Running: ['***', 'tasks', 'run', 'my_scraping_dag', 'main_task', 'scheduled__2023-04-22T00:00:00+00:00', '--job-id', '222', '--raw', '--subdir', 'DAGS_FOLDER/main.py', '--cfg-path', '/tmp/tmpmahwtam7']
[2023-12-07T14:52:19.266+0000] {standard_task_runner.py:85} INFO - Job 222: Subtask main_task
[2023-12-07T14:52:19.306+0000] {task_command.py:416} INFO - Running <TaskInstance: my_scraping_dag.main_task scheduled__2023-04-22T00:00:00+00:00 [running]> on host 63b0c7e341c0
[2023-12-07T14:52:19.344+0000] {taskinstance.py:1662} INFO - Exporting env vars: AIRFLOW_CTX_DAG_OWNER='***' AIRFLOW_CTX_DAG_ID='my_scraping_dag' AIRFLOW_CTX_TASK_ID='main_task' AIRFLOW_CTX_EXECUTION_DATE='2023-04-22T00:00:00+00:00' AIRFLOW_CTX_TRY_NUMBER='1' AIRFLOW_CTX_DAG_RUN_ID='scheduled__2023-04-22T00:00:00+00:00'
[2023-12-07T14:52:19.346+0000] {taskinstance.py:1937} ERROR - Task failed with exception
Traceback (most recent call last):
  File "/usr/local/lib/python3.8/configparser.py", line 846, in items
    d.update(self._sections[section])
KeyError: 'web'

During handling of the above exception, another exception occurred:

Traceback (most recent call last):
  File "/home/airflow/.local/lib/python3.8/site-packages/airflow/operators/python.py", line 192, in execute
    return_value = self.execute_callable()
  File "/home/airflow/.local/lib/python3.8/site-packages/airflow/operators/python.py", line 209, in execute_callable
    return self.python_callable(*self.op_args, **self.op_kwargs)
  File "/opt/airflow/dags/main.py", line 61, in main
    config = get_config('web')
  File "/opt/airflow/dags/main.py", line 23, in get_config
    return {key: value for key, value in parser.items(section)}
  File "/usr/local/lib/python3.8/configparser.py", line 849, in items
    raise NoSectionError(section)
configparser.NoSectionError: No section: 'web'
[2023-12-07T14:52:19.355+0000] {taskinstance.py:1400} INFO - Marking task as FAILED. dag_id=my_scraping_dag, task_id=main_task, execution_date=20230422T000000, start_date=20231207T145219, end_date=20231207T145219
[2023-12-07T14:52:19.361+0000] {standard_task_runner.py:104} ERROR - Failed to execute job 222 for task main_task (No section: 'web'; 984)
[2023-12-07T14:52:19.398+0000] {local_task_job_runner.py:228} INFO - Task exited with return code 1
[2023-12-07T14:52:19.426+0000] {taskinstance.py:2778} INFO - 0 downstream tasks scheduled from follow-on schedule check
[2023-12-07T16:32:14.112+0000] {taskinstance.py:1159} INFO - Dependencies all met for dep_context=non-requeueable deps ti=<TaskInstance: my_scraping_dag.main_task scheduled__2023-04-22T00:00:00+00:00 [queued]>
[2023-12-07T16:32:14.117+0000] {taskinstance.py:1159} INFO - Dependencies all met for dep_context=requeueable deps ti=<TaskInstance: my_scraping_dag.main_task scheduled__2023-04-22T00:00:00+00:00 [queued]>
[2023-12-07T16:32:14.117+0000] {taskinstance.py:1361} INFO - Starting attempt 1 of 1
[2023-12-07T16:32:14.125+0000] {taskinstance.py:1382} INFO - Executing <Task(PythonOperator): main_task> on 2023-04-22 00:00:00+00:00
[2023-12-07T16:32:14.128+0000] {standard_task_runner.py:57} INFO - Started process 3764 to run task
[2023-12-07T16:32:14.130+0000] {standard_task_runner.py:84} INFO - Running: ['***', 'tasks', 'run', 'my_scraping_dag', 'main_task', 'scheduled__2023-04-22T00:00:00+00:00', '--job-id', '700', '--raw', '--subdir', 'DAGS_FOLDER/main.py', '--cfg-path', '/tmp/tmp6kof6p92']
[2023-12-07T16:32:14.133+0000] {standard_task_runner.py:85} INFO - Job 700: Subtask main_task
[2023-12-07T16:32:14.162+0000] {task_command.py:416} INFO - Running <TaskInstance: my_scraping_dag.main_task scheduled__2023-04-22T00:00:00+00:00 [running]> on host 63b0c7e341c0
[2023-12-07T16:32:14.199+0000] {taskinstance.py:1662} INFO - Exporting env vars: AIRFLOW_CTX_DAG_OWNER='***' AIRFLOW_CTX_DAG_ID='my_scraping_dag' AIRFLOW_CTX_TASK_ID='main_task' AIRFLOW_CTX_EXECUTION_DATE='2023-04-22T00:00:00+00:00' AIRFLOW_CTX_TRY_NUMBER='1' AIRFLOW_CTX_DAG_RUN_ID='scheduled__2023-04-22T00:00:00+00:00'
[2023-12-07T16:32:14.200+0000] {taskinstance.py:1937} ERROR - Task failed with exception
Traceback (most recent call last):
  File "/usr/local/lib/python3.8/configparser.py", line 846, in items
    d.update(self._sections[section])
KeyError: 'web'

During handling of the above exception, another exception occurred:

Traceback (most recent call last):
  File "/home/airflow/.local/lib/python3.8/site-packages/airflow/operators/python.py", line 192, in execute
    return_value = self.execute_callable()
  File "/home/airflow/.local/lib/python3.8/site-packages/airflow/operators/python.py", line 209, in execute_callable
    return self.python_callable(*self.op_args, **self.op_kwargs)
  File "/opt/airflow/dags/main.py", line 60, in main
    config = get_config('web')
  File "/opt/airflow/dags/main.py", line 22, in get_config
    return {key: value for key, value in parser.items(section)}
  File "/usr/local/lib/python3.8/configparser.py", line 849, in items
    raise NoSectionError(section)
configparser.NoSectionError: No section: 'web'
[2023-12-07T16:32:14.205+0000] {taskinstance.py:1400} INFO - Marking task as FAILED. dag_id=my_scraping_dag, task_id=main_task, execution_date=20230422T000000, start_date=20231207T163214, end_date=20231207T163214
[2023-12-07T16:32:14.211+0000] {standard_task_runner.py:104} ERROR - Failed to execute job 700 for task main_task (No section: 'web'; 3764)
[2023-12-07T16:32:14.223+0000] {local_task_job_runner.py:228} INFO - Task exited with return code 1
[2023-12-07T16:32:14.262+0000] {taskinstance.py:2778} INFO - 0 downstream tasks scheduled from follow-on schedule check
[2023-12-07T16:41:31.136+0000] {taskinstance.py:1159} INFO - Dependencies all met for dep_context=non-requeueable deps ti=<TaskInstance: my_scraping_dag.main_task scheduled__2023-04-22T00:00:00+00:00 [queued]>
[2023-12-07T16:41:31.141+0000] {taskinstance.py:1159} INFO - Dependencies all met for dep_context=requeueable deps ti=<TaskInstance: my_scraping_dag.main_task scheduled__2023-04-22T00:00:00+00:00 [queued]>
[2023-12-07T16:41:31.141+0000] {taskinstance.py:1361} INFO - Starting attempt 1 of 1
[2023-12-07T16:41:31.147+0000] {taskinstance.py:1382} INFO - Executing <Task(PythonOperator): main_task> on 2023-04-22 00:00:00+00:00
[2023-12-07T16:41:31.149+0000] {standard_task_runner.py:57} INFO - Started process 4661 to run task
[2023-12-07T16:41:31.151+0000] {standard_task_runner.py:84} INFO - Running: ['***', 'tasks', 'run', 'my_scraping_dag', 'main_task', 'scheduled__2023-04-22T00:00:00+00:00', '--job-id', '1042', '--raw', '--subdir', 'DAGS_FOLDER/main.py', '--cfg-path', '/tmp/tmpcz3y4ing']
[2023-12-07T16:41:31.153+0000] {standard_task_runner.py:85} INFO - Job 1042: Subtask main_task
[2023-12-07T16:41:31.175+0000] {task_command.py:416} INFO - Running <TaskInstance: my_scraping_dag.main_task scheduled__2023-04-22T00:00:00+00:00 [running]> on host 63b0c7e341c0
[2023-12-07T16:41:31.209+0000] {taskinstance.py:1662} INFO - Exporting env vars: AIRFLOW_CTX_DAG_OWNER='***' AIRFLOW_CTX_DAG_ID='my_scraping_dag' AIRFLOW_CTX_TASK_ID='main_task' AIRFLOW_CTX_EXECUTION_DATE='2023-04-22T00:00:00+00:00' AIRFLOW_CTX_TRY_NUMBER='1' AIRFLOW_CTX_DAG_RUN_ID='scheduled__2023-04-22T00:00:00+00:00'
[2023-12-07T16:41:31.210+0000] {taskinstance.py:1937} ERROR - Task failed with exception
Traceback (most recent call last):
  File "/usr/local/lib/python3.8/configparser.py", line 846, in items
    d.update(self._sections[section])
KeyError: 'web'

During handling of the above exception, another exception occurred:

Traceback (most recent call last):
  File "/home/airflow/.local/lib/python3.8/site-packages/airflow/operators/python.py", line 192, in execute
    return_value = self.execute_callable()
  File "/home/airflow/.local/lib/python3.8/site-packages/airflow/operators/python.py", line 209, in execute_callable
    return self.python_callable(*self.op_args, **self.op_kwargs)
  File "/opt/airflow/dags/main.py", line 60, in main
    config = get_config('web')
  File "/opt/airflow/dags/main.py", line 22, in get_config
    return {key: value for key, value in parser.items(section)}
  File "/usr/local/lib/python3.8/configparser.py", line 849, in items
    raise NoSectionError(section)
configparser.NoSectionError: No section: 'web'
[2023-12-07T16:41:31.214+0000] {taskinstance.py:1400} INFO - Marking task as FAILED. dag_id=my_scraping_dag, task_id=main_task, execution_date=20230422T000000, start_date=20231207T164131, end_date=20231207T164131
[2023-12-07T16:41:31.219+0000] {standard_task_runner.py:104} ERROR - Failed to execute job 1042 for task main_task (No section: 'web'; 4661)
[2023-12-07T16:41:31.245+0000] {local_task_job_runner.py:228} INFO - Task exited with return code 1
[2023-12-07T16:41:31.258+0000] {taskinstance.py:2778} INFO - 0 downstream tasks scheduled from follow-on schedule check
[2023-12-07T17:00:35.468+0000] {taskinstance.py:1159} INFO - Dependencies all met for dep_context=non-requeueable deps ti=<TaskInstance: my_scraping_dag.main_task scheduled__2023-04-22T00:00:00+00:00 [queued]>
[2023-12-07T17:00:35.472+0000] {taskinstance.py:1159} INFO - Dependencies all met for dep_context=requeueable deps ti=<TaskInstance: my_scraping_dag.main_task scheduled__2023-04-22T00:00:00+00:00 [queued]>
[2023-12-07T17:00:35.473+0000] {taskinstance.py:1361} INFO - Starting attempt 1 of 1
[2023-12-07T17:00:35.480+0000] {taskinstance.py:1382} INFO - Executing <Task(PythonOperator): main_task> on 2023-04-22 00:00:00+00:00
[2023-12-07T17:00:35.482+0000] {standard_task_runner.py:57} INFO - Started process 5820 to run task
[2023-12-07T17:00:35.484+0000] {standard_task_runner.py:84} INFO - Running: ['***', 'tasks', 'run', 'my_scraping_dag', 'main_task', 'scheduled__2023-04-22T00:00:00+00:00', '--job-id', '1386', '--raw', '--subdir', 'DAGS_FOLDER/main.py', '--cfg-path', '/tmp/tmpyb0h5tge']
[2023-12-07T17:00:35.486+0000] {standard_task_runner.py:85} INFO - Job 1386: Subtask main_task
[2023-12-07T17:00:35.509+0000] {task_command.py:416} INFO - Running <TaskInstance: my_scraping_dag.main_task scheduled__2023-04-22T00:00:00+00:00 [running]> on host 63b0c7e341c0
[2023-12-07T17:00:35.545+0000] {taskinstance.py:1662} INFO - Exporting env vars: AIRFLOW_CTX_DAG_OWNER='***' AIRFLOW_CTX_DAG_ID='my_scraping_dag' AIRFLOW_CTX_TASK_ID='main_task' AIRFLOW_CTX_EXECUTION_DATE='2023-04-22T00:00:00+00:00' AIRFLOW_CTX_TRY_NUMBER='1' AIRFLOW_CTX_DAG_RUN_ID='scheduled__2023-04-22T00:00:00+00:00'
[2023-12-07T17:00:35.564+0000] {taskinstance.py:1937} ERROR - Task failed with exception
Traceback (most recent call last):
  File "/home/airflow/.local/lib/python3.8/site-packages/airflow/operators/python.py", line 192, in execute
    return_value = self.execute_callable()
  File "/home/airflow/.local/lib/python3.8/site-packages/airflow/operators/python.py", line 209, in execute_callable
    return self.python_callable(*self.op_args, **self.op_kwargs)
  File "/opt/airflow/dags/main.py", line 33, in main
    'host': get_config('localhost'),
  File "/opt/airflow/dags/main.py", line 20, in get_config
    return Variable.get(key)
  File "/home/airflow/.local/lib/python3.8/site-packages/airflow/models/variable.py", line 140, in get
    raise KeyError(f"Variable {key} does not exist")
KeyError: 'Variable localhost does not exist'
[2023-12-07T17:00:35.568+0000] {taskinstance.py:1400} INFO - Marking task as FAILED. dag_id=my_scraping_dag, task_id=main_task, execution_date=20230422T000000, start_date=20231207T170035, end_date=20231207T170035
[2023-12-07T17:00:35.574+0000] {standard_task_runner.py:104} ERROR - Failed to execute job 1386 for task main_task ('Variable localhost does not exist'; 5820)
[2023-12-07T17:00:35.617+0000] {local_task_job_runner.py:228} INFO - Task exited with return code 1
[2023-12-07T17:00:35.629+0000] {taskinstance.py:2778} INFO - 0 downstream tasks scheduled from follow-on schedule check
[2023-12-07T17:03:54.607+0000] {taskinstance.py:1159} INFO - Dependencies all met for dep_context=non-requeueable deps ti=<TaskInstance: my_scraping_dag.main_task scheduled__2023-04-22T00:00:00+00:00 [queued]>
[2023-12-07T17:03:54.613+0000] {taskinstance.py:1159} INFO - Dependencies all met for dep_context=requeueable deps ti=<TaskInstance: my_scraping_dag.main_task scheduled__2023-04-22T00:00:00+00:00 [queued]>
[2023-12-07T17:03:54.614+0000] {taskinstance.py:1361} INFO - Starting attempt 1 of 1
[2023-12-07T17:03:54.629+0000] {taskinstance.py:1382} INFO - Executing <Task(PythonOperator): main_task> on 2023-04-22 00:00:00+00:00
[2023-12-07T17:03:54.632+0000] {standard_task_runner.py:57} INFO - Started process 7256 to run task
[2023-12-07T17:03:54.635+0000] {standard_task_runner.py:84} INFO - Running: ['***', 'tasks', 'run', 'my_scraping_dag', 'main_task', 'scheduled__2023-04-22T00:00:00+00:00', '--job-id', '2065', '--raw', '--subdir', 'DAGS_FOLDER/main.py', '--cfg-path', '/tmp/tmpojh0wd1i']
[2023-12-07T17:03:54.638+0000] {standard_task_runner.py:85} INFO - Job 2065: Subtask main_task
[2023-12-07T17:03:54.676+0000] {task_command.py:416} INFO - Running <TaskInstance: my_scraping_dag.main_task scheduled__2023-04-22T00:00:00+00:00 [running]> on host 63b0c7e341c0
[2023-12-07T17:03:54.724+0000] {taskinstance.py:1662} INFO - Exporting env vars: AIRFLOW_CTX_DAG_OWNER='***' AIRFLOW_CTX_DAG_ID='my_scraping_dag' AIRFLOW_CTX_TASK_ID='main_task' AIRFLOW_CTX_EXECUTION_DATE='2023-04-22T00:00:00+00:00' AIRFLOW_CTX_TRY_NUMBER='1' AIRFLOW_CTX_DAG_RUN_ID='scheduled__2023-04-22T00:00:00+00:00'
[2023-12-07T17:03:54.745+0000] {logging_mixin.py:154} INFO - base_url: https://tuncbotanik.com
[2023-12-07T17:03:54.746+0000] {python.py:194} INFO - Done. Returned value was: ('https://tuncbotanik.com', {'User-Agent': 'Mozilla/5.0 (Macintosh; Intel Mac OS X 10_15_7) AppleWebKit/537.36 (KHTML, like Gecko) Chrome/119.0.0.0 Safari/537.36', 'Accept-Language': 'tr-TR,tr;q=0.9,en-US;q=0.8,en;q=0.7'}, {'dbname': 'plant', 'user': 'aozgokme', 'password': '***', 'host': 'localhost', 'port': '5432'})
[2023-12-07T17:03:54.756+0000] {taskinstance.py:1400} INFO - Marking task as SUCCESS. dag_id=my_scraping_dag, task_id=main_task, execution_date=20230422T000000, start_date=20231207T170354, end_date=20231207T170354
[2023-12-07T17:03:54.770+0000] {local_task_job_runner.py:228} INFO - Task exited with return code 0
[2023-12-07T17:03:54.793+0000] {taskinstance.py:2778} INFO - 1 downstream tasks scheduled from follow-on schedule check
[2023-12-07T17:18:40.791+0000] {taskinstance.py:1159} INFO - Dependencies all met for dep_context=non-requeueable deps ti=<TaskInstance: my_scraping_dag.main_task scheduled__2023-04-22T00:00:00+00:00 [queued]>
[2023-12-07T17:18:40.795+0000] {taskinstance.py:1159} INFO - Dependencies all met for dep_context=requeueable deps ti=<TaskInstance: my_scraping_dag.main_task scheduled__2023-04-22T00:00:00+00:00 [queued]>
[2023-12-07T17:18:40.795+0000] {taskinstance.py:1361} INFO - Starting attempt 1 of 1
[2023-12-07T17:18:40.801+0000] {taskinstance.py:1382} INFO - Executing <Task(PythonOperator): main_task> on 2023-04-22 00:00:00+00:00
[2023-12-07T17:18:40.803+0000] {standard_task_runner.py:57} INFO - Started process 8769 to run task
[2023-12-07T17:18:40.805+0000] {standard_task_runner.py:84} INFO - Running: ['***', 'tasks', 'run', 'my_scraping_dag', 'main_task', 'scheduled__2023-04-22T00:00:00+00:00', '--job-id', '2641', '--raw', '--subdir', 'DAGS_FOLDER/main.py', '--cfg-path', '/tmp/tmpl23kdpgi']
[2023-12-07T17:18:40.807+0000] {standard_task_runner.py:85} INFO - Job 2641: Subtask main_task
[2023-12-07T17:18:40.831+0000] {task_command.py:416} INFO - Running <TaskInstance: my_scraping_dag.main_task scheduled__2023-04-22T00:00:00+00:00 [running]> on host 63b0c7e341c0
[2023-12-07T17:18:40.861+0000] {taskinstance.py:1662} INFO - Exporting env vars: AIRFLOW_CTX_DAG_OWNER='***' AIRFLOW_CTX_DAG_ID='my_scraping_dag' AIRFLOW_CTX_TASK_ID='main_task' AIRFLOW_CTX_EXECUTION_DATE='2023-04-22T00:00:00+00:00' AIRFLOW_CTX_TRY_NUMBER='1' AIRFLOW_CTX_DAG_RUN_ID='scheduled__2023-04-22T00:00:00+00:00'
[2023-12-07T17:18:41.493+0000] {taskinstance.py:1937} ERROR - Task failed with exception
Traceback (most recent call last):
  File "/home/airflow/.local/lib/python3.8/site-packages/airflow/operators/python.py", line 192, in execute
    return_value = self.execute_callable()
  File "/home/airflow/.local/lib/python3.8/site-packages/airflow/operators/python.py", line 209, in execute_callable
    return self.python_callable(*self.op_args, **self.op_kwargs)
  File "/opt/airflow/dags/main.py", line 80, in main
    insert_data_to_db(products, db_params)
  File "/opt/airflow/dags/main.py", line 43, in insert_data_to_db
    with psycopg2.connect(**db_params) as conn:
  File "/home/airflow/.local/lib/python3.8/site-packages/psycopg2/__init__.py", line 122, in connect
    conn = _connect(dsn, connection_factory=connection_factory, **kwasync)
psycopg2.OperationalError: connection to server at "localhost" (127.0.0.1), port 5432 failed: Connection refused
	Is the server running on that host and accepting TCP/IP connections?
connection to server at "localhost" (::1), port 5432 failed: Cannot assign requested address
	Is the server running on that host and accepting TCP/IP connections?

[2023-12-07T17:18:41.500+0000] {taskinstance.py:1400} INFO - Marking task as FAILED. dag_id=my_scraping_dag, task_id=main_task, execution_date=20230422T000000, start_date=20231207T171840, end_date=20231207T171841
[2023-12-07T17:18:41.505+0000] {standard_task_runner.py:104} ERROR - Failed to execute job 2641 for task main_task (connection to server at "localhost" (127.0.0.1), port 5432 failed: Connection refused
	Is the server running on that host and accepting TCP/IP connections?
connection to server at "localhost" (::1), port 5432 failed: Cannot assign requested address
	Is the server running on that host and accepting TCP/IP connections?
; 8769)
[2023-12-07T17:18:41.547+0000] {local_task_job_runner.py:228} INFO - Task exited with return code 1
[2023-12-07T17:18:41.556+0000] {taskinstance.py:2778} INFO - 0 downstream tasks scheduled from follow-on schedule check
[2023-12-07T17:23:00.103+0000] {taskinstance.py:1159} INFO - Dependencies all met for dep_context=non-requeueable deps ti=<TaskInstance: my_scraping_dag.main_task scheduled__2023-04-22T00:00:00+00:00 [queued]>
[2023-12-07T17:23:00.108+0000] {taskinstance.py:1159} INFO - Dependencies all met for dep_context=requeueable deps ti=<TaskInstance: my_scraping_dag.main_task scheduled__2023-04-22T00:00:00+00:00 [queued]>
[2023-12-07T17:23:00.109+0000] {taskinstance.py:1361} INFO - Starting attempt 1 of 1
[2023-12-07T17:23:00.116+0000] {taskinstance.py:1382} INFO - Executing <Task(PythonOperator): main_task> on 2023-04-22 00:00:00+00:00
[2023-12-07T17:23:00.119+0000] {standard_task_runner.py:57} INFO - Started process 9573 to run task
[2023-12-07T17:23:00.121+0000] {standard_task_runner.py:84} INFO - Running: ['***', 'tasks', 'run', 'my_scraping_dag', 'main_task', 'scheduled__2023-04-22T00:00:00+00:00', '--job-id', '2983', '--raw', '--subdir', 'DAGS_FOLDER/main.py', '--cfg-path', '/tmp/tmpb28bu1ze']
[2023-12-07T17:23:00.124+0000] {standard_task_runner.py:85} INFO - Job 2983: Subtask main_task
[2023-12-07T17:23:00.156+0000] {task_command.py:416} INFO - Running <TaskInstance: my_scraping_dag.main_task scheduled__2023-04-22T00:00:00+00:00 [running]> on host 63b0c7e341c0
[2023-12-07T17:23:00.218+0000] {taskinstance.py:1662} INFO - Exporting env vars: AIRFLOW_CTX_DAG_OWNER='***' AIRFLOW_CTX_DAG_ID='my_scraping_dag' AIRFLOW_CTX_TASK_ID='main_task' AIRFLOW_CTX_EXECUTION_DATE='2023-04-22T00:00:00+00:00' AIRFLOW_CTX_TRY_NUMBER='1' AIRFLOW_CTX_DAG_RUN_ID='scheduled__2023-04-22T00:00:00+00:00'
[2023-12-07T17:23:00.969+0000] {taskinstance.py:1937} ERROR - Task failed with exception
Traceback (most recent call last):
  File "/home/airflow/.local/lib/python3.8/site-packages/airflow/operators/python.py", line 192, in execute
    return_value = self.execute_callable()
  File "/home/airflow/.local/lib/python3.8/site-packages/airflow/operators/python.py", line 209, in execute_callable
    return self.python_callable(*self.op_args, **self.op_kwargs)
  File "/opt/airflow/dags/main.py", line 73, in main
    insert_data_to_db(products, db_params)
  File "/opt/airflow/dags/main.py", line 40, in insert_data_to_db
    with psycopg2.connect(**db_params) as conn:
  File "/home/airflow/.local/lib/python3.8/site-packages/psycopg2/__init__.py", line 122, in connect
    conn = _connect(dsn, connection_factory=connection_factory, **kwasync)
psycopg2.OperationalError: connection to server at "localhost" (127.0.0.1), port 5432 failed: Connection refused
	Is the server running on that host and accepting TCP/IP connections?
connection to server at "localhost" (::1), port 5432 failed: Cannot assign requested address
	Is the server running on that host and accepting TCP/IP connections?

[2023-12-07T17:23:00.992+0000] {taskinstance.py:1400} INFO - Marking task as FAILED. dag_id=my_scraping_dag, task_id=main_task, execution_date=20230422T000000, start_date=20231207T172300, end_date=20231207T172300
[2023-12-07T17:23:01.046+0000] {standard_task_runner.py:104} ERROR - Failed to execute job 2983 for task main_task (connection to server at "localhost" (127.0.0.1), port 5432 failed: Connection refused
	Is the server running on that host and accepting TCP/IP connections?
connection to server at "localhost" (::1), port 5432 failed: Cannot assign requested address
	Is the server running on that host and accepting TCP/IP connections?
; 9573)
[2023-12-07T17:23:01.097+0000] {local_task_job_runner.py:228} INFO - Task exited with return code 1
[2023-12-07T17:23:01.144+0000] {taskinstance.py:2778} INFO - 0 downstream tasks scheduled from follow-on schedule check
[2023-12-07T17:28:42.710+0000] {taskinstance.py:1159} INFO - Dependencies all met for dep_context=non-requeueable deps ti=<TaskInstance: my_scraping_dag.main_task scheduled__2023-04-22T00:00:00+00:00 [queued]>
[2023-12-07T17:28:42.713+0000] {taskinstance.py:1159} INFO - Dependencies all met for dep_context=requeueable deps ti=<TaskInstance: my_scraping_dag.main_task scheduled__2023-04-22T00:00:00+00:00 [queued]>
[2023-12-07T17:28:42.714+0000] {taskinstance.py:1361} INFO - Starting attempt 1 of 1
[2023-12-07T17:28:42.727+0000] {taskinstance.py:1382} INFO - Executing <Task(PythonOperator): main_task> on 2023-04-22 00:00:00+00:00
[2023-12-07T17:28:42.729+0000] {standard_task_runner.py:57} INFO - Started process 10409 to run task
[2023-12-07T17:28:42.731+0000] {standard_task_runner.py:84} INFO - Running: ['***', 'tasks', 'run', 'my_scraping_dag', 'main_task', 'scheduled__2023-04-22T00:00:00+00:00', '--job-id', '3325', '--raw', '--subdir', 'DAGS_FOLDER/main.py', '--cfg-path', '/tmp/tmpodc290lg']
[2023-12-07T17:28:42.733+0000] {standard_task_runner.py:85} INFO - Job 3325: Subtask main_task
[2023-12-07T17:28:42.758+0000] {task_command.py:416} INFO - Running <TaskInstance: my_scraping_dag.main_task scheduled__2023-04-22T00:00:00+00:00 [running]> on host 63b0c7e341c0
[2023-12-07T17:28:42.795+0000] {taskinstance.py:1662} INFO - Exporting env vars: AIRFLOW_CTX_DAG_OWNER='***' AIRFLOW_CTX_DAG_ID='my_scraping_dag' AIRFLOW_CTX_TASK_ID='main_task' AIRFLOW_CTX_EXECUTION_DATE='2023-04-22T00:00:00+00:00' AIRFLOW_CTX_TRY_NUMBER='1' AIRFLOW_CTX_DAG_RUN_ID='scheduled__2023-04-22T00:00:00+00:00'
[2023-12-07T17:28:43.482+0000] {taskinstance.py:1937} ERROR - Task failed with exception
Traceback (most recent call last):
  File "/home/airflow/.local/lib/python3.8/site-packages/airflow/operators/python.py", line 192, in execute
    return_value = self.execute_callable()
  File "/home/airflow/.local/lib/python3.8/site-packages/airflow/operators/python.py", line 209, in execute_callable
    return self.python_callable(*self.op_args, **self.op_kwargs)
  File "/opt/airflow/dags/main.py", line 73, in main
    insert_data_to_db(products, db_params)
  File "/opt/airflow/dags/main.py", line 40, in insert_data_to_db
    with psycopg2.connect(**db_params) as conn:
  File "/home/airflow/.local/lib/python3.8/site-packages/psycopg2/__init__.py", line 122, in connect
    conn = _connect(dsn, connection_factory=connection_factory, **kwasync)
psycopg2.OperationalError: connection to server at "localhost" (127.0.0.1), port 5432 failed: Connection refused
	Is the server running on that host and accepting TCP/IP connections?
connection to server at "localhost" (::1), port 5432 failed: Cannot assign requested address
	Is the server running on that host and accepting TCP/IP connections?

[2023-12-07T17:28:43.495+0000] {taskinstance.py:1400} INFO - Marking task as FAILED. dag_id=my_scraping_dag, task_id=main_task, execution_date=20230422T000000, start_date=20231207T172842, end_date=20231207T172843
[2023-12-07T17:28:43.512+0000] {standard_task_runner.py:104} ERROR - Failed to execute job 3325 for task main_task (connection to server at "localhost" (127.0.0.1), port 5432 failed: Connection refused
	Is the server running on that host and accepting TCP/IP connections?
connection to server at "localhost" (::1), port 5432 failed: Cannot assign requested address
	Is the server running on that host and accepting TCP/IP connections?
; 10409)
[2023-12-07T17:28:43.546+0000] {local_task_job_runner.py:228} INFO - Task exited with return code 1
[2023-12-07T17:28:43.561+0000] {taskinstance.py:2778} INFO - 0 downstream tasks scheduled from follow-on schedule check
[2023-12-09T07:34:38.748+0000] {taskinstance.py:1159} INFO - Dependencies all met for dep_context=non-requeueable deps ti=<TaskInstance: my_scraping_dag.main_task scheduled__2023-04-22T00:00:00+00:00 [queued]>
[2023-12-09T07:34:38.752+0000] {taskinstance.py:1159} INFO - Dependencies all met for dep_context=requeueable deps ti=<TaskInstance: my_scraping_dag.main_task scheduled__2023-04-22T00:00:00+00:00 [queued]>
[2023-12-09T07:34:38.752+0000] {taskinstance.py:1361} INFO - Starting attempt 1 of 1
[2023-12-09T07:34:38.759+0000] {taskinstance.py:1382} INFO - Executing <Task(PythonOperator): main_task> on 2023-04-22 00:00:00+00:00
[2023-12-09T07:34:38.761+0000] {standard_task_runner.py:57} INFO - Started process 821 to run task
[2023-12-09T07:34:38.763+0000] {standard_task_runner.py:84} INFO - Running: ['***', 'tasks', 'run', 'my_scraping_dag', 'main_task', 'scheduled__2023-04-22T00:00:00+00:00', '--job-id', '115', '--raw', '--subdir', 'DAGS_FOLDER/main.py', '--cfg-path', '/tmp/tmpe99849kw']
[2023-12-09T07:34:38.765+0000] {standard_task_runner.py:85} INFO - Job 115: Subtask main_task
[2023-12-09T07:34:38.791+0000] {task_command.py:416} INFO - Running <TaskInstance: my_scraping_dag.main_task scheduled__2023-04-22T00:00:00+00:00 [running]> on host 36b5ef2505c9
[2023-12-09T07:34:38.830+0000] {taskinstance.py:1662} INFO - Exporting env vars: AIRFLOW_CTX_DAG_OWNER='***' AIRFLOW_CTX_DAG_ID='my_scraping_dag' AIRFLOW_CTX_TASK_ID='main_task' AIRFLOW_CTX_EXECUTION_DATE='2023-04-22T00:00:00+00:00' AIRFLOW_CTX_TRY_NUMBER='1' AIRFLOW_CTX_DAG_RUN_ID='scheduled__2023-04-22T00:00:00+00:00'
[2023-12-09T07:34:38.836+0000] {taskinstance.py:1937} ERROR - Task failed with exception
Traceback (most recent call last):
  File "/home/airflow/.local/lib/python3.8/site-packages/airflow/operators/python.py", line 192, in execute
    return_value = self.execute_callable()
  File "/home/airflow/.local/lib/python3.8/site-packages/airflow/operators/python.py", line 209, in execute_callable
    return self.python_callable(*self.op_args, **self.op_kwargs)
  File "/opt/airflow/dags/main.py", line 64, in main
    base_url = Variable.get('base_url')
  File "/home/airflow/.local/lib/python3.8/site-packages/airflow/models/variable.py", line 140, in get
    raise KeyError(f"Variable {key} does not exist")
KeyError: 'Variable base_url does not exist'
[2023-12-09T07:34:38.843+0000] {taskinstance.py:1400} INFO - Marking task as FAILED. dag_id=my_scraping_dag, task_id=main_task, execution_date=20230422T000000, start_date=20231209T073438, end_date=20231209T073438
[2023-12-09T07:34:38.852+0000] {standard_task_runner.py:104} ERROR - Failed to execute job 115 for task main_task ('Variable base_url does not exist'; 821)
[2023-12-09T07:34:38.896+0000] {local_task_job_runner.py:228} INFO - Task exited with return code 1
[2023-12-09T07:34:38.907+0000] {taskinstance.py:2778} INFO - 0 downstream tasks scheduled from follow-on schedule check
