[2023-12-07T16:33:59.900+0000] {taskinstance.py:1159} INFO - Dependencies all met for dep_context=non-requeueable deps ti=<TaskInstance: my_scraping_dag.main_task scheduled__2023-09-25T00:00:00+00:00 [queued]>
[2023-12-07T16:33:59.904+0000] {taskinstance.py:1159} INFO - Dependencies all met for dep_context=requeueable deps ti=<TaskInstance: my_scraping_dag.main_task scheduled__2023-09-25T00:00:00+00:00 [queued]>
[2023-12-07T16:33:59.905+0000] {taskinstance.py:1361} INFO - Starting attempt 1 of 1
[2023-12-07T16:33:59.918+0000] {taskinstance.py:1382} INFO - Executing <Task(PythonOperator): main_task> on 2023-09-25 00:00:00+00:00
[2023-12-07T16:33:59.921+0000] {standard_task_runner.py:57} INFO - Started process 4113 to run task
[2023-12-07T16:33:59.924+0000] {standard_task_runner.py:84} INFO - Running: ['***', 'tasks', 'run', 'my_scraping_dag', 'main_task', 'scheduled__2023-09-25T00:00:00+00:00', '--job-id', '856', '--raw', '--subdir', 'DAGS_FOLDER/main.py', '--cfg-path', '/tmp/tmpcwq1xzvt']
[2023-12-07T16:33:59.926+0000] {standard_task_runner.py:85} INFO - Job 856: Subtask main_task
[2023-12-07T16:33:59.976+0000] {task_command.py:416} INFO - Running <TaskInstance: my_scraping_dag.main_task scheduled__2023-09-25T00:00:00+00:00 [running]> on host 63b0c7e341c0
[2023-12-07T16:34:00.078+0000] {taskinstance.py:1662} INFO - Exporting env vars: AIRFLOW_CTX_DAG_OWNER='***' AIRFLOW_CTX_DAG_ID='my_scraping_dag' AIRFLOW_CTX_TASK_ID='main_task' AIRFLOW_CTX_EXECUTION_DATE='2023-09-25T00:00:00+00:00' AIRFLOW_CTX_TRY_NUMBER='1' AIRFLOW_CTX_DAG_RUN_ID='scheduled__2023-09-25T00:00:00+00:00'
[2023-12-07T16:34:00.079+0000] {taskinstance.py:1937} ERROR - Task failed with exception
Traceback (most recent call last):
  File "/usr/local/lib/python3.8/configparser.py", line 846, in items
    d.update(self._sections[section])
KeyError: 'web'

During handling of the above exception, another exception occurred:

Traceback (most recent call last):
  File "/home/airflow/.local/lib/python3.8/site-packages/airflow/operators/python.py", line 192, in execute
    return_value = self.execute_callable()
  File "/home/airflow/.local/lib/python3.8/site-packages/airflow/operators/python.py", line 209, in execute_callable
    return self.python_callable(*self.op_args, **self.op_kwargs)
  File "/opt/airflow/dags/main.py", line 60, in main
    config = get_config('web')
  File "/opt/airflow/dags/main.py", line 22, in get_config
    return {key: value for key, value in parser.items(section)}
  File "/usr/local/lib/python3.8/configparser.py", line 849, in items
    raise NoSectionError(section)
configparser.NoSectionError: No section: 'web'
[2023-12-07T16:34:00.088+0000] {taskinstance.py:1400} INFO - Marking task as FAILED. dag_id=my_scraping_dag, task_id=main_task, execution_date=20230925T000000, start_date=20231207T163359, end_date=20231207T163400
[2023-12-07T16:34:00.126+0000] {standard_task_runner.py:104} ERROR - Failed to execute job 856 for task main_task (No section: 'web'; 4113)
[2023-12-07T16:34:00.138+0000] {local_task_job_runner.py:228} INFO - Task exited with return code 1
[2023-12-07T16:34:00.158+0000] {taskinstance.py:2778} INFO - 0 downstream tasks scheduled from follow-on schedule check
[2023-12-07T16:42:40.319+0000] {taskinstance.py:1159} INFO - Dependencies all met for dep_context=non-requeueable deps ti=<TaskInstance: my_scraping_dag.main_task scheduled__2023-09-25T00:00:00+00:00 [queued]>
[2023-12-07T16:42:40.326+0000] {taskinstance.py:1159} INFO - Dependencies all met for dep_context=requeueable deps ti=<TaskInstance: my_scraping_dag.main_task scheduled__2023-09-25T00:00:00+00:00 [queued]>
[2023-12-07T16:42:40.326+0000] {taskinstance.py:1361} INFO - Starting attempt 1 of 1
[2023-12-07T16:42:40.336+0000] {taskinstance.py:1382} INFO - Executing <Task(PythonOperator): main_task> on 2023-09-25 00:00:00+00:00
[2023-12-07T16:42:40.340+0000] {standard_task_runner.py:57} INFO - Started process 5008 to run task
[2023-12-07T16:42:40.344+0000] {standard_task_runner.py:84} INFO - Running: ['***', 'tasks', 'run', 'my_scraping_dag', 'main_task', 'scheduled__2023-09-25T00:00:00+00:00', '--job-id', '1201', '--raw', '--subdir', 'DAGS_FOLDER/main.py', '--cfg-path', '/tmp/tmp9nqynabk']
[2023-12-07T16:42:40.347+0000] {standard_task_runner.py:85} INFO - Job 1201: Subtask main_task
[2023-12-07T16:42:40.377+0000] {task_command.py:416} INFO - Running <TaskInstance: my_scraping_dag.main_task scheduled__2023-09-25T00:00:00+00:00 [running]> on host 63b0c7e341c0
[2023-12-07T16:42:40.423+0000] {taskinstance.py:1662} INFO - Exporting env vars: AIRFLOW_CTX_DAG_OWNER='***' AIRFLOW_CTX_DAG_ID='my_scraping_dag' AIRFLOW_CTX_TASK_ID='main_task' AIRFLOW_CTX_EXECUTION_DATE='2023-09-25T00:00:00+00:00' AIRFLOW_CTX_TRY_NUMBER='1' AIRFLOW_CTX_DAG_RUN_ID='scheduled__2023-09-25T00:00:00+00:00'
[2023-12-07T16:42:40.424+0000] {taskinstance.py:1937} ERROR - Task failed with exception
Traceback (most recent call last):
  File "/usr/local/lib/python3.8/configparser.py", line 846, in items
    d.update(self._sections[section])
KeyError: 'web'

During handling of the above exception, another exception occurred:

Traceback (most recent call last):
  File "/home/airflow/.local/lib/python3.8/site-packages/airflow/operators/python.py", line 192, in execute
    return_value = self.execute_callable()
  File "/home/airflow/.local/lib/python3.8/site-packages/airflow/operators/python.py", line 209, in execute_callable
    return self.python_callable(*self.op_args, **self.op_kwargs)
  File "/opt/airflow/dags/main.py", line 60, in main
    config = get_config('web')
  File "/opt/airflow/dags/main.py", line 22, in get_config
    return {key: value for key, value in parser.items(section)}
  File "/usr/local/lib/python3.8/configparser.py", line 849, in items
    raise NoSectionError(section)
configparser.NoSectionError: No section: 'web'
[2023-12-07T16:42:40.429+0000] {taskinstance.py:1400} INFO - Marking task as FAILED. dag_id=my_scraping_dag, task_id=main_task, execution_date=20230925T000000, start_date=20231207T164240, end_date=20231207T164240
[2023-12-07T16:42:40.434+0000] {standard_task_runner.py:104} ERROR - Failed to execute job 1201 for task main_task (No section: 'web'; 5008)
[2023-12-07T16:42:40.475+0000] {local_task_job_runner.py:228} INFO - Task exited with return code 1
[2023-12-07T16:42:40.488+0000] {taskinstance.py:2778} INFO - 0 downstream tasks scheduled from follow-on schedule check
[2023-12-07T17:01:26.768+0000] {taskinstance.py:1159} INFO - Dependencies all met for dep_context=non-requeueable deps ti=<TaskInstance: my_scraping_dag.main_task scheduled__2023-09-25T00:00:00+00:00 [queued]>
[2023-12-07T17:01:26.775+0000] {taskinstance.py:1159} INFO - Dependencies all met for dep_context=requeueable deps ti=<TaskInstance: my_scraping_dag.main_task scheduled__2023-09-25T00:00:00+00:00 [queued]>
[2023-12-07T17:01:26.776+0000] {taskinstance.py:1361} INFO - Starting attempt 1 of 1
[2023-12-07T17:01:26.794+0000] {taskinstance.py:1382} INFO - Executing <Task(PythonOperator): main_task> on 2023-09-25 00:00:00+00:00
[2023-12-07T17:01:26.804+0000] {standard_task_runner.py:57} INFO - Started process 6448 to run task
[2023-12-07T17:01:26.807+0000] {standard_task_runner.py:84} INFO - Running: ['***', 'tasks', 'run', 'my_scraping_dag', 'main_task', 'scheduled__2023-09-25T00:00:00+00:00', '--job-id', '1691', '--raw', '--subdir', 'DAGS_FOLDER/main.py', '--cfg-path', '/tmp/tmpca5ejvxh']
[2023-12-07T17:01:26.810+0000] {standard_task_runner.py:85} INFO - Job 1691: Subtask main_task
[2023-12-07T17:01:26.844+0000] {task_command.py:416} INFO - Running <TaskInstance: my_scraping_dag.main_task scheduled__2023-09-25T00:00:00+00:00 [running]> on host 63b0c7e341c0
[2023-12-07T17:01:26.888+0000] {taskinstance.py:1662} INFO - Exporting env vars: AIRFLOW_CTX_DAG_OWNER='***' AIRFLOW_CTX_DAG_ID='my_scraping_dag' AIRFLOW_CTX_TASK_ID='main_task' AIRFLOW_CTX_EXECUTION_DATE='2023-09-25T00:00:00+00:00' AIRFLOW_CTX_TRY_NUMBER='1' AIRFLOW_CTX_DAG_RUN_ID='scheduled__2023-09-25T00:00:00+00:00'
[2023-12-07T17:01:26.925+0000] {logging_mixin.py:154} INFO - base_url: https://tuncbotanik.com
[2023-12-07T17:01:26.927+0000] {python.py:194} INFO - Done. Returned value was: ('https://tuncbotanik.com', {'User-Agent': 'Mozilla/5.0 (Macintosh; Intel Mac OS X 10_15_7) AppleWebKit/537.36 (KHTML, like Gecko) Chrome/119.0.0.0 Safari/537.36', 'Accept-Language': 'tr-TR,tr;q=0.9,en-US;q=0.8,en;q=0.7'}, {'dbname': 'plant', 'user': 'aozgokme', 'password': '***', 'host': 'localhost', 'port': '5432'})
[2023-12-07T17:01:26.953+0000] {taskinstance.py:1400} INFO - Marking task as SUCCESS. dag_id=my_scraping_dag, task_id=main_task, execution_date=20230925T000000, start_date=20231207T170126, end_date=20231207T170126
[2023-12-07T17:01:26.981+0000] {local_task_job_runner.py:228} INFO - Task exited with return code 0
[2023-12-07T17:01:26.997+0000] {taskinstance.py:2778} INFO - 1 downstream tasks scheduled from follow-on schedule check
[2023-12-07T17:04:48.217+0000] {taskinstance.py:1159} INFO - Dependencies all met for dep_context=non-requeueable deps ti=<TaskInstance: my_scraping_dag.main_task scheduled__2023-09-25T00:00:00+00:00 [queued]>
[2023-12-07T17:04:48.226+0000] {taskinstance.py:1159} INFO - Dependencies all met for dep_context=requeueable deps ti=<TaskInstance: my_scraping_dag.main_task scheduled__2023-09-25T00:00:00+00:00 [queued]>
[2023-12-07T17:04:48.227+0000] {taskinstance.py:1361} INFO - Starting attempt 1 of 1
[2023-12-07T17:04:48.239+0000] {taskinstance.py:1382} INFO - Executing <Task(PythonOperator): main_task> on 2023-09-25 00:00:00+00:00
[2023-12-07T17:04:48.246+0000] {standard_task_runner.py:57} INFO - Started process 7899 to run task
[2023-12-07T17:04:48.251+0000] {standard_task_runner.py:84} INFO - Running: ['***', 'tasks', 'run', 'my_scraping_dag', 'main_task', 'scheduled__2023-09-25T00:00:00+00:00', '--job-id', '2373', '--raw', '--subdir', 'DAGS_FOLDER/main.py', '--cfg-path', '/tmp/tmp9z2qd8ja']
[2023-12-07T17:04:48.253+0000] {standard_task_runner.py:85} INFO - Job 2373: Subtask main_task
[2023-12-07T17:04:48.289+0000] {task_command.py:416} INFO - Running <TaskInstance: my_scraping_dag.main_task scheduled__2023-09-25T00:00:00+00:00 [running]> on host 63b0c7e341c0
[2023-12-07T17:04:48.340+0000] {taskinstance.py:1662} INFO - Exporting env vars: AIRFLOW_CTX_DAG_OWNER='***' AIRFLOW_CTX_DAG_ID='my_scraping_dag' AIRFLOW_CTX_TASK_ID='main_task' AIRFLOW_CTX_EXECUTION_DATE='2023-09-25T00:00:00+00:00' AIRFLOW_CTX_TRY_NUMBER='1' AIRFLOW_CTX_DAG_RUN_ID='scheduled__2023-09-25T00:00:00+00:00'
[2023-12-07T17:04:48.387+0000] {logging_mixin.py:154} INFO - base_url: https://tuncbotanik.com
[2023-12-07T17:04:48.388+0000] {python.py:194} INFO - Done. Returned value was: ('https://tuncbotanik.com', {'User-Agent': 'Mozilla/5.0 (Macintosh; Intel Mac OS X 10_15_7) AppleWebKit/537.36 (KHTML, like Gecko) Chrome/119.0.0.0 Safari/537.36', 'Accept-Language': 'tr-TR,tr;q=0.9,en-US;q=0.8,en;q=0.7'}, {'dbname': 'plant', 'user': 'aozgokme', 'password': '***', 'host': 'localhost', 'port': '5432'})
[2023-12-07T17:04:48.416+0000] {taskinstance.py:1400} INFO - Marking task as SUCCESS. dag_id=my_scraping_dag, task_id=main_task, execution_date=20230925T000000, start_date=20231207T170448, end_date=20231207T170448
[2023-12-07T17:04:48.463+0000] {local_task_job_runner.py:228} INFO - Task exited with return code 0
[2023-12-07T17:04:48.512+0000] {taskinstance.py:2778} INFO - 0 downstream tasks scheduled from follow-on schedule check
[2023-12-07T17:19:14.379+0000] {taskinstance.py:1159} INFO - Dependencies all met for dep_context=non-requeueable deps ti=<TaskInstance: my_scraping_dag.main_task scheduled__2023-09-25T00:00:00+00:00 [queued]>
[2023-12-07T17:19:14.385+0000] {taskinstance.py:1159} INFO - Dependencies all met for dep_context=requeueable deps ti=<TaskInstance: my_scraping_dag.main_task scheduled__2023-09-25T00:00:00+00:00 [queued]>
[2023-12-07T17:19:14.385+0000] {taskinstance.py:1361} INFO - Starting attempt 1 of 1
[2023-12-07T17:19:14.406+0000] {taskinstance.py:1382} INFO - Executing <Task(PythonOperator): main_task> on 2023-09-25 00:00:00+00:00
[2023-12-07T17:19:14.409+0000] {standard_task_runner.py:57} INFO - Started process 9095 to run task
[2023-12-07T17:19:14.412+0000] {standard_task_runner.py:84} INFO - Running: ['***', 'tasks', 'run', 'my_scraping_dag', 'main_task', 'scheduled__2023-09-25T00:00:00+00:00', '--job-id', '2797', '--raw', '--subdir', 'DAGS_FOLDER/main.py', '--cfg-path', '/tmp/tmph5mrzzy0']
[2023-12-07T17:19:14.414+0000] {standard_task_runner.py:85} INFO - Job 2797: Subtask main_task
[2023-12-07T17:19:14.450+0000] {task_command.py:416} INFO - Running <TaskInstance: my_scraping_dag.main_task scheduled__2023-09-25T00:00:00+00:00 [running]> on host 63b0c7e341c0
[2023-12-07T17:19:14.499+0000] {taskinstance.py:1662} INFO - Exporting env vars: AIRFLOW_CTX_DAG_OWNER='***' AIRFLOW_CTX_DAG_ID='my_scraping_dag' AIRFLOW_CTX_TASK_ID='main_task' AIRFLOW_CTX_EXECUTION_DATE='2023-09-25T00:00:00+00:00' AIRFLOW_CTX_TRY_NUMBER='1' AIRFLOW_CTX_DAG_RUN_ID='scheduled__2023-09-25T00:00:00+00:00'
[2023-12-07T17:19:15.333+0000] {taskinstance.py:1937} ERROR - Task failed with exception
Traceback (most recent call last):
  File "/home/airflow/.local/lib/python3.8/site-packages/airflow/operators/python.py", line 192, in execute
    return_value = self.execute_callable()
  File "/home/airflow/.local/lib/python3.8/site-packages/airflow/operators/python.py", line 209, in execute_callable
    return self.python_callable(*self.op_args, **self.op_kwargs)
  File "/opt/airflow/dags/main.py", line 80, in main
    insert_data_to_db(products, db_params)
  File "/opt/airflow/dags/main.py", line 43, in insert_data_to_db
    with psycopg2.connect(**db_params) as conn:
  File "/home/airflow/.local/lib/python3.8/site-packages/psycopg2/__init__.py", line 122, in connect
    conn = _connect(dsn, connection_factory=connection_factory, **kwasync)
psycopg2.OperationalError: connection to server at "localhost" (127.0.0.1), port 5432 failed: Connection refused
	Is the server running on that host and accepting TCP/IP connections?
connection to server at "localhost" (::1), port 5432 failed: Cannot assign requested address
	Is the server running on that host and accepting TCP/IP connections?

[2023-12-07T17:19:15.381+0000] {taskinstance.py:1400} INFO - Marking task as FAILED. dag_id=my_scraping_dag, task_id=main_task, execution_date=20230925T000000, start_date=20231207T171914, end_date=20231207T171915
[2023-12-07T17:19:15.401+0000] {standard_task_runner.py:104} ERROR - Failed to execute job 2797 for task main_task (connection to server at "localhost" (127.0.0.1), port 5432 failed: Connection refused
	Is the server running on that host and accepting TCP/IP connections?
connection to server at "localhost" (::1), port 5432 failed: Cannot assign requested address
	Is the server running on that host and accepting TCP/IP connections?
; 9095)
[2023-12-07T17:19:15.433+0000] {local_task_job_runner.py:228} INFO - Task exited with return code 1
[2023-12-07T17:19:15.462+0000] {taskinstance.py:2778} INFO - 0 downstream tasks scheduled from follow-on schedule check
[2023-12-07T17:23:31.253+0000] {taskinstance.py:1159} INFO - Dependencies all met for dep_context=non-requeueable deps ti=<TaskInstance: my_scraping_dag.main_task scheduled__2023-09-25T00:00:00+00:00 [queued]>
[2023-12-07T17:23:31.261+0000] {taskinstance.py:1159} INFO - Dependencies all met for dep_context=requeueable deps ti=<TaskInstance: my_scraping_dag.main_task scheduled__2023-09-25T00:00:00+00:00 [queued]>
[2023-12-07T17:23:31.264+0000] {taskinstance.py:1361} INFO - Starting attempt 1 of 1
[2023-12-07T17:23:31.275+0000] {taskinstance.py:1382} INFO - Executing <Task(PythonOperator): main_task> on 2023-09-25 00:00:00+00:00
[2023-12-07T17:23:31.285+0000] {standard_task_runner.py:57} INFO - Started process 9896 to run task
[2023-12-07T17:23:31.294+0000] {standard_task_runner.py:84} INFO - Running: ['***', 'tasks', 'run', 'my_scraping_dag', 'main_task', 'scheduled__2023-09-25T00:00:00+00:00', '--job-id', '3139', '--raw', '--subdir', 'DAGS_FOLDER/main.py', '--cfg-path', '/tmp/tmpj_ph139q']
[2023-12-07T17:23:31.300+0000] {standard_task_runner.py:85} INFO - Job 3139: Subtask main_task
[2023-12-07T17:23:31.385+0000] {task_command.py:416} INFO - Running <TaskInstance: my_scraping_dag.main_task scheduled__2023-09-25T00:00:00+00:00 [running]> on host 63b0c7e341c0
[2023-12-07T17:23:31.499+0000] {taskinstance.py:1662} INFO - Exporting env vars: AIRFLOW_CTX_DAG_OWNER='***' AIRFLOW_CTX_DAG_ID='my_scraping_dag' AIRFLOW_CTX_TASK_ID='main_task' AIRFLOW_CTX_EXECUTION_DATE='2023-09-25T00:00:00+00:00' AIRFLOW_CTX_TRY_NUMBER='1' AIRFLOW_CTX_DAG_RUN_ID='scheduled__2023-09-25T00:00:00+00:00'
[2023-12-07T17:23:32.481+0000] {taskinstance.py:1937} ERROR - Task failed with exception
Traceback (most recent call last):
  File "/home/airflow/.local/lib/python3.8/site-packages/airflow/operators/python.py", line 192, in execute
    return_value = self.execute_callable()
  File "/home/airflow/.local/lib/python3.8/site-packages/airflow/operators/python.py", line 209, in execute_callable
    return self.python_callable(*self.op_args, **self.op_kwargs)
  File "/opt/airflow/dags/main.py", line 73, in main
    insert_data_to_db(products, db_params)
  File "/opt/airflow/dags/main.py", line 40, in insert_data_to_db
    with psycopg2.connect(**db_params) as conn:
  File "/home/airflow/.local/lib/python3.8/site-packages/psycopg2/__init__.py", line 122, in connect
    conn = _connect(dsn, connection_factory=connection_factory, **kwasync)
psycopg2.OperationalError: connection to server at "localhost" (127.0.0.1), port 5432 failed: Connection refused
	Is the server running on that host and accepting TCP/IP connections?
connection to server at "localhost" (::1), port 5432 failed: Cannot assign requested address
	Is the server running on that host and accepting TCP/IP connections?

[2023-12-07T17:23:32.486+0000] {taskinstance.py:1400} INFO - Marking task as FAILED. dag_id=my_scraping_dag, task_id=main_task, execution_date=20230925T000000, start_date=20231207T172331, end_date=20231207T172332
[2023-12-07T17:23:32.492+0000] {standard_task_runner.py:104} ERROR - Failed to execute job 3139 for task main_task (connection to server at "localhost" (127.0.0.1), port 5432 failed: Connection refused
	Is the server running on that host and accepting TCP/IP connections?
connection to server at "localhost" (::1), port 5432 failed: Cannot assign requested address
	Is the server running on that host and accepting TCP/IP connections?
; 9896)
[2023-12-07T17:23:32.532+0000] {local_task_job_runner.py:228} INFO - Task exited with return code 1
[2023-12-07T17:23:32.540+0000] {taskinstance.py:2778} INFO - 0 downstream tasks scheduled from follow-on schedule check
[2023-12-07T17:29:09.663+0000] {taskinstance.py:1159} INFO - Dependencies all met for dep_context=non-requeueable deps ti=<TaskInstance: my_scraping_dag.main_task scheduled__2023-09-25T00:00:00+00:00 [queued]>
[2023-12-07T17:29:09.678+0000] {taskinstance.py:1159} INFO - Dependencies all met for dep_context=requeueable deps ti=<TaskInstance: my_scraping_dag.main_task scheduled__2023-09-25T00:00:00+00:00 [queued]>
[2023-12-07T17:29:09.678+0000] {taskinstance.py:1361} INFO - Starting attempt 1 of 1
[2023-12-07T17:29:09.688+0000] {taskinstance.py:1382} INFO - Executing <Task(PythonOperator): main_task> on 2023-09-25 00:00:00+00:00
[2023-12-07T17:29:09.695+0000] {standard_task_runner.py:57} INFO - Started process 10727 to run task
[2023-12-07T17:29:09.698+0000] {standard_task_runner.py:84} INFO - Running: ['***', 'tasks', 'run', 'my_scraping_dag', 'main_task', 'scheduled__2023-09-25T00:00:00+00:00', '--job-id', '3481', '--raw', '--subdir', 'DAGS_FOLDER/main.py', '--cfg-path', '/tmp/tmpfie38q65']
[2023-12-07T17:29:09.701+0000] {standard_task_runner.py:85} INFO - Job 3481: Subtask main_task
[2023-12-07T17:29:09.757+0000] {task_command.py:416} INFO - Running <TaskInstance: my_scraping_dag.main_task scheduled__2023-09-25T00:00:00+00:00 [running]> on host 63b0c7e341c0
[2023-12-07T17:29:10.071+0000] {taskinstance.py:1662} INFO - Exporting env vars: AIRFLOW_CTX_DAG_OWNER='***' AIRFLOW_CTX_DAG_ID='my_scraping_dag' AIRFLOW_CTX_TASK_ID='main_task' AIRFLOW_CTX_EXECUTION_DATE='2023-09-25T00:00:00+00:00' AIRFLOW_CTX_TRY_NUMBER='1' AIRFLOW_CTX_DAG_RUN_ID='scheduled__2023-09-25T00:00:00+00:00'
[2023-12-07T17:29:10.809+0000] {taskinstance.py:1937} ERROR - Task failed with exception
Traceback (most recent call last):
  File "/home/airflow/.local/lib/python3.8/site-packages/airflow/operators/python.py", line 192, in execute
    return_value = self.execute_callable()
  File "/home/airflow/.local/lib/python3.8/site-packages/airflow/operators/python.py", line 209, in execute_callable
    return self.python_callable(*self.op_args, **self.op_kwargs)
  File "/opt/airflow/dags/main.py", line 73, in main
    insert_data_to_db(products, db_params)
  File "/opt/airflow/dags/main.py", line 40, in insert_data_to_db
    with psycopg2.connect(**db_params) as conn:
  File "/home/airflow/.local/lib/python3.8/site-packages/psycopg2/__init__.py", line 122, in connect
    conn = _connect(dsn, connection_factory=connection_factory, **kwasync)
psycopg2.OperationalError: connection to server at "localhost" (127.0.0.1), port 5432 failed: Connection refused
	Is the server running on that host and accepting TCP/IP connections?
connection to server at "localhost" (::1), port 5432 failed: Cannot assign requested address
	Is the server running on that host and accepting TCP/IP connections?

[2023-12-07T17:29:10.814+0000] {taskinstance.py:1400} INFO - Marking task as FAILED. dag_id=my_scraping_dag, task_id=main_task, execution_date=20230925T000000, start_date=20231207T172909, end_date=20231207T172910
[2023-12-07T17:29:10.819+0000] {standard_task_runner.py:104} ERROR - Failed to execute job 3481 for task main_task (connection to server at "localhost" (127.0.0.1), port 5432 failed: Connection refused
	Is the server running on that host and accepting TCP/IP connections?
connection to server at "localhost" (::1), port 5432 failed: Cannot assign requested address
	Is the server running on that host and accepting TCP/IP connections?
; 10727)
[2023-12-07T17:29:10.848+0000] {local_task_job_runner.py:228} INFO - Task exited with return code 1
[2023-12-07T17:29:10.857+0000] {taskinstance.py:2778} INFO - 0 downstream tasks scheduled from follow-on schedule check
