[2023-12-07T14:46:14.173+0000] {taskinstance.py:1159} INFO - Dependencies all met for dep_context=non-requeueable deps ti=<TaskInstance: my_scraping_dag.main_task scheduled__2023-03-17T00:00:00+00:00 [queued]>
[2023-12-07T14:46:14.177+0000] {taskinstance.py:1159} INFO - Dependencies all met for dep_context=requeueable deps ti=<TaskInstance: my_scraping_dag.main_task scheduled__2023-03-17T00:00:00+00:00 [queued]>
[2023-12-07T14:46:14.177+0000] {taskinstance.py:1361} INFO - Starting attempt 1 of 1
[2023-12-07T14:46:14.182+0000] {taskinstance.py:1382} INFO - Executing <Task(PythonOperator): main_task> on 2023-03-17 00:00:00+00:00
[2023-12-07T14:46:14.184+0000] {standard_task_runner.py:57} INFO - Started process 553 to run task
[2023-12-07T14:46:14.186+0000] {standard_task_runner.py:84} INFO - Running: ['***', 'tasks', 'run', 'my_scraping_dag', 'main_task', 'scheduled__2023-03-17T00:00:00+00:00', '--job-id', '87', '--raw', '--subdir', 'DAGS_FOLDER/main.py', '--cfg-path', '/tmp/tmpfak2jmvy']
[2023-12-07T14:46:14.187+0000] {standard_task_runner.py:85} INFO - Job 87: Subtask main_task
[2023-12-07T14:46:14.208+0000] {task_command.py:416} INFO - Running <TaskInstance: my_scraping_dag.main_task scheduled__2023-03-17T00:00:00+00:00 [running]> on host 63b0c7e341c0
[2023-12-07T14:46:14.236+0000] {taskinstance.py:1662} INFO - Exporting env vars: AIRFLOW_CTX_DAG_OWNER='***' AIRFLOW_CTX_DAG_ID='my_scraping_dag' AIRFLOW_CTX_TASK_ID='main_task' AIRFLOW_CTX_EXECUTION_DATE='2023-03-17T00:00:00+00:00' AIRFLOW_CTX_TRY_NUMBER='1' AIRFLOW_CTX_DAG_RUN_ID='scheduled__2023-03-17T00:00:00+00:00'
[2023-12-07T14:46:14.237+0000] {taskinstance.py:1937} ERROR - Task failed with exception
Traceback (most recent call last):
  File "/usr/local/lib/python3.8/configparser.py", line 846, in items
    d.update(self._sections[section])
KeyError: 'web'

During handling of the above exception, another exception occurred:

Traceback (most recent call last):
  File "/home/airflow/.local/lib/python3.8/site-packages/airflow/operators/python.py", line 192, in execute
    return_value = self.execute_callable()
  File "/home/airflow/.local/lib/python3.8/site-packages/airflow/operators/python.py", line 209, in execute_callable
    return self.python_callable(*self.op_args, **self.op_kwargs)
  File "/opt/airflow/dags/main.py", line 61, in main
    config = get_config('web')
  File "/opt/airflow/dags/main.py", line 23, in get_config
    return {key: value for key, value in parser.items(section)}
  File "/usr/local/lib/python3.8/configparser.py", line 849, in items
    raise NoSectionError(section)
configparser.NoSectionError: No section: 'web'
[2023-12-07T14:46:14.241+0000] {taskinstance.py:1400} INFO - Marking task as FAILED. dag_id=my_scraping_dag, task_id=main_task, execution_date=20230317T000000, start_date=20231207T144614, end_date=20231207T144614
[2023-12-07T14:46:14.245+0000] {standard_task_runner.py:104} ERROR - Failed to execute job 87 for task main_task (No section: 'web'; 553)
[2023-12-07T14:46:14.279+0000] {local_task_job_runner.py:228} INFO - Task exited with return code 1
[2023-12-07T14:46:14.291+0000] {taskinstance.py:2778} INFO - 0 downstream tasks scheduled from follow-on schedule check
[2023-12-07T14:52:01.149+0000] {taskinstance.py:1159} INFO - Dependencies all met for dep_context=non-requeueable deps ti=<TaskInstance: my_scraping_dag.main_task scheduled__2023-03-17T00:00:00+00:00 [queued]>
[2023-12-07T14:52:01.153+0000] {taskinstance.py:1159} INFO - Dependencies all met for dep_context=requeueable deps ti=<TaskInstance: my_scraping_dag.main_task scheduled__2023-03-17T00:00:00+00:00 [queued]>
[2023-12-07T14:52:01.154+0000] {taskinstance.py:1361} INFO - Starting attempt 1 of 1
[2023-12-07T14:52:01.163+0000] {taskinstance.py:1382} INFO - Executing <Task(PythonOperator): main_task> on 2023-03-17 00:00:00+00:00
[2023-12-07T14:52:01.166+0000] {standard_task_runner.py:57} INFO - Started process 905 to run task
[2023-12-07T14:52:01.168+0000] {standard_task_runner.py:84} INFO - Running: ['***', 'tasks', 'run', 'my_scraping_dag', 'main_task', 'scheduled__2023-03-17T00:00:00+00:00', '--job-id', '186', '--raw', '--subdir', 'DAGS_FOLDER/main.py', '--cfg-path', '/tmp/tmppkxrj7na']
[2023-12-07T14:52:01.170+0000] {standard_task_runner.py:85} INFO - Job 186: Subtask main_task
[2023-12-07T14:52:01.196+0000] {task_command.py:416} INFO - Running <TaskInstance: my_scraping_dag.main_task scheduled__2023-03-17T00:00:00+00:00 [running]> on host 63b0c7e341c0
[2023-12-07T14:52:01.232+0000] {taskinstance.py:1662} INFO - Exporting env vars: AIRFLOW_CTX_DAG_OWNER='***' AIRFLOW_CTX_DAG_ID='my_scraping_dag' AIRFLOW_CTX_TASK_ID='main_task' AIRFLOW_CTX_EXECUTION_DATE='2023-03-17T00:00:00+00:00' AIRFLOW_CTX_TRY_NUMBER='1' AIRFLOW_CTX_DAG_RUN_ID='scheduled__2023-03-17T00:00:00+00:00'
[2023-12-07T14:52:01.233+0000] {taskinstance.py:1937} ERROR - Task failed with exception
Traceback (most recent call last):
  File "/usr/local/lib/python3.8/configparser.py", line 846, in items
    d.update(self._sections[section])
KeyError: 'web'

During handling of the above exception, another exception occurred:

Traceback (most recent call last):
  File "/home/airflow/.local/lib/python3.8/site-packages/airflow/operators/python.py", line 192, in execute
    return_value = self.execute_callable()
  File "/home/airflow/.local/lib/python3.8/site-packages/airflow/operators/python.py", line 209, in execute_callable
    return self.python_callable(*self.op_args, **self.op_kwargs)
  File "/opt/airflow/dags/main.py", line 61, in main
    config = get_config('web')
  File "/opt/airflow/dags/main.py", line 23, in get_config
    return {key: value for key, value in parser.items(section)}
  File "/usr/local/lib/python3.8/configparser.py", line 849, in items
    raise NoSectionError(section)
configparser.NoSectionError: No section: 'web'
[2023-12-07T14:52:01.238+0000] {taskinstance.py:1400} INFO - Marking task as FAILED. dag_id=my_scraping_dag, task_id=main_task, execution_date=20230317T000000, start_date=20231207T145201, end_date=20231207T145201
[2023-12-07T14:52:01.245+0000] {standard_task_runner.py:104} ERROR - Failed to execute job 186 for task main_task (No section: 'web'; 905)
[2023-12-07T14:52:01.260+0000] {local_task_job_runner.py:228} INFO - Task exited with return code 1
[2023-12-07T14:52:01.284+0000] {taskinstance.py:2778} INFO - 0 downstream tasks scheduled from follow-on schedule check
[2023-12-07T15:00:12.308+0000] {taskinstance.py:1159} INFO - Dependencies all met for dep_context=non-requeueable deps ti=<TaskInstance: my_scraping_dag.main_task scheduled__2023-03-17T00:00:00+00:00 [queued]>
[2023-12-07T15:00:12.312+0000] {taskinstance.py:1159} INFO - Dependencies all met for dep_context=requeueable deps ti=<TaskInstance: my_scraping_dag.main_task scheduled__2023-03-17T00:00:00+00:00 [queued]>
[2023-12-07T15:00:12.312+0000] {taskinstance.py:1361} INFO - Starting attempt 1 of 1
[2023-12-07T15:00:12.319+0000] {taskinstance.py:1382} INFO - Executing <Task(PythonOperator): main_task> on 2023-03-17 00:00:00+00:00
[2023-12-07T15:00:12.321+0000] {standard_task_runner.py:57} INFO - Started process 1527 to run task
[2023-12-07T15:00:12.323+0000] {standard_task_runner.py:84} INFO - Running: ['***', 'tasks', 'run', 'my_scraping_dag', 'main_task', 'scheduled__2023-03-17T00:00:00+00:00', '--job-id', '391', '--raw', '--subdir', 'DAGS_FOLDER/main.py', '--cfg-path', '/tmp/tmpwlm9w212']
[2023-12-07T15:00:12.325+0000] {standard_task_runner.py:85} INFO - Job 391: Subtask main_task
[2023-12-07T15:00:12.346+0000] {task_command.py:416} INFO - Running <TaskInstance: my_scraping_dag.main_task scheduled__2023-03-17T00:00:00+00:00 [running]> on host 63b0c7e341c0
[2023-12-07T15:00:12.376+0000] {taskinstance.py:1662} INFO - Exporting env vars: AIRFLOW_CTX_DAG_OWNER='***' AIRFLOW_CTX_DAG_ID='my_scraping_dag' AIRFLOW_CTX_TASK_ID='main_task' AIRFLOW_CTX_EXECUTION_DATE='2023-03-17T00:00:00+00:00' AIRFLOW_CTX_TRY_NUMBER='1' AIRFLOW_CTX_DAG_RUN_ID='scheduled__2023-03-17T00:00:00+00:00'
[2023-12-07T15:00:12.377+0000] {taskinstance.py:1937} ERROR - Task failed with exception
Traceback (most recent call last):
  File "/usr/local/lib/python3.8/configparser.py", line 846, in items
    d.update(self._sections[section])
KeyError: 'web'

During handling of the above exception, another exception occurred:

Traceback (most recent call last):
  File "/home/airflow/.local/lib/python3.8/site-packages/airflow/operators/python.py", line 192, in execute
    return_value = self.execute_callable()
  File "/home/airflow/.local/lib/python3.8/site-packages/airflow/operators/python.py", line 209, in execute_callable
    return self.python_callable(*self.op_args, **self.op_kwargs)
  File "/opt/airflow/dags/main.py", line 60, in main
    config = get_config('web')
  File "/opt/airflow/dags/main.py", line 22, in get_config
    return {key: value for key, value in parser.items(section)}
  File "/usr/local/lib/python3.8/configparser.py", line 849, in items
    raise NoSectionError(section)
configparser.NoSectionError: No section: 'web'
[2023-12-07T15:00:12.381+0000] {taskinstance.py:1400} INFO - Marking task as FAILED. dag_id=my_scraping_dag, task_id=main_task, execution_date=20230317T000000, start_date=20231207T150012, end_date=20231207T150012
[2023-12-07T15:00:12.385+0000] {standard_task_runner.py:104} ERROR - Failed to execute job 391 for task main_task (No section: 'web'; 1527)
[2023-12-07T15:00:12.415+0000] {local_task_job_runner.py:228} INFO - Task exited with return code 1
[2023-12-07T15:00:12.427+0000] {taskinstance.py:2778} INFO - 0 downstream tasks scheduled from follow-on schedule check
[2023-12-07T15:11:00.124+0000] {taskinstance.py:1159} INFO - Dependencies all met for dep_context=non-requeueable deps ti=<TaskInstance: my_scraping_dag.main_task scheduled__2023-03-17T00:00:00+00:00 [queued]>
[2023-12-07T15:11:00.131+0000] {taskinstance.py:1159} INFO - Dependencies all met for dep_context=requeueable deps ti=<TaskInstance: my_scraping_dag.main_task scheduled__2023-03-17T00:00:00+00:00 [queued]>
[2023-12-07T15:11:00.132+0000] {taskinstance.py:1361} INFO - Starting attempt 1 of 1
[2023-12-07T15:11:00.143+0000] {taskinstance.py:1382} INFO - Executing <Task(PythonOperator): main_task> on 2023-03-17 00:00:00+00:00
[2023-12-07T15:11:00.156+0000] {standard_task_runner.py:57} INFO - Started process 1996 to run task
[2023-12-07T15:11:00.161+0000] {standard_task_runner.py:84} INFO - Running: ['***', 'tasks', 'run', 'my_scraping_dag', 'main_task', 'scheduled__2023-03-17T00:00:00+00:00', '--job-id', '497', '--raw', '--subdir', 'DAGS_FOLDER/main.py', '--cfg-path', '/tmp/tmpdqjzsrti']
[2023-12-07T15:11:00.175+0000] {standard_task_runner.py:85} INFO - Job 497: Subtask main_task
[2023-12-07T15:11:00.226+0000] {task_command.py:416} INFO - Running <TaskInstance: my_scraping_dag.main_task scheduled__2023-03-17T00:00:00+00:00 [running]> on host 63b0c7e341c0
[2023-12-07T15:11:00.284+0000] {taskinstance.py:1662} INFO - Exporting env vars: AIRFLOW_CTX_DAG_OWNER='***' AIRFLOW_CTX_DAG_ID='my_scraping_dag' AIRFLOW_CTX_TASK_ID='main_task' AIRFLOW_CTX_EXECUTION_DATE='2023-03-17T00:00:00+00:00' AIRFLOW_CTX_TRY_NUMBER='1' AIRFLOW_CTX_DAG_RUN_ID='scheduled__2023-03-17T00:00:00+00:00'
[2023-12-07T15:11:00.285+0000] {taskinstance.py:1937} ERROR - Task failed with exception
Traceback (most recent call last):
  File "/usr/local/lib/python3.8/configparser.py", line 846, in items
    d.update(self._sections[section])
KeyError: 'web'

During handling of the above exception, another exception occurred:

Traceback (most recent call last):
  File "/home/airflow/.local/lib/python3.8/site-packages/airflow/operators/python.py", line 192, in execute
    return_value = self.execute_callable()
  File "/home/airflow/.local/lib/python3.8/site-packages/airflow/operators/python.py", line 209, in execute_callable
    return self.python_callable(*self.op_args, **self.op_kwargs)
  File "/opt/airflow/dags/main.py", line 63, in main
    config = get_config('web')
  File "/opt/airflow/dags/main.py", line 14, in get_config
    return {key: value for key, value in parser.items(section)}
  File "/usr/local/lib/python3.8/configparser.py", line 849, in items
    raise NoSectionError(section)
configparser.NoSectionError: No section: 'web'
[2023-12-07T15:11:00.293+0000] {taskinstance.py:1400} INFO - Marking task as FAILED. dag_id=my_scraping_dag, task_id=main_task, execution_date=20230317T000000, start_date=20231207T151100, end_date=20231207T151100
[2023-12-07T15:11:00.300+0000] {standard_task_runner.py:104} ERROR - Failed to execute job 497 for task main_task (No section: 'web'; 1996)
[2023-12-07T15:11:00.342+0000] {local_task_job_runner.py:228} INFO - Task exited with return code 1
[2023-12-07T15:11:00.351+0000] {taskinstance.py:2778} INFO - 0 downstream tasks scheduled from follow-on schedule check
[2023-12-07T15:12:23.424+0000] {taskinstance.py:1159} INFO - Dependencies all met for dep_context=non-requeueable deps ti=<TaskInstance: my_scraping_dag.main_task scheduled__2023-03-17T00:00:00+00:00 [queued]>
[2023-12-07T15:12:23.427+0000] {taskinstance.py:1159} INFO - Dependencies all met for dep_context=requeueable deps ti=<TaskInstance: my_scraping_dag.main_task scheduled__2023-03-17T00:00:00+00:00 [queued]>
[2023-12-07T15:12:23.428+0000] {taskinstance.py:1361} INFO - Starting attempt 1 of 1
[2023-12-07T15:12:23.435+0000] {taskinstance.py:1382} INFO - Executing <Task(PythonOperator): main_task> on 2023-03-17 00:00:00+00:00
[2023-12-07T15:12:23.438+0000] {standard_task_runner.py:57} INFO - Started process 2219 to run task
[2023-12-07T15:12:23.440+0000] {standard_task_runner.py:84} INFO - Running: ['***', 'tasks', 'run', 'my_scraping_dag', 'main_task', 'scheduled__2023-03-17T00:00:00+00:00', '--job-id', '586', '--raw', '--subdir', 'DAGS_FOLDER/main.py', '--cfg-path', '/tmp/tmphuka0qv5']
[2023-12-07T15:12:23.442+0000] {standard_task_runner.py:85} INFO - Job 586: Subtask main_task
[2023-12-07T15:12:23.470+0000] {task_command.py:416} INFO - Running <TaskInstance: my_scraping_dag.main_task scheduled__2023-03-17T00:00:00+00:00 [running]> on host 63b0c7e341c0
[2023-12-07T15:12:23.501+0000] {taskinstance.py:1662} INFO - Exporting env vars: AIRFLOW_CTX_DAG_OWNER='***' AIRFLOW_CTX_DAG_ID='my_scraping_dag' AIRFLOW_CTX_TASK_ID='main_task' AIRFLOW_CTX_EXECUTION_DATE='2023-03-17T00:00:00+00:00' AIRFLOW_CTX_TRY_NUMBER='1' AIRFLOW_CTX_DAG_RUN_ID='scheduled__2023-03-17T00:00:00+00:00'
[2023-12-07T15:12:23.502+0000] {taskinstance.py:1937} ERROR - Task failed with exception
Traceback (most recent call last):
  File "/usr/local/lib/python3.8/configparser.py", line 846, in items
    d.update(self._sections[section])
KeyError: 'web'

During handling of the above exception, another exception occurred:

Traceback (most recent call last):
  File "/home/airflow/.local/lib/python3.8/site-packages/airflow/operators/python.py", line 192, in execute
    return_value = self.execute_callable()
  File "/home/airflow/.local/lib/python3.8/site-packages/airflow/operators/python.py", line 209, in execute_callable
    return self.python_callable(*self.op_args, **self.op_kwargs)
  File "/opt/airflow/dags/main.py", line 63, in main
    config = get_config('web')
  File "/opt/airflow/dags/main.py", line 14, in get_config
    return {key: value for key, value in parser.items(section)}
  File "/usr/local/lib/python3.8/configparser.py", line 849, in items
    raise NoSectionError(section)
configparser.NoSectionError: No section: 'web'
[2023-12-07T15:12:23.506+0000] {taskinstance.py:1400} INFO - Marking task as FAILED. dag_id=my_scraping_dag, task_id=main_task, execution_date=20230317T000000, start_date=20231207T151223, end_date=20231207T151223
[2023-12-07T15:12:23.510+0000] {standard_task_runner.py:104} ERROR - Failed to execute job 586 for task main_task (No section: 'web'; 2219)
[2023-12-07T15:12:23.533+0000] {local_task_job_runner.py:228} INFO - Task exited with return code 1
[2023-12-07T15:12:23.541+0000] {taskinstance.py:2778} INFO - 0 downstream tasks scheduled from follow-on schedule check
[2023-12-07T16:31:50.962+0000] {taskinstance.py:1159} INFO - Dependencies all met for dep_context=non-requeueable deps ti=<TaskInstance: my_scraping_dag.main_task scheduled__2023-03-17T00:00:00+00:00 [queued]>
[2023-12-07T16:31:50.965+0000] {taskinstance.py:1159} INFO - Dependencies all met for dep_context=requeueable deps ti=<TaskInstance: my_scraping_dag.main_task scheduled__2023-03-17T00:00:00+00:00 [queued]>
[2023-12-07T16:31:50.966+0000] {taskinstance.py:1361} INFO - Starting attempt 1 of 1
[2023-12-07T16:31:50.971+0000] {taskinstance.py:1382} INFO - Executing <Task(PythonOperator): main_task> on 2023-03-17 00:00:00+00:00
[2023-12-07T16:31:50.973+0000] {standard_task_runner.py:57} INFO - Started process 3669 to run task
[2023-12-07T16:31:50.975+0000] {standard_task_runner.py:84} INFO - Running: ['***', 'tasks', 'run', 'my_scraping_dag', 'main_task', 'scheduled__2023-03-17T00:00:00+00:00', '--job-id', '664', '--raw', '--subdir', 'DAGS_FOLDER/main.py', '--cfg-path', '/tmp/tmpb88om6eg']
[2023-12-07T16:31:50.977+0000] {standard_task_runner.py:85} INFO - Job 664: Subtask main_task
[2023-12-07T16:31:50.997+0000] {task_command.py:416} INFO - Running <TaskInstance: my_scraping_dag.main_task scheduled__2023-03-17T00:00:00+00:00 [running]> on host 63b0c7e341c0
[2023-12-07T16:31:51.028+0000] {taskinstance.py:1662} INFO - Exporting env vars: AIRFLOW_CTX_DAG_OWNER='***' AIRFLOW_CTX_DAG_ID='my_scraping_dag' AIRFLOW_CTX_TASK_ID='main_task' AIRFLOW_CTX_EXECUTION_DATE='2023-03-17T00:00:00+00:00' AIRFLOW_CTX_TRY_NUMBER='1' AIRFLOW_CTX_DAG_RUN_ID='scheduled__2023-03-17T00:00:00+00:00'
[2023-12-07T16:31:51.029+0000] {taskinstance.py:1937} ERROR - Task failed with exception
Traceback (most recent call last):
  File "/usr/local/lib/python3.8/configparser.py", line 846, in items
    d.update(self._sections[section])
KeyError: 'web'

During handling of the above exception, another exception occurred:

Traceback (most recent call last):
  File "/home/airflow/.local/lib/python3.8/site-packages/airflow/operators/python.py", line 192, in execute
    return_value = self.execute_callable()
  File "/home/airflow/.local/lib/python3.8/site-packages/airflow/operators/python.py", line 209, in execute_callable
    return self.python_callable(*self.op_args, **self.op_kwargs)
  File "/opt/airflow/dags/main.py", line 60, in main
    config = get_config('web')
  File "/opt/airflow/dags/main.py", line 22, in get_config
    return {key: value for key, value in parser.items(section)}
  File "/usr/local/lib/python3.8/configparser.py", line 849, in items
    raise NoSectionError(section)
configparser.NoSectionError: No section: 'web'
[2023-12-07T16:31:51.033+0000] {taskinstance.py:1400} INFO - Marking task as FAILED. dag_id=my_scraping_dag, task_id=main_task, execution_date=20230317T000000, start_date=20231207T163150, end_date=20231207T163151
[2023-12-07T16:31:51.038+0000] {standard_task_runner.py:104} ERROR - Failed to execute job 664 for task main_task (No section: 'web'; 3669)
[2023-12-07T16:31:51.068+0000] {local_task_job_runner.py:228} INFO - Task exited with return code 1
[2023-12-07T16:31:51.080+0000] {taskinstance.py:2778} INFO - 0 downstream tasks scheduled from follow-on schedule check
[2023-12-07T16:41:17.518+0000] {taskinstance.py:1159} INFO - Dependencies all met for dep_context=non-requeueable deps ti=<TaskInstance: my_scraping_dag.main_task scheduled__2023-03-17T00:00:00+00:00 [queued]>
[2023-12-07T16:41:17.522+0000] {taskinstance.py:1159} INFO - Dependencies all met for dep_context=requeueable deps ti=<TaskInstance: my_scraping_dag.main_task scheduled__2023-03-17T00:00:00+00:00 [queued]>
[2023-12-07T16:41:17.522+0000] {taskinstance.py:1361} INFO - Starting attempt 1 of 1
[2023-12-07T16:41:17.529+0000] {taskinstance.py:1382} INFO - Executing <Task(PythonOperator): main_task> on 2023-03-17 00:00:00+00:00
[2023-12-07T16:41:17.531+0000] {standard_task_runner.py:57} INFO - Started process 4585 to run task
[2023-12-07T16:41:17.533+0000] {standard_task_runner.py:84} INFO - Running: ['***', 'tasks', 'run', 'my_scraping_dag', 'main_task', 'scheduled__2023-03-17T00:00:00+00:00', '--job-id', '1006', '--raw', '--subdir', 'DAGS_FOLDER/main.py', '--cfg-path', '/tmp/tmpf6n4xrqw']
[2023-12-07T16:41:17.535+0000] {standard_task_runner.py:85} INFO - Job 1006: Subtask main_task
[2023-12-07T16:41:17.560+0000] {task_command.py:416} INFO - Running <TaskInstance: my_scraping_dag.main_task scheduled__2023-03-17T00:00:00+00:00 [running]> on host 63b0c7e341c0
[2023-12-07T16:41:17.598+0000] {taskinstance.py:1662} INFO - Exporting env vars: AIRFLOW_CTX_DAG_OWNER='***' AIRFLOW_CTX_DAG_ID='my_scraping_dag' AIRFLOW_CTX_TASK_ID='main_task' AIRFLOW_CTX_EXECUTION_DATE='2023-03-17T00:00:00+00:00' AIRFLOW_CTX_TRY_NUMBER='1' AIRFLOW_CTX_DAG_RUN_ID='scheduled__2023-03-17T00:00:00+00:00'
[2023-12-07T16:41:17.599+0000] {taskinstance.py:1937} ERROR - Task failed with exception
Traceback (most recent call last):
  File "/usr/local/lib/python3.8/configparser.py", line 846, in items
    d.update(self._sections[section])
KeyError: 'web'

During handling of the above exception, another exception occurred:

Traceback (most recent call last):
  File "/home/airflow/.local/lib/python3.8/site-packages/airflow/operators/python.py", line 192, in execute
    return_value = self.execute_callable()
  File "/home/airflow/.local/lib/python3.8/site-packages/airflow/operators/python.py", line 209, in execute_callable
    return self.python_callable(*self.op_args, **self.op_kwargs)
  File "/opt/airflow/dags/main.py", line 60, in main
    config = get_config('web')
  File "/opt/airflow/dags/main.py", line 22, in get_config
    return {key: value for key, value in parser.items(section)}
  File "/usr/local/lib/python3.8/configparser.py", line 849, in items
    raise NoSectionError(section)
configparser.NoSectionError: No section: 'web'
[2023-12-07T16:41:17.605+0000] {taskinstance.py:1400} INFO - Marking task as FAILED. dag_id=my_scraping_dag, task_id=main_task, execution_date=20230317T000000, start_date=20231207T164117, end_date=20231207T164117
[2023-12-07T16:41:17.612+0000] {standard_task_runner.py:104} ERROR - Failed to execute job 1006 for task main_task (No section: 'web'; 4585)
[2023-12-07T16:41:17.625+0000] {local_task_job_runner.py:228} INFO - Task exited with return code 1
[2023-12-07T16:41:17.666+0000] {taskinstance.py:2778} INFO - 0 downstream tasks scheduled from follow-on schedule check
[2023-12-07T17:00:18.362+0000] {taskinstance.py:1159} INFO - Dependencies all met for dep_context=non-requeueable deps ti=<TaskInstance: my_scraping_dag.main_task scheduled__2023-03-17T00:00:00+00:00 [queued]>
[2023-12-07T17:00:18.366+0000] {taskinstance.py:1159} INFO - Dependencies all met for dep_context=requeueable deps ti=<TaskInstance: my_scraping_dag.main_task scheduled__2023-03-17T00:00:00+00:00 [queued]>
[2023-12-07T17:00:18.366+0000] {taskinstance.py:1361} INFO - Starting attempt 1 of 1
[2023-12-07T17:00:18.374+0000] {taskinstance.py:1382} INFO - Executing <Task(PythonOperator): main_task> on 2023-03-17 00:00:00+00:00
[2023-12-07T17:00:18.377+0000] {standard_task_runner.py:57} INFO - Started process 5741 to run task
[2023-12-07T17:00:18.379+0000] {standard_task_runner.py:84} INFO - Running: ['***', 'tasks', 'run', 'my_scraping_dag', 'main_task', 'scheduled__2023-03-17T00:00:00+00:00', '--job-id', '1350', '--raw', '--subdir', 'DAGS_FOLDER/main.py', '--cfg-path', '/tmp/tmpp4z9dh5c']
[2023-12-07T17:00:18.382+0000] {standard_task_runner.py:85} INFO - Job 1350: Subtask main_task
[2023-12-07T17:00:18.407+0000] {task_command.py:416} INFO - Running <TaskInstance: my_scraping_dag.main_task scheduled__2023-03-17T00:00:00+00:00 [running]> on host 63b0c7e341c0
[2023-12-07T17:00:18.436+0000] {taskinstance.py:1662} INFO - Exporting env vars: AIRFLOW_CTX_DAG_OWNER='***' AIRFLOW_CTX_DAG_ID='my_scraping_dag' AIRFLOW_CTX_TASK_ID='main_task' AIRFLOW_CTX_EXECUTION_DATE='2023-03-17T00:00:00+00:00' AIRFLOW_CTX_TRY_NUMBER='1' AIRFLOW_CTX_DAG_RUN_ID='scheduled__2023-03-17T00:00:00+00:00'
[2023-12-07T17:00:18.453+0000] {taskinstance.py:1937} ERROR - Task failed with exception
Traceback (most recent call last):
  File "/home/airflow/.local/lib/python3.8/site-packages/airflow/operators/python.py", line 192, in execute
    return_value = self.execute_callable()
  File "/home/airflow/.local/lib/python3.8/site-packages/airflow/operators/python.py", line 209, in execute_callable
    return self.python_callable(*self.op_args, **self.op_kwargs)
  File "/opt/airflow/dags/main.py", line 33, in main
    'host': get_config('localhost'),
  File "/opt/airflow/dags/main.py", line 20, in get_config
    return Variable.get(key)
  File "/home/airflow/.local/lib/python3.8/site-packages/airflow/models/variable.py", line 140, in get
    raise KeyError(f"Variable {key} does not exist")
KeyError: 'Variable localhost does not exist'
[2023-12-07T17:00:18.457+0000] {taskinstance.py:1400} INFO - Marking task as FAILED. dag_id=my_scraping_dag, task_id=main_task, execution_date=20230317T000000, start_date=20231207T170018, end_date=20231207T170018
[2023-12-07T17:00:18.462+0000] {standard_task_runner.py:104} ERROR - Failed to execute job 1350 for task main_task ('Variable localhost does not exist'; 5741)
[2023-12-07T17:00:18.472+0000] {local_task_job_runner.py:228} INFO - Task exited with return code 1
[2023-12-07T17:00:18.484+0000] {taskinstance.py:2778} INFO - 0 downstream tasks scheduled from follow-on schedule check
[2023-12-07T17:03:40.963+0000] {taskinstance.py:1159} INFO - Dependencies all met for dep_context=non-requeueable deps ti=<TaskInstance: my_scraping_dag.main_task scheduled__2023-03-17T00:00:00+00:00 [queued]>
[2023-12-07T17:03:40.968+0000] {taskinstance.py:1159} INFO - Dependencies all met for dep_context=requeueable deps ti=<TaskInstance: my_scraping_dag.main_task scheduled__2023-03-17T00:00:00+00:00 [queued]>
[2023-12-07T17:03:40.969+0000] {taskinstance.py:1361} INFO - Starting attempt 1 of 1
[2023-12-07T17:03:40.976+0000] {taskinstance.py:1382} INFO - Executing <Task(PythonOperator): main_task> on 2023-03-17 00:00:00+00:00
[2023-12-07T17:03:40.981+0000] {standard_task_runner.py:57} INFO - Started process 7108 to run task
[2023-12-07T17:03:40.984+0000] {standard_task_runner.py:84} INFO - Running: ['***', 'tasks', 'run', 'my_scraping_dag', 'main_task', 'scheduled__2023-03-17T00:00:00+00:00', '--job-id', '1991', '--raw', '--subdir', 'DAGS_FOLDER/main.py', '--cfg-path', '/tmp/tmpxnhacab2']
[2023-12-07T17:03:40.986+0000] {standard_task_runner.py:85} INFO - Job 1991: Subtask main_task
[2023-12-07T17:03:41.020+0000] {task_command.py:416} INFO - Running <TaskInstance: my_scraping_dag.main_task scheduled__2023-03-17T00:00:00+00:00 [running]> on host 63b0c7e341c0
[2023-12-07T17:03:41.076+0000] {taskinstance.py:1662} INFO - Exporting env vars: AIRFLOW_CTX_DAG_OWNER='***' AIRFLOW_CTX_DAG_ID='my_scraping_dag' AIRFLOW_CTX_TASK_ID='main_task' AIRFLOW_CTX_EXECUTION_DATE='2023-03-17T00:00:00+00:00' AIRFLOW_CTX_TRY_NUMBER='1' AIRFLOW_CTX_DAG_RUN_ID='scheduled__2023-03-17T00:00:00+00:00'
[2023-12-07T17:03:41.120+0000] {logging_mixin.py:154} INFO - base_url: https://tuncbotanik.com
[2023-12-07T17:03:41.121+0000] {python.py:194} INFO - Done. Returned value was: ('https://tuncbotanik.com', {'User-Agent': 'Mozilla/5.0 (Macintosh; Intel Mac OS X 10_15_7) AppleWebKit/537.36 (KHTML, like Gecko) Chrome/119.0.0.0 Safari/537.36', 'Accept-Language': 'tr-TR,tr;q=0.9,en-US;q=0.8,en;q=0.7'}, {'dbname': 'plant', 'user': 'aozgokme', 'password': '***', 'host': 'localhost', 'port': '5432'})
[2023-12-07T17:03:41.140+0000] {taskinstance.py:1400} INFO - Marking task as SUCCESS. dag_id=my_scraping_dag, task_id=main_task, execution_date=20230317T000000, start_date=20231207T170340, end_date=20231207T170341
[2023-12-07T17:03:41.198+0000] {local_task_job_runner.py:228} INFO - Task exited with return code 0
[2023-12-07T17:03:41.220+0000] {taskinstance.py:2778} INFO - 1 downstream tasks scheduled from follow-on schedule check
[2023-12-07T17:18:33.075+0000] {taskinstance.py:1159} INFO - Dependencies all met for dep_context=non-requeueable deps ti=<TaskInstance: my_scraping_dag.main_task scheduled__2023-03-17T00:00:00+00:00 [queued]>
[2023-12-07T17:18:33.085+0000] {taskinstance.py:1159} INFO - Dependencies all met for dep_context=requeueable deps ti=<TaskInstance: my_scraping_dag.main_task scheduled__2023-03-17T00:00:00+00:00 [queued]>
[2023-12-07T17:18:33.086+0000] {taskinstance.py:1361} INFO - Starting attempt 1 of 1
[2023-12-07T17:18:33.093+0000] {taskinstance.py:1382} INFO - Executing <Task(PythonOperator): main_task> on 2023-03-17 00:00:00+00:00
[2023-12-07T17:18:33.097+0000] {standard_task_runner.py:57} INFO - Started process 8694 to run task
[2023-12-07T17:18:33.100+0000] {standard_task_runner.py:84} INFO - Running: ['***', 'tasks', 'run', 'my_scraping_dag', 'main_task', 'scheduled__2023-03-17T00:00:00+00:00', '--job-id', '2605', '--raw', '--subdir', 'DAGS_FOLDER/main.py', '--cfg-path', '/tmp/tmpc6oa1al6']
[2023-12-07T17:18:33.103+0000] {standard_task_runner.py:85} INFO - Job 2605: Subtask main_task
[2023-12-07T17:18:33.162+0000] {task_command.py:416} INFO - Running <TaskInstance: my_scraping_dag.main_task scheduled__2023-03-17T00:00:00+00:00 [running]> on host 63b0c7e341c0
[2023-12-07T17:18:33.245+0000] {taskinstance.py:1662} INFO - Exporting env vars: AIRFLOW_CTX_DAG_OWNER='***' AIRFLOW_CTX_DAG_ID='my_scraping_dag' AIRFLOW_CTX_TASK_ID='main_task' AIRFLOW_CTX_EXECUTION_DATE='2023-03-17T00:00:00+00:00' AIRFLOW_CTX_TRY_NUMBER='1' AIRFLOW_CTX_DAG_RUN_ID='scheduled__2023-03-17T00:00:00+00:00'
[2023-12-07T17:18:33.996+0000] {taskinstance.py:1937} ERROR - Task failed with exception
Traceback (most recent call last):
  File "/home/airflow/.local/lib/python3.8/site-packages/airflow/operators/python.py", line 192, in execute
    return_value = self.execute_callable()
  File "/home/airflow/.local/lib/python3.8/site-packages/airflow/operators/python.py", line 209, in execute_callable
    return self.python_callable(*self.op_args, **self.op_kwargs)
  File "/opt/airflow/dags/main.py", line 80, in main
    insert_data_to_db(products, db_params)
  File "/opt/airflow/dags/main.py", line 43, in insert_data_to_db
    with psycopg2.connect(**db_params) as conn:
  File "/home/airflow/.local/lib/python3.8/site-packages/psycopg2/__init__.py", line 122, in connect
    conn = _connect(dsn, connection_factory=connection_factory, **kwasync)
psycopg2.OperationalError: connection to server at "localhost" (127.0.0.1), port 5432 failed: Connection refused
	Is the server running on that host and accepting TCP/IP connections?
connection to server at "localhost" (::1), port 5432 failed: Cannot assign requested address
	Is the server running on that host and accepting TCP/IP connections?

[2023-12-07T17:18:34.000+0000] {taskinstance.py:1400} INFO - Marking task as FAILED. dag_id=my_scraping_dag, task_id=main_task, execution_date=20230317T000000, start_date=20231207T171833, end_date=20231207T171833
[2023-12-07T17:18:34.004+0000] {standard_task_runner.py:104} ERROR - Failed to execute job 2605 for task main_task (connection to server at "localhost" (127.0.0.1), port 5432 failed: Connection refused
	Is the server running on that host and accepting TCP/IP connections?
connection to server at "localhost" (::1), port 5432 failed: Cannot assign requested address
	Is the server running on that host and accepting TCP/IP connections?
; 8694)
[2023-12-07T17:18:34.047+0000] {local_task_job_runner.py:228} INFO - Task exited with return code 1
[2023-12-07T17:18:34.055+0000] {taskinstance.py:2778} INFO - 0 downstream tasks scheduled from follow-on schedule check
[2023-12-07T17:22:50.693+0000] {taskinstance.py:1159} INFO - Dependencies all met for dep_context=non-requeueable deps ti=<TaskInstance: my_scraping_dag.main_task scheduled__2023-03-17T00:00:00+00:00 [queued]>
[2023-12-07T17:22:50.698+0000] {taskinstance.py:1159} INFO - Dependencies all met for dep_context=requeueable deps ti=<TaskInstance: my_scraping_dag.main_task scheduled__2023-03-17T00:00:00+00:00 [queued]>
[2023-12-07T17:22:50.698+0000] {taskinstance.py:1361} INFO - Starting attempt 1 of 1
[2023-12-07T17:22:50.756+0000] {taskinstance.py:1382} INFO - Executing <Task(PythonOperator): main_task> on 2023-03-17 00:00:00+00:00
[2023-12-07T17:22:50.761+0000] {standard_task_runner.py:57} INFO - Started process 9489 to run task
[2023-12-07T17:22:50.773+0000] {standard_task_runner.py:84} INFO - Running: ['***', 'tasks', 'run', 'my_scraping_dag', 'main_task', 'scheduled__2023-03-17T00:00:00+00:00', '--job-id', '2947', '--raw', '--subdir', 'DAGS_FOLDER/main.py', '--cfg-path', '/tmp/tmpvgzkc163']
[2023-12-07T17:22:50.779+0000] {standard_task_runner.py:85} INFO - Job 2947: Subtask main_task
[2023-12-07T17:22:50.823+0000] {task_command.py:416} INFO - Running <TaskInstance: my_scraping_dag.main_task scheduled__2023-03-17T00:00:00+00:00 [running]> on host 63b0c7e341c0
[2023-12-07T17:22:50.888+0000] {taskinstance.py:1662} INFO - Exporting env vars: AIRFLOW_CTX_DAG_OWNER='***' AIRFLOW_CTX_DAG_ID='my_scraping_dag' AIRFLOW_CTX_TASK_ID='main_task' AIRFLOW_CTX_EXECUTION_DATE='2023-03-17T00:00:00+00:00' AIRFLOW_CTX_TRY_NUMBER='1' AIRFLOW_CTX_DAG_RUN_ID='scheduled__2023-03-17T00:00:00+00:00'
[2023-12-07T17:22:51.580+0000] {taskinstance.py:1937} ERROR - Task failed with exception
Traceback (most recent call last):
  File "/home/airflow/.local/lib/python3.8/site-packages/airflow/operators/python.py", line 192, in execute
    return_value = self.execute_callable()
  File "/home/airflow/.local/lib/python3.8/site-packages/airflow/operators/python.py", line 209, in execute_callable
    return self.python_callable(*self.op_args, **self.op_kwargs)
  File "/opt/airflow/dags/main.py", line 73, in main
    insert_data_to_db(products, db_params)
  File "/opt/airflow/dags/main.py", line 40, in insert_data_to_db
    with psycopg2.connect(**db_params) as conn:
  File "/home/airflow/.local/lib/python3.8/site-packages/psycopg2/__init__.py", line 122, in connect
    conn = _connect(dsn, connection_factory=connection_factory, **kwasync)
psycopg2.OperationalError: connection to server at "localhost" (127.0.0.1), port 5432 failed: Connection refused
	Is the server running on that host and accepting TCP/IP connections?
connection to server at "localhost" (::1), port 5432 failed: Cannot assign requested address
	Is the server running on that host and accepting TCP/IP connections?

[2023-12-07T17:22:51.584+0000] {taskinstance.py:1400} INFO - Marking task as FAILED. dag_id=my_scraping_dag, task_id=main_task, execution_date=20230317T000000, start_date=20231207T172250, end_date=20231207T172251
[2023-12-07T17:22:51.589+0000] {standard_task_runner.py:104} ERROR - Failed to execute job 2947 for task main_task (connection to server at "localhost" (127.0.0.1), port 5432 failed: Connection refused
	Is the server running on that host and accepting TCP/IP connections?
connection to server at "localhost" (::1), port 5432 failed: Cannot assign requested address
	Is the server running on that host and accepting TCP/IP connections?
; 9489)
[2023-12-07T17:22:51.626+0000] {local_task_job_runner.py:228} INFO - Task exited with return code 1
[2023-12-07T17:22:51.635+0000] {taskinstance.py:2778} INFO - 0 downstream tasks scheduled from follow-on schedule check
[2023-12-07T17:28:32.698+0000] {taskinstance.py:1159} INFO - Dependencies all met for dep_context=non-requeueable deps ti=<TaskInstance: my_scraping_dag.main_task scheduled__2023-03-17T00:00:00+00:00 [queued]>
[2023-12-07T17:28:32.708+0000] {taskinstance.py:1159} INFO - Dependencies all met for dep_context=requeueable deps ti=<TaskInstance: my_scraping_dag.main_task scheduled__2023-03-17T00:00:00+00:00 [queued]>
[2023-12-07T17:28:32.709+0000] {taskinstance.py:1361} INFO - Starting attempt 1 of 1
[2023-12-07T17:28:32.722+0000] {taskinstance.py:1382} INFO - Executing <Task(PythonOperator): main_task> on 2023-03-17 00:00:00+00:00
[2023-12-07T17:28:32.726+0000] {standard_task_runner.py:57} INFO - Started process 10331 to run task
[2023-12-07T17:28:32.729+0000] {standard_task_runner.py:84} INFO - Running: ['***', 'tasks', 'run', 'my_scraping_dag', 'main_task', 'scheduled__2023-03-17T00:00:00+00:00', '--job-id', '3289', '--raw', '--subdir', 'DAGS_FOLDER/main.py', '--cfg-path', '/tmp/tmpb4_g1vqk']
[2023-12-07T17:28:32.731+0000] {standard_task_runner.py:85} INFO - Job 3289: Subtask main_task
[2023-12-07T17:28:32.791+0000] {task_command.py:416} INFO - Running <TaskInstance: my_scraping_dag.main_task scheduled__2023-03-17T00:00:00+00:00 [running]> on host 63b0c7e341c0
[2023-12-07T17:28:32.844+0000] {taskinstance.py:1662} INFO - Exporting env vars: AIRFLOW_CTX_DAG_OWNER='***' AIRFLOW_CTX_DAG_ID='my_scraping_dag' AIRFLOW_CTX_TASK_ID='main_task' AIRFLOW_CTX_EXECUTION_DATE='2023-03-17T00:00:00+00:00' AIRFLOW_CTX_TRY_NUMBER='1' AIRFLOW_CTX_DAG_RUN_ID='scheduled__2023-03-17T00:00:00+00:00'
[2023-12-07T17:28:33.490+0000] {taskinstance.py:1937} ERROR - Task failed with exception
Traceback (most recent call last):
  File "/home/airflow/.local/lib/python3.8/site-packages/airflow/operators/python.py", line 192, in execute
    return_value = self.execute_callable()
  File "/home/airflow/.local/lib/python3.8/site-packages/airflow/operators/python.py", line 209, in execute_callable
    return self.python_callable(*self.op_args, **self.op_kwargs)
  File "/opt/airflow/dags/main.py", line 73, in main
    insert_data_to_db(products, db_params)
  File "/opt/airflow/dags/main.py", line 40, in insert_data_to_db
    with psycopg2.connect(**db_params) as conn:
  File "/home/airflow/.local/lib/python3.8/site-packages/psycopg2/__init__.py", line 122, in connect
    conn = _connect(dsn, connection_factory=connection_factory, **kwasync)
psycopg2.OperationalError: connection to server at "localhost" (127.0.0.1), port 5432 failed: Connection refused
	Is the server running on that host and accepting TCP/IP connections?
connection to server at "localhost" (::1), port 5432 failed: Cannot assign requested address
	Is the server running on that host and accepting TCP/IP connections?

[2023-12-07T17:28:33.495+0000] {taskinstance.py:1400} INFO - Marking task as FAILED. dag_id=my_scraping_dag, task_id=main_task, execution_date=20230317T000000, start_date=20231207T172832, end_date=20231207T172833
[2023-12-07T17:28:33.501+0000] {standard_task_runner.py:104} ERROR - Failed to execute job 3289 for task main_task (connection to server at "localhost" (127.0.0.1), port 5432 failed: Connection refused
	Is the server running on that host and accepting TCP/IP connections?
connection to server at "localhost" (::1), port 5432 failed: Cannot assign requested address
	Is the server running on that host and accepting TCP/IP connections?
; 10331)
[2023-12-07T17:28:33.526+0000] {local_task_job_runner.py:228} INFO - Task exited with return code 1
[2023-12-07T17:28:33.536+0000] {taskinstance.py:2778} INFO - 0 downstream tasks scheduled from follow-on schedule check
