[2023-12-07T14:52:34.399+0000] {taskinstance.py:1159} INFO - Dependencies all met for dep_context=non-requeueable deps ti=<TaskInstance: my_scraping_dag.main_task scheduled__2023-05-18T00:00:00+00:00 [queued]>
[2023-12-07T14:52:34.402+0000] {taskinstance.py:1159} INFO - Dependencies all met for dep_context=requeueable deps ti=<TaskInstance: my_scraping_dag.main_task scheduled__2023-05-18T00:00:00+00:00 [queued]>
[2023-12-07T14:52:34.402+0000] {taskinstance.py:1361} INFO - Starting attempt 1 of 1
[2023-12-07T14:52:34.407+0000] {taskinstance.py:1382} INFO - Executing <Task(PythonOperator): main_task> on 2023-05-18 00:00:00+00:00
[2023-12-07T14:52:34.410+0000] {standard_task_runner.py:57} INFO - Started process 1046 to run task
[2023-12-07T14:52:34.412+0000] {standard_task_runner.py:84} INFO - Running: ['***', 'tasks', 'run', 'my_scraping_dag', 'main_task', 'scheduled__2023-05-18T00:00:00+00:00', '--job-id', '248', '--raw', '--subdir', 'DAGS_FOLDER/main.py', '--cfg-path', '/tmp/tmp22cf1g0n']
[2023-12-07T14:52:34.414+0000] {standard_task_runner.py:85} INFO - Job 248: Subtask main_task
[2023-12-07T14:52:34.435+0000] {task_command.py:416} INFO - Running <TaskInstance: my_scraping_dag.main_task scheduled__2023-05-18T00:00:00+00:00 [running]> on host 63b0c7e341c0
[2023-12-07T14:52:34.463+0000] {taskinstance.py:1662} INFO - Exporting env vars: AIRFLOW_CTX_DAG_OWNER='***' AIRFLOW_CTX_DAG_ID='my_scraping_dag' AIRFLOW_CTX_TASK_ID='main_task' AIRFLOW_CTX_EXECUTION_DATE='2023-05-18T00:00:00+00:00' AIRFLOW_CTX_TRY_NUMBER='1' AIRFLOW_CTX_DAG_RUN_ID='scheduled__2023-05-18T00:00:00+00:00'
[2023-12-07T14:52:34.464+0000] {taskinstance.py:1937} ERROR - Task failed with exception
Traceback (most recent call last):
  File "/usr/local/lib/python3.8/configparser.py", line 846, in items
    d.update(self._sections[section])
KeyError: 'web'

During handling of the above exception, another exception occurred:

Traceback (most recent call last):
  File "/home/airflow/.local/lib/python3.8/site-packages/airflow/operators/python.py", line 192, in execute
    return_value = self.execute_callable()
  File "/home/airflow/.local/lib/python3.8/site-packages/airflow/operators/python.py", line 209, in execute_callable
    return self.python_callable(*self.op_args, **self.op_kwargs)
  File "/opt/airflow/dags/main.py", line 61, in main
    config = get_config('web')
  File "/opt/airflow/dags/main.py", line 23, in get_config
    return {key: value for key, value in parser.items(section)}
  File "/usr/local/lib/python3.8/configparser.py", line 849, in items
    raise NoSectionError(section)
configparser.NoSectionError: No section: 'web'
[2023-12-07T14:52:34.467+0000] {taskinstance.py:1400} INFO - Marking task as FAILED. dag_id=my_scraping_dag, task_id=main_task, execution_date=20230518T000000, start_date=20231207T145234, end_date=20231207T145234
[2023-12-07T14:52:34.471+0000] {standard_task_runner.py:104} ERROR - Failed to execute job 248 for task main_task (No section: 'web'; 1046)
[2023-12-07T14:52:34.510+0000] {local_task_job_runner.py:228} INFO - Task exited with return code 1
[2023-12-07T14:52:34.522+0000] {taskinstance.py:2778} INFO - 0 downstream tasks scheduled from follow-on schedule check
[2023-12-07T16:32:27.375+0000] {taskinstance.py:1159} INFO - Dependencies all met for dep_context=non-requeueable deps ti=<TaskInstance: my_scraping_dag.main_task scheduled__2023-05-18T00:00:00+00:00 [queued]>
[2023-12-07T16:32:27.378+0000] {taskinstance.py:1159} INFO - Dependencies all met for dep_context=requeueable deps ti=<TaskInstance: my_scraping_dag.main_task scheduled__2023-05-18T00:00:00+00:00 [queued]>
[2023-12-07T16:32:27.379+0000] {taskinstance.py:1361} INFO - Starting attempt 1 of 1
[2023-12-07T16:32:27.390+0000] {taskinstance.py:1382} INFO - Executing <Task(PythonOperator): main_task> on 2023-05-18 00:00:00+00:00
[2023-12-07T16:32:27.392+0000] {standard_task_runner.py:57} INFO - Started process 3816 to run task
[2023-12-07T16:32:27.395+0000] {standard_task_runner.py:84} INFO - Running: ['***', 'tasks', 'run', 'my_scraping_dag', 'main_task', 'scheduled__2023-05-18T00:00:00+00:00', '--job-id', '726', '--raw', '--subdir', 'DAGS_FOLDER/main.py', '--cfg-path', '/tmp/tmpplae0jpc']
[2023-12-07T16:32:27.397+0000] {standard_task_runner.py:85} INFO - Job 726: Subtask main_task
[2023-12-07T16:32:27.425+0000] {task_command.py:416} INFO - Running <TaskInstance: my_scraping_dag.main_task scheduled__2023-05-18T00:00:00+00:00 [running]> on host 63b0c7e341c0
[2023-12-07T16:32:27.464+0000] {taskinstance.py:1662} INFO - Exporting env vars: AIRFLOW_CTX_DAG_OWNER='***' AIRFLOW_CTX_DAG_ID='my_scraping_dag' AIRFLOW_CTX_TASK_ID='main_task' AIRFLOW_CTX_EXECUTION_DATE='2023-05-18T00:00:00+00:00' AIRFLOW_CTX_TRY_NUMBER='1' AIRFLOW_CTX_DAG_RUN_ID='scheduled__2023-05-18T00:00:00+00:00'
[2023-12-07T16:32:27.465+0000] {taskinstance.py:1937} ERROR - Task failed with exception
Traceback (most recent call last):
  File "/usr/local/lib/python3.8/configparser.py", line 846, in items
    d.update(self._sections[section])
KeyError: 'web'

During handling of the above exception, another exception occurred:

Traceback (most recent call last):
  File "/home/airflow/.local/lib/python3.8/site-packages/airflow/operators/python.py", line 192, in execute
    return_value = self.execute_callable()
  File "/home/airflow/.local/lib/python3.8/site-packages/airflow/operators/python.py", line 209, in execute_callable
    return self.python_callable(*self.op_args, **self.op_kwargs)
  File "/opt/airflow/dags/main.py", line 60, in main
    config = get_config('web')
  File "/opt/airflow/dags/main.py", line 22, in get_config
    return {key: value for key, value in parser.items(section)}
  File "/usr/local/lib/python3.8/configparser.py", line 849, in items
    raise NoSectionError(section)
configparser.NoSectionError: No section: 'web'
[2023-12-07T16:32:27.471+0000] {taskinstance.py:1400} INFO - Marking task as FAILED. dag_id=my_scraping_dag, task_id=main_task, execution_date=20230518T000000, start_date=20231207T163227, end_date=20231207T163227
[2023-12-07T16:32:27.476+0000] {standard_task_runner.py:104} ERROR - Failed to execute job 726 for task main_task (No section: 'web'; 3816)
[2023-12-07T16:32:27.487+0000] {local_task_job_runner.py:228} INFO - Task exited with return code 1
[2023-12-07T16:32:27.524+0000] {taskinstance.py:2778} INFO - 0 downstream tasks scheduled from follow-on schedule check
[2023-12-07T16:41:43.545+0000] {taskinstance.py:1159} INFO - Dependencies all met for dep_context=non-requeueable deps ti=<TaskInstance: my_scraping_dag.main_task scheduled__2023-05-18T00:00:00+00:00 [queued]>
[2023-12-07T16:41:43.552+0000] {taskinstance.py:1159} INFO - Dependencies all met for dep_context=requeueable deps ti=<TaskInstance: my_scraping_dag.main_task scheduled__2023-05-18T00:00:00+00:00 [queued]>
[2023-12-07T16:41:43.553+0000] {taskinstance.py:1361} INFO - Starting attempt 1 of 1
[2023-12-07T16:41:43.562+0000] {taskinstance.py:1382} INFO - Executing <Task(PythonOperator): main_task> on 2023-05-18 00:00:00+00:00
[2023-12-07T16:41:43.567+0000] {standard_task_runner.py:57} INFO - Started process 4722 to run task
[2023-12-07T16:41:43.572+0000] {standard_task_runner.py:84} INFO - Running: ['***', 'tasks', 'run', 'my_scraping_dag', 'main_task', 'scheduled__2023-05-18T00:00:00+00:00', '--job-id', '1069', '--raw', '--subdir', 'DAGS_FOLDER/main.py', '--cfg-path', '/tmp/tmpv5suzla1']
[2023-12-07T16:41:43.579+0000] {standard_task_runner.py:85} INFO - Job 1069: Subtask main_task
[2023-12-07T16:41:43.612+0000] {task_command.py:416} INFO - Running <TaskInstance: my_scraping_dag.main_task scheduled__2023-05-18T00:00:00+00:00 [running]> on host 63b0c7e341c0
[2023-12-07T16:41:43.657+0000] {taskinstance.py:1662} INFO - Exporting env vars: AIRFLOW_CTX_DAG_OWNER='***' AIRFLOW_CTX_DAG_ID='my_scraping_dag' AIRFLOW_CTX_TASK_ID='main_task' AIRFLOW_CTX_EXECUTION_DATE='2023-05-18T00:00:00+00:00' AIRFLOW_CTX_TRY_NUMBER='1' AIRFLOW_CTX_DAG_RUN_ID='scheduled__2023-05-18T00:00:00+00:00'
[2023-12-07T16:41:43.658+0000] {taskinstance.py:1937} ERROR - Task failed with exception
Traceback (most recent call last):
  File "/usr/local/lib/python3.8/configparser.py", line 846, in items
    d.update(self._sections[section])
KeyError: 'web'

During handling of the above exception, another exception occurred:

Traceback (most recent call last):
  File "/home/airflow/.local/lib/python3.8/site-packages/airflow/operators/python.py", line 192, in execute
    return_value = self.execute_callable()
  File "/home/airflow/.local/lib/python3.8/site-packages/airflow/operators/python.py", line 209, in execute_callable
    return self.python_callable(*self.op_args, **self.op_kwargs)
  File "/opt/airflow/dags/main.py", line 60, in main
    config = get_config('web')
  File "/opt/airflow/dags/main.py", line 22, in get_config
    return {key: value for key, value in parser.items(section)}
  File "/usr/local/lib/python3.8/configparser.py", line 849, in items
    raise NoSectionError(section)
configparser.NoSectionError: No section: 'web'
[2023-12-07T16:41:43.663+0000] {taskinstance.py:1400} INFO - Marking task as FAILED. dag_id=my_scraping_dag, task_id=main_task, execution_date=20230518T000000, start_date=20231207T164143, end_date=20231207T164143
[2023-12-07T16:41:43.669+0000] {standard_task_runner.py:104} ERROR - Failed to execute job 1069 for task main_task (No section: 'web'; 4722)
[2023-12-07T16:41:43.712+0000] {local_task_job_runner.py:228} INFO - Task exited with return code 1
[2023-12-07T16:41:43.724+0000] {taskinstance.py:2778} INFO - 0 downstream tasks scheduled from follow-on schedule check
[2023-12-07T17:00:44.584+0000] {taskinstance.py:1159} INFO - Dependencies all met for dep_context=non-requeueable deps ti=<TaskInstance: my_scraping_dag.main_task scheduled__2023-05-18T00:00:00+00:00 [queued]>
[2023-12-07T17:00:44.595+0000] {taskinstance.py:1159} INFO - Dependencies all met for dep_context=requeueable deps ti=<TaskInstance: my_scraping_dag.main_task scheduled__2023-05-18T00:00:00+00:00 [queued]>
[2023-12-07T17:00:44.599+0000] {taskinstance.py:1361} INFO - Starting attempt 1 of 1
[2023-12-07T17:00:44.613+0000] {taskinstance.py:1382} INFO - Executing <Task(PythonOperator): main_task> on 2023-05-18 00:00:00+00:00
[2023-12-07T17:00:44.617+0000] {standard_task_runner.py:57} INFO - Started process 5916 to run task
[2023-12-07T17:00:44.621+0000] {standard_task_runner.py:84} INFO - Running: ['***', 'tasks', 'run', 'my_scraping_dag', 'main_task', 'scheduled__2023-05-18T00:00:00+00:00', '--job-id', '1431', '--raw', '--subdir', 'DAGS_FOLDER/main.py', '--cfg-path', '/tmp/tmpu51qxuwl']
[2023-12-07T17:00:44.625+0000] {standard_task_runner.py:85} INFO - Job 1431: Subtask main_task
[2023-12-07T17:00:44.670+0000] {task_command.py:416} INFO - Running <TaskInstance: my_scraping_dag.main_task scheduled__2023-05-18T00:00:00+00:00 [running]> on host 63b0c7e341c0
[2023-12-07T17:00:44.721+0000] {taskinstance.py:1662} INFO - Exporting env vars: AIRFLOW_CTX_DAG_OWNER='***' AIRFLOW_CTX_DAG_ID='my_scraping_dag' AIRFLOW_CTX_TASK_ID='main_task' AIRFLOW_CTX_EXECUTION_DATE='2023-05-18T00:00:00+00:00' AIRFLOW_CTX_TRY_NUMBER='1' AIRFLOW_CTX_DAG_RUN_ID='scheduled__2023-05-18T00:00:00+00:00'
[2023-12-07T17:00:44.751+0000] {logging_mixin.py:154} INFO - base_url: https://tuncbotanik.com
[2023-12-07T17:00:44.752+0000] {python.py:194} INFO - Done. Returned value was: ('https://tuncbotanik.com', {'User-Agent': 'Mozilla/5.0 (Macintosh; Intel Mac OS X 10_15_7) AppleWebKit/537.36 (KHTML, like Gecko) Chrome/119.0.0.0 Safari/537.36', 'Accept-Language': 'tr-TR,tr;q=0.9,en-US;q=0.8,en;q=0.7'}, {'dbname': 'plant', 'user': 'aozgokme', 'password': '***', 'host': 'localhost', 'port': '5432'})
[2023-12-07T17:00:44.764+0000] {taskinstance.py:1400} INFO - Marking task as SUCCESS. dag_id=my_scraping_dag, task_id=main_task, execution_date=20230518T000000, start_date=20231207T170044, end_date=20231207T170044
[2023-12-07T17:00:44.798+0000] {local_task_job_runner.py:228} INFO - Task exited with return code 0
[2023-12-07T17:00:44.818+0000] {taskinstance.py:2778} INFO - 1 downstream tasks scheduled from follow-on schedule check
[2023-12-07T17:03:59.506+0000] {taskinstance.py:1159} INFO - Dependencies all met for dep_context=non-requeueable deps ti=<TaskInstance: my_scraping_dag.main_task scheduled__2023-05-18T00:00:00+00:00 [queued]>
[2023-12-07T17:03:59.510+0000] {taskinstance.py:1159} INFO - Dependencies all met for dep_context=requeueable deps ti=<TaskInstance: my_scraping_dag.main_task scheduled__2023-05-18T00:00:00+00:00 [queued]>
[2023-12-07T17:03:59.511+0000] {taskinstance.py:1361} INFO - Starting attempt 1 of 1
[2023-12-07T17:03:59.518+0000] {taskinstance.py:1382} INFO - Executing <Task(PythonOperator): main_task> on 2023-05-18 00:00:00+00:00
[2023-12-07T17:03:59.521+0000] {standard_task_runner.py:57} INFO - Started process 7354 to run task
[2023-12-07T17:03:59.524+0000] {standard_task_runner.py:84} INFO - Running: ['***', 'tasks', 'run', 'my_scraping_dag', 'main_task', 'scheduled__2023-05-18T00:00:00+00:00', '--job-id', '2114', '--raw', '--subdir', 'DAGS_FOLDER/main.py', '--cfg-path', '/tmp/tmp83okcdb9']
[2023-12-07T17:03:59.526+0000] {standard_task_runner.py:85} INFO - Job 2114: Subtask main_task
[2023-12-07T17:03:59.563+0000] {task_command.py:416} INFO - Running <TaskInstance: my_scraping_dag.main_task scheduled__2023-05-18T00:00:00+00:00 [running]> on host 63b0c7e341c0
[2023-12-07T17:03:59.599+0000] {taskinstance.py:1662} INFO - Exporting env vars: AIRFLOW_CTX_DAG_OWNER='***' AIRFLOW_CTX_DAG_ID='my_scraping_dag' AIRFLOW_CTX_TASK_ID='main_task' AIRFLOW_CTX_EXECUTION_DATE='2023-05-18T00:00:00+00:00' AIRFLOW_CTX_TRY_NUMBER='1' AIRFLOW_CTX_DAG_RUN_ID='scheduled__2023-05-18T00:00:00+00:00'
[2023-12-07T17:03:59.630+0000] {logging_mixin.py:154} INFO - base_url: https://tuncbotanik.com
[2023-12-07T17:03:59.631+0000] {python.py:194} INFO - Done. Returned value was: ('https://tuncbotanik.com', {'User-Agent': 'Mozilla/5.0 (Macintosh; Intel Mac OS X 10_15_7) AppleWebKit/537.36 (KHTML, like Gecko) Chrome/119.0.0.0 Safari/537.36', 'Accept-Language': 'tr-TR,tr;q=0.9,en-US;q=0.8,en;q=0.7'}, {'dbname': 'plant', 'user': 'aozgokme', 'password': '***', 'host': 'localhost', 'port': '5432'})
[2023-12-07T17:03:59.643+0000] {taskinstance.py:1400} INFO - Marking task as SUCCESS. dag_id=my_scraping_dag, task_id=main_task, execution_date=20230518T000000, start_date=20231207T170359, end_date=20231207T170359
[2023-12-07T17:03:59.699+0000] {local_task_job_runner.py:228} INFO - Task exited with return code 0
[2023-12-07T17:03:59.741+0000] {taskinstance.py:2778} INFO - 0 downstream tasks scheduled from follow-on schedule check
[2023-12-07T17:18:45.183+0000] {taskinstance.py:1159} INFO - Dependencies all met for dep_context=non-requeueable deps ti=<TaskInstance: my_scraping_dag.main_task scheduled__2023-05-18T00:00:00+00:00 [queued]>
[2023-12-07T17:18:45.188+0000] {taskinstance.py:1159} INFO - Dependencies all met for dep_context=requeueable deps ti=<TaskInstance: my_scraping_dag.main_task scheduled__2023-05-18T00:00:00+00:00 [queued]>
[2023-12-07T17:18:45.188+0000] {taskinstance.py:1361} INFO - Starting attempt 1 of 1
[2023-12-07T17:18:45.195+0000] {taskinstance.py:1382} INFO - Executing <Task(PythonOperator): main_task> on 2023-05-18 00:00:00+00:00
[2023-12-07T17:18:45.197+0000] {standard_task_runner.py:57} INFO - Started process 8821 to run task
[2023-12-07T17:18:45.200+0000] {standard_task_runner.py:84} INFO - Running: ['***', 'tasks', 'run', 'my_scraping_dag', 'main_task', 'scheduled__2023-05-18T00:00:00+00:00', '--job-id', '2667', '--raw', '--subdir', 'DAGS_FOLDER/main.py', '--cfg-path', '/tmp/tmp08f09p9s']
[2023-12-07T17:18:45.202+0000] {standard_task_runner.py:85} INFO - Job 2667: Subtask main_task
[2023-12-07T17:18:45.231+0000] {task_command.py:416} INFO - Running <TaskInstance: my_scraping_dag.main_task scheduled__2023-05-18T00:00:00+00:00 [running]> on host 63b0c7e341c0
[2023-12-07T17:18:45.271+0000] {taskinstance.py:1662} INFO - Exporting env vars: AIRFLOW_CTX_DAG_OWNER='***' AIRFLOW_CTX_DAG_ID='my_scraping_dag' AIRFLOW_CTX_TASK_ID='main_task' AIRFLOW_CTX_EXECUTION_DATE='2023-05-18T00:00:00+00:00' AIRFLOW_CTX_TRY_NUMBER='1' AIRFLOW_CTX_DAG_RUN_ID='scheduled__2023-05-18T00:00:00+00:00'
[2023-12-07T17:18:45.881+0000] {taskinstance.py:1937} ERROR - Task failed with exception
Traceback (most recent call last):
  File "/home/airflow/.local/lib/python3.8/site-packages/airflow/operators/python.py", line 192, in execute
    return_value = self.execute_callable()
  File "/home/airflow/.local/lib/python3.8/site-packages/airflow/operators/python.py", line 209, in execute_callable
    return self.python_callable(*self.op_args, **self.op_kwargs)
  File "/opt/airflow/dags/main.py", line 80, in main
    insert_data_to_db(products, db_params)
  File "/opt/airflow/dags/main.py", line 43, in insert_data_to_db
    with psycopg2.connect(**db_params) as conn:
  File "/home/airflow/.local/lib/python3.8/site-packages/psycopg2/__init__.py", line 122, in connect
    conn = _connect(dsn, connection_factory=connection_factory, **kwasync)
psycopg2.OperationalError: connection to server at "localhost" (127.0.0.1), port 5432 failed: Connection refused
	Is the server running on that host and accepting TCP/IP connections?
connection to server at "localhost" (::1), port 5432 failed: Cannot assign requested address
	Is the server running on that host and accepting TCP/IP connections?

[2023-12-07T17:18:45.885+0000] {taskinstance.py:1400} INFO - Marking task as FAILED. dag_id=my_scraping_dag, task_id=main_task, execution_date=20230518T000000, start_date=20231207T171845, end_date=20231207T171845
[2023-12-07T17:18:45.890+0000] {standard_task_runner.py:104} ERROR - Failed to execute job 2667 for task main_task (connection to server at "localhost" (127.0.0.1), port 5432 failed: Connection refused
	Is the server running on that host and accepting TCP/IP connections?
connection to server at "localhost" (::1), port 5432 failed: Cannot assign requested address
	Is the server running on that host and accepting TCP/IP connections?
; 8821)
[2023-12-07T17:18:45.899+0000] {local_task_job_runner.py:228} INFO - Task exited with return code 1
[2023-12-07T17:18:45.907+0000] {taskinstance.py:2778} INFO - 0 downstream tasks scheduled from follow-on schedule check
[2023-12-07T17:23:03.924+0000] {taskinstance.py:1159} INFO - Dependencies all met for dep_context=non-requeueable deps ti=<TaskInstance: my_scraping_dag.main_task scheduled__2023-05-18T00:00:00+00:00 [queued]>
[2023-12-07T17:23:03.933+0000] {taskinstance.py:1159} INFO - Dependencies all met for dep_context=requeueable deps ti=<TaskInstance: my_scraping_dag.main_task scheduled__2023-05-18T00:00:00+00:00 [queued]>
[2023-12-07T17:23:03.933+0000] {taskinstance.py:1361} INFO - Starting attempt 1 of 1
[2023-12-07T17:23:03.952+0000] {taskinstance.py:1382} INFO - Executing <Task(PythonOperator): main_task> on 2023-05-18 00:00:00+00:00
[2023-12-07T17:23:03.968+0000] {standard_task_runner.py:57} INFO - Started process 9625 to run task
[2023-12-07T17:23:03.990+0000] {standard_task_runner.py:84} INFO - Running: ['***', 'tasks', 'run', 'my_scraping_dag', 'main_task', 'scheduled__2023-05-18T00:00:00+00:00', '--job-id', '3009', '--raw', '--subdir', 'DAGS_FOLDER/main.py', '--cfg-path', '/tmp/tmpz93p7umy']
[2023-12-07T17:23:04.000+0000] {standard_task_runner.py:85} INFO - Job 3009: Subtask main_task
[2023-12-07T17:23:04.074+0000] {task_command.py:416} INFO - Running <TaskInstance: my_scraping_dag.main_task scheduled__2023-05-18T00:00:00+00:00 [running]> on host 63b0c7e341c0
[2023-12-07T17:23:04.198+0000] {taskinstance.py:1662} INFO - Exporting env vars: AIRFLOW_CTX_DAG_OWNER='***' AIRFLOW_CTX_DAG_ID='my_scraping_dag' AIRFLOW_CTX_TASK_ID='main_task' AIRFLOW_CTX_EXECUTION_DATE='2023-05-18T00:00:00+00:00' AIRFLOW_CTX_TRY_NUMBER='1' AIRFLOW_CTX_DAG_RUN_ID='scheduled__2023-05-18T00:00:00+00:00'
[2023-12-07T17:23:04.883+0000] {taskinstance.py:1937} ERROR - Task failed with exception
Traceback (most recent call last):
  File "/home/airflow/.local/lib/python3.8/site-packages/airflow/operators/python.py", line 192, in execute
    return_value = self.execute_callable()
  File "/home/airflow/.local/lib/python3.8/site-packages/airflow/operators/python.py", line 209, in execute_callable
    return self.python_callable(*self.op_args, **self.op_kwargs)
  File "/opt/airflow/dags/main.py", line 73, in main
    insert_data_to_db(products, db_params)
  File "/opt/airflow/dags/main.py", line 40, in insert_data_to_db
    with psycopg2.connect(**db_params) as conn:
  File "/home/airflow/.local/lib/python3.8/site-packages/psycopg2/__init__.py", line 122, in connect
    conn = _connect(dsn, connection_factory=connection_factory, **kwasync)
psycopg2.OperationalError: connection to server at "localhost" (127.0.0.1), port 5432 failed: Connection refused
	Is the server running on that host and accepting TCP/IP connections?
connection to server at "localhost" (::1), port 5432 failed: Cannot assign requested address
	Is the server running on that host and accepting TCP/IP connections?

[2023-12-07T17:23:04.888+0000] {taskinstance.py:1400} INFO - Marking task as FAILED. dag_id=my_scraping_dag, task_id=main_task, execution_date=20230518T000000, start_date=20231207T172303, end_date=20231207T172304
[2023-12-07T17:23:04.894+0000] {standard_task_runner.py:104} ERROR - Failed to execute job 3009 for task main_task (connection to server at "localhost" (127.0.0.1), port 5432 failed: Connection refused
	Is the server running on that host and accepting TCP/IP connections?
connection to server at "localhost" (::1), port 5432 failed: Cannot assign requested address
	Is the server running on that host and accepting TCP/IP connections?
; 9625)
[2023-12-07T17:23:04.923+0000] {local_task_job_runner.py:228} INFO - Task exited with return code 1
[2023-12-07T17:23:04.931+0000] {taskinstance.py:2778} INFO - 0 downstream tasks scheduled from follow-on schedule check
[2023-12-07T17:28:46.293+0000] {taskinstance.py:1159} INFO - Dependencies all met for dep_context=non-requeueable deps ti=<TaskInstance: my_scraping_dag.main_task scheduled__2023-05-18T00:00:00+00:00 [queued]>
[2023-12-07T17:28:46.302+0000] {taskinstance.py:1159} INFO - Dependencies all met for dep_context=requeueable deps ti=<TaskInstance: my_scraping_dag.main_task scheduled__2023-05-18T00:00:00+00:00 [queued]>
[2023-12-07T17:28:46.302+0000] {taskinstance.py:1361} INFO - Starting attempt 1 of 1
[2023-12-07T17:28:46.318+0000] {taskinstance.py:1382} INFO - Executing <Task(PythonOperator): main_task> on 2023-05-18 00:00:00+00:00
[2023-12-07T17:28:46.326+0000] {standard_task_runner.py:57} INFO - Started process 10458 to run task
[2023-12-07T17:28:46.347+0000] {standard_task_runner.py:84} INFO - Running: ['***', 'tasks', 'run', 'my_scraping_dag', 'main_task', 'scheduled__2023-05-18T00:00:00+00:00', '--job-id', '3351', '--raw', '--subdir', 'DAGS_FOLDER/main.py', '--cfg-path', '/tmp/tmppcrlo4l3']
[2023-12-07T17:28:46.361+0000] {standard_task_runner.py:85} INFO - Job 3351: Subtask main_task
[2023-12-07T17:28:46.400+0000] {task_command.py:416} INFO - Running <TaskInstance: my_scraping_dag.main_task scheduled__2023-05-18T00:00:00+00:00 [running]> on host 63b0c7e341c0
[2023-12-07T17:28:46.482+0000] {taskinstance.py:1662} INFO - Exporting env vars: AIRFLOW_CTX_DAG_OWNER='***' AIRFLOW_CTX_DAG_ID='my_scraping_dag' AIRFLOW_CTX_TASK_ID='main_task' AIRFLOW_CTX_EXECUTION_DATE='2023-05-18T00:00:00+00:00' AIRFLOW_CTX_TRY_NUMBER='1' AIRFLOW_CTX_DAG_RUN_ID='scheduled__2023-05-18T00:00:00+00:00'
[2023-12-07T17:28:47.193+0000] {taskinstance.py:1937} ERROR - Task failed with exception
Traceback (most recent call last):
  File "/home/airflow/.local/lib/python3.8/site-packages/airflow/operators/python.py", line 192, in execute
    return_value = self.execute_callable()
  File "/home/airflow/.local/lib/python3.8/site-packages/airflow/operators/python.py", line 209, in execute_callable
    return self.python_callable(*self.op_args, **self.op_kwargs)
  File "/opt/airflow/dags/main.py", line 73, in main
    insert_data_to_db(products, db_params)
  File "/opt/airflow/dags/main.py", line 40, in insert_data_to_db
    with psycopg2.connect(**db_params) as conn:
  File "/home/airflow/.local/lib/python3.8/site-packages/psycopg2/__init__.py", line 122, in connect
    conn = _connect(dsn, connection_factory=connection_factory, **kwasync)
psycopg2.OperationalError: connection to server at "localhost" (127.0.0.1), port 5432 failed: Connection refused
	Is the server running on that host and accepting TCP/IP connections?
connection to server at "localhost" (::1), port 5432 failed: Cannot assign requested address
	Is the server running on that host and accepting TCP/IP connections?

[2023-12-07T17:28:47.198+0000] {taskinstance.py:1400} INFO - Marking task as FAILED. dag_id=my_scraping_dag, task_id=main_task, execution_date=20230518T000000, start_date=20231207T172846, end_date=20231207T172847
[2023-12-07T17:28:47.203+0000] {standard_task_runner.py:104} ERROR - Failed to execute job 3351 for task main_task (connection to server at "localhost" (127.0.0.1), port 5432 failed: Connection refused
	Is the server running on that host and accepting TCP/IP connections?
connection to server at "localhost" (::1), port 5432 failed: Cannot assign requested address
	Is the server running on that host and accepting TCP/IP connections?
; 10458)
[2023-12-07T17:28:47.234+0000] {local_task_job_runner.py:228} INFO - Task exited with return code 1
[2023-12-07T17:28:47.243+0000] {taskinstance.py:2778} INFO - 0 downstream tasks scheduled from follow-on schedule check
[2023-12-09T07:34:46.089+0000] {taskinstance.py:1159} INFO - Dependencies all met for dep_context=non-requeueable deps ti=<TaskInstance: my_scraping_dag.main_task scheduled__2023-05-18T00:00:00+00:00 [queued]>
[2023-12-09T07:34:46.093+0000] {taskinstance.py:1159} INFO - Dependencies all met for dep_context=requeueable deps ti=<TaskInstance: my_scraping_dag.main_task scheduled__2023-05-18T00:00:00+00:00 [queued]>
[2023-12-09T07:34:46.093+0000] {taskinstance.py:1361} INFO - Starting attempt 1 of 1
[2023-12-09T07:34:46.102+0000] {taskinstance.py:1382} INFO - Executing <Task(PythonOperator): main_task> on 2023-05-18 00:00:00+00:00
[2023-12-09T07:34:46.105+0000] {standard_task_runner.py:57} INFO - Started process 873 to run task
[2023-12-09T07:34:46.107+0000] {standard_task_runner.py:84} INFO - Running: ['***', 'tasks', 'run', 'my_scraping_dag', 'main_task', 'scheduled__2023-05-18T00:00:00+00:00', '--job-id', '141', '--raw', '--subdir', 'DAGS_FOLDER/main.py', '--cfg-path', '/tmp/tmpss91g9x8']
[2023-12-09T07:34:46.109+0000] {standard_task_runner.py:85} INFO - Job 141: Subtask main_task
[2023-12-09T07:34:46.138+0000] {task_command.py:416} INFO - Running <TaskInstance: my_scraping_dag.main_task scheduled__2023-05-18T00:00:00+00:00 [running]> on host 36b5ef2505c9
[2023-12-09T07:34:46.180+0000] {taskinstance.py:1662} INFO - Exporting env vars: AIRFLOW_CTX_DAG_OWNER='***' AIRFLOW_CTX_DAG_ID='my_scraping_dag' AIRFLOW_CTX_TASK_ID='main_task' AIRFLOW_CTX_EXECUTION_DATE='2023-05-18T00:00:00+00:00' AIRFLOW_CTX_TRY_NUMBER='1' AIRFLOW_CTX_DAG_RUN_ID='scheduled__2023-05-18T00:00:00+00:00'
[2023-12-09T07:34:46.185+0000] {taskinstance.py:1937} ERROR - Task failed with exception
Traceback (most recent call last):
  File "/home/airflow/.local/lib/python3.8/site-packages/airflow/operators/python.py", line 192, in execute
    return_value = self.execute_callable()
  File "/home/airflow/.local/lib/python3.8/site-packages/airflow/operators/python.py", line 209, in execute_callable
    return self.python_callable(*self.op_args, **self.op_kwargs)
  File "/opt/airflow/dags/main.py", line 64, in main
    base_url = Variable.get('base_url')
  File "/home/airflow/.local/lib/python3.8/site-packages/airflow/models/variable.py", line 140, in get
    raise KeyError(f"Variable {key} does not exist")
KeyError: 'Variable base_url does not exist'
[2023-12-09T07:34:46.189+0000] {taskinstance.py:1400} INFO - Marking task as FAILED. dag_id=my_scraping_dag, task_id=main_task, execution_date=20230518T000000, start_date=20231209T073446, end_date=20231209T073446
[2023-12-09T07:34:46.197+0000] {standard_task_runner.py:104} ERROR - Failed to execute job 141 for task main_task ('Variable base_url does not exist'; 873)
[2023-12-09T07:34:46.240+0000] {local_task_job_runner.py:228} INFO - Task exited with return code 1
[2023-12-09T07:34:46.252+0000] {taskinstance.py:2778} INFO - 0 downstream tasks scheduled from follow-on schedule check
