[2023-12-07T14:52:19.406+0000] {taskinstance.py:1159} INFO - Dependencies all met for dep_context=non-requeueable deps ti=<TaskInstance: my_scraping_dag.main_task scheduled__2023-04-25T00:00:00+00:00 [queued]>
[2023-12-07T14:52:19.410+0000] {taskinstance.py:1159} INFO - Dependencies all met for dep_context=requeueable deps ti=<TaskInstance: my_scraping_dag.main_task scheduled__2023-04-25T00:00:00+00:00 [queued]>
[2023-12-07T14:52:19.410+0000] {taskinstance.py:1361} INFO - Starting attempt 1 of 1
[2023-12-07T14:52:19.416+0000] {taskinstance.py:1382} INFO - Executing <Task(PythonOperator): main_task> on 2023-04-25 00:00:00+00:00
[2023-12-07T14:52:19.418+0000] {standard_task_runner.py:57} INFO - Started process 989 to run task
[2023-12-07T14:52:19.421+0000] {standard_task_runner.py:84} INFO - Running: ['***', 'tasks', 'run', 'my_scraping_dag', 'main_task', 'scheduled__2023-04-25T00:00:00+00:00', '--job-id', '225', '--raw', '--subdir', 'DAGS_FOLDER/main.py', '--cfg-path', '/tmp/tmpyi61ar7i']
[2023-12-07T14:52:19.423+0000] {standard_task_runner.py:85} INFO - Job 225: Subtask main_task
[2023-12-07T14:52:19.454+0000] {task_command.py:416} INFO - Running <TaskInstance: my_scraping_dag.main_task scheduled__2023-04-25T00:00:00+00:00 [running]> on host 63b0c7e341c0
[2023-12-07T14:52:19.490+0000] {taskinstance.py:1662} INFO - Exporting env vars: AIRFLOW_CTX_DAG_OWNER='***' AIRFLOW_CTX_DAG_ID='my_scraping_dag' AIRFLOW_CTX_TASK_ID='main_task' AIRFLOW_CTX_EXECUTION_DATE='2023-04-25T00:00:00+00:00' AIRFLOW_CTX_TRY_NUMBER='1' AIRFLOW_CTX_DAG_RUN_ID='scheduled__2023-04-25T00:00:00+00:00'
[2023-12-07T14:52:19.491+0000] {taskinstance.py:1937} ERROR - Task failed with exception
Traceback (most recent call last):
  File "/usr/local/lib/python3.8/configparser.py", line 846, in items
    d.update(self._sections[section])
KeyError: 'web'

During handling of the above exception, another exception occurred:

Traceback (most recent call last):
  File "/home/airflow/.local/lib/python3.8/site-packages/airflow/operators/python.py", line 192, in execute
    return_value = self.execute_callable()
  File "/home/airflow/.local/lib/python3.8/site-packages/airflow/operators/python.py", line 209, in execute_callable
    return self.python_callable(*self.op_args, **self.op_kwargs)
  File "/opt/airflow/dags/main.py", line 61, in main
    config = get_config('web')
  File "/opt/airflow/dags/main.py", line 23, in get_config
    return {key: value for key, value in parser.items(section)}
  File "/usr/local/lib/python3.8/configparser.py", line 849, in items
    raise NoSectionError(section)
configparser.NoSectionError: No section: 'web'
[2023-12-07T14:52:19.496+0000] {taskinstance.py:1400} INFO - Marking task as FAILED. dag_id=my_scraping_dag, task_id=main_task, execution_date=20230425T000000, start_date=20231207T145219, end_date=20231207T145219
[2023-12-07T14:52:19.503+0000] {standard_task_runner.py:104} ERROR - Failed to execute job 225 for task main_task (No section: 'web'; 989)
[2023-12-07T14:52:19.513+0000] {local_task_job_runner.py:228} INFO - Task exited with return code 1
[2023-12-07T14:52:19.526+0000] {taskinstance.py:2778} INFO - 0 downstream tasks scheduled from follow-on schedule check
[2023-12-07T16:32:14.309+0000] {taskinstance.py:1159} INFO - Dependencies all met for dep_context=non-requeueable deps ti=<TaskInstance: my_scraping_dag.main_task scheduled__2023-04-25T00:00:00+00:00 [queued]>
[2023-12-07T16:32:14.314+0000] {taskinstance.py:1159} INFO - Dependencies all met for dep_context=requeueable deps ti=<TaskInstance: my_scraping_dag.main_task scheduled__2023-04-25T00:00:00+00:00 [queued]>
[2023-12-07T16:32:14.315+0000] {taskinstance.py:1361} INFO - Starting attempt 1 of 1
[2023-12-07T16:32:14.322+0000] {taskinstance.py:1382} INFO - Executing <Task(PythonOperator): main_task> on 2023-04-25 00:00:00+00:00
[2023-12-07T16:32:14.325+0000] {standard_task_runner.py:57} INFO - Started process 3769 to run task
[2023-12-07T16:32:14.327+0000] {standard_task_runner.py:84} INFO - Running: ['***', 'tasks', 'run', 'my_scraping_dag', 'main_task', 'scheduled__2023-04-25T00:00:00+00:00', '--job-id', '703', '--raw', '--subdir', 'DAGS_FOLDER/main.py', '--cfg-path', '/tmp/tmpmp7ryssi']
[2023-12-07T16:32:14.330+0000] {standard_task_runner.py:85} INFO - Job 703: Subtask main_task
[2023-12-07T16:32:14.363+0000] {task_command.py:416} INFO - Running <TaskInstance: my_scraping_dag.main_task scheduled__2023-04-25T00:00:00+00:00 [running]> on host 63b0c7e341c0
[2023-12-07T16:32:14.421+0000] {taskinstance.py:1662} INFO - Exporting env vars: AIRFLOW_CTX_DAG_OWNER='***' AIRFLOW_CTX_DAG_ID='my_scraping_dag' AIRFLOW_CTX_TASK_ID='main_task' AIRFLOW_CTX_EXECUTION_DATE='2023-04-25T00:00:00+00:00' AIRFLOW_CTX_TRY_NUMBER='1' AIRFLOW_CTX_DAG_RUN_ID='scheduled__2023-04-25T00:00:00+00:00'
[2023-12-07T16:32:14.423+0000] {taskinstance.py:1937} ERROR - Task failed with exception
Traceback (most recent call last):
  File "/usr/local/lib/python3.8/configparser.py", line 846, in items
    d.update(self._sections[section])
KeyError: 'web'

During handling of the above exception, another exception occurred:

Traceback (most recent call last):
  File "/home/airflow/.local/lib/python3.8/site-packages/airflow/operators/python.py", line 192, in execute
    return_value = self.execute_callable()
  File "/home/airflow/.local/lib/python3.8/site-packages/airflow/operators/python.py", line 209, in execute_callable
    return self.python_callable(*self.op_args, **self.op_kwargs)
  File "/opt/airflow/dags/main.py", line 60, in main
    config = get_config('web')
  File "/opt/airflow/dags/main.py", line 22, in get_config
    return {key: value for key, value in parser.items(section)}
  File "/usr/local/lib/python3.8/configparser.py", line 849, in items
    raise NoSectionError(section)
configparser.NoSectionError: No section: 'web'
[2023-12-07T16:32:14.432+0000] {taskinstance.py:1400} INFO - Marking task as FAILED. dag_id=my_scraping_dag, task_id=main_task, execution_date=20230425T000000, start_date=20231207T163214, end_date=20231207T163214
[2023-12-07T16:32:14.441+0000] {standard_task_runner.py:104} ERROR - Failed to execute job 703 for task main_task (No section: 'web'; 3769)
[2023-12-07T16:32:14.460+0000] {local_task_job_runner.py:228} INFO - Task exited with return code 1
[2023-12-07T16:32:14.476+0000] {taskinstance.py:2778} INFO - 0 downstream tasks scheduled from follow-on schedule check
[2023-12-07T16:41:34.663+0000] {taskinstance.py:1159} INFO - Dependencies all met for dep_context=non-requeueable deps ti=<TaskInstance: my_scraping_dag.main_task scheduled__2023-04-25T00:00:00+00:00 [queued]>
[2023-12-07T16:41:34.670+0000] {taskinstance.py:1159} INFO - Dependencies all met for dep_context=requeueable deps ti=<TaskInstance: my_scraping_dag.main_task scheduled__2023-04-25T00:00:00+00:00 [queued]>
[2023-12-07T16:41:34.670+0000] {taskinstance.py:1361} INFO - Starting attempt 1 of 1
[2023-12-07T16:41:34.684+0000] {taskinstance.py:1382} INFO - Executing <Task(PythonOperator): main_task> on 2023-04-25 00:00:00+00:00
[2023-12-07T16:41:34.687+0000] {standard_task_runner.py:57} INFO - Started process 4669 to run task
[2023-12-07T16:41:34.690+0000] {standard_task_runner.py:84} INFO - Running: ['***', 'tasks', 'run', 'my_scraping_dag', 'main_task', 'scheduled__2023-04-25T00:00:00+00:00', '--job-id', '1045', '--raw', '--subdir', 'DAGS_FOLDER/main.py', '--cfg-path', '/tmp/tmpmlrz9wk1']
[2023-12-07T16:41:34.693+0000] {standard_task_runner.py:85} INFO - Job 1045: Subtask main_task
[2023-12-07T16:41:34.719+0000] {task_command.py:416} INFO - Running <TaskInstance: my_scraping_dag.main_task scheduled__2023-04-25T00:00:00+00:00 [running]> on host 63b0c7e341c0
[2023-12-07T16:41:34.759+0000] {taskinstance.py:1662} INFO - Exporting env vars: AIRFLOW_CTX_DAG_OWNER='***' AIRFLOW_CTX_DAG_ID='my_scraping_dag' AIRFLOW_CTX_TASK_ID='main_task' AIRFLOW_CTX_EXECUTION_DATE='2023-04-25T00:00:00+00:00' AIRFLOW_CTX_TRY_NUMBER='1' AIRFLOW_CTX_DAG_RUN_ID='scheduled__2023-04-25T00:00:00+00:00'
[2023-12-07T16:41:34.761+0000] {taskinstance.py:1937} ERROR - Task failed with exception
Traceback (most recent call last):
  File "/usr/local/lib/python3.8/configparser.py", line 846, in items
    d.update(self._sections[section])
KeyError: 'web'

During handling of the above exception, another exception occurred:

Traceback (most recent call last):
  File "/home/airflow/.local/lib/python3.8/site-packages/airflow/operators/python.py", line 192, in execute
    return_value = self.execute_callable()
  File "/home/airflow/.local/lib/python3.8/site-packages/airflow/operators/python.py", line 209, in execute_callable
    return self.python_callable(*self.op_args, **self.op_kwargs)
  File "/opt/airflow/dags/main.py", line 60, in main
    config = get_config('web')
  File "/opt/airflow/dags/main.py", line 22, in get_config
    return {key: value for key, value in parser.items(section)}
  File "/usr/local/lib/python3.8/configparser.py", line 849, in items
    raise NoSectionError(section)
configparser.NoSectionError: No section: 'web'
[2023-12-07T16:41:34.772+0000] {taskinstance.py:1400} INFO - Marking task as FAILED. dag_id=my_scraping_dag, task_id=main_task, execution_date=20230425T000000, start_date=20231207T164134, end_date=20231207T164134
[2023-12-07T16:41:34.780+0000] {standard_task_runner.py:104} ERROR - Failed to execute job 1045 for task main_task (No section: 'web'; 4669)
[2023-12-07T16:41:34.822+0000] {local_task_job_runner.py:228} INFO - Task exited with return code 1
[2023-12-07T16:41:34.837+0000] {taskinstance.py:2778} INFO - 0 downstream tasks scheduled from follow-on schedule check
[2023-12-07T17:00:38.322+0000] {taskinstance.py:1159} INFO - Dependencies all met for dep_context=non-requeueable deps ti=<TaskInstance: my_scraping_dag.main_task scheduled__2023-04-25T00:00:00+00:00 [queued]>
[2023-12-07T17:00:38.325+0000] {taskinstance.py:1159} INFO - Dependencies all met for dep_context=requeueable deps ti=<TaskInstance: my_scraping_dag.main_task scheduled__2023-04-25T00:00:00+00:00 [queued]>
[2023-12-07T17:00:38.326+0000] {taskinstance.py:1361} INFO - Starting attempt 1 of 1
[2023-12-07T17:00:38.331+0000] {taskinstance.py:1382} INFO - Executing <Task(PythonOperator): main_task> on 2023-04-25 00:00:00+00:00
[2023-12-07T17:00:38.333+0000] {standard_task_runner.py:57} INFO - Started process 5830 to run task
[2023-12-07T17:00:38.335+0000] {standard_task_runner.py:84} INFO - Running: ['***', 'tasks', 'run', 'my_scraping_dag', 'main_task', 'scheduled__2023-04-25T00:00:00+00:00', '--job-id', '1389', '--raw', '--subdir', 'DAGS_FOLDER/main.py', '--cfg-path', '/tmp/tmpgayubrj3']
[2023-12-07T17:00:38.336+0000] {standard_task_runner.py:85} INFO - Job 1389: Subtask main_task
[2023-12-07T17:00:38.356+0000] {task_command.py:416} INFO - Running <TaskInstance: my_scraping_dag.main_task scheduled__2023-04-25T00:00:00+00:00 [running]> on host 63b0c7e341c0
[2023-12-07T17:00:38.385+0000] {taskinstance.py:1662} INFO - Exporting env vars: AIRFLOW_CTX_DAG_OWNER='***' AIRFLOW_CTX_DAG_ID='my_scraping_dag' AIRFLOW_CTX_TASK_ID='main_task' AIRFLOW_CTX_EXECUTION_DATE='2023-04-25T00:00:00+00:00' AIRFLOW_CTX_TRY_NUMBER='1' AIRFLOW_CTX_DAG_RUN_ID='scheduled__2023-04-25T00:00:00+00:00'
[2023-12-07T17:00:38.398+0000] {logging_mixin.py:154} INFO - base_url: https://tuncbotanik.com
[2023-12-07T17:00:38.398+0000] {python.py:194} INFO - Done. Returned value was: ('https://tuncbotanik.com', {'User-Agent': 'Mozilla/5.0 (Macintosh; Intel Mac OS X 10_15_7) AppleWebKit/537.36 (KHTML, like Gecko) Chrome/119.0.0.0 Safari/537.36', 'Accept-Language': 'tr-TR,tr;q=0.9,en-US;q=0.8,en;q=0.7'}, {'dbname': 'plant', 'user': 'aozgokme', 'password': '***', 'host': 'localhost', 'port': '5432'})
[2023-12-07T17:00:38.406+0000] {taskinstance.py:1400} INFO - Marking task as SUCCESS. dag_id=my_scraping_dag, task_id=main_task, execution_date=20230425T000000, start_date=20231207T170038, end_date=20231207T170038
[2023-12-07T17:00:38.428+0000] {local_task_job_runner.py:228} INFO - Task exited with return code 0
[2023-12-07T17:00:38.440+0000] {taskinstance.py:2778} INFO - 1 downstream tasks scheduled from follow-on schedule check
[2023-12-07T17:03:54.780+0000] {taskinstance.py:1159} INFO - Dependencies all met for dep_context=non-requeueable deps ti=<TaskInstance: my_scraping_dag.main_task scheduled__2023-04-25T00:00:00+00:00 [queued]>
[2023-12-07T17:03:54.786+0000] {taskinstance.py:1159} INFO - Dependencies all met for dep_context=requeueable deps ti=<TaskInstance: my_scraping_dag.main_task scheduled__2023-04-25T00:00:00+00:00 [queued]>
[2023-12-07T17:03:54.789+0000] {taskinstance.py:1361} INFO - Starting attempt 1 of 1
[2023-12-07T17:03:54.798+0000] {taskinstance.py:1382} INFO - Executing <Task(PythonOperator): main_task> on 2023-04-25 00:00:00+00:00
[2023-12-07T17:03:54.802+0000] {standard_task_runner.py:57} INFO - Started process 7264 to run task
[2023-12-07T17:03:54.805+0000] {standard_task_runner.py:84} INFO - Running: ['***', 'tasks', 'run', 'my_scraping_dag', 'main_task', 'scheduled__2023-04-25T00:00:00+00:00', '--job-id', '2068', '--raw', '--subdir', 'DAGS_FOLDER/main.py', '--cfg-path', '/tmp/tmp1jb0mgaw']
[2023-12-07T17:03:54.808+0000] {standard_task_runner.py:85} INFO - Job 2068: Subtask main_task
[2023-12-07T17:03:54.847+0000] {task_command.py:416} INFO - Running <TaskInstance: my_scraping_dag.main_task scheduled__2023-04-25T00:00:00+00:00 [running]> on host 63b0c7e341c0
[2023-12-07T17:03:54.899+0000] {taskinstance.py:1662} INFO - Exporting env vars: AIRFLOW_CTX_DAG_OWNER='***' AIRFLOW_CTX_DAG_ID='my_scraping_dag' AIRFLOW_CTX_TASK_ID='main_task' AIRFLOW_CTX_EXECUTION_DATE='2023-04-25T00:00:00+00:00' AIRFLOW_CTX_TRY_NUMBER='1' AIRFLOW_CTX_DAG_RUN_ID='scheduled__2023-04-25T00:00:00+00:00'
[2023-12-07T17:03:54.938+0000] {logging_mixin.py:154} INFO - base_url: https://tuncbotanik.com
[2023-12-07T17:03:54.940+0000] {python.py:194} INFO - Done. Returned value was: ('https://tuncbotanik.com', {'User-Agent': 'Mozilla/5.0 (Macintosh; Intel Mac OS X 10_15_7) AppleWebKit/537.36 (KHTML, like Gecko) Chrome/119.0.0.0 Safari/537.36', 'Accept-Language': 'tr-TR,tr;q=0.9,en-US;q=0.8,en;q=0.7'}, {'dbname': 'plant', 'user': 'aozgokme', 'password': '***', 'host': 'localhost', 'port': '5432'})
[2023-12-07T17:03:54.967+0000] {taskinstance.py:1400} INFO - Marking task as SUCCESS. dag_id=my_scraping_dag, task_id=main_task, execution_date=20230425T000000, start_date=20231207T170354, end_date=20231207T170354
[2023-12-07T17:03:54.981+0000] {local_task_job_runner.py:228} INFO - Task exited with return code 0
[2023-12-07T17:03:54.998+0000] {taskinstance.py:2778} INFO - 1 downstream tasks scheduled from follow-on schedule check
[2023-12-07T17:18:42.454+0000] {taskinstance.py:1159} INFO - Dependencies all met for dep_context=non-requeueable deps ti=<TaskInstance: my_scraping_dag.main_task scheduled__2023-04-25T00:00:00+00:00 [queued]>
[2023-12-07T17:18:42.459+0000] {taskinstance.py:1159} INFO - Dependencies all met for dep_context=requeueable deps ti=<TaskInstance: my_scraping_dag.main_task scheduled__2023-04-25T00:00:00+00:00 [queued]>
[2023-12-07T17:18:42.460+0000] {taskinstance.py:1361} INFO - Starting attempt 1 of 1
[2023-12-07T17:18:42.466+0000] {taskinstance.py:1382} INFO - Executing <Task(PythonOperator): main_task> on 2023-04-25 00:00:00+00:00
[2023-12-07T17:18:42.469+0000] {standard_task_runner.py:57} INFO - Started process 8778 to run task
[2023-12-07T17:18:42.471+0000] {standard_task_runner.py:84} INFO - Running: ['***', 'tasks', 'run', 'my_scraping_dag', 'main_task', 'scheduled__2023-04-25T00:00:00+00:00', '--job-id', '2644', '--raw', '--subdir', 'DAGS_FOLDER/main.py', '--cfg-path', '/tmp/tmp8q7nrkx9']
[2023-12-07T17:18:42.473+0000] {standard_task_runner.py:85} INFO - Job 2644: Subtask main_task
[2023-12-07T17:18:42.502+0000] {task_command.py:416} INFO - Running <TaskInstance: my_scraping_dag.main_task scheduled__2023-04-25T00:00:00+00:00 [running]> on host 63b0c7e341c0
[2023-12-07T17:18:42.548+0000] {taskinstance.py:1662} INFO - Exporting env vars: AIRFLOW_CTX_DAG_OWNER='***' AIRFLOW_CTX_DAG_ID='my_scraping_dag' AIRFLOW_CTX_TASK_ID='main_task' AIRFLOW_CTX_EXECUTION_DATE='2023-04-25T00:00:00+00:00' AIRFLOW_CTX_TRY_NUMBER='1' AIRFLOW_CTX_DAG_RUN_ID='scheduled__2023-04-25T00:00:00+00:00'
[2023-12-07T17:18:43.253+0000] {taskinstance.py:1937} ERROR - Task failed with exception
Traceback (most recent call last):
  File "/home/airflow/.local/lib/python3.8/site-packages/airflow/operators/python.py", line 192, in execute
    return_value = self.execute_callable()
  File "/home/airflow/.local/lib/python3.8/site-packages/airflow/operators/python.py", line 209, in execute_callable
    return self.python_callable(*self.op_args, **self.op_kwargs)
  File "/opt/airflow/dags/main.py", line 80, in main
    insert_data_to_db(products, db_params)
  File "/opt/airflow/dags/main.py", line 43, in insert_data_to_db
    with psycopg2.connect(**db_params) as conn:
  File "/home/airflow/.local/lib/python3.8/site-packages/psycopg2/__init__.py", line 122, in connect
    conn = _connect(dsn, connection_factory=connection_factory, **kwasync)
psycopg2.OperationalError: connection to server at "localhost" (127.0.0.1), port 5432 failed: Connection refused
	Is the server running on that host and accepting TCP/IP connections?
connection to server at "localhost" (::1), port 5432 failed: Cannot assign requested address
	Is the server running on that host and accepting TCP/IP connections?

[2023-12-07T17:18:43.259+0000] {taskinstance.py:1400} INFO - Marking task as FAILED. dag_id=my_scraping_dag, task_id=main_task, execution_date=20230425T000000, start_date=20231207T171842, end_date=20231207T171843
[2023-12-07T17:18:43.265+0000] {standard_task_runner.py:104} ERROR - Failed to execute job 2644 for task main_task (connection to server at "localhost" (127.0.0.1), port 5432 failed: Connection refused
	Is the server running on that host and accepting TCP/IP connections?
connection to server at "localhost" (::1), port 5432 failed: Cannot assign requested address
	Is the server running on that host and accepting TCP/IP connections?
; 8778)
[2023-12-07T17:18:43.291+0000] {local_task_job_runner.py:228} INFO - Task exited with return code 1
[2023-12-07T17:18:43.301+0000] {taskinstance.py:2778} INFO - 0 downstream tasks scheduled from follow-on schedule check
[2023-12-07T17:23:00.234+0000] {taskinstance.py:1159} INFO - Dependencies all met for dep_context=non-requeueable deps ti=<TaskInstance: my_scraping_dag.main_task scheduled__2023-04-25T00:00:00+00:00 [queued]>
[2023-12-07T17:23:00.242+0000] {taskinstance.py:1159} INFO - Dependencies all met for dep_context=requeueable deps ti=<TaskInstance: my_scraping_dag.main_task scheduled__2023-04-25T00:00:00+00:00 [queued]>
[2023-12-07T17:23:00.243+0000] {taskinstance.py:1361} INFO - Starting attempt 1 of 1
[2023-12-07T17:23:00.251+0000] {taskinstance.py:1382} INFO - Executing <Task(PythonOperator): main_task> on 2023-04-25 00:00:00+00:00
[2023-12-07T17:23:00.257+0000] {standard_task_runner.py:57} INFO - Started process 9579 to run task
[2023-12-07T17:23:00.259+0000] {standard_task_runner.py:84} INFO - Running: ['***', 'tasks', 'run', 'my_scraping_dag', 'main_task', 'scheduled__2023-04-25T00:00:00+00:00', '--job-id', '2986', '--raw', '--subdir', 'DAGS_FOLDER/main.py', '--cfg-path', '/tmp/tmp1g3a4j1g']
[2023-12-07T17:23:00.261+0000] {standard_task_runner.py:85} INFO - Job 2986: Subtask main_task
[2023-12-07T17:23:00.302+0000] {task_command.py:416} INFO - Running <TaskInstance: my_scraping_dag.main_task scheduled__2023-04-25T00:00:00+00:00 [running]> on host 63b0c7e341c0
[2023-12-07T17:23:00.343+0000] {taskinstance.py:1662} INFO - Exporting env vars: AIRFLOW_CTX_DAG_OWNER='***' AIRFLOW_CTX_DAG_ID='my_scraping_dag' AIRFLOW_CTX_TASK_ID='main_task' AIRFLOW_CTX_EXECUTION_DATE='2023-04-25T00:00:00+00:00' AIRFLOW_CTX_TRY_NUMBER='1' AIRFLOW_CTX_DAG_RUN_ID='scheduled__2023-04-25T00:00:00+00:00'
[2023-12-07T17:23:01.217+0000] {taskinstance.py:1937} ERROR - Task failed with exception
Traceback (most recent call last):
  File "/home/airflow/.local/lib/python3.8/site-packages/airflow/operators/python.py", line 192, in execute
    return_value = self.execute_callable()
  File "/home/airflow/.local/lib/python3.8/site-packages/airflow/operators/python.py", line 209, in execute_callable
    return self.python_callable(*self.op_args, **self.op_kwargs)
  File "/opt/airflow/dags/main.py", line 73, in main
    insert_data_to_db(products, db_params)
  File "/opt/airflow/dags/main.py", line 40, in insert_data_to_db
    with psycopg2.connect(**db_params) as conn:
  File "/home/airflow/.local/lib/python3.8/site-packages/psycopg2/__init__.py", line 122, in connect
    conn = _connect(dsn, connection_factory=connection_factory, **kwasync)
psycopg2.OperationalError: connection to server at "localhost" (127.0.0.1), port 5432 failed: Connection refused
	Is the server running on that host and accepting TCP/IP connections?
connection to server at "localhost" (::1), port 5432 failed: Cannot assign requested address
	Is the server running on that host and accepting TCP/IP connections?

[2023-12-07T17:23:01.225+0000] {taskinstance.py:1400} INFO - Marking task as FAILED. dag_id=my_scraping_dag, task_id=main_task, execution_date=20230425T000000, start_date=20231207T172300, end_date=20231207T172301
[2023-12-07T17:23:01.232+0000] {standard_task_runner.py:104} ERROR - Failed to execute job 2986 for task main_task (connection to server at "localhost" (127.0.0.1), port 5432 failed: Connection refused
	Is the server running on that host and accepting TCP/IP connections?
connection to server at "localhost" (::1), port 5432 failed: Cannot assign requested address
	Is the server running on that host and accepting TCP/IP connections?
; 9579)
[2023-12-07T17:23:01.275+0000] {local_task_job_runner.py:228} INFO - Task exited with return code 1
[2023-12-07T17:23:01.285+0000] {taskinstance.py:2778} INFO - 0 downstream tasks scheduled from follow-on schedule check
[2023-12-07T17:28:42.815+0000] {taskinstance.py:1159} INFO - Dependencies all met for dep_context=non-requeueable deps ti=<TaskInstance: my_scraping_dag.main_task scheduled__2023-04-25T00:00:00+00:00 [queued]>
[2023-12-07T17:28:42.819+0000] {taskinstance.py:1159} INFO - Dependencies all met for dep_context=requeueable deps ti=<TaskInstance: my_scraping_dag.main_task scheduled__2023-04-25T00:00:00+00:00 [queued]>
[2023-12-07T17:28:42.819+0000] {taskinstance.py:1361} INFO - Starting attempt 1 of 1
[2023-12-07T17:28:42.827+0000] {taskinstance.py:1382} INFO - Executing <Task(PythonOperator): main_task> on 2023-04-25 00:00:00+00:00
[2023-12-07T17:28:42.830+0000] {standard_task_runner.py:57} INFO - Started process 10414 to run task
[2023-12-07T17:28:42.834+0000] {standard_task_runner.py:84} INFO - Running: ['***', 'tasks', 'run', 'my_scraping_dag', 'main_task', 'scheduled__2023-04-25T00:00:00+00:00', '--job-id', '3328', '--raw', '--subdir', 'DAGS_FOLDER/main.py', '--cfg-path', '/tmp/tmp4jdxmdcf']
[2023-12-07T17:28:42.836+0000] {standard_task_runner.py:85} INFO - Job 3328: Subtask main_task
[2023-12-07T17:28:42.863+0000] {task_command.py:416} INFO - Running <TaskInstance: my_scraping_dag.main_task scheduled__2023-04-25T00:00:00+00:00 [running]> on host 63b0c7e341c0
[2023-12-07T17:28:42.899+0000] {taskinstance.py:1662} INFO - Exporting env vars: AIRFLOW_CTX_DAG_OWNER='***' AIRFLOW_CTX_DAG_ID='my_scraping_dag' AIRFLOW_CTX_TASK_ID='main_task' AIRFLOW_CTX_EXECUTION_DATE='2023-04-25T00:00:00+00:00' AIRFLOW_CTX_TRY_NUMBER='1' AIRFLOW_CTX_DAG_RUN_ID='scheduled__2023-04-25T00:00:00+00:00'
[2023-12-07T17:28:43.618+0000] {taskinstance.py:1937} ERROR - Task failed with exception
Traceback (most recent call last):
  File "/home/airflow/.local/lib/python3.8/site-packages/airflow/operators/python.py", line 192, in execute
    return_value = self.execute_callable()
  File "/home/airflow/.local/lib/python3.8/site-packages/airflow/operators/python.py", line 209, in execute_callable
    return self.python_callable(*self.op_args, **self.op_kwargs)
  File "/opt/airflow/dags/main.py", line 73, in main
    insert_data_to_db(products, db_params)
  File "/opt/airflow/dags/main.py", line 40, in insert_data_to_db
    with psycopg2.connect(**db_params) as conn:
  File "/home/airflow/.local/lib/python3.8/site-packages/psycopg2/__init__.py", line 122, in connect
    conn = _connect(dsn, connection_factory=connection_factory, **kwasync)
psycopg2.OperationalError: connection to server at "localhost" (127.0.0.1), port 5432 failed: Connection refused
	Is the server running on that host and accepting TCP/IP connections?
connection to server at "localhost" (::1), port 5432 failed: Cannot assign requested address
	Is the server running on that host and accepting TCP/IP connections?

[2023-12-07T17:28:43.627+0000] {taskinstance.py:1400} INFO - Marking task as FAILED. dag_id=my_scraping_dag, task_id=main_task, execution_date=20230425T000000, start_date=20231207T172842, end_date=20231207T172843
[2023-12-07T17:28:43.634+0000] {standard_task_runner.py:104} ERROR - Failed to execute job 3328 for task main_task (connection to server at "localhost" (127.0.0.1), port 5432 failed: Connection refused
	Is the server running on that host and accepting TCP/IP connections?
connection to server at "localhost" (::1), port 5432 failed: Cannot assign requested address
	Is the server running on that host and accepting TCP/IP connections?
; 10414)
[2023-12-07T17:28:43.647+0000] {local_task_job_runner.py:228} INFO - Task exited with return code 1
[2023-12-07T17:28:43.662+0000] {taskinstance.py:2778} INFO - 0 downstream tasks scheduled from follow-on schedule check
[2023-12-09T07:34:38.854+0000] {taskinstance.py:1159} INFO - Dependencies all met for dep_context=non-requeueable deps ti=<TaskInstance: my_scraping_dag.main_task scheduled__2023-04-25T00:00:00+00:00 [queued]>
[2023-12-09T07:34:38.858+0000] {taskinstance.py:1159} INFO - Dependencies all met for dep_context=requeueable deps ti=<TaskInstance: my_scraping_dag.main_task scheduled__2023-04-25T00:00:00+00:00 [queued]>
[2023-12-09T07:34:38.858+0000] {taskinstance.py:1361} INFO - Starting attempt 1 of 1
[2023-12-09T07:34:38.867+0000] {taskinstance.py:1382} INFO - Executing <Task(PythonOperator): main_task> on 2023-04-25 00:00:00+00:00
[2023-12-09T07:34:38.871+0000] {standard_task_runner.py:57} INFO - Started process 827 to run task
[2023-12-09T07:34:38.873+0000] {standard_task_runner.py:84} INFO - Running: ['***', 'tasks', 'run', 'my_scraping_dag', 'main_task', 'scheduled__2023-04-25T00:00:00+00:00', '--job-id', '118', '--raw', '--subdir', 'DAGS_FOLDER/main.py', '--cfg-path', '/tmp/tmp__f_ks3b']
[2023-12-09T07:34:38.875+0000] {standard_task_runner.py:85} INFO - Job 118: Subtask main_task
[2023-12-09T07:34:38.902+0000] {task_command.py:416} INFO - Running <TaskInstance: my_scraping_dag.main_task scheduled__2023-04-25T00:00:00+00:00 [running]> on host 36b5ef2505c9
[2023-12-09T07:34:38.942+0000] {taskinstance.py:1662} INFO - Exporting env vars: AIRFLOW_CTX_DAG_OWNER='***' AIRFLOW_CTX_DAG_ID='my_scraping_dag' AIRFLOW_CTX_TASK_ID='main_task' AIRFLOW_CTX_EXECUTION_DATE='2023-04-25T00:00:00+00:00' AIRFLOW_CTX_TRY_NUMBER='1' AIRFLOW_CTX_DAG_RUN_ID='scheduled__2023-04-25T00:00:00+00:00'
[2023-12-09T07:34:38.946+0000] {taskinstance.py:1937} ERROR - Task failed with exception
Traceback (most recent call last):
  File "/home/airflow/.local/lib/python3.8/site-packages/airflow/operators/python.py", line 192, in execute
    return_value = self.execute_callable()
  File "/home/airflow/.local/lib/python3.8/site-packages/airflow/operators/python.py", line 209, in execute_callable
    return self.python_callable(*self.op_args, **self.op_kwargs)
  File "/opt/airflow/dags/main.py", line 64, in main
    base_url = Variable.get('base_url')
  File "/home/airflow/.local/lib/python3.8/site-packages/airflow/models/variable.py", line 140, in get
    raise KeyError(f"Variable {key} does not exist")
KeyError: 'Variable base_url does not exist'
[2023-12-09T07:34:38.953+0000] {taskinstance.py:1400} INFO - Marking task as FAILED. dag_id=my_scraping_dag, task_id=main_task, execution_date=20230425T000000, start_date=20231209T073438, end_date=20231209T073438
[2023-12-09T07:34:38.959+0000] {standard_task_runner.py:104} ERROR - Failed to execute job 118 for task main_task ('Variable base_url does not exist'; 827)
[2023-12-09T07:34:38.966+0000] {local_task_job_runner.py:228} INFO - Task exited with return code 1
[2023-12-09T07:34:38.975+0000] {taskinstance.py:2778} INFO - 0 downstream tasks scheduled from follow-on schedule check
